Workbook
Name budi: DF!$O$75
Name eko: DF!$D$85
Name kode_jawaban: DF!$D$86

Sheet XL-Test
B1: Hard Level (⭐⭐⭐)
B2: KODE SOAL | D2: SBEH010 | F2: KODE JAWABAN | G2: =kode_jawaban -> HJ2|66-7594;20-23BE;42-210C;1B-4CF4;30-E0B5F;22-5B40;30-138B35680;26-850;4A-79E0;38-76C0
B5: Team | C5: Rank 1 (n) | D5: SoT 2 (%) | E5: G/SoT 3 (n) | F5: Last 5 Results | G5: Last 5 Points 4 (n) | H5: Average Attendance 5 (n) | I5: Occupancy 6 (%) | J5: Ticket Price | K5: Stadium Revenue 7 (€) | L5: Yellow Card 8 (n) | M5: Goals 9 (n) | N5: ITA Players 10 (n)
B6: Torino | C6: =MATCH(B6,LS!$A$4:$A$23,0) -> 11 | D6: =ROUND(SUMIFS(LS!$I$4:$I$23,LS!$A$4:$A$23,'XL-Test'!B6)/SUMIFS(LS!$H$4:$H$23,LS!$A$4:$A$23,'XL-Test'!B6),2) -> 0.32 | E6: =ROUND((SUMIFS(LS!$G$4:$G$23,LS!$A$4:$A$23,'XL-Test'!B6)-SUMIFS(LS!$J$4:$J$23,LS!$A$4:$A$23,'XL-Test'!B6))/SUMIFS(LS!$I$4:$I$23,LS!$A$4:$A$23,'XL-Test'!B6),2) -> 0.28 | F6: LDLLL | G6: {=SUMPRODUCT(_xlfn.SWITCH(MID(F6,{1,2,3,4,5},1),"W",3,"D",1,0))} -> 1 | H6: =ROUND(AVERAGEIFS(SA!$F$4:$F$383,SA!$B$4:$B$383,'XL-Test'!B6),0) -> 23324 | I6: =ROUND(H6/_xlfn.XLOOKUP(B6,SA!$B$4:$B$383,SA!$E$4:$E$383),2) -> 0.83 | J6: 230 | K6: =SUMIFS(SA!$F$4:$F$383,SA!$B$4:$B$383,'XL-Test'!B6)*J6 -> 101925650 | L6: =SUMIFS(PS!$H$4:$H$637,PS!$D$4:$D$637,'XL-Test'!B6) -> 80 | M6: =_xlfn.MAXIFS(PS!$F$4:$F$637,PS!$D$4:$D$637,'XL-Test'!B6) -> 9 | N6: =COUNTIFS(PS!$D$4:$D$637,'XL-Test'!B6,PS!$B$4:$B$637,"ITA") -> 8
B7: Fiorentina | C7: =MATCH(B7,LS!$A$4:$A$23,0) -> 6 | D7: =ROUND(SUMIFS(LS!$I$4:$I$23,LS!$A$4:$A$23,'XL-Test'!B7)/SUMIFS(LS!$H$4:$H$23,LS!$A$4:$A$23,'XL-Test'!B7),2) -> 0.38 | E7: =ROUND((SUMIFS(LS!$G$4:$G$23,LS!$A$4:$A$23,'XL-Test'!B7)-SUMIFS(LS!$J$4:$J$23,LS!$A$4:$A$23,'XL-Test'!B7))/SUMIFS(LS!$I$4:$I$23,LS!$A$4:$A$23,'XL-Test'!B7),2) -> 0.31 | F7: WLLWW | G7: {=SUMPRODUCT(_xlfn.SWITCH(MID(F7,{1,2,3,4,5},1),"W",3,"D",1,0))} -> 9 | H7: =ROUND(AVERAGEIFS(SA!$F$4:$F$383,SA!$B$4:$B$383,'XL-Test'!B7),0) -> 20410 | I7: =ROUND(H7/_xlfn.XLOOKUP(B7,SA!$B$4:$B$383,SA!$E$4:$E$383),2) -> 0.47 | J7: 350 | K7: =SUMIFS(SA!$F$4:$F$383,SA!$B$4:$B$383,'XL-Test'!B7)*J7 -> 135727550 | L7: =SUMIFS(PS!$H$4:$H$637,PS!$D$4:$D$637,'XL-Test'!B7) -> 82 | M7: =_xlfn.MAXIFS(PS!$F$4:$F$637,PS!$D$4:$D$637,'XL-Test'!B7) -> 19 | N7: =COUNTIFS(PS!$D$4:$D$637,'XL-Test'!B7,PS!$B$4:$B$637,"ITA") -> 19
B8: Bologna | C8: =MATCH(B8,LS!$A$4:$A$23,0) -> 9 | D8: =ROUND(SUMIFS(LS!$I$4:$I$23,LS!$A$4:$A$23,'XL-Test'!B8)/SUMIFS(LS!$H$4:$H$23,LS!$A$4:$A$23,'XL-Test'!B8),2) -> 0.33 | E8: =ROUND((SUMIFS(LS!$G$4:$G$23,LS!$A$4:$A$23,'XL-Test'!B8)-SUMIFS(LS!$J$4:$J$23,LS!$A$4:$A$23,'XL-Test'!B8))/SUMIFS(LS!$I$4:$I$23,LS!$A$4:$A$23,'XL-Test'!B8),2) -> 0.3 | F8: DDLLL | G8: {=SUMPRODUCT(_xlfn.SWITCH(MID(F8,{1,2,3,4,5},1),"W",3,"D",1,0))} -> 2 | H8: =ROUND(AVERAGEIFS(SA!$F$4:$F$383,SA!$B$4:$B$383,'XL-Test'!B8),0) -> 28213 | I8: =ROUND(H8/_xlfn.XLOOKUP(B8,SA!$B$4:$B$383,SA!$E$4:$E$383),2) -> 0.77 | J8: 300 | K8: =SUMIFS(SA!$F$4:$F$383,SA!$B$4:$B$383,'XL-Test'!B8)*J8 -> 160811400 | L8: =SUMIFS(PS!$H$4:$H$637,PS!$D$4:$D$637,'XL-Test'!B8) -> 61 | M8: =_xlfn.MAXIFS(PS!$F$4:$F$637,PS!$D$4:$D$637,'XL-Test'!B8) -> 15 | N8: =COUNTIFS(PS!$D$4:$D$637,'XL-Test'!B8,PS!$B$4:$B$637,"ITA") -> 8
B9: Como | C9: =MATCH(B9,LS!$A$4:$A$23,0) -> 10 | D9: =ROUND(SUMIFS(LS!$I$4:$I$23,LS!$A$4:$A$23,'XL-Test'!B9)/SUMIFS(LS!$H$4:$H$23,LS!$A$4:$A$23,'XL-Test'!B9),2) -> 0.34 | E9: =ROUND((SUMIFS(LS!$G$4:$G$23,LS!$A$4:$A$23,'XL-Test'!B9)-SUMIFS(LS!$J$4:$J$23,LS!$A$4:$A$23,'XL-Test'!B9))/SUMIFS(LS!$I$4:$I$23,LS!$A$4:$A$23,'XL-Test'!B9),2) -> 0.25 | F9: WWWDL | G9: {=SUMPRODUCT(_xlfn.SWITCH(MID(F9,{1,2,3,4,5},1),"W",3,"D",1,0))} -> 10 | H9: =ROUND(AVERAGEIFS(SA!$F$4:$F$383,SA!$B$4:$B$383,'XL-Test'!B9),0) -> 10830 | I9: =ROUND(H9/_xlfn.XLOOKUP(B9,SA!$B$4:$B$383,SA!$E$4:$E$383),2) -> 0.9 | J9: 304 | K9: =SUMIFS(SA!$F$4:$F$383,SA!$B$4:$B$383,'XL-Test'!B9)*J9 -> 62554080 | L9: =SUMIFS(PS!$H$4:$H$637,PS!$D$4:$D$637,'XL-Test'!B9) -> 87 | M9: =_xlfn.MAXIFS(PS!$F$4:$F$637,PS!$D$4:$D$637,'XL-Test'!B9) -> 8 | N9: =COUNTIFS(PS!$D$4:$D$637,'XL-Test'!B9,PS!$B$4:$B$637,"ITA") -> 12
B10: Empoli | C10: =MATCH(B10,LS!$A$4:$A$23,0) -> 18 | D10: =ROUND(SUMIFS(LS!$I$4:$I$23,LS!$A$4:$A$23,'XL-Test'!B10)/SUMIFS(LS!$H$4:$H$23,LS!$A$4:$A$23,'XL-Test'!B10),2) -> 0.29 | E10: =ROUND((SUMIFS(LS!$G$4:$G$23,LS!$A$4:$A$23,'XL-Test'!B10)-SUMIFS(LS!$J$4:$J$23,LS!$A$4:$A$23,'XL-Test'!B10))/SUMIFS(LS!$I$4:$I$23,LS!$A$4:$A$23,'XL-Test'!B10),2) -> 0.27 | F10: LLWWL | G10: {=SUMPRODUCT(_xlfn.SWITCH(MID(F10,{1,2,3,4,5},1),"W",3,"D",1,0))} -> 6 | H10: =ROUND(AVERAGEIFS(SA!$F$4:$F$383,SA!$B$4:$B$383,'XL-Test'!B10),0) -> 11151 | I10: =ROUND(H10/_xlfn.XLOOKUP(B10,SA!$B$4:$B$383,SA!$E$4:$E$383),2) -> 0.56 | J10: 255 | K10: =SUMIFS(SA!$F$4:$F$383,SA!$B$4:$B$383,'XL-Test'!B10)*J10 -> 54026340 | L10: =SUMIFS(PS!$H$4:$H$637,PS!$D$4:$D$637,'XL-Test'!B10) -> 68 | M10: =_xlfn.MAXIFS(PS!$F$4:$F$637,PS!$D$4:$D$637,'XL-Test'!B10) -> 8 | N10: =COUNTIFS(PS!$D$4:$D$637,'XL-Test'!B10,PS!$B$4:$B$637,"ITA") -> 16
B11: Genoa | C11: =MATCH(B11,LS!$A$4:$A$23,0) -> 13 | D11: =ROUND(SUMIFS(LS!$I$4:$I$23,LS!$A$4:$A$23,'XL-Test'!B11)/SUMIFS(LS!$H$4:$H$23,LS!$A$4:$A$23,'XL-Test'!B11),2) -> 0.31 | E11: =ROUND((SUMIFS(LS!$G$4:$G$23,LS!$A$4:$A$23,'XL-Test'!B11)-SUMIFS(LS!$J$4:$J$23,LS!$A$4:$A$23,'XL-Test'!B11))/SUMIFS(LS!$I$4:$I$23,LS!$A$4:$A$23,'XL-Test'!B11),2) -> 0.3 | F11: LLDLW | G11: {=SUMPRODUCT(_xlfn.SWITCH(MID(F11,{1,2,3,4,5},1),"W",3,"D",1,0))} -> 4 | H11: =ROUND(AVERAGEIFS(SA!$F$4:$F$383,SA!$B$4:$B$383,'XL-Test'!B11),0) -> 30772 | I11: =ROUND(H11/_xlfn.XLOOKUP(B11,SA!$B$4:$B$383,SA!$E$4:$E$383),2) -> 0.88 | J11: 225 | K11: =SUMIFS(SA!$F$4:$F$383,SA!$B$4:$B$383,'XL-Test'!B11)*J11 -> 131550750 | L11: =SUMIFS(PS!$H$4:$H$637,PS!$D$4:$D$637,'XL-Test'!B11) -> 71 | M11: =_xlfn.MAXIFS(PS!$F$4:$F$637,PS!$D$4:$D$637,'XL-Test'!B11) -> 10 | N11: =COUNTIFS(PS!$D$4:$D$637,'XL-Test'!B11,PS!$B$4:$B$637,"ITA") -> 17
B12: Udinese | C12: =MATCH(B12,LS!$A$4:$A$23,0) -> 12 | D12: =ROUND(SUMIFS(LS!$I$4:$I$23,LS!$A$4:$A$23,'XL-Test'!B12)/SUMIFS(LS!$H$4:$H$23,LS!$A$4:$A$23,'XL-Test'!B12),2) -> 0.32 | E12: =ROUND((SUMIFS(LS!$G$4:$G$23,LS!$A$4:$A$23,'XL-Test'!B12)-SUMIFS(LS!$J$4:$J$23,LS!$A$4:$A$23,'XL-Test'!B12))/SUMIFS(LS!$I$4:$I$23,LS!$A$4:$A$23,'XL-Test'!B12),2) -> 0.28 | F12: DWLLL | G12: {=SUMPRODUCT(_xlfn.SWITCH(MID(F12,{1,2,3,4,5},1),"W",3,"D",1,0))} -> 4 | H12: =ROUND(AVERAGEIFS(SA!$F$4:$F$383,SA!$B$4:$B$383,'XL-Test'!B12),0) -> 21823 | I12: =ROUND(H12/_xlfn.XLOOKUP(B12,SA!$B$4:$B$383,SA!$E$4:$E$383),2) -> 0.87 | J12: 250 | K12: =SUMIFS(SA!$F$4:$F$383,SA!$B$4:$B$383,'XL-Test'!B12)*J12 -> 103660250 | L12: =SUMIFS(PS!$H$4:$H$637,PS!$D$4:$D$637,'XL-Test'!B12) -> 88 | M12: =_xlfn.MAXIFS(PS!$F$4:$F$637,PS!$D$4:$D$637,'XL-Test'!B12) -> 12 | N12: =COUNTIFS(PS!$D$4:$D$637,'XL-Test'!B12,PS!$B$4:$B$637,"ITA") -> 3
B13: Juventus | C13: =MATCH(B13,LS!$A$4:$A$23,0) -> 4 | D13: =ROUND(SUMIFS(LS!$I$4:$I$23,LS!$A$4:$A$23,'XL-Test'!B13)/SUMIFS(LS!$H$4:$H$23,LS!$A$4:$A$23,'XL-Test'!B13),2) -> 0.34 | E13: =ROUND((SUMIFS(LS!$G$4:$G$23,LS!$A$4:$A$23,'XL-Test'!B13)-SUMIFS(LS!$J$4:$J$23,LS!$A$4:$A$23,'XL-Test'!B13))/SUMIFS(LS!$I$4:$I$23,LS!$A$4:$A$23,'XL-Test'!B13),2) -> 0.29 | F13: WDDWW | G13: {=SUMPRODUCT(_xlfn.SWITCH(MID(F13,{1,2,3,4,5},1),"W",3,"D",1,0))} -> 11 | H13: =ROUND(AVERAGEIFS(SA!$F$4:$F$383,SA!$B$4:$B$383,'XL-Test'!B13),0) -> 40228 | I13: =ROUND(H13/_xlfn.XLOOKUP(B13,SA!$B$4:$B$383,SA!$E$4:$E$383),2) -> 0.97 | J13: 544 | K13: =SUMIFS(SA!$F$4:$F$383,SA!$B$4:$B$383,'XL-Test'!B13)*J13 -> 415793344 | L13: =SUMIFS(PS!$H$4:$H$637,PS!$D$4:$D$637,'XL-Test'!B13) -> 67 | M13: =_xlfn.MAXIFS(PS!$F$4:$F$637,PS!$D$4:$D$637,'XL-Test'!B13) -> 10 | N13: =COUNTIFS(PS!$D$4:$D$637,'XL-Test'!B13,PS!$B$4:$B$637,"ITA") -> 9
B14: Monza | C14: =MATCH(B14,LS!$A$4:$A$23,0) -> 20 | D14: =ROUND(SUMIFS(LS!$I$4:$I$23,LS!$A$4:$A$23,'XL-Test'!B14)/SUMIFS(LS!$H$4:$H$23,LS!$A$4:$A$23,'XL-Test'!B14),2) -> 0.3 | E14: =ROUND((SUMIFS(LS!$G$4:$G$23,LS!$A$4:$A$23,'XL-Test'!B14)-SUMIFS(LS!$J$4:$J$23,LS!$A$4:$A$23,'XL-Test'!B14))/SUMIFS(LS!$I$4:$I$23,LS!$A$4:$A$23,'XL-Test'!B14),2) -> 0.24 | F14: LLWLL | G14: {=SUMPRODUCT(_xlfn.SWITCH(MID(F14,{1,2,3,4,5},1),"W",3,"D",1,0))} -> 3 | H14: =ROUND(AVERAGEIFS(SA!$F$4:$F$383,SA!$B$4:$B$383,'XL-Test'!B14),0) -> 11274 | I14: =ROUND(H14/_xlfn.XLOOKUP(B14,SA!$B$4:$B$383,SA!$E$4:$E$383),2) -> 0.66 | J14: 260 | K14: =SUMIFS(SA!$F$4:$F$383,SA!$B$4:$B$383,'XL-Test'!B14)*J14 -> 55691220 | L14: =SUMIFS(PS!$H$4:$H$637,PS!$D$4:$D$637,'XL-Test'!B14) -> 90 | M14: =_xlfn.MAXIFS(PS!$F$4:$F$637,PS!$D$4:$D$637,'XL-Test'!B14) -> 5 | N14: =COUNTIFS(PS!$D$4:$D$637,'XL-Test'!B14,PS!$B$4:$B$637,"ITA") -> 21
B15: Napoli | C15: =MATCH(B15,LS!$A$4:$A$23,0) -> 1 | D15: =ROUND(SUMIFS(LS!$I$4:$I$23,LS!$A$4:$A$23,'XL-Test'!B15)/SUMIFS(LS!$H$4:$H$23,LS!$A$4:$A$23,'XL-Test'!B15),2) -> 0.3 | E15: =ROUND((SUMIFS(LS!$G$4:$G$23,LS!$A$4:$A$23,'XL-Test'!B15)-SUMIFS(LS!$J$4:$J$23,LS!$A$4:$A$23,'XL-Test'!B15))/SUMIFS(LS!$I$4:$I$23,LS!$A$4:$A$23,'XL-Test'!B15),2) -> 0.35 | F15: WWDDW | G15: {=SUMPRODUCT(_xlfn.SWITCH(MID(F15,{1,2,3,4,5},1),"W",3,"D",1,0))} -> 11 | H15: =ROUND(AVERAGEIFS(SA!$F$4:$F$383,SA!$B$4:$B$383,'XL-Test'!B15),0) -> 51398 | I15: =ROUND(H15/_xlfn.XLOOKUP(B15,SA!$B$4:$B$383,SA!$E$4:$E$383),2) -> 0.94 | J15: 280 | K15: =SUMIFS(SA!$F$4:$F$383,SA!$B$4:$B$383,'XL-Test'!B15)*J15 -> 273439880 | L15: =SUMIFS(PS!$H$4:$H$637,PS!$D$4:$D$637,'XL-Test'!B15) -> 46 | M15: =_xlfn.MAXIFS(PS!$F$4:$F$637,PS!$D$4:$D$637,'XL-Test'!B15) -> 14 | N15: =COUNTIFS(PS!$D$4:$D$637,'XL-Test'!B15,PS!$B$4:$B$637,"ITA") -> 11
B16: Lecce | C16: =MATCH(B16,LS!$A$4:$A$23,0) -> 17 | D16: =ROUND(SUMIFS(LS!$I$4:$I$23,LS!$A$4:$A$23,'XL-Test'!B16)/SUMIFS(LS!$H$4:$H$23,LS!$A$4:$A$23,'XL-Test'!B16),2) -> 0.26 | E16: =ROUND((SUMIFS(LS!$G$4:$G$23,LS!$A$4:$A$23,'XL-Test'!B16)-SUMIFS(LS!$J$4:$J$23,LS!$A$4:$A$23,'XL-Test'!B16))/SUMIFS(LS!$I$4:$I$23,LS!$A$4:$A$23,'XL-Test'!B16),2) -> 0.2 | F16: DLDWW | G16: {=SUMPRODUCT(_xlfn.SWITCH(MID(F16,{1,2,3,4,5},1),"W",3,"D",1,0))} -> 8 | H16: =ROUND(AVERAGEIFS(SA!$F$4:$F$383,SA!$B$4:$B$383,'XL-Test'!B16),0) -> 26031 | I16: =ROUND(H16/_xlfn.XLOOKUP(B16,SA!$B$4:$B$383,SA!$E$4:$E$383),2) -> 0.82 | J16: 305 | K16: =SUMIFS(SA!$F$4:$F$383,SA!$B$4:$B$383,'XL-Test'!B16)*J16 -> 150846900 | L16: =SUMIFS(PS!$H$4:$H$637,PS!$D$4:$D$637,'XL-Test'!B16) -> 61 | M16: =_xlfn.MAXIFS(PS!$F$4:$F$637,PS!$D$4:$D$637,'XL-Test'!B16) -> 11 | N16: =COUNTIFS(PS!$D$4:$D$637,'XL-Test'!B16,PS!$B$4:$B$637,"ITA") -> 6
B17: Cagliari | C17: =MATCH(B17,LS!$A$4:$A$23,0) -> 15 | D17: =ROUND(SUMIFS(LS!$I$4:$I$23,LS!$A$4:$A$23,'XL-Test'!B17)/SUMIFS(LS!$H$4:$H$23,LS!$A$4:$A$23,'XL-Test'!B17),2) -> 0.27 | E17: =ROUND((SUMIFS(LS!$G$4:$G$23,LS!$A$4:$A$23,'XL-Test'!B17)-SUMIFS(LS!$J$4:$J$23,LS!$A$4:$A$23,'XL-Test'!B17))/SUMIFS(LS!$I$4:$I$23,LS!$A$4:$A$23,'XL-Test'!B17),2) -> 0.3 | F17: WLLWL | G17: {=SUMPRODUCT(_xlfn.SWITCH(MID(F17,{1,2,3,4,5},1),"W",3,"D",1,0))} -> 6 | H17: =ROUND(AVERAGEIFS(SA!$F$4:$F$383,SA!$B$4:$B$383,'XL-Test'!B17),0) -> 15745 | I17: =ROUND(H17/_xlfn.XLOOKUP(B17,SA!$B$4:$B$383,SA!$E$4:$E$383),2) -> 0.96 | J17: 280 | K17: =SUMIFS(SA!$F$4:$F$383,SA!$B$4:$B$383,'XL-Test'!B17)*J17 -> 83763120 | L17: =SUMIFS(PS!$H$4:$H$637,PS!$D$4:$D$637,'XL-Test'!B17) -> 68 | M17: =_xlfn.MAXIFS(PS!$F$4:$F$637,PS!$D$4:$D$637,'XL-Test'!B17) -> 10 | N17: =COUNTIFS(PS!$D$4:$D$637,'XL-Test'!B17,PS!$B$4:$B$637,"ITA") -> 15
... B25: Hellas Verona | C25: =MATCH(B25,LS!$A$4:$A$23,0) -> 14 | D25: =ROUND(SUMIFS(LS!$I$4:$I$23,LS!$A$4:$A$23,'XL-Test'!B25)/SUMIFS(LS!$H$4:$H$23,LS!$A$4:$A$23,'XL-Test'!B25),2) -> 0.26 | E25: =ROUND((SUMIFS(LS!$G$4:$G$23,LS!$A$4:$A$23,'XL-Test'!B25)-SUMIFS(LS!$J$4:$J$23,LS!$A$4:$A$23,'XL-Test'!B25))/SUMIFS(LS!$I$4:$I$23,LS!$A$4:$A$23,'XL-Test'!B25),2) -> 0.31 | F25: LLDDW | G25: {=SUMPRODUCT(_xlfn.SWITCH(MID(F25,{1,2,3,4,5},1),"W",3,"D",1,0))} -> 5 | H25: =ROUND(AVERAGEIFS(SA!$F$4:$F$383,SA!$B$4:$B$383,'XL-Test'!B25),0) -> 24787 | I25: =ROUND(H25/_xlfn.XLOOKUP(B25,SA!$B$4:$B$383,SA!$E$4:$E$383),2) -> 0.63 | J25: 190 | K25: =SUMIFS(SA!$F$4:$F$383,SA!$B$4:$B$383,'XL-Test'!B25)*J25 -> 89482210 | L25: =SUMIFS(PS!$H$4:$H$637,PS!$D$4:$D$637,'XL-Test'!B25) -> 97 | M25: =_xlfn.MAXIFS(PS!$F$4:$F$637,PS!$D$4:$D$637,'XL-Test'!B25) -> 6 | N25: =COUNTIFS(PS!$D$4:$D$637,'XL-Test'!B25,PS!$B$4:$B$637,"ITA") -> 7
B27: kirim Kode Soal dan Kode Jawaban diatas ke alamat : https://belajarexcel.id/xl-test/jawaban untuk mengecek hasil benar/salah
B29: Soal 1 | C29: Tentukan peringkat klasemen setiap tim berdasarkan jumlah PTS.
C30: Contoh : Peringkat pertama ditempati oleh Napoli karena memiliki poin tertinggi (lihat Sheet LS).
B32: Soal 2 | C32: Berapa persentase tembakan tepat sasaran (SoT%) untuk setiap tim?
C33: Contoh: Total tembakan tepat sasaran (SoT) tim Torino adalah 123, sedangkan total tembakan (SH) adalah 383 (lihat Sheet LS). Maka, persentase tembakan tepat sasaran (SoT%) tim Torino adalah 32% (setelah pembulatan).
B36: Soal 3 | C36: Berapa rata-rata gol yang dicetak per tembakan tepat sasaran (G/SoT) untuk setiap tim?
C37: Contoh: Total tembakan tepat sasaran (SoT) tim Torino adalah 123, total gol (G) adalah 36, dan tendangan penalti (PK) adalah 2 (lihat Sheet LS). Maka, rata-rata gol yang dicetak per tembakan tepat sasaran (G/SoT) tim Torino adalah 0.28 (setelah pembulatan). Note : G/SoT dihitung dari gol per tembakan tepat sasaran, tidak termasuk gol dari penalti.
B42: Soal 4 | C42: Berapa besarnya poin yang dihasilkan oleh setiap tim pada 5 laga terakhir?
C43: Contoh : Hasil 5 laga terakhir tim Torino adalah LDLLL. Setiap kemenangan (W) mendapatkan 3 poin, kekalahan (L) mendapatkan 0 poin, dan jika imbang (D) mendapatkan 1 poin. Dengan demikian, di 5 laga terakhir Torino memperoleh poin 0,1,0,0,0. Maka, total poin untuk tim Torino adalah 1.
B47: Soal 5 | C47: Berapa rata-rata jumlah penonton di masing-masing stadion pada laga kandang?
C48: Contoh : Penonton tim Torino sepanjang musim adalah 443155 dan jumlah pertandingan kandang adalah 19 (lihat Sheet SA). Maka, rata-rata penonton tim Torino adalah 23324 (setelah pembulatan).
B51: Soal 6 | C51: Berapa persentase keterisian bangku pada setiap laga kandang?
C52: Contoh : Rata-rata penonton tim Torino dalam setiap laga adalah 23324 dan kapasitas stadion tim Torino adalah 28177 (lihat Sheet SA). Maka persentase keterisian bangku tim Torino adalah 83% (setelah pembulatan).
B55: Soal 7 | C55: Berapa besar pendapatan yang diperoleh setiap tim dari laga kandang di stadion?
C56: Contoh : Penonton tim Torino sepanjang musim adalah 443155 dan harga tiket musimannya adalah 230 (lihat Sheet SA). Maka, total pendapatan tim Torino dari stadion adalah 101925650.
B59: Soal 8 | C59: Berapa jumlah kartu kuning yang diterima oleh setiap tim?
C60: Contoh : Kartu kuning yang diterima oleh Torino adalah 1,1,1,2,2,2,3,3,3,4,4,4,4,5,5,6,6,6,8,10 (lihat Sheet PS). Maka, total kartu kuning tim Torino adalah 80.
B63: Soal 9 | C63: Berapa jumlah gol terbanyak yang dicetak oleh seorang pemain dalam sebuah tim?
C64: Contoh : Gol yang dicetak pemain Torino adalah 9,5,4,3,3,2,2,1,1,1,1,1,1,1,1 (lihat Sheet PS). Maka, jumlah gol terbanyak yang dicetak tim Torino adalah 9.
B67: Soal 10 | C67: Berapa banyak pemain berkewarganegaraan Italia (ITA) pada masing-masing tim?
C68: Contoh: Kewarganegaraan pemain tim Torino adalah (lihat Sheet PS) : SCO,ITA,ITA,ITA,ITA,ITA,EQG,FRA,MKD,ITA,LTU,SRB,FRA,AUT,POL,CHI,MAR,SRB,SWE,ITA,NOR,MDA,ITA,PAR,GEO,CRO,CMR,CRO,KVX,POL,COL Maka, jumlah pemain dengan kewarganegaraan Italia (ITA) adalah 8.
B74: Sudah selesai mengerjakan?
B75: kirim Kode Soal dan Kode Jawaban diatas ke alamat : https://belajarexcel.id/xl-test/jawaban untuk mengecek hasil benar/salah

Sheet About
C6: XL-TEST adalah platform inovatif yang menyediakan latihan Excel interaktif dengan pemeriksaan otomatis,
C7: sehingga pengguna dapat langsung mengetahui jawaban yang benar maupun salah.
C10: Terdapat 5 Level soal :
D12: Easy Level | F12: (⭐)
D13: Medium Level | F13: (⭐⭐)
D14: Hard Level | F14: (⭐⭐⭐)
D15: Extreme Level | F15: (⭐⭐⭐⭐)
D16: Championship Level | F16: (⭐⭐⭐⭐⭐)
C19: Free Access
C20: https://belajarexcel.id/xl-test/

Sheet DF
A1: DF | D1: 1 | E1: 2 | F1: 3 | G1: 4 | H1: 5 | I1: 6 | J1: 7 | K1: 8 | L1: 9 | M1: 10 | S1: 1 | T1: 2 | U1: 3 | V1: 4 | W1: 5 | X1: 6 | Y1: 7 | Z1: 8 | AA1: 9 | AB1: 10
A2: HJ2 | C2: 1 | D2: ='XL-Test'!C6 -> 11 | E2: ='XL-Test'!D6 -> 0.32 | F2: ='XL-Test'!E6 -> 0.28 | G2: ='XL-Test'!G6 -> 1 | H2: ='XL-Test'!H6 -> 23324 | I2: ='XL-Test'!I6 -> 0.83 | J2: ='XL-Test'!K6 -> 101925650 | K2: ='XL-Test'!L6 -> 80 | L2: ='XL-Test'!M6 -> 9 | M2: ='XL-Test'!N6 -> 8 | R2: 1 | S2: =_xlfn.FORMULATEXT('XL-Test'!C6) -> =MATCH(B6;LS!$A$4:$A$23;0) | T2: =_xlfn.FORMULATEXT('XL-Test'!D6) -> =ROUND(SUMIFS(LS!$I$4:$I$23;LS!$A$4:$A$23;'XL-Test'!B6)/SUMIFS(LS!$H$4:$H$23;LS!$A$4:$A$23;'XL-Test'!B6);2) | U2: =_xlfn.FORMULATEXT('XL-Test'!E6) -> =ROUND((SUMIFS(LS!$G$4:$G$23;LS!$A$4:$A$23;'XL-Test'!B6)-SUMIFS(LS!$J$4:$J$23;LS!$A$4:$A$23;'XL-Test'!B6))/SUMIFS(LS!$I$4:$I$23;LS!$A$4:$A$23;'XL-Test'!B6);2) | V2: =_xlfn.FORMULATEXT('XL-Test'!G6) -> =SUMPRODUCT(SWITCH(MID(F6;{1\2\3\4\5};1);"W";3;"D";1;0)) | W2: =_xlfn.FORMULATEXT('XL-Test'!H6) -> =ROUND(AVERAGEIFS(SA!$F$4:$F$383;SA!$B$4:$B$383;'XL-Test'!B6);0) | X2: =_xlfn.FORMULATEXT('XL-Test'!I6) -> =ROUND(H6/XLOOKUP(B6;SA!$B$4:$B$383;SA!$E$4:$E$383);2) | Y2: =_xlfn.FORMULATEXT('XL-Test'!K6) -> =SUMIFS(SA!$F$4:$F$383;SA!$B$4:$B$383;'XL-Test'!B6)*J6 | Z2: =_xlfn.FORMULATEXT('XL-Test'!L6) -> =SUMIFS(PS!$H$4:$H$637;PS!$D$4:$D$637;'XL-Test'!B6) | AA2: =_xlfn.FORMULATEXT('XL-Test'!M6) -> =MAXIFS(PS!$F$4:$F$637;PS!$D$4:$D$637;'XL-Test'!B6) | AB2: =_xlfn.FORMULATEXT('XL-Test'!N6) -> =COUNTIFS(PS!$D$4:$D$637;'XL-Test'!B6;PS!$B$4:$B$637;"ITA")
C3: 2 | D3: ='XL-Test'!C7 -> 6 | E3: ='XL-Test'!D7 -> 0.38 | F3: ='XL-Test'!E7 -> 0.31 | G3: ='XL-Test'!G7 -> 9 | H3: ='XL-Test'!H7 -> 20410 | I3: ='XL-Test'!I7 -> 0.47 | J3: ='XL-Test'!K7 -> 135727550 | K3: ='XL-Test'!L7 -> 82 | L3: ='XL-Test'!M7 -> 19 | M3: ='XL-Test'!N7 -> 19 | R3: 2 | S3: =T2 -> =ROUND(SUMIFS(LS!$I$4:$I$23;LS!$A$4:$A$23;'XL-Test'!B6)/SUMIFS(LS!$H$4:$H$23;LS!$A$4:$A$23;'XL-Test'!B6);2)
C4: 3 | D4: ='XL-Test'!C8 -> 9 | E4: ='XL-Test'!D8 -> 0.33 | F4: ='XL-Test'!E8 -> 0.3 | G4: ='XL-Test'!G8 -> 2 | H4: ='XL-Test'!H8 -> 28213 | I4: ='XL-Test'!I8 -> 0.77 | J4: ='XL-Test'!K8 -> 160811400 | K4: ='XL-Test'!L8 -> 61 | L4: ='XL-Test'!M8 -> 15 | M4: ='XL-Test'!N8 -> 8 | R4: 3 | S4: =U2 -> =ROUND((SUMIFS(LS!$G$4:$G$23;LS!$A$4:$A$23;'XL-Test'!B6)-SUMIFS(LS!$J$4:$J$23;LS!$A$4:$A$23;'XL-Test'!B6))/SUMIFS(LS!$I$4:$I$23;LS!$A$4:$A$23;'XL-Test'!B6);2)
C5: 4 | D5: ='XL-Test'!C9 -> 10 | E5: ='XL-Test'!D9 -> 0.34 | F5: ='XL-Test'!E9 -> 0.25 | G5: ='XL-Test'!G9 -> 10 | H5: ='XL-Test'!H9 -> 10830 | I5: ='XL-Test'!I9 -> 0.9 | J5: ='XL-Test'!K9 -> 62554080 | K5: ='XL-Test'!L9 -> 87 | L5: ='XL-Test'!M9 -> 8 | M5: ='XL-Test'!N9 -> 12 | R5: 4 | S5: =V2 -> =SUMPRODUCT(SWITCH(MID(F6;{1\2\3\4\5};1);"W";3;"D";1;0))
C6: 5 | D6: ='XL-Test'!C10 -> 18 | E6: ='XL-Test'!D10 -> 0.29 | F6: ='XL-Test'!E10 -> 0.27 | G6: ='XL-Test'!G10 -> 6 | H6: ='XL-Test'!H10 -> 11151 | I6: ='XL-Test'!I10 -> 0.56 | J6: ='XL-Test'!K10 -> 54026340 | K6: ='XL-Test'!L10 -> 68 | L6: ='XL-Test'!M10 -> 8 | M6: ='XL-Test'!N10 -> 16 | R6: 5 | S6: =W2 -> =ROUND(AVERAGEIFS(SA!$F$4:$F$383;SA!$B$4:$B$383;'XL-Test'!B6);0)
C7: 6 | D7: ='XL-Test'!C11 -> 13 | E7: ='XL-Test'!D11 -> 0.31 | F7: ='XL-Test'!E11 -> 0.3 | G7: ='XL-Test'!G11 -> 4 | H7: ='XL-Test'!H11 -> 30772 | I7: ='XL-Test'!I11 -> 0.88 | J7: ='XL-Test'!K11 -> 131550750 | K7: ='XL-Test'!L11 -> 71 | L7: ='XL-Test'!M11 -> 10 | M7: ='XL-Test'!N11 -> 17 | R7: 6 | S7: =X2 -> =ROUND(H6/XLOOKUP(B6;SA!$B$4:$B$383;SA!$E$4:$E$383);2)
C8: 7 | D8: ='XL-Test'!C12 -> 12 | E8: ='XL-Test'!D12 -> 0.32 | F8: ='XL-Test'!E12 -> 0.28 | G8: ='XL-Test'!G12 -> 4 | H8: ='XL-Test'!H12 -> 21823 | I8: ='XL-Test'!I12 -> 0.87 | J8: ='XL-Test'!K12 -> 103660250 | K8: ='XL-Test'!L12 -> 88 | L8: ='XL-Test'!M12 -> 12 | M8: ='XL-Test'!N12 -> 3 | R8: 7 | S8: =Y2 -> =SUMIFS(SA!$F$4:$F$383;SA!$B$4:$B$383;'XL-Test'!B6)*J6
C9: 8 | D9: ='XL-Test'!C13 -> 4 | E9: ='XL-Test'!D13 -> 0.34 | F9: ='XL-Test'!E13 -> 0.29 | G9: ='XL-Test'!G13 -> 11 | H9: ='XL-Test'!H13 -> 40228 | I9: ='XL-Test'!I13 -> 0.97 | J9: ='XL-Test'!K13 -> 415793344 | K9: ='XL-Test'!L13 -> 67 | L9: ='XL-Test'!M13 -> 10 | M9: ='XL-Test'!N13 -> 9 | R9: 8 | S9: =Z2 -> =SUMIFS(PS!$H$4:$H$637;PS!$D$4:$D$637;'XL-Test'!B6)
C10: 9 | D10: ='XL-Test'!C14 -> 20 | E10: ='XL-Test'!D14 -> 0.3 | F10: ='XL-Test'!E14 -> 0.24 | G10: ='XL-Test'!G14 -> 3 | H10: ='XL-Test'!H14 -> 11274 | I10: ='XL-Test'!I14 -> 0.66 | J10: ='XL-Test'!K14 -> 55691220 | K10: ='XL-Test'!L14 -> 90 | L10: ='XL-Test'!M14 -> 5 | M10: ='XL-Test'!N14 -> 21 | R10: 9 | S10: =AA2 -> =MAXIFS(PS!$F$4:$F$637;PS!$D$4:$D$637;'XL-Test'!B6)
C11: 10 | D11: ='XL-Test'!C15 -> 1 | E11: ='XL-Test'!D15 -> 0.3 | F11: ='XL-Test'!E15 -> 0.35 | G11: ='XL-Test'!G15 -> 11 | H11: ='XL-Test'!H15 -> 51398 | I11: ='XL-Test'!I15 -> 0.94 | J11: ='XL-Test'!K15 -> 273439880 | K11: ='XL-Test'!L15 -> 46 | L11: ='XL-Test'!M15 -> 14 | M11: ='XL-Test'!N15 -> 11 | R11: 10 | S11: =AB2 -> =COUNTIFS(PS!$D$4:$D$637;'XL-Test'!B6;PS!$B$4:$B$637;"ITA")
C12: 11 | D12: ='XL-Test'!C16 -> 17 | E12: ='XL-Test'!D16 -> 0.26 | F12: ='XL-Test'!E16 -> 0.2 | G12: ='XL-Test'!G16 -> 8 | H12: ='XL-Test'!H16 -> 26031 | I12: ='XL-Test'!I16 -> 0.82 | J12: ='XL-Test'!K16 -> 150846900 | K12: ='XL-Test'!L16 -> 61 | L12: ='XL-Test'!M16 -> 11 | M12: ='XL-Test'!N16 -> 6
C13: 12 | D13: ='XL-Test'!C17 -> 15 | E13: ='XL-Test'!D17 -> 0.27 | F13: ='XL-Test'!E17 -> 0.3 | G13: ='XL-Test'!G17 -> 6 | H13: ='XL-Test'!H17 -> 15745 | I13: ='XL-Test'!I17 -> 0.96 | J13: ='XL-Test'!K17 -> 83763120 | K13: ='XL-Test'!L17 -> 68 | L13: ='XL-Test'!M17 -> 10 | M13: ='XL-Test'!N17 -> 15
C14: 13 | D14: ='XL-Test'!C18 -> 19 | E14: ='XL-Test'!D18 -> 0.31 | F14: ='XL-Test'!E18 -> 0.23 | G14: ='XL-Test'!G18 -> 4 | H14: ='XL-Test'!H18 -> 10379 | I14: ='XL-Test'!I18 -> 0.86 | J14: ='XL-Test'!K18 -> 59162100 | K14: ='XL-Test'!L18 -> 75 | L14: ='XL-Test'!M18 -> 6 | M14: ='XL-Test'!N18 -> 12
C15: 14 | D15: ='XL-Test'!C19 -> 2 | E15: ='XL-Test'!D19 -> 0.32 | F15: ='XL-Test'!E19 -> 0.38 | G15: ='XL-Test'!G19 -> 10 | H15: ='XL-Test'!H19 -> 70600 | I15: ='XL-Test'!I19 -> 0.93 | J15: ='XL-Test'!K19 -> 360837138 | K15: ='XL-Test'!L19 -> 56 | L15: ='XL-Test'!M19 -> 14 | M15: ='XL-Test'!N19 -> 6
C16: 15 | D16: ='XL-Test'!C20 -> 7 | E16: ='XL-Test'!D20 -> 0.35 | F16: ='XL-Test'!E20 -> 0.3 | G16: ='XL-Test'!G20 -> 6 | H16: ='XL-Test'!H20 -> 43303 | I16: ='XL-Test'!I20 -> 0.61 | J16: ='XL-Test'!K20 -> 242710660 | K16: ='XL-Test'!L20 -> 93 | L16: ='XL-Test'!M20 -> 11 | M16: ='XL-Test'!N20 -> 8
C17: 16 | D17: ='XL-Test'!C21 -> 16 | E17: ='XL-Test'!D21 -> 0.33 | F17: ='XL-Test'!E21 -> 0.26 | G17: ='XL-Test'!G21 -> 5 | H17: ='XL-Test'!H21 -> 19230 | I17: ='XL-Test'!I21 -> 0.86 | J17: ='XL-Test'!K21 -> 89515405 | K17: ='XL-Test'!L21 -> 78 | L17: ='XL-Test'!M21 -> 6 | M17: ='XL-Test'!N21 -> 5
C18: 17 | D18: ='XL-Test'!C22 -> 5 | E18: ='XL-Test'!D22 -> 0.32 | F18: ='XL-Test'!E22 -> 0.29 | G18: ='XL-Test'!G22 -> 12 | H18: ='XL-Test'!H22 -> 62435 | I18: ='XL-Test'!I22 -> 0.88 | J18: ='XL-Test'!K22 -> 328595959 | K18: ='XL-Test'!L22 -> 66 | L18: ='XL-Test'!M22 -> 12 | M18: ='XL-Test'!N22 -> 6
C19: 18 | D19: ='XL-Test'!C23 -> 8 | E19: ='XL-Test'!D23 -> 0.33 | F19: ='XL-Test'!E23 -> 0.3 | G19: ='XL-Test'!G23 -> 12 | H19: ='XL-Test'!H23 -> 71512 | I19: ='XL-Test'!I23 -> 0.94 | J19: ='XL-Test'!K23 -> 407620200 | K19: ='XL-Test'!L23 -> 70 | L19: ='XL-Test'!M23 -> 11 | M19: ='XL-Test'!N23 -> 11
C20: 19 | D20: ='XL-Test'!C24 -> 3 | E20: ='XL-Test'!D24 -> 0.34 | F20: ='XL-Test'!E24 -> 0.39 | G20: ='XL-Test'!G24 -> 10 | H20: ='XL-Test'!H24 -> 22675 | I20: ='XL-Test'!I24 -> 0.91 | J20: ='XL-Test'!K24 -> 133558540 | K20: ='XL-Test'!L24 -> 67 | L20: ='XL-Test'!M24 -> 25 | M20: ='XL-Test'!N24 -> 14
C21: 20 | D21: ='XL-Test'!C25 -> 14 | E21: ='XL-Test'!D25 -> 0.26 | F21: ='XL-Test'!E25 -> 0.31 | G21: ='XL-Test'!G25 -> 5 | H21: ='XL-Test'!H25 -> 24787 | I21: ='XL-Test'!I25 -> 0.63 | J21: ='XL-Test'!K25 -> 89482210 | K21: ='XL-Test'!L25 -> 97 | L21: ='XL-Test'!M25 -> 6 | M21: ='XL-Test'!N25 -> 7
C23: Value | D23: =SUM(D2:D21)+D2+D4+D6+D9+D11+D14+D16+D19+D21 -> 301 | E23: =SUM(E2:E21)+E2+E4+E6+E9+E11+E14+E16+E19+E21 -> 9.15 | F23: =SUM(F2:F21)+F2+F4+F6+F9+F11+F14+F16+F19+F21 -> 8.46 | G23: =SUM(G2:G21)+G2+G4+G6+G9+G11+G14+G16+G19+G21 -> 197 | H23: =SUM(H2:H21)+H2+H4+H6+H9+H11+H14+H16+H19+H21 -> 920415 | I23: =SUM(I2:I21)+I2+I4+I6+I9+I11+I14+I16+I19+I21 -> 23.36 | J23: =SUM(J2:J21)+J2+J4+J6+J9+J11+J14+J16+J19+J21 -> 5246244480 | K23: =SUM(K2:K21)+K2+K4+K6+K9+K11+K14+K16+K19+K21 -> 2128 | ... M23: =SUM(M2:M21)+M2+M4+M6+M9+M11+M14+M16+M19+M21 -> 304
D24: 100 | E24: 1000 | F24: 1000 | G24: 100 | H24: 1 | I24: 1000 | J24: 1 | K24: 1 | L24: 100 | M24: 100
D25: =INT(D23*D24) -> 30100 | E25: =INT(E23*E24) -> 9150 | F25: =INT(F23*F24) -> 8460 | G25: =INT(G23*G24) -> 19700 | H25: =INT(H23*H24) -> 920415 | I25: =INT(I23*I24) -> 23360 | J25: =INT(J23*J24) -> 5246244480 | K25: =INT(K23*K24) -> 2128 | ... M25: =INT(M23*M24) -> 30400
D26: =DEC2HEX(D25) -> 7594 | E26: =DEC2HEX(E25) -> 23BE | F26: =DEC2HEX(F25) -> 210C | G26: =DEC2HEX(G25) -> 4CF4 | H26: =DEC2HEX(H25) -> E0B5F | I26: =DEC2HEX(I25) -> 5B40 | J26: =DEC2HEX(J25) -> 138B35680 | K26: =DEC2HEX(K25) -> 850 | ... M26: =DEC2HEX(M25) -> 76C0
C28: Rand | D28: 9843 | E28: 2716 | F28: 6091 | G28: 2014 | H28: 4088 | I28: 2596 | J28: 3879 | K28: 2714 | L28: 6297 | M28: 4354
D29: =DEC2HEX(D28) -> 2673 | E29: =DEC2HEX(E28) -> A9C | F29: =DEC2HEX(F28) -> 17CB | G29: =DEC2HEX(G28) -> 7DE | H29: =DEC2HEX(H28) -> FF8 | I29: =DEC2HEX(I28) -> A24 | J29: =DEC2HEX(J28) -> F27 | K29: =DEC2HEX(K28) -> A9A | ... M29: =DEC2HEX(M28) -> 1102
C31: TRUE | D31: =DEC2HEX(LEFT(D28,2)+COLUMN()) -> 66 | E31: =DEC2HEX(LEFT(E28,2)+COLUMN()) -> 20 | F31: =DEC2HEX(LEFT(F28,2)+COLUMN()) -> 42 | G31: =DEC2HEX(LEFT(G28,2)+COLUMN()) -> 1B | H31: =DEC2HEX(LEFT(H28,2)+COLUMN()) -> 30 | I31: =DEC2HEX(LEFT(I28,2)+COLUMN()) -> 22 | J31: =DEC2HEX(LEFT(J28,2)+COLUMN()) -> 30 | K31: =DEC2HEX(LEFT(K28,2)+COLUMN()) -> 26 | ... M31: =DEC2HEX(LEFT(M28,2)+COLUMN()) -> 38
C32: FALSE | D32: =DEC2HEX(RIGHT(D28,2)+COLUMN()) -> 2F | E32: =DEC2HEX(RIGHT(E28,2)+COLUMN()) -> 15 | F32: =DEC2HEX(RIGHT(F28,2)+COLUMN()) -> 61 | G32: =DEC2HEX(RIGHT(G28,2)+COLUMN()) -> 15 | H32: =DEC2HEX(RIGHT(H28,2)+COLUMN()) -> 60 | I32: =DEC2HEX(RIGHT(I28,2)+COLUMN()) -> 69 | J32: =DEC2HEX(RIGHT(J28,2)+COLUMN()) -> 59 | K32: =DEC2HEX(RIGHT(K28,2)+COLUMN()) -> 19 | ... M32: =DEC2HEX(RIGHT(M28,2)+COLUMN()) -> 43
B34: Nilai | C34: Cek Manual | D34: =AND(ISNUMBER(FIND("=",S2)),ISNUMBER(FIND("(",S2))) -> TRUE | E34: =AND(ISNUMBER(FIND("=",T2)),ISNUMBER(FIND("(",T2))) -> TRUE | F34: =AND(ISNUMBER(FIND("=",U2)),ISNUMBER(FIND("(",U2))) -> TRUE | G34: =AND(ISNUMBER(FIND("=",V2)),ISNUMBER(FIND("(",V2))) -> TRUE | H34: =AND(ISNUMBER(FIND("=",W2)),ISNUMBER(FIND("(",W2))) -> TRUE | I34: =AND(ISNUMBER(FIND("=",X2)),ISNUMBER(FIND("(",X2))) -> TRUE | J34: =AND(ISNUMBER(FIND("=",Y2)),ISNUMBER(FIND("(",Y2))) -> TRUE | K34: =AND(ISNUMBER(FIND("=",Z2)),ISNUMBER(FIND("(",Z2))) -> TRUE | ... M34: =AND(ISNUMBER(FIND("=",AB2)),ISNUMBER(FIND("(",AB2))) -> TRUE
C35: Cek isi Manu | D35: =D74 -> TRUE | E35: =E74 -> TRUE | F35: =F74 -> TRUE | G35: =G74 -> TRUE | H35: =H74 -> TRUE | I35: =I74 -> TRUE | J35: =J74 -> TRUE | K35: =K74 -> TRUE | ... M35: =M74 -> TRUE
C36: cek Kosong | D36: =NOT(OR(D2=0,D2="")) -> TRUE | E36: =NOT(OR(E2=0,E2="")) -> TRUE | F36: =NOT(OR(F2=0,F2="")) -> TRUE | G36: =NOT(OR(G2=0,G2="")) -> TRUE | H36: =NOT(OR(H2=0,H2="")) -> TRUE | I36: =NOT(OR(I2=0,I2="")) -> TRUE | J36: =NOT(OR(J2=0,J2="")) -> TRUE | K36: =NOT(OR(K2=0,K2="")) -> TRUE | ... M36: =NOT(OR(M2=0,M2="")) -> TRUE
B37: ** | D37: =AND(D34,D35,D36) -> TRUE | E37: =AND(E34,E35,E36) -> TRUE | F37: =AND(F34,F35,F36) -> TRUE | G37: =AND(G34,G35,G36) -> TRUE | H37: =AND(H34,H35,H36) -> TRUE | I37: =AND(I34,I35,I36) -> TRUE | J37: =AND(J34,J35,J36) -> TRUE | K37: =AND(K34,K35,K36) -> TRUE | ... M37: =AND(M34,M35,M36) -> TRUE
B39: Formula | C39: Cek Formula | D39: =ISNUMBER(FIND("ATCH",S2)) -> TRUE | E39: =AND(ISNUMBER(FIND("OUN",T2)),OR(ISNUMBER(FIND("SUM",T2)),ISNUMBER(FIND("LOOK",T2)))) -> TRUE | F39: =AND(ISNUMBER(FIND("OUN",U2)),OR(ISNUMBER(FIND("SUM",U2)),ISNUMBER(FIND("LOOK",U2)))) -> TRUE | G39: =AND(ISNUMBER(FIND("SUM",V2)),OR(ISNUMBER(FIND("LOOK",V2)),ISNUMBER(FIND("WITC",V2)))) -> TRUE | H39: =AND(ISNUMBER(FIND("OUN",W2)),ISNUMBER(FIND("AGEI",W2))) -> TRUE | I39: =AND(ISNUMBER(FIND("OUN",X2)),ISNUMBER(FIND("LOOK",X2))) -> TRUE | J39: =AND(ISNUMBER(FIND("UMI",Y2))) -> TRUE | K39: =AND(ISNUMBER(FIND("UMI",Z2))) -> TRUE | L39: =OR(ISNUMBER(FIND("AXI",AA2)),AND(ISNUMBER(FIND("MAX",AA2)),ISNUMBER(FIND("IF",AA2)))) -> TRUE | M39: =AND(ISNUMBER(FIND("OUNTI",AB2))) -> TRUE
C40: Jml Formula | D40: =IFERROR(LEN(S2)-LEN(SUBSTITUTE(S2,"(","")),99) -> 1 | E40: =IFERROR(LEN(T2)-LEN(SUBSTITUTE(T2,"(","")),99) -> 3 | F40: =IFERROR(LEN(U2)-LEN(SUBSTITUTE(U2,"(","")),99) -> 5 | G40: =IFERROR(LEN(V2)-LEN(SUBSTITUTE(V2,"(","")),99) -> 3 | H40: =IFERROR(LEN(W2)-LEN(SUBSTITUTE(W2,"(","")),99) -> 2 | I40: =IFERROR(LEN(X2)-LEN(SUBSTITUTE(X2,"(","")),99) -> 2 | J40: =IFERROR(LEN(Y2)-LEN(SUBSTITUTE(Y2,"(","")),99) -> 1 | K40: =IFERROR(LEN(Z2)-LEN(SUBSTITUTE(Z2,"(","")),99) -> 1 | ... M40: =IFERROR(LEN(AB2)-LEN(SUBSTITUTE(AB2,"(","")),99) -> 1
D41: 1 | E41: 3 | F41: 5 | G41: 3 | H41: 2 | I41: 2 | J41: 1 | K41: 1 | L41: 1 | M41: 1
D42: =D40<=D41 -> TRUE | E42: =E40<=E41 -> TRUE | F42: =F40<=F41 -> TRUE | G42: =G40<=G41 -> TRUE | H42: =H40<=H41 -> TRUE | I42: =I40<=I41 -> TRUE | J42: =J40<=J41 -> TRUE | K42: =K40<=K41 -> TRUE | ... M42: =M40<=M41 -> TRUE
B43: ** | D43: =AND(D42,D39) -> TRUE | E43: =AND(E42,E39) -> TRUE | F43: =AND(F42,F39) -> TRUE | G43: =AND(G42,G39) -> TRUE | H43: =AND(H42,H39) -> TRUE | I43: =AND(I42,I39) -> TRUE | J43: =AND(J42,J39) -> TRUE | K43: =AND(K42,K39) -> TRUE | ... M43: =AND(M42,M39) -> TRUE
B45: 1 | C45: 6 | D45: =IFERROR(LEN(_xlfn.FORMULATEXT('XL-Test'!C6)),0) -> 26 | E45: =IFERROR(LEN(_xlfn.FORMULATEXT('XL-Test'!D6)),0) -> 107 | F45: =IFERROR(LEN(_xlfn.FORMULATEXT('XL-Test'!E6)),0) -> 158 | G45: =IFERROR(LEN(_xlfn.FORMULATEXT('XL-Test'!G6)),0) -> 56 | H45: =IFERROR(LEN(_xlfn.FORMULATEXT('XL-Test'!H6)),0) -> 64 | I45: =IFERROR(LEN(_xlfn.FORMULATEXT('XL-Test'!I6)),0) -> 54 | J45: =IFERROR(LEN(_xlfn.FORMULATEXT('XL-Test'!K6)),0) -> 54 | K45: =IFERROR(LEN(_xlfn.FORMULATEXT('XL-Test'!L6)),0) -> 51 | L45: =IFERROR(LEN(_xlfn.FORMULATEXT('XL-Test'!M6)),0) -> 51 | M45: =IFERROR(LEN(_xlfn.FORMULATEXT('XL-Test'!N6)),0) -> 59
B46: 2 | C46: 7 | D46: =IFERROR(LEN(_xlfn.FORMULATEXT('XL-Test'!C7)),0) -> 26 | E46: =IFERROR(LEN(_xlfn.FORMULATEXT('XL-Test'!D7)),0) -> 107 | F46: =IFERROR(LEN(_xlfn.FORMULATEXT('XL-Test'!E7)),0) -> 158 | G46: =IFERROR(LEN(_xlfn.FORMULATEXT('XL-Test'!G7)),0) -> 56 | H46: =IFERROR(LEN(_xlfn.FORMULATEXT('XL-Test'!H7)),0) -> 64 | I46: =IFERROR(LEN(_xlfn.FORMULATEXT('XL-Test'!I7)),0) -> 54 | J46: =IFERROR(LEN(_xlfn.FORMULATEXT('XL-Test'!K7)),0) -> 54 | K46: =IFERROR(LEN(_xlfn.FORMULATEXT('XL-Test'!L7)),0) -> 51 | L46: =IFERROR(LEN(_xlfn.FORMULATEXT('XL-Test'!M7)),0) -> 51 | M46: =IFERROR(LEN(_xlfn.FORMULATEXT('XL-Test'!N7)),0) -> 59
...

Sheet LS
A1: League Summary
A3: Team | B3: P | C3: W | D3: D | E3: L | F3: PTS | G3: G | H3: SH | I3: SoT | J3: PK | L3: Label | M3: Description
A4: Napoli | B4: 38 | C4: 24 | D4: 10 | E4: 4 | F4: 82 | G4: 56 | H4: 499 | I4: 150 | J4: 4 | L4: P | M4: Played
A5: Inter Milan | B5: 38 | C5: 25 | D5: 6 | E5: 7 | F5: 81 | G5: 76 | H5: 565 | I5: 179 | J5: 8 | L5: W | M5: Win
A6: Atalanta | B6: 38 | C6: 22 | D6: 8 | E6: 8 | F6: 74 | G6: 76 | H6: 538 | I6: 181 | J6: 5 | L6: D | M6: Draw
A7: Juventus | B7: 38 | C7: 19 | D7: 12 | E7: 7 | F7: 69 | G7: 56 | H7: 509 | I7: 175 | J7: 6 | L7: L | M7: Lose
A8: AS Roma | B8: 38 | C8: 20 | D8: 8 | E8: 10 | F8: 68 | G8: 55 | H8: 514 | I8: 162 | J8: 8 | L8: PTS | M8: Points
A9: Fiorentina | B9: 38 | C9: 19 | D9: 7 | E9: 12 | F9: 64 | G9: 58 | H9: 439 | I9: 166 | J9: 6 | L9: G | M9: Goals
A10: Lazio | B10: 38 | C10: 18 | D10: 9 | E10: 11 | F10: 63 | G10: 61 | H10: 529 | I10: 186 | J10: 6 | L10: SH | M10: Shoot
A11: AC Milan | B11: 38 | C11: 17 | D11: 11 | E11: 10 | F11: 62 | G11: 59 | H11: 555 | I11: 185 | J11: 4 | L11: SoT | M11: Shoot on Target
A12: Bologna | B12: 38 | C12: 16 | D12: 10 | E12: 12 | F12: 58 | G12: 56 | H12: 505 | I12: 166 | J12: 6 | L12: PK | M12: Penalty Kick
A13: Como | B13: 38 | C13: 14 | D13: 6 | E13: 18 | F13: 48 | G13: 44 | H13: 519 | I13: 176 | J13: 0
A14: Torino | B14: 38 | C14: 11 | D14: 9 | E14: 18 | F14: 42 | G14: 36 | H14: 383 | I14: 123 | J14: 2
A15: Udinese | B15: 38 | C15: 11 | D15: 8 | E15: 19 | F15: 41 | G15: 41 | H15: 430 | I15: 137 | J15: 2
A16: Genoa | B16: 38 | C16: 10 | D16: 10 | E16: 18 | F16: 40 | G16: 35 | H16: 383 | I16: 117 | J16: 0
A17: Hellas Verona | B17: 38 | C17: 10 | D17: 7 | E17: 21 | F17: 37 | G17: 31 | H17: 372 | I17: 95 | J17: 2
A18: Cagliari | B18: 38 | C18: 9 | D18: 9 | E18: 20 | F18: 36 | G18: 38 | H18: 421 | I18: 115 | J18: 3
A19: Parma | B19: 38 | C19: 8 | D19: 11 | E19: 19 | F19: 35 | G19: 43 | H19: 418 | I19: 140 | J19: 6
A20: Lecce | B20: 38 | C20: 8 | D20: 9 | E20: 21 | F20: 33 | G20: 27 | H20: 450 | I20: 119 | J20: 3
A21: Empoli | B21: 38 | C21: 7 | D21: 9 | E21: 22 | F21: 30 | G21: 31 | H21: 367 | I21: 107 | J21: 2
A22: Venezia | B22: 38 | C22: 6 | D22: 8 | E22: 24 | F22: 26 | G22: 31 | H22: 381 | I22: 120 | J22: 4
A23: Monza | B23: 38 | C23: 4 | D23: 5 | E23: 29 | F23: 17 | G23: 27 | H23: 333 | I23: 99 | J23: 3

Sheet SA
A1: Stadium Attendance
A3: Date | B3: Team | C3: Opponent | D3: Stadium | E3: Capacity | F3: Attendance
A4: 45521 | B4: AC Milan | C4: Torino | D4: Giuseppe Meazza | E4: 75923 | F4: 70742
A5: 45521 | B5: Genoa | C5: Inter Milan | D5: Luigi Ferraris | E5: 34901 | F5: 33300
A6: 45521 | B6: Parma | C6: Fiorentina | D6: Ennio Tardini | E6: 22352 | F6: 21384
A7: 45521 | B7: Empoli | C7: Monza | D7: Stadio Carlo Castellani | E7: 19847 | F7: 7746
A8: 45522 | B8: Lazio | C8: Venezia | D8: Stadio Olimpico | E8: 70634 | F8: 42000
A9: 45522 | B9: Bologna | C9: Udinese | D9: Renato Dall'Ara | E9: 36462 | F9: 26418
A10: 45522 | B10: Hellas Verona | C10: Napoli | D10: Stadio Marcantonio Bentegodi | E10: 39211 | F10: 20027
A11: 45522 | B11: Cagliari | C11: AS Roma | D11: Unipol Domus | E11: 16365 | F11: 16261
A12: 45523 | B12: Juventus | C12: Como | D12: Allianz Stadium | E12: 41507 | F12: 40696
A13: 45523 | B13: Lecce | C13: Atalanta | D13: Stadio Via del Mare | E13: 31559 | F13: 28719
A14: 45528 | B14: Inter Milan | C14: Lecce | D14: Giuseppe Meazza | E14: 75923 | F14: 70921
A15: 45528 | B15: Udinese | C15: Lazio | D15: Bluenergy Stadium | E15: 25144 | F15: 21636
... A383: 45802 | B383: Venezia | C383: Juventus | D383: Pier Luigi Penzo | E383: 12048 | F383: 12048

Sheet PS
A1: Player Stats
A3: Player | B3: Nation | C3: Pos | D3: Team | E3: Age | F3: Goals | G3: Assists | H3: Yellow Card | I3: Red Card
A4: James Abankwah | B4: IRL | C4: DF,MF | D4: Udinese | E4: 20 | F4: 0 | G4: 0 | H4: 1 | I4: 0
A5: Saud Abdulhamid | B5: KSA | C5: DF | D5: AS Roma | E5: 25 | F5: 0 | G5: 1 | H5: 0 | I5: 0
A6: Oliver Abildgaard | B6: DEN | C6: MF | D6: Como | E6: 28 | F6: 0 | G6: 0 | H6: 0 | I6: 0
A7: Tammy Abraham | B7: ENG | C7: FW | D7: AS Roma | E7: 26 | F7: 0 | G7: 0 | H7: 0 | I7: 0
A8: Tammy Abraham | B8: ENG | C8: FW | D8: AC Milan | E8: 26 | F8: 3 | G8: 4 | H8: 1 | I8: 0
A9: Federico Accornero | B9: ITA | C9: MF | D9: Genoa | E9: 20 | F9: 0 | G9: 0 | H9: 0 | I9: 0
A10: Francesco Acerbi | B10: ITA | C10: DF | D10: Inter Milan | E10: 36 | F10: 0 | G10: 1 | H10: 0 | I10: 0
A11: Che Adams | B11: SCO | C11: FW | D11: Torino | E11: 28 | F11: 9 | G11: 3 | H11: 2 | I11: 0
A12: Yacine Adli | B12: FRA | C12: MF | D12: Fiorentina | E12: 24 | F12: 4 | G12: 6 | H12: 3 | I12: 1
A13: Vasilije Adžić | B13: MNE | C13: MF,FW | D13: Juventus | E13: 18 | F13: 0 | G13: 0 | H13: 0 | I13: 0
A14: Michel Aebischer | B14: SUI | C14: MF | D14: Bologna | E14: 27 | F14: 0 | G14: 0 | H14: 2 | I14: 0
A15: Honest Ahanor | B15: ITA | C15: DF,MF | D15: Genoa | E15: 16 | F15: 0 | G15: 0 | H15: 0 | I15: 0
... A637: Milan Đurić | B637: BIH | C637: FW | D637: Parma | E637: 34 | F637: 1 | G637: 0 | H637: 1 | I637: 0
