Workbook
Name kunci_jawaban: DF!$C$33

Sheet XL-TEST
B2: Hard Level (⭐⭐⭐)
B3: KODE SOAL | D3: SBEH007 | F3: KODE JAWABAN | H3: =kunci_jawaban -> HG2|B91-3471;D01-3531;921-3F61;AC1-45E1;B41-4041;5F1-60E1;CB1-1ACB1;3F1-46A1;B91-46A1;221-40E1;AC1-2921;F01-ABE1
F5: Selesai mengerjakan? Kirimkan Kode Jawaban diatas ke alamat : https://belajarexcel.id/xl-test/ untuk mengecek hasil jawaban
C8: Hari ini | D8: 45896
E9: (1) IF | F9: (2) CHOOSE | G9: (3) CHOOSE | H9: (4) SWITCH | I9: (5) SWITCH | J9: (6)IF | K9: (7)IF | N9: (8) IF | O9: (9) SWITCH | R9: (10) SWITCH | S9: (11) IFS | T9: (12) IFS
B10: No | C10: Kode Pelanggan | D10: Kode Produk | E10: Nama Pelanggan | F10: Asal Gudang | G10: Asal Produksi | H10: Jenis Produk | I10: Warna Produk | J10: Biaya Tambahan | K10: Bonus | L10: Penjualan 1 | M10: Penjualan 2 | N10: Kategori | O10: Kategori | P10: Tanggal Mulai Promo | Q10: Tanggal Berakhir Promo | R10: Status Promo | S10: Grade | T10: Ongkos Kirim
B11: 1 | C11: P-002 | D11: TS-BLK-A2 | E11: =IF(C11="P-001","Toko Cemerlang",IF(C11="P-002","Toko Bagus","Toko Sinar")) -> Toko Bagus | F11: =CHOOSE(RIGHT(D11,1),"Gudang Jakarta","Gudang Bandung","Gudang Bogor") -> Gudang Bandung | G11: =CHOOSE(CODE(MID(D11,8,1))-64,"Tasikmalaya","Bandung","Garut","Sukabumi") -> Tasikmalaya | H11: {=_xlfn.SWITCH(LEFT(D11,2),"TS","T-Shirt","JP","Jaket Pria","HB","Hoodie Basic","KM","Kemeja","SW","Sweater")} -> T-Shirt | I11: {=_xlfn.SWITCH(MID(D11,4,3),"WHT","White","BLK","Black","RED","Red")} -> Black | J11: =IF(OR(G11="Tasikmalaya",G11="Garut"),10000,5000) -> 10000 | K11: =IF(AND(OR(G11="Bandung",G11="Sukabumi"),F11="Gudang Jakarta"),50000,0) -> 0 | L11: 74 | M11: 90 | N11: =IF(AND(L11>80,M11>80),"Laku",IF(AND(L11>=80,M11<80),"Turun",IF(AND(L11<80,M11>=80),"Naik","Kurang Laku"))) -> Naik | O11: {=_xlfn.SWITCH(TRUE, L11<80, IF(M11>=80, "Naik", "Kurang Laku"), M11>=80, "Laku", "Turun")} -> Naik | P11: 45868 | Q11: 45968 | R11: {=_xlfn.SWITCH(TRUE,$D$8<P11,"Belum Mulai",AND($D$8>=P11,$D$8<=Q11),"Sedang Berlangsung",$D$8>Q11,"Promo Selesai")} -> Sedang Berlangsung | S11: {=_xlfn.IFS(M11>=80,"A",M11>=60,"B",M11>=40,"C",TRUE,"D")} -> A | T11: {=_xlfn.IFS(H11="T-Shirt",5000,H11="Kemeja",10000,TRUE,20000)} -> 5000
B12: 2 | C12: P-001 | D12: KM-WHT-C1 | E12: =IF(C12="P-001","Toko Cemerlang",IF(C12="P-002","Toko Bagus","Toko Sinar")) -> Toko Cemerlang | F12: =CHOOSE(RIGHT(D12,1),"Gudang Jakarta","Gudang Bandung","Gudang Bogor") -> Gudang Jakarta | G12: =CHOOSE(CODE(MID(D12,8,1))-64,"Tasikmalaya","Bandung","Garut","Sukabumi") -> Garut | H12: {=_xlfn.SWITCH(LEFT(D12,2),"TS","T-Shirt","JP","Jaket Pria","HB","Hoodie Basic","KM","Kemeja","SW","Sweater")} -> Kemeja | I12: {=_xlfn.SWITCH(MID(D12,4,3),"WHT","White","BLK","Black","RED","Red")} -> White | J12: =IF(OR(G12="Tasikmalaya",G12="Garut"),10000,5000) -> 10000 | K12: =IF(AND(OR(G12="Bandung",G12="Sukabumi"),F12="Gudang Jakarta"),50000,0) -> 0 | L12: 94 | M12: 84 | N12: =IF(AND(L12>80,M12>80),"Laku",IF(AND(L12>=80,M12<80),"Turun",IF(AND(L12<80,M12>=80),"Naik","Kurang Laku"))) -> Laku | O12: {=_xlfn.SWITCH(TRUE, L12<80, IF(M12>=80, "Naik", "Kurang Laku"), M12>=80, "Laku", "Turun")} -> Laku | P12: 45782 | Q12: 45836 | R12: {=_xlfn.SWITCH(TRUE,$D$8<P12,"Belum Mulai",AND($D$8>=P12,$D$8<=Q12),"Sedang Berlangsung",$D$8>Q12,"Promo Selesai")} -> Promo Selesai | S12: {=_xlfn.IFS(M12>=80,"A",M12>=60,"B",M12>=40,"C",TRUE,"D")} -> A | T12: {=_xlfn.IFS(H12="T-Shirt",5000,H12="Kemeja",10000,TRUE,20000)} -> 10000
B13: 3 | C13: P-003 | D13: TS-RED-B1 | E13: =IF(C13="P-001","Toko Cemerlang",IF(C13="P-002","Toko Bagus","Toko Sinar")) -> Toko Sinar | F13: =CHOOSE(RIGHT(D13,1),"Gudang Jakarta","Gudang Bandung","Gudang Bogor") -> Gudang Jakarta | G13: =CHOOSE(CODE(MID(D13,8,1))-64,"Tasikmalaya","Bandung","Garut","Sukabumi") -> Bandung | H13: {=_xlfn.SWITCH(LEFT(D13,2),"TS","T-Shirt","JP","Jaket Pria","HB","Hoodie Basic","KM","Kemeja","SW","Sweater")} -> T-Shirt | I13: {=_xlfn.SWITCH(MID(D13,4,3),"WHT","White","BLK","Black","RED","Red")} -> Red | J13: =IF(OR(G13="Tasikmalaya",G13="Garut"),10000,5000) -> 5000 | K13: =IF(AND(OR(G13="Bandung",G13="Sukabumi"),F13="Gudang Jakarta"),50000,0) -> 50000 | L13: 48 | M13: 67 | N13: =IF(AND(L13>80,M13>80),"Laku",IF(AND(L13>=80,M13<80),"Turun",IF(AND(L13<80,M13>=80),"Naik","Kurang Laku"))) -> Kurang Laku | O13: {=_xlfn.SWITCH(TRUE, L13<80, IF(M13>=80, "Naik", "Kurang Laku"), M13>=80, "Laku", "Turun")} -> Kurang Laku | P13: 45934 | Q13: 46028 | R13: {=_xlfn.SWITCH(TRUE,$D$8<P13,"Belum Mulai",AND($D$8>=P13,$D$8<=Q13),"Sedang Berlangsung",$D$8>Q13,"Promo Selesai")} -> Belum Mulai | S13: {=_xlfn.IFS(M13>=80,"A",M13>=60,"B",M13>=40,"C",TRUE,"D")} -> B | T13: {=_xlfn.IFS(H13="T-Shirt",5000,H13="Kemeja",10000,TRUE,20000)} -> 5000
B14: 4 | C14: P-002 | D14: JP-BLK-C3 | E14: =IF(C14="P-001","Toko Cemerlang",IF(C14="P-002","Toko Bagus","Toko Sinar")) -> Toko Bagus | F14: =CHOOSE(RIGHT(D14,1),"Gudang Jakarta","Gudang Bandung","Gudang Bogor") -> Gudang Bogor | G14: =CHOOSE(CODE(MID(D14,8,1))-64,"Tasikmalaya","Bandung","Garut","Sukabumi") -> Garut | H14: {=_xlfn.SWITCH(LEFT(D14,2),"TS","T-Shirt","JP","Jaket Pria","HB","Hoodie Basic","KM","Kemeja","SW","Sweater")} -> Jaket Pria | I14: {=_xlfn.SWITCH(MID(D14,4,3),"WHT","White","BLK","Black","RED","Red")} -> Black | J14: =IF(OR(G14="Tasikmalaya",G14="Garut"),10000,5000) -> 10000 | K14: =IF(AND(OR(G14="Bandung",G14="Sukabumi"),F14="Gudang Jakarta"),50000,0) -> 0 | L14: 52 | M14: 51 | N14: =IF(AND(L14>80,M14>80),"Laku",IF(AND(L14>=80,M14<80),"Turun",IF(AND(L14<80,M14>=80),"Naik","Kurang Laku"))) -> Kurang Laku | O14: {=_xlfn.SWITCH(TRUE, L14<80, IF(M14>=80, "Naik", "Kurang Laku"), M14>=80, "Laku", "Turun")} -> Kurang Laku | P14: 45897 | Q14: 46008 | R14: {=_xlfn.SWITCH(TRUE,$D$8<P14,"Belum Mulai",AND($D$8>=P14,$D$8<=Q14),"Sedang Berlangsung",$D$8>Q14,"Promo Selesai")} -> Belum Mulai | S14: {=_xlfn.IFS(M14>=80,"A",M14>=60,"B",M14>=40,"C",TRUE,"D")} -> C | T14: {=_xlfn.IFS(H14="T-Shirt",5000,H14="Kemeja",10000,TRUE,20000)} -> 20000
B15: 5 | C15: P-001 | D15: KM-WHT-C1 | E15: =IF(C15="P-001","Toko Cemerlang",IF(C15="P-002","Toko Bagus","Toko Sinar")) -> Toko Cemerlang | F15: =CHOOSE(RIGHT(D15,1),"Gudang Jakarta","Gudang Bandung","Gudang Bogor") -> Gudang Jakarta | G15: =CHOOSE(CODE(MID(D15,8,1))-64,"Tasikmalaya","Bandung","Garut","Sukabumi") -> Garut | H15: {=_xlfn.SWITCH(LEFT(D15,2),"TS","T-Shirt","JP","Jaket Pria","HB","Hoodie Basic","KM","Kemeja","SW","Sweater")} -> Kemeja | I15: {=_xlfn.SWITCH(MID(D15,4,3),"WHT","White","BLK","Black","RED","Red")} -> White | J15: =IF(OR(G15="Tasikmalaya",G15="Garut"),10000,5000) -> 10000 | K15: =IF(AND(OR(G15="Bandung",G15="Sukabumi"),F15="Gudang Jakarta"),50000,0) -> 0 | L15: 65 | M15: 80 | N15: =IF(AND(L15>80,M15>80),"Laku",IF(AND(L15>=80,M15<80),"Turun",IF(AND(L15<80,M15>=80),"Naik","Kurang Laku"))) -> Naik | O15: {=_xlfn.SWITCH(TRUE, L15<80, IF(M15>=80, "Naik", "Kurang Laku"), M15>=80, "Laku", "Turun")} -> Naik | P15: 45845 | Q15: 45907 | R15: {=_xlfn.SWITCH(TRUE,$D$8<P15,"Belum Mulai",AND($D$8>=P15,$D$8<=Q15),"Sedang Berlangsung",$D$8>Q15,"Promo Selesai")} -> Sedang Berlangsung | S15: {=_xlfn.IFS(M15>=80,"A",M15>=60,"B",M15>=40,"C",TRUE,"D")} -> A | T15: {=_xlfn.IFS(H15="T-Shirt",5000,H15="Kemeja",10000,TRUE,20000)} -> 10000
B16: 6 | C16: P-002 | D16: JP-RED-D1 | E16: =IF(C16="P-001","Toko Cemerlang",IF(C16="P-002","Toko Bagus","Toko Sinar")) -> Toko Bagus | F16: =CHOOSE(RIGHT(D16,1),"Gudang Jakarta","Gudang Bandung","Gudang Bogor") -> Gudang Jakarta | G16: =CHOOSE(CODE(MID(D16,8,1))-64,"Tasikmalaya","Bandung","Garut","Sukabumi") -> Sukabumi | H16: {=_xlfn.SWITCH(LEFT(D16,2),"TS","T-Shirt","JP","Jaket Pria","HB","Hoodie Basic","KM","Kemeja","SW","Sweater")} -> Jaket Pria | I16: {=_xlfn.SWITCH(MID(D16,4,3),"WHT","White","BLK","Black","RED","Red")} -> Red | J16: =IF(OR(G16="Tasikmalaya",G16="Garut"),10000,5000) -> 5000 | K16: =IF(AND(OR(G16="Bandung",G16="Sukabumi"),F16="Gudang Jakarta"),50000,0) -> 50000 | L16: 76 | M16: 35 | N16: =IF(AND(L16>80,M16>80),"Laku",IF(AND(L16>=80,M16<80),"Turun",IF(AND(L16<80,M16>=80),"Naik","Kurang Laku"))) -> Kurang Laku | O16: {=_xlfn.SWITCH(TRUE, L16<80, IF(M16>=80, "Naik", "Kurang Laku"), M16>=80, "Laku", "Turun")} -> Kurang Laku | P16: 45798 | Q16: 45894 | R16: {=_xlfn.SWITCH(TRUE,$D$8<P16,"Belum Mulai",AND($D$8>=P16,$D$8<=Q16),"Sedang Berlangsung",$D$8>Q16,"Promo Selesai")} -> Promo Selesai | S16: {=_xlfn.IFS(M16>=80,"A",M16>=60,"B",M16>=40,"C",TRUE,"D")} -> D | T16: {=_xlfn.IFS(H16="T-Shirt",5000,H16="Kemeja",10000,TRUE,20000)} -> 20000
B17: 7 | C17: P-001 | D17: HB-BLK-B3 | E17: =IF(C17="P-001","Toko Cemerlang",IF(C17="P-002","Toko Bagus","Toko Sinar")) -> Toko Cemerlang | F17: =CHOOSE(RIGHT(D17,1),"Gudang Jakarta","Gudang Bandung","Gudang Bogor") -> Gudang Bogor | G17: =CHOOSE(CODE(MID(D17,8,1))-64,"Tasikmalaya","Bandung","Garut","Sukabumi") -> Bandung | H17: {=_xlfn.SWITCH(LEFT(D17,2),"TS","T-Shirt","JP","Jaket Pria","HB","Hoodie Basic","KM","Kemeja","SW","Sweater")} -> Hoodie Basic | I17: {=_xlfn.SWITCH(MID(D17,4,3),"WHT","White","BLK","Black","RED","Red")} -> Black | J17: =IF(OR(G17="Tasikmalaya",G17="Garut"),10000,5000) -> 5000 | K17: =IF(AND(OR(G17="Bandung",G17="Sukabumi"),F17="Gudang Jakarta"),50000,0) -> 0 | L17: 61 | M17: 98 | N17: =IF(AND(L17>80,M17>80),"Laku",IF(AND(L17>=80,M17<80),"Turun",IF(AND(L17<80,M17>=80),"Naik","Kurang Laku"))) -> Naik | O17: {=_xlfn.SWITCH(TRUE, L17<80, IF(M17>=80, "Naik", "Kurang Laku"), M17>=80, "Laku", "Turun")} -> Naik | P17: 45894 | Q17: 46006 | R17: {=_xlfn.SWITCH(TRUE,$D$8<P17,"Belum Mulai",AND($D$8>=P17,$D$8<=Q17),"Sedang Berlangsung",$D$8>Q17,"Promo Selesai")} -> Sedang Berlangsung | S17: {=_xlfn.IFS(M17>=80,"A",M17>=60,"B",M17>=40,"C",TRUE,"D")} -> A | T17: {=_xlfn.IFS(H17="T-Shirt",5000,H17="Kemeja",10000,TRUE,20000)} -> 20000
B18: 8 | C18: P-001 | D18: SW-WHT-C1 | E18: =IF(C18="P-001","Toko Cemerlang",IF(C18="P-002","Toko Bagus","Toko Sinar")) -> Toko Cemerlang | F18: =CHOOSE(RIGHT(D18,1),"Gudang Jakarta","Gudang Bandung","Gudang Bogor") -> Gudang Jakarta | G18: =CHOOSE(CODE(MID(D18,8,1))-64,"Tasikmalaya","Bandung","Garut","Sukabumi") -> Garut | H18: {=_xlfn.SWITCH(LEFT(D18,2),"TS","T-Shirt","JP","Jaket Pria","HB","Hoodie Basic","KM","Kemeja","SW","Sweater")} -> Sweater | I18: {=_xlfn.SWITCH(MID(D18,4,3),"WHT","White","BLK","Black","RED","Red")} -> White | J18: =IF(OR(G18="Tasikmalaya",G18="Garut"),10000,5000) -> 10000 | K18: =IF(AND(OR(G18="Bandung",G18="Sukabumi"),F18="Gudang Jakarta"),50000,0) -> 0 | L18: 56 | M18: 74 | N18: =IF(AND(L18>80,M18>80),"Laku",IF(AND(L18>=80,M18<80),"Turun",IF(AND(L18<80,M18>=80),"Naik","Kurang Laku"))) -> Kurang Laku | O18: {=_xlfn.SWITCH(TRUE, L18<80, IF(M18>=80, "Naik", "Kurang Laku"), M18>=80, "Laku", "Turun")} -> Kurang Laku | P18: 45816 | Q18: 45855 | R18: {=_xlfn.SWITCH(TRUE,$D$8<P18,"Belum Mulai",AND($D$8>=P18,$D$8<=Q18),"Sedang Berlangsung",$D$8>Q18,"Promo Selesai")} -> Promo Selesai | S18: {=_xlfn.IFS(M18>=80,"A",M18>=60,"B",M18>=40,"C",TRUE,"D")} -> B | T18: {=_xlfn.IFS(H18="T-Shirt",5000,H18="Kemeja",10000,TRUE,20000)} -> 20000
B19: 9 | C19: P-001 | D19: HB-RED-A3 | E19: =IF(C19="P-001","Toko Cemerlang",IF(C19="P-002","Toko Bagus","Toko Sinar")) -> Toko Cemerlang | F19: =CHOOSE(RIGHT(D19,1),"Gudang Jakarta","Gudang Bandung","Gudang Bogor") -> Gudang Bogor | G19: =CHOOSE(CODE(MID(D19,8,1))-64,"Tasikmalaya","Bandung","Garut","Sukabumi") -> Tasikmalaya | H19: {=_xlfn.SWITCH(LEFT(D19,2),"TS","T-Shirt","JP","Jaket Pria","HB","Hoodie Basic","KM","Kemeja","SW","Sweater")} -> Hoodie Basic | I19: {=_xlfn.SWITCH(MID(D19,4,3),"WHT","White","BLK","Black","RED","Red")} -> Red | J19: =IF(OR(G19="Tasikmalaya",G19="Garut"),10000,5000) -> 10000 | K19: =IF(AND(OR(G19="Bandung",G19="Sukabumi"),F19="Gudang Jakarta"),50000,0) -> 0 | L19: 83 | M19: 45 | N19: =IF(AND(L19>80,M19>80),"Laku",IF(AND(L19>=80,M19<80),"Turun",IF(AND(L19<80,M19>=80),"Naik","Kurang Laku"))) -> Turun | O19: {=_xlfn.SWITCH(TRUE, L19<80, IF(M19>=80, "Naik", "Kurang Laku"), M19>=80, "Laku", "Turun")} -> Turun | P19: 45936 | Q19: 46089 | R19: {=_xlfn.SWITCH(TRUE,$D$8<P19,"Belum Mulai",AND($D$8>=P19,$D$8<=Q19),"Sedang Berlangsung",$D$8>Q19,"Promo Selesai")} -> Belum Mulai | S19: {=_xlfn.IFS(M19>=80,"A",M19>=60,"B",M19>=40,"C",TRUE,"D")} -> C | T19: {=_xlfn.IFS(H19="T-Shirt",5000,H19="Kemeja",10000,TRUE,20000)} -> 20000
B20: 10 | C20: P-003 | D20: TS-BLK-D1 | E20: =IF(C20="P-001","Toko Cemerlang",IF(C20="P-002","Toko Bagus","Toko Sinar")) -> Toko Sinar | F20: =CHOOSE(RIGHT(D20,1),"Gudang Jakarta","Gudang Bandung","Gudang Bogor") -> Gudang Jakarta | G20: =CHOOSE(CODE(MID(D20,8,1))-64,"Tasikmalaya","Bandung","Garut","Sukabumi") -> Sukabumi | H20: {=_xlfn.SWITCH(LEFT(D20,2),"TS","T-Shirt","JP","Jaket Pria","HB","Hoodie Basic","KM","Kemeja","SW","Sweater")} -> T-Shirt | I20: {=_xlfn.SWITCH(MID(D20,4,3),"WHT","White","BLK","Black","RED","Red")} -> Black | J20: =IF(OR(G20="Tasikmalaya",G20="Garut"),10000,5000) -> 5000 | K20: =IF(AND(OR(G20="Bandung",G20="Sukabumi"),F20="Gudang Jakarta"),50000,0) -> 50000 | L20: 95 | M20: 94 | N20: =IF(AND(L20>80,M20>80),"Laku",IF(AND(L20>=80,M20<80),"Turun",IF(AND(L20<80,M20>=80),"Naik","Kurang Laku"))) -> Laku | O20: {=_xlfn.SWITCH(TRUE, L20<80, IF(M20>=80, "Naik", "Kurang Laku"), M20>=80, "Laku", "Turun")} -> Laku | P20: 45818 | Q20: 45922 | R20: {=_xlfn.SWITCH(TRUE,$D$8<P20,"Belum Mulai",AND($D$8>=P20,$D$8<=Q20),"Sedang Berlangsung",$D$8>Q20,"Promo Selesai")} -> Sedang Berlangsung | S20: {=_xlfn.IFS(M20>=80,"A",M20>=60,"B",M20>=40,"C",TRUE,"D")} -> A | T20: {=_xlfn.IFS(H20="T-Shirt",5000,H20="Kemeja",10000,TRUE,20000)} -> 5000
B21: 11 | C21: P-003 | D21: JP-WHT-A2 | E21: =IF(C21="P-001","Toko Cemerlang",IF(C21="P-002","Toko Bagus","Toko Sinar")) -> Toko Sinar | F21: =CHOOSE(RIGHT(D21,1),"Gudang Jakarta","Gudang Bandung","Gudang Bogor") -> Gudang Bandung | G21: =CHOOSE(CODE(MID(D21,8,1))-64,"Tasikmalaya","Bandung","Garut","Sukabumi") -> Tasikmalaya | H21: {=_xlfn.SWITCH(LEFT(D21,2),"TS","T-Shirt","JP","Jaket Pria","HB","Hoodie Basic","KM","Kemeja","SW","Sweater")} -> Jaket Pria | I21: {=_xlfn.SWITCH(MID(D21,4,3),"WHT","White","BLK","Black","RED","Red")} -> White | J21: =IF(OR(G21="Tasikmalaya",G21="Garut"),10000,5000) -> 10000 | K21: =IF(AND(OR(G21="Bandung",G21="Sukabumi"),F21="Gudang Jakarta"),50000,0) -> 0 | L21: 81 | M21: 54 | N21: =IF(AND(L21>80,M21>80),"Laku",IF(AND(L21>=80,M21<80),"Turun",IF(AND(L21<80,M21>=80),"Naik","Kurang Laku"))) -> Turun | O21: {=_xlfn.SWITCH(TRUE, L21<80, IF(M21>=80, "Naik", "Kurang Laku"), M21>=80, "Laku", "Turun")} -> Turun | P21: 45896 | Q21: 46005 | R21: {=_xlfn.SWITCH(TRUE,$D$8<P21,"Belum Mulai",AND($D$8>=P21,$D$8<=Q21),"Sedang Berlangsung",$D$8>Q21,"Promo Selesai")} -> Sedang Berlangsung | S21: {=_xlfn.IFS(M21>=80,"A",M21>=60,"B",M21>=40,"C",TRUE,"D")} -> C | T21: {=_xlfn.IFS(H21="T-Shirt",5000,H21="Kemeja",10000,TRUE,20000)} -> 20000
B22: 12 | C22: P-002 | D22: HB-BLK-A3 | E22: =IF(C22="P-001","Toko Cemerlang",IF(C22="P-002","Toko Bagus","Toko Sinar")) -> Toko Bagus | F22: =CHOOSE(RIGHT(D22,1),"Gudang Jakarta","Gudang Bandung","Gudang Bogor") -> Gudang Bogor | G22: =CHOOSE(CODE(MID(D22,8,1))-64,"Tasikmalaya","Bandung","Garut","Sukabumi") -> Tasikmalaya | H22: {=_xlfn.SWITCH(LEFT(D22,2),"TS","T-Shirt","JP","Jaket Pria","HB","Hoodie Basic","KM","Kemeja","SW","Sweater")} -> Hoodie Basic | I22: {=_xlfn.SWITCH(MID(D22,4,3),"WHT","White","BLK","Black","RED","Red")} -> Black | J22: =IF(OR(G22="Tasikmalaya",G22="Garut"),10000,5000) -> 10000 | K22: =IF(AND(OR(G22="Bandung",G22="Sukabumi"),F22="Gudang Jakarta"),50000,0) -> 0 | L22: 69 | M22: 39 | N22: =IF(AND(L22>80,M22>80),"Laku",IF(AND(L22>=80,M22<80),"Turun",IF(AND(L22<80,M22>=80),"Naik","Kurang Laku"))) -> Kurang Laku | O22: {=_xlfn.SWITCH(TRUE, L22<80, IF(M22>=80, "Naik", "Kurang Laku"), M22>=80, "Laku", "Turun")} -> Kurang Laku | P22: 45938 | Q22: 46073 | R22: {=_xlfn.SWITCH(TRUE,$D$8<P22,"Belum Mulai",AND($D$8>=P22,$D$8<=Q22),"Sedang Berlangsung",$D$8>Q22,"Promo Selesai")} -> Belum Mulai | S22: {=_xlfn.IFS(M22>=80,"A",M22>=60,"B",M22>=40,"C",TRUE,"D")} -> D | T22: {=_xlfn.IFS(H22="T-Shirt",5000,H22="Kemeja",10000,TRUE,20000)} -> 20000
... B25: 15 | C25: P-003 | D25: SW-RED-A2 | E25: =IF(C25="P-001","Toko Cemerlang",IF(C25="P-002","Toko Bagus","Toko Sinar")) -> Toko Sinar | F25: =CHOOSE(RIGHT(D25,1),"Gudang Jakarta","Gudang Bandung","Gudang Bogor") -> Gudang Bandung | G25: =CHOOSE(CODE(MID(D25,8,1))-64,"Tasikmalaya","Bandung","Garut","Sukabumi") -> Tasikmalaya | H25: {=_xlfn.SWITCH(LEFT(D25,2),"TS","T-Shirt","JP","Jaket Pria","HB","Hoodie Basic","KM","Kemeja","SW","Sweater")} -> Sweater | I25: {=_xlfn.SWITCH(MID(D25,4,3),"WHT","White","BLK","Black","RED","Red")} -> Red | J25: =IF(OR(G25="Tasikmalaya",G25="Garut"),10000,5000) -> 10000 | K25: =IF(AND(OR(G25="Bandung",G25="Sukabumi"),F25="Gudang Jakarta"),50000,0) -> 0 | L25: 41 | M25: 97 | N25: =IF(AND(L25>80,M25>80),"Laku",IF(AND(L25>=80,M25<80),"Turun",IF(AND(L25<80,M25>=80),"Naik","Kurang Laku"))) -> Naik | O25: {=_xlfn.SWITCH(TRUE, L25<80, IF(M25>=80, "Naik", "Kurang Laku"), M25>=80, "Laku", "Turun")} -> Naik | P25: 45823 | Q25: 45913 | R25: {=_xlfn.SWITCH(TRUE,$D$8<P25,"Belum Mulai",AND($D$8>=P25,$D$8<=Q25),"Sedang Berlangsung",$D$8>Q25,"Promo Selesai")} -> Sedang Berlangsung | S25: {=_xlfn.IFS(M25>=80,"A",M25>=60,"B",M25>=40,"C",TRUE,"D")} -> A | T25: {=_xlfn.IFS(H25="T-Shirt",5000,H25="Kemeja",10000,TRUE,20000)} -> 20000
B27: Tidak menggunakan kolom bantu.
C29: * | D29: Isi Kolom-kolom kosong diatas menggunakan Fungsi logika yang ditentukan oleh soal:
C30: ** | D30: Pada soal ini akan menggunakan fungsi IF,IFS,SWITCH dan CHOOSE dimana Versi Excel minimal yang dibutuhkan adalah versi Excel 2019
D32: Soal
C35: 1 | D35: Isi kolom Nama Pelangan berdasarkan Kode Pelanggan Menggunakan Fungsi IF | K35: 9 | L35: Isi Kolom Kategori berdasarkan Penjualan 1 dan Penjualan 2 mengunakan Fungsi SWITCH
D36: => Jika P-001 maka "Toko Cemerlang", Jika P-002 maka "Toko Bagus", Jika P-003 maka "Toko Sinar" | L36: => Jika Penjuala 1 dan Penjualan 2 lebih besar sama dengan 80 maka "Laku"
L37: => Jika Penjuala 1 lebih besar sama dengan 80 dan Penjualan 2 lebih kecil dari 80 maka "Turun"
C38: 2 | D38: Isi Kolom Asal Gudang berdasarkan Kode Produk karakter terakhir mengunakan Fungsi CHOOSE | L38: => Jika Penjuala 1 lebih kecil dari 80 dan Penjualan 2 lebih besar sama dengan 80 maka "Naik"
D39: => Jika 1 maka "Gudang Jakarta", Jika 2 maka "Gudang Bandung" dan Jika 3 maka "Gudang Bogor" | L39: => Jika Penjuala 1 dan Penjualan 2 lebih kecil dari 80 maka "Kurang Laku"
B40: Copyright © 2025 | BelajarExcel.id
D41: Isi Kolom Asal Produksi berdasarkan Kode Produk karakter ke 8 mengunakan Fungsi CHOOSE | K41: 10 | L41: Isi Kolom Status Promo berdasarkan Tanggal mengunakan Fungsi SWITCH
C42: 3 | D42: => Jika A maka "Tasikmalaya", Jika B maka "Bandung" , Jika C maka "Garut", jika D maka "Sukabumi" | L42: => Jika Tanggal Hari ini (D5) Lebih kecil dari Tanggal Mulai Promo , maka "Belum Mulai"
L43: => Jika Tanggal Hari ini (D5) Sama atau Berada diantara Tanggal Mulai Promo dan Tanggal Berakhir Promo , maka "Sedang Berlangsung"
C44: 4 | D44: Isi Kolom Jenis Produk berdasarkan Kode Produk karakter ke 1 dan ke 2 mengunakan Fungsi SWITCH | L44: => Jika Tanggal Hari ini (D5) Lebih besar dari Tanggal Berakhir Promo , maka "Promo Selesai"
D45: => Jika TS maka "T-Shirt", Jika JP maka "Jaket Pria" , Jika HB maka "Hoodie Basic", jika KM maka "Kemeja", jika SW maka "Sweater"
K46: 11 | L46: Isi Kolom Grade berdasarkan Penjualan 2 mengunakan Fungsi IFS
C47: 5 | D47: Isi Kolom Warna Produk berdasarkan Kode Produk karakter ke 4 sampai 6 mengunakan Fungsi SWITCH | L47: => Jika nilai Penjualan 2 barada pada nilai 80 dan 100 Maka "A"
D48: => Jika WHT maka "White" , Jika BLK maka "Black", jika RED maka "Red" | L48: => Jika nilai Penjualan 2 barada pada nilai 60 dan 79 Maka "B"
L49: => Jika nilai Penjualan 2 barada pada nilai 40 dan 59 Maka "C"
C50: 6 | D50: Isi Kolom Biaya Tambahan berdasarkan Asal Produksi mengunakan Fungsi IF | L50: => Jika nilai Penjualan 2 barada pada nilai 0 dan 39 Maka "D"
D51: => Jika Asal Produksi dari "Tasikmalaya" atau "Garut" , Biaya tambahan sebesar 10.000 , Selain "Tasikmalaya" dan "Garut" biaya tambahan 5.000
...

Sheet DF
A1: DF | C1: 1 | D1: 2 | E1: 3 | F1: 4 | G1: 5 | H1: 6 | I1: 7 | J1: 8 | K1: 9 | L1: 10 | M1: 11 | N1: 12 | V1: 1 | W1: =_xlfn.FORMULATEXT('XL-TEST'!E11) -> =IF(C11="P-001";"Toko Cemerlang";IF(C11="P-002";"Toko Bagus";"Toko Sinar")) | X1: =_xlfn.FORMULATEXT('XL-TEST'!F11) -> =CHOOSE(RIGHT(D11;1);"Gudang Jakarta";"Gudang Bandung";"Gudang Bogor") | Y1: =_xlfn.FORMULATEXT('XL-TEST'!G11) -> =CHOOSE(CODE(MID(D11;8;1))-64;"Tasikmalaya";"Bandung";"Garut";"Sukabumi") | Z1: =_xlfn.FORMULATEXT('XL-TEST'!H11) -> =SWITCH(LEFT(D11;2);"TS";"T-Shirt";"JP";"Jaket Pria";"HB";"Hoodie Basic";"KM";"Kemeja";"SW";"Sweater") | AA1: =_xlfn.FORMULATEXT('XL-TEST'!I11) -> =SWITCH(MID(D11;4;3);"WHT";"White";"BLK";"Black";"RED";"Red") | AB1: =_xlfn.FORMULATEXT('XL-TEST'!J11) -> =IF(OR(G11="Tasikmalaya";G11="Garut");10000;5000) | AC1: =_xlfn.FORMULATEXT('XL-TEST'!K11) -> =IF(AND(OR(G11="Bandung";G11="Sukabumi");F11="Gudang Jakarta");50000;0) | AD1: =_xlfn.FORMULATEXT('XL-TEST'!N11) -> =IF(AND(L11>80;M11>80);"Laku";IF(AND(L11>=80;M11<80);"Turun";IF(AND(L11<80;M11>=80);"Naik";"Kurang Laku"))) | AE1: =_xlfn.FORMULATEXT('XL-TEST'!O11) -> =SWITCH(TRUE; L11<80; IF(M11>=80; "Naik"; "Kurang Laku"); M11>=80; "Laku"; "Turun") | AF1: =_xlfn.FORMULATEXT('XL-TEST'!R11) -> =SWITCH(TRUE;$D$8<P11;"Belum Mulai";AND($D$8>=P11;$D$8<=Q11);"Sedang Berlangsung";$D$8>Q11;"Promo Selesai") | AG1: =_xlfn.FORMULATEXT('XL-TEST'!S11) -> =IFS(M11>=80;"A";M11>=60;"B";M11>=40;"C";TRUE;"D") | AH1: =_xlfn.FORMULATEXT('XL-TEST'!T11) -> =IFS(H11="T-Shirt";5000;H11="Kemeja";10000;TRUE;20000)
A2: HG2 | B2: 1 | C2: ='XL-TEST'!E11 -> Toko Bagus | D2: ='XL-TEST'!F11 -> Gudang Bandung | E2: ='XL-TEST'!G11 -> Tasikmalaya | F2: ='XL-TEST'!H11 -> T-Shirt | G2: ='XL-TEST'!I11 -> Black | H2: ='XL-TEST'!J11 -> 10000 | I2: ='XL-TEST'!K11 -> 0 | J2: ='XL-TEST'!N11 -> Naik | K2: ='XL-TEST'!O11 -> Naik | L2: ='XL-TEST'!R11 -> Sedang Berlangsung | M2: ='XL-TEST'!S11 -> A | N2: ='XL-TEST'!T11 -> 5000 | V2: 2 | W2: =_xlfn.FORMULATEXT('XL-TEST'!F11) -> =CHOOSE(RIGHT(D11;1);"Gudang Jakarta";"Gudang Bandung";"Gudang Bogor")
B3: 2 | C3: ='XL-TEST'!E13 -> Toko Sinar | D3: ='XL-TEST'!F13 -> Gudang Jakarta | E3: ='XL-TEST'!G13 -> Bandung | F3: ='XL-TEST'!H13 -> T-Shirt | G3: ='XL-TEST'!I13 -> Red | H3: ='XL-TEST'!J13 -> 5000 | I3: ='XL-TEST'!K13 -> 50000 | J3: ='XL-TEST'!N13 -> Kurang Laku | K3: ='XL-TEST'!O13 -> Kurang Laku | L3: ='XL-TEST'!R13 -> Belum Mulai | M3: ='XL-TEST'!S13 -> B | N3: ='XL-TEST'!T13 -> 5000 | V3: 3 | W3: =_xlfn.FORMULATEXT('XL-TEST'!G11) -> =CHOOSE(CODE(MID(D11;8;1))-64;"Tasikmalaya";"Bandung";"Garut";"Sukabumi")
B4: 3 | C4: ='XL-TEST'!E16 -> Toko Bagus | D4: ='XL-TEST'!F16 -> Gudang Jakarta | E4: ='XL-TEST'!G16 -> Sukabumi | F4: ='XL-TEST'!H16 -> Jaket Pria | G4: ='XL-TEST'!I16 -> Red | H4: ='XL-TEST'!J16 -> 5000 | I4: ='XL-TEST'!K16 -> 50000 | J4: ='XL-TEST'!N16 -> Kurang Laku | K4: ='XL-TEST'!O16 -> Kurang Laku | L4: ='XL-TEST'!R16 -> Promo Selesai | M4: ='XL-TEST'!S16 -> D | N4: ='XL-TEST'!T16 -> 20000 | V4: 4 | W4: =_xlfn.FORMULATEXT('XL-TEST'!H11) -> =SWITCH(LEFT(D11;2);"TS";"T-Shirt";"JP";"Jaket Pria";"HB";"Hoodie Basic";"KM";"Kemeja";"SW";"Sweater")
B5: 4 | C5: ='XL-TEST'!E20 -> Toko Sinar | D5: ='XL-TEST'!F20 -> Gudang Jakarta | E5: ='XL-TEST'!G20 -> Sukabumi | F5: ='XL-TEST'!H20 -> T-Shirt | G5: ='XL-TEST'!I20 -> Black | H5: ='XL-TEST'!J20 -> 5000 | I5: ='XL-TEST'!K20 -> 50000 | J5: ='XL-TEST'!N20 -> Laku | K5: ='XL-TEST'!O20 -> Laku | L5: ='XL-TEST'!R20 -> Sedang Berlangsung | M5: ='XL-TEST'!S20 -> A | N5: ='XL-TEST'!T20 -> 5000 | V5: 5 | W5: =_xlfn.FORMULATEXT('XL-TEST'!I11) -> =SWITCH(MID(D11;4;3);"WHT";"White";"BLK";"Black";"RED";"Red")
B6: 5 | C6: ='XL-TEST'!E25 -> Toko Sinar | D6: ='XL-TEST'!F25 -> Gudang Bandung | E6: ='XL-TEST'!G25 -> Tasikmalaya | F6: ='XL-TEST'!H25 -> Sweater | G6: ='XL-TEST'!I25 -> Red | H6: ='XL-TEST'!J25 -> 10000 | I6: ='XL-TEST'!K25 -> 0 | J6: ='XL-TEST'!N25 -> Naik | K6: ='XL-TEST'!O25 -> Naik | L6: ='XL-TEST'!R25 -> Sedang Berlangsung | M6: ='XL-TEST'!S25 -> A | N6: ='XL-TEST'!T25 -> 20000 | V6: 6 | W6: =_xlfn.FORMULATEXT('XL-TEST'!J11) -> =IF(OR(G11="Tasikmalaya";G11="Garut");10000;5000)
B7: Sum 1 | H7: =SUM('XL-TEST'!J11:J25) -> 120000 | I7: =SUM('XL-TEST'!K11:K25) -> 200000 | N7: =SUM('XL-TEST'!T11:T25) -> 220000 | V7: 7 | W7: =_xlfn.FORMULATEXT('XL-TEST'!K11) -> =IF(AND(OR(G11="Bandung";G11="Sukabumi");F11="Gudang Jakarta");50000;0)
B8: Sum 2 | H8: =SUM(H2:H7) -> 155000 | I8: =SUM(I2:I7) -> 350000 | N8: =SUM(N2:N7) -> 275000 | V8: 8 | W8: =_xlfn.FORMULATEXT('XL-TEST'!N11) -> =IF(AND(L11>80;M11>80);"Laku";IF(AND(L11>=80;M11<80);"Turun";IF(AND(L11<80;M11>=80);"Naik";"Kurang Laku")))
V9: 9 | W9: =_xlfn.FORMULATEXT('XL-TEST'!O11) -> =SWITCH(TRUE; L11<80; IF(M11>=80; "Naik"; "Kurang Laku"); M11>=80; "Laku"; "Turun")
B10: Rand | C10: 8121 | D10: 7120 | E10: 6802 | F10: 3244 | G10: 7092 | H10: 9823 | I10: 6859 | J10: 3135 | K10: 6329 | L10: 6946 | M10: 2220 | N10: 8432 | V10: 10 | W10: =_xlfn.FORMULATEXT('XL-TEST'!R11) -> =SWITCH(TRUE;$D$8<P11;"Belum Mulai";AND($D$8>=P11;$D$8<=Q11);"Sedang Berlangsung";$D$8>Q11;"Promo Selesai")
B11: Value Final | C11: =CODE(MID(C2,6,1))+CODE(MID(C3,6,1))+CODE(MID(C4,6,1))+CODE(MID(C5,6,1))+CODE(MID(C6,6,1))+CODE(RIGHT(C2,1))+CODE(RIGHT(C3,1))+CODE(RIGHT(C4,1))+CODE(RIGHT(C5,1)) -> 839 | D11: =CODE(MID(D2,8,1))+CODE(MID(D3,8,1))+CODE(MID(D4,8,1))+CODE(MID(D5,8,1))+CODE(MID(D6,8,1))+CODE(RIGHT(D2,1))+CODE(RIGHT(D3,1))+CODE(RIGHT(D4,1))+CODE(RIGHT(D5,1))+CODE(RIGHT(D6,1)) -> 851 | E11: =CODE(RIGHT(E2,1))+CODE(RIGHT(E3,1))+CODE(RIGHT(E4,1))+CODE(RIGHT(E5,1))+CODE(RIGHT(E6,1))+CODE(RIGHT(E2,1))+CODE(RIGHT(E3,1))+CODE(RIGHT(E4,1))+CODE(RIGHT(E5,1))+CODE(RIGHT(E6,1)) -> 1014 | F11: =CODE(RIGHT(F2,1))+CODE(RIGHT(F3,1))+CODE(RIGHT(F4,1))+CODE(RIGHT(F5,1))+CODE(RIGHT(F6,1))+CODE(RIGHT(F2,1))+CODE(RIGHT(F3,1))+CODE(RIGHT(F4,1))+CODE(RIGHT(F5,1))+CODE(RIGHT(F6,1)) -> 1118 | G11: =CODE(RIGHT(G2,1))+CODE(RIGHT(G3,1))+CODE(RIGHT(G4,1))+CODE(RIGHT(G5,1))+CODE(RIGHT(G6,1))+CODE(RIGHT(G2,1))+CODE(RIGHT(G3,1))+CODE(RIGHT(G4,1))+CODE(RIGHT(G5,1))+CODE(RIGHT(G6,1)) -> 1028 | H11: =H8/100 -> 1550 | I11: =I8/100 -> 3500 | J11: =CODE(RIGHT(J2,1))+CODE(RIGHT(J3,1))+CODE(RIGHT(J4,1))+CODE(RIGHT(J5,1))+CODE(RIGHT(J6,1))+CODE(RIGHT(J2,1))+CODE(RIGHT(J3,1))+CODE(RIGHT(J4,1))+CODE(RIGHT(J5,1))+CODE(RIGHT(J6,1)) -> 1130 | K11: =CODE(RIGHT(K2,1))+CODE(RIGHT(K3,1))+CODE(RIGHT(K4,1))+CODE(RIGHT(K5,1))+CODE(RIGHT(K6,1))+CODE(RIGHT(K2,1))+CODE(RIGHT(K3,1))+CODE(RIGHT(K4,1))+CODE(RIGHT(K5,1))+CODE(RIGHT(K6,1)) -> 1130 | L11: =CODE(RIGHT(L2,1))+CODE(RIGHT(L3,1))+CODE(RIGHT(L4,1))+CODE(RIGHT(L5,1))+CODE(RIGHT(L6,1))+CODE(RIGHT(L2,1))+CODE(RIGHT(L3,1))+CODE(RIGHT(L4,1))+CODE(RIGHT(L5,1))+CODE(RIGHT(L6,1)) -> 1038 | M11: =CODE(RIGHT(M2,1))+CODE(RIGHT(M3,1))+CODE(RIGHT(M4,1))+CODE(RIGHT(M5,1))+CODE(RIGHT(M6,1))+CODE(RIGHT(M2,1))+CODE(RIGHT(M3,1))+CODE(RIGHT(M4,1))+CODE(RIGHT(M5,1))+CODE(RIGHT(M6,1)) -> 658 | N11: =N8/100 -> 2750 | V11: 11 | W11: =_xlfn.FORMULATEXT('XL-TEST'!S11) -> =IFS(M11>=80;"A";M11>=60;"B";M11>=40;"C";TRUE;"D")
C12: =IFERROR(DEC2HEX(IF(OR(C2="",C2=0),C10,C11))&C22,"EEEE") -> 3471 | D12: =IFERROR(DEC2HEX(IF(OR(D2="",D2=0),D10,D11))&D22,"EEEE") -> 3531 | E12: =IFERROR(DEC2HEX(IF(OR(E2="",E2=0),E10,E11))&E22,"EEEE") -> 3F61 | F12: =IFERROR(DEC2HEX(IF(OR(F2="",F2=0),F10,F11))&F22,"EEEE") -> 45E1 | G12: =IFERROR(DEC2HEX(IF(OR(G2="",G2=0),G10,G11))&G22,"EEEE") -> 4041 | H12: =IFERROR(DEC2HEX(IF(OR(H2="",H2=0),H10,H11))&H22,"EEEE") -> 60E1 | I12: =IFERROR(DEC2HEX(IF(OR(I2="",I2=0),I10,I11))&I22,"EEEE") -> 1ACB1 | J12: =IFERROR(DEC2HEX(IF(OR(J2="",J2=0),J10,J11))&J22,"EEEE") -> 46A1 | ... N12: =IFERROR(DEC2HEX(IF(OR(N2="",N2=0),N10,N11))&N22,"EEEE") -> ABE1 | V12: 12 | W12: =_xlfn.FORMULATEXT('XL-TEST'!T11) -> =IFS(H11="T-Shirt";5000;H11="Kemeja";10000;TRUE;20000)
B14: TRUE | C14: =RIGHT(DEC2HEX(C10),2)&C31 -> B91 | D14: =RIGHT(DEC2HEX(D10),2)&D31 -> D01 | E14: =RIGHT(DEC2HEX(E10),2)&E31 -> 921 | F14: =RIGHT(DEC2HEX(F10),2)&F31 -> AC1 | G14: =RIGHT(DEC2HEX(G10),2)&G31 -> B41 | H14: =RIGHT(DEC2HEX(H10),2)&H31 -> 5F1 | I14: =RIGHT(DEC2HEX(I10),2)&I31 -> CB1 | J14: =RIGHT(DEC2HEX(J10),2)&J31 -> 3F1 | ... N14: =RIGHT(DEC2HEX(N10),2)&N31 -> F01 | W14: 1 | X14: 2 | Y14: 3 | Z14: 4 | AA14: 5 | AB14: 6 | AC14: 7 | AD14: 8 | AE14: 9 | AF14: 10 | AG14: 11 | AH14: 12
B15: FALSE | C15: =LEFT(DEC2HEX(C10),2)&C31 -> 1F1 | D15: =LEFT(DEC2HEX(D10),2)&D31 -> 1B1 | E15: =LEFT(DEC2HEX(E10),2)&E31 -> 1A1 | F15: =LEFT(DEC2HEX(F10),2)&F31 -> CA1 | G15: =LEFT(DEC2HEX(G10),2)&G31 -> 1B1 | H15: =LEFT(DEC2HEX(H10),2)&H31 -> 261 | I15: =LEFT(DEC2HEX(I10),2)&I31 -> 1A1 | J15: =LEFT(DEC2HEX(J10),2)&J31 -> C31 | ... N15: =LEFT(DEC2HEX(N10),2)&N31 -> 201
B18: Cek Rumus | C18: =IF(C22=1,C14,C15) -> B91 | D18: =IF(D22=1,D14,D15) -> D01 | E18: =IF(E22=1,E14,E15) -> 921 | F18: =IF(F22=1,F14,F15) -> AC1 | G18: =IF(G22=1,G14,G15) -> B41 | H18: =IF(H22=1,H14,H15) -> 5F1 | I18: =IF(I22=1,I14,I15) -> CB1 | J18: =IF(J22=1,J14,J15) -> 3F1 | ... N18: =IF(N22=1,N14,N15) -> F01
B20: Gabung IF | C20: =C18&"-"&C12&";" -> B91-3471; | D20: =D18&"-"&D12&";" -> D01-3531; | E20: =E18&"-"&E12&";" -> 921-3F61; | F20: =F18&"-"&F12&";" -> AC1-45E1; | G20: =G18&"-"&G12&";" -> B41-4041; | H20: =H18&"-"&H12&";" -> 5F1-60E1; | I20: =I18&"-"&I12&";" -> CB1-1ACB1; | J20: =J18&"-"&J12&";" -> 3F1-46A1; | ... M20: =M18&"-"&M12&";" -> AC1-2921; | N20: =N18&"-"&N12 -> F01-ABE1
B22: Rumus Wajib | C22: =ISNUMBER(FIND("IF(",W1))+0 -> 1 | D22: =ISNUMBER(FIND("CHOOSE",X1))+0 -> 1 | E22: =ISNUMBER(FIND("CHOOSE",Y1))+0 -> 1 | F22: =ISNUMBER(FIND("SWITCH",Z1))+0 -> 1 | G22: =ISNUMBER(FIND("SWITCH",AA1))+0 -> 1 | H22: =ISNUMBER(FIND("IF(",AB1))+0 -> 1 | I22: =ISNUMBER(FIND("IF(",AC1))+0 -> 1 | J22: =ISNUMBER(FIND("IF(",AD1))+0 -> 1 | K22: =ISNUMBER(FIND("SWITCH",AE1))+0 -> 1 | L22: =ISNUMBER(FIND("SWITCH",AF1))+0 -> 1 | M22: =ISNUMBER(FIND("IFS(",AG1))+0 -> 1 | N22: =ISNUMBER(FIND("IFS(",AH1))+0 -> 1
B23: Jumlah Fungsi | C23: =IFERROR(LEN(W1)-LEN(SUBSTITUTE(W1,"(","")),99) -> 2 | D23: =IFERROR(LEN(X1)-LEN(SUBSTITUTE(X1,"(","")),99) -> 2 | E23: =IFERROR(LEN(Y1)-LEN(SUBSTITUTE(Y1,"(","")),99) -> 3 | F23: =IFERROR(LEN(Z1)-LEN(SUBSTITUTE(Z1,"(","")),99) -> 2 | G23: =IFERROR(LEN(AA1)-LEN(SUBSTITUTE(AA1,"(","")),99) -> 2 | H23: =IFERROR(LEN(AB1)-LEN(SUBSTITUTE(AB1,"(","")),99) -> 2 | I23: =IFERROR(LEN(AC1)-LEN(SUBSTITUTE(AC1,"(","")),99) -> 3 | J23: =IFERROR(LEN(AD1)-LEN(SUBSTITUTE(AD1,"(","")),99) -> 6 | ... N23: =IFERROR(LEN(AH1)-LEN(SUBSTITUTE(AH1,"(","")),99) -> 1
B24: Masuk | C24: 3 | D24: 3 | E24: 3 | F24: 2 | G24: 2 | H24: 2 | I24: 3 | J24: 6 | K24: 3 | L24: 2 | M24: 1 | N24: 1
B25: Fungsi | C25: =(C23<=C24)+0 -> 1 | D25: =(D23<=D24)+0 -> 1 | E25: =(E23<=E24)+0 -> 1 | F25: =(F23<=F24)+0 -> 1 | G25: =(G23<=G24)+0 -> 1 | H25: =(H23<=H24)+0 -> 1 | I25: =(I23<=I24)+0 -> 1 | J25: =(J23<=J24)+0 -> 1 | ... N25: =(N23<=N24)+0 -> 1
B27: Param | C27: =IFERROR(LEN(W1)-LEN(SUBSTITUTE(W1,IF(ISNUMBER(FIND(",",W1)),",",";"),"")),99) -> 4 | D27: =IFERROR(LEN(X1)-LEN(SUBSTITUTE(X1,IF(ISNUMBER(FIND(",",X1)),",",";"),"")),99) -> 4 | E27: =IFERROR(LEN(Y1)-LEN(SUBSTITUTE(Y1,IF(ISNUMBER(FIND(",",Y1)),",",";"),"")),99) -> 6 | F27: =IFERROR(LEN(Z1)-LEN(SUBSTITUTE(Z1,IF(ISNUMBER(FIND(",",Z1)),",",";"),"")),99) -> 11 | G27: =IFERROR(LEN(AA1)-LEN(SUBSTITUTE(AA1,IF(ISNUMBER(FIND(",",AA1)),",",";"),"")),99) -> 8 | H27: =IFERROR(LEN(AB1)-LEN(SUBSTITUTE(AB1,IF(ISNUMBER(FIND(",",AB1)),",",";"),"")),99) -> 3 | I27: =IFERROR(LEN(AC1)-LEN(SUBSTITUTE(AC1,IF(ISNUMBER(FIND(",",AC1)),",",";"),"")),99) -> 4 | J27: =IFERROR(LEN(AD1)-LEN(SUBSTITUTE(AD1,IF(ISNUMBER(FIND(",",AD1)),",",";"),"")),99) -> 9 | ... N27: =IFERROR(LEN(AH1)-LEN(SUBSTITUTE(AH1,IF(ISNUMBER(FIND(",",AH1)),",",";"),"")),99) -> 5
C28: 4 | D28: 4 | E28: 6 | F28: 11 | G28: 8 | H28: 3 | I28: 4 | J28: 9 | K28: 8 | L28: 8 | M28: 7 | N28: 5
C29: =(C28>=C27)+0 -> 1 | D29: =(D28>=D27)+0 -> 1 | E29: =(E28>=E27)+0 -> 1 | F29: =(F28>=F27)+0 -> 1 | G29: =(G28>=G27)+0 -> 1 | H29: =(H28>=H27)+0 -> 1 | I29: =(I28>=I27)+0 -> 1 | J29: =(J28>=J27)+0 -> 1 | ... N29: =(N28>=N27)+0 -> 1
C31: =AND(C25=1,C29=1)+0 -> 1 | D31: =AND(D25=1,D29=1)+0 -> 1 | E31: =AND(E25=1,E29=1)+0 -> 1 | F31: =AND(F25=1,F29=1)+0 -> 1 | G31: =AND(G25=1,G29=1)+0 -> 1 | H31: =AND(H25=1,H29=1)+0 -> 1 | I31: =AND(I25=1,I29=1)+0 -> 1 | J31: =AND(J25=1,J29=1)+0 -> 1 | ... N31: =AND(N25=1,N29=1)+0 -> 1
C33: =A2&"|"&C20&D20&E20&F20&G20&H20&I20&J20&K20&L20&M20&N20 -> HG2|B91-3471;D01-3531;921-3F61;AC1-45E1;B41-4041;5F1-60E1;CB1-1ACB1;3F1-46A1;B91-46A1;221-40E1;AC1-2921;F01-ABE1
