Workbook

Sheet XL-Test
B1: Hard Level (⭐⭐⭐)
B2: KODE SOAL | C2: SBEH009 | E2: KODE JAWABAN | F2: =DF!D37 -> HI4|2A-2446F;23-3A303;22-A8A6231
B5: No | C5: Data | E5: Blok Rumah 1 | F5: Harga 2 | G5: Urutan Pengantaran 3
B6: 1 | C6: Lisa membeli sabun mandi di toko Sejahtera kemarin. | E6: {=INDEX($38:$38, SUMPRODUCT(($B$39:$U$51=LEFT(C6,FIND(" ",C6&" ")-1))*COLUMN($B$39:$U$51)))} -> Blok A | F6: {=INDEX($D$26:$H$35,MATCH(1,ISNUMBER(SEARCH($C$26:$C$35,C6))*1,0),MATCH(1,COUNTIF(C6,"*"&$D$25:$H$25&"*"),0))} -> 10500 | G6: {=SUMPRODUCT(($E$6:$E$20<E6)*1)+COUNTIF($E$6:$E6,E6)} -> 1 | I6: Soal
B7: 2 | C7: Rudi memesan pasta gigi di toko Mulia pagi ini. | E7: {=INDEX($38:$38, SUMPRODUCT(($B$39:$U$51=LEFT(C7,FIND(" ",C7&" ")-1))*COLUMN($B$39:$U$51)))} -> Blok B | F7: {=INDEX($D$26:$H$35,MATCH(1,ISNUMBER(SEARCH($C$26:$C$35,C7))*1,0),MATCH(1,COUNTIF(C7,"*"&$D$25:$H$25&"*"),0))} -> 12500 | G7: {=SUMPRODUCT(($E$6:$E$20<E7)*1)+COUNTIF($E$6:$E7,E7)} -> 3 | H7: 1 | I7: Isi kolom Blok rumah sesuai dengan nama yang ada pada Data berdasarkan Data Blok Rumah
B8: 3 | C8: Tina membeli kopi di toko Harmoni kemarin. | E8: {=INDEX($38:$38, SUMPRODUCT(($B$39:$U$51=LEFT(C8,FIND(" ",C8&" ")-1))*COLUMN($B$39:$U$51)))} -> Blok A | F8: {=INDEX($D$26:$H$35,MATCH(1,ISNUMBER(SEARCH($C$26:$C$35,C8))*1,0),MATCH(1,COUNTIF(C8,"*"&$D$25:$H$25&"*"),0))} -> 15100 | G8: {=SUMPRODUCT(($E$6:$E$20<E8)*1)+COUNTIF($E$6:$E8,E8)} -> 2 | I8: Contoh : Lisa membeli sabun mandi di toko Sejahtera kemarin. | K8: Blok A
B9: 4 | C9: Budi membeli roti dari toko Lestari tadi pagi. | E9: {=INDEX($38:$38, SUMPRODUCT(($B$39:$U$51=LEFT(C9,FIND(" ",C9&" ")-1))*COLUMN($B$39:$U$51)))} -> Blok E | F9: {=INDEX($D$26:$H$35,MATCH(1,ISNUMBER(SEARCH($C$26:$C$35,C9))*1,0),MATCH(1,COUNTIF(C9,"*"&$D$25:$H$25&"*"),0))} -> 7300 | G9: {=SUMPRODUCT(($E$6:$E$20<E9)*1)+COUNTIF($E$6:$E9,E9)} -> 10 | H9: 2 | I9: Isi kolom Harga sesuai dengan Table Data Produk dan Harga berdasarkan keterangan Data
B10: 5 | C10: Andi membeli minyak goreng di toko Anugrah siang tadi. | E10: {=INDEX($38:$38, SUMPRODUCT(($B$39:$U$51=LEFT(C10,FIND(" ",C10&" ")-1))*COLUMN($B$39:$U$51)))} -> Blok B | F10: {=INDEX($D$26:$H$35,MATCH(1,ISNUMBER(SEARCH($C$26:$C$35,C10))*1,0),MATCH(1,COUNTIF(C10,"*"&$D$25:$H$25&"*"),0))} -> 20000 | G10: {=SUMPRODUCT(($E$6:$E$20<E10)*1)+COUNTIF($E$6:$E10,E10)} -> 4 | I10: Contoh : Lisa membeli sabun mandi di toko Sejahtera kemarin. | K10: 10500
B11: 6 | C11: Sari beli kopi di toko Lestari kemarin. | E11: {=INDEX($38:$38, SUMPRODUCT(($B$39:$U$51=LEFT(C11,FIND(" ",C11&" ")-1))*COLUMN($B$39:$U$51)))} -> Blok E | F11: {=INDEX($D$26:$H$35,MATCH(1,ISNUMBER(SEARCH($C$26:$C$35,C11))*1,0),MATCH(1,COUNTIF(C11,"*"&$D$25:$H$25&"*"),0))} -> 15300 | G11: {=SUMPRODUCT(($E$6:$E$20<E11)*1)+COUNTIF($E$6:$E11,E11)} -> 11 | H11: 3 | I11: Isi Kolom Urutan Pengantaran Berdasarkan Blok Rumah
B12: 7 | C12: Dedi memesan hand sanitizer di toko Harmoni pagi ini. | E12: {=INDEX($38:$38, SUMPRODUCT(($B$39:$U$51=LEFT(C12,FIND(" ",C12&" ")-1))*COLUMN($B$39:$U$51)))} -> Blok B | F12: {=INDEX($D$26:$H$35,MATCH(1,ISNUMBER(SEARCH($C$26:$C$35,C12))*1,0),MATCH(1,COUNTIF(C12,"*"&$D$25:$H$25&"*"),0))} -> 30200 | G12: {=SUMPRODUCT(($E$6:$E$20<E12)*1)+COUNTIF($E$6:$E12,E12)} -> 5 | I12: Contoh : Lisa berada di Blok A, sehingga urutan pengantarannya 1, | K12: 1
B13: 8 | C13: Maya membeli sabun mandi di toko Lestari sore tadi. | E13: {=INDEX($38:$38, SUMPRODUCT(($B$39:$U$51=LEFT(C13,FIND(" ",C13&" ")-1))*COLUMN($B$39:$U$51)))} -> Blok G | F13: {=INDEX($D$26:$H$35,MATCH(1,ISNUMBER(SEARCH($C$26:$C$35,C13))*1,0),MATCH(1,COUNTIF(C13,"*"&$D$25:$H$25&"*"),0))} -> 10300 | G13: {=SUMPRODUCT(($E$6:$E$20<E13)*1)+COUNTIF($E$6:$E13,E13)} -> 13 | I13: dilanjutkan ke Tina 2 (karena tina di blok A), setelah itu ke Rudi 3 (Blok B) | K13: 3
B14: 9 | C14: Hendra belanja deterjen di toko Mulia kemarin. | E14: {=INDEX($38:$38, SUMPRODUCT(($B$39:$U$51=LEFT(C14,FIND(" ",C14&" ")-1))*COLUMN($B$39:$U$51)))} -> Blok F | F14: {=INDEX($D$26:$H$35,MATCH(1,ISNUMBER(SEARCH($C$26:$C$35,C14))*1,0),MATCH(1,COUNTIF(C14,"*"&$D$25:$H$25&"*"),0))} -> 21800 | G14: {=SUMPRODUCT(($E$6:$E$20<E14)*1)+COUNTIF($E$6:$E14,E14)} -> 12 | I14: dan selanjutnya Andi 4 (blok B) | K14: 2
B15: 10 | C15: Rina membeli kopi ke toko Sejahtera pagi tadi. | E15: {=INDEX($38:$38, SUMPRODUCT(($B$39:$U$51=LEFT(C15,FIND(" ",C15&" ")-1))*COLUMN($B$39:$U$51)))} -> Blok C | F15: {=INDEX($D$26:$H$35,MATCH(1,ISNUMBER(SEARCH($C$26:$C$35,C15))*1,0),MATCH(1,COUNTIF(C15,"*"&$D$25:$H$25&"*"),0))} -> 15200 | G15: {=SUMPRODUCT(($E$6:$E$20<E15)*1)+COUNTIF($E$6:$E15,E15)} -> 6
B16: 11 | C16: Fajar belanja teh di toko Harmoni sore kemarin. | E16: {=INDEX($38:$38, SUMPRODUCT(($B$39:$U$51=LEFT(C16,FIND(" ",C16&" ")-1))*COLUMN($B$39:$U$51)))} -> Blok J | F16: {=INDEX($D$26:$H$35,MATCH(1,ISNUMBER(SEARCH($C$26:$C$35,C16))*1,0),MATCH(1,COUNTIF(C16,"*"&$D$25:$H$25&"*"),0))} -> 8600 | G16: {=SUMPRODUCT(($E$6:$E$20<E16)*1)+COUNTIF($E$6:$E16,E16)} -> 15 | I16: * Selesaikan Pertanyaan diatas dengan menggunakan Formula/Rumus Excel
B17: 12 | C17: Nia membeli roti di toko Mulia pagi ini. | E17: {=INDEX($38:$38, SUMPRODUCT(($B$39:$U$51=LEFT(C17,FIND(" ",C17&" ")-1))*COLUMN($B$39:$U$51)))} -> Blok C | F17: {=INDEX($D$26:$H$35,MATCH(1,ISNUMBER(SEARCH($C$26:$C$35,C17))*1,0),MATCH(1,COUNTIF(C17,"*"&$D$25:$H$25&"*"),0))} -> 6800 | G17: {=SUMPRODUCT(($E$6:$E$20<E17)*1)+COUNTIF($E$6:$E17,E17)} -> 7 | I17: Selsaikan tanpa menambahkan atau menggunakan kolom bantuan atau Table bantu.
B18: 13 | C18: Arif membeli sampo di toko Lestari tadi siang. | E18: {=INDEX($38:$38, SUMPRODUCT(($B$39:$U$51=LEFT(C18,FIND(" ",C18&" ")-1))*COLUMN($B$39:$U$51)))} -> Blok C | F18: {=INDEX($D$26:$H$35,MATCH(1,ISNUMBER(SEARCH($C$26:$C$35,C18))*1,0),MATCH(1,COUNTIF(C18,"*"&$D$25:$H$25&"*"),0))} -> 26200 | G18: {=SUMPRODUCT(($E$6:$E$20<E18)*1)+COUNTIF($E$6:$E18,E18)} -> 8
B19: 14 | C19: Vina membeli susu dari toko Anugrah kemarin sore. | E19: {=INDEX($38:$38, SUMPRODUCT(($B$39:$U$51=LEFT(C19,FIND(" ",C19&" ")-1))*COLUMN($B$39:$U$51)))} -> Blok I | F19: {=INDEX($D$26:$H$35,MATCH(1,ISNUMBER(SEARCH($C$26:$C$35,C19))*1,0),MATCH(1,COUNTIF(C19,"*"&$D$25:$H$25&"*"),0))} -> 18000 | G19: {=SUMPRODUCT(($E$6:$E$20<E19)*1)+COUNTIF($E$6:$E19,E19)} -> 14 | I19: Sudah selesai mengerjakan?
B20: 15 | C20: Ilham ambil minyak goreng di toko Lestari hari ini. | E20: {=INDEX($38:$38, SUMPRODUCT(($B$39:$U$51=LEFT(C20,FIND(" ",C20&" ")-1))*COLUMN($B$39:$U$51)))} -> Blok D | F20: {=INDEX($D$26:$H$35,MATCH(1,ISNUMBER(SEARCH($C$26:$C$35,C20))*1,0),MATCH(1,COUNTIF(C20,"*"&$D$25:$H$25&"*"),0))} -> 20100 | G20: {=SUMPRODUCT(($E$6:$E$20<E20)*1)+COUNTIF($E$6:$E20,E20)} -> 9 | I20: Kirimkan Kode Soal dan Kode Jawaban ke alamat : https://belajarexcel.id/xl-test/jawaban untuk mengecek hasil benar/salah
B24: DATA Produk dan Harga
B25: No | C25: Produk | D25: Toko Anugrah | E25: Toko Sejahtera | F25: Toko Mulia | G25: Toko Harmoni | H25: Toko Lestari
B26: 1 | C26: Sampo | D26: 25000 | E26: 26000 | F26: 24500 | G26: 25500 | H26: 26200
B27: 2 | C27: Sabun Mandi | D27: 10000 | E27: 10500 | F27: 9800 | G27: 10200 | H27: 10300
B28: 3 | C28: Pasta Gigi | D28: 12000 | E28: 11800 | F28: 12500 | G28: 12200 | H28: 12300
B29: 4 | C29: Minyak Goreng | D29: 20000 | E29: 19800 | F29: 20500 | G29: 20200 | H29: 20100
B30: 5 | C30: Kopi | D30: 15000 | E30: 15200 | F30: 14800 | G30: 15100 | H30: 15300
B31: 6 | C31: Teh | D31: 8500 | E31: 8700 | F31: 8300 | G31: 8600 | H31: 8800
B32: 7 | C32: Roti | D32: 7000 | E32: 7200 | F32: 6800 | G32: 7100 | H32: 7300
B33: 8 | C33: Susu | D33: 18000 | E33: 17800 | F33: 18500 | G33: 18200 | H33: 18300
B34: 9 | C34: Deterjen | D34: 22000 | E34: 22500 | F34: 21800 | G34: 22200 | H34: 22300
B35: 10 | C35: Hand Sanitizer | D35: 30000 | E35: 29800 | F35: 30500 | G35: 30200 | H35: 30100
B37: DATA Blok Rumah
B38: Blok A | D38: Blok B | F38: Blok C | H38: Blok D | J38: Blok E | L38: Blok F | N38: Blok G | P38: Blok H | R38: Blok I | T38: Blok J
B39: Lisa | C39: No.101 | D39: Andi | E39: No.115 | F39: Rina | G39: No.201 | H39: Surya | I39: No.165 | J39: Sinta | K39: No. 145 | L39: Dewi | M39: No. 155 | N39: Rangga | O39: No. 176 | P39: Melly | Q39: No. 186 | R39: Kevin | S39: No.211 | T39: Riko | U39: No.235
B40: Elsa | C40: No.102 | D40: Rudi | E40: No.116 | F40: Bella | G40: No.202 | H40: Ilham | I40: No.166 | J40: Lala | K40: No. 146 | L40: Aldi | M40: No. 156 | N40: Citra | O40: No. 177 | P40: Yoga | Q40: No. 187 | R40: Risa | S40: No.212 | T40: Fajar | U40: No.236
B41: Tina | C41: No.103 | D41: Dedi | E41: No.117 | F41: Nia | G41: No.203 | H41: Andik | I41: No.167 | J41: Galih | K41: No. 147 | L41: Wulan | M41: No. 157 | N41: Maya | O41: No. 178 | P41: Farah | Q41: No. 188 | R41: Dimas | S41: No.213 | T41: Felicia | U41: No.237
B42: Dino | C42: No.104 | D42: Bagus | E42: No.118 | F42: Arif | G42: No.204 | H42: Ronald | I42: No.168 | J42: Putri | K42: No. 148 | L42: Ferry | M42: No. 158 | N42: Intan | O42: No. 179 | P42: Tony | Q42: No. 189 | R42: Ayla | S42: No.214 | T42: Iqbal | U42: No.238
B43: Nurul | C43: No.105 | D43: Sheila | E43: No.119 | F43: Silvia | G43: No.205 | H43: Tania | I43: No.169 | J43: Budi | K43: No. 149 | L43: Wawan | M43: No. 159 | N43: Fathan | O43: No. 180 | P43: Yesi | Q43: No. 190 | R43: Meylina | S43: No.215 | T43: Ratna | U43: No.239
B44: Samuel | C44: No.106 | D44: Aditya | E44: No.120 | F44: Joko | G44: No.206 | H44: Yudi | I44: No.170 | J44: Sari | K44: No. 150 | L44: Laras | M44: No. 160 | N44: Yuni | O44: No. 181 | P44: Umar | Q44: No. 191 | R44: Vina | S44: No.216
B45: Karina | C45: No.107 | D45: Clara | E45: No.121 | F45: Nadia | G45: No.207 | H45: Salma | I45: No.171 | J45: Tristan | K45: No. 151 | L45: Hendra | M45: No. 161 | N45: Billy | O45: No. 182 | P45: Desi | Q45: No. 192 | R45: Oskar | S45: No.217
B46: Rizky | C46: No.108 | D46: Dion | E46: No.122 | F46: Hafiz | G46: No.208 | H46: Fikri | I46: No.172 | J46: Zahra | K46: No. 152 | L46: Aulia | M46: No. 162 | N46: Livia | O46: No. 183 | P46: Ranggi | Q46: No. 193 | R46: Hanum | S46: No.218
...

Sheet About
C6: XL-TEST adalah platform inovatif yang menyediakan latihan Excel interaktif dengan pemeriksaan otomatis,
C7: sehingga pengguna dapat langsung mengetahui jawaban yang benar maupun salah.
C10: Terdapat 5 Level soal :
D12: Easy Level | F12: (⭐)
D13: Medium Level | F13: (⭐⭐)
D14: Hard Level | F14: (⭐⭐⭐)
D15: Extreme Level | F15: (⭐⭐⭐⭐)
D16: Championship Level | F16: (⭐⭐⭐⭐⭐)
C19: Free Access
C20: https://belajarexcel.id/xl-test/

Sheet DF
A1: DEF | D1: 1 | E1: 2 | F1: 3 | H1: Formula Cek
A2: HI4 | C2: 1 | D2: ='XL-Test'!E6 -> Blok A | E2: ='XL-Test'!F6 -> 10500 | F2: ='XL-Test'!G6 -> 1 | H2: =IFERROR(LEN(_xlfn.FORMULATEXT('XL-Test'!E6)),0) -> 90 | I2: =IFERROR(LEN(_xlfn.FORMULATEXT('XL-Test'!F6)),0) -> 108 | J2: =IFERROR(LEN(_xlfn.FORMULATEXT('XL-Test'!G6)),0) -> 51 | N2: =SUBSTITUTE(_xlfn.FORMULATEXT('XL-Test'!E6),"$","") -> =INDEX(38:38; SUMPRODUCT((B39:U51=LEFT(C6;FIND(" ";C6&" ")-1))*COLUMN(B39:U51))) | O2: =SUBSTITUTE(_xlfn.FORMULATEXT('XL-Test'!F6),"$","") -> =INDEX(D26:H35;MATCH(1;ISNUMBER(SEARCH(C26:C35;C6))*1;0);MATCH(1;COUNTIF(C6;"*"&D25:H25&"*");0)) | P2: =SUBSTITUTE(_xlfn.FORMULATEXT('XL-Test'!G6),"$","") -> =SUMPRODUCT((E6:E20<E6)*1)+COUNTIF(E6:E6;E6)
C3: 2 | D3: ='XL-Test'!E7 -> Blok B | E3: ='XL-Test'!F7 -> 12500 | F3: ='XL-Test'!G7 -> 3 | H3: =IFERROR(LEN(_xlfn.FORMULATEXT('XL-Test'!E7)),0) -> 90 | I3: =IFERROR(LEN(_xlfn.FORMULATEXT('XL-Test'!F7)),0) -> 108 | J3: =IFERROR(LEN(_xlfn.FORMULATEXT('XL-Test'!G7)),0) -> 51 | N3: =O2 -> =INDEX(D26:H35;MATCH(1;ISNUMBER(SEARCH(C26:C35;C6))*1;0);MATCH(1;COUNTIF(C6;"*"&D25:H25&"*");0))
C4: 3 | D4: ='XL-Test'!E8 -> Blok A | E4: ='XL-Test'!F8 -> 15100 | F4: ='XL-Test'!G8 -> 2 | H4: =IFERROR(LEN(_xlfn.FORMULATEXT('XL-Test'!E8)),0) -> 90 | I4: =IFERROR(LEN(_xlfn.FORMULATEXT('XL-Test'!F8)),0) -> 108 | J4: =IFERROR(LEN(_xlfn.FORMULATEXT('XL-Test'!G8)),0) -> 51 | N4: =P2 -> =SUMPRODUCT((E6:E20<E6)*1)+COUNTIF(E6:E6;E6)
C5: 4 | D5: ='XL-Test'!E9 -> Blok E | E5: ='XL-Test'!F9 -> 7300 | F5: ='XL-Test'!G9 -> 10 | H5: =IFERROR(LEN(_xlfn.FORMULATEXT('XL-Test'!E9)),0) -> 90 | I5: =IFERROR(LEN(_xlfn.FORMULATEXT('XL-Test'!F9)),0) -> 108 | J5: =IFERROR(LEN(_xlfn.FORMULATEXT('XL-Test'!G9)),0) -> 51
C6: 5 | D6: ='XL-Test'!E10 -> Blok B | E6: ='XL-Test'!F10 -> 20000 | F6: ='XL-Test'!G10 -> 4 | H6: =IFERROR(LEN(_xlfn.FORMULATEXT('XL-Test'!E10)),0) -> 92 | I6: =IFERROR(LEN(_xlfn.FORMULATEXT('XL-Test'!F10)),0) -> 110 | J6: =IFERROR(LEN(_xlfn.FORMULATEXT('XL-Test'!G10)),0) -> 54
C7: 6 | D7: ='XL-Test'!E11 -> Blok E | E7: ='XL-Test'!F11 -> 15300 | F7: ='XL-Test'!G11 -> 11 | H7: =IFERROR(LEN(_xlfn.FORMULATEXT('XL-Test'!E11)),0) -> 92 | I7: =IFERROR(LEN(_xlfn.FORMULATEXT('XL-Test'!F11)),0) -> 110 | J7: =IFERROR(LEN(_xlfn.FORMULATEXT('XL-Test'!G11)),0) -> 54
C8: 7 | D8: ='XL-Test'!E12 -> Blok B | E8: ='XL-Test'!F12 -> 30200 | F8: ='XL-Test'!G12 -> 5 | H8: =IFERROR(LEN(_xlfn.FORMULATEXT('XL-Test'!E12)),0) -> 92 | I8: =IFERROR(LEN(_xlfn.FORMULATEXT('XL-Test'!F12)),0) -> 110 | J8: =IFERROR(LEN(_xlfn.FORMULATEXT('XL-Test'!G12)),0) -> 54
C9: 8 | D9: ='XL-Test'!E13 -> Blok G | E9: ='XL-Test'!F13 -> 10300 | F9: ='XL-Test'!G13 -> 13 | H9: =IFERROR(LEN(_xlfn.FORMULATEXT('XL-Test'!E13)),0) -> 92 | I9: =IFERROR(LEN(_xlfn.FORMULATEXT('XL-Test'!F13)),0) -> 110 | J9: =IFERROR(LEN(_xlfn.FORMULATEXT('XL-Test'!G13)),0) -> 54
C10: 9 | D10: ='XL-Test'!E14 -> Blok F | E10: ='XL-Test'!F14 -> 21800 | F10: ='XL-Test'!G14 -> 12 | H10: =IFERROR(LEN(_xlfn.FORMULATEXT('XL-Test'!E14)),0) -> 92 | I10: =IFERROR(LEN(_xlfn.FORMULATEXT('XL-Test'!F14)),0) -> 110 | J10: =IFERROR(LEN(_xlfn.FORMULATEXT('XL-Test'!G14)),0) -> 54
C11: 10 | D11: ='XL-Test'!E15 -> Blok C | E11: ='XL-Test'!F15 -> 15200 | F11: ='XL-Test'!G15 -> 6 | H11: =IFERROR(LEN(_xlfn.FORMULATEXT('XL-Test'!E15)),0) -> 92 | I11: =IFERROR(LEN(_xlfn.FORMULATEXT('XL-Test'!F15)),0) -> 110 | J11: =IFERROR(LEN(_xlfn.FORMULATEXT('XL-Test'!G15)),0) -> 54
C12: 11 | D12: ='XL-Test'!E16 -> Blok J | E12: ='XL-Test'!F16 -> 8600 | F12: ='XL-Test'!G16 -> 15 | H12: =IFERROR(LEN(_xlfn.FORMULATEXT('XL-Test'!E16)),0) -> 92 | I12: =IFERROR(LEN(_xlfn.FORMULATEXT('XL-Test'!F16)),0) -> 110 | J12: =IFERROR(LEN(_xlfn.FORMULATEXT('XL-Test'!G16)),0) -> 54
C13: 12 | D13: ='XL-Test'!E17 -> Blok C | E13: ='XL-Test'!F17 -> 6800 | F13: ='XL-Test'!G17 -> 7 | H13: =IFERROR(LEN(_xlfn.FORMULATEXT('XL-Test'!E17)),0) -> 92 | I13: =IFERROR(LEN(_xlfn.FORMULATEXT('XL-Test'!F17)),0) -> 110 | J13: =IFERROR(LEN(_xlfn.FORMULATEXT('XL-Test'!G17)),0) -> 54
C14: 13 | D14: ='XL-Test'!E18 -> Blok C | E14: ='XL-Test'!F18 -> 26200 | F14: ='XL-Test'!G18 -> 8 | H14: =IFERROR(LEN(_xlfn.FORMULATEXT('XL-Test'!E18)),0) -> 92 | I14: =IFERROR(LEN(_xlfn.FORMULATEXT('XL-Test'!F18)),0) -> 110 | J14: =IFERROR(LEN(_xlfn.FORMULATEXT('XL-Test'!G18)),0) -> 54
C15: 14 | D15: ='XL-Test'!E19 -> Blok I | E15: ='XL-Test'!F19 -> 18000 | F15: ='XL-Test'!G19 -> 14 | H15: =IFERROR(LEN(_xlfn.FORMULATEXT('XL-Test'!E19)),0) -> 92 | I15: =IFERROR(LEN(_xlfn.FORMULATEXT('XL-Test'!F19)),0) -> 110 | J15: =IFERROR(LEN(_xlfn.FORMULATEXT('XL-Test'!G19)),0) -> 54
C16: 15 | D16: ='XL-Test'!E20 -> Blok D | E16: ='XL-Test'!F20 -> 20100 | F16: ='XL-Test'!G20 -> 9 | H16: =IFERROR(LEN(_xlfn.FORMULATEXT('XL-Test'!E20)),0) -> 92 | I16: =IFERROR(LEN(_xlfn.FORMULATEXT('XL-Test'!F20)),0) -> 110 | J16: =IFERROR(LEN(_xlfn.FORMULATEXT('XL-Test'!G20)),0) -> 54
H18: =AVERAGE(H6:H16)=H6 -> TRUE | I18: =AVERAGE(I6:I16)=I6 -> TRUE | J18: =AVERAGE(J6:J16)=J6 -> TRUE
C19: V | D19: =CODE(RIGHT(D2))+CODE(RIGHT(D3))+CODE(RIGHT(D4))+CODE(RIGHT(D5))+CODE(RIGHT(D6))+CODE(RIGHT(D7))+CODE(RIGHT(D8))+CODE(RIGHT(D9))+CODE(RIGHT(D10))+CODE(RIGHT(D11))+CODE(RIGHT(D12))+CODE(RIGHT(D13))+CODE(RIGHT(D14))+CODE(RIGHT(D15))+CODE(RIGHT(D16))+147568 -> 148591 | E19: =SUM(E2:E16)+LEFT(E2,2)+LEFT(E3,2)+LEFT(E4,2)+LEFT(E5,2)+LEFT(E6,2)+LEFT(E7,2)+LEFT(E8,2)+LEFT(E9,2)+LEFT(E10,2)+LEFT(E11,2)+LEFT(E12,2)+LEFT(E13,2)+LEFT(E14,2)+LEFT(E15,2)+LEFT(E16,2) -> 238339 | F19: =VALUE(F2&F3&F4&F5&F6)+VALUE(F7&F8&F9&F5&F10)+VALUE(F11&F12&F13&F14&F15&F16) -> 176841265 | H19: =AVERAGE(H2:H5)=H2 -> TRUE | I19: =AVERAGE(I2:I5)=I2 -> TRUE | J19: =AVERAGE(J2:J5)=J2 -> TRUE
C20: V2 | D20: =IFERROR(DEC2HEX(IF(H24,D19,D21)),"EEEE") -> 2446F | E20: =IFERROR(DEC2HEX(IF(I24,E19,E21)),"EEEE") -> 3A303 | F20: =IFERROR(DEC2HEX(IF(J24,F19,F21)),"EEEE") -> A8A6231 | H20: =IFERROR(AND(H19,H18),FALSE) -> TRUE | I20: =IFERROR(AND(I19,I18),FALSE) -> TRUE | J20: =IFERROR(AND(J19,J18),FALSE) -> TRUE
C21: Random | D21: 158414 | E21: 124510 | F21: 484511250
G22: Manual | H22: =AND(ISNUMBER(FIND("=",N2)),ISNUMBER(FIND("(",N2)),ISNUMBER(FIND("C6",N2))) -> TRUE | I22: =AND(ISNUMBER(FIND("=",O2)),ISNUMBER(FIND("(",O2)),ISNUMBER(FIND("C6",O2))) -> TRUE | J22: =AND(ISNUMBER(FIND("=",P2)),ISNUMBER(FIND("(",P2)),ISNUMBER(FIND("E6",P2))) -> TRUE
C23: TRUE | D23: =DEC2HEX(HEX2DEC(LEFT(DEC2HEX(D21),2))+COLUMN()) -> 2A | E23: =DEC2HEX(HEX2DEC(LEFT(DEC2HEX(E21),2))+COLUMN()) -> 23 | F23: =DEC2HEX(HEX2DEC(LEFT(DEC2HEX(F21),2))+COLUMN()) -> 22
C24: FALSE | D24: =DEC2HEX(HEX2DEC(RIGHT(DEC2HEX(D21),2))+COLUMN()) -> D2 | E24: =DEC2HEX(HEX2DEC(RIGHT(DEC2HEX(E21),2))+COLUMN()) -> 63 | F24: =DEC2HEX(HEX2DEC(RIGHT(DEC2HEX(F21),2))+COLUMN()) -> 18 | G24: ** | H24: =AND(H22,OR(H20,H26),NOT(OR(D2=0,D2=""))) -> TRUE | I24: =AND(I22,OR(I20,I26),NOT(OR(E2=0,E2=""))) -> TRUE | J24: =AND(J22,OR(J20,J26),NOT(OR(F2=0,F2=""))) -> TRUE
C26: Banyak | D26: =IFERROR(LEN(N2)-LEN(SUBSTITUTE(N2,"(","")),99) -> 6 | E26: =IFERROR(LEN(O2)-LEN(SUBSTITUTE(O2,"(","")),99) -> 6 | F26: =IFERROR(LEN(P2)-LEN(SUBSTITUTE(P2,"(","")),99) -> 3 | H26: =AND(H2>0,H4=0,D4>0) -> FALSE | I26: =AND(I2>0,I4=0,E4>0) -> FALSE | J26: =AND(J2>0,J4=0,F4>0) -> FALSE
D27: 7 | E27: 6 | F27: 3
D28: =(D26<=D27) -> TRUE | E28: =(E26<=E27) -> TRUE | F28: =(F26<=F27) -> TRUE
C30: Formula | D30: =OR(AND(ISNUMBER(FIND("INDEX",N2)),OR(ISNUMBER(FIND("SUM",N2)),ISNUMBER(FIND("MATC",N2))),OR(ISNUMBER(FIND("FIND",N2)),ISNUMBER(FIND("SEAR",N2)))),AND(OR(ISNUMBER(FIND("IF",N2)),ISNUMBER(FIND("FILT",N2))),OR(ISNUMBER(FIND("TOCO",N2)),ISNUMBER(FIND("TRAN",N2))))) -> TRUE | E30: =OR(AND(ISNUMBER(FIND("INDEX",O2)),ISNUMBER(FIND("MATCH",O2))),AND(ISNUMBER(FIND("REG",N2)),OR(ISNUMBER(FIND("TOCO",N2)),ISNUMBER(FIND("TRAN",N2))))) -> TRUE | F30: =OR(AND(ISNUMBER(FIND("SUM",P2)),ISNUMBER(FIND("COUNT",P2))),AND(ISNUMBER(FIND("MATC",P2)),ISNUMBER(FIND("SORT",P2)))) -> TRUE
C32: ** | D32: =AND(D30,D28) -> TRUE | E32: =AND(E30,E28) -> TRUE | F32: =AND(F30,F28) -> TRUE
D34: =IF(D32,D23,D24) -> 2A | E34: =IF(E32,E23,E24) -> 23 | F34: =IF(F32,F23,F24) -> 22
D36: =D34&"-"&D20&";" -> 2A-2446F; | E36: =E34&"-"&E20&";" -> 23-3A303; | F36: =F34&"-"&F20 -> 22-A8A6231
D37: =A2&"|"&D36&E36&F36 -> HI4|2A-2446F;23-3A303;22-A8A6231
