Workbook
Name kode_jawaban: DF!$C$31

Sheet XL-TEST
B1: Hard Level (⭐⭐⭐)
B2: KODE SOAL | D2: SBEH003 | E2: KODE JAWABAN | F2: =kode_jawaban -> HC1|181-2C01;251-FA2C71;111-3341;161-2DA1;551-2B5C1;EA1-FA001
D4: 1 | E4: 2 | F4: 3 | G4: 4 | H4: 5 | L4: 6
B5: NO | C5: NIK | D5: Jenis Kelamin | E5: Tanggal Lahir | F5: Usia (Tahun) | G5: NIK Ganda | H5: Jumlah Bayar | J5: NO | K5: NIK | L5: Total Bayar
B6: 1 | C6: 3273011201980001 | D6: =IF(MID(C6,7,2)*1<40,"Laki-Laki","Perempuan") -> Laki-Laki | E6: =DATE(IF(MID(C6,11,2)*1>25,1900,2000)+MID(C6,11,2)*1,MID(C6,9,2),MOD(MID(C6,7,2),40)) -> 35807 | F6: =DATEDIF(E6,"20-05-2025","Y") -> 27 | G6: {=IF(SUMPRODUCT(($C$6:$C$25=C6)*1)>1,"Ganda","Tidak")} -> Tidak | H6: =IF(D6="Laki-Laki",40000,35000) -> 40000 | J6: 1 | K6: 3273041606890001 | L6: {=SUMPRODUCT(($C$6:$C$25=K6)*$H$6:$H$25)} -> 40000
B7: 2 | C7: 3273011201980008 | D7: =IF(MID(C7,7,2)*1<40,"Laki-Laki","Perempuan") -> Laki-Laki | E7: =DATE(IF(MID(C7,11,2)*1>25,1900,2000)+MID(C7,11,2)*1,MID(C7,9,2),MOD(MID(C7,7,2),40)) -> 35807 | F7: =DATEDIF(E7,"20-05-2025","Y") -> 27 | G7: {=IF(SUMPRODUCT(($C$6:$C$25=C7)*1)>1,"Ganda","Tidak")} -> Tidak | H7: =IF(D7="Laki-Laki",40000,35000) -> 40000 | J7: 2 | K7: 3273052302030001 | L7: {=SUMPRODUCT(($C$6:$C$25=K7)*$H$6:$H$25)} -> 40000
B8: 3 | C8: 3273024503990001 | D8: =IF(MID(C8,7,2)*1<40,"Laki-Laki","Perempuan") -> Perempuan | E8: =DATE(IF(MID(C8,11,2)*1>25,1900,2000)+MID(C8,11,2)*1,MID(C8,9,2),MOD(MID(C8,7,2),40)) -> 36224 | F8: =DATEDIF(E8,"20-05-2025","Y") -> 26 | G8: {=IF(SUMPRODUCT(($C$6:$C$25=C8)*1)>1,"Ganda","Tidak")} -> Tidak | H8: =IF(D8="Laki-Laki",40000,35000) -> 35000 | J8: 3 | K8: 3273100412770001 | L8: {=SUMPRODUCT(($C$6:$C$25=K8)*$H$6:$H$25)} -> 0
B9: 4 | C9: 3273100412770007 | D9: =IF(MID(C9,7,2)*1<40,"Laki-Laki","Perempuan") -> Laki-Laki | E9: =DATE(IF(MID(C9,11,2)*1>25,1900,2000)+MID(C9,11,2)*1,MID(C9,9,2),MOD(MID(C9,7,2),40)) -> 28463 | F9: =DATEDIF(E9,"20-05-2025","Y") -> 47 | G9: {=IF(SUMPRODUCT(($C$6:$C$25=C9)*1)>1,"Ganda","Tidak")} -> Ganda | H9: =IF(D9="Laki-Laki",40000,35000) -> 40000 | J9: 4 | K9: 3273131404940001 | L9: {=SUMPRODUCT(($C$6:$C$25=K9)*$H$6:$H$25)} -> 120000
B10: 5 | C10: 3273036807010001 | D10: =IF(MID(C10,7,2)*1<40,"Laki-Laki","Perempuan") -> Perempuan | E10: =DATE(IF(MID(C10,11,2)*1>25,1900,2000)+MID(C10,11,2)*1,MID(C10,9,2),MOD(MID(C10,7,2),40)) -> 37100 | F10: =DATEDIF(E10,"20-05-2025","Y") -> 23 | G10: {=IF(SUMPRODUCT(($C$6:$C$25=C10)*1)>1,"Ganda","Tidak")} -> Tidak | H10: =IF(D10="Laki-Laki",40000,35000) -> 35000
B11: 6 | C11: 3273041606890001 | D11: =IF(MID(C11,7,2)*1<40,"Laki-Laki","Perempuan") -> Laki-Laki | E11: =DATE(IF(MID(C11,11,2)*1>25,1900,2000)+MID(C11,11,2)*1,MID(C11,9,2),MOD(MID(C11,7,2),40)) -> 32675 | F11: =DATEDIF(E11,"20-05-2025","Y") -> 35 | G11: {=IF(SUMPRODUCT(($C$6:$C$25=C11)*1)>1,"Ganda","Tidak")} -> Tidak | H11: =IF(D11="Laki-Laki",40000,35000) -> 40000
B12: 7 | C12: 3273052302030001 | D12: =IF(MID(C12,7,2)*1<40,"Laki-Laki","Perempuan") -> Laki-Laki | E12: =DATE(IF(MID(C12,11,2)*1>25,1900,2000)+MID(C12,11,2)*1,MID(C12,9,2),MOD(MID(C12,7,2),40)) -> 37675 | F12: =DATEDIF(E12,"20-05-2025","Y") -> 22 | G12: {=IF(SUMPRODUCT(($C$6:$C$25=C12)*1)>1,"Ganda","Tidak")} -> Tidak | H12: =IF(D12="Laki-Laki",40000,35000) -> 40000
B13: 8 | C13: 3273020503990002 | D13: =IF(MID(C13,7,2)*1<40,"Laki-Laki","Perempuan") -> Laki-Laki | E13: =DATE(IF(MID(C13,11,2)*1>25,1900,2000)+MID(C13,11,2)*1,MID(C13,9,2),MOD(MID(C13,7,2),40)) -> 36224 | F13: =DATEDIF(E13,"20-05-2025","Y") -> 26 | G13: {=IF(SUMPRODUCT(($C$6:$C$25=C13)*1)>1,"Ganda","Tidak")} -> Tidak | H13: =IF(D13="Laki-Laki",40000,35000) -> 40000
B14: 9 | C14: 3273052302030003 | D14: =IF(MID(C14,7,2)*1<40,"Laki-Laki","Perempuan") -> Laki-Laki | E14: =DATE(IF(MID(C14,11,2)*1>25,1900,2000)+MID(C14,11,2)*1,MID(C14,9,2),MOD(MID(C14,7,2),40)) -> 37675 | F14: =DATEDIF(E14,"20-05-2025","Y") -> 22 | G14: {=IF(SUMPRODUCT(($C$6:$C$25=C14)*1)>1,"Ganda","Tidak")} -> Tidak | H14: =IF(D14="Laki-Laki",40000,35000) -> 40000
B15: 10 | C15: 3273131404940001 | D15: =IF(MID(C15,7,2)*1<40,"Laki-Laki","Perempuan") -> Laki-Laki | E15: =DATE(IF(MID(C15,11,2)*1>25,1900,2000)+MID(C15,11,2)*1,MID(C15,9,2),MOD(MID(C15,7,2),40)) -> 34438 | F15: =DATEDIF(E15,"20-05-2025","Y") -> 31 | G15: {=IF(SUMPRODUCT(($C$6:$C$25=C15)*1)>1,"Ganda","Tidak")} -> Ganda | H15: =IF(D15="Laki-Laki",40000,35000) -> 40000
B16: 11 | C16: 3273075103050001 | D16: =IF(MID(C16,7,2)*1<40,"Laki-Laki","Perempuan") -> Perempuan | E16: =DATE(IF(MID(C16,11,2)*1>25,1900,2000)+MID(C16,11,2)*1,MID(C16,9,2),MOD(MID(C16,7,2),40)) -> 38422 | F16: =DATEDIF(E16,"20-05-2025","Y") -> 20 | G16: {=IF(SUMPRODUCT(($C$6:$C$25=C16)*1)>1,"Ganda","Tidak")} -> Tidak | H16: =IF(D16="Laki-Laki",40000,35000) -> 35000
B17: 12 | C17: 3273081205000001 | D17: =IF(MID(C17,7,2)*1<40,"Laki-Laki","Perempuan") -> Laki-Laki | E17: =DATE(IF(MID(C17,11,2)*1>25,1900,2000)+MID(C17,11,2)*1,MID(C17,9,2),MOD(MID(C17,7,2),40)) -> 36658 | F17: =DATEDIF(E17,"20-05-2025","Y") -> 25 | G17: {=IF(SUMPRODUCT(($C$6:$C$25=C17)*1)>1,"Ganda","Tidak")} -> Tidak | H17: =IF(D17="Laki-Laki",40000,35000) -> 40000
B18: 13 | C18: 3273092709990001 | D18: =IF(MID(C18,7,2)*1<40,"Laki-Laki","Perempuan") -> Laki-Laki | E18: =DATE(IF(MID(C18,11,2)*1>25,1900,2000)+MID(C18,11,2)*1,MID(C18,9,2),MOD(MID(C18,7,2),40)) -> 36430 | F18: =DATEDIF(E18,"20-05-2025","Y") -> 25 | G18: {=IF(SUMPRODUCT(($C$6:$C$25=C18)*1)>1,"Ganda","Tidak")} -> Tidak | H18: =IF(D18="Laki-Laki",40000,35000) -> 40000
B19: 14 | C19: 3273100412770007 | D19: =IF(MID(C19,7,2)*1<40,"Laki-Laki","Perempuan") -> Laki-Laki | E19: =DATE(IF(MID(C19,11,2)*1>25,1900,2000)+MID(C19,11,2)*1,MID(C19,9,2),MOD(MID(C19,7,2),40)) -> 28463 | F19: =DATEDIF(E19,"20-05-2025","Y") -> 47 | G19: {=IF(SUMPRODUCT(($C$6:$C$25=C19)*1)>1,"Ganda","Tidak")} -> Ganda | H19: =IF(D19="Laki-Laki",40000,35000) -> 40000
B20: 15 | C20: 3273131404940001 | D20: =IF(MID(C20,7,2)*1<40,"Laki-Laki","Perempuan") -> Laki-Laki | E20: =DATE(IF(MID(C20,11,2)*1>25,1900,2000)+MID(C20,11,2)*1,MID(C20,9,2),MOD(MID(C20,7,2),40)) -> 34438 | F20: =DATEDIF(E20,"20-05-2025","Y") -> 31 | G20: {=IF(SUMPRODUCT(($C$6:$C$25=C20)*1)>1,"Ganda","Tidak")} -> Ganda | H20: =IF(D20="Laki-Laki",40000,35000) -> 40000
B21: 16 | C21: 3273104412770003 | D21: =IF(MID(C21,7,2)*1<40,"Laki-Laki","Perempuan") -> Perempuan | E21: =DATE(IF(MID(C21,11,2)*1>25,1900,2000)+MID(C21,11,2)*1,MID(C21,9,2),MOD(MID(C21,7,2),40)) -> 28463 | F21: =DATEDIF(E21,"20-05-2025","Y") -> 47 | G21: {=IF(SUMPRODUCT(($C$6:$C$25=C21)*1)>1,"Ganda","Tidak")} -> Tidak | H21: =IF(D21="Laki-Laki",40000,35000) -> 35000
... B25: 20 | C25: 3273145910010001 | D25: =IF(MID(C25,7,2)*1<40,"Laki-Laki","Perempuan") -> Perempuan | E25: =DATE(IF(MID(C25,11,2)*1>25,1900,2000)+MID(C25,11,2)*1,MID(C25,9,2),MOD(MID(C25,7,2),40)) -> 37183 | F25: =DATEDIF(E25,"20-05-2025","Y") -> 23 | G25: {=IF(SUMPRODUCT(($C$6:$C$25=C25)*1)>1,"Ganda","Tidak")} -> Tidak | H25: =IF(D25="Laki-Laki",40000,35000) -> 35000
D29: Soal
C30: 1 | D30: Jenis Kelamin | H30: Format NIK (16 digit):
D31: Tentukan jenis kelamin berdasarkan NIK sesuai dengan ketentuan format NIK yang berlaku. | H31: AABBCCDDMMYYXXXX
C33: 2 | D33: Tanggal Lahir | H33: AABB: Kode provinsi dan kabupaten/kota
D34: Isi tanggal lahir berdasarkan informasi yang terkandung dalam NIK sesuai ketentuan standar penulisan NIK. | H34: CC: Kode kecamatan
H35: DDMMYY: Tanggal lahir (untuk perempuan, tanggal + 40)
C36: 3 | D36: Usia Saat Ini | H36: Tahun lahir diatas 25 adalah 19YY dibawah 25 adalah 20YY
D37: Hitung usia berdasarkan tanggal lahir yang diperoleh dari NIK, dengan acuan tanggal saat ini yaitu 20 Mei 2025. | H37: XXXX: Nomor urut registrasi
C39: 4 | D39: Status Duplikasi NIK
D40: Periksa keberadaan duplikat NIK dalam dataset:
D41: Isi kolom dengan "Ganda" jika ditemukan lebih dari satu entri dengan NIK yang sama.
D42: Isi dengan "Tidak" jika NIK bersifat unik (tidak duplikat).
C44: 5 | D44: Jumlah Pembayaran
D45: Tentukan jumlah pembayaran berdasarkan jenis kelamin:
D46: Laki-laki: Rp40.000
D47: Perempuan: Rp35.000
C49: 6 | D49: Total Bayar (Kolom L)
D50: Hitung total pembayaran berdasarkan NIK pada kolom K, berdasarkan data yang telah diolah pada poin sebelumnya.
D53: Sudah selesai mengerjakan?
...

Sheet DF
A1: DF | C1: 1 | D1: 2 | E1: 3 | F1: 4 | G1: 5 | H1: 6 | S1: 1 | T1: 2 | U1: 3 | V1: 4 | W1: 5 | X1: 6
A2: HC1 | C2: ='XL-TEST'!D6 -> Laki-Laki | D2: ='XL-TEST'!E6 -> 35807 | E2: ='XL-TEST'!F6 -> 27 | F2: ='XL-TEST'!G6 -> Tidak | G2: ='XL-TEST'!H6 -> 40000 | H2: ='XL-TEST'!L6 -> 40000 | R2: 1 | S2: =_xlfn.FORMULATEXT('XL-TEST'!D6) -> =IF(MID(C6;7;2)*1<40;"Laki-Laki";"Perempuan") | T2: =_xlfn.FORMULATEXT('XL-TEST'!E6) -> =DATE(IF(MID(C6;11;2)*1>25;1900;2000)+MID(C6;11;2)*1;MID(C6;9;2);MOD(MID(C6;7;2);40)) | U2: =_xlfn.FORMULATEXT('XL-TEST'!F6) -> =DATEDIF(E6;"20-05-2025";"Y") | V2: =_xlfn.FORMULATEXT('XL-TEST'!G6) -> =IF(SUMPRODUCT(($C$6:$C$25=C6)*1)>1;"Ganda";"Tidak") | W2: =_xlfn.FORMULATEXT('XL-TEST'!H6) -> =IF(D6="Laki-Laki";40000;35000) | X2: =_xlfn.FORMULATEXT('XL-TEST'!L6) -> =SUMPRODUCT(($C$6:$C$25=K6)*$H$6:$H$25)
C3: ='XL-TEST'!D8 -> Perempuan | D3: ='XL-TEST'!E8 -> 36224 | E3: ='XL-TEST'!F8 -> 26 | F3: ='XL-TEST'!G8 -> Tidak | G3: ='XL-TEST'!H8 -> 35000 | H3: ='XL-TEST'!L7 -> 40000 | R3: 2 | S3: =_xlfn.FORMULATEXT('XL-TEST'!E6) -> =DATE(IF(MID(C6;11;2)*1>25;1900;2000)+MID(C6;11;2)*1;MID(C6;9;2);MOD(MID(C6;7;2);40))
C4: ='XL-TEST'!D10 -> Perempuan | D4: ='XL-TEST'!E10 -> 37100 | E4: ='XL-TEST'!F10 -> 23 | F4: ='XL-TEST'!G10 -> Tidak | G4: ='XL-TEST'!H10 -> 35000 | H4: ='XL-TEST'!L8 -> 0 | R4: 3 | S4: =_xlfn.FORMULATEXT('XL-TEST'!F6) -> =DATEDIF(E6;"20-05-2025";"Y")
C5: ='XL-TEST'!D14 -> Laki-Laki | D5: ='XL-TEST'!E14 -> 37675 | E5: ='XL-TEST'!F14 -> 22 | F5: ='XL-TEST'!G14 -> Tidak | G5: ='XL-TEST'!H14 -> 40000 | H5: ='XL-TEST'!L9 -> 120000 | R5: 4 | S5: =_xlfn.FORMULATEXT('XL-TEST'!G6) -> =IF(SUMPRODUCT(($C$6:$C$25=C6)*1)>1;"Ganda";"Tidak")
C6: ='XL-TEST'!D16 -> Perempuan | D6: ='XL-TEST'!E16 -> 38422 | E6: ='XL-TEST'!F16 -> 20 | F6: ='XL-TEST'!G16 -> Tidak | G6: ='XL-TEST'!H16 -> 35000 | H6: ='XL-TEST'!L10 -> 0 | R6: 5 | S6: =_xlfn.FORMULATEXT('XL-TEST'!H6) -> =IF(D6="Laki-Laki";40000;35000)
C7: ='XL-TEST'!D20 -> Laki-Laki | D7: ='XL-TEST'!E20 -> 34438 | E7: ='XL-TEST'!F20 -> 31 | F7: ='XL-TEST'!G20 -> Ganda | G7: ='XL-TEST'!H20 -> 40000 | R7: 6 | S7: =_xlfn.FORMULATEXT('XL-TEST'!L6) -> =SUMPRODUCT(($C$6:$C$25=K6)*$H$6:$H$25)
C8: ='XL-TEST'!D21 -> Perempuan | D8: ='XL-TEST'!E21 -> 28463 | E8: ='XL-TEST'!F21 -> 47 | F8: ='XL-TEST'!G21 -> Tidak | G8: ='XL-TEST'!H21 -> 35000
C9: ='XL-TEST'!D24 -> Laki-Laki | D9: ='XL-TEST'!E24 -> 34438 | E9: ='XL-TEST'!F24 -> 31 | F9: ='XL-TEST'!G24 -> Ganda | G9: ='XL-TEST'!H24 -> 40000
C10: ='XL-TEST'!D25 -> Perempuan | D10: ='XL-TEST'!E25 -> 37183 | E10: ='XL-TEST'!F25 -> 23 | F10: ='XL-TEST'!G25 -> Tidak | G10: ='XL-TEST'!H25 -> 35000
D11: =SUM('XL-TEST'!E6:E25) -> 704961 | E11: =SUM('XL-TEST'!F6:F25) -> 570 | G11: =SUM('XL-TEST'!H6:H25) -> 775000 | H11: =SUM(H2:H6) -> 200000
C12: =CODE(LEFT(UPPER(C2)))+CODE(LEFT(UPPER(C3)))+CODE(LEFT(UPPER(C4)))+CODE(LEFT(UPPER(C5)))+CODE(LEFT(UPPER(C6)))+CODE(LEFT(UPPER(C7)))+CODE(LEFT(UPPER(C8)))+CODE(LEFT(UPPER(C9)))+CODE(LEFT(UPPER(C10))) -> 704 | D12: =SUM(D2:D11) -> 1024711 | E12: =SUM(E2:E11) -> 820 | F12: =CODE(LEFT(UPPER(F2)))+CODE(LEFT(UPPER(F3)))+CODE(LEFT(UPPER(F4)))+CODE(LEFT(UPPER(F5)))+CODE(LEFT(UPPER(F6)))+CODE(LEFT(UPPER(F7)))+CODE(LEFT(UPPER(F8)))+CODE(LEFT(UPPER(F9)))+CODE(LEFT(UPPER(F10))) -> 730 | G12: =SUM(G2:G11)/100 -> 11100 | H12: =SUM(H2:H11)/100 -> 4000
B13: Value | C13: =DEC2HEX(IF(OR(C2=0,C2=""),C15,C12)) -> 2C0 | D13: =DEC2HEX(IF(OR(D2=0,D2=""),D15,D12)) -> FA2C7 | E13: =DEC2HEX(IF(OR(E2=0,E2=""),E15,E12)) -> 334 | F13: =DEC2HEX(IF(OR(F2=0,F2=""),F15,F12)) -> 2DA | G13: =DEC2HEX(IF(OR(G2=0,G2=""),G15,G12)) -> 2B5C | H13: =DEC2HEX(IF(OR(H2=0,H2=""),H15,H12))&LEFT(H4) -> FA00
C14: =IFERROR(C13,"EEEE")&C19 -> 2C01 | D14: =IFERROR(D13,"EEEE")&D19 -> FA2C71 | E14: =IFERROR(E13,"EEEE")&E19 -> 3341 | F14: =IFERROR(F13,"EEEE")&F19 -> 2DA1 | G14: =IFERROR(G13,"EEEE")&G19 -> 2B5C1 | H14: =IFERROR(H13,"EEEE")&H19 -> FA001
B15: Random | C15: 6175 | D15: 9711 | E15: 4484 | F15: 5868 | G15: 1362 | H15: 3750
B17: TRUE | C17: =LEFT(DEC2HEX(C15),2) -> 18 | D17: =LEFT(DEC2HEX(D15),2) -> 25 | E17: =LEFT(DEC2HEX(E15),2) -> 11 | F17: =LEFT(DEC2HEX(F15),2) -> 16 | G17: =LEFT(DEC2HEX(G15),2) -> 55 | H17: =LEFT(DEC2HEX(H15),2) -> EA
B18: FALSE | C18: =RIGHT(DEC2HEX(C15),2) -> 1F | D18: =RIGHT(DEC2HEX(D15),2) -> EF | E18: =RIGHT(DEC2HEX(E15),2) -> 84 | F18: =RIGHT(DEC2HEX(F15),2) -> EC | G18: =RIGHT(DEC2HEX(G15),2) -> 52 | H18: =RIGHT(DEC2HEX(H15),2) -> A6
B19: Cek Manual | C19: =AND(ISNUMBER(FIND("=",S2)),ISNUMBER(FIND("(",S2)))+0 -> 1 | D19: =AND(ISNUMBER(FIND("=",T2)),ISNUMBER(FIND("(",T2)))+0 -> 1 | E19: =AND(ISNUMBER(FIND("=",U2)),ISNUMBER(FIND("(",U2)))+0 -> 1 | F19: =AND(ISNUMBER(FIND("=",V2)),ISNUMBER(FIND("(",V2)))+0 -> 1 | G19: =AND(ISNUMBER(FIND("=",W2)),ISNUMBER(FIND("(",W2)))+0 -> 1 | H19: =AND(ISNUMBER(FIND("=",X2)),ISNUMBER(FIND("(",X2)))+0 -> 1
B21: Cek Formula | C21: =AND(ISNUMBER(FIND("IF",S2)),ISNUMBER(FIND("MI",S2))) -> TRUE | D21: =AND(ISNUMBER(FIND("ATE",T2)),ISNUMBER(FIND("MI",T2))) -> TRUE | E21: =AND(ISNUMBER(FIND("ATED",U2)),ISNUMBER(FIND("Y",U2))) -> TRUE | F21: =AND(ISNUMBER(FIND("IF",V2)),OR(ISNUMBER(FIND("SUM(",V2)),ISNUMBER(FIND("MPRO",V2)),ISNUMBER(FIND("OUNTI",V2)))) -> TRUE | G21: =AND(ISNUMBER(FIND("IF",W2))) -> TRUE | H21: =OR(ISNUMBER(FIND("SUM(",X2)),ISNUMBER(FIND("MPRO",X2)),ISNUMBER(FIND("MIF",X2))) -> TRUE
B23: Cek Jumlah | C23: =IFERROR(LEN(S2)-LEN(SUBSTITUTE(S2,"(","")),99) -> 2 | D23: =IFERROR(LEN(T2)-LEN(SUBSTITUTE(T2,"(","")),99) -> 7 | E23: =IFERROR(LEN(U2)-LEN(SUBSTITUTE(U2,"(","")),99) -> 1 | F23: =IFERROR(LEN(V2)-LEN(SUBSTITUTE(V2,"(","")),99) -> 3 | G23: =IFERROR(LEN(W2)-LEN(SUBSTITUTE(W2,"(","")),99) -> 1 | H23: =IFERROR(LEN(X2)-LEN(SUBSTITUTE(X2,"(","")),99) -> 2
B24: Asli | C24: 3 | D24: 8 | E24: 2 | F24: 3 | G24: 1 | H24: 2
B25: Logika | C25: =(C23<=C24)+0 -> 1 | D25: =(D23<=D24)+0 -> 1 | E25: =(E23<=E24)+0 -> 1 | F25: =(F23<=F24)+0 -> 1 | G25: =(G23<=G24)+0 -> 1 | H25: =(H23<=H24)+0 -> 1
B27: Value | C27: =IF(C21,C17,C18)&C25 -> 181 | D27: =IF(D21,D17,D18)&D25 -> 251 | E27: =IF(E21,E17,E18)&E25 -> 111 | F27: =IF(F21,F17,F18)&F25 -> 161 | G27: =IF(G21,G17,G18)&G25 -> 551 | H27: =IF(H21,H17,H18)&H25 -> EA1
B29: Gabung | C29: =C27&"-"&C14&";" -> 181-2C01; | D29: =D27&"-"&D14&";" -> 251-FA2C71; | E29: =E27&"-"&E14&";" -> 111-3341; | F29: =F27&"-"&F14&";" -> 161-2DA1; | G29: =G27&"-"&G14&";" -> 551-2B5C1; | H29: =H27&"-"&H14 -> EA1-FA001
C31: =A2&"|"&C29&D29&E29&F29&G29&H29 -> HC1|181-2C01;251-FA2C71;111-3341;161-2DA1;551-2B5C1;EA1-FA001
