Workbook
Name kode_jawaban: DF!$C$38

Sheet XL-Test
C1: Hard Level (⭐⭐⭐)
C2: KODE SOAL | D2: SBEH008 | E2: KODE JAWABAN | G2: =kode_jawaban -> HH1|54-13BC47;D5-6AC8;F9-28EC;12-13A605;98-13BA8B;C9-13A4BC;E4-13BBD7;97-13AE8A;3B-13BA2E;5A-D04D
B5: Rekapitulasi Data dan Tanggal Proyek
G7: 1 | H7: 2 | I7: 3 | J7: 4 | K7: 5 | L7: 6 | M7: 7 | N7: 8 | O7: 9 | P7: 10
B8: NO | C8: ID PROYEK | D8: NAMA PROYEK | E8: TANGGAL MULAI PROYEK | F8: DURASI PROYEK (Hari Kerja) | G8: TANGGAL SELESAI PROYEK | H8: JUMLAH GAJI (Gaji Setiap Tanggal 1) | I8: JML Ibadah Jum'at | J8: Tanggal Gaji Pertama | K8: Tanggal Gaji Terkahir | L8: Tanggal Ibadah Jum'at Pertama | M8: Tanggal Ibadah Jum'at Terakhir | N8: TANGGAL REVIEW PROYEK (3 Bulan Setelah Mulai) | O8: TANGGAL REVIEW PROYEK 2 (6 Bulan di akhir bulan) | P8: JML KUNJUNGAN BOS (Tanggal Genap)
B9: 1 | C9: ID-PM-001 | D9: Proyek Peningkatan Infrastruktur Nasional | E9: 45664 | F9: 153 | G9: =WORKDAY.INTL(E9,F9,7) -> 45879 | H9: {=SUMPRODUCT(--(DAY(ROW(INDIRECT(E9&":"&G9)))=1))} -> 7 | I9: =NETWORKDAYS.INTL(E9,G9,"1111011") -> 31 | J9: =EOMONTH(E9,IF(DAY(E9)=1,-1,0))+1 -> 45689 | K9: =EOMONTH(G9,-1)+1 -> 45870 | L9: =WORKDAY.INTL(E9 -1,1,"1111011") -> 45667 | M9: =WORKDAY.INTL(G9+1,-1,"1111011") -> 45877 | N9: =EDATE(E9,3) -> 45754 | O9: =EOMONTH(E9,6) -> 45869 | P9: {=SUM(--(ISEVEN(DAY(E9+_xlfn.SEQUENCE(G9-E9+1,1,0)))*(WEEKDAY(E9+_xlfn.SEQUENCE(G9-E9+1,1,0))<6)))} -> 76
B10: 2 | C10: ID-CE-002 | D10: Proyek Digitalisasi Layanan Publik | E10: 45870 | F10: 102 | G10: =WORKDAY.INTL(E10,F10,7) -> 46013 | H10: {=SUMPRODUCT(--(DAY(ROW(INDIRECT(E10&":"&G10)))=1))} -> 5 | I10: =NETWORKDAYS.INTL(E10,G10,"1111011") -> 21 | J10: =EOMONTH(E10,IF(DAY(E10)=1,-1,0))+1 -> 45870 | K10: =EOMONTH(G10,-1)+1 -> 45992 | L10: =WORKDAY.INTL(E10 -1,1,"1111011") -> 45870 | M10: =WORKDAY.INTL(G10+1,-1,"1111011") -> 46010 | N10: =EDATE(E10,3) -> 45962 | O10: =EOMONTH(E10,6) -> 46081 | P10: {=SUM(--(ISEVEN(DAY(E10+_xlfn.SEQUENCE(G10-E10+1,1,0)))*(WEEKDAY(E10+_xlfn.SEQUENCE(G10-E10+1,1,0))<6)))} -> 51
B11: 3 | C11: ID-QS-003 | D11: Proyek Energi Bersih Berkelanjutan | E11: 46365 | F11: 222 | G11: =WORKDAY.INTL(E11,F11,7) -> 46677 | H11: {=SUMPRODUCT(--(DAY(ROW(INDIRECT(E11&":"&G11)))=1))} -> 10 | I11: =NETWORKDAYS.INTL(E11,G11,"1111011") -> 45 | J11: =EOMONTH(E11,IF(DAY(E11)=1,-1,0))+1 -> 46388 | K11: =EOMONTH(G11,-1)+1 -> 46661 | L11: =WORKDAY.INTL(E11 -1,1,"1111011") -> 46367 | M11: =WORKDAY.INTL(G11+1,-1,"1111011") -> 46675 | N11: =EDATE(E11,3) -> 46455 | O11: =EOMONTH(E11,6) -> 46568 | P11: {=SUM(--(ISEVEN(DAY(E11+_xlfn.SEQUENCE(G11-E11+1,1,0)))*(WEEKDAY(E11+_xlfn.SEQUENCE(G11-E11+1,1,0))<6)))} -> 108
B12: 4 | C12: ID-CE-004 | D12: Proyek Reformasi Birokrasi Terpadu | E12: 45709 | F12: 111 | G12: =WORKDAY.INTL(E12,F12,7) -> 45865 | H12: {=SUMPRODUCT(--(DAY(ROW(INDIRECT(E12&":"&G12)))=1))} -> 5 | I12: =NETWORKDAYS.INTL(E12,G12,"1111011") -> 23 | J12: =EOMONTH(E12,IF(DAY(E12)=1,-1,0))+1 -> 45717 | K12: =EOMONTH(G12,-1)+1 -> 45839 | L12: =WORKDAY.INTL(E12 -1,1,"1111011") -> 45709 | M12: =WORKDAY.INTL(G12+1,-1,"1111011") -> 45863 | N12: =EDATE(E12,3) -> 45798 | O12: =EOMONTH(E12,6) -> 45900 | P12: {=SUM(--(ISEVEN(DAY(E12+_xlfn.SEQUENCE(G12-E12+1,1,0)))*(WEEKDAY(E12+_xlfn.SEQUENCE(G12-E12+1,1,0))<6)))} -> 54
B13: 5 | C13: ID-CE-005 | D13: Proyek Penguatan Ekonomi Daerah | E13: 46013 | F13: 202 | G13: =WORKDAY.INTL(E13,F13,7) -> 46295 | H13: {=SUMPRODUCT(--(DAY(ROW(INDIRECT(E13&":"&G13)))=1))} -> 9 | I13: =NETWORKDAYS.INTL(E13,G13,"1111011") -> 40 | J13: =EOMONTH(E13,IF(DAY(E13)=1,-1,0))+1 -> 46023 | K13: =EOMONTH(G13,-1)+1 -> 46266 | L13: =WORKDAY.INTL(E13 -1,1,"1111011") -> 46017 | M13: =WORKDAY.INTL(G13+1,-1,"1111011") -> 46290 | N13: =EDATE(E13,3) -> 46103 | O13: =EOMONTH(E13,6) -> 46203 | P13: {=SUM(--(ISEVEN(DAY(E13+_xlfn.SEQUENCE(G13-E13+1,1,0)))*(WEEKDAY(E13+_xlfn.SEQUENCE(G13-E13+1,1,0))<6)))} -> 100
B14: 6 | C14: ID-QS-006 | D14: Proyek Modernisasi Transportasi Umum | E14: 45863 | F14: 85 | G14: =WORKDAY.INTL(E14,F14,7) -> 45981 | H14: {=SUMPRODUCT(--(DAY(ROW(INDIRECT(E14&":"&G14)))=1))} -> 4 | I14: =NETWORKDAYS.INTL(E14,G14,"1111011") -> 17 | J14: =EOMONTH(E14,IF(DAY(E14)=1,-1,0))+1 -> 45870 | K14: =EOMONTH(G14,-1)+1 -> 45962 | L14: =WORKDAY.INTL(E14 -1,1,"1111011") -> 45863 | M14: =WORKDAY.INTL(G14+1,-1,"1111011") -> 45975 | N14: =EDATE(E14,3) -> 45955 | O14: =EOMONTH(E14,6) -> 46053 | P14: {=SUM(--(ISEVEN(DAY(E14+_xlfn.SEQUENCE(G14-E14+1,1,0)))*(WEEKDAY(E14+_xlfn.SEQUENCE(G14-E14+1,1,0))<6)))} -> 42
B15: 7 | C15: ID-PM-007 | D15: Proyek Ketahanan Pangan Nasional | E15: 46080 | F15: 153 | G15: =WORKDAY.INTL(E15,F15,7) -> 46294 | H15: {=SUMPRODUCT(--(DAY(ROW(INDIRECT(E15&":"&G15)))=1))} -> 7 | I15: =NETWORKDAYS.INTL(E15,G15,"1111011") -> 31 | J15: =EOMONTH(E15,IF(DAY(E15)=1,-1,0))+1 -> 46082 | K15: =EOMONTH(G15,-1)+1 -> 46266 | L15: =WORKDAY.INTL(E15 -1,1,"1111011") -> 46080 | M15: =WORKDAY.INTL(G15+1,-1,"1111011") -> 46290 | N15: =EDATE(E15,3) -> 46169 | O15: =EOMONTH(E15,6) -> 46265 | P15: {=SUM(--(ISEVEN(DAY(E15+_xlfn.SEQUENCE(G15-E15+1,1,0)))*(WEEKDAY(E15+_xlfn.SEQUENCE(G15-E15+1,1,0))<6)))} -> 75
B16: 8 | C16: ID-QS-008 | D16: Proyek Pembangunan Kawasan Terpadu | E16: 46097 | F16: 212 | G16: =WORKDAY.INTL(E16,F16,7) -> 46393 | H16: {=SUMPRODUCT(--(DAY(ROW(INDIRECT(E16&":"&G16)))=1))} -> 10 | I16: =NETWORKDAYS.INTL(E16,G16,"1111011") -> 42 | J16: =EOMONTH(E16,IF(DAY(E16)=1,-1,0))+1 -> 46113 | K16: =EOMONTH(G16,-1)+1 -> 46388 | L16: =WORKDAY.INTL(E16 -1,1,"1111011") -> 46101 | M16: =WORKDAY.INTL(G16+1,-1,"1111011") -> 46388 | N16: =EDATE(E16,3) -> 46189 | O16: =EOMONTH(E16,6) -> 46295 | P16: {=SUM(--(ISEVEN(DAY(E16+_xlfn.SEQUENCE(G16-E16+1,1,0)))*(WEEKDAY(E16+_xlfn.SEQUENCE(G16-E16+1,1,0))<6)))} -> 105
B17: 9 | C17: ID-PM-009 | D17: Proyek Revitalisasi Pendidikan Dasar | E17: 45805 | F17: 119 | G17: =WORKDAY.INTL(E17,F17,7) -> 45972 | H17: {=SUMPRODUCT(--(DAY(ROW(INDIRECT(E17&":"&G17)))=1))} -> 6 | I17: =NETWORKDAYS.INTL(E17,G17,"1111011") -> 24 | J17: =EOMONTH(E17,IF(DAY(E17)=1,-1,0))+1 -> 45809 | K17: =EOMONTH(G17,-1)+1 -> 45962 | L17: =WORKDAY.INTL(E17 -1,1,"1111011") -> 45807 | M17: =WORKDAY.INTL(G17+1,-1,"1111011") -> 45968 | N17: =EDATE(E17,3) -> 45897 | O17: =EOMONTH(E17,6) -> 45991 | P17: {=SUM(--(ISEVEN(DAY(E17+_xlfn.SEQUENCE(G17-E17+1,1,0)))*(WEEKDAY(E17+_xlfn.SEQUENCE(G17-E17+1,1,0))<6)))} -> 59
B18: 10 | C18: ID-PM-010 | D18: Proyek Akselerasi Kesehatan Masyarakat | E18: 46296 | F18: 256 | G18: =WORKDAY.INTL(E18,F18,7) -> 46656 | H18: {=SUMPRODUCT(--(DAY(ROW(INDIRECT(E18&":"&G18)))=1))} -> 12 | I18: =NETWORKDAYS.INTL(E18,G18,"1111011") -> 52 | J18: =EOMONTH(E18,IF(DAY(E18)=1,-1,0))+1 -> 46296 | K18: =EOMONTH(G18,-1)+1 -> 46631 | L18: =WORKDAY.INTL(E18 -1,1,"1111011") -> 46297 | M18: =WORKDAY.INTL(G18+1,-1,"1111011") -> 46654 | N18: =EDATE(E18,3) -> 46388 | O18: =EOMONTH(E18,6) -> 46507 | P18: {=SUM(--(ISEVEN(DAY(E18+_xlfn.SEQUENCE(G18-E18+1,1,0)))*(WEEKDAY(E18+_xlfn.SEQUENCE(G18-E18+1,1,0))<6)))} -> 125
B19: 11 | C19: ID-CE-011 | D19: Proyek Pengelolaan Sumber Daya Alam Lestari | E19: 45876 | F19: 155 | G19: =WORKDAY.INTL(E19,F19,7) -> 46093 | H19: {=SUMPRODUCT(--(DAY(ROW(INDIRECT(E19&":"&G19)))=1))} -> 7 | I19: =NETWORKDAYS.INTL(E19,G19,"1111011") -> 31 | J19: =EOMONTH(E19,IF(DAY(E19)=1,-1,0))+1 -> 45901 | K19: =EOMONTH(G19,-1)+1 -> 46082 | L19: =WORKDAY.INTL(E19 -1,1,"1111011") -> 45877 | M19: =WORKDAY.INTL(G19+1,-1,"1111011") -> 46087 | N19: =EDATE(E19,3) -> 45968 | O19: =EOMONTH(E19,6) -> 46081 | P19: {=SUM(--(ISEVEN(DAY(E19+_xlfn.SEQUENCE(G19-E19+1,1,0)))*(WEEKDAY(E19+_xlfn.SEQUENCE(G19-E19+1,1,0))<6)))} -> 77
B20: 12 | C20: ID-PM-012 | D20: Proyek Sistem Informasi Terintegrasi | E20: 46371 | F20: 246 | G20: =WORKDAY.INTL(E20,F20,7) -> 46715 | H20: {=SUMPRODUCT(--(DAY(ROW(INDIRECT(E20&":"&G20)))=1))} -> 11 | I20: =NETWORKDAYS.INTL(E20,G20,"1111011") -> 49 | J20: =EOMONTH(E20,IF(DAY(E20)=1,-1,0))+1 -> 46388 | K20: =EOMONTH(G20,-1)+1 -> 46692 | L20: =WORKDAY.INTL(E20 -1,1,"1111011") -> 46374 | M20: =WORKDAY.INTL(G20+1,-1,"1111011") -> 46710 | N20: =EDATE(E20,3) -> 46461 | O20: =EOMONTH(E20,6) -> 46568 | P20: {=SUM(--(ISEVEN(DAY(E20+_xlfn.SEQUENCE(G20-E20+1,1,0)))*(WEEKDAY(E20+_xlfn.SEQUENCE(G20-E20+1,1,0))<6)))} -> 120
... B28: 20 | C28: ID-CE-020 | D28: Proyek Peningkatan Kapasitas SDM Nasional | E28: 45737 | F28: 84 | G28: =WORKDAY.INTL(E28,F28,7) -> 45854 | H28: {=SUMPRODUCT(--(DAY(ROW(INDIRECT(E28&":"&G28)))=1))} -> 4 | I28: =NETWORKDAYS.INTL(E28,G28,"1111011") -> 17 | J28: =EOMONTH(E28,IF(DAY(E28)=1,-1,0))+1 -> 45748 | K28: =EOMONTH(G28,-1)+1 -> 45839 | L28: =WORKDAY.INTL(E28 -1,1,"1111011") -> 45737 | M28: =WORKDAY.INTL(G28+1,-1,"1111011") -> 45849 | N28: =EDATE(E28,3) -> 45829 | O28: =EOMONTH(E28,6) -> 45930 | P28: {=SUM(--(ISEVEN(DAY(E28+_xlfn.SEQUENCE(G28-E28+1,1,0)))*(WEEKDAY(E28+_xlfn.SEQUENCE(G28-E28+1,1,0))<6)))} -> 41
B30: Kirimkan Kode Jawaban diatas ke alamat : https://belajarexcel.id/xl-test/ untuk mengecek hasil jawaban
C32: Soal
B33: 1 | C33: Isi Kolom TANGGAL SELESAI PROYEK mengacu data dari kolom TANGGAL MULAI PROYEK dijumlahkan dengan kolom ESTIMASI DURASI PROYEK (Hari Kerja)
C34: Hari kerja Minggu-Kamis, Hari Jum'at dan Sabtu Libur | L34: Copyright © 2025 | BelajarExcel.id
B35: 2 | C35: Isi kolom JML Gaji dengan ketentuan : Gaji diberikan disetiap tanggal 1 setiap bulannya, Berapakali Gaji yang terima selama Proyek tersebut berlangsung
B36: 3 | C36: Isi kolom JML Ibadah Jum'at dengan ketentuan : Berapakali Ibadah sholat jum'at selama Proyek tersebut berlangsung
B37: 4 | C37: Kapan Tanggal Gaji pertama diterima pada proyek tersebut
B38: 5 | C38: Kapan Tanggal Gaji terakhir diterima pada proyek tersebut
B39: 6 | C39: Kapan Tanggal ibadah jum'at pertama dilaksanakan pada proyek tersebut
B40: 7 | C40: Kapan Tanggal ibadah jum'at terkahir dilaksanakan pada proyek tersebut
B41: 8 | C41: TANGGAL REVIEW PROYEK dilaksanakan tepat 3 bulan setelah TANGGAL MULAI PROYEK
C42: Contoh : Tanggal Mulai Proyek 12 Juli 2025 maka Review Proyek di tanggal 12 Oktober 2025
B43: 9 | C43: TANGGAL REVIEW PROYEK 2 dilaksanakan pada bulan ke 6 di akhir bulan setelah TANGGAL MULAI PROYEK
C44: Contoh : Tanggal Mulai Proyek 12 Juli 2025 maka Review Proyek di tanggal 31 Januari 2026
B45: 10 | C45: Bos memiliki Plat Nomor mobil genap, jadi Bos akan mengunjungi Proyek setiap tanggal genap pada hari kerja,
C46: Isi Kolom JML KUNJUNGAN BOS dengan berapa kali tanggal genap selama proyek berlangsung
C48: * Selesaikan Pertanyaan diatas dengan menggunakan Formula/Rumus Excel
C49: Selsaikan tanpa menambahkan atau menggunakan kolom bantuan atau Table bantu.
C51: Sudah selesai mengerjakan?
C52: Kirimkan Kode Soal dan Kode Jawaban ke alamat : https://belajarexcel.id/xl-test/jawaban untuk mengecek hasil benar/salah

Sheet About
C6: XL-TEST adalah platform inovatif yang menyediakan latihan Excel interaktif dengan pemeriksaan otomatis,
C7: sehingga pengguna dapat langsung mengetahui jawaban yang benar maupun salah.
C10: Terdapat 5 Level soal :
D12: Easy Level | F12: (⭐)
D13: Medium Level | F13: (⭐⭐)
D14: Hard Level | F14: (⭐⭐⭐)
D15: Extreme Level | F15: (⭐⭐⭐⭐)
D16: Championship Level | F16: (⭐⭐⭐⭐⭐)
C19: Free Access
C20: https://belajarexcel.id/xl-test/

Sheet DF
A1: DEF | C1: 1 | D1: 2 | E1: 3 | F1: 4 | G1: 5 | H1: 6 | I1: 7 | J1: 8 | K1: 9 | L1: 10
A2: HH1 | B2: 1 | C2: ='XL-Test'!G9 -> 45879 | D2: ='XL-Test'!H9 -> 7 | E2: ='XL-Test'!I9 -> 31 | F2: ='XL-Test'!J9 -> 45689 | G2: ='XL-Test'!K9 -> 45870 | H2: ='XL-Test'!L9 -> 45667 | I2: ='XL-Test'!M9 -> 45877 | J2: ='XL-Test'!N9 -> 45754 | ... L2: ='XL-Test'!P9 -> 76 | S2: 1 | T2: =SUBSTITUTE(_xlfn.FORMULATEXT('XL-Test'!G11),"$","") -> =WORKDAY.INTL(E11;F11;7) | U2: =SUBSTITUTE(_xlfn.FORMULATEXT('XL-Test'!H11),"$","") -> =SUMPRODUCT(--(DAY(ROW(INDIRECT(E11&":"&G11)))=1)) | V2: =SUBSTITUTE(_xlfn.FORMULATEXT('XL-Test'!I11),"$","") -> =NETWORKDAYS.INTL(E11;G11;"1111011") | W2: =SUBSTITUTE(_xlfn.FORMULATEXT('XL-Test'!J11),"$","") -> =EOMONTH(E11;IF(DAY(E11)=1;-1;0))+1 | X2: =SUBSTITUTE(_xlfn.FORMULATEXT('XL-Test'!K11),"$","") -> =EOMONTH(G11;-1)+1 | Y2: =SUBSTITUTE(_xlfn.FORMULATEXT('XL-Test'!L11),"$","") -> =WORKDAY.INTL(E11 -1;1;"1111011") | Z2: =SUBSTITUTE(_xlfn.FORMULATEXT('XL-Test'!M11),"$","") -> =WORKDAY.INTL(G11+1;-1;"1111011") | AA2: =SUBSTITUTE(_xlfn.FORMULATEXT('XL-Test'!N11),"$","") -> =EDATE(E11;3) | ... AC2: =SUBSTITUTE(_xlfn.FORMULATEXT('XL-Test'!P11),"$","") -> =SUM(--(ISEVEN(DAY(E11+SEQUENCE(G11-E11+1;1;0)))*(WEEKDAY(E11+SEQUENCE(G11-E11+1;1;0))<6)))
B3: 2 | C3: ='XL-Test'!G10 -> 46013 | D3: ='XL-Test'!H10 -> 5 | E3: ='XL-Test'!I10 -> 21 | F3: ='XL-Test'!J10 -> 45870 | G3: ='XL-Test'!K10 -> 45992 | H3: ='XL-Test'!L10 -> 45870 | I3: ='XL-Test'!M10 -> 46010 | J3: ='XL-Test'!N10 -> 45962 | ... L3: ='XL-Test'!P10 -> 51 | S3: 2 | T3: =U2 -> =SUMPRODUCT(--(DAY(ROW(INDIRECT(E11&":"&G11)))=1))
B4: 3 | C4: ='XL-Test'!G11 -> 46677 | D4: ='XL-Test'!H11 -> 10 | E4: ='XL-Test'!I11 -> 45 | F4: ='XL-Test'!J11 -> 46388 | G4: ='XL-Test'!K11 -> 46661 | H4: ='XL-Test'!L11 -> 46367 | I4: ='XL-Test'!M11 -> 46675 | J4: ='XL-Test'!N11 -> 46455 | ... L4: ='XL-Test'!P11 -> 108 | S4: 3 | T4: =V2 -> =NETWORKDAYS.INTL(E11;G11;"1111011")
B5: 4 | C5: ='XL-Test'!G12 -> 45865 | D5: ='XL-Test'!H12 -> 5 | E5: ='XL-Test'!I12 -> 23 | F5: ='XL-Test'!J12 -> 45717 | G5: ='XL-Test'!K12 -> 45839 | H5: ='XL-Test'!L12 -> 45709 | I5: ='XL-Test'!M12 -> 45863 | J5: ='XL-Test'!N12 -> 45798 | ... L5: ='XL-Test'!P12 -> 54 | S5: 4 | T5: =W2 -> =EOMONTH(E11;IF(DAY(E11)=1;-1;0))+1
B6: 5 | C6: ='XL-Test'!G13 -> 46295 | D6: ='XL-Test'!H13 -> 9 | E6: ='XL-Test'!I13 -> 40 | F6: ='XL-Test'!J13 -> 46023 | G6: ='XL-Test'!K13 -> 46266 | H6: ='XL-Test'!L13 -> 46017 | I6: ='XL-Test'!M13 -> 46290 | J6: ='XL-Test'!N13 -> 46103 | ... L6: ='XL-Test'!P13 -> 100 | S6: 5 | T6: =X2 -> =EOMONTH(G11;-1)+1
B7: 6 | C7: ='XL-Test'!G14 -> 45981 | D7: ='XL-Test'!H14 -> 4 | E7: ='XL-Test'!I14 -> 17 | F7: ='XL-Test'!J14 -> 45870 | G7: ='XL-Test'!K14 -> 45962 | H7: ='XL-Test'!L14 -> 45863 | I7: ='XL-Test'!M14 -> 45975 | J7: ='XL-Test'!N14 -> 45955 | ... L7: ='XL-Test'!P14 -> 42 | S7: 6 | T7: =Y2 -> =WORKDAY.INTL(E11 -1;1;"1111011")
B8: 7 | C8: ='XL-Test'!G15 -> 46294 | D8: ='XL-Test'!H15 -> 7 | E8: ='XL-Test'!I15 -> 31 | F8: ='XL-Test'!J15 -> 46082 | G8: ='XL-Test'!K15 -> 46266 | H8: ='XL-Test'!L15 -> 46080 | I8: ='XL-Test'!M15 -> 46290 | J8: ='XL-Test'!N15 -> 46169 | ... L8: ='XL-Test'!P15 -> 75 | S8: 7 | T8: =Z2 -> =WORKDAY.INTL(G11+1;-1;"1111011")
B9: 8 | C9: ='XL-Test'!G16 -> 46393 | D9: ='XL-Test'!H16 -> 10 | E9: ='XL-Test'!I16 -> 42 | F9: ='XL-Test'!J16 -> 46113 | G9: ='XL-Test'!K16 -> 46388 | H9: ='XL-Test'!L16 -> 46101 | I9: ='XL-Test'!M16 -> 46388 | J9: ='XL-Test'!N16 -> 46189 | ... L9: ='XL-Test'!P16 -> 105 | S9: 8 | T9: =AA2 -> =EDATE(E11;3)
B10: 9 | C10: ='XL-Test'!G17 -> 45972 | D10: ='XL-Test'!H17 -> 6 | E10: ='XL-Test'!I17 -> 24 | F10: ='XL-Test'!J17 -> 45809 | G10: ='XL-Test'!K17 -> 45962 | H10: ='XL-Test'!L17 -> 45807 | I10: ='XL-Test'!M17 -> 45968 | J10: ='XL-Test'!N17 -> 45897 | ... L10: ='XL-Test'!P17 -> 59 | S10: 9 | T10: =AB2 -> =EOMONTH(E11;6)
B11: 10 | C11: ='XL-Test'!G18 -> 46656 | D11: ='XL-Test'!H18 -> 12 | E11: ='XL-Test'!I18 -> 52 | F11: ='XL-Test'!J18 -> 46296 | G11: ='XL-Test'!K18 -> 46631 | H11: ='XL-Test'!L18 -> 46297 | I11: ='XL-Test'!M18 -> 46654 | J11: ='XL-Test'!N18 -> 46388 | ... L11: ='XL-Test'!P18 -> 125 | S11: 10 | T11: =AC2 -> =SUM(--(ISEVEN(DAY(E11+SEQUENCE(G11-E11+1;1;0)))*(WEEKDAY(E11+SEQUENCE(G11-E11+1;1;0))<6)))
B12: 11 | C12: ='XL-Test'!G19 -> 46093 | D12: ='XL-Test'!H19 -> 7 | E12: ='XL-Test'!I19 -> 31 | F12: ='XL-Test'!J19 -> 45901 | G12: ='XL-Test'!K19 -> 46082 | H12: ='XL-Test'!L19 -> 45877 | I12: ='XL-Test'!M19 -> 46087 | J12: ='XL-Test'!N19 -> 45968 | ... L12: ='XL-Test'!P19 -> 77
B13: 12 | C13: ='XL-Test'!G20 -> 46715 | D13: ='XL-Test'!H20 -> 11 | E13: ='XL-Test'!I20 -> 49 | F13: ='XL-Test'!J20 -> 46388 | G13: ='XL-Test'!K20 -> 46692 | H13: ='XL-Test'!L20 -> 46374 | I13: ='XL-Test'!M20 -> 46710 | J13: ='XL-Test'!N20 -> 46461 | ... L13: ='XL-Test'!P20 -> 120
B14: 13 | C14: ='XL-Test'!G21 -> 46307 | D14: ='XL-Test'!H21 -> 9 | E14: ='XL-Test'!I21 -> 41 | F14: ='XL-Test'!J21 -> 46054 | G14: ='XL-Test'!K21 -> 46296 | H14: ='XL-Test'!L21 -> 46024 | I14: ='XL-Test'!M21 -> 46304 | J14: ='XL-Test'!N21 -> 46114 | ... L14: ='XL-Test'!P21 -> 100
B15: 14 | C15: ='XL-Test'!G22 -> 45986 | D15: ='XL-Test'!H22 -> 7 | E15: ='XL-Test'!I22 -> 30 | F15: ='XL-Test'!J22 -> 45778 | G15: ='XL-Test'!K22 -> 45962 | H15: ='XL-Test'!L22 -> 45779 | I15: ='XL-Test'!M22 -> 45982 | J15: ='XL-Test'!N22 -> 45866 | ... L15: ='XL-Test'!P22 -> 75
B16: 15 | C16: ='XL-Test'!G23 -> 46447 | D16: ='XL-Test'!H23 -> 6 | E16: ='XL-Test'!I23 -> 22 | F16: ='XL-Test'!J23 -> 46296 | G16: ='XL-Test'!K23 -> 46447 | H16: ='XL-Test'!L23 -> 46297 | I16: ='XL-Test'!M23 -> 46444 | J16: ='XL-Test'!N23 -> 46388 | ... L16: ='XL-Test'!P23 -> 52
B17: 16 | C17: ='XL-Test'!G24 -> 46553 | D17: ='XL-Test'!H24 -> 8 | E17: ='XL-Test'!I24 -> 36 | F17: ='XL-Test'!J24 -> 46327 | G17: ='XL-Test'!K24 -> 46539 | H17: ='XL-Test'!L24 -> 46304 | I17: ='XL-Test'!M24 -> 46549 | J17: ='XL-Test'!N24 -> 46395 | ... L17: ='XL-Test'!P24 -> 87
B18: 17 | C18: ='XL-Test'!G25 -> 46457 | D18: ='XL-Test'!H25 -> 7 | E18: ='XL-Test'!I25 -> 28 | F18: ='XL-Test'!J25 -> 46266 | G18: ='XL-Test'!K25 -> 46447 | H18: ='XL-Test'!L25 -> 46262 | I18: ='XL-Test'!M25 -> 46451 | J18: ='XL-Test'!N25 -> 46354 | ... L18: ='XL-Test'!P25 -> 68
B19: 18 | C19: ='XL-Test'!G26 -> 46558 | D19: ='XL-Test'!H26 -> 8 | E19: ='XL-Test'!I26 -> 36 | F19: ='XL-Test'!J26 -> 46327 | G19: ='XL-Test'!K26 -> 46539 | H19: ='XL-Test'!L26 -> 46311 | I19: ='XL-Test'!M26 -> 46556 | J19: ='XL-Test'!N26 -> 46399 | ... L19: ='XL-Test'!P26 -> 88
B20: 19 | C20: ='XL-Test'!G27 -> 45980 | D20: ='XL-Test'!H27 -> 10 | E20: ='XL-Test'!I27 -> 45 | F20: ='XL-Test'!J27 -> 45689 | G20: ='XL-Test'!K27 -> 45962 | H20: ='XL-Test'!L27 -> 45667 | I20: ='XL-Test'!M27 -> 45975 | J20: ='XL-Test'!N27 -> 45753 | ... L20: ='XL-Test'!P27 -> 113
B21: 20 | C21: ='XL-Test'!G28 -> 45854 | D21: ='XL-Test'!H28 -> 4 | E21: ='XL-Test'!I28 -> 17 | F21: ='XL-Test'!J28 -> 45748 | G21: ='XL-Test'!K28 -> 45839 | H21: ='XL-Test'!L28 -> 45737 | I21: ='XL-Test'!M28 -> 45849 | J21: ='XL-Test'!N28 -> 45829 | ... L21: ='XL-Test'!P28 -> 41
B25: SUM | C25: =SUM(C2:C21)+SUM(C2,C5,C10,C14,C18,C12,C7,C21) -> 1293383 | D25: =(SUM(D2:D21)+SUM(D2,D5,D10,D14,D18,D12,D7,D21))*136 -> 27336 | E25: =(SUM(E2:E21)+SUM(E2,E5,E10,E14,E18,E12,E7,E21))*12 -> 10476 | F25: =SUM(F2:F21)+SUM(F2,F5,F10,F14,F18,F12,F7,F21) -> 1287685 | G25: =SUM(G2:G21)+SUM(G2,G5,G10,G14,G18,G12,G7,G21) -> 1292939 | H25: =SUM(H2:H21)+SUM(H2,H5,H10,H14,H18,H12,H7,H21) -> 1287356 | I25: =SUM(I2:I21)+SUM(I2,I5,I10,I14,I18,I12,I7,I21) -> 1293271 | J25: =SUM(J2:J21)+SUM(J2,J5,J10,J14,J18,J12,J7,J21) -> 1289866 | K25: =SUM(K2:K21)+SUM(K2,K5,K10,K14,K18,K12,K7,K21) -> 1292846 | L25: =(SUM(L2:L21)+SUM(L2,L5,L10,L14,L18,L12,L7,L21))*25 -> 53325
B26: random | C26: 51754 | D26: 41698 | E26: 13905 | F26: 67796 | G26: 37450 | H26: 45215 | I26: 62825 | J26: 14767 | K26: 87361 | L26: 11883
B29: Cek Manual | C29: =AND(ISNUMBER(FIND("(",T2)),ISNUMBER(FIND("=",T2))) -> TRUE | D29: =AND(ISNUMBER(FIND("(",U2)),ISNUMBER(FIND("=",U2))) -> TRUE | E29: =AND(ISNUMBER(FIND("(",V2)),ISNUMBER(FIND("=",V2))) -> TRUE | F29: =AND(ISNUMBER(FIND("(",W2)),ISNUMBER(FIND("=",W2))) -> TRUE | G29: =AND(ISNUMBER(FIND("(",X2)),ISNUMBER(FIND("=",X2))) -> TRUE | H29: =AND(ISNUMBER(FIND("(",Y2)),ISNUMBER(FIND("=",Y2))) -> TRUE | I29: =AND(ISNUMBER(FIND("(",Z2)),ISNUMBER(FIND("=",Z2))) -> TRUE | J29: =AND(ISNUMBER(FIND("(",AA2)),ISNUMBER(FIND("=",AA2))) -> TRUE | ... L29: =AND(ISNUMBER(FIND("(",AC2)),ISNUMBER(FIND("=",AC2))) -> TRUE
A30: ** | B30: Value | C30: =IFERROR(DEC2HEX(IF(AND(NOT(C25=0),C76),C25,C26)),"EEE") -> 13BC47 | D30: =IFERROR(DEC2HEX(IF(AND(NOT(D25=0),D76),D25,D26)),"EEE") -> 6AC8 | E30: =IFERROR(DEC2HEX(IF(AND(NOT(E25=0),E76),E25,E26)),"EEE") -> 28EC | F30: =IFERROR(DEC2HEX(IF(AND(NOT(F25=0),F76),F25,F26)),"EEE") -> 13A605 | G30: =IFERROR(DEC2HEX(IF(AND(NOT(G25=0),G76),G25,G26)),"EEE") -> 13BA8B | H30: =IFERROR(DEC2HEX(IF(AND(NOT(H25=0),H76),H25,H26)),"EEE") -> 13A4BC | I30: =IFERROR(DEC2HEX(IF(AND(NOT(I25=0),I76),I25,I26)),"EEE") -> 13BBD7 | J30: =IFERROR(DEC2HEX(IF(AND(NOT(J25=0),J76),J25,J26)),"EEE") -> 13AE8A | ... L30: =IFERROR(DEC2HEX(IF(AND(NOT(L25=0),L76),L25,L26)),"EEE") -> D04D
B32: TRUE | C32: =DEC2HEX(HEX2DEC(RIGHT(C30,2))+13) -> 54 | D32: =DEC2HEX(HEX2DEC(RIGHT(D30,2))+13) -> D5 | E32: =DEC2HEX(HEX2DEC(RIGHT(E30,2))+13) -> F9 | F32: =DEC2HEX(HEX2DEC(RIGHT(F30,2))+13) -> 12 | G32: =DEC2HEX(HEX2DEC(RIGHT(G30,2))+13) -> 98 | H32: =DEC2HEX(HEX2DEC(RIGHT(H30,2))+13) -> C9 | I32: =DEC2HEX(HEX2DEC(RIGHT(I30,2))+13) -> E4 | J32: =DEC2HEX(HEX2DEC(RIGHT(J30,2))+13) -> 97 | ... L32: =DEC2HEX(HEX2DEC(RIGHT(L30,2))+13) -> 5A
B33: FALSE | C33: =DEC2HEX(HEX2DEC(LEFT(C30,2))+14+COLUMN()) -> 24 | D33: =DEC2HEX(HEX2DEC(LEFT(D30,2))+14+COLUMN()) -> 7C | E33: =DEC2HEX(HEX2DEC(LEFT(E30,2))+14+COLUMN()) -> 3B | F33: =DEC2HEX(HEX2DEC(LEFT(F30,2))+14+COLUMN()) -> 27 | G33: =DEC2HEX(HEX2DEC(LEFT(G30,2))+14+COLUMN()) -> 28 | H33: =DEC2HEX(HEX2DEC(LEFT(H30,2))+14+COLUMN()) -> 29 | I33: =DEC2HEX(HEX2DEC(LEFT(I30,2))+14+COLUMN()) -> 2A | J33: =DEC2HEX(HEX2DEC(LEFT(J30,2))+14+COLUMN()) -> 2B | ... L33: =DEC2HEX(HEX2DEC(LEFT(L30,2))+14+COLUMN()) -> EA
B34: Cek Rumus | C34: =AND(ISNUMBER(FIND("DAY.INTL",T2)),OR(ISNUMBER(FIND("7",T2)),ISNUMBER(FIND("0000110",T2)))) -> TRUE | D34: =AND(ISNUMBER(FIND("SUM",U2)),ISNUMBER(FIND("DAY",U2))) -> TRUE | E34: =AND(ISNUMBER(FIND("DAYS.INTL",V2)),ISNUMBER(FIND("1111011",V2))) -> TRUE | F34: =AND(ISNUMBER(FIND("EOM",W2)),ISNUMBER(FIND("IF",W2))) -> TRUE | G34: =ISNUMBER(FIND("EOM",X2)) -> TRUE | H34: =AND(ISNUMBER(FIND("DAY.INTL",Y2)),ISNUMBER(FIND("1111011",Y2))) -> TRUE | I34: =AND(ISNUMBER(FIND("DAY.INTL",Z2)),ISNUMBER(FIND("1111011",Z2))) -> TRUE | J34: =ISNUMBER(FIND("EDA",AA2)) -> TRUE | K34: =ISNUMBER(FIND("EOMO",AB2)) -> TRUE | L34: =AND(ISNUMBER(FIND("SUM",AC2)),OR(ISNUMBER(FIND("EVEN",AC2)),ISNUMBER(FIND("ODD",AC2)))) -> TRUE
C38: =C83 -> HH1|54-13BC47;D5-6AC8;F9-28EC;12-13A605;98-13BA8B;C9-13A4BC;E4-13BBD7;97-13AE8A;3B-13BA2E;5A-D04D
A42: 9 | B42: 1 | C42: =LEN(_xlfn.FORMULATEXT('XL-Test'!G9)) -> 22 | D42: =LEN(_xlfn.FORMULATEXT('XL-Test'!H9)) -> 48 | E42: =LEN(_xlfn.FORMULATEXT('XL-Test'!I9)) -> 34 | F42: =LEN(_xlfn.FORMULATEXT('XL-Test'!J9)) -> 33 | G42: =LEN(_xlfn.FORMULATEXT('XL-Test'!K9)) -> 17 | H42: =LEN(_xlfn.FORMULATEXT('XL-Test'!L9)) -> 32 | I42: =LEN(_xlfn.FORMULATEXT('XL-Test'!M9)) -> 32 | J42: =LEN(_xlfn.FORMULATEXT('XL-Test'!N9)) -> 12 | ... L42: =LEN(_xlfn.FORMULATEXT('XL-Test'!P9)) -> 85
A43: 10 | B43: 2 | C43: =LEN(_xlfn.FORMULATEXT('XL-Test'!G10)) -> 24 | D43: =LEN(_xlfn.FORMULATEXT('XL-Test'!H10)) -> 50 | E43: =LEN(_xlfn.FORMULATEXT('XL-Test'!I10)) -> 36 | F43: =LEN(_xlfn.FORMULATEXT('XL-Test'!J10)) -> 35 | G43: =LEN(_xlfn.FORMULATEXT('XL-Test'!K10)) -> 18 | H43: =LEN(_xlfn.FORMULATEXT('XL-Test'!L10)) -> 33 | I43: =LEN(_xlfn.FORMULATEXT('XL-Test'!M10)) -> 33 | J43: =LEN(_xlfn.FORMULATEXT('XL-Test'!N10)) -> 13 | ... L43: =LEN(_xlfn.FORMULATEXT('XL-Test'!P10)) -> 91
A44: 11 | B44: 3 | C44: =LEN(_xlfn.FORMULATEXT('XL-Test'!G11)) -> 24 | D44: =LEN(_xlfn.FORMULATEXT('XL-Test'!H11)) -> 50 | E44: =LEN(_xlfn.FORMULATEXT('XL-Test'!I11)) -> 36 | F44: =LEN(_xlfn.FORMULATEXT('XL-Test'!J11)) -> 35 | G44: =LEN(_xlfn.FORMULATEXT('XL-Test'!K11)) -> 18 | H44: =LEN(_xlfn.FORMULATEXT('XL-Test'!L11)) -> 33 | I44: =LEN(_xlfn.FORMULATEXT('XL-Test'!M11)) -> 33 | J44: =LEN(_xlfn.FORMULATEXT('XL-Test'!N11)) -> 13 | ... L44: =LEN(_xlfn.FORMULATEXT('XL-Test'!P11)) -> 91
A45: 12 | B45: 4 | C45: =LEN(_xlfn.FORMULATEXT('XL-Test'!G12)) -> 24 | D45: =LEN(_xlfn.FORMULATEXT('XL-Test'!H12)) -> 50 | E45: =LEN(_xlfn.FORMULATEXT('XL-Test'!I12)) -> 36 | F45: =LEN(_xlfn.FORMULATEXT('XL-Test'!J12)) -> 35 | G45: =LEN(_xlfn.FORMULATEXT('XL-Test'!K12)) -> 18 | H45: =LEN(_xlfn.FORMULATEXT('XL-Test'!L12)) -> 33 | I45: =LEN(_xlfn.FORMULATEXT('XL-Test'!M12)) -> 33 | J45: =LEN(_xlfn.FORMULATEXT('XL-Test'!N12)) -> 13 | ... L45: =LEN(_xlfn.FORMULATEXT('XL-Test'!P12)) -> 91
A46: 13 | B46: 5 | C46: =LEN(_xlfn.FORMULATEXT('XL-Test'!G13)) -> 24 | D46: =LEN(_xlfn.FORMULATEXT('XL-Test'!H13)) -> 50 | E46: =LEN(_xlfn.FORMULATEXT('XL-Test'!I13)) -> 36 | F46: =LEN(_xlfn.FORMULATEXT('XL-Test'!J13)) -> 35 | G46: =LEN(_xlfn.FORMULATEXT('XL-Test'!K13)) -> 18 | H46: =LEN(_xlfn.FORMULATEXT('XL-Test'!L13)) -> 33 | I46: =LEN(_xlfn.FORMULATEXT('XL-Test'!M13)) -> 33 | J46: =LEN(_xlfn.FORMULATEXT('XL-Test'!N13)) -> 13 | ... L46: =LEN(_xlfn.FORMULATEXT('XL-Test'!P13)) -> 91
A47: 14 | B47: 6 | C47: =LEN(_xlfn.FORMULATEXT('XL-Test'!G14)) -> 24 | D47: =LEN(_xlfn.FORMULATEXT('XL-Test'!H14)) -> 50 | E47: =LEN(_xlfn.FORMULATEXT('XL-Test'!I14)) -> 36 | F47: =LEN(_xlfn.FORMULATEXT('XL-Test'!J14)) -> 35 | G47: =LEN(_xlfn.FORMULATEXT('XL-Test'!K14)) -> 18 | H47: =LEN(_xlfn.FORMULATEXT('XL-Test'!L14)) -> 33 | I47: =LEN(_xlfn.FORMULATEXT('XL-Test'!M14)) -> 33 | J47: =LEN(_xlfn.FORMULATEXT('XL-Test'!N14)) -> 13 | ... L47: =LEN(_xlfn.FORMULATEXT('XL-Test'!P14)) -> 91
A48: 15 | B48: 7 | C48: =LEN(_xlfn.FORMULATEXT('XL-Test'!G15)) -> 24 | D48: =LEN(_xlfn.FORMULATEXT('XL-Test'!H15)) -> 50 | E48: =LEN(_xlfn.FORMULATEXT('XL-Test'!I15)) -> 36 | F48: =LEN(_xlfn.FORMULATEXT('XL-Test'!J15)) -> 35 | G48: =LEN(_xlfn.FORMULATEXT('XL-Test'!K15)) -> 18 | H48: =LEN(_xlfn.FORMULATEXT('XL-Test'!L15)) -> 33 | I48: =LEN(_xlfn.FORMULATEXT('XL-Test'!M15)) -> 33 | J48: =LEN(_xlfn.FORMULATEXT('XL-Test'!N15)) -> 13 | ... L48: =LEN(_xlfn.FORMULATEXT('XL-Test'!P15)) -> 91
A49: 16 | B49: 8 | C49: =LEN(_xlfn.FORMULATEXT('XL-Test'!G16)) -> 24 | D49: =LEN(_xlfn.FORMULATEXT('XL-Test'!H16)) -> 50 | E49: =LEN(_xlfn.FORMULATEXT('XL-Test'!I16)) -> 36 | F49: =LEN(_xlfn.FORMULATEXT('XL-Test'!J16)) -> 35 | G49: =LEN(_xlfn.FORMULATEXT('XL-Test'!K16)) -> 18 | H49: =LEN(_xlfn.FORMULATEXT('XL-Test'!L16)) -> 33 | I49: =LEN(_xlfn.FORMULATEXT('XL-Test'!M16)) -> 33 | J49: =LEN(_xlfn.FORMULATEXT('XL-Test'!N16)) -> 13 | ... L49: =LEN(_xlfn.FORMULATEXT('XL-Test'!P16)) -> 91
A50: 17 | B50: 9 | C50: =LEN(_xlfn.FORMULATEXT('XL-Test'!G17)) -> 24 | D50: =LEN(_xlfn.FORMULATEXT('XL-Test'!H17)) -> 50 | E50: =LEN(_xlfn.FORMULATEXT('XL-Test'!I17)) -> 36 | F50: =LEN(_xlfn.FORMULATEXT('XL-Test'!J17)) -> 35 | G50: =LEN(_xlfn.FORMULATEXT('XL-Test'!K17)) -> 18 | H50: =LEN(_xlfn.FORMULATEXT('XL-Test'!L17)) -> 33 | I50: =LEN(_xlfn.FORMULATEXT('XL-Test'!M17)) -> 33 | J50: =LEN(_xlfn.FORMULATEXT('XL-Test'!N17)) -> 13 | ... L50: =LEN(_xlfn.FORMULATEXT('XL-Test'!P17)) -> 91
A51: 18 | B51: 10 | C51: =LEN(_xlfn.FORMULATEXT('XL-Test'!G18)) -> 24 | D51: =LEN(_xlfn.FORMULATEXT('XL-Test'!H18)) -> 50 | E51: =LEN(_xlfn.FORMULATEXT('XL-Test'!I18)) -> 36 | F51: =LEN(_xlfn.FORMULATEXT('XL-Test'!J18)) -> 35 | G51: =LEN(_xlfn.FORMULATEXT('XL-Test'!K18)) -> 18 | H51: =LEN(_xlfn.FORMULATEXT('XL-Test'!L18)) -> 33 | I51: =LEN(_xlfn.FORMULATEXT('XL-Test'!M18)) -> 33 | J51: =LEN(_xlfn.FORMULATEXT('XL-Test'!N18)) -> 13 | ... L51: =LEN(_xlfn.FORMULATEXT('XL-Test'!P18)) -> 91
A52: 19 | B52: 11 | C52: =LEN(_xlfn.FORMULATEXT('XL-Test'!G19)) -> 24 | D52: =LEN(_xlfn.FORMULATEXT('XL-Test'!H19)) -> 50 | E52: =LEN(_xlfn.FORMULATEXT('XL-Test'!I19)) -> 36 | F52: =LEN(_xlfn.FORMULATEXT('XL-Test'!J19)) -> 35 | G52: =LEN(_xlfn.FORMULATEXT('XL-Test'!K19)) -> 18 | H52: =LEN(_xlfn.FORMULATEXT('XL-Test'!L19)) -> 33 | I52: =LEN(_xlfn.FORMULATEXT('XL-Test'!M19)) -> 33 | J52: =LEN(_xlfn.FORMULATEXT('XL-Test'!N19)) -> 13 | ... L52: =LEN(_xlfn.FORMULATEXT('XL-Test'!P19)) -> 91
...
