Workbook
Name Kode_jawaban: DF!$C$64

Sheet XL-Test
B1: Hard Level (⭐⭐⭐)
B2: KODE SOAL | C2: SBEH004 | E2: KODE JAWABAN | F2: =Kode_jawaban -> HD2|17-9D2;22-9C4;20-795E9;18-9B043;8F-B2A34
B5: NO | C5: ID | D5: Name | E5: F/Name | F5: D.O.B | G5: Join Date | H5: Length of Service (Weeks)
B6: 1 | C6: 116809 | D6: {=_xlfn.XLOOKUP(C6,INT(Database!B$1:B$120/100000),Database!D$2:D$121,,0,1)} -> Komal | E6: {=_xlfn.XLOOKUP(C6,INT(Database!B$1:B$120/100000),Database!D$3:D$122,,0,1)} -> Arif | F6: {=_xlfn.XLOOKUP(C6,INT(Database!B$1:B$120/100000),Database!D$4:D$123,,0,1)} -> 31668 | G6: {=VLOOKUP(C6&"*",TEXT(Database!B:B,0),1,0)*1-C6*100000} -> 40250 | H6: =INT(DATEDIF(G6, DATE(2025,4,1), "D")/7) -> 785
B7: 2 | C7: 123010 | D7: {=_xlfn.XLOOKUP(C7,INT(Database!B$1:B$120/100000),Database!D$2:D$121,,0,1)} -> Hina | E7: {=_xlfn.XLOOKUP(C7,INT(Database!B$1:B$120/100000),Database!D$3:D$122,,0,1)} -> Aslam | F7: {=_xlfn.XLOOKUP(C7,INT(Database!B$1:B$120/100000),Database!D$4:D$123,,0,1)} -> 33286 | G7: {=VLOOKUP(C7&"*",TEXT(Database!B:B,0),1,0)*1-C7*100000} -> 43421 | H7: =INT(DATEDIF(G7, DATE(2025,4,1), "D")/7) -> 332
B8: 3 | C8: 177992 | D8: {=_xlfn.XLOOKUP(C8,INT(Database!B$1:B$120/100000),Database!D$2:D$121,,0,1)} -> Mariam | E8: {=_xlfn.XLOOKUP(C8,INT(Database!B$1:B$120/100000),Database!D$3:D$122,,0,1)} -> Rashid | F8: {=_xlfn.XLOOKUP(C8,INT(Database!B$1:B$120/100000),Database!D$4:D$123,,0,1)} -> 33807 | G8: {=VLOOKUP(C8&"*",TEXT(Database!B:B,0),1,0)*1-C8*100000} -> 42665 | H8: =INT(DATEDIF(G8, DATE(2025,4,1), "D")/7) -> 440
B9: 4 | C9: 197510 | D9: {=_xlfn.XLOOKUP(C9,INT(Database!B$1:B$120/100000),Database!D$2:D$121,,0,1)} -> Noor | E9: {=_xlfn.XLOOKUP(C9,INT(Database!B$1:B$120/100000),Database!D$3:D$122,,0,1)} -> Ahmed | F9: {=_xlfn.XLOOKUP(C9,INT(Database!B$1:B$120/100000),Database!D$4:D$123,,0,1)} -> 32435 | G9: {=VLOOKUP(C9&"*",TEXT(Database!B:B,0),1,0)*1-C9*100000} -> 40927 | H9: =INT(DATEDIF(G9, DATE(2025,4,1), "D")/7) -> 688
B10: 5 | C10: 215240 | D10: {=_xlfn.XLOOKUP(C10,INT(Database!B$1:B$120/100000),Database!D$2:D$121,,0,1)} -> Rehan | E10: {=_xlfn.XLOOKUP(C10,INT(Database!B$1:B$120/100000),Database!D$3:D$122,,0,1)} -> Farooq | F10: {=_xlfn.XLOOKUP(C10,INT(Database!B$1:B$120/100000),Database!D$4:D$123,,0,1)} -> 34881 | G10: {=VLOOKUP(C10&"*",TEXT(Database!B:B,0),1,0)*1-C10*100000} -> 43282 | H10: =INT(DATEDIF(G10, DATE(2025,4,1), "D")/7) -> 352
B11: 6 | C11: 350434 | D11: {=_xlfn.XLOOKUP(C11,INT(Database!B$1:B$120/100000),Database!D$2:D$121,,0,1)} -> Sana | E11: {=_xlfn.XLOOKUP(C11,INT(Database!B$1:B$120/100000),Database!D$3:D$122,,0,1)} -> Nasir | F11: {=_xlfn.XLOOKUP(C11,INT(Database!B$1:B$120/100000),Database!D$4:D$123,,0,1)} -> 33243 | G11: {=VLOOKUP(C11&"*",TEXT(Database!B:B,0),1,0)*1-C11*100000} -> 43013 | H11: =INT(DATEDIF(G11, DATE(2025,4,1), "D")/7) -> 390
B12: 7 | C12: 440324 | D12: {=_xlfn.XLOOKUP(C12,INT(Database!B$1:B$120/100000),Database!D$2:D$121,,0,1)} -> Ayesha | E12: {=_xlfn.XLOOKUP(C12,INT(Database!B$1:B$120/100000),Database!D$3:D$122,,0,1)} -> Usman | F12: {=_xlfn.XLOOKUP(C12,INT(Database!B$1:B$120/100000),Database!D$4:D$123,,0,1)} -> 31833 | G12: {=VLOOKUP(C12&"*",TEXT(Database!B:B,0),1,0)*1-C12*100000} -> 40142 | H12: =INT(DATEDIF(G12, DATE(2025,4,1), "D")/7) -> 800
B13: 8 | C13: 489281 | D13: {=_xlfn.XLOOKUP(C13,INT(Database!B$1:B$120/100000),Database!D$2:D$121,,0,1)} -> Omar | E13: {=_xlfn.XLOOKUP(C13,INT(Database!B$1:B$120/100000),Database!D$3:D$122,,0,1)} -> Salman | F13: {=_xlfn.XLOOKUP(C13,INT(Database!B$1:B$120/100000),Database!D$4:D$123,,0,1)} -> 34073 | G13: {=VLOOKUP(C13&"*",TEXT(Database!B:B,0),1,0)*1-C13*100000} -> 42383 | H13: =INT(DATEDIF(G13, DATE(2025,4,1), "D")/7) -> 480
B14: 9 | C14: 502463 | D14: {=_xlfn.XLOOKUP(C14,INT(Database!B$1:B$120/100000),Database!D$2:D$121,,0,1)} -> Ali | E14: {=_xlfn.XLOOKUP(C14,INT(Database!B$1:B$120/100000),Database!D$3:D$122,,0,1)} -> Imran | F14: {=_xlfn.XLOOKUP(C14,INT(Database!B$1:B$120/100000),Database!D$4:D$123,,0,1)} -> 32760 | G14: {=VLOOKUP(C14&"*",TEXT(Database!B:B,0),1,0)*1-C14*100000} -> 42803 | H14: =INT(DATEDIF(G14, DATE(2025,4,1), "D")/7) -> 420
B15: 10 | C15: 581782 | D15: {=_xlfn.XLOOKUP(C15,INT(Database!B$1:B$120/100000),Database!D$2:D$121,,0,1)} -> Ibrahim | E15: {=_xlfn.XLOOKUP(C15,INT(Database!B$1:B$120/100000),Database!D$3:D$122,,0,1)} -> Hamid | F15: {=_xlfn.XLOOKUP(C15,INT(Database!B$1:B$120/100000),Database!D$4:D$123,,0,1)} -> 32811 | G15: {=VLOOKUP(C15&"*",TEXT(Database!B:B,0),1,0)*1-C15*100000} -> 40237 | H15: =INT(DATEDIF(G15, DATE(2025,4,1), "D")/7) -> 787
B16: 11 | C16: 636392 | D16: {=_xlfn.XLOOKUP(C16,INT(Database!B$1:B$120/100000),Database!D$2:D$121,,0,1)} -> Laila | E16: {=_xlfn.XLOOKUP(C16,INT(Database!B$1:B$120/100000),Database!D$3:D$122,,0,1)} -> Murtaza | F16: {=_xlfn.XLOOKUP(C16,INT(Database!B$1:B$120/100000),Database!D$4:D$123,,0,1)} -> 35158 | G16: {=VLOOKUP(C16&"*",TEXT(Database!B:B,0),1,0)*1-C16*100000} -> 45691 | H16: =INT(DATEDIF(G16, DATE(2025,4,1), "D")/7) -> 8
B17: 12 | C17: 700161 | D17: {=_xlfn.XLOOKUP(C17,INT(Database!B$1:B$120/100000),Database!D$2:D$121,,0,1)} -> Usman | E17: {=_xlfn.XLOOKUP(C17,INT(Database!B$1:B$120/100000),Database!D$3:D$122,,0,1)} -> Waqas | F17: {=_xlfn.XLOOKUP(C17,INT(Database!B$1:B$120/100000),Database!D$4:D$123,,0,1)} -> 34496 | G17: {=VLOOKUP(C17&"*",TEXT(Database!B:B,0),1,0)*1-C17*100000} -> 42411 | H17: =INT(DATEDIF(G17, DATE(2025,4,1), "D")/7) -> 476
... B20: 15 | C20: 823830 | D20: {=_xlfn.XLOOKUP(C20,INT(Database!B$1:B$120/100000),Database!D$2:D$121,,0,1)} -> Zara | E20: {=_xlfn.XLOOKUP(C20,INT(Database!B$1:B$120/100000),Database!D$3:D$122,,0,1)} -> Bilal | F20: {=_xlfn.XLOOKUP(C20,INT(Database!B$1:B$120/100000),Database!D$4:D$123,,0,1)} -> 31652 | G20: {=VLOOKUP(C20&"*",TEXT(Database!B:B,0),1,0)*1-C20*100000} -> 42091 | H20: =INT(DATEDIF(G20, DATE(2025,4,1), "D")/7) -> 522
B22: Kirimkan Kode Soal dan Kode Jawaban ke alamat : https://belajarexcel.id/xl-test/jawaban untuk mengecek hasil benar/salah
B24: Soal
B25: * Selesaikan Pertanyaan diatas dengan menggunakan Formula/Rumus Excel
B26: Selsaikan tanpa menambahkan atau menggunakan kolom bantuan atau Table bantu.
B28: 1 | C28: Isi Name berdasarkan ID dari SID Pada Sheet Database. ID adalah 6 digit pertama dari SID
B29: 2 | C29: Isi F/Name berdasarkan ID dari SID Pada Sheet Database
B30: 3 | C30: Isi D.O.B berdasarkan ID dari SID Pada Sheet Database
B31: 4 | C31: Isi Join Date Berdasarkan ID. Join Date adalah 5 digit angka terakhir di Nomor SID
C32: Join Date harus berupa Tanggal Valid
B33: 5 | C33: Isi Length of Service (Weeks) dengan lama bekerja dari Join date sampai tanggal 1 April 2025
C34: dalam format minggu bulat tanpa pecahan.
B39: https://belajarexcel.id/xl-test/

Sheet Database
A1: SID : | B1: 78314543254 | F1: =VLOOKUP("1*",Database!B$1:B$120,1,0) -> #N/A
C2: Name | D2: Ahmad
C3: F/Name | D3: Hassan
C4: D.O.B | D4: 33210
C5: Age | D5: 34
C6: Add: | D6: XYZ
A7: SID : | B7: 95511941619
C8: Name | D8: Fatima
C9: F/Name | D9: Khalid
C10: D.O.B | D10: 31178
C11: Age | D11: 39
C12: Add: | D12: DEF
A13: SID : | B13: 94390642356
C14: Name | D14: Yusuf
C15: F/Name | D15: Mohammad
C16: D.O.B | D16: 33773
C17: Age | D17: 32
C18: Add: | D18: GHI
A19: SID : | B19: 44032440142
C20: Name | D20: Ayesha
C21: F/Name | D21: Usman
C22: D.O.B | D22: 31833
C23: Age | D23: 38
C24: Add: | D24: JKL
A25: SID : | B25: 50246342803
C26: Name | D26: Ali
C27: F/Name | D27: Imran
C28: D.O.B | D28: 32760
C29: Age | D29: 35
C30: Add: | D30: MNO
A31: SID : | B31: 35043443013
C32: Name | D32: Sana
C33: F/Name | D33: Nasir
C34: D.O.B | D34: 33243
C35: Age | D35: 33
C36: Add: | D36: PQR
A37: SID : | B37: 48928142383
C38: Name | D38: Omar
C39: F/Name | D39: Salman
C40: D.O.B | D40: 34073
...

Sheet About
C6: XL-TEST adalah platform inovatif yang menyediakan latihan Excel interaktif dengan pemeriksaan otomatis,
C7: sehingga pengguna dapat langsung mengetahui jawaban yang benar maupun salah.
C10: Terdapat 5 Level soal :
D12: Easy Level | F12: (⭐)
D13: Medium Level | F13: (⭐⭐)
D14: Hard Level | F14: (⭐⭐⭐)
D15: Extreme Level | F15: (⭐⭐⭐⭐)
D16: Championship Level | F16: (⭐⭐⭐⭐⭐)
C19: Free Access
C20: https://belajarexcel.id/xl-test/

Sheet DF
A1: DEF | C1: Value | L1: 1 | M1: 2 | N1: 3 | O1: 4 | P1: 5
A2: HD2 | B2: 1 | C2: ='XL-Test'!D6 -> Komal | D2: ='XL-Test'!E6 -> Arif | E2: ='XL-Test'!F6 -> 31668 | F2: ='XL-Test'!G6 -> 40250 | G2: ='XL-Test'!H6 -> 785 | K2: 1 | L2: =SUBSTITUTE(_xlfn.FORMULATEXT('XL-Test'!D6),"$","") -> =XLOOKUP(C6;INT(Database!B1:B120/100000);Database!D2:D121;;0;1) | M2: =SUBSTITUTE(_xlfn.FORMULATEXT('XL-Test'!E6),"$","") -> =XLOOKUP(C6;INT(Database!B1:B120/100000);Database!D3:D122;;0;1) | N2: =SUBSTITUTE(_xlfn.FORMULATEXT('XL-Test'!F6),"$","") -> =XLOOKUP(C6;INT(Database!B1:B120/100000);Database!D4:D123;;0;1) | O2: =SUBSTITUTE(_xlfn.FORMULATEXT('XL-Test'!G6),"$","") -> =VLOOKUP(C6&"*";TEXT(Database!B:B;0);1;0)*1-C6*100000 | P2: =SUBSTITUTE(_xlfn.FORMULATEXT('XL-Test'!H6),"$","") -> =INT(DATEDIF(G6; DATE(2025;4;1); "D")/7)
A3: =A2&"|" -> HD2| | B3: 2 | C3: ='XL-Test'!D7 -> Hina | D3: ='XL-Test'!E7 -> Aslam | E3: ='XL-Test'!F7 -> 33286 | F3: ='XL-Test'!G7 -> 43421 | G3: ='XL-Test'!H7 -> 332 | K3: 2 | L3: =SUBSTITUTE(_xlfn.FORMULATEXT('XL-Test'!E6),"$","") -> =XLOOKUP(C6;INT(Database!B1:B120/100000);Database!D3:D122;;0;1)
B4: 3 | C4: ='XL-Test'!D8 -> Mariam | D4: ='XL-Test'!E8 -> Rashid | E4: ='XL-Test'!F8 -> 33807 | F4: ='XL-Test'!G8 -> 42665 | G4: ='XL-Test'!H8 -> 440 | K4: 3 | L4: =SUBSTITUTE(_xlfn.FORMULATEXT('XL-Test'!F6),"$","") -> =XLOOKUP(C6;INT(Database!B1:B120/100000);Database!D4:D123;;0;1)
B5: 4 | C5: ='XL-Test'!D9 -> Noor | D5: ='XL-Test'!E9 -> Ahmed | E5: ='XL-Test'!F9 -> 32435 | F5: ='XL-Test'!G9 -> 40927 | G5: ='XL-Test'!H9 -> 688 | K5: 4 | L5: =SUBSTITUTE(_xlfn.FORMULATEXT('XL-Test'!G6),"$","") -> =VLOOKUP(C6&"*";TEXT(Database!B:B;0);1;0)*1-C6*100000
B6: 5 | C6: ='XL-Test'!D10 -> Rehan | D6: ='XL-Test'!E10 -> Farooq | E6: ='XL-Test'!F10 -> 34881 | F6: ='XL-Test'!G10 -> 43282 | G6: ='XL-Test'!H10 -> 352 | K6: 5 | L6: =SUBSTITUTE(_xlfn.FORMULATEXT('XL-Test'!H6),"$","") -> =INT(DATEDIF(G6; DATE(2025;4;1); "D")/7)
B7: 6 | C7: ='XL-Test'!D11 -> Sana | D7: ='XL-Test'!E11 -> Nasir | E7: ='XL-Test'!F11 -> 33243 | F7: ='XL-Test'!G11 -> 43013 | G7: ='XL-Test'!H11 -> 390
B8: 7 | C8: ='XL-Test'!D12 -> Ayesha | D8: ='XL-Test'!E12 -> Usman | E8: ='XL-Test'!F12 -> 31833 | F8: ='XL-Test'!G12 -> 40142 | G8: ='XL-Test'!H12 -> 800
B9: 8 | C9: ='XL-Test'!D13 -> Omar | D9: ='XL-Test'!E13 -> Salman | E9: ='XL-Test'!F13 -> 34073 | F9: ='XL-Test'!G13 -> 42383 | G9: ='XL-Test'!H13 -> 480
B10: 9 | C10: ='XL-Test'!D14 -> Ali | D10: ='XL-Test'!E14 -> Imran | E10: ='XL-Test'!F14 -> 32760 | F10: ='XL-Test'!G14 -> 42803 | G10: ='XL-Test'!H14 -> 420
B11: 10 | C11: ='XL-Test'!D15 -> Ibrahim | D11: ='XL-Test'!E15 -> Hamid | E11: ='XL-Test'!F15 -> 32811 | F11: ='XL-Test'!G15 -> 40237 | G11: ='XL-Test'!H15 -> 787
B12: 11 | C12: ='XL-Test'!D16 -> Laila | D12: ='XL-Test'!E16 -> Murtaza | E12: ='XL-Test'!F16 -> 35158 | F12: ='XL-Test'!G16 -> 45691 | G12: ='XL-Test'!H16 -> 8
B13: 12 | C13: ='XL-Test'!D17 -> Usman | D13: ='XL-Test'!E17 -> Waqas | E13: ='XL-Test'!F17 -> 34496 | F13: ='XL-Test'!G17 -> 42411 | G13: ='XL-Test'!H17 -> 476
B14: 13 | C14: ='XL-Test'!D18 -> Noman | D14: ='XL-Test'!E18 -> Shahid | E14: ='XL-Test'!F18 -> 31816 | F14: ='XL-Test'!G18 -> 42377 | G14: ='XL-Test'!H18 -> 481
B15: 14 | C15: ='XL-Test'!D19 -> Ahmad | D15: ='XL-Test'!E19 -> Hassan | E15: ='XL-Test'!F19 -> 33210 | F15: ='XL-Test'!G19 -> 43254 | G15: ='XL-Test'!H19 -> 356
B16: 15 | C16: ='XL-Test'!D20 -> Zara | D16: ='XL-Test'!E20 -> Bilal | E16: ='XL-Test'!F20 -> 31652 | F16: ='XL-Test'!G20 -> 42091 | G16: ='XL-Test'!H20 -> 522
B18: Value | C18: =IFERROR(CODE(LEFT(C2))+CODE(LEFT(C3))+CODE(LEFT(C4))+CODE(LEFT(C5))+CODE(LEFT(C6))+CODE(LEFT(C7))+CODE(LEFT(C8))+CODE(LEFT(C9))+CODE(LEFT(C10))+CODE(LEFT(C11))+CODE(LEFT(C12))+CODE(LEFT(C13))+CODE(LEFT(C14))+CODE(LEFT(C15))+CODE(LEFT(C16)) +CODE(RIGHT(C3))+CODE(RIGHT(C5))+CODE(RIGHT(C7))+CODE(RIGHT(C9))+CODE(RIGHT(C11))+CODE(RIGHT(C12))+CODE(RIGHT(C15)) +CODE(MID(C3,2,1))+CODE(MID(C4,2,1))+CODE(MID(C6,2,1))+CODE(MID(C8,2,1))+CODE(MID(C10,2,1))+CODE(MID(C14,2,1)),0) -> 2514 | D18: =IFERROR(CODE(LEFT(D2))+CODE(LEFT(D3))+CODE(LEFT(D4))+CODE(LEFT(D5))+CODE(LEFT(D6))+CODE(LEFT(D7))+CODE(LEFT(D8))+CODE(LEFT(D9))+CODE(LEFT(D10))+CODE(LEFT(D11))+CODE(LEFT(D12))+CODE(LEFT(D13))+CODE(LEFT(D14))+CODE(LEFT(D15))+CODE(LEFT(D16)) +CODE(RIGHT(D3))+CODE(RIGHT(D5))+CODE(RIGHT(D7))+CODE(RIGHT(D9))+CODE(RIGHT(D11))+CODE(RIGHT(D12))+CODE(RIGHT(D15)) +CODE(MID(D3,2,1))+CODE(MID(D4,2,1))+CODE(MID(D6,2,1))+CODE(MID(D8,2,1))+CODE(MID(D10,2,1))+CODE(MID(D14,2,1)),0) -> 2500 | E18: =SUM(E2:E16) -> 497129 | F18: =SUM(F2:F16) -> 634947 | G18: =SUM(G2:G16)*100 -> 731700
A19: ** | C19: =IFERROR(DEC2HEX(IF(AND(NOT(OR(C2=0,C2="")),C25,C59),C18,C20)),"EEEE") -> 9D2 | D19: =IFERROR(DEC2HEX(IF(AND(NOT(OR(D2=0,D2="")),D25,D59),D18,D20)),"EEEE") -> 9C4 | E19: =IFERROR(DEC2HEX(IF(AND(NOT(OR(E2=0,E2="")),E25,E59),E18,E20)),"EEEE") -> 795E9 | F19: =IFERROR(DEC2HEX(IF(AND(NOT(OR(F2=0,F2="")),F25,F59),F18,F20)),"EEEE") -> 9B043 | G19: =IFERROR(DEC2HEX(IF(AND(NOT(OR(G2=0,G2="")),G25,G59),G18,G20)),"EEEE") -> B2A34
B20: Random | C20: 5941 | D20: 8808 | E20: 8352 | F20: 6360 | G20: 2301
B22: TRUE | C22: =LEFT(DEC2HEX(C20),2) -> 17 | D22: =LEFT(DEC2HEX(D20),2) -> 22 | E22: =LEFT(DEC2HEX(E20),2) -> 20 | F22: =LEFT(DEC2HEX(F20),2) -> 18 | G22: =LEFT(DEC2HEX(G20),2) -> 8F
B23: FALSE | C23: =RIGHT(DEC2HEX(C20),2) -> 35 | D23: =RIGHT(DEC2HEX(D20),2) -> 68 | E23: =RIGHT(DEC2HEX(E20),2) -> A0 | F23: =RIGHT(DEC2HEX(F20),2) -> D8 | G23: =RIGHT(DEC2HEX(G20),2) -> FD
B25: Cek Manual | C25: =AND(ISNUMBER(SEARCH("!B",L2)),ISNUMBER(SEARCH("!D",L2)),ISNUMBER(SEARCH(":",L2))) -> TRUE | D25: =AND(ISNUMBER(SEARCH("!B",M2)),ISNUMBER(SEARCH("!D",M2)),ISNUMBER(SEARCH(":",M2))) -> TRUE | E25: =AND(ISNUMBER(SEARCH("!B",N2)),ISNUMBER(SEARCH("!D",N2)),ISNUMBER(SEARCH(":",N2))) -> TRUE | F25: =AND(ISNUMBER(SEARCH("!B",O2)),ISNUMBER(SEARCH(":",N2))) -> TRUE | G25: =AND(ISNUMBER(SEARCH("=",P2)),ISNUMBER(SEARCH("(",P2))) -> TRUE
B27: Formula Cek | C27: =OR(AND(ISNUMBER(SEARCH("~"&CHAR(42),L2)),ISNUMBER(SEARCH("NDE",L2)),ISNUMBER(SEARCH("ATC",L2))),ISNUMBER(SEARCH("XLOO",L2))) -> TRUE | D27: =OR(AND(ISNUMBER(SEARCH("~"&CHAR(42),M2)),ISNUMBER(SEARCH("NDE",M2)),ISNUMBER(SEARCH("ATC",M2))),ISNUMBER(SEARCH("XLOO",M2))) -> TRUE | E27: =OR(AND(ISNUMBER(SEARCH("~"&CHAR(42),N2)),ISNUMBER(SEARCH("NDE",N2)),ISNUMBER(SEARCH("ATC",N2))),ISNUMBER(SEARCH("XLOO",N2))) -> TRUE | F27: =AND(ISNUMBER(SEARCH("~"&CHAR(42),O2)),OR(ISNUMBER(SEARCH("VL",O2)),AND(ISNUMBER(SEARCH("NDE",O2)),ISNUMBER(SEARCH("ATC",O2))))) -> TRUE | G27: =AND(OR(ISNUMBER(SEARCH("INT",P2)),ISNUMBER(SEARCH("ROUN",P2))),ISNUMBER(SEARCH("DATE",P2))) -> TRUE
A29: ** | C29: =IF(AND(C27,C33),C22,C23) -> 17 | D29: =IF(AND(D27,D33),D22,D23) -> 22 | E29: =IF(AND(E27,E33),E22,E23) -> 20 | F29: =IF(AND(F27,F33),F22,F23) -> 18 | G29: =IF(AND(G27,G33),G22,G23) -> 8F
B31: Cek Jml | C31: =IFERROR(LEN(L2)-LEN(SUBSTITUTE(L2,"(","")),99) -> 2 | D31: =IFERROR(LEN(M2)-LEN(SUBSTITUTE(M2,"(","")),99) -> 2 | E31: =IFERROR(LEN(N2)-LEN(SUBSTITUTE(N2,"(","")),99) -> 2 | F31: =IFERROR(LEN(O2)-LEN(SUBSTITUTE(O2,"(","")),99) -> 2 | G31: =IFERROR(LEN(P2)-LEN(SUBSTITUTE(P2,"(","")),99) -> 3
C32: 2 | D32: 2 | E32: 2 | F32: 2 | G32: 3
B33: Bol | C33: =(C31<=C32) -> TRUE | D33: =(D31<=D32) -> TRUE | E33: =(E31<=E32) -> TRUE | F33: =(F31<=F32) -> TRUE | G33: =(G31<=G32) -> TRUE
B36: 6 | C36: =LEN(_xlfn.FORMULATEXT('XL-Test'!D6)) -> 67 | D36: =LEN(_xlfn.FORMULATEXT('XL-Test'!E6)) -> 67 | E36: =LEN(_xlfn.FORMULATEXT('XL-Test'!F6)) -> 67 | F36: =LEN(_xlfn.FORMULATEXT('XL-Test'!G6)) -> 53 | G36: =LEN(_xlfn.FORMULATEXT('XL-Test'!H6)) -> 40
B37: 7 | C37: =LEN(_xlfn.FORMULATEXT('XL-Test'!D7)) -> 67 | D37: =LEN(_xlfn.FORMULATEXT('XL-Test'!E7)) -> 67 | E37: =LEN(_xlfn.FORMULATEXT('XL-Test'!F7)) -> 67 | F37: =LEN(_xlfn.FORMULATEXT('XL-Test'!G7)) -> 53 | G37: =LEN(_xlfn.FORMULATEXT('XL-Test'!H7)) -> 40
B38: 8 | C38: =LEN(_xlfn.FORMULATEXT('XL-Test'!D8)) -> 67 | D38: =LEN(_xlfn.FORMULATEXT('XL-Test'!E8)) -> 67 | E38: =LEN(_xlfn.FORMULATEXT('XL-Test'!F8)) -> 67 | F38: =LEN(_xlfn.FORMULATEXT('XL-Test'!G8)) -> 53 | G38: =LEN(_xlfn.FORMULATEXT('XL-Test'!H8)) -> 40
B39: 9 | C39: =LEN(_xlfn.FORMULATEXT('XL-Test'!D9)) -> 67 | D39: =LEN(_xlfn.FORMULATEXT('XL-Test'!E9)) -> 67 | E39: =LEN(_xlfn.FORMULATEXT('XL-Test'!F9)) -> 67 | F39: =LEN(_xlfn.FORMULATEXT('XL-Test'!G9)) -> 53 | G39: =LEN(_xlfn.FORMULATEXT('XL-Test'!H9)) -> 40
B40: x | C40: =AVERAGE(C36:C39) -> 67 | D40: =AVERAGE(D36:D39) -> 67 | E40: =AVERAGE(E36:E39) -> 67 | F40: =AVERAGE(F36:F39) -> 53 | G40: =AVERAGE(G36:G39) -> 40
B41: B | C41: =IFERROR(C40=C36,FALSE) -> TRUE | D41: =IFERROR(D40=D36,FALSE) -> TRUE | E41: =IFERROR(E40=E36,FALSE) -> TRUE | F41: =IFERROR(F40=F36,FALSE) -> TRUE | G41: =IFERROR(G40=G36,FALSE) -> TRUE
B44: 10 | C44: =LEN(_xlfn.FORMULATEXT('XL-Test'!D10)) -> 68 | D44: =LEN(_xlfn.FORMULATEXT('XL-Test'!E10)) -> 68 | E44: =LEN(_xlfn.FORMULATEXT('XL-Test'!F10)) -> 68 | F44: =LEN(_xlfn.FORMULATEXT('XL-Test'!G10)) -> 55 | G44: =LEN(_xlfn.FORMULATEXT('XL-Test'!H10)) -> 41
B45: 11 | C45: =LEN(_xlfn.FORMULATEXT('XL-Test'!D11)) -> 68 | D45: =LEN(_xlfn.FORMULATEXT('XL-Test'!E11)) -> 68 | E45: =LEN(_xlfn.FORMULATEXT('XL-Test'!F11)) -> 68 | F45: =LEN(_xlfn.FORMULATEXT('XL-Test'!G11)) -> 55 | G45: =LEN(_xlfn.FORMULATEXT('XL-Test'!H11)) -> 41
B46: 12 | C46: =LEN(_xlfn.FORMULATEXT('XL-Test'!D12)) -> 68 | D46: =LEN(_xlfn.FORMULATEXT('XL-Test'!E12)) -> 68 | E46: =LEN(_xlfn.FORMULATEXT('XL-Test'!F12)) -> 68 | F46: =LEN(_xlfn.FORMULATEXT('XL-Test'!G12)) -> 55 | G46: =LEN(_xlfn.FORMULATEXT('XL-Test'!H12)) -> 41
B47: 13 | C47: =LEN(_xlfn.FORMULATEXT('XL-Test'!D13)) -> 68 | D47: =LEN(_xlfn.FORMULATEXT('XL-Test'!E13)) -> 68 | E47: =LEN(_xlfn.FORMULATEXT('XL-Test'!F13)) -> 68 | F47: =LEN(_xlfn.FORMULATEXT('XL-Test'!G13)) -> 55 | G47: =LEN(_xlfn.FORMULATEXT('XL-Test'!H13)) -> 41
B48: 14 | C48: =LEN(_xlfn.FORMULATEXT('XL-Test'!D14)) -> 68 | D48: =LEN(_xlfn.FORMULATEXT('XL-Test'!E14)) -> 68 | E48: =LEN(_xlfn.FORMULATEXT('XL-Test'!F14)) -> 68 | F48: =LEN(_xlfn.FORMULATEXT('XL-Test'!G14)) -> 55 | G48: =LEN(_xlfn.FORMULATEXT('XL-Test'!H14)) -> 41
B49: 15 | C49: =LEN(_xlfn.FORMULATEXT('XL-Test'!D15)) -> 68 | D49: =LEN(_xlfn.FORMULATEXT('XL-Test'!E15)) -> 68 | E49: =LEN(_xlfn.FORMULATEXT('XL-Test'!F15)) -> 68 | F49: =LEN(_xlfn.FORMULATEXT('XL-Test'!G15)) -> 55 | G49: =LEN(_xlfn.FORMULATEXT('XL-Test'!H15)) -> 41
B50: 16 | C50: =LEN(_xlfn.FORMULATEXT('XL-Test'!D16)) -> 68 | D50: =LEN(_xlfn.FORMULATEXT('XL-Test'!E16)) -> 68 | E50: =LEN(_xlfn.FORMULATEXT('XL-Test'!F16)) -> 68 | F50: =LEN(_xlfn.FORMULATEXT('XL-Test'!G16)) -> 55 | G50: =LEN(_xlfn.FORMULATEXT('XL-Test'!H16)) -> 41
...
