Workbook
Name kamujuga: DF!$C$48
Name kode_jawaban: DF!$C$52

Sheet Soal
A18: KODE SOAL | C18: SBEH011 | E18: KODE JAWABAN | G18: =kode_jawaban -> HK1|F4-FFC81;25-F58;2A-66B5F20;18-BAC48;DF-6A412C;22-501BD0;12-192D50;1B-4864D0
A20: Intruksi
B22: Hard Level - Latihan Soal Excel MIN MAX Level Hard
B24: Soal : | C24: Gunakan Fungsi Excel (Function) MIN dan atau MAX atau MINIFS (MIN+IF) atau MAXIFS (MAX+IF) pada soal-soal berikut ini :
B25: 1 | C25: Kapan tanggal terakhir kerja dari masing masing nama
B26: 2 | C26: Hitung berapa jumlah jam kerja dari masing masing nama diambil dari tanggal terbaru
B27: 3 | C27: Hitung berapa Gaji kotor dengan ketentuan sebagai berikut :
D28: Tarif Kerja Normal: Rp25.000 /jam (untuk 160 jam pertama).
D29: Tarif Lembur: Rp35.000 /jam (untuk kelebihan jam di atas 160).
B30: 4 | C30: Tunjangan anak sebesar Rp15.000 per anak, maximal 3 anak saja
B31: 5 | C31: Hitung berapa nilai asuransi , asuransi adalah 5% dari Gaji kotor dengan minimal nilai pembayaran asuransi sebesar Rp250.000
B32: 6 | C32: Bonus diberikan sebesar Rp350.000 untuk karyawan dengan gaji kotor dibawah Rp5.000.000
B33: 7 | C33: Potongan Infak sebesar Rp150.000 bagi karyawan dengan Gaji kotor diatas Rp4.000.000
B34: 8 | C34: PPH sebesar 5% untuk Gaji dibawah Rp5.000.000 dan selebihnya dikenakan tarif 2% dari Gaji Kotor, dengan tarif PPH minimal Rp100.000
D35: Misalnya Gaji kotor Rp6.000.000 maka Rp5.000.000 terkena PPH 5% dan Rp1.000.000 terkena PPH 2%, dengan minimal Nilai PPH adalah Rp100.000
C37: Sudah selesai mengerjakan? kirim Kode Soal dan Kode Jawaban diatas ke alamat : https://belajarexcel.id/xl-test/jawaban untuk mengecek hasilnya
C38: atau klik tombol disamping
A43: Data Gaji Karyawan
E46: 1 | F46: 2 | G46: 3 | H46: 4 | I46: 5 | J46: 6 | K46: 7 | L46: 8
A47: No | B47: NIK | C47: Nama | D47: Jml Anak | E47: Tanggal Terakhir Kerja | F47: Akumulasi Jam Kerja | G47: Gaji Kotor | H47: Tunjangan Anak | I47: Asuransi | J47: Bonus | K47: Potongan Infak | L47: PPH
A48: Example | B48: ID001 | C48: Austin Cooke | D48: 4 | E48: 45608 | F48: 235 | G48: 6625000 | H48: 45000 | I48: 331250 | J48: 0 | K48: 150000 | L48: 282500
A50: 1 | B50: ID002 | C50: Randy Beasley | D50: 3 | E50: =_xlfn.MAXIFS('Data Kerja'!$D$4:$D$46,'Data Kerja'!$B$4:$B$46,Soal!B50) -> 45625 | F50: =_xlfn.MAXIFS('Data Kerja'!$E$4:$E$46,'Data Kerja'!$B$4:$B$46,Soal!B50,'Data Kerja'!$D$4:$D$46,Soal!E50) -> 227 | G50: =MIN(F50,160)*25000 + MAX(0,F50-160)*35000 -> 6345000 | H50: =MIN(3,D50)*15000 -> 45000 | I50: =MAX(250000,G50*5%) -> 317250 | J50: =MIN(350000,MAX(0,G50<5000000)*350000) -> 0 | K50: =MAX(150000*(G50>4000000),0) -> 150000 | L50: =MAX(100000,MIN(G50,5000000)*5% + MAX(0,G50-5000000)*2%) -> 276900
A51: 2 | B51: ID003 | C51: Kelly Williams | D51: 5 | E51: =_xlfn.MAXIFS('Data Kerja'!$D$4:$D$46,'Data Kerja'!$B$4:$B$46,Soal!B51) -> 45517 | F51: =_xlfn.MAXIFS('Data Kerja'!$E$4:$E$46,'Data Kerja'!$B$4:$B$46,Soal!B51,'Data Kerja'!$D$4:$D$46,Soal!E51) -> 348 | G51: =MIN(F51,160)*25000 + MAX(0,F51-160)*35000 -> 10580000 | H51: =MIN(3,D51)*15000 -> 45000 | I51: =MAX(250000,G51*5%) -> 529000 | J51: =MIN(350000,MAX(0,G51<5000000)*350000) -> 0 | K51: =MAX(150000*(G51>4000000),0) -> 150000 | L51: =MAX(100000,MIN(G51,5000000)*5% + MAX(0,G51-5000000)*2%) -> 361600
A52: 3 | B52: ID004 | C52: Steven Daniel | D52: 3 | E52: =_xlfn.MAXIFS('Data Kerja'!$D$4:$D$46,'Data Kerja'!$B$4:$B$46,Soal!B52) -> 45443 | F52: =_xlfn.MAXIFS('Data Kerja'!$E$4:$E$46,'Data Kerja'!$B$4:$B$46,Soal!B52,'Data Kerja'!$D$4:$D$46,Soal!E52) -> 130 | G52: =MIN(F52,160)*25000 + MAX(0,F52-160)*35000 -> 3250000 | H52: =MIN(3,D52)*15000 -> 45000 | I52: =MAX(250000,G52*5%) -> 250000 | J52: =MIN(350000,MAX(0,G52<5000000)*350000) -> 350000 | K52: =MAX(150000*(G52>4000000),0) -> 0 | L52: =MAX(100000,MIN(G52,5000000)*5% + MAX(0,G52-5000000)*2%) -> 162500
A53: 4 | B53: ID005 | C53: Anthony Sharp | D53: 5 | E53: =_xlfn.MAXIFS('Data Kerja'!$D$4:$D$46,'Data Kerja'!$B$4:$B$46,Soal!B53) -> 45596 | F53: =_xlfn.MAXIFS('Data Kerja'!$E$4:$E$46,'Data Kerja'!$B$4:$B$46,Soal!B53,'Data Kerja'!$D$4:$D$46,Soal!E53) -> 56 | G53: =MIN(F53,160)*25000 + MAX(0,F53-160)*35000 -> 1400000 | H53: =MIN(3,D53)*15000 -> 45000 | I53: =MAX(250000,G53*5%) -> 250000 | J53: =MIN(350000,MAX(0,G53<5000000)*350000) -> 350000 | K53: =MAX(150000*(G53>4000000),0) -> 0 | L53: =MAX(100000,MIN(G53,5000000)*5% + MAX(0,G53-5000000)*2%) -> 100000
A54: 5 | B54: ID006 | C54: Richard Miller | D54: 4 | E54: =_xlfn.MAXIFS('Data Kerja'!$D$4:$D$46,'Data Kerja'!$B$4:$B$46,Soal!B54) -> 45622 | F54: =_xlfn.MAXIFS('Data Kerja'!$E$4:$E$46,'Data Kerja'!$B$4:$B$46,Soal!B54,'Data Kerja'!$D$4:$D$46,Soal!E54) -> 411 | G54: =MIN(F54,160)*25000 + MAX(0,F54-160)*35000 -> 12785000 | H54: =MIN(3,D54)*15000 -> 45000 | I54: =MAX(250000,G54*5%) -> 639250 | J54: =MIN(350000,MAX(0,G54<5000000)*350000) -> 0 | K54: =MAX(150000*(G54>4000000),0) -> 150000 | L54: =MAX(100000,MIN(G54,5000000)*5% + MAX(0,G54-5000000)*2%) -> 405700
A55: 6 | B55: ID007 | C55: Elizabeth White | D55: 5 | E55: =_xlfn.MAXIFS('Data Kerja'!$D$4:$D$46,'Data Kerja'!$B$4:$B$46,Soal!B55) -> 45619 | F55: =_xlfn.MAXIFS('Data Kerja'!$E$4:$E$46,'Data Kerja'!$B$4:$B$46,Soal!B55,'Data Kerja'!$D$4:$D$46,Soal!E55) -> 120 | G55: =MIN(F55,160)*25000 + MAX(0,F55-160)*35000 -> 3000000 | H55: =MIN(3,D55)*15000 -> 45000 | I55: =MAX(250000,G55*5%) -> 250000 | J55: =MIN(350000,MAX(0,G55<5000000)*350000) -> 350000 | K55: =MAX(150000*(G55>4000000),0) -> 0 | L55: =MAX(100000,MIN(G55,5000000)*5% + MAX(0,G55-5000000)*2%) -> 150000
A56: 7 | B56: ID008 | C56: Brian Tucker | D56: 3 | E56: =_xlfn.MAXIFS('Data Kerja'!$D$4:$D$46,'Data Kerja'!$B$4:$B$46,Soal!B56) -> 45628 | F56: =_xlfn.MAXIFS('Data Kerja'!$E$4:$E$46,'Data Kerja'!$B$4:$B$46,Soal!B56,'Data Kerja'!$D$4:$D$46,Soal!E56) -> 162 | G56: =MIN(F56,160)*25000 + MAX(0,F56-160)*35000 -> 4070000 | H56: =MIN(3,D56)*15000 -> 45000 | I56: =MAX(250000,G56*5%) -> 250000 | J56: =MIN(350000,MAX(0,G56<5000000)*350000) -> 350000 | K56: =MAX(150000*(G56>4000000),0) -> 150000 | L56: =MAX(100000,MIN(G56,5000000)*5% + MAX(0,G56-5000000)*2%) -> 203500
A57: 8 | B57: ID009 | C57: Elizabeth Villarreal | D57: 5 | E57: =_xlfn.MAXIFS('Data Kerja'!$D$4:$D$46,'Data Kerja'!$B$4:$B$46,Soal!B57) -> 45585 | F57: =_xlfn.MAXIFS('Data Kerja'!$E$4:$E$46,'Data Kerja'!$B$4:$B$46,Soal!B57,'Data Kerja'!$D$4:$D$46,Soal!E57) -> 184 | G57: =MIN(F57,160)*25000 + MAX(0,F57-160)*35000 -> 4840000 | H57: =MIN(3,D57)*15000 -> 45000 | I57: =MAX(250000,G57*5%) -> 250000 | J57: =MIN(350000,MAX(0,G57<5000000)*350000) -> 350000 | K57: =MAX(150000*(G57>4000000),0) -> 150000 | L57: =MAX(100000,MIN(G57,5000000)*5% + MAX(0,G57-5000000)*2%) -> 242000
A58: 9 | B58: ID010 | C58: Norman Beck | D58: 1 | E58: =_xlfn.MAXIFS('Data Kerja'!$D$4:$D$46,'Data Kerja'!$B$4:$B$46,Soal!B58) -> 45569 | F58: =_xlfn.MAXIFS('Data Kerja'!$E$4:$E$46,'Data Kerja'!$B$4:$B$46,Soal!B58,'Data Kerja'!$D$4:$D$46,Soal!E58) -> 98 | G58: =MIN(F58,160)*25000 + MAX(0,F58-160)*35000 -> 2450000 | H58: =MIN(3,D58)*15000 -> 15000 | I58: =MAX(250000,G58*5%) -> 250000 | J58: =MIN(350000,MAX(0,G58<5000000)*350000) -> 350000 | K58: =MAX(150000*(G58>4000000),0) -> 0 | L58: =MAX(100000,MIN(G58,5000000)*5% + MAX(0,G58-5000000)*2%) -> 122500
A59: 10 | B59: ID011 | C59: Sheila Daniels | D59: 5 | E59: =_xlfn.MAXIFS('Data Kerja'!$D$4:$D$46,'Data Kerja'!$B$4:$B$46,Soal!B59) -> 45456 | F59: =_xlfn.MAXIFS('Data Kerja'!$E$4:$E$46,'Data Kerja'!$B$4:$B$46,Soal!B59,'Data Kerja'!$D$4:$D$46,Soal!E59) -> 145 | G59: =MIN(F59,160)*25000 + MAX(0,F59-160)*35000 -> 3625000 | H59: =MIN(3,D59)*15000 -> 45000 | I59: =MAX(250000,G59*5%) -> 250000 | J59: =MIN(350000,MAX(0,G59<5000000)*350000) -> 350000 | K59: =MAX(150000*(G59>4000000),0) -> 0 | L59: =MAX(100000,MIN(G59,5000000)*5% + MAX(0,G59-5000000)*2%) -> 181250
A60: 11 | B60: ID012 | C60: Jessica Burton | D60: 0 | E60: =_xlfn.MAXIFS('Data Kerja'!$D$4:$D$46,'Data Kerja'!$B$4:$B$46,Soal!B60) -> 45449 | F60: =_xlfn.MAXIFS('Data Kerja'!$E$4:$E$46,'Data Kerja'!$B$4:$B$46,Soal!B60,'Data Kerja'!$D$4:$D$46,Soal!E60) -> 140 | G60: =MIN(F60,160)*25000 + MAX(0,F60-160)*35000 -> 3500000 | H60: =MIN(3,D60)*15000 -> 0 | I60: =MAX(250000,G60*5%) -> 250000 | J60: =MIN(350000,MAX(0,G60<5000000)*350000) -> 350000 | K60: =MAX(150000*(G60>4000000),0) -> 0 | L60: =MAX(100000,MIN(G60,5000000)*5% + MAX(0,G60-5000000)*2%) -> 175000
A61: 12 | B61: ID013 | C61: Melissa Garcia | D61: 2 | E61: =_xlfn.MAXIFS('Data Kerja'!$D$4:$D$46,'Data Kerja'!$B$4:$B$46,Soal!B61) -> 45483 | F61: =_xlfn.MAXIFS('Data Kerja'!$E$4:$E$46,'Data Kerja'!$B$4:$B$46,Soal!B61,'Data Kerja'!$D$4:$D$46,Soal!E61) -> 58 | G61: =MIN(F61,160)*25000 + MAX(0,F61-160)*35000 -> 1450000 | H61: =MIN(3,D61)*15000 -> 30000 | I61: =MAX(250000,G61*5%) -> 250000 | J61: =MIN(350000,MAX(0,G61<5000000)*350000) -> 350000 | K61: =MAX(150000*(G61>4000000),0) -> 0 | L61: =MAX(100000,MIN(G61,5000000)*5% + MAX(0,G61-5000000)*2%) -> 100000
... A65: 16 | B65: ID017 | C65: Brenda Chan | D65: 1 | E65: =_xlfn.MAXIFS('Data Kerja'!$D$4:$D$46,'Data Kerja'!$B$4:$B$46,Soal!B65) -> 45548 | F65: =_xlfn.MAXIFS('Data Kerja'!$E$4:$E$46,'Data Kerja'!$B$4:$B$46,Soal!B65,'Data Kerja'!$D$4:$D$46,Soal!E65) -> 86 | G65: =MIN(F65,160)*25000 + MAX(0,F65-160)*35000 -> 2150000 | H65: =MIN(3,D65)*15000 -> 15000 | I65: =MAX(250000,G65*5%) -> 250000 | J65: =MIN(350000,MAX(0,G65<5000000)*350000) -> 350000 | K65: =MAX(150000*(G65>4000000),0) -> 0 | L65: =MAX(100000,MIN(G65,5000000)*5% + MAX(0,G65-5000000)*2%) -> 107500
A70: Dilarang mengubah Table atau Menambah Table Baru atau Menambah Kolom Bantuan !!, Gunakan Table seperti yang sudah di sediakan soal.

Sheet Data Kerja
B1: Update Akumulasi Jam Kerja
A3: No | B3: NIK | C3: Nama | D3: Tanggal Update | E3: Akumulasi Jam Kerja
A4: 1 | B4: ID003 | C4: Kelly Williams | D4: 45309 | E4: 48
A5: 2 | B5: ID001 | C5: Austin Cooke | D5: 45320 | E5: 65
A6: 3 | B6: ID012 | C6: Jessica Burton | D6: 45328 | E6: 43
A7: 4 | B7: ID008 | C7: Brian Tucker | D7: 45329 | E7: 35
A8: 5 | B8: ID003 | C8: Kelly Williams | D8: 45334 | E8: 88
A9: 6 | B9: ID004 | C9: Steven Daniel | D9: 45361 | E9: 63
A10: 7 | B10: ID002 | C10: Randy Beasley | D10: 45387 | E10: 59
A11: 8 | B11: ID015 | C11: Wayne Harris | D11: 45395 | E11: 55
A12: 9 | B12: ID011 | C12: Sheila Daniels | D12: 45411 | E12: 45
A13: 10 | B13: ID007 | C13: Elizabeth White | D13: 45415 | E13: 64
A14: 11 | B14: ID014 | C14: Veronica Wilson | D14: 45422 | E14: 33
A15: 12 | B15: ID006 | C15: Richard Miller | D15: 45438 | E15: 43
... A46: 43 | B46: ID016 | C46: Stanley Dorsey | D46: 45642 | E46: 246

Sheet About
I6: XL-TEST adalah platform inovatif yang menyediakan latihan Excel interaktif dengan pemeriksaan otomatis,
I7: sehingga pengguna dapat langsung mengetahui jawaban yang benar maupun salah.
I10: Terdapat 5 Level soal :
J12: Easy Level | L12: (⭐)
J13: Medium Level | L13: (⭐⭐)
J14: Hard Level | L14: (⭐⭐⭐)
J15: Extreme Level | L15: (⭐⭐⭐⭐)
J16: Championship Level | L16: (⭐⭐⭐⭐⭐)
B17: Saya adalah seorang Excel Holic yang percaya bahwa setiap angka memiliki cerita yang bisa ditemukan dengan cara yang tepat. | I17: Free Access
B18: “Excel bukan cuma soal kerjaan tapi juga hobi yang aku nikmati.” | I18: https://belajarexcel.id/xl-test/
B19: Contact :
B20: 🌐 Web | C20: https://setiadi.me
B21: 🪡threads | C21: https://www.threads.com/@andisetiadi
D27: Perlu Video Penjelasan atau Kunci Jawaban ?
D28: Scan barcode atau kunjungi
D29: https://lynk.id/setiadi/page/jawaban-xl-test

Sheet DF
A1: DEF | C1: 1 | D1: 2 | E1: 3 | F1: 4 | G1: 5 | H1: 6 | I1: 7 | J1: 8 | L1: 1 | M1: 2 | N1: 3 | O1: 4 | P1: 5 | Q1: 6 | R1: 7 | S1: 8 | W1: 1 | X1: 2 | Y1: 3 | Z1: 4 | AA1: 5 | AB1: 6 | AC1: 7 | AD1: 8
A2: HK1 | B2: 1 | C2: =Soal!E50 -> 45625 | D2: =Soal!F50 -> 227 | E2: =Soal!G50 -> 6345000 | F2: =Soal!H50 -> 45000 | G2: =Soal!I50 -> 317250 | H2: =Soal!J50 -> 0 | I2: =Soal!K50 -> 150000 | J2: =Soal!L50 -> 276900 | L2: =LEN(_xlfn.FORMULATEXT(Soal!E50)) -> 65 | M2: =LEN(_xlfn.FORMULATEXT(Soal!F50)) -> 98 | N2: =LEN(_xlfn.FORMULATEXT(Soal!G50)) -> 42 | O2: =LEN(_xlfn.FORMULATEXT(Soal!H50)) -> 17 | P2: =LEN(_xlfn.FORMULATEXT(Soal!I50)) -> 19 | Q2: =LEN(_xlfn.FORMULATEXT(Soal!J50)) -> 38 | R2: =LEN(_xlfn.FORMULATEXT(Soal!K50)) -> 28 | S2: =LEN(_xlfn.FORMULATEXT(Soal!L50)) -> 56 | V2: 1 | W2: =SUBSTITUTE(_xlfn.FORMULATEXT(Soal!E50),"$","") -> =MAXIFS('Data Kerja'!D4:D46;'Data Kerja'!B4:B46;Soal!B50) | X2: =SUBSTITUTE(_xlfn.FORMULATEXT(Soal!F50),"$","") -> =MAXIFS('Data Kerja'!E4:E46;'Data Kerja'!B4:B46;Soal!B50;'Data Kerja'!D4:D46;Soal!E50) | Y2: =SUBSTITUTE(_xlfn.FORMULATEXT(Soal!G50),"$","") -> =MIN(F50;160)*25000 + MAX(0;F50-160)*35000 | Z2: =SUBSTITUTE(_xlfn.FORMULATEXT(Soal!H50),"$","") -> =MIN(3;D50)*15000 | AA2: =SUBSTITUTE(_xlfn.FORMULATEXT(Soal!I50),"$","") -> =MAX(250000;G50*5%) | AB2: =SUBSTITUTE(_xlfn.FORMULATEXT(Soal!J50),"$","") -> =MIN(350000;MAX(0;G50<5000000)*350000) | AC2: =SUBSTITUTE(_xlfn.FORMULATEXT(Soal!K50),"$","") -> =MAX(150000*(G50>4000000);0) | AD2: =SUBSTITUTE(_xlfn.FORMULATEXT(Soal!L50),"$","") -> =MAX(100000;MIN(G50;5000000)*5% + MAX(0;G50-5000000)*2%)
B3: 2 | C3: =Soal!E51 -> 45517 | D3: =Soal!F51 -> 348 | E3: =Soal!G51 -> 10580000 | F3: =Soal!H51 -> 45000 | G3: =Soal!I51 -> 529000 | H3: =Soal!J51 -> 0 | I3: =Soal!K51 -> 150000 | J3: =Soal!L51 -> 361600 | L3: =LEN(_xlfn.FORMULATEXT(Soal!E51)) -> 65 | M3: =LEN(_xlfn.FORMULATEXT(Soal!F51)) -> 98 | N3: =LEN(_xlfn.FORMULATEXT(Soal!G51)) -> 42 | O3: =LEN(_xlfn.FORMULATEXT(Soal!H51)) -> 17 | P3: =LEN(_xlfn.FORMULATEXT(Soal!I51)) -> 19 | Q3: =LEN(_xlfn.FORMULATEXT(Soal!J51)) -> 38 | R3: =LEN(_xlfn.FORMULATEXT(Soal!K51)) -> 28 | S3: =LEN(_xlfn.FORMULATEXT(Soal!L51)) -> 56 | V3: 2 | W3: =SUBSTITUTE(_xlfn.FORMULATEXT(Soal!F50),"$","") -> =MAXIFS('Data Kerja'!E4:E46;'Data Kerja'!B4:B46;Soal!B50;'Data Kerja'!D4:D46;Soal!E50)
B4: 3 | C4: =Soal!E52 -> 45443 | D4: =Soal!F52 -> 130 | E4: =Soal!G52 -> 3250000 | F4: =Soal!H52 -> 45000 | G4: =Soal!I52 -> 250000 | H4: =Soal!J52 -> 350000 | I4: =Soal!K52 -> 0 | J4: =Soal!L52 -> 162500 | L4: =LEN(_xlfn.FORMULATEXT(Soal!E52)) -> 65 | M4: =LEN(_xlfn.FORMULATEXT(Soal!F52)) -> 98 | N4: =LEN(_xlfn.FORMULATEXT(Soal!G52)) -> 42 | O4: =LEN(_xlfn.FORMULATEXT(Soal!H52)) -> 17 | P4: =LEN(_xlfn.FORMULATEXT(Soal!I52)) -> 19 | Q4: =LEN(_xlfn.FORMULATEXT(Soal!J52)) -> 38 | R4: =LEN(_xlfn.FORMULATEXT(Soal!K52)) -> 28 | S4: =LEN(_xlfn.FORMULATEXT(Soal!L52)) -> 56 | V4: 3 | W4: =SUBSTITUTE(_xlfn.FORMULATEXT(Soal!G50),"$","") -> =MIN(F50;160)*25000 + MAX(0;F50-160)*35000
B5: 4 | C5: =Soal!E53 -> 45596 | D5: =Soal!F53 -> 56 | E5: =Soal!G53 -> 1400000 | F5: =Soal!H53 -> 45000 | G5: =Soal!I53 -> 250000 | H5: =Soal!J53 -> 350000 | I5: =Soal!K53 -> 0 | J5: =Soal!L53 -> 100000 | L5: =LEN(_xlfn.FORMULATEXT(Soal!E53)) -> 65 | M5: =LEN(_xlfn.FORMULATEXT(Soal!F53)) -> 98 | N5: =LEN(_xlfn.FORMULATEXT(Soal!G53)) -> 42 | O5: =LEN(_xlfn.FORMULATEXT(Soal!H53)) -> 17 | P5: =LEN(_xlfn.FORMULATEXT(Soal!I53)) -> 19 | Q5: =LEN(_xlfn.FORMULATEXT(Soal!J53)) -> 38 | R5: =LEN(_xlfn.FORMULATEXT(Soal!K53)) -> 28 | S5: =LEN(_xlfn.FORMULATEXT(Soal!L53)) -> 56 | V5: 4 | W5: =SUBSTITUTE(_xlfn.FORMULATEXT(Soal!H50),"$","") -> =MIN(3;D50)*15000
B6: 5 | C6: =Soal!E54 -> 45622 | D6: =Soal!F54 -> 411 | E6: =Soal!G54 -> 12785000 | F6: =Soal!H54 -> 45000 | G6: =Soal!I54 -> 639250 | H6: =Soal!J54 -> 0 | I6: =Soal!K54 -> 150000 | J6: =Soal!L54 -> 405700 | L6: =LEN(_xlfn.FORMULATEXT(Soal!E54)) -> 65 | M6: =LEN(_xlfn.FORMULATEXT(Soal!F54)) -> 98 | N6: =LEN(_xlfn.FORMULATEXT(Soal!G54)) -> 42 | O6: =LEN(_xlfn.FORMULATEXT(Soal!H54)) -> 17 | P6: =LEN(_xlfn.FORMULATEXT(Soal!I54)) -> 19 | Q6: =LEN(_xlfn.FORMULATEXT(Soal!J54)) -> 38 | R6: =LEN(_xlfn.FORMULATEXT(Soal!K54)) -> 28 | S6: =LEN(_xlfn.FORMULATEXT(Soal!L54)) -> 56 | V6: 5 | W6: =SUBSTITUTE(_xlfn.FORMULATEXT(Soal!I50),"$","") -> =MAX(250000;G50*5%)
B7: 6 | C7: =Soal!E55 -> 45619 | D7: =Soal!F55 -> 120 | E7: =Soal!G55 -> 3000000 | F7: =Soal!H55 -> 45000 | G7: =Soal!I55 -> 250000 | H7: =Soal!J55 -> 350000 | I7: =Soal!K55 -> 0 | J7: =Soal!L55 -> 150000 | L7: =LEN(_xlfn.FORMULATEXT(Soal!E55)) -> 65 | M7: =LEN(_xlfn.FORMULATEXT(Soal!F55)) -> 98 | N7: =LEN(_xlfn.FORMULATEXT(Soal!G55)) -> 42 | O7: =LEN(_xlfn.FORMULATEXT(Soal!H55)) -> 17 | P7: =LEN(_xlfn.FORMULATEXT(Soal!I55)) -> 19 | Q7: =LEN(_xlfn.FORMULATEXT(Soal!J55)) -> 38 | R7: =LEN(_xlfn.FORMULATEXT(Soal!K55)) -> 28 | S7: =LEN(_xlfn.FORMULATEXT(Soal!L55)) -> 56 | V7: 6 | W7: =SUBSTITUTE(_xlfn.FORMULATEXT(Soal!J50),"$","") -> =MIN(350000;MAX(0;G50<5000000)*350000)
B8: 7 | C8: =Soal!E56 -> 45628 | D8: =Soal!F56 -> 162 | E8: =Soal!G56 -> 4070000 | F8: =Soal!H56 -> 45000 | G8: =Soal!I56 -> 250000 | H8: =Soal!J56 -> 350000 | I8: =Soal!K56 -> 150000 | J8: =Soal!L56 -> 203500 | L8: =LEN(_xlfn.FORMULATEXT(Soal!E56)) -> 65 | M8: =LEN(_xlfn.FORMULATEXT(Soal!F56)) -> 98 | N8: =LEN(_xlfn.FORMULATEXT(Soal!G56)) -> 42 | O8: =LEN(_xlfn.FORMULATEXT(Soal!H56)) -> 17 | P8: =LEN(_xlfn.FORMULATEXT(Soal!I56)) -> 19 | Q8: =LEN(_xlfn.FORMULATEXT(Soal!J56)) -> 38 | R8: =LEN(_xlfn.FORMULATEXT(Soal!K56)) -> 28 | S8: =LEN(_xlfn.FORMULATEXT(Soal!L56)) -> 56 | V8: 7 | W8: =SUBSTITUTE(_xlfn.FORMULATEXT(Soal!K50),"$","") -> =MAX(150000*(G50>4000000);0)
B9: 8 | C9: =Soal!E57 -> 45585 | D9: =Soal!F57 -> 184 | E9: =Soal!G57 -> 4840000 | F9: =Soal!H57 -> 45000 | G9: =Soal!I57 -> 250000 | H9: =Soal!J57 -> 350000 | I9: =Soal!K57 -> 150000 | J9: =Soal!L57 -> 242000 | L9: =LEN(_xlfn.FORMULATEXT(Soal!E57)) -> 65 | M9: =LEN(_xlfn.FORMULATEXT(Soal!F57)) -> 98 | N9: =LEN(_xlfn.FORMULATEXT(Soal!G57)) -> 42 | O9: =LEN(_xlfn.FORMULATEXT(Soal!H57)) -> 17 | P9: =LEN(_xlfn.FORMULATEXT(Soal!I57)) -> 19 | Q9: =LEN(_xlfn.FORMULATEXT(Soal!J57)) -> 38 | R9: =LEN(_xlfn.FORMULATEXT(Soal!K57)) -> 28 | S9: =LEN(_xlfn.FORMULATEXT(Soal!L57)) -> 56 | V9: 8 | W9: =SUBSTITUTE(_xlfn.FORMULATEXT(Soal!L50),"$","") -> =MAX(100000;MIN(G50;5000000)*5% + MAX(0;G50-5000000)*2%)
B10: 9 | C10: =Soal!E58 -> 45569 | D10: =Soal!F58 -> 98 | E10: =Soal!G58 -> 2450000 | F10: =Soal!H58 -> 15000 | G10: =Soal!I58 -> 250000 | H10: =Soal!J58 -> 350000 | I10: =Soal!K58 -> 0 | J10: =Soal!L58 -> 122500 | L10: =LEN(_xlfn.FORMULATEXT(Soal!E58)) -> 65 | M10: =LEN(_xlfn.FORMULATEXT(Soal!F58)) -> 98 | N10: =LEN(_xlfn.FORMULATEXT(Soal!G58)) -> 42 | O10: =LEN(_xlfn.FORMULATEXT(Soal!H58)) -> 17 | P10: =LEN(_xlfn.FORMULATEXT(Soal!I58)) -> 19 | Q10: =LEN(_xlfn.FORMULATEXT(Soal!J58)) -> 38 | R10: =LEN(_xlfn.FORMULATEXT(Soal!K58)) -> 28 | S10: =LEN(_xlfn.FORMULATEXT(Soal!L58)) -> 56
B11: 10 | C11: =Soal!E59 -> 45456 | D11: =Soal!F59 -> 145 | E11: =Soal!G59 -> 3625000 | F11: =Soal!H59 -> 45000 | G11: =Soal!I59 -> 250000 | H11: =Soal!J59 -> 350000 | I11: =Soal!K59 -> 0 | J11: =Soal!L59 -> 181250 | L11: =LEN(_xlfn.FORMULATEXT(Soal!E59)) -> 65 | M11: =LEN(_xlfn.FORMULATEXT(Soal!F59)) -> 98 | N11: =LEN(_xlfn.FORMULATEXT(Soal!G59)) -> 42 | O11: =LEN(_xlfn.FORMULATEXT(Soal!H59)) -> 17 | P11: =LEN(_xlfn.FORMULATEXT(Soal!I59)) -> 19 | Q11: =LEN(_xlfn.FORMULATEXT(Soal!J59)) -> 38 | R11: =LEN(_xlfn.FORMULATEXT(Soal!K59)) -> 28 | S11: =LEN(_xlfn.FORMULATEXT(Soal!L59)) -> 56
B12: 11 | C12: =Soal!E60 -> 45449 | D12: =Soal!F60 -> 140 | E12: =Soal!G60 -> 3500000 | F12: =Soal!H60 -> 0 | G12: =Soal!I60 -> 250000 | H12: =Soal!J60 -> 350000 | I12: =Soal!K60 -> 0 | J12: =Soal!L60 -> 175000 | L12: =LEN(_xlfn.FORMULATEXT(Soal!E60)) -> 65 | M12: =LEN(_xlfn.FORMULATEXT(Soal!F60)) -> 98 | N12: =LEN(_xlfn.FORMULATEXT(Soal!G60)) -> 42 | O12: =LEN(_xlfn.FORMULATEXT(Soal!H60)) -> 17 | P12: =LEN(_xlfn.FORMULATEXT(Soal!I60)) -> 19 | Q12: =LEN(_xlfn.FORMULATEXT(Soal!J60)) -> 38 | R12: =LEN(_xlfn.FORMULATEXT(Soal!K60)) -> 28 | S12: =LEN(_xlfn.FORMULATEXT(Soal!L60)) -> 56
B13: 12 | C13: =Soal!E61 -> 45483 | D13: =Soal!F61 -> 58 | E13: =Soal!G61 -> 1450000 | F13: =Soal!H61 -> 30000 | G13: =Soal!I61 -> 250000 | H13: =Soal!J61 -> 350000 | I13: =Soal!K61 -> 0 | J13: =Soal!L61 -> 100000 | L13: =LEN(_xlfn.FORMULATEXT(Soal!E61)) -> 65 | M13: =LEN(_xlfn.FORMULATEXT(Soal!F61)) -> 98 | N13: =LEN(_xlfn.FORMULATEXT(Soal!G61)) -> 42 | O13: =LEN(_xlfn.FORMULATEXT(Soal!H61)) -> 17 | P13: =LEN(_xlfn.FORMULATEXT(Soal!I61)) -> 19 | Q13: =LEN(_xlfn.FORMULATEXT(Soal!J61)) -> 38 | R13: =LEN(_xlfn.FORMULATEXT(Soal!K61)) -> 28 | S13: =LEN(_xlfn.FORMULATEXT(Soal!L61)) -> 56
B14: 13 | C14: =Soal!E62 -> 45477 | D14: =Soal!F62 -> 194 | E14: =Soal!G62 -> 5190000 | F14: =Soal!H62 -> 15000 | G14: =Soal!I62 -> 259500 | H14: =Soal!J62 -> 0 | I14: =Soal!K62 -> 150000 | J14: =Soal!L62 -> 253800 | L14: =LEN(_xlfn.FORMULATEXT(Soal!E62)) -> 65 | M14: =LEN(_xlfn.FORMULATEXT(Soal!F62)) -> 98 | N14: =LEN(_xlfn.FORMULATEXT(Soal!G62)) -> 42 | O14: =LEN(_xlfn.FORMULATEXT(Soal!H62)) -> 17 | P14: =LEN(_xlfn.FORMULATEXT(Soal!I62)) -> 19 | Q14: =LEN(_xlfn.FORMULATEXT(Soal!J62)) -> 38 | R14: =LEN(_xlfn.FORMULATEXT(Soal!K62)) -> 28 | S14: =LEN(_xlfn.FORMULATEXT(Soal!L62)) -> 56
B15: 14 | C15: =Soal!E63 -> 45631 | D15: =Soal!F63 -> 234 | E15: =Soal!G63 -> 6590000 | F15: =Soal!H63 -> 15000 | G15: =Soal!I63 -> 329500 | H15: =Soal!J63 -> 0 | I15: =Soal!K63 -> 150000 | J15: =Soal!L63 -> 281800 | L15: =LEN(_xlfn.FORMULATEXT(Soal!E63)) -> 65 | M15: =LEN(_xlfn.FORMULATEXT(Soal!F63)) -> 98 | N15: =LEN(_xlfn.FORMULATEXT(Soal!G63)) -> 42 | O15: =LEN(_xlfn.FORMULATEXT(Soal!H63)) -> 17 | P15: =LEN(_xlfn.FORMULATEXT(Soal!I63)) -> 19 | Q15: =LEN(_xlfn.FORMULATEXT(Soal!J63)) -> 38 | R15: =LEN(_xlfn.FORMULATEXT(Soal!K63)) -> 28 | S15: =LEN(_xlfn.FORMULATEXT(Soal!L63)) -> 56
B16: 15 | C16: =Soal!E64 -> 45642 | D16: =Soal!F64 -> 246 | E16: =Soal!G64 -> 7010000 | F16: =Soal!H64 -> 45000 | G16: =Soal!I64 -> 350500 | H16: =Soal!J64 -> 0 | I16: =Soal!K64 -> 150000 | J16: =Soal!L64 -> 290200 | L16: =LEN(_xlfn.FORMULATEXT(Soal!E64)) -> 65 | M16: =LEN(_xlfn.FORMULATEXT(Soal!F64)) -> 98 | N16: =LEN(_xlfn.FORMULATEXT(Soal!G64)) -> 42 | O16: =LEN(_xlfn.FORMULATEXT(Soal!H64)) -> 17 | P16: =LEN(_xlfn.FORMULATEXT(Soal!I64)) -> 19 | Q16: =LEN(_xlfn.FORMULATEXT(Soal!J64)) -> 38 | R16: =LEN(_xlfn.FORMULATEXT(Soal!K64)) -> 28 | S16: =LEN(_xlfn.FORMULATEXT(Soal!L64)) -> 56
B17: 16 | C17: =Soal!E65 -> 45548 | D17: =Soal!F65 -> 86 | E17: =Soal!G65 -> 2150000 | F17: =Soal!H65 -> 15000 | G17: =Soal!I65 -> 250000 | H17: =Soal!J65 -> 350000 | I17: =Soal!K65 -> 0 | J17: =Soal!L65 -> 107500 | L17: =LEN(_xlfn.FORMULATEXT(Soal!E65)) -> 65 | M17: =LEN(_xlfn.FORMULATEXT(Soal!F65)) -> 98 | N17: =LEN(_xlfn.FORMULATEXT(Soal!G65)) -> 42 | O17: =LEN(_xlfn.FORMULATEXT(Soal!H65)) -> 17 | P17: =LEN(_xlfn.FORMULATEXT(Soal!I65)) -> 19 | Q17: =LEN(_xlfn.FORMULATEXT(Soal!J65)) -> 38 | R17: =LEN(_xlfn.FORMULATEXT(Soal!K65)) -> 28 | S17: =LEN(_xlfn.FORMULATEXT(Soal!L65)) -> 56
C21: =SUM(C2:C17,C3,C5,C8,C11,C14,C17,C10) -> 1047681 | D21: =SUM(D2:D17,D3,D5,D8,D11,D14,D17,D10) -> 3928 | E21: =SUM(E2:E17,E3,E5,E8,E11,E14,E17,E10) -> 107700000 | F21: =SUM(F2:F17,F3,F5,F8,F11,F14,F17,F10) -> 765000 | G21: =SUM(G2:G17,G3,G5,G8,G11,G14,G17,G10) -> 6963500 | H21: =SUM(H2:H17,H3,H5,H8,H11,H14,H17,H10) -> 5250000 | I21: =SUM(I2:I17,I3,I5,I8,I11,I14,I17,I10) -> 1650000 | J21: =SUM(J2:J17,J3,J5,J8,J11,J14,J17,J10) -> 4744400 | L21: =AVERAGE(L2:L18)=L2 -> TRUE | M21: =AVERAGE(M2:M18)=M2 -> TRUE | N21: =AVERAGE(N2:N18)=N2 -> TRUE | O21: =AVERAGE(O2:O18)=O2 -> TRUE | P21: =AVERAGE(P2:P18)=P2 -> TRUE | Q21: =AVERAGE(Q2:Q18)=Q2 -> TRUE | R21: =AVERAGE(R2:R18)=R2 -> TRUE | S21: =AVERAGE(S2:S18)=S2 -> TRUE
K22: Arr | L22: =AND(L2>0,L6=0,C6>0) -> FALSE | M22: =AND(M2>0,M6=0,D6>0) -> FALSE | N22: =AND(N2>0,N6=0,E6>0) -> FALSE | O22: =AND(O2>0,O6=0,F6>0) -> FALSE | P22: =AND(P2>0,P6=0,G6>0) -> FALSE | Q22: =AND(Q2>0,Q6=0,H6>0) -> FALSE | R22: =AND(R2>0,R6=0,I6>0) -> FALSE | S22: =AND(S2>0,S6=0,J6>0) -> FALSE
K23: ** | L23: =IFERROR(OR(L21:L22),FALSE) -> TRUE | M23: =IFERROR(OR(M21:M22),FALSE) -> TRUE | N23: =IFERROR(OR(N21:N22),FALSE) -> TRUE | O23: =IFERROR(OR(O21:O22),FALSE) -> TRUE | P23: =IFERROR(OR(P21:P22),FALSE) -> TRUE | Q23: =IFERROR(OR(Q21:Q22),FALSE) -> TRUE | R23: =IFERROR(OR(R21:R22),FALSE) -> TRUE | S23: =IFERROR(OR(S21:S22),FALSE) -> TRUE
B24: Rand | C24: 2904 | D24: 8683 | E24: 9973 | F24: 5366 | G24: 2573 | H24: 7931 | I24: 3832 | J24: 6152
B26: TRUE | C26: =LEFT(DEC2HEX(C24+COLUMN()+1000),2) -> F4 | D26: =LEFT(DEC2HEX(D24+COLUMN()+1000),2) -> 25 | E26: =LEFT(DEC2HEX(E24+COLUMN()+1000),2) -> 2A | F26: =LEFT(DEC2HEX(F24+COLUMN()+1000),2) -> 18 | G26: =LEFT(DEC2HEX(G24+COLUMN()+1000),2) -> DF | H26: =LEFT(DEC2HEX(H24+COLUMN()+1000),2) -> 22 | I26: =LEFT(DEC2HEX(I24+COLUMN()+1000),2) -> 12 | J26: =LEFT(DEC2HEX(J24+COLUMN()+1000),2) -> 1B
B27: FALSE | C27: =RIGHT(DEC2HEX(C24+COLUMN()+2),2) -> 5D | D27: =RIGHT(DEC2HEX(D24+COLUMN()+2),2) -> F1 | E27: =RIGHT(DEC2HEX(E24+COLUMN()+2),2) -> FC | F27: =RIGHT(DEC2HEX(F24+COLUMN()+2),2) -> FE | G27: =RIGHT(DEC2HEX(G24+COLUMN()+2),2) -> 16 | H27: =RIGHT(DEC2HEX(H24+COLUMN()+2),2) -> 05 | I27: =RIGHT(DEC2HEX(I24+COLUMN()+2),2) -> 03 | J27: =RIGHT(DEC2HEX(J24+COLUMN()+2),2) -> 14
B29: Kosong | C29: =IF(AND(C2="",C2=0),FALSE,TRUE) -> TRUE | D29: =IF(AND(D2="",D2=0),FALSE,TRUE) -> TRUE | E29: =IF(AND(E2="",E2=0),FALSE,TRUE) -> TRUE | F29: =IF(AND(F2="",F2=0),FALSE,TRUE) -> TRUE | G29: =IF(AND(G2="",G2=0),FALSE,TRUE) -> TRUE | H29: =IF(AND(H2="",H2=0),FALSE,TRUE) -> TRUE | I29: =IF(AND(I2="",I2=0),FALSE,TRUE) -> TRUE | J29: =IF(AND(J2="",J2=0),FALSE,TRUE) -> TRUE
B30: Cek Form | C30: =OR(AND(ISNUMBER(FIND("=",W2)),ISNUMBER(FIND("(",W2))),ISNUMBER(FIND("MAX",W2)),ISNUMBER(FIND("MIN",W2))) -> TRUE | D30: =OR(AND(ISNUMBER(FIND("=",X2)),ISNUMBER(FIND("(",X2))),ISNUMBER(FIND("MAX",X2)),ISNUMBER(FIND("MIN",X2))) -> TRUE | E30: =OR(AND(ISNUMBER(FIND("=",Y2)),ISNUMBER(FIND("(",Y2))),ISNUMBER(FIND("MAX",Y2)),ISNUMBER(FIND("MIN",Y2))) -> TRUE | F30: =OR(AND(ISNUMBER(FIND("=",Z2)),ISNUMBER(FIND("(",Z2))),ISNUMBER(FIND("MAX",Z2)),ISNUMBER(FIND("MIN",Z2))) -> TRUE | G30: =OR(AND(ISNUMBER(FIND("=",AA2)),ISNUMBER(FIND("(",AA2))),ISNUMBER(FIND("MAX",AA2)),ISNUMBER(FIND("MIN",AA2))) -> TRUE | H30: =OR(AND(ISNUMBER(FIND("=",AB2)),ISNUMBER(FIND("(",AB2))),ISNUMBER(FIND("MAX",AB2)),ISNUMBER(FIND("MIN",AB2))) -> TRUE | I30: =OR(AND(ISNUMBER(FIND("=",AC2)),ISNUMBER(FIND("(",AC2))),ISNUMBER(FIND("MAX",AC2)),ISNUMBER(FIND("MIN",AC2))) -> TRUE | J30: =OR(AND(ISNUMBER(FIND("=",AD2)),ISNUMBER(FIND("(",AD2))),ISNUMBER(FIND("MAX",AD2)),ISNUMBER(FIND("MIN",AD2))) -> TRUE
C31: =L23 -> TRUE | D31: =M23 -> TRUE | E31: =N23 -> TRUE | F31: =O23 -> TRUE | G31: =P23 -> TRUE | H31: =Q23 -> TRUE | I31: =R23 -> TRUE | J31: =S23 -> TRUE
B33: Akhir | C33: =AND(C29:C31) -> TRUE | D33: =AND(D29:D31) -> TRUE | E33: =AND(E29:E31) -> TRUE | F33: =AND(F29:F31) -> TRUE | G33: =AND(G29:G31) -> TRUE | H33: =AND(H29:H31) -> TRUE | I33: =AND(I29:I31) -> TRUE | J33: =AND(J29:J31) -> TRUE
B35: Cek Formula | C35: =AND(ISNUMBER(FIND("MAX",W2))) -> TRUE | D35: =AND(ISNUMBER(FIND("MAX",X2))) -> TRUE | E35: =AND(ISNUMBER(FIND("MIN",Y2)),ISNUMBER(FIND("MAX",Y2))) -> TRUE | F35: =AND(ISNUMBER(FIND("MIN",Z2))) -> TRUE | G35: =AND(ISNUMBER(FIND("MAX",AA2))) -> TRUE | H35: =AND(ISNUMBER(FIND("MIN",AB2))) -> TRUE | I35: =AND(ISNUMBER(FIND("MAX",AC2))) -> TRUE | J35: =AND(ISNUMBER(FIND("MIN",AD2)),ISNUMBER(FIND("MAX",AD2))) -> TRUE | M35: ka | N35: mu | R35: juga
B36: Cek banyak | C36: =IFERROR(LEN(W2)-LEN(SUBSTITUTE(W2,"(","")),99) -> 1 | D36: =IFERROR(LEN(X2)-LEN(SUBSTITUTE(X2,"(","")),99) -> 1 | E36: =IFERROR(LEN(Y2)-LEN(SUBSTITUTE(Y2,"(","")),99) -> 2 | F36: =IFERROR(LEN(Z2)-LEN(SUBSTITUTE(Z2,"(","")),99) -> 1 | G36: =IFERROR(LEN(AA2)-LEN(SUBSTITUTE(AA2,"(","")),99) -> 1 | H36: =IFERROR(LEN(AB2)-LEN(SUBSTITUTE(AB2,"(","")),99) -> 2 | I36: =IFERROR(LEN(AC2)-LEN(SUBSTITUTE(AC2,"(","")),99) -> 2 | J36: =IFERROR(LEN(AD2)-LEN(SUBSTITUTE(AD2,"(","")),99) -> 3
C37: 2 | D37: 2 | E37: 2 | F37: 1 | G37: 1 | H37: 2 | I37: 2 | J37: 3
C38: =C36<=C37 -> TRUE | D38: =D36<=D37 -> TRUE | E38: =E36<=E37 -> TRUE | F38: =F36<=F37 -> TRUE | G38: =G36<=G37 -> TRUE | H38: =H36<=H37 -> TRUE | I38: =I36<=I37 -> TRUE | J38: =J36<=J37 -> TRUE
B40: Akhir | C40: =AND(C38,C35,C59) -> TRUE | D40: =AND(D38,D35,D59) -> TRUE | E40: =AND(E38,E35,E59) -> TRUE | F40: =AND(F38,F35,F59) -> TRUE | G40: =AND(G38,G35,G59) -> TRUE | H40: =AND(H38,H35,H59) -> TRUE | I40: =AND(I38,I35,I59) -> TRUE | J40: =AND(J38,J35,J59) -> TRUE
B43: N | C43: =IFERROR(DEC2HEX(IF(C33,C21,C24)),"EEE") -> FFC81 | D43: =IFERROR(DEC2HEX(IF(D33,D21,D24)),"EEE") -> F58 | E43: =IFERROR(DEC2HEX(IF(E33,E21,E24)),"EEE") -> 66B5F20 | F43: =IFERROR(DEC2HEX(IF(F33,F21,F24)),"EEE") -> BAC48 | G43: =IFERROR(DEC2HEX(IF(G33,G21,G24)),"EEE") -> 6A412C | H43: =IFERROR(DEC2HEX(IF(H33,H21,H24)),"EEE") -> 501BD0 | I43: =IFERROR(DEC2HEX(IF(I33,I21,I24)),"EEE") -> 192D50 | J43: =IFERROR(DEC2HEX(IF(J33,J21,J24)),"EEE") -> 4864D0
B44: A | C44: =IF(C40,C26,C27) -> F4 | D44: =IF(D40,D26,D27) -> 25 | E44: =IF(E40,E26,E27) -> 2A | F44: =IF(F40,F26,F27) -> 18 | G44: =IF(G40,G26,G27) -> DF | H44: =IF(H40,H26,H27) -> 22 | I44: =IF(I40,I26,I27) -> 12 | J44: =IF(J40,J26,J27) -> 1B
C46: =C44&"-"&C43&";" -> F4-FFC81; | D46: =D44&"-"&D43&";" -> 25-F58; | E46: =E44&"-"&E43&";" -> 2A-66B5F20; | F46: =F44&"-"&F43&";" -> 18-BAC48; | G46: =G44&"-"&G43&";" -> DF-6A412C; | H46: =H44&"-"&H43&";" -> 22-501BD0; | I46: =I44&"-"&I43&";" -> 12-192D50; | J46: =J44&"-"&J43 -> 1B-4864D0
C48: =A2&"|"&C46&D46&E46&F46&G46&H46&I46&J46 -> HK1|F4-FFC81;25-F58;2A-66B5F20;18-BAC48;DF-6A412C;22-501BD0;12-192D50;1B-4864D0
C50: {=INDIRECT(M35&N35&R35)} -> HK1|F4-FFC81;25-F58;2A-66B5F20;18-BAC48;DF-6A412C;22-501BD0;12-192D50;1B-4864D0
C52: =C50 -> HK1|F4-FFC81;25-F58;2A-66B5F20;18-BAC48;DF-6A412C;22-501BD0;12-192D50;1B-4864D0
B54: MAX | C54: =IFERROR(LEN(W2)-LEN(SUBSTITUTE(W2,$B$54,"")),99)/3 -> 1 | D54: =IFERROR(LEN(X2)-LEN(SUBSTITUTE(X2,$B$54,"")),99)/3 -> 1 | E54: =IFERROR(LEN(Y2)-LEN(SUBSTITUTE(Y2,$B$54,"")),99)/3 -> 1 | F54: =IFERROR(LEN(Z2)-LEN(SUBSTITUTE(Z2,$B$54,"")),99)/3 -> 0 | G54: =IFERROR(LEN(AA2)-LEN(SUBSTITUTE(AA2,$B$54,"")),99)/3 -> 1 | H54: =IFERROR(LEN(AB2)-LEN(SUBSTITUTE(AB2,$B$54,"")),99)/3 -> 1 | I54: =IFERROR(LEN(AC2)-LEN(SUBSTITUTE(AC2,$B$54,"")),99)/3 -> 1 | J54: =IFERROR(LEN(AD2)-LEN(SUBSTITUTE(AD2,$B$54,"")),99)/3 -> 2
B55: MIN | C55: =IFERROR(LEN(W2)-LEN(SUBSTITUTE(W2,$B$55,"")),99)/3 -> 0 | D55: =IFERROR(LEN(X2)-LEN(SUBSTITUTE(X2,$B$55,"")),99)/3 -> 0 | E55: =IFERROR(LEN(Y2)-LEN(SUBSTITUTE(Y2,$B$55,"")),99)/3 -> 1 | F55: =IFERROR(LEN(Z2)-LEN(SUBSTITUTE(Z2,$B$55,"")),99)/3 -> 1 | G55: =IFERROR(LEN(AA2)-LEN(SUBSTITUTE(AA2,$B$55,"")),99)/3 -> 0 | H55: =IFERROR(LEN(AB2)-LEN(SUBSTITUTE(AB2,$B$55,"")),99)/3 -> 1 | I55: =IFERROR(LEN(AC2)-LEN(SUBSTITUTE(AC2,$B$55,"")),99)/3 -> 0 | J55: =IFERROR(LEN(AD2)-LEN(SUBSTITUTE(AD2,$B$55,"")),99)/3 -> 1
...
