Workbook
Name kode_jawaban: DF!$C$41
Name pat: _xlfn.LAMBDA(_xlpm.x,IF(ISNUMBER(_xlpm.x),"*."&_xlpm.x&".*",_xlpm.x&".*"))
Name saya: DF!$C$39

Sheet XL-Test
A19: KODE SOAL | C19: SBEM005 | E19: KODE JAWABAN | G19: =kode_jawaban -> ME5|B8-524;23-D7668;7B-1720;F6-E90;1C-2DC;1A-6743;8F-60E;23-D33EC
A21: Intruksi
B23: Medium Level - Latihan Soal Jumlah Siswa dan Rata-rata
B25: Soal : | C25: Untuk menjawab soal-soal ini, buatlah sebuah fungsi bersifat universal yang cukup dituliskan di bagian atas. | I25: Kode Siswa
C26: Selanjutnya, fungsi tersebut dapat drag/seret untuk mengisi bagian berikutnya. | I26: X.Y.Z | J26: X = Tingkat ( 7,8,9)
B27: 1 | C27: Berapa Jumlah Siswa berdasarkan kelas atau kode kelas | J27: Y = Kelas (A,B)
B28: 2 | C28: Berapa rata-rata nilai berdasarkan kelas atau kode kelas, Bulatkan hasilnya sampai 2 digit dibelakang koma | J28: Z = Nomot urut (1,2,3..)
B29: 3 | C29: Berapa Nilai Terbesar berdasarkan kelas atau kode kelas | I29: Contoh
B30: 4 | C30: Berapa Nilai Terkecil berdasarkan kelas atau kode kelas | I30: A.2.8 | J30: kelas 7B Nomor Urut 8
B31: 5 | C31: Berapa Jumlah Siswa berdasarkan kelas atau kode kelas dengan Nilai lebih besar dari 80 | I31: C.1.1 | J31: Kelas 9A Nomor Urut 1
B32: 6 | C32: Berapa Total Jumlah nilai berdasarkan kelas atau kode kelas | I32: B.1.5 | J32: kelas 8A Nomor Urut 5
B33: 7 | C33: Berapa Jumlah Siswa yang namanya diawali dengan Hurup Vocal (A,E,I,O,U) berdasarkan kelas atau kode kelas
B34: 8 | C34: Berapa rata-rata nilai berdasarkan kelas atau kode kelas dengan nomor urut Absen diatas 10 (10 termasuk), Bulatkan hasilnya sampai 2 digit dibelakang koma
C36: Sudah selesai mengerjakan? kirim Kode Soal dan Kode Jawaban diatas ke alamat : https://belajarexcel.id/xl-test/jawaban untuk mengecek hasilnya
C37: atau klik tombol disamping
D43: 1 | E43: 2 | F43: 3 | G43: 4 | H43: 5 | I43: 6 | J43: 7 | K43: 8
B44: Kode Kelas | C44: Kelas | D44: Jumlah Siswa | E44: Rata-Rata Nilai | F44: Nilai Terbesar | G44: Nilai Terkecil | H44: Jml Siswa Nilai >80 | I44: Total Nilai | J44: Jumlah Siswa Vocal | K44: Rata-Rata Nilai +10
B45: A | C45: Kelas 7 | D45: =COUNTIF(Database!$A$3:$A$80,"*"&B45&".*") -> 27 | E45: =ROUND(AVERAGEIFS(Database!$D$3:$D$80,Database!$A$3:$A$80,"*"&B45&".*"),2) -> 80.7 | F45: =_xlfn.MAXIFS(Database!$D$3:$D$80,Database!$A$3:$A$80,"*"&B45&".*") -> 100 | G45: =_xlfn.MINIFS(Database!$D$3:$D$80,Database!$A$3:$A$80,"*"&B45&".*") -> 62 | H45: =COUNTIFS(Database!$A$3:$A$80,"*"&B45&".*",Database!$D$3:$D$80,">80") -> 14 | I45: =SUMIFS(Database!$D$3:$D$80,Database!$A$3:$A$80,"*"&B45&".*") -> 2179 | J45: {=SUM(COUNTIFS(Database!$A$3:$A$80,"*"&B45&".*",Database!$B$3:$B$80,{"A*";"E*";"I*";"O*";"U*"}))} -> 6 | K45: =ROUND(AVERAGEIFS(Database!$D$3:$D$80,Database!$A$3:$A$80,"*"&B45&".*",Database!$A$3:$A$80,"*.*." & "??*"),2) -> 79.22
B46: B | C46: Kelas 8 | D46: =COUNTIF(Database!$A$3:$A$80,"*"&B46&".*") -> 25 | E46: =ROUND(AVERAGEIFS(Database!$D$3:$D$80,Database!$A$3:$A$80,"*"&B46&".*"),2) -> 80.32 | F46: =_xlfn.MAXIFS(Database!$D$3:$D$80,Database!$A$3:$A$80,"*"&B46&".*") -> 99 | G46: =_xlfn.MINIFS(Database!$D$3:$D$80,Database!$A$3:$A$80,"*"&B46&".*") -> 61 | H46: =COUNTIFS(Database!$A$3:$A$80,"*"&B46&".*",Database!$D$3:$D$80,">80") -> 15 | I46: =SUMIFS(Database!$D$3:$D$80,Database!$A$3:$A$80,"*"&B46&".*") -> 2008 | J46: {=SUM(COUNTIFS(Database!$A$3:$A$80,"*"&B46&".*",Database!$B$3:$B$80,{"A*";"E*";"I*";"O*";"U*"}))} -> 3 | K46: =ROUND(AVERAGEIFS(Database!$D$3:$D$80,Database!$A$3:$A$80,"*"&B46&".*",Database!$A$3:$A$80,"*.*." & "??*"),2) -> 78.57
B47: C | C47: Kelas 9 | D47: =COUNTIF(Database!$A$3:$A$80,"*"&B47&".*") -> 26 | E47: =ROUND(AVERAGEIFS(Database!$D$3:$D$80,Database!$A$3:$A$80,"*"&B47&".*"),2) -> 79.81 | F47: =_xlfn.MAXIFS(Database!$D$3:$D$80,Database!$A$3:$A$80,"*"&B47&".*") -> 97 | G47: =_xlfn.MINIFS(Database!$D$3:$D$80,Database!$A$3:$A$80,"*"&B47&".*") -> 62 | H47: =COUNTIFS(Database!$A$3:$A$80,"*"&B47&".*",Database!$D$3:$D$80,">80") -> 14 | I47: =SUMIFS(Database!$D$3:$D$80,Database!$A$3:$A$80,"*"&B47&".*") -> 2075 | J47: {=SUM(COUNTIFS(Database!$A$3:$A$80,"*"&B47&".*",Database!$B$3:$B$80,{"A*";"E*";"I*";"O*";"U*"}))} -> 6 | K47: =ROUND(AVERAGEIFS(Database!$D$3:$D$80,Database!$A$3:$A$80,"*"&B47&".*",Database!$A$3:$A$80,"*.*." & "??*"),2) -> 80.25
B48: A.1 | C48: Kelas 7A | D48: =COUNTIF(Database!$A$3:$A$80,"*"&B48&".*") -> 14 | E48: =ROUND(AVERAGEIFS(Database!$D$3:$D$80,Database!$A$3:$A$80,"*"&B48&".*"),2) -> 79.21 | F48: =_xlfn.MAXIFS(Database!$D$3:$D$80,Database!$A$3:$A$80,"*"&B48&".*") -> 100 | G48: =_xlfn.MINIFS(Database!$D$3:$D$80,Database!$A$3:$A$80,"*"&B48&".*") -> 64 | H48: =COUNTIFS(Database!$A$3:$A$80,"*"&B48&".*",Database!$D$3:$D$80,">80") -> 6 | I48: =SUMIFS(Database!$D$3:$D$80,Database!$A$3:$A$80,"*"&B48&".*") -> 1109 | J48: {=SUM(COUNTIFS(Database!$A$3:$A$80,"*"&B48&".*",Database!$B$3:$B$80,{"A*";"E*";"I*";"O*";"U*"}))} -> 3 | K48: =ROUND(AVERAGEIFS(Database!$D$3:$D$80,Database!$A$3:$A$80,"*"&B48&".*",Database!$A$3:$A$80,"*.*." & "??*"),2) -> 83.6
B49: A.2 | C49: Kelas 7B | D49: =COUNTIF(Database!$A$3:$A$80,"*"&B49&".*") -> 13 | E49: =ROUND(AVERAGEIFS(Database!$D$3:$D$80,Database!$A$3:$A$80,"*"&B49&".*"),2) -> 82.31 | F49: =_xlfn.MAXIFS(Database!$D$3:$D$80,Database!$A$3:$A$80,"*"&B49&".*") -> 99 | G49: =_xlfn.MINIFS(Database!$D$3:$D$80,Database!$A$3:$A$80,"*"&B49&".*") -> 62 | H49: =COUNTIFS(Database!$A$3:$A$80,"*"&B49&".*",Database!$D$3:$D$80,">80") -> 8 | I49: =SUMIFS(Database!$D$3:$D$80,Database!$A$3:$A$80,"*"&B49&".*") -> 1070 | J49: {=SUM(COUNTIFS(Database!$A$3:$A$80,"*"&B49&".*",Database!$B$3:$B$80,{"A*";"E*";"I*";"O*";"U*"}))} -> 3 | K49: =ROUND(AVERAGEIFS(Database!$D$3:$D$80,Database!$A$3:$A$80,"*"&B49&".*",Database!$A$3:$A$80,"*.*." & "??*"),2) -> 73.75
B50: B.1 | C50: Kelas 8A | D50: =COUNTIF(Database!$A$3:$A$80,"*"&B50&".*") -> 14 | E50: =ROUND(AVERAGEIFS(Database!$D$3:$D$80,Database!$A$3:$A$80,"*"&B50&".*"),2) -> 82.5 | F50: =_xlfn.MAXIFS(Database!$D$3:$D$80,Database!$A$3:$A$80,"*"&B50&".*") -> 98 | G50: =_xlfn.MINIFS(Database!$D$3:$D$80,Database!$A$3:$A$80,"*"&B50&".*") -> 64 | H50: =COUNTIFS(Database!$A$3:$A$80,"*"&B50&".*",Database!$D$3:$D$80,">80") -> 9 | I50: =SUMIFS(Database!$D$3:$D$80,Database!$A$3:$A$80,"*"&B50&".*") -> 1155 | J50: {=SUM(COUNTIFS(Database!$A$3:$A$80,"*"&B50&".*",Database!$B$3:$B$80,{"A*";"E*";"I*";"O*";"U*"}))} -> 0 | K50: =ROUND(AVERAGEIFS(Database!$D$3:$D$80,Database!$A$3:$A$80,"*"&B50&".*",Database!$A$3:$A$80,"*.*." & "??*"),2) -> 80.8
B51: B.2 | C51: Kelas 8B | D51: =COUNTIF(Database!$A$3:$A$80,"*"&B51&".*") -> 11 | E51: =ROUND(AVERAGEIFS(Database!$D$3:$D$80,Database!$A$3:$A$80,"*"&B51&".*"),2) -> 77.55 | F51: =_xlfn.MAXIFS(Database!$D$3:$D$80,Database!$A$3:$A$80,"*"&B51&".*") -> 99 | G51: =_xlfn.MINIFS(Database!$D$3:$D$80,Database!$A$3:$A$80,"*"&B51&".*") -> 61 | H51: =COUNTIFS(Database!$A$3:$A$80,"*"&B51&".*",Database!$D$3:$D$80,">80") -> 6 | I51: =SUMIFS(Database!$D$3:$D$80,Database!$A$3:$A$80,"*"&B51&".*") -> 853 | J51: {=SUM(COUNTIFS(Database!$A$3:$A$80,"*"&B51&".*",Database!$B$3:$B$80,{"A*";"E*";"I*";"O*";"U*"}))} -> 3 | K51: =ROUND(AVERAGEIFS(Database!$D$3:$D$80,Database!$A$3:$A$80,"*"&B51&".*",Database!$A$3:$A$80,"*.*." & "??*"),2) -> 73
B52: C.1 | C52: Kelas 9A | D52: =COUNTIF(Database!$A$3:$A$80,"*"&B52&".*") -> 14 | E52: =ROUND(AVERAGEIFS(Database!$D$3:$D$80,Database!$A$3:$A$80,"*"&B52&".*"),2) -> 81 | F52: =_xlfn.MAXIFS(Database!$D$3:$D$80,Database!$A$3:$A$80,"*"&B52&".*") -> 97 | G52: =_xlfn.MINIFS(Database!$D$3:$D$80,Database!$A$3:$A$80,"*"&B52&".*") -> 62 | H52: =COUNTIFS(Database!$A$3:$A$80,"*"&B52&".*",Database!$D$3:$D$80,">80") -> 9 | I52: =SUMIFS(Database!$D$3:$D$80,Database!$A$3:$A$80,"*"&B52&".*") -> 1134 | J52: {=SUM(COUNTIFS(Database!$A$3:$A$80,"*"&B52&".*",Database!$B$3:$B$80,{"A*";"E*";"I*";"O*";"U*"}))} -> 4 | K52: =ROUND(AVERAGEIFS(Database!$D$3:$D$80,Database!$A$3:$A$80,"*"&B52&".*",Database!$A$3:$A$80,"*.*." & "??*"),2) -> 82.2
B53: C.2 | C53: Kelas 9B | D53: =COUNTIF(Database!$A$3:$A$80,"*"&B53&".*") -> 12 | E53: =ROUND(AVERAGEIFS(Database!$D$3:$D$80,Database!$A$3:$A$80,"*"&B53&".*"),2) -> 78.42 | F53: =_xlfn.MAXIFS(Database!$D$3:$D$80,Database!$A$3:$A$80,"*"&B53&".*") -> 96 | G53: =_xlfn.MINIFS(Database!$D$3:$D$80,Database!$A$3:$A$80,"*"&B53&".*") -> 62 | H53: =COUNTIFS(Database!$A$3:$A$80,"*"&B53&".*",Database!$D$3:$D$80,">80") -> 5 | I53: =SUMIFS(Database!$D$3:$D$80,Database!$A$3:$A$80,"*"&B53&".*") -> 941 | J53: {=SUM(COUNTIFS(Database!$A$3:$A$80,"*"&B53&".*",Database!$B$3:$B$80,{"A*";"E*";"I*";"O*";"U*"}))} -> 2 | K53: =ROUND(AVERAGEIFS(Database!$D$3:$D$80,Database!$A$3:$A$80,"*"&B53&".*",Database!$A$3:$A$80,"*.*." & "??*"),2) -> 77
B54: 1 | C54: Kelas A | D54: =COUNTIF(Database!$A$3:$A$80,"*"&B54&".*") -> 42 | E54: =ROUND(AVERAGEIFS(Database!$D$3:$D$80,Database!$A$3:$A$80,"*"&B54&".*"),2) -> 80.9 | F54: =_xlfn.MAXIFS(Database!$D$3:$D$80,Database!$A$3:$A$80,"*"&B54&".*") -> 100 | G54: =_xlfn.MINIFS(Database!$D$3:$D$80,Database!$A$3:$A$80,"*"&B54&".*") -> 62 | H54: =COUNTIFS(Database!$A$3:$A$80,"*"&B54&".*",Database!$D$3:$D$80,">80") -> 24 | I54: =SUMIFS(Database!$D$3:$D$80,Database!$A$3:$A$80,"*"&B54&".*") -> 3398 | J54: {=SUM(COUNTIFS(Database!$A$3:$A$80,"*"&B54&".*",Database!$B$3:$B$80,{"A*";"E*";"I*";"O*";"U*"}))} -> 7 | K54: =ROUND(AVERAGEIFS(Database!$D$3:$D$80,Database!$A$3:$A$80,"*"&B54&".*",Database!$A$3:$A$80,"*.*." & "??*"),2) -> 82.2
B55: 2 | C55: Kelas B | D55: =COUNTIF(Database!$A$3:$A$80,"*"&B55&".*") -> 36 | E55: =ROUND(AVERAGEIFS(Database!$D$3:$D$80,Database!$A$3:$A$80,"*"&B55&".*"),2) -> 79.56 | F55: =_xlfn.MAXIFS(Database!$D$3:$D$80,Database!$A$3:$A$80,"*"&B55&".*") -> 99 | G55: =_xlfn.MINIFS(Database!$D$3:$D$80,Database!$A$3:$A$80,"*"&B55&".*") -> 61 | H55: =COUNTIFS(Database!$A$3:$A$80,"*"&B55&".*",Database!$D$3:$D$80,">80") -> 19 | I55: =SUMIFS(Database!$D$3:$D$80,Database!$A$3:$A$80,"*"&B55&".*") -> 2864 | J55: {=SUM(COUNTIFS(Database!$A$3:$A$80,"*"&B55&".*",Database!$B$3:$B$80,{"A*";"E*";"I*";"O*";"U*"}))} -> 8 | K55: =ROUND(AVERAGEIFS(Database!$D$3:$D$80,Database!$A$3:$A$80,"*"&B55&".*",Database!$A$3:$A$80,"*.*." & "??*"),2) -> 74.67
A59: Dilarang mengubah Table atau Menambah Table Baru atau Menambah Kolom Bantuan !!, Gunakan Table seperti yang sudah di sediakan soal.

Sheet Database
A2: Kode Siswa | B2: Nama | C2: Keterangan | D2: Nilai
A3: A.2.8 | B3: Diah | C3: Siswa | D3: 73 | G3: Kode Siswa
A4: C.2.5 | B4: Lanjar | C4: Siswa | D4: 66 | G4: X.Y.Z | H4: X = Tingkat ( 7,8,9)
A5: A.2.4 | B5: Karsa | C5: Siswa | D5: 99 | H5: Y = Kelas (A,B)
A6: C.1.1 | B6: Kusuma | C6: Siswa | D6: 82 | H6: Z = Nomot urut (1,2,3..)
A7: B.1.10 | B7: Najwa | C7: Siswa | D7: 93 | G7: Contoh
A8: C.1.4 | B8: Hartaka | C8: Siswa | D8: 91 | G8: A.2.8 | H8: kelas 7B Nomor Urut 8
A9: C.1.6 | B9: Upik | C9: Siswa | D9: 72 | G9: C.1.1 | H9: Kelas 9A Nomor Urut 1
A10: B.1.9 | B10: Calista | C10: Siswa | D10: 92 | G10: B.1.5 | H10: kelas 8A Nomor Urut 5
A11: A.2.13 | B11: Adikara | C11: Siswa | D11: 62
A12: C.1.11 | B12: Najwa | C12: Siswa | D12: 84
A13: B.2.1 | B13: Argono | C13: Siswa | D13: 66
A14: B.1.8 | B14: Jaswadi | C14: Siswa | D14: 93
A15: B.2.5 | B15: Harsaya | C15: Siswa | D15: 82
A16: C.1.5 | B16: Kala | C16: Siswa | D16: 62
A17: A.2.10 | B17: Bakidin | C17: Siswa | D17: 63
A18: C.2.6 | B18: Vanesa | C18: Siswa | D18: 83
A19: B.1.13 | B19: Bakti | C19: Siswa | D19: 66
A20: A.2.3 | B20: Prabu | C20: Siswa | D20: 94
A21: C.1.7 | B21: Almira | C21: Siswa | D21: 64
A22: C.2.3 | B22: Diah | C22: Siswa | D22: 72
... A80: A.1.4 | B80: Panca | C80: Siswa | D80: 67

Sheet About
I6: XL-TEST adalah platform inovatif yang menyediakan latihan Excel interaktif dengan pemeriksaan otomatis,
I7: sehingga pengguna dapat langsung mengetahui jawaban yang benar maupun salah.
I10: Terdapat 5 Level soal :
J12: Easy Level | L12: (⭐)
J13: Medium Level | L13: (⭐⭐)
J14: Hard Level | L14: (⭐⭐⭐)
J15: Extreme Level | L15: (⭐⭐⭐⭐)
J16: Championship Level | L16: (⭐⭐⭐⭐⭐)
B17: Saya adalah seorang Excel Holic yang percaya bahwa setiap angka memiliki cerita yang bisa ditemukan dengan cara yang tepat. | I17: Free Access
B18: “Excel bukan cuma soal kerjaan tapi juga hobi yang aku nikmati.” | I18: https://belajarexcel.id/xl-test/
B19: Contact :
B20: 🌐 Web | C20: https://setiadi.me
B21: 🪡threads | C21: https://www.threads.com/@andisetiadi
D27: Perlu Video Penjelasan atau Kunci Jawaban ?
D28: Scan barcode atau kunjungi
D29: https://lynk.id/setiadi/page/jawaban-xl-test

Sheet DF
A1: DEF | C1: 1 | D1: 2 | E1: 3 | F1: 4 | G1: 5 | H1: 6 | I1: 7 | J1: 8 | P1: 1 | Q1: =SUBSTITUTE(_xlfn.FORMULATEXT('XL-Test'!D45),"$","") -> =COUNTIF(Database!A3:A80;"*"&B45&".*") | R1: =SUBSTITUTE(_xlfn.FORMULATEXT('XL-Test'!E45),"$","") -> =ROUND(AVERAGEIFS(Database!D3:D80;Database!A3:A80;"*"&B45&".*");2) | S1: =SUBSTITUTE(_xlfn.FORMULATEXT('XL-Test'!F45),"$","") -> =MAXIFS(Database!D3:D80;Database!A3:A80;"*"&B45&".*") | T1: =SUBSTITUTE(_xlfn.FORMULATEXT('XL-Test'!G45),"$","") -> =MINIFS(Database!D3:D80;Database!A3:A80;"*"&B45&".*") | U1: =SUBSTITUTE(_xlfn.FORMULATEXT('XL-Test'!H45),"$","") -> =COUNTIFS(Database!A3:A80;"*"&B45&".*";Database!D3:D80;">80") | V1: =SUBSTITUTE(_xlfn.FORMULATEXT('XL-Test'!I45),"$","") -> =SUMIFS(Database!D3:D80;Database!A3:A80;"*"&B45&".*") | W1: =SUBSTITUTE(_xlfn.FORMULATEXT('XL-Test'!J45),"$","") -> =SUM(COUNTIFS(Database!A3:A80;"*"&B45&".*";Database!B3:B80;{"A*";"E*";"I*";"O*";"U*"})) | X1: =SUBSTITUTE(_xlfn.FORMULATEXT('XL-Test'!K45),"$","") -> =ROUND(AVERAGEIFS(Database!D3:D80;Database!A3:A80;"*"&B45&".*";Database!A3:A80;"*.*." & "??*");2)
A2: ME5 | B2: 1 | C2: ='XL-Test'!D45 -> 27 | D2: ='XL-Test'!E45 -> 80.7 | E2: ='XL-Test'!F45 -> 100 | F2: ='XL-Test'!G45 -> 62 | G2: ='XL-Test'!H45 -> 14 | H2: ='XL-Test'!I45 -> 2179 | I2: ='XL-Test'!J45 -> 6 | J2: ='XL-Test'!K45 -> 79.22 | P2: 2 | Q2: =R1 -> =ROUND(AVERAGEIFS(Database!D3:D80;Database!A3:A80;"*"&B45&".*");2)
B3: 2 | C3: ='XL-Test'!D46 -> 25 | D3: ='XL-Test'!E46 -> 80.32 | E3: ='XL-Test'!F46 -> 99 | F3: ='XL-Test'!G46 -> 61 | G3: ='XL-Test'!H46 -> 15 | H3: ='XL-Test'!I46 -> 2008 | I3: ='XL-Test'!J46 -> 3 | J3: ='XL-Test'!K46 -> 78.57 | P3: 3 | Q3: =S1 -> =MAXIFS(Database!D3:D80;Database!A3:A80;"*"&B45&".*")
B4: 3 | C4: ='XL-Test'!D47 -> 26 | D4: ='XL-Test'!E47 -> 79.81 | E4: ='XL-Test'!F47 -> 97 | F4: ='XL-Test'!G47 -> 62 | G4: ='XL-Test'!H47 -> 14 | H4: ='XL-Test'!I47 -> 2075 | I4: ='XL-Test'!J47 -> 6 | J4: ='XL-Test'!K47 -> 80.25 | P4: 4 | Q4: =T1 -> =MINIFS(Database!D3:D80;Database!A3:A80;"*"&B45&".*")
B5: 4 | C5: ='XL-Test'!D48 -> 14 | D5: ='XL-Test'!E48 -> 79.21 | E5: ='XL-Test'!F48 -> 100 | F5: ='XL-Test'!G48 -> 64 | G5: ='XL-Test'!H48 -> 6 | H5: ='XL-Test'!I48 -> 1109 | I5: ='XL-Test'!J48 -> 3 | J5: ='XL-Test'!K48 -> 83.6 | P5: 5 | Q5: =U1 -> =COUNTIFS(Database!A3:A80;"*"&B45&".*";Database!D3:D80;">80")
B6: 5 | C6: ='XL-Test'!D49 -> 13 | D6: ='XL-Test'!E49 -> 82.31 | E6: ='XL-Test'!F49 -> 99 | F6: ='XL-Test'!G49 -> 62 | G6: ='XL-Test'!H49 -> 8 | H6: ='XL-Test'!I49 -> 1070 | I6: ='XL-Test'!J49 -> 3 | J6: ='XL-Test'!K49 -> 73.75 | P6: 6 | Q6: =V1 -> =SUMIFS(Database!D3:D80;Database!A3:A80;"*"&B45&".*")
B7: 6 | C7: ='XL-Test'!D50 -> 14 | D7: ='XL-Test'!E50 -> 82.5 | E7: ='XL-Test'!F50 -> 98 | F7: ='XL-Test'!G50 -> 64 | G7: ='XL-Test'!H50 -> 9 | H7: ='XL-Test'!I50 -> 1155 | I7: ='XL-Test'!J50 -> 0 | J7: ='XL-Test'!K50 -> 80.8 | P7: 7 | Q7: =W1 -> =SUM(COUNTIFS(Database!A3:A80;"*"&B45&".*";Database!B3:B80;{"A*";"E*";"I*";"O*";"U*"}))
B8: 7 | C8: ='XL-Test'!D51 -> 11 | D8: ='XL-Test'!E51 -> 77.55 | E8: ='XL-Test'!F51 -> 99 | F8: ='XL-Test'!G51 -> 61 | G8: ='XL-Test'!H51 -> 6 | H8: ='XL-Test'!I51 -> 853 | I8: ='XL-Test'!J51 -> 3 | J8: ='XL-Test'!K51 -> 73 | P8: 8 | Q8: =X1 -> =ROUND(AVERAGEIFS(Database!D3:D80;Database!A3:A80;"*"&B45&".*";Database!A3:A80;"*.*." & "??*");2)
B9: 8 | C9: ='XL-Test'!D52 -> 14 | D9: ='XL-Test'!E52 -> 81 | E9: ='XL-Test'!F52 -> 97 | F9: ='XL-Test'!G52 -> 62 | G9: ='XL-Test'!H52 -> 9 | H9: ='XL-Test'!I52 -> 1134 | I9: ='XL-Test'!J52 -> 4 | J9: ='XL-Test'!K52 -> 82.2
B10: 9 | C10: ='XL-Test'!D53 -> 12 | D10: ='XL-Test'!E53 -> 78.42 | E10: ='XL-Test'!F53 -> 96 | F10: ='XL-Test'!G53 -> 62 | G10: ='XL-Test'!H53 -> 5 | H10: ='XL-Test'!I53 -> 941 | I10: ='XL-Test'!J53 -> 2 | J10: ='XL-Test'!K53 -> 77 | Q10: 1 | R10: 2 | S10: 3 | T10: 4 | U10: 5 | V10: 6 | W10: 7 | X10: 8
B11: 10 | C11: ='XL-Test'!D54 -> 42 | D11: ='XL-Test'!E54 -> 80.9 | E11: ='XL-Test'!F54 -> 100 | F11: ='XL-Test'!G54 -> 62 | G11: ='XL-Test'!H54 -> 24 | H11: ='XL-Test'!I54 -> 3398 | I11: ='XL-Test'!J54 -> 7 | J11: ='XL-Test'!K54 -> 82.2
B12: 11 | C12: ='XL-Test'!D55 -> 36 | D12: ='XL-Test'!E55 -> 79.56 | E12: ='XL-Test'!F55 -> 99 | F12: ='XL-Test'!G55 -> 61 | G12: ='XL-Test'!H55 -> 19 | H12: ='XL-Test'!I55 -> 2864 | I12: ='XL-Test'!J55 -> 8 | J12: ='XL-Test'!K55 -> 74.67
C14: =(SUM(C2:C12)+C3+C5+C9+C11)*4 -> 1316 | D14: =SUM(D2:D12)*1000 -> 882280 | E14: =(SUM(E2:E12)+E3+E5+E9+E11)*4 -> 5920 | F14: =(SUM(F2:F12)+F3+F5+F9+F11)*4 -> 3728 | G14: =(SUM(G2:G12)+G3+G5+G9+G11)*4 -> 732 | H14: =(SUM(H2:H12)+H3+H5+H9+H11) -> 26435 | I14: =(SUM(I2:I12)+I3+I5+I9+I11)*25 -> 1550 | J14: =SUM(J2:J12)*1000 -> 865260
B17: Random | C17: 2944 | D17: 9108 | E17: 1970 | F17: 3940 | G17: 7248 | H17: 6780 | I17: 2285 | J17: 9083
B19: TRUE | C19: =LEFT(DEC2HEX(C17+COLUMN()+2),2) -> B8 | D19: =LEFT(DEC2HEX(D17+COLUMN()+2),2) -> 23 | E19: =LEFT(DEC2HEX(E17+COLUMN()+2),2) -> 7B | F19: =LEFT(DEC2HEX(F17+COLUMN()+2),2) -> F6 | G19: =LEFT(DEC2HEX(G17+COLUMN()+2),2) -> 1C | H19: =LEFT(DEC2HEX(H17+COLUMN()+2),2) -> 1A | I19: =LEFT(DEC2HEX(I17+COLUMN()+2),2) -> 8F | J19: =LEFT(DEC2HEX(J17+COLUMN()+2),2) -> 23
B20: FALSE | C20: =RIGHT(DEC2HEX(C17+COLUMN()+6),2) -> 89 | D20: =RIGHT(DEC2HEX(D17+COLUMN()+6),2) -> 9E | E20: =RIGHT(DEC2HEX(E17+COLUMN()+6),2) -> BD | F20: =RIGHT(DEC2HEX(F17+COLUMN()+6),2) -> 70 | G20: =RIGHT(DEC2HEX(G17+COLUMN()+6),2) -> 5D | H20: =RIGHT(DEC2HEX(H17+COLUMN()+6),2) -> 8A | I20: =RIGHT(DEC2HEX(I17+COLUMN()+6),2) -> FC | J20: =RIGHT(DEC2HEX(J17+COLUMN()+6),2) -> 8B
B22: Cek Manual | C22: =AND(ISNUMBER(FIND("=",Q1)),ISNUMBER(FIND("(",Q1))) -> TRUE | D22: =AND(ISNUMBER(FIND("=",R1)),ISNUMBER(FIND("(",R1))) -> TRUE | E22: =AND(ISNUMBER(FIND("=",S1)),ISNUMBER(FIND("(",S1))) -> TRUE | F22: =AND(ISNUMBER(FIND("=",T1)),ISNUMBER(FIND("(",T1))) -> TRUE | G22: =AND(ISNUMBER(FIND("=",U1)),ISNUMBER(FIND("(",U1))) -> TRUE | H22: =AND(ISNUMBER(FIND("=",V1)),ISNUMBER(FIND("(",V1))) -> TRUE | I22: =AND(ISNUMBER(FIND("=",W1)),ISNUMBER(FIND("(",W1)),I56) -> TRUE | J22: =AND(ISNUMBER(FIND("=",X1)),ISNUMBER(FIND("(",X1)),J56) -> TRUE
B23: Cek Range | C23: =ISNUMBER(FIND("base!A",SUBSTITUTE(Q1,"$",""))) -> TRUE | D23: =ISNUMBER(FIND("base!A",SUBSTITUTE(R1,"$",""))) -> TRUE | E23: =ISNUMBER(FIND("base!A",SUBSTITUTE(S1,"$",""))) -> TRUE | F23: =ISNUMBER(FIND("base!A",SUBSTITUTE(T1,"$",""))) -> TRUE | G23: =ISNUMBER(FIND("base!A",SUBSTITUTE(U1,"$",""))) -> TRUE | H23: =ISNUMBER(FIND("base!A",SUBSTITUTE(V1,"$",""))) -> TRUE | I23: =ISNUMBER(FIND("base!A",SUBSTITUTE(W1,"$",""))) -> TRUE | J23: =ISNUMBER(FIND("base!A",SUBSTITUTE(X1,"$",""))) -> TRUE
B24: Cek Kosong | C24: =NOT(OR(C2=0,C2="")) -> TRUE | D24: =NOT(OR(D2=0,D2="")) -> TRUE | E24: =NOT(OR(E2=0,E2="")) -> TRUE | F24: =NOT(OR(F2=0,F2="")) -> TRUE | G24: =NOT(OR(G2=0,G2="")) -> TRUE | H24: =NOT(OR(H2=0,H2="")) -> TRUE | I24: =NOT(OR(I2=0,I2="")) -> TRUE | J24: =NOT(OR(J2=0,J2="")) -> TRUE
B26: Final | C26: =AND(C22:C24) -> TRUE | D26: =AND(D22:D24) -> TRUE | E26: =AND(E22:E24) -> TRUE | F26: =AND(F22:F24) -> TRUE | G26: =AND(G22:G24) -> TRUE | H26: =AND(H22:H24) -> TRUE | I26: =AND(I22:I24) -> TRUE | J26: =AND(J22:J24) -> TRUE
B28: Cek F | C28: =AND(ISNUMBER(FIND("NTI",Q1)),ISNUMBER(FIND(CHAR(42),Q1))) -> TRUE | D28: =AND(ISNUMBER(FIND("AGEI",R1)),ISNUMBER(FIND(CHAR(42),R1))) -> TRUE | E28: =AND(ISNUMBER(FIND("MAX",S1)),ISNUMBER(FIND(CHAR(42),S1))) -> TRUE | F28: =AND(ISNUMBER(FIND("MIN",T1)),ISNUMBER(FIND(CHAR(42),T1))) -> TRUE | G28: =AND(ISNUMBER(FIND("NTI",U1)),ISNUMBER(FIND(CHAR(42),U1))) -> TRUE | H28: =AND(ISNUMBER(FIND("UMI",V1)),ISNUMBER(FIND(CHAR(42),V1))) -> TRUE | I28: =AND(ISNUMBER(FIND("NTI",W1)),ISNUMBER(FIND(CHAR(42),W1))) -> TRUE | J28: =AND(ISNUMBER(FIND("AGEIFS",X1)),ISNUMBER(FIND(CHAR(42),X1))) -> TRUE
B31: Cek jml | C31: =IFERROR(LEN(Q1)-LEN(SUBSTITUTE(Q1,"(","")),99) -> 1 | D31: =IFERROR(LEN(R1)-LEN(SUBSTITUTE(R1,"(","")),99) -> 2 | E31: =IFERROR(LEN(S1)-LEN(SUBSTITUTE(S1,"(","")),99) -> 1 | F31: =IFERROR(LEN(T1)-LEN(SUBSTITUTE(T1,"(","")),99) -> 1 | G31: =IFERROR(LEN(U1)-LEN(SUBSTITUTE(U1,"(","")),99) -> 1 | H31: =IFERROR(LEN(V1)-LEN(SUBSTITUTE(V1,"(","")),99) -> 1 | I31: =IFERROR(LEN(W1)-LEN(SUBSTITUTE(W1,"(","")),99) -> 2 | J31: =IFERROR(LEN(X1)-LEN(SUBSTITUTE(X1,"(","")),99) -> 2
B32: isi | C32: 1 | D32: 2 | E32: 1 | F32: 1 | G32: 1 | H32: 1 | I32: 2 | J32: 2 | N32: sa | O32: ya
B33: Hasil | C33: =(C31<=C32) -> TRUE | D33: =(D31<=D32) -> TRUE | E33: =(E31<=E32) -> TRUE | F33: =(F31<=F32) -> TRUE | G33: =(G31<=G32) -> TRUE | H33: =(H31<=H32) -> TRUE | I33: =(I31<=I32) -> TRUE | J33: =(J31<=J32) -> TRUE
B35: Final | C35: =AND(C28,C33,C59) -> TRUE | D35: =AND(D28,D33,D59) -> TRUE | E35: =AND(E28,E33,E59) -> TRUE | F35: =AND(F28,F33,F59) -> TRUE | G35: =AND(G28,G33,G59) -> TRUE | H35: =AND(H28,H33,H59) -> TRUE | I35: =AND(I28,I33,I59) -> TRUE | J35: =AND(J28,J33,J59) -> TRUE
B37: F hasil | C37: =IF(C35,C19,C20)&"-"&IFERROR(DEC2HEX(IF(C26,C14,C17)),"EEE")&";" -> B8-524; | D37: =IF(D35,D19,D20)&"-"&IFERROR(DEC2HEX(IF(D26,D14,D17)),"EEE")&";" -> 23-D7668; | E37: =IF(E35,E19,E20)&"-"&IFERROR(DEC2HEX(IF(E26,E14,E17)),"EEE")&";" -> 7B-1720; | F37: =IF(F35,F19,F20)&"-"&IFERROR(DEC2HEX(IF(F26,F14,F17)),"EEE")&";" -> F6-E90; | G37: =IF(G35,G19,G20)&"-"&IFERROR(DEC2HEX(IF(G26,G14,G17)),"EEE")&";" -> 1C-2DC; | H37: =IF(H35,H19,H20)&"-"&IFERROR(DEC2HEX(IF(H26,H14,H17)),"EEE")&";" -> 1A-6743; | I37: =IF(I35,I19,I20)&"-"&IFERROR(DEC2HEX(IF(I26,I14,I17)),"EEE")&";" -> 8F-60E; | J37: =IF(J35,J19,J20)&"-"&IFERROR(DEC2HEX(IF(J26,J14,J17)),"EEE") -> 23-D33EC
B39: Gabung | C39: =A2&"|"&C37&D37&E37&F37&G37&H37&I37&J37 -> ME5|B8-524;23-D7668;7B-1720;F6-E90;1C-2DC;1A-6743;8F-60E;23-D33EC | N39: {=INDIRECT(N32&O32)} -> ME5|B8-524;23-D7668;7B-1720;F6-E90;1C-2DC;1A-6743;8F-60E;23-D33EC
C41: =N39 -> ME5|B8-524;23-D7668;7B-1720;F6-E90;1C-2DC;1A-6743;8F-60E;23-D33EC
B44: 1 | C44: =LEN(_xlfn.FORMULATEXT('XL-Test'!D45)) -> 42 | D44: =LEN(_xlfn.FORMULATEXT('XL-Test'!E45)) -> 74 | E44: =LEN(_xlfn.FORMULATEXT('XL-Test'!F45)) -> 61 | F44: =LEN(_xlfn.FORMULATEXT('XL-Test'!G45)) -> 61 | G44: =LEN(_xlfn.FORMULATEXT('XL-Test'!H45)) -> 69 | H44: =LEN(_xlfn.FORMULATEXT('XL-Test'!I45)) -> 61
B45: 2 | C45: =LEN(_xlfn.FORMULATEXT('XL-Test'!D46)) -> 42 | D45: =LEN(_xlfn.FORMULATEXT('XL-Test'!E46)) -> 74 | E45: =LEN(_xlfn.FORMULATEXT('XL-Test'!F46)) -> 61 | F45: =LEN(_xlfn.FORMULATEXT('XL-Test'!G46)) -> 61 | G45: =LEN(_xlfn.FORMULATEXT('XL-Test'!H46)) -> 69 | H45: =LEN(_xlfn.FORMULATEXT('XL-Test'!I46)) -> 61
B46: 3 | C46: =LEN(_xlfn.FORMULATEXT('XL-Test'!D47)) -> 42 | D46: =LEN(_xlfn.FORMULATEXT('XL-Test'!E47)) -> 74 | E46: =LEN(_xlfn.FORMULATEXT('XL-Test'!F47)) -> 61 | F46: =LEN(_xlfn.FORMULATEXT('XL-Test'!G47)) -> 61 | G46: =LEN(_xlfn.FORMULATEXT('XL-Test'!H47)) -> 69 | H46: =LEN(_xlfn.FORMULATEXT('XL-Test'!I47)) -> 61
B47: 4 | C47: =LEN(_xlfn.FORMULATEXT('XL-Test'!D48)) -> 42 | D47: =LEN(_xlfn.FORMULATEXT('XL-Test'!E48)) -> 74 | E47: =LEN(_xlfn.FORMULATEXT('XL-Test'!F48)) -> 61 | F47: =LEN(_xlfn.FORMULATEXT('XL-Test'!G48)) -> 61 | G47: =LEN(_xlfn.FORMULATEXT('XL-Test'!H48)) -> 69 | H47: =LEN(_xlfn.FORMULATEXT('XL-Test'!I48)) -> 61
B48: 5 | C48: =LEN(_xlfn.FORMULATEXT('XL-Test'!D49)) -> 42 | D48: =LEN(_xlfn.FORMULATEXT('XL-Test'!E49)) -> 74 | E48: =LEN(_xlfn.FORMULATEXT('XL-Test'!F49)) -> 61 | F48: =LEN(_xlfn.FORMULATEXT('XL-Test'!G49)) -> 61 | G48: =LEN(_xlfn.FORMULATEXT('XL-Test'!H49)) -> 69 | H48: =LEN(_xlfn.FORMULATEXT('XL-Test'!I49)) -> 61
B49: 6 | C49: =LEN(_xlfn.FORMULATEXT('XL-Test'!D50)) -> 42 | D49: =LEN(_xlfn.FORMULATEXT('XL-Test'!E50)) -> 74 | E49: =LEN(_xlfn.FORMULATEXT('XL-Test'!F50)) -> 61 | F49: =LEN(_xlfn.FORMULATEXT('XL-Test'!G50)) -> 61 | G49: =LEN(_xlfn.FORMULATEXT('XL-Test'!H50)) -> 69 | H49: =LEN(_xlfn.FORMULATEXT('XL-Test'!I50)) -> 61
B50: 7 | C50: =LEN(_xlfn.FORMULATEXT('XL-Test'!D51)) -> 42 | D50: =LEN(_xlfn.FORMULATEXT('XL-Test'!E51)) -> 74 | E50: =LEN(_xlfn.FORMULATEXT('XL-Test'!F51)) -> 61 | F50: =LEN(_xlfn.FORMULATEXT('XL-Test'!G51)) -> 61 | G50: =LEN(_xlfn.FORMULATEXT('XL-Test'!H51)) -> 69 | H50: =LEN(_xlfn.FORMULATEXT('XL-Test'!I51)) -> 61
B51: 8 | C51: =LEN(_xlfn.FORMULATEXT('XL-Test'!D52)) -> 42 | D51: =LEN(_xlfn.FORMULATEXT('XL-Test'!E52)) -> 74 | E51: =LEN(_xlfn.FORMULATEXT('XL-Test'!F52)) -> 61 | F51: =LEN(_xlfn.FORMULATEXT('XL-Test'!G52)) -> 61 | G51: =LEN(_xlfn.FORMULATEXT('XL-Test'!H52)) -> 69 | H51: =LEN(_xlfn.FORMULATEXT('XL-Test'!I52)) -> 61
B52: 9 | C52: =LEN(_xlfn.FORMULATEXT('XL-Test'!D53)) -> 42 | D52: =LEN(_xlfn.FORMULATEXT('XL-Test'!E53)) -> 74 | E52: =LEN(_xlfn.FORMULATEXT('XL-Test'!F53)) -> 61 | F52: =LEN(_xlfn.FORMULATEXT('XL-Test'!G53)) -> 61 | G52: =LEN(_xlfn.FORMULATEXT('XL-Test'!H53)) -> 69 | H52: =LEN(_xlfn.FORMULATEXT('XL-Test'!I53)) -> 61
B53: 10 | C53: =LEN(_xlfn.FORMULATEXT('XL-Test'!D54)) -> 42 | D53: =LEN(_xlfn.FORMULATEXT('XL-Test'!E54)) -> 74 | E53: =LEN(_xlfn.FORMULATEXT('XL-Test'!F54)) -> 61 | F53: =LEN(_xlfn.FORMULATEXT('XL-Test'!G54)) -> 61 | G53: =LEN(_xlfn.FORMULATEXT('XL-Test'!H54)) -> 69 | H53: =LEN(_xlfn.FORMULATEXT('XL-Test'!I54)) -> 61
B54: 11 | C54: =LEN(_xlfn.FORMULATEXT('XL-Test'!D55)) -> 42 | D54: =LEN(_xlfn.FORMULATEXT('XL-Test'!E55)) -> 74 | E54: =LEN(_xlfn.FORMULATEXT('XL-Test'!F55)) -> 61 | F54: =LEN(_xlfn.FORMULATEXT('XL-Test'!G55)) -> 61 | G54: =LEN(_xlfn.FORMULATEXT('XL-Test'!H55)) -> 69 | H54: =LEN(_xlfn.FORMULATEXT('XL-Test'!I55)) -> 61
B56: N | C56: =AVERAGE(C44:C54)=C44 -> TRUE | D56: =AVERAGE(D44:D54)=D44 -> TRUE | E56: =AVERAGE(E44:E54)=E44 -> TRUE | F56: =AVERAGE(F44:F54)=F44 -> TRUE | G56: =AVERAGE(G44:G54)=G44 -> TRUE | H56: =AVERAGE(H44:H54)=H44 -> TRUE
...
