Workbook
Name amb: DF!$C$38
Name Kode_jawaban: DF!$C$39

Sheet XL-Test
A18: KODE SOAL | C18: SBEM013 | E18: KODE JAWABAN | G18: =Kode_jawaban -> MM2|40-121D;4B-103;50-4156;6D-25F9;35-2BCA;3E-4D8;3B-B842
A20: Intruksi
B22: Medium Level - Latihan Soal Excel Kiriman Se-Indonesia
B24: Soal : | C24: Gunakan Fungsi Excel (Function) untuk menyelsaikan kasus dibawah ini, tidak disarankan menggunakan cara manual
C25: Selesaikan kasus tanpa menggunakan kolom bantuan, mengubah Table atau Menambah Table Baru!!, Gunakan Table seperti yang sudah di sediakan soal!!
B26: 1 | C26: Isi kolom Berat Expedisi dari berat asli, jika berat lebih dari 0.3 kg maka dibulatkan menjadi 1 kg dan Minimal Berat Pengiriman adalah 1 Kg
C27: Contoh : 1.2 kg dihitung 1 kg, 1.6 kg dihitung 2 kg, dan 0.2 kg dihitung 1 kg
B28: 2 | C28: Berapa Durasi Hari pengiriman, dihitung dari tanggal kirim hingga tanggal sampai (perhatikan Zona Waktunya)
B29: 3 | C29: Berapa sisa Durasi menit pengiriman, dihitung dari tanggal kirim hingga tanggal sampai (perhatikan Zona Waktunya) sisa dari durasi hari
B30: 4 | C30: Isi kolom Jenis Pembayaran yang diambil dari bagian akhir Nomor Resi
B31: 5 | C31: Isi Ongkos Kirim dengan ketentuan Table dibawah ini, untuk memudahkan gunakan Formula HLOOKUP/XLOOKUP dari baris 1 agar pada saat table Update Promo ikut berubah
B32: 6 | C32: Isi Promo Ongkir dengan ketentuan Table dibawah ini, untuk memudahkan gunakan Formula HLOOKUP/XLOOKUP dari baris 2 agar pada saat table Update Promo ikut berubah
B33: 7 | C33: Isi Kolom Total Ongkos kirim yang didapat dari Ongkos Kirim dikali Berat Expedisi (kg) kemudian dikurangi Promo Ongkir
C35: Jangan diubah | D35: COD/CASH | E35: TRANSFER/QRIS | F35: DANA/OVO
C36: Ongkos Kirim | D36: 54000 | E36: 51000 | F36: 56000
C37: Promo Ongkir | D37: 3000 | E37: 9000 | F37: 4000
C39: Sudah selesai mengerjakan? kirim Kode Soal dan Kode Jawaban diatas ke alamat : https://belajarexcel.id/xl-test/jawaban untuk mengecek hasilnya
C40: atau klik tombol disamping
H46: 1 | I46: 2 | J46: 3 | K46: 4 | L46: 5 | M46: 6 | N46: 7
A47: No | B47: Berat Asli (Kg) | C47: Nomor Resi | D47: Tanggal Kirim | E47: Zona | F47: Tanggal Sampai | G47: Zona | H47: Berat Expedisi (Kg) | I47: Durasi Hari | J47: Durasi Menit | K47: Jenis Pembayaran | L47: Ongkos Kirim | M47: Promo Ongkir | N47: Total Ongkos Kirim
A48: Contoh | B48: 1.6 | C48: JT483920175634-QRIS | D48: 46058.778 | E48: WIB | F48: 46059.888 | G48: WIB | H48: 2 | I48: 1 | J48: 158 | K48: QRIS | L48: 51000 | M48: 9000 | N48: 93000
A50: 1 | B50: 5.9 | C50: JT762915034821-COD | D50: 46076.353 | E50: WIT | F50: 46079.537 | G50: WIB | H50: =MAX(1,CEILING(B50-0.3,1)) -> 6 | I50: =INT((F50 - IF(G50="WITA",1/24,IF(G50="WIT",2/24,0))) - (D50 - IF(E50="WITA",1/24,IF(E50="WIT",2/24,0)))) -> 3 | J50: {=ROUND(MOD((F50-_xlfn.SWITCH(G50,"WIB",0,"WITA",1,"WIT",2)/24)-(D50-_xlfn.SWITCH(E50,"WIB",0,"WITA",1,"WIT",2)/24),1)*24*60,0)} -> 384 | K50: =_xlfn.TEXTAFTER(C50,"-") -> COD | L50: =_xlfn.XLOOKUP("*"&K50&"*",$D$35:$F$35,$D$36:$F$36,,2) -> 54000 | M50: =_xlfn.XLOOKUP("*"&K50&"*",$D$35:$F$35,$D$37:$F$37,,2) -> 3000 | N50: =L50*H50-M50 -> 321000
A51: 2 | B51: 6.3 | C51: JT915348672104-TRANSFER | D51: 46073.955 | E51: WITA | F51: 46075.977 | G51: WIT | H51: =MAX(1,CEILING(B51-0.3,1)) -> 6 | I51: =INT((F51 - IF(G51="WITA",1/24,IF(G51="WIT",2/24,0))) - (D51 - IF(E51="WITA",1/24,IF(E51="WIT",2/24,0)))) -> 1 | J51: {=ROUND(MOD((F51-_xlfn.SWITCH(G51,"WIB",0,"WITA",1,"WIT",2)/24)-(D51-_xlfn.SWITCH(E51,"WIB",0,"WITA",1,"WIT",2)/24),1)*24*60,0)} -> 1412 | K51: =_xlfn.TEXTAFTER(C51, "-") -> TRANSFER | L51: =_xlfn.XLOOKUP("*"&K51&"*",$D$35:$F$35,$D$36:$F$36,,2) -> 51000 | M51: =_xlfn.XLOOKUP("*"&K51&"*",$D$35:$F$35,$D$37:$F$37,,2) -> 9000 | N51: =L51*H51-M51 -> 297000
A52: 3 | B52: 5.4 | C52: JT604829173560-DANA | D52: 46049.268 | E52: WIT | F52: 46051.913 | G52: WITA | H52: =MAX(1,CEILING(B52-0.3,1)) -> 6 | I52: =INT((F52 - IF(G52="WITA",1/24,IF(G52="WIT",2/24,0))) - (D52 - IF(E52="WITA",1/24,IF(E52="WIT",2/24,0)))) -> 2 | J52: {=ROUND(MOD((F52-_xlfn.SWITCH(G52,"WIB",0,"WITA",1,"WIT",2)/24)-(D52-_xlfn.SWITCH(E52,"WIB",0,"WITA",1,"WIT",2)/24),1)*24*60,0)} -> 989 | K52: =_xlfn.TEXTAFTER(C52, "-") -> DANA | L52: =_xlfn.XLOOKUP("*"&K52&"*",$D$35:$F$35,$D$36:$F$36,,2) -> 56000 | M52: =_xlfn.XLOOKUP("*"&K52&"*",$D$35:$F$35,$D$37:$F$37,,2) -> 4000 | N52: =L52*H52-M52 -> 332000
A53: 4 | B53: 8.7 | C53: JT738204915672-CASH | D53: 46045.24 | E53: WIB | F53: 46048.279 | G53: WIT | H53: =MAX(1,CEILING(B53-0.3,1)) -> 9 | I53: =INT((F53 - IF(G53="WITA",1/24,IF(G53="WIT",2/24,0))) - (D53 - IF(E53="WITA",1/24,IF(E53="WIT",2/24,0)))) -> 2 | J53: {=ROUND(MOD((F53-_xlfn.SWITCH(G53,"WIB",0,"WITA",1,"WIT",2)/24)-(D53-_xlfn.SWITCH(E53,"WIB",0,"WITA",1,"WIT",2)/24),1)*24*60,0)} -> 1376 | K53: =_xlfn.TEXTAFTER(C53, "-") -> CASH | L53: =_xlfn.XLOOKUP("*"&K53&"*",$D$35:$F$35,$D$36:$F$36,,2) -> 54000 | M53: =_xlfn.XLOOKUP("*"&K53&"*",$D$35:$F$35,$D$37:$F$37,,2) -> 3000 | N53: =L53*H53-M53 -> 483000
A54: 5 | B54: 0.4 | C54: JT192837465908-OVO | D54: 46046.897 | E54: WIT | F54: 46049.249 | G54: WIT | H54: =MAX(1,CEILING(B54-0.3,1)) -> 1 | I54: =INT((F54 - IF(G54="WITA",1/24,IF(G54="WIT",2/24,0))) - (D54 - IF(E54="WITA",1/24,IF(E54="WIT",2/24,0)))) -> 2 | J54: {=ROUND(MOD((F54-_xlfn.SWITCH(G54,"WIB",0,"WITA",1,"WIT",2)/24)-(D54-_xlfn.SWITCH(E54,"WIB",0,"WITA",1,"WIT",2)/24),1)*24*60,0)} -> 508 | K54: =_xlfn.TEXTAFTER(C54, "-") -> OVO | L54: =_xlfn.XLOOKUP("*"&K54&"*",$D$35:$F$35,$D$36:$F$36,,2) -> 56000 | M54: =_xlfn.XLOOKUP("*"&K54&"*",$D$35:$F$35,$D$37:$F$37,,2) -> 4000 | N54: =L54*H54-M54 -> 52000
A55: 6 | B55: 1.3 | C55: JT564738291045-TRANSFER | D55: 46078.155 | E55: WIB | F55: 46081.455 | G55: WITA | H55: =MAX(1,CEILING(B55-0.3,1)) -> 1 | I55: =INT((F55 - IF(G55="WITA",1/24,IF(G55="WIT",2/24,0))) - (D55 - IF(E55="WITA",1/24,IF(E55="WIT",2/24,0)))) -> 3 | J55: {=ROUND(MOD((F55-_xlfn.SWITCH(G55,"WIB",0,"WITA",1,"WIT",2)/24)-(D55-_xlfn.SWITCH(E55,"WIB",0,"WITA",1,"WIT",2)/24),1)*24*60,0)} -> 372 | K55: =_xlfn.TEXTAFTER(C55, "-") -> TRANSFER | L55: =_xlfn.XLOOKUP("*"&K55&"*",$D$35:$F$35,$D$36:$F$36,,2) -> 51000 | M55: =_xlfn.XLOOKUP("*"&K55&"*",$D$35:$F$35,$D$37:$F$37,,2) -> 9000 | N55: =L55*H55-M55 -> 42000
A56: 7 | B56: 3.7 | C56: JT820174635920-COD | D56: 46041.653 | E56: WITA | F56: 46044.572 | G56: WIT | H56: =MAX(1,CEILING(B56-0.3,1)) -> 4 | I56: =INT((F56 - IF(G56="WITA",1/24,IF(G56="WIT",2/24,0))) - (D56 - IF(E56="WITA",1/24,IF(E56="WIT",2/24,0)))) -> 2 | J56: {=ROUND(MOD((F56-_xlfn.SWITCH(G56,"WIB",0,"WITA",1,"WIT",2)/24)-(D56-_xlfn.SWITCH(E56,"WIB",0,"WITA",1,"WIT",2)/24),1)*24*60,0)} -> 1262 | K56: =_xlfn.TEXTAFTER(C56, "-") -> COD | L56: =_xlfn.XLOOKUP("*"&K56&"*",$D$35:$F$35,$D$36:$F$36,,2) -> 54000 | M56: =_xlfn.XLOOKUP("*"&K56&"*",$D$35:$F$35,$D$37:$F$37,,2) -> 3000 | N56: =L56*H56-M56 -> 213000
A57: 8 | B57: 3.6 | C57: JT309485716203-QRIS | D57: 46036.974 | E57: WITA | F57: 46038.203 | G57: WIB | H57: =MAX(1,CEILING(B57-0.3,1)) -> 4 | I57: =INT((F57 - IF(G57="WITA",1/24,IF(G57="WIT",2/24,0))) - (D57 - IF(E57="WITA",1/24,IF(E57="WIT",2/24,0)))) -> 1 | J57: {=ROUND(MOD((F57-_xlfn.SWITCH(G57,"WIB",0,"WITA",1,"WIT",2)/24)-(D57-_xlfn.SWITCH(E57,"WIB",0,"WITA",1,"WIT",2)/24),1)*24*60,0)} -> 391 | K57: =_xlfn.TEXTAFTER(C57, "-") -> QRIS | L57: =_xlfn.XLOOKUP("*"&K57&"*",$D$35:$F$35,$D$36:$F$36,,2) -> 51000 | M57: =_xlfn.XLOOKUP("*"&K57&"*",$D$35:$F$35,$D$37:$F$37,,2) -> 9000 | N57: =L57*H57-M57 -> 195000
A58: 9 | B58: 0.2 | C58: JT675920384716-DANA | D58: 46046.452 | E58: WITA | F58: 46049.251 | G58: WITA | H58: =MAX(1,CEILING(B58-0.3,1)) -> 1 | I58: =INT((F58 - IF(G58="WITA",1/24,IF(G58="WIT",2/24,0))) - (D58 - IF(E58="WITA",1/24,IF(E58="WIT",2/24,0)))) -> 2 | J58: {=ROUND(MOD((F58-_xlfn.SWITCH(G58,"WIB",0,"WITA",1,"WIT",2)/24)-(D58-_xlfn.SWITCH(E58,"WIB",0,"WITA",1,"WIT",2)/24),1)*24*60,0)} -> 1151 | K58: =_xlfn.TEXTAFTER(C58, "-") -> DANA | L58: =_xlfn.XLOOKUP("*"&K58&"*",$D$35:$F$35,$D$36:$F$36,,2) -> 56000 | M58: =_xlfn.XLOOKUP("*"&K58&"*",$D$35:$F$35,$D$37:$F$37,,2) -> 4000 | N58: =L58*H58-M58 -> 52000
A59: 10 | B59: 3.2 | C59: JT483716205948-TRANSFER | D59: 46039.459 | E59: WIT | F59: 46042.054 | G59: WIT | H59: =MAX(1,CEILING(B59-0.3,1)) -> 3 | I59: =INT((F59 - IF(G59="WITA",1/24,IF(G59="WIT",2/24,0))) - (D59 - IF(E59="WITA",1/24,IF(E59="WIT",2/24,0)))) -> 2 | J59: {=ROUND(MOD((F59-_xlfn.SWITCH(G59,"WIB",0,"WITA",1,"WIT",2)/24)-(D59-_xlfn.SWITCH(E59,"WIB",0,"WITA",1,"WIT",2)/24),1)*24*60,0)} -> 857 | K59: =_xlfn.TEXTAFTER(C59, "-") -> TRANSFER | L59: =_xlfn.XLOOKUP("*"&K59&"*",$D$35:$F$35,$D$36:$F$36,,2) -> 51000 | M59: =_xlfn.XLOOKUP("*"&K59&"*",$D$35:$F$35,$D$37:$F$37,,2) -> 9000 | N59: =L59*H59-M59 -> 144000
A60: 11 | B60: 7.7 | C60: JT920384756120-QRIS | D60: 46054.338 | E60: WIB | F60: 46056.792 | G60: WIB | H60: =MAX(1,CEILING(B60-0.3,1)) -> 8 | I60: =INT((F60 - IF(G60="WITA",1/24,IF(G60="WIT",2/24,0))) - (D60 - IF(E60="WITA",1/24,IF(E60="WIT",2/24,0)))) -> 2 | J60: {=ROUND(MOD((F60-_xlfn.SWITCH(G60,"WIB",0,"WITA",1,"WIT",2)/24)-(D60-_xlfn.SWITCH(E60,"WIB",0,"WITA",1,"WIT",2)/24),1)*24*60,0)} -> 653 | K60: =_xlfn.TEXTAFTER(C60, "-") -> QRIS | L60: =_xlfn.XLOOKUP("*"&K60&"*",$D$35:$F$35,$D$36:$F$36,,2) -> 51000 | M60: =_xlfn.XLOOKUP("*"&K60&"*",$D$35:$F$35,$D$37:$F$37,,2) -> 9000 | N60: =L60*H60-M60 -> 399000
A61: 12 | B61: 5.9 | C61: JT561029384756-OVO | D61: 46053.927 | E61: WIT | F61: 46054.893 | G61: WIB | H61: =MAX(1,CEILING(B61-0.3,1)) -> 6 | I61: =INT((F61 - IF(G61="WITA",1/24,IF(G61="WIT",2/24,0))) - (D61 - IF(E61="WITA",1/24,IF(E61="WIT",2/24,0)))) -> 1 | J61: {=ROUND(MOD((F61-_xlfn.SWITCH(G61,"WIB",0,"WITA",1,"WIT",2)/24)-(D61-_xlfn.SWITCH(E61,"WIB",0,"WITA",1,"WIT",2)/24),1)*24*60,0)} -> 71 | K61: =_xlfn.TEXTAFTER(C61, "-") -> OVO | L61: =_xlfn.XLOOKUP("*"&K61&"*",$D$35:$F$35,$D$36:$F$36,,2) -> 56000 | M61: =_xlfn.XLOOKUP("*"&K61&"*",$D$35:$F$35,$D$37:$F$37,,2) -> 4000 | N61: =L61*H61-M61 -> 332000
A62: 13 | B62: 4.8 | C62: JT708192635401-TRANSFER | D62: 46040.789 | E62: WITA | F62: 46042.392 | G62: WIB | H62: =MAX(1,CEILING(B62-0.3,1)) -> 5 | I62: =INT((F62 - IF(G62="WITA",1/24,IF(G62="WIT",2/24,0))) - (D62 - IF(E62="WITA",1/24,IF(E62="WIT",2/24,0)))) -> 1 | J62: {=ROUND(MOD((F62-_xlfn.SWITCH(G62,"WIB",0,"WITA",1,"WIT",2)/24)-(D62-_xlfn.SWITCH(E62,"WIB",0,"WITA",1,"WIT",2)/24),1)*24*60,0)} -> 928 | K62: =_xlfn.TEXTAFTER(C62, "-") -> TRANSFER | L62: =_xlfn.XLOOKUP("*"&K62&"*",$D$35:$F$35,$D$36:$F$36,,2) -> 51000 | M62: =_xlfn.XLOOKUP("*"&K62&"*",$D$35:$F$35,$D$37:$F$37,,2) -> 9000 | N62: =L62*H62-M62 -> 246000
... A64: 15 | B64: 6.8 | C64: JT650192837465-CASH | D64: 46078.076 | E64: WIT | F64: 46081.101 | G64: WIB | H64: =MAX(1,CEILING(B64-0.3,1)) -> 7 | I64: =INT((F64 - IF(G64="WITA",1/24,IF(G64="WIT",2/24,0))) - (D64 - IF(E64="WITA",1/24,IF(E64="WIT",2/24,0)))) -> 3 | J64: {=ROUND(MOD((F64-_xlfn.SWITCH(G64,"WIB",0,"WITA",1,"WIT",2)/24)-(D64-_xlfn.SWITCH(E64,"WIB",0,"WITA",1,"WIT",2)/24),1)*24*60,0)} -> 156 | K64: =_xlfn.TEXTAFTER(C64, "-") -> CASH | L64: =_xlfn.XLOOKUP("*"&K64&"*",$D$35:$F$35,$D$36:$F$36,,2) -> 54000 | M64: =_xlfn.XLOOKUP("*"&K64&"*",$D$35:$F$35,$D$37:$F$37,,2) -> 3000 | N64: =L64*H64-M64 -> 375000
A68: Selesaikan kasus tanpa menggunakan kolom bantuan, mengubah Table atau Menambah Table Baru!!, Gunakan Table seperti yang sudah di sediakan soal!!

Sheet About
I6: XL-TEST adalah platform inovatif yang menyediakan latihan Excel interaktif dengan pemeriksaan otomatis,
I7: sehingga pengguna dapat langsung mengetahui jawaban yang benar maupun salah.
I10: Terdapat 5 Level soal :
J12: Easy Level | L12: (⭐)
J13: Medium Level | L13: (⭐⭐)
J14: Hard Level | L14: (⭐⭐⭐)
J15: Extreme Level | L15: (⭐⭐⭐⭐)
J16: Championship Level | L16: (⭐⭐⭐⭐⭐)
B17: Saya adalah seorang Excel Holic yang percaya bahwa setiap angka memiliki cerita yang bisa ditemukan dengan cara yang tepat. | I17: Free Access
B18: “Excel bukan cuma soal kerjaan tapi juga hobi yang aku nikmati.” | I18: https://belajarexcel.id/xl-test/
B19: Contact :
B20: 🌐 Web | C20: https://setiadi.me
B21: 🪡threads | C21: https://www.threads.com/@andisetiadi
D27: Perlu Video Penjelasan atau Kunci Jawaban ?
D28: Scan barcode atau kunjungi
D29: https://lynk.id/setiadi/page/jawaban-xl-test

Sheet DF
A1: Def | C1: 1 | D1: 2 | E1: 3 | F1: 4 | G1: 5 | H1: 6 | I1: 7 | N1: 1 | O1: 2 | P1: 3 | Q1: 4 | R1: 5 | S1: 6 | T1: 7
A2: MM2 | B2: 1 | C2: ='XL-Test'!H50 -> 6 | D2: ='XL-Test'!I50 -> 3 | E2: =ROUND('XL-Test'!J50,0) -> 384 | F2: ='XL-Test'!K50 -> COD | G2: ='XL-Test'!L50 -> 54000 | H2: ='XL-Test'!M50 -> 3000 | I2: ='XL-Test'!N50 -> 321000 | M2: 1 | N2: =_xlfn.FORMULATEXT('XL-Test'!H50) -> =MAX(1;CEILING(B50-0,3;1)) | O2: =_xlfn.FORMULATEXT('XL-Test'!I50) -> =INT((F50 - IF(G50="WITA";1/24;IF(G50="WIT";2/24;0))) - (D50 - IF(E50="WITA";1/24;IF(E50="WIT";2/24;0)))) | P2: =_xlfn.FORMULATEXT('XL-Test'!J50) -> =ROUND(MOD((F50-SWITCH(G50;"WIB";0;"WITA";1;"WIT";2)/24)-(D50-SWITCH(E50;"WIB";0;"WITA";1;"WIT";2)/24);1)*24*60;0) | Q2: =_xlfn.FORMULATEXT('XL-Test'!K50) -> =TEXTAFTER(C50;"-") | R2: =_xlfn.FORMULATEXT('XL-Test'!L50) -> =XLOOKUP("*"&K50&"*";$D$35:$F$35;$D$36:$F$36;;2) | S2: =_xlfn.FORMULATEXT('XL-Test'!M50) -> =XLOOKUP("*"&K50&"*";$D$35:$F$35;$D$37:$F$37;;2) | T2: =_xlfn.FORMULATEXT('XL-Test'!N50) -> =L50*H50-M50
B3: 2 | C3: ='XL-Test'!H51 -> 6 | D3: ='XL-Test'!I51 -> 1 | E3: =ROUND('XL-Test'!J51,0) -> 1412 | F3: ='XL-Test'!K51 -> TRANSFER | G3: ='XL-Test'!L51 -> 51000 | H3: ='XL-Test'!M51 -> 9000 | I3: ='XL-Test'!N51 -> 297000 | M3: 2 | N3: =O2 -> =INT((F50 - IF(G50="WITA";1/24;IF(G50="WIT";2/24;0))) - (D50 - IF(E50="WITA";1/24;IF(E50="WIT";2/24;0))))
B4: 3 | C4: ='XL-Test'!H52 -> 6 | D4: ='XL-Test'!I52 -> 2 | E4: =ROUND('XL-Test'!J52,0) -> 989 | F4: ='XL-Test'!K52 -> DANA | G4: ='XL-Test'!L52 -> 56000 | H4: ='XL-Test'!M52 -> 4000 | I4: ='XL-Test'!N52 -> 332000 | M4: 3 | N4: =P2 -> =ROUND(MOD((F50-SWITCH(G50;"WIB";0;"WITA";1;"WIT";2)/24)-(D50-SWITCH(E50;"WIB";0;"WITA";1;"WIT";2)/24);1)*24*60;0)
B5: 4 | C5: ='XL-Test'!H53 -> 9 | D5: ='XL-Test'!I53 -> 2 | E5: =ROUND('XL-Test'!J53,0) -> 1376 | F5: ='XL-Test'!K53 -> CASH | G5: ='XL-Test'!L53 -> 54000 | H5: ='XL-Test'!M53 -> 3000 | I5: ='XL-Test'!N53 -> 483000 | M5: 4 | N5: =Q2 -> =TEXTAFTER(C50;"-")
B6: 5 | C6: ='XL-Test'!H54 -> 1 | D6: ='XL-Test'!I54 -> 2 | E6: =ROUND('XL-Test'!J54,0) -> 508 | F6: ='XL-Test'!K54 -> OVO | G6: ='XL-Test'!L54 -> 56000 | H6: ='XL-Test'!M54 -> 4000 | I6: ='XL-Test'!N54 -> 52000 | M6: 5 | N6: =R2 -> =XLOOKUP("*"&K50&"*";$D$35:$F$35;$D$36:$F$36;;2)
B7: 6 | C7: ='XL-Test'!H55 -> 1 | D7: ='XL-Test'!I55 -> 3 | E7: =ROUND('XL-Test'!J55,0) -> 372 | F7: ='XL-Test'!K55 -> TRANSFER | G7: ='XL-Test'!L55 -> 51000 | H7: ='XL-Test'!M55 -> 9000 | I7: ='XL-Test'!N55 -> 42000 | M7: 6 | N7: =S2 -> =XLOOKUP("*"&K50&"*";$D$35:$F$35;$D$37:$F$37;;2)
B8: 7 | C8: ='XL-Test'!H56 -> 4 | D8: ='XL-Test'!I56 -> 2 | E8: =ROUND('XL-Test'!J56,0) -> 1262 | F8: ='XL-Test'!K56 -> COD | G8: ='XL-Test'!L56 -> 54000 | H8: ='XL-Test'!M56 -> 3000 | I8: ='XL-Test'!N56 -> 213000 | M8: 7 | N8: =T2 -> =L50*H50-M50
B9: 8 | C9: ='XL-Test'!H57 -> 4 | D9: ='XL-Test'!I57 -> 1 | E9: =ROUND('XL-Test'!J57,0) -> 391 | F9: ='XL-Test'!K57 -> QRIS | G9: ='XL-Test'!L57 -> 51000 | H9: ='XL-Test'!M57 -> 9000 | I9: ='XL-Test'!N57 -> 195000
B10: 9 | C10: ='XL-Test'!H58 -> 1 | D10: ='XL-Test'!I58 -> 2 | E10: =ROUND('XL-Test'!J58,0) -> 1151 | F10: ='XL-Test'!K58 -> DANA | G10: ='XL-Test'!L58 -> 56000 | H10: ='XL-Test'!M58 -> 4000 | I10: ='XL-Test'!N58 -> 52000
B11: 10 | C11: ='XL-Test'!H59 -> 3 | D11: ='XL-Test'!I59 -> 2 | E11: =ROUND('XL-Test'!J59,0) -> 857 | F11: ='XL-Test'!K59 -> TRANSFER | G11: ='XL-Test'!L59 -> 51000 | H11: ='XL-Test'!M59 -> 9000 | I11: ='XL-Test'!N59 -> 144000
B12: 11 | C12: ='XL-Test'!H60 -> 8 | D12: ='XL-Test'!I60 -> 2 | E12: =ROUND('XL-Test'!J60,0) -> 653 | F12: ='XL-Test'!K60 -> QRIS | G12: ='XL-Test'!L60 -> 51000 | H12: ='XL-Test'!M60 -> 9000 | I12: ='XL-Test'!N60 -> 399000
B13: 12 | C13: ='XL-Test'!H61 -> 6 | D13: ='XL-Test'!I61 -> 1 | E13: =ROUND('XL-Test'!J61,0) -> 71 | F13: ='XL-Test'!K61 -> OVO | G13: ='XL-Test'!L61 -> 56000 | H13: ='XL-Test'!M61 -> 4000 | I13: ='XL-Test'!N61 -> 332000
B14: 13 | C14: ='XL-Test'!H62 -> 5 | D14: ='XL-Test'!I62 -> 1 | E14: =ROUND('XL-Test'!J62,0) -> 928 | F14: ='XL-Test'!K62 -> TRANSFER | G14: ='XL-Test'!L62 -> 51000 | H14: ='XL-Test'!M62 -> 9000 | I14: ='XL-Test'!N62 -> 246000
B15: 14 | C15: ='XL-Test'!H63 -> 3 | D15: ='XL-Test'!I63 -> 2 | E15: =ROUND('XL-Test'!J63,0) -> 185 | F15: ='XL-Test'!K63 -> QRIS | G15: ='XL-Test'!L63 -> 51000 | H15: ='XL-Test'!M63 -> 9000 | I15: ='XL-Test'!N63 -> 144000
B16: 15 | C16: ='XL-Test'!H64 -> 7 | D16: ='XL-Test'!I64 -> 3 | E16: =ROUND('XL-Test'!J64,0) -> 156 | F16: ='XL-Test'!K64 -> CASH | G16: ='XL-Test'!L64 -> 54000 | H16: ='XL-Test'!M64 -> 3000 | I16: ='XL-Test'!N64 -> 375000
C18: =SUM(C2:C16)+C2+C4+C6+C8+C10+C12+C14+C16*C3*C5*C7*C9*C11 -> 4637 | D18: =SUM(D2:D16)+D2+D4+D6+D8+D10+D12+D14+D16*D3*D5*D7*D9*D11*D15*D16 -> 259 | E18: =SUM(E2:E16)+E2+E4+E6+E8+E10+E12+E14+E16 -> 16726 | F18: =CODE(LEFT(F2))+CODE(RIGHT(F2))+CODE(LEFT(F3))+CODE(RIGHT(F3))+CODE(LEFT(F4))+CODE(RIGHT(F4))+CODE(LEFT(F5))+CODE(RIGHT(F5))+CODE(LEFT(F6))+CODE(RIGHT(F6))+CODE(LEFT(F6))+CODE(RIGHT(F6))+CODE(LEFT(F7))+CODE(RIGHT(F7))+CODE(LEFT(F8))+CODE(RIGHT(F8))+CODE(LEFT(F9))+CODE(RIGHT(F9))+CODE(LEFT(F10))+CODE(RIGHT(F10))+CODE(LEFT(F11))+CODE(RIGHT(F11))+CODE(MID(F2,3,1))+CODE(MID(F11,3,1))+CODE(LEFT(RIGHT(F9,3)))+CODE(LEFT(F12))+CODE(LEFT(F13))+CODE(LEFT(F14))+CODE(LEFT(F15))+CODE(LEFT(F16))+CODE(RIGHT(F2))+CODE(RIGHT(F4))+CODE(RIGHT(F6))+CODE(RIGHT(F8))+CODE(RIGHT(F12))+CODE(RIGHT(F15))+CODE(MID(F2,3,1))+CODE(MID(F6,3,1))+CODE(MID(F11,3,1))+CODE(MID(F15,3,1)) -> 2991 | G18: =(SUM(G2:G16)+G3+G6+G10+G13+G15+G8)/100 -> 11210 | H18: =(SUM(H2:H16)+H3+H6+H10+H13+H15+H8)/100 -> 1240 | I18: =(SUM(I2:I16)+I3+I6+I10+I13+I15+I8)/100 -> 47170
B19: Rand | C19: 5598 | D19: 6517 | E19: 6991 | F19: 9721 | G19: 4016 | H19: 4877 | I19: 4455
B21: TRUE | C21: =DEC2HEX(LEFT(C19,2)+COLUMN()+6) -> 40 | D21: =DEC2HEX(LEFT(D19,2)+COLUMN()+6) -> 4B | E21: =DEC2HEX(LEFT(E19,2)+COLUMN()+6) -> 50 | F21: =DEC2HEX(LEFT(F19,2)+COLUMN()+6) -> 6D | G21: =DEC2HEX(LEFT(G19,2)+COLUMN()+6) -> 35 | H21: =DEC2HEX(LEFT(H19,2)+COLUMN()+6) -> 3E | I21: =DEC2HEX(LEFT(I19,2)+COLUMN()+6) -> 3B
B22: FALSE | C22: =DEC2HEX(RIGHT(C19,2)+COLUMN()) -> 65 | D22: =DEC2HEX(RIGHT(D19,2)+COLUMN()) -> 15 | E22: =DEC2HEX(RIGHT(E19,2)+COLUMN()) -> 60 | F22: =DEC2HEX(RIGHT(F19,2)+COLUMN()) -> 1B | G22: =DEC2HEX(RIGHT(G19,2)+COLUMN()) -> 17 | H22: =DEC2HEX(RIGHT(H19,2)+COLUMN()) -> 55 | I22: =DEC2HEX(RIGHT(I19,2)+COLUMN()) -> 40
B24: Cek Kosong | C24: =IF(OR(C2="",C2=0),FALSE,TRUE) -> TRUE | D24: =IF(OR(D2="",D2=0),FALSE,TRUE) -> TRUE | E24: =IF(OR(E2="",E2=0),FALSE,TRUE) -> TRUE | F24: =IF(OR(F2="",F2=0),FALSE,TRUE) -> TRUE | G24: =IF(OR(G2="",G2=0),FALSE,TRUE) -> TRUE | H24: =IF(OR(H2="",H2=0),FALSE,TRUE) -> TRUE | I24: =IF(OR(I2="",I2=0),FALSE,TRUE) -> TRUE
B25: Cek Fungsi | C25: =AND(ISNUMBER(FIND("=",N2)),ISNUMBER(FIND("(",N2))) -> TRUE | D25: =AND(ISNUMBER(FIND("=",O2)),ISNUMBER(FIND("(",O2))) -> TRUE | E25: =AND(ISNUMBER(FIND("=",P2)),ISNUMBER(FIND("(",P2))) -> TRUE | F25: =AND(ISNUMBER(FIND("=",Q2)),ISNUMBER(FIND("(",Q2))) -> TRUE | G25: =AND(ISNUMBER(FIND("=",R2)),ISNUMBER(FIND("(",R2))) -> TRUE | H25: =AND(ISNUMBER(FIND("=",S2)),ISNUMBER(FIND("(",S2))) -> TRUE | I25: =AND(ISNUMBER(FIND("=",T2)),ISNUMBER(FIND("-",T2))) -> TRUE
C27: =IFERROR(DEC2HEX(IF(AND(C24:C25,C61),C18,C19)),"EEE") -> 121D | D27: =IFERROR(DEC2HEX(IF(AND(D24:D25,D61),D18,D19)),"EEE") -> 103 | E27: =IFERROR(DEC2HEX(IF(AND(E24:E25,E61),E18,E19)),"EEE") -> 4156 | F27: =IFERROR(DEC2HEX(IF(AND(F24:F25,F61),F18,F19)),"EEE") -> 25F9 | G27: =IFERROR(DEC2HEX(IF(AND(G24:G25,G61),G18,G19)),"EEE") -> 2BCA | H27: =IFERROR(DEC2HEX(IF(AND(H24:H25,H61),H18,H19)),"EEE") -> 4D8 | I27: =IFERROR(DEC2HEX(IF(AND(I24:I25,I61),I18,I19)),"EEE") -> B842
B29: Cek Rumus | C29: =OR(ISNUMBER(FIND("OUND",N2)),ISNUMBER(FIND("CEIL",N2))) -> TRUE | D29: =OR(ISNUMBER(FIND("IF",O2)),ISNUMBER(FIND("SW",O2))) -> TRUE | E29: =OR(ISNUMBER(FIND("IF",P2)),ISNUMBER(FIND("SW",P2))) -> TRUE | F29: =OR(ISNUMBER(FIND("TAFT",Q2)),ISNUMBER(FIND("RIGH",Q2)),,ISNUMBER(FIND("MID",Q2))) -> TRUE | G29: =OR(ISNUMBER(FIND("HLOO",R2)),ISNUMBER(FIND("XLOO",R2))) -> TRUE | H29: =OR(ISNUMBER(FIND("HLOO",S2)),ISNUMBER(FIND("XLOO",S2))) -> TRUE | I29: =AND(ISNUMBER(FIND("*",T2)),ISNUMBER(FIND("-",T2))) -> TRUE
B30: Cek banyak | C30: =IFERROR(LEN(N2)-LEN(SUBSTITUTE(N2,"(","")),99) -> 2 | D30: =IFERROR(LEN(O2)-LEN(SUBSTITUTE(O2,"(","")),99) -> 7 | E30: =IFERROR(LEN(P2)-LEN(SUBSTITUTE(P2,"(","")),99) -> 6 | F30: =IFERROR(LEN(Q2)-LEN(SUBSTITUTE(Q2,"(","")),99) -> 1 | G30: =IFERROR(LEN(R2)-LEN(SUBSTITUTE(R2,"(","")),99) -> 1 | H30: =IFERROR(LEN(S2)-LEN(SUBSTITUTE(S2,"(","")),99) -> 1 | I30: =IFERROR(LEN(T2)-LEN(SUBSTITUTE(T2,"(","")),99) -> 0
C31: 2 | D31: 9 | E31: 9 | F31: 2 | G31: 1 | H31: 1 | I31: 1
C32: =C30<=C31 -> TRUE | D32: =D30<=D31 -> TRUE | E32: =E30<=E31 -> TRUE | F32: =F30<=F31 -> TRUE | G32: =G30<=G31 -> TRUE | H32: =H30<=H31 -> TRUE | I32: =I30<=I31 -> TRUE
C34: =IF(AND(C29,C32),C21,C22)&"-"&C27&";" -> 40-121D; | D34: =IF(AND(D29,D32),D21,D22)&"-"&D27&";" -> 4B-103; | E34: =IF(AND(E29,E32),E21,E22)&"-"&E27&";" -> 50-4156; | F34: =IF(AND(F29,F32),F21,F22)&"-"&F27&";" -> 6D-25F9; | G34: =IF(AND(G29,G32),G21,G22)&"-"&G27&";" -> 35-2BCA; | H34: =IF(AND(H29,H32),H21,H22)&"-"&H27&";" -> 3E-4D8; | I34: =IF(AND(I29,I32),I21,I22)&"-"&I27 -> 3B-B842
C36: =A2&"|"&C34&D34&E34&F34&G34&H34&I34 -> MM2|40-121D;4B-103;50-4156;6D-25F9;35-2BCA;3E-4D8;3B-B842
C38: =C36 -> MM2|40-121D;4B-103;50-4156;6D-25F9;35-2BCA;3E-4D8;3B-B842 | E38: am | G38: b
C39: {=INDIRECT(E38&G38)} -> MM2|40-121D;4B-103;50-4156;6D-25F9;35-2BCA;3E-4D8;3B-B842
A42: Cek Tarik | B42: 1 | C42: =LEN(_xlfn.FORMULATEXT('XL-Test'!H50)) -> 26 | D42: =LEN(_xlfn.FORMULATEXT('XL-Test'!I50)) -> 105 | E42: =LEN(_xlfn.FORMULATEXT('XL-Test'!J50)) -> 114 | F42: =LEN(_xlfn.FORMULATEXT('XL-Test'!K50)) -> 19 | G42: =LEN(_xlfn.FORMULATEXT('XL-Test'!L50)) -> 48 | H42: =LEN(_xlfn.FORMULATEXT('XL-Test'!M50)) -> 48 | I42: =LEN(_xlfn.FORMULATEXT('XL-Test'!N50)) -> 12
B43: 2 | C43: =LEN(_xlfn.FORMULATEXT('XL-Test'!H51)) -> 26 | D43: =LEN(_xlfn.FORMULATEXT('XL-Test'!I51)) -> 105 | E43: =LEN(_xlfn.FORMULATEXT('XL-Test'!J51)) -> 114 | F43: =LEN(_xlfn.FORMULATEXT('XL-Test'!K51)) -> 20 | G43: =LEN(_xlfn.FORMULATEXT('XL-Test'!L51)) -> 48 | H43: =LEN(_xlfn.FORMULATEXT('XL-Test'!M51)) -> 48 | I43: =LEN(_xlfn.FORMULATEXT('XL-Test'!N51)) -> 12
B44: 3 | C44: =LEN(_xlfn.FORMULATEXT('XL-Test'!H52)) -> 26 | D44: =LEN(_xlfn.FORMULATEXT('XL-Test'!I52)) -> 105 | E44: =LEN(_xlfn.FORMULATEXT('XL-Test'!J52)) -> 114 | F44: =LEN(_xlfn.FORMULATEXT('XL-Test'!K52)) -> 20 | G44: =LEN(_xlfn.FORMULATEXT('XL-Test'!L52)) -> 48 | H44: =LEN(_xlfn.FORMULATEXT('XL-Test'!M52)) -> 48 | I44: =LEN(_xlfn.FORMULATEXT('XL-Test'!N52)) -> 12
B45: 4 | C45: =LEN(_xlfn.FORMULATEXT('XL-Test'!H53)) -> 26 | D45: =LEN(_xlfn.FORMULATEXT('XL-Test'!I53)) -> 105 | E45: =LEN(_xlfn.FORMULATEXT('XL-Test'!J53)) -> 114 | F45: =LEN(_xlfn.FORMULATEXT('XL-Test'!K53)) -> 20 | G45: =LEN(_xlfn.FORMULATEXT('XL-Test'!L53)) -> 48 | H45: =LEN(_xlfn.FORMULATEXT('XL-Test'!M53)) -> 48 | I45: =LEN(_xlfn.FORMULATEXT('XL-Test'!N53)) -> 12
B46: 5 | C46: =LEN(_xlfn.FORMULATEXT('XL-Test'!H54)) -> 26 | D46: =LEN(_xlfn.FORMULATEXT('XL-Test'!I54)) -> 105 | E46: =LEN(_xlfn.FORMULATEXT('XL-Test'!J54)) -> 114 | F46: =LEN(_xlfn.FORMULATEXT('XL-Test'!K54)) -> 20 | G46: =LEN(_xlfn.FORMULATEXT('XL-Test'!L54)) -> 48 | H46: =LEN(_xlfn.FORMULATEXT('XL-Test'!M54)) -> 48 | I46: =LEN(_xlfn.FORMULATEXT('XL-Test'!N54)) -> 12
B47: 6 | C47: =LEN(_xlfn.FORMULATEXT('XL-Test'!H55)) -> 26 | D47: =LEN(_xlfn.FORMULATEXT('XL-Test'!I55)) -> 105 | E47: =LEN(_xlfn.FORMULATEXT('XL-Test'!J55)) -> 114 | F47: =LEN(_xlfn.FORMULATEXT('XL-Test'!K55)) -> 20 | G47: =LEN(_xlfn.FORMULATEXT('XL-Test'!L55)) -> 48 | H47: =LEN(_xlfn.FORMULATEXT('XL-Test'!M55)) -> 48 | I47: =LEN(_xlfn.FORMULATEXT('XL-Test'!N55)) -> 12
B48: 7 | C48: =LEN(_xlfn.FORMULATEXT('XL-Test'!H56)) -> 26 | D48: =LEN(_xlfn.FORMULATEXT('XL-Test'!I56)) -> 105 | E48: =LEN(_xlfn.FORMULATEXT('XL-Test'!J56)) -> 114 | F48: =LEN(_xlfn.FORMULATEXT('XL-Test'!K56)) -> 20 | G48: =LEN(_xlfn.FORMULATEXT('XL-Test'!L56)) -> 48 | H48: =LEN(_xlfn.FORMULATEXT('XL-Test'!M56)) -> 48 | I48: =LEN(_xlfn.FORMULATEXT('XL-Test'!N56)) -> 12
B49: 8 | C49: =LEN(_xlfn.FORMULATEXT('XL-Test'!H57)) -> 26 | D49: =LEN(_xlfn.FORMULATEXT('XL-Test'!I57)) -> 105 | E49: =LEN(_xlfn.FORMULATEXT('XL-Test'!J57)) -> 114 | F49: =LEN(_xlfn.FORMULATEXT('XL-Test'!K57)) -> 20 | G49: =LEN(_xlfn.FORMULATEXT('XL-Test'!L57)) -> 48 | H49: =LEN(_xlfn.FORMULATEXT('XL-Test'!M57)) -> 48 | I49: =LEN(_xlfn.FORMULATEXT('XL-Test'!N57)) -> 12
B50: 9 | C50: =LEN(_xlfn.FORMULATEXT('XL-Test'!H58)) -> 26 | D50: =LEN(_xlfn.FORMULATEXT('XL-Test'!I58)) -> 105 | E50: =LEN(_xlfn.FORMULATEXT('XL-Test'!J58)) -> 114 | F50: =LEN(_xlfn.FORMULATEXT('XL-Test'!K58)) -> 20 | G50: =LEN(_xlfn.FORMULATEXT('XL-Test'!L58)) -> 48 | H50: =LEN(_xlfn.FORMULATEXT('XL-Test'!M58)) -> 48 | I50: =LEN(_xlfn.FORMULATEXT('XL-Test'!N58)) -> 12
...
