Workbook
Name kode_jawaban: DF!$M$39

Sheet XL-Test
A20: KODE SOAL | C20: SBEM011 | E20: KODE JAWABAN | G20: =kode_jawaban -> MK4|12-1BA4;5B-D950;2C-EAB99;23-113C6F;67-EABF7;26-334A4;27-8032;28-17156
A22: Intruksi
B24: Medium Level - Latihan Soal Excel Packing Dus Pesanan
B26: Soal : | C26: Gunakan Fungsi Excel (Function) untuk menyelsaikan kasus dibawah ini, tidak disarankan menggunakan cara manual
B27: 1 | C27: Isi kolom Jumlah Dus dengan berapa jumlah Dus yang dibutuhkan untuk mengisi Jumlah Pesanan
B28: 2 | C28: Isi kolom Jumlah Pcs dengan berapa Pcs sisa yang tidak bisa masuk kedalam Dus
B29: 3 | C29: Isi kolom Tanggal Pesanan dengan Tanggal Pesanan System
B30: 4 | C30: Isi kolom Jam Pesanan dengan Jam Pesanan System | M30: 1 Dus = 42 Pcs
B31: 5 | C31: Isi kolom Tanggal Pembayaran dengan tanggal di hari Sabtu terdekat setelah Tanggal pesanan.
C32: Untuk tanggal pesanan pada hari Sabtu, maka Tanggal pembayaran adalah Sabtu di minggu berikutnya.
B33: 6 | C33: Berapa Jumlah Pcs yang sudah berada didalam Dus dari jumlah pesanan yang selsai di proses
B34: 7 | C34: isi kolom Kekurangan Pcs dengan berapa Pcs Kekurangan Jika ingin menjadi 1 Dus utuh berikutnya di sisa Pesanan selsai di proses yg belum masuk ke dus
C35: jika kekurangan tidak memenuhi untuk 1 dus, isi dengan sisa kekurangan pesanan
B36: 8 | C36: Isi kolom Kekurangan dengan berapa Pcs kekurangan yang belum di proses untuk pesanan
C38: Sudah selesai mengerjakan? kirim Kode Soal dan Kode Jawaban diatas ke alamat : https://belajarexcel.id/xl-test/jawaban untuk mengecek hasilnya
C39: atau klik tombol disamping
F45: 1 | G45: 2 | H45: 3 | I45: 4 | J45: 5 | L45: 6 | M45: 7 | N45: 8
B46: No | C46: Nama Lengkap | D46: Tanggal Pesanan (System) | E46: Jumlah Pesanan | F46: Jumlah Dus | G46: Jumlah Pcs | H46: Tanggal Pesanan | I46: Jam Pesanan | J46: Tanggal Pembayaran | K46: Pesanan Selesai di proses | L46: Jumlah Pcs (didalam dus) | M46: Kekurangan Pcs (untuk 1 dus) | N46: Kekurangan Pcs (Pesanan)
B47: 1 | C47: Andi Pratama | D47: 45673.197 | E47: 52 | F47: =QUOTIENT(E47,42) -> 1 | G47: =MOD(E47,42) -> 10 | H47: =INT(D47) -> 45673 | I47: =MOD(D47,1) -> 0.19722222 | J47: =H47+MOD(13-H47,7)+1 -> 45675 | K47: 50 | L47: =FLOOR(K47,42) -> 42 | M47: =MIN(CEILING(K47,42)-K47,E47-K47) -> 2 | N47: =E47-K47 -> 2
B48: 2 | C48: Siti Nurhaliza Ramadhani | D48: 45852.639 | E48: 234 | F48: =QUOTIENT(E48,42) -> 5 | G48: =MOD(E48,42) -> 24 | H48: =INT(D48) -> 45852 | I48: =MOD(D48,1) -> 0.63888889 | J48: =H48+MOD(13-H48,7)+1 -> 45857 | K48: 93 | L48: =FLOOR(K48,42) -> 84 | M48: =MIN(CEILING(K48,42)-K48,E48-K48) -> 33 | N48: =E48-K48 -> 141
B49: 3 | C49: Budi Santoso | D49: 45951.439 | E49: 157 | F49: =QUOTIENT(E49,42) -> 3 | G49: =MOD(E49,42) -> 31 | H49: =INT(D49) -> 45951 | I49: =MOD(D49,1) -> 0.43888889 | J49: =H49+MOD(13-H49,7)+1 -> 45955 | K49: 130 | L49: =FLOOR(K49,42) -> 126 | M49: =MIN(CEILING(K49,42)-K49,E49-K49) -> 27 | N49: =E49-K49 -> 27
B50: 4 | C50: Rani Oktaviani | D50: 45891.824 | E50: 201 | F50: =QUOTIENT(E50,42) -> 4 | G50: =MOD(E50,42) -> 33 | H50: =INT(D50) -> 45891 | I50: =MOD(D50,1) -> 0.82361111 | J50: =H50+MOD(13-H50,7)+1 -> 45892 | K50: 145 | L50: =FLOOR(K50,42) -> 126 | M50: =MIN(CEILING(K50,42)-K50,E50-K50) -> 23 | N50: =E50-K50 -> 56
B51: 5 | C51: Dwi Putra Nugroho | D51: 45725.899 | E51: 225 | F51: =QUOTIENT(E51,42) -> 5 | G51: =MOD(E51,42) -> 15 | H51: =INT(D51) -> 45725 | I51: =MOD(D51,1) -> 0.89930556 | J51: =H51+MOD(13-H51,7)+1 -> 45731 | K51: 220 | L51: =FLOOR(K51,42) -> 210 | M51: =MIN(CEILING(K51,42)-K51,E51-K51) -> 5 | N51: =E51-K51 -> 5
B52: 6 | C52: Fitri Ayu Lestari | D52: 45685.772 | E52: 219 | F52: =QUOTIENT(E52,42) -> 5 | G52: =MOD(E52,42) -> 9 | H52: =INT(D52) -> 45685 | I52: =MOD(D52,1) -> 0.77222222 | J52: =H52+MOD(13-H52,7)+1 -> 45689 | K52: 119 | L52: =FLOOR(K52,42) -> 84 | M52: =MIN(CEILING(K52,42)-K52,E52-K52) -> 7 | N52: =E52-K52 -> 100
B53: 7 | C53: Rizky Aditya Saputra | D53: 45828.167 | E53: 57 | F53: =QUOTIENT(E53,42) -> 1 | G53: =MOD(E53,42) -> 15 | H53: =INT(D53) -> 45828 | I53: =MOD(D53,1) -> 0.16736111 | J53: =H53+MOD(13-H53,7)+1 -> 45829 | K53: 32 | L53: =FLOOR(K53,42) -> 0 | M53: =MIN(CEILING(K53,42)-K53,E53-K53) -> 10 | N53: =E53-K53 -> 25
B54: 8 | C54: Maya Salsabila | D54: 45702.815 | E54: 120 | F54: =QUOTIENT(E54,42) -> 2 | G54: =MOD(E54,42) -> 36 | H54: =INT(D54) -> 45702 | I54: =MOD(D54,1) -> 0.81527778 | J54: =H54+MOD(13-H54,7)+1 -> 45703 | K54: 87 | L54: =FLOOR(K54,42) -> 84 | M54: =MIN(CEILING(K54,42)-K54,E54-K54) -> 33 | N54: =E54-K54 -> 33
B55: 9 | C55: Joko Prasetyo | D55: 45661.065 | E55: 32 | F55: =QUOTIENT(E55,42) -> 0 | G55: =MOD(E55,42) -> 32 | H55: =INT(D55) -> 45661 | I55: =MOD(D55,1) -> 0.064583333 | J55: =H55+MOD(13-H55,7)+1 -> 45668 | K55: 32 | L55: =FLOOR(K55,42) -> 0 | M55: =MIN(CEILING(K55,42)-K55,E55-K55) -> 0 | N55: =E55-K55 -> 0
B56: 10 | C56: Lestari Widyaningsih | D56: 45872.338 | E56: 159 | F56: =QUOTIENT(E56,42) -> 3 | G56: =MOD(E56,42) -> 33 | H56: =INT(D56) -> 45872 | I56: =MOD(D56,1) -> 0.33819444 | J56: =H56+MOD(13-H56,7)+1 -> 45878 | K56: 41 | L56: =FLOOR(K56,42) -> 0 | M56: =MIN(CEILING(K56,42)-K56,E56-K56) -> 1 | N56: =E56-K56 -> 118
B57: 11 | C57: Fajar Hidayatullah | D57: 45929.386 | E57: 187 | F57: =QUOTIENT(E57,42) -> 4 | G57: =MOD(E57,42) -> 19 | H57: =INT(D57) -> 45929 | I57: =MOD(D57,1) -> 0.38611111 | J57: =H57+MOD(13-H57,7)+1 -> 45934 | K57: 150 | L57: =FLOOR(K57,42) -> 126 | M57: =MIN(CEILING(K57,42)-K57,E57-K57) -> 18 | N57: =E57-K57 -> 37
B58: 12 | C58: Dewi Kartika Sari | D58: 45662.74 | E58: 66 | F58: =QUOTIENT(E58,42) -> 1 | G58: =MOD(E58,42) -> 24 | H58: =INT(D58) -> 45662 | I58: =MOD(D58,1) -> 0.73958333 | J58: =H58+MOD(13-H58,7)+1 -> 45668 | K58: 45 | L58: =FLOOR(K58,42) -> 42 | M58: =MIN(CEILING(K58,42)-K58,E58-K58) -> 21 | N58: =E58-K58 -> 21
... B61: 15 | C61: Rangga Saputro | D61: 45955.994 | E61: 177 | F61: =QUOTIENT(E61,42) -> 4 | G61: =MOD(E61,42) -> 9 | H61: =INT(D61) -> 45955 | I61: =MOD(D61,1) -> 0.99375 | J61: =H61+MOD(13-H61,7)+1 -> 45962 | K61: 169 | L61: =FLOOR(K61,42) -> 168 | M61: =MIN(CEILING(K61,42)-K61,E61-K61) -> 8 | N61: =E61-K61 -> 8

Sheet About
I6: XL-TEST adalah platform inovatif yang menyediakan latihan Excel interaktif dengan pemeriksaan otomatis,
I7: sehingga pengguna dapat langsung mengetahui jawaban yang benar maupun salah.
I10: Terdapat 5 Level soal :
J12: Easy Level | L12: (⭐)
J13: Medium Level | L13: (⭐⭐)
J14: Hard Level | L14: (⭐⭐⭐)
J15: Extreme Level | L15: (⭐⭐⭐⭐)
J16: Championship Level | L16: (⭐⭐⭐⭐⭐)
B17: Saya adalah seorang Excel Holic yang percaya bahwa setiap angka memiliki cerita yang bisa ditemukan dengan cara yang tepat. | I17: Free Access
B18: “Excel bukan cuma soal kerjaan tapi juga hobi yang aku nikmati.” | I18: https://belajarexcel.id/xl-test/
B19: Contact :
B20: 🌐 Web | C20: https://setiadi.me
B21: 🪡threads | C21: https://www.threads.com/@andisetiadi
D27: Perlu Video Penjelasan atau Kunci Jawaban ?
D28: Scan barcode atau kunjungi
D29: https://lynk.id/setiadi/page/jawaban-xl-test

Sheet DF
A1: DEF | C1: 1 | D1: 2 | E1: 3 | F1: 4 | G1: 5 | H1: 6 | I1: 7 | J1: 8 | P1: 1 | Q1: 2 | R1: 3 | S1: 4 | T1: 5 | U1: 6 | V1: 7 | W1: 8
A2: MK4 | B2: 1 | C2: ='XL-Test'!F47 -> 1 | D2: ='XL-Test'!G47 -> 10 | E2: ='XL-Test'!H47 -> 45673 | F2: ='XL-Test'!I47 -> 0.19722222 | G2: ='XL-Test'!J47 -> 45675 | H2: ='XL-Test'!L47 -> 42 | I2: ='XL-Test'!M47 -> 2 | J2: ='XL-Test'!N47 -> 2 | O2: 1 | P2: =_xlfn.FORMULATEXT('XL-Test'!F47) -> =QUOTIENT(E47;42) | Q2: =_xlfn.FORMULATEXT('XL-Test'!G47) -> =MOD(E47;42) | R2: =_xlfn.FORMULATEXT('XL-Test'!H47) -> =INT(D47) | S2: =_xlfn.FORMULATEXT('XL-Test'!I47) -> =MOD(D47;1) | T2: =_xlfn.FORMULATEXT('XL-Test'!J47) -> =H47+MOD(13-H47;7)+1 | U2: =_xlfn.FORMULATEXT('XL-Test'!L47) -> =FLOOR(K47;42) | V2: =_xlfn.FORMULATEXT('XL-Test'!M47) -> =MIN(CEILING(K47;42)-K47;E47-K47) | W2: =_xlfn.FORMULATEXT('XL-Test'!N47) -> =E47-K47
B3: 2 | C3: ='XL-Test'!F48 -> 5 | D3: ='XL-Test'!G48 -> 24 | E3: ='XL-Test'!H48 -> 45852 | F3: ='XL-Test'!I48 -> 0.63888889 | G3: ='XL-Test'!J48 -> 45857 | H3: ='XL-Test'!L48 -> 84 | I3: ='XL-Test'!M48 -> 33 | J3: ='XL-Test'!N48 -> 141 | O3: 2 | P3: =Q2 -> =MOD(E47;42)
B4: 3 | C4: ='XL-Test'!F49 -> 3 | D4: ='XL-Test'!G49 -> 31 | E4: ='XL-Test'!H49 -> 45951 | F4: ='XL-Test'!I49 -> 0.43888889 | G4: ='XL-Test'!J49 -> 45955 | H4: ='XL-Test'!L49 -> 126 | I4: ='XL-Test'!M49 -> 27 | J4: ='XL-Test'!N49 -> 27 | O4: 3 | P4: =R2 -> =INT(D47)
B5: 4 | C5: ='XL-Test'!F50 -> 4 | D5: ='XL-Test'!G50 -> 33 | E5: ='XL-Test'!H50 -> 45891 | F5: ='XL-Test'!I50 -> 0.82361111 | G5: ='XL-Test'!J50 -> 45892 | H5: ='XL-Test'!L50 -> 126 | I5: ='XL-Test'!M50 -> 23 | J5: ='XL-Test'!N50 -> 56 | O5: 4 | P5: =S2 -> =MOD(D47;1)
B6: 5 | C6: ='XL-Test'!F51 -> 5 | D6: ='XL-Test'!G51 -> 15 | E6: ='XL-Test'!H51 -> 45725 | F6: ='XL-Test'!I51 -> 0.89930556 | G6: ='XL-Test'!J51 -> 45731 | H6: ='XL-Test'!L51 -> 210 | I6: ='XL-Test'!M51 -> 5 | J6: ='XL-Test'!N51 -> 5 | O6: 5 | P6: =T2 -> =H47+MOD(13-H47;7)+1
B7: 6 | C7: ='XL-Test'!F52 -> 5 | D7: ='XL-Test'!G52 -> 9 | E7: ='XL-Test'!H52 -> 45685 | F7: ='XL-Test'!I52 -> 0.77222222 | G7: ='XL-Test'!J52 -> 45689 | H7: ='XL-Test'!L52 -> 84 | I7: ='XL-Test'!M52 -> 7 | J7: ='XL-Test'!N52 -> 100 | O7: 6 | P7: =U2 -> =FLOOR(K47;42)
B8: 7 | C8: ='XL-Test'!F53 -> 1 | D8: ='XL-Test'!G53 -> 15 | E8: ='XL-Test'!H53 -> 45828 | F8: ='XL-Test'!I53 -> 0.16736111 | G8: ='XL-Test'!J53 -> 45829 | H8: ='XL-Test'!L53 -> 0 | I8: ='XL-Test'!M53 -> 10 | J8: ='XL-Test'!N53 -> 25 | O8: 7 | P8: =V2 -> =MIN(CEILING(K47;42)-K47;E47-K47)
B9: 8 | C9: ='XL-Test'!F54 -> 2 | D9: ='XL-Test'!G54 -> 36 | E9: ='XL-Test'!H54 -> 45702 | F9: ='XL-Test'!I54 -> 0.81527778 | G9: ='XL-Test'!J54 -> 45703 | H9: ='XL-Test'!L54 -> 84 | I9: ='XL-Test'!M54 -> 33 | J9: ='XL-Test'!N54 -> 33 | O9: 8 | P9: =W2 -> =E47-K47
B10: 9 | C10: ='XL-Test'!F55 -> 0 | D10: ='XL-Test'!G55 -> 32 | E10: ='XL-Test'!H55 -> 45661 | F10: ='XL-Test'!I55 -> 0.064583333 | G10: ='XL-Test'!J55 -> 45668 | H10: ='XL-Test'!L55 -> 0 | I10: ='XL-Test'!M55 -> 0 | J10: ='XL-Test'!N55 -> 0
B11: 10 | C11: ='XL-Test'!F56 -> 3 | D11: ='XL-Test'!G56 -> 33 | E11: ='XL-Test'!H56 -> 45872 | F11: ='XL-Test'!I56 -> 0.33819444 | G11: ='XL-Test'!J56 -> 45878 | H11: ='XL-Test'!L56 -> 0 | I11: ='XL-Test'!M56 -> 1 | J11: ='XL-Test'!N56 -> 118
B12: 11 | C12: ='XL-Test'!F57 -> 4 | D12: ='XL-Test'!G57 -> 19 | E12: ='XL-Test'!H57 -> 45929 | F12: ='XL-Test'!I57 -> 0.38611111 | G12: ='XL-Test'!J57 -> 45934 | H12: ='XL-Test'!L57 -> 126 | I12: ='XL-Test'!M57 -> 18 | J12: ='XL-Test'!N57 -> 37
B13: 12 | C13: ='XL-Test'!F58 -> 1 | D13: ='XL-Test'!G58 -> 24 | E13: ='XL-Test'!H58 -> 45662 | F13: ='XL-Test'!I58 -> 0.73958333 | G13: ='XL-Test'!J58 -> 45668 | H13: ='XL-Test'!L58 -> 42 | I13: ='XL-Test'!M58 -> 21 | J13: ='XL-Test'!N58 -> 21
B14: 13 | C14: ='XL-Test'!F59 -> 3 | D14: ='XL-Test'!G59 -> 9 | E14: ='XL-Test'!H59 -> 45822 | F14: ='XL-Test'!I59 -> 0.67569444 | G14: ='XL-Test'!J59 -> 45829 | H14: ='XL-Test'!L59 -> 84 | I14: ='XL-Test'!M59 -> 1 | J14: ='XL-Test'!N59 -> 10
B15: 14 | C15: ='XL-Test'!F60 -> 2 | D15: ='XL-Test'!G60 -> 28 | E15: ='XL-Test'!H60 -> 45663 | F15: ='XL-Test'!I60 -> 0.74305556 | G15: ='XL-Test'!J60 -> 45668 | H15: ='XL-Test'!L60 -> 84 | I15: ='XL-Test'!M60 -> 13 | J15: ='XL-Test'!N60 -> 13
B16: 15 | C16: ='XL-Test'!F61 -> 4 | D16: ='XL-Test'!G61 -> 9 | E16: ='XL-Test'!H61 -> 45955 | F16: ='XL-Test'!I61 -> 0.99375 | G16: ='XL-Test'!J61 -> 45962 | H16: ='XL-Test'!L61 -> 168 | I16: ='XL-Test'!M61 -> 8 | J16: ='XL-Test'!N61 -> 8
B18: Value | C18: =SUM(C2:C16)+C4+C7+C10+C12+C15+C2 -> 58 | D18: =SUM(D2:D16)+D4+D7+D10+D12+D15+D2 -> 456 | E18: =SUM(E2:E16)+E4+E7+E10+E12+E15+E2 -> 961433 | F18: =SUM(F2:F16)+F4+F7+F10+F12+F15+F2 -> 11.295833 | G18: =SUM(G2:G16)+G4+G7+G10+G12+G15+G2 -> 961527 | H18: =SUM(H2:H16)+H4+H7+H10+H12+H15+H2 -> 1722 | I18: =SUM(I2:I16)+I4+I7+I10+I12+I15+I2 -> 269 | J18: =SUM(J2:J16)+J4+J7+J10+J12+J15+J2 -> 775
C19: =C18*122 -> 7076 | D19: =D18*122 -> 55632 | F19: =INT(F18*100000) -> 1129583 | H19: =H18*122 -> 210084 | I19: =I18*122 -> 32818 | J19: =J18*122 -> 94550
B20: Value F | C20: =IF(C19=0,C18,C19) -> 7076 | D20: =IF(D19=0,D18,D19) -> 55632 | E20: =IF(E19=0,E18,E19) -> 961433 | F20: =IF(F19=0,F18,F19) -> 1129583 | G20: =IF(G19=0,G18,G19) -> 961527 | H20: =IF(H19=0,H18,H19) -> 210084 | I20: =IF(I19=0,I18,I19) -> 32818 | J20: =IF(J19=0,J18,J19) -> 94550
B21: Random | C21: 1561 | D21: 8776 | E21: 3934 | F21: 2936 | G21: 9671 | H21: 3019 | I21: 3020 | J21: 3021
B23: Cek Kosong | C23: =NOT(OR(C2="",C2=0)) -> TRUE | D23: =NOT(OR(D2="",D2=0)) -> TRUE | E23: =NOT(OR(E2="",E2=0)) -> TRUE | F23: =NOT(OR(F2="",F2=0)) -> TRUE | G23: =NOT(OR(G2="",G2=0)) -> TRUE | H23: =NOT(OR(H2="",H2=0)) -> TRUE | I23: =NOT(OR(I2="",I2=0)) -> TRUE | J23: =NOT(OR(J2="",J2=0)) -> TRUE
B24: Cek Manual | C24: =AND(ISNUMBER(FIND("=",P2)),ISNUMBER(FIND("(",P2)),ISNUMBER(C2)) -> TRUE | D24: =AND(ISNUMBER(FIND("=",Q2)),ISNUMBER(FIND("(",Q2)),ISNUMBER(D2)) -> TRUE | E24: =AND(ISNUMBER(FIND("=",R2)),ISNUMBER(FIND("(",R2)),ISNUMBER(E2)) -> TRUE | F24: =AND(ISNUMBER(FIND("=",S2)),ISNUMBER(FIND("(",S2)),ISNUMBER(F2)) -> TRUE | G24: =AND(ISNUMBER(FIND("=",T2)),ISNUMBER(FIND("(",T2)),ISNUMBER(G2)) -> TRUE | H24: =AND(ISNUMBER(FIND("=",U2)),ISNUMBER(FIND("(",U2)),ISNUMBER(H2)) -> TRUE | I24: =AND(ISNUMBER(FIND("=",V2)),ISNUMBER(FIND("(",V2)),ISNUMBER(I2)) -> TRUE | J24: =AND(ISNUMBER(FIND("=",W2)),ISNUMBER(J2)) -> TRUE
A26: ** | B26: F Value | C26: =IFERROR(DEC2HEX(IF(AND(C23,C24,C66),C20,C21)),"EEE") -> 1BA4 | D26: =IFERROR(DEC2HEX(IF(AND(D23,D24,D66),D20,D21)),"EEE") -> D950 | E26: =IFERROR(DEC2HEX(IF(AND(E23,E24,E66),E20,E21)),"EEE") -> EAB99 | F26: =IFERROR(DEC2HEX(IF(AND(F23,F24,F66),F20,F21)),"EEE") -> 113C6F | G26: =IFERROR(DEC2HEX(IF(AND(G23,G24,G66),G20,G21)),"EEE") -> EABF7 | H26: =IFERROR(DEC2HEX(IF(AND(H23,H24,H66),H20,H21)),"EEE") -> 334A4 | I26: =IFERROR(DEC2HEX(IF(AND(I23,I24,I66),I20,I21)),"EEE") -> 8032 | J26: =IFERROR(DEC2HEX(IF(AND(J23,J24,J66),J20,J21)),"EEE") -> 17156
M27: D | N27: R | O27: 1
B28: TRUE | C28: =DEC2HEX(LEFT(C21,2)+COLUMN()) -> 12 | D28: =DEC2HEX(LEFT(D21,2)+COLUMN()) -> 5B | E28: =DEC2HEX(LEFT(E21,2)+COLUMN()) -> 2C | F28: =DEC2HEX(LEFT(F21,2)+COLUMN()) -> 23 | G28: =DEC2HEX(LEFT(G21,2)+COLUMN()) -> 67 | H28: =DEC2HEX(LEFT(H21,2)+COLUMN()) -> 26 | I28: =DEC2HEX(LEFT(I21,2)+COLUMN()) -> 27 | J28: =DEC2HEX(LEFT(J21,2)+COLUMN()) -> 28 | M28: K | N28: T | O28: 2
B29: FALSE | C29: =DEC2HEX(RIGHT(C21,2)+COLUMN()) -> 40 | D29: =DEC2HEX(RIGHT(D21,2)+COLUMN()) -> 50 | E29: =DEC2HEX(RIGHT(E21,2)+COLUMN()) -> 27 | F29: =DEC2HEX(RIGHT(F21,2)+COLUMN()) -> 2A | G29: =DEC2HEX(RIGHT(G21,2)+COLUMN()) -> 4E | H29: =DEC2HEX(RIGHT(H21,2)+COLUMN()) -> 1B | I29: =DEC2HEX(RIGHT(I21,2)+COLUMN()) -> 1D | J29: =DEC2HEX(RIGHT(J21,2)+COLUMN()) -> 1F | M29: F | N29: U | O29: 3
M30: M | N30: X | O30: 38
B31: Cek Jumlah | C31: =IFERROR(LEN(P2)-LEN(SUBSTITUTE(P2,"(","")),99) -> 1 | D31: =IFERROR(LEN(Q2)-LEN(SUBSTITUTE(Q2,"(","")),99) -> 1 | E31: =IFERROR(LEN(R2)-LEN(SUBSTITUTE(R2,"(","")),99) -> 1 | F31: =IFERROR(LEN(S2)-LEN(SUBSTITUTE(S2,"(","")),99) -> 1 | G31: =IFERROR(LEN(T2)-LEN(SUBSTITUTE(T2,"(","")),99) -> 1 | H31: =IFERROR(LEN(U2)-LEN(SUBSTITUTE(U2,"(","")),99) -> 1 | I31: =IFERROR(LEN(V2)-LEN(SUBSTITUTE(V2,"(","")),99) -> 2 | J31: =IFERROR(LEN(W2)-LEN(SUBSTITUTE(W2,"(","")),99) -> 0 | M31: E | N31: M | O31: 2
C32: 1 | D32: 1 | E32: 1 | F32: 1 | G32: 1 | H32: 1 | I32: 2 | J32: 1
B33: ** Bool | C33: =C31<=C32 -> TRUE | D33: =D31<=D32 -> TRUE | E33: =E31<=E32 -> TRUE | F33: =F31<=F32 -> TRUE | G33: =G31<=G32 -> TRUE | H33: =H31<=H32 -> TRUE | I33: =I31<=I32 -> TRUE | J33: =J31<=J32 -> TRUE
B35: Cek Formula | C35: =ISNUMBER(FIND("UOTI",P2)) -> TRUE | D35: =ISNUMBER(FIND("MOD",Q2)) -> TRUE | E35: =ISNUMBER(FIND("INT",R2)) -> TRUE | F35: =ISNUMBER(FIND("MOD",S2)) -> TRUE | G35: =ISNUMBER(FIND("MOD",T2)) -> TRUE | H35: =ISNUMBER(FIND("LOOR",U2)) -> TRUE | I35: =OR(ISNUMBER(FIND("CEI",V2)),ISNUMBER(FIND("MOD",V2))) -> TRUE | J35: =ISNUMBER(FIND("-",W2)) -> TRUE
B37: F Formula | C37: =IF(AND(C35,C33),C28,C29)&"-"&C26&";" -> 12-1BA4; | D37: =IF(AND(D35,D33),D28,D29)&"-"&D26&";" -> 5B-D950; | E37: =IF(AND(E35,E33),E28,E29)&"-"&E26&";" -> 2C-EAB99; | F37: =IF(AND(F35,F33),F28,F29)&"-"&F26&";" -> 23-113C6F; | G37: =IF(AND(G35,G33),G28,G29)&"-"&G26&";" -> 67-EABF7; | H37: =IF(AND(H35,H33),H28,H29)&"-"&H26&";" -> 26-334A4; | I37: =IF(AND(I35,I33),I28,I29)&"-"&I26&";" -> 27-8032; | J37: =IF(AND(J35,J33),J28,J29)&"-"&J26 -> 28-17156
C38: =A2&"|"&C37&D37&E37&F37&G37&H37&I37&J37 -> MK4|12-1BA4;5B-D950;2C-EAB99;23-113C6F;67-EABF7;26-334A4;27-8032;28-17156 | M38: =C38 -> MK4|12-1BA4;5B-D950;2C-EAB99;23-113C6F;67-EABF7;26-334A4;27-8032;28-17156
M39: {=INDIRECT(VLOOKUP("E",M27:O31,2,0)&VLOOKUP("M",M27:O31,3,0))} -> MK4|12-1BA4;5B-D950;2C-EAB99;23-113C6F;67-EABF7;26-334A4;27-8032;28-17156
B40: Cek Manual F
A41: 1 | B41: 6 | C41: =IFERROR(LEN(_xlfn.FORMULATEXT('XL-Test'!F47)),0) -> 17 | D41: =IFERROR(LEN(_xlfn.FORMULATEXT('XL-Test'!G47)),0) -> 12 | E41: =IFERROR(LEN(_xlfn.FORMULATEXT('XL-Test'!H47)),0) -> 9 | F41: =IFERROR(LEN(_xlfn.FORMULATEXT('XL-Test'!I47)),0) -> 11 | G41: =IFERROR(LEN(_xlfn.FORMULATEXT('XL-Test'!J47)),0) -> 20 | H41: =IFERROR(LEN(_xlfn.FORMULATEXT('XL-Test'!L47)),0) -> 14 | I41: =IFERROR(LEN(_xlfn.FORMULATEXT('XL-Test'!M47)),0) -> 33 | J41: =IFERROR(LEN(_xlfn.FORMULATEXT('XL-Test'!N47)),0) -> 8
A42: 2 | B42: 7 | C42: =IFERROR(LEN(_xlfn.FORMULATEXT('XL-Test'!F48)),0) -> 17 | D42: =IFERROR(LEN(_xlfn.FORMULATEXT('XL-Test'!G48)),0) -> 12 | E42: =IFERROR(LEN(_xlfn.FORMULATEXT('XL-Test'!H48)),0) -> 9 | F42: =IFERROR(LEN(_xlfn.FORMULATEXT('XL-Test'!I48)),0) -> 11 | G42: =IFERROR(LEN(_xlfn.FORMULATEXT('XL-Test'!J48)),0) -> 20 | H42: =IFERROR(LEN(_xlfn.FORMULATEXT('XL-Test'!L48)),0) -> 14 | I42: =IFERROR(LEN(_xlfn.FORMULATEXT('XL-Test'!M48)),0) -> 33 | J42: =IFERROR(LEN(_xlfn.FORMULATEXT('XL-Test'!N48)),0) -> 8
A43: 3 | B43: 8 | C43: =IFERROR(LEN(_xlfn.FORMULATEXT('XL-Test'!F49)),0) -> 17 | D43: =IFERROR(LEN(_xlfn.FORMULATEXT('XL-Test'!G49)),0) -> 12 | E43: =IFERROR(LEN(_xlfn.FORMULATEXT('XL-Test'!H49)),0) -> 9 | F43: =IFERROR(LEN(_xlfn.FORMULATEXT('XL-Test'!I49)),0) -> 11 | G43: =IFERROR(LEN(_xlfn.FORMULATEXT('XL-Test'!J49)),0) -> 20 | H43: =IFERROR(LEN(_xlfn.FORMULATEXT('XL-Test'!L49)),0) -> 14 | I43: =IFERROR(LEN(_xlfn.FORMULATEXT('XL-Test'!M49)),0) -> 33 | J43: =IFERROR(LEN(_xlfn.FORMULATEXT('XL-Test'!N49)),0) -> 8
A44: 4 | B44: 9 | C44: =IFERROR(LEN(_xlfn.FORMULATEXT('XL-Test'!F50)),0) -> 17 | D44: =IFERROR(LEN(_xlfn.FORMULATEXT('XL-Test'!G50)),0) -> 12 | E44: =IFERROR(LEN(_xlfn.FORMULATEXT('XL-Test'!H50)),0) -> 9 | F44: =IFERROR(LEN(_xlfn.FORMULATEXT('XL-Test'!I50)),0) -> 11 | G44: =IFERROR(LEN(_xlfn.FORMULATEXT('XL-Test'!J50)),0) -> 20 | H44: =IFERROR(LEN(_xlfn.FORMULATEXT('XL-Test'!L50)),0) -> 14 | I44: =IFERROR(LEN(_xlfn.FORMULATEXT('XL-Test'!M50)),0) -> 33 | J44: =IFERROR(LEN(_xlfn.FORMULATEXT('XL-Test'!N50)),0) -> 8
A45: 5 | B45: 10 | C45: =IFERROR(LEN(_xlfn.FORMULATEXT('XL-Test'!F51)),0) -> 17 | D45: =IFERROR(LEN(_xlfn.FORMULATEXT('XL-Test'!G51)),0) -> 12 | E45: =IFERROR(LEN(_xlfn.FORMULATEXT('XL-Test'!H51)),0) -> 9 | F45: =IFERROR(LEN(_xlfn.FORMULATEXT('XL-Test'!I51)),0) -> 11 | G45: =IFERROR(LEN(_xlfn.FORMULATEXT('XL-Test'!J51)),0) -> 20 | H45: =IFERROR(LEN(_xlfn.FORMULATEXT('XL-Test'!L51)),0) -> 14 | I45: =IFERROR(LEN(_xlfn.FORMULATEXT('XL-Test'!M51)),0) -> 33 | J45: =IFERROR(LEN(_xlfn.FORMULATEXT('XL-Test'!N51)),0) -> 8
...
