Workbook
Name kode_jawaban: 'Arti Kode Pagawai'!$AB$107

Sheet Soal
D1: 1 | E1: 2 | F1: 3 | G1: 4 | H1: 5 | I1: 6 | J1: 7 | K1: 8 | M1: 9 | N1: 10 | O1: 11 | P1: 12 | Q1: 13 | R1: 14 | S1: 15 | T1: 16 | U1: 17 | V1: 18 | W1: 19
A2: No | B2: Nama | C2: No Pegawai | D2: Tanggal Lahir | E2: Umur (Tahun) | F2: Status Karyawan | G2: Status Pernikahan | H2: Jumlah Anak | I2: Agama | J2: Tanggal Masuk Kerja | K2: Lama Bekerja (Dalam Bulan) | L2: Jam Kerja | M2: Golongan | N2: Upah Normal | O2: Upah Lembur | P2: Tunjangan Anak | Q2: Tunjangan Status | R2: Tunjangan Bonus | S2: Tunjangan Lauk Pauk | T2: Tunjangan Hari Raya | U2: Total Perolehan | V2: Iuran Koperasi | W2: Total Pendapatan Bersih | X2: 100000 | Y2: 50000 | Z2: 20000 | AA2: 10000 | AB2: 5000 | AC2: 1000 | AD2: Total Uang Sesuai Pecahan
A3: 1 | B3: Andi | C3: KC07111992-H12071990-2-KS | D3: =DATE(MID(Soal!C3,17,4),MID(Soal!C3,15,2),MID(Soal!C3,13,2)) -> 33066 | E3: =DATEDIF(D3,"04/04/2025","Y") -> 34 | F3: =IF(MID(C3,2,1)="C","Kontrak",IF(MID(Soal!C3,2,1)="T","Tetap","Lepas")) -> Kontrak | G3: =IF(LEFT(C3,1)="K","Kawin",IF(LEFT(C3,1)="B","Belum Kawin",IF(LEFT(C3,1)="D","Duda","Janda"))) -> Kawin | H3: =VALUE(MID(C3,22,1)) -> 2 | I3: =IF(MID(C3,12,1)="H","Hindu",IF(MID(C3,12,1)="I","Islam",IF(MID(C3,12,1)="N","Nasrani",IF(MID(C3,12,1)="B","Budha","Lainnya")))) -> Hindu | J3: =DATE(MID(Soal!C3,7,4),MID(Soal!C3,5,2),MID(Soal!C3,3,2)) -> 33915 | K3: =DATEDIF(J3,"04/04/2025","M") -> 388 | L3: 209 | M3: =IF(K3>432,4,IF(K3>=372,3,IF(K3>=300,2,1))) -> 3 | N3: =MIN(L3,200)*9555 -> 1911000 | O3: =IF(L3<=200,0,IF((L3-200)<=10,(L3-200)*35555,(10*35555)+((L3-210)*35555*110%))) -> 319995 | P3: =MIN(3,H3)*(10%*N3) -> 382200 | Q3: =IF(G3="Belum Kawin",0,5%*N3) -> 95550 | R3: =HLOOKUP(M3,$I$28:$L$29,2,FALSE)*N3 -> 171990 | S3: {=_xlfn.XLOOKUP(M3,$H$33:$H$36,_xlfn.XLOOKUP(RIGHT(C3,2),$I$32:$L$32,$I$33:$L$36))*N3} -> 191100 | T3: =IF(I3="Islam",10%,IF(I3="Nasrani",10.2%,10.3%))*N3 -> 196833 | U3: =ROUNDUP(SUM(N3:T3)/1000,0)*1000 -> 3269000 | V3: =VLOOKUP(M3,$N$29:$O$33,2,0)*N3 -> 76440 | W3: =ROUNDDOWN((U3-V3)/1000,0)*1000 -> 3192000 | X3: =QUOTIENT(W3,$X$2) -> 31 | Y3: =QUOTIENT(W3-SUMPRODUCT(X3,$X$2),$Y$2) -> 1 | Z3: =QUOTIENT(W3-SUMPRODUCT(X3:Y3,$X$2:$Y$2),$Z$2) -> 2 | AA3: =QUOTIENT(W3-SUMPRODUCT(X3:Z3,$X$2:$Z$2),$AA$2) -> 0 | AB3: =QUOTIENT(W3-SUMPRODUCT(X3:AA3,$X$2:$AA$2),$AB$2) -> 0 | AC3: =QUOTIENT(W3-SUMPRODUCT(X3:AB3,$X$2:$AB$2),$AC$2) -> 2 | AD3: =SUMPRODUCT(X3:AC3,$X$2:$AC$2) -> 3192000
A4: 2 | B4: Roni | C4: KT29111996-I05051995-3-KB | D4: =DATE(MID(Soal!C4,17,4),MID(Soal!C4,15,2),MID(Soal!C4,13,2)) -> 34824 | E4: =DATEDIF(D4,"04/04/2025","Y") -> 29 | F4: =IF(MID(C4,2,1)="C","Kontrak",IF(MID(Soal!C4,2,1)="T","Tetap","Lepas")) -> Tetap | G4: =IF(LEFT(C4,1)="K","Kawin",IF(LEFT(C4,1)="B","Belum Kawin",IF(LEFT(C4,1)="D","Duda","Janda"))) -> Kawin | H4: =VALUE(MID(C4,22,1)) -> 3 | I4: =IF(MID(C4,12,1)="H","Hindu",IF(MID(C4,12,1)="I","Islam",IF(MID(C4,12,1)="N","Nasrani",IF(MID(C4,12,1)="B","Budha","Lainnya")))) -> Islam | J4: =DATE(MID(Soal!C4,7,4),MID(Soal!C4,5,2),MID(Soal!C4,3,2)) -> 35398 | K4: =DATEDIF(J4,"04/04/2025","M") -> 340 | L4: 111 | M4: =IF(K4>432,4,IF(K4>=372,3,IF(K4>=300,2,1))) -> 2 | N4: =MIN(L4,200)*9555 -> 1060605 | O4: =IF(L4<=200,0,IF((L4-200)<=10,(L4-200)*35555,(10*35555)+((L4-200-10)*35555*110%))) -> 0 | P4: =MIN(3,H4)*(10%*N4) -> 318181.5 | Q4: =IF(G4="Belum Kawin",0,5%*N4) -> 53030.25 | R4: =HLOOKUP(M4,$I$28:$L$29,2,FALSE)*N4 -> 84848.4 | S4: {=_xlfn.XLOOKUP(M4,$H$33:$H$36,_xlfn.XLOOKUP(RIGHT(C4,2),$I$32:$L$32,$I$33:$L$36))*N4} -> 79545.375 | T4: =IF(I4="Islam",10%,IF(I4="Nasrani",10.2%,10.3%))*N4 -> 106060.5 | U4: =ROUNDUP(SUM(N4:T4)/1000,0)*1000 -> 1703000 | V4: =VLOOKUP(M4,$N$29:$O$33,2,0)*N4 -> 31818.15 | W4: =ROUNDDOWN((U4-V4)/1000,0)*1000 -> 1671000 | X4: =QUOTIENT(W4,$X$2) -> 16 | Y4: =QUOTIENT(W4-SUMPRODUCT(X4,$X$2),$Y$2) -> 1 | Z4: =QUOTIENT(W4-SUMPRODUCT(X4:Y4,$X$2:$Y$2),$Z$2) -> 1 | AA4: =QUOTIENT(W4-SUMPRODUCT(X4:Z4,$X$2:$Z$2),$AA$2) -> 0 | AB4: =QUOTIENT(W4-SUMPRODUCT(X4:AA4,$X$2:$AA$2),$AB$2) -> 0 | AC4: =QUOTIENT(W4-SUMPRODUCT(X4:AB4,$X$2:$AB$2),$AC$2) -> 1 | AD4: =SUMPRODUCT(X4:AC4,$X$2:$AC$2) -> 1671000
A5: 3 | B5: Dewi | C5: JC19091997-N20101995-4-DR | D5: =DATE(MID(Soal!C5,17,4),MID(Soal!C5,15,2),MID(Soal!C5,13,2)) -> 34992 | E5: =DATEDIF(D5,"04/04/2025","Y") -> 29 | F5: =IF(MID(C5,2,1)="C","Kontrak",IF(MID(Soal!C5,2,1)="T","Tetap","Lepas")) -> Kontrak | G5: =IF(LEFT(C5,1)="K","Kawin",IF(LEFT(C5,1)="B","Belum Kawin",IF(LEFT(C5,1)="D","Duda","Janda"))) -> Janda | H5: =VALUE(MID(C5,22,1)) -> 4 | I5: =IF(MID(C5,12,1)="H","Hindu",IF(MID(C5,12,1)="I","Islam",IF(MID(C5,12,1)="N","Nasrani",IF(MID(C5,12,1)="B","Budha","Lainnya")))) -> Nasrani | J5: =DATE(MID(Soal!C5,7,4),MID(Soal!C5,5,2),MID(Soal!C5,3,2)) -> 35692 | K5: =DATEDIF(J5,"04/04/2025","M") -> 330 | L5: 129 | M5: =IF(K5>432,4,IF(K5>=372,3,IF(K5>=300,2,1))) -> 2 | N5: =MIN(L5,200)*9555 -> 1232595 | O5: =IF(L5<=200,0,IF((L5-200)<=10,(L5-200)*35555,(10*35555)+((L5-200-10)*35555*110%))) -> 0 | P5: =MIN(3,H5)*(10%*N5) -> 369778.5 | Q5: =IF(G5="Belum Kawin",0,5%*N5) -> 61629.75 | R5: =HLOOKUP(M5,$I$28:$L$29,2,FALSE)*N5 -> 98607.6 | S5: {=_xlfn.XLOOKUP(M5,$H$33:$H$36,_xlfn.XLOOKUP(RIGHT(C5,2),$I$32:$L$32,$I$33:$L$36))*N5} -> 86281.65 | T5: =IF(I5="Islam",10%,IF(I5="Nasrani",10.2%,10.3%))*N5 -> 125724.69 | U5: =ROUNDUP(SUM(N5:T5)/1000,0)*1000 -> 1975000 | V5: =VLOOKUP(M5,$N$29:$O$33,2,0)*N5 -> 36977.85 | W5: =ROUNDDOWN((U5-V5)/1000,0)*1000 -> 1938000 | X5: =QUOTIENT(W5,$X$2) -> 19 | Y5: =QUOTIENT(W5-SUMPRODUCT(X5,$X$2),$Y$2) -> 0 | Z5: =QUOTIENT(W5-SUMPRODUCT(X5:Y5,$X$2:$Y$2),$Z$2) -> 1 | AA5: =QUOTIENT(W5-SUMPRODUCT(X5:Z5,$X$2:$Z$2),$AA$2) -> 1 | AB5: =QUOTIENT(W5-SUMPRODUCT(X5:AA5,$X$2:$AA$2),$AB$2) -> 1 | AC5: =QUOTIENT(W5-SUMPRODUCT(X5:AB5,$X$2:$AB$2),$AC$2) -> 3 | AD5: =SUMPRODUCT(X5:AC5,$X$2:$AC$2) -> 1938000
A6: 4 | B6: Ana | C6: JC14091991-B01011980-1-AG | D6: =DATE(MID(Soal!C6,17,4),MID(Soal!C6,15,2),MID(Soal!C6,13,2)) -> 29221 | E6: =DATEDIF(D6,"04/04/2025","Y") -> 45 | F6: =IF(MID(C6,2,1)="C","Kontrak",IF(MID(Soal!C6,2,1)="T","Tetap","Lepas")) -> Kontrak | G6: =IF(LEFT(C6,1)="K","Kawin",IF(LEFT(C6,1)="B","Belum Kawin",IF(LEFT(C6,1)="D","Duda","Janda"))) -> Janda | H6: =VALUE(MID(C6,22,1)) -> 1 | I6: =IF(MID(C6,12,1)="H","Hindu",IF(MID(C6,12,1)="I","Islam",IF(MID(C6,12,1)="N","Nasrani",IF(MID(C6,12,1)="B","Budha","Lainnya")))) -> Budha | J6: =DATE(MID(Soal!C6,7,4),MID(Soal!C6,5,2),MID(Soal!C6,3,2)) -> 33495 | K6: =DATEDIF(J6,"04/04/2025","M") -> 402 | L6: 227 | M6: =IF(K6>432,4,IF(K6>=372,3,IF(K6>=300,2,1))) -> 3 | N6: =MIN(L6,200)*9555 -> 1911000 | O6: =IF(L6<=200,0,IF((L6-200)<=10,(L6-200)*35555,(10*35555)+((L6-200-10)*35555*110%))) -> 1020428.5 | P6: =MIN(3,H6)*(10%*N6) -> 191100 | Q6: =IF(G6="Belum Kawin",0,5%*N6) -> 95550 | R6: =HLOOKUP(M6,$I$28:$L$29,2,FALSE)*N6 -> 171990 | S6: {=_xlfn.XLOOKUP(M6,$H$33:$H$36,_xlfn.XLOOKUP(RIGHT(C6,2),$I$32:$L$32,$I$33:$L$36))*N6} -> 200655 | T6: =IF(I6="Islam",10%,IF(I6="Nasrani",10.2%,10.3%))*N6 -> 196833 | U6: =ROUNDUP(SUM(N6:T6)/1000,0)*1000 -> 3788000 | V6: =VLOOKUP(M6,$N$29:$O$33,2,0)*N6 -> 76440 | W6: =ROUNDDOWN((U6-V6)/1000,0)*1000 -> 3711000 | X6: =QUOTIENT(W6,$X$2) -> 37 | Y6: =QUOTIENT(W6-SUMPRODUCT(X6,$X$2),$Y$2) -> 0 | Z6: =QUOTIENT(W6-SUMPRODUCT(X6:Y6,$X$2:$Y$2),$Z$2) -> 0 | AA6: =QUOTIENT(W6-SUMPRODUCT(X6:Z6,$X$2:$Z$2),$AA$2) -> 1 | AB6: =QUOTIENT(W6-SUMPRODUCT(X6:AA6,$X$2:$AA$2),$AB$2) -> 0 | AC6: =QUOTIENT(W6-SUMPRODUCT(X6:AB6,$X$2:$AB$2),$AC$2) -> 1 | AD6: =SUMPRODUCT(X6:AC6,$X$2:$AC$2) -> 3711000
A7: 5 | B7: Bambang | C7: KT15032004-I25072002-5-KB | D7: =DATE(MID(Soal!C7,17,4),MID(Soal!C7,15,2),MID(Soal!C7,13,2)) -> 37462 | E7: =DATEDIF(D7,"04/04/2025","Y") -> 22 | F7: =IF(MID(C7,2,1)="C","Kontrak",IF(MID(Soal!C7,2,1)="T","Tetap","Lepas")) -> Tetap | G7: =IF(LEFT(C7,1)="K","Kawin",IF(LEFT(C7,1)="B","Belum Kawin",IF(LEFT(C7,1)="D","Duda","Janda"))) -> Kawin | H7: =VALUE(MID(C7,22,1)) -> 5 | I7: =IF(MID(C7,12,1)="H","Hindu",IF(MID(C7,12,1)="I","Islam",IF(MID(C7,12,1)="N","Nasrani",IF(MID(C7,12,1)="B","Budha","Lainnya")))) -> Islam | J7: =DATE(MID(Soal!C7,7,4),MID(Soal!C7,5,2),MID(Soal!C7,3,2)) -> 38061 | K7: =DATEDIF(J7,"04/04/2025","M") -> 252 | L7: 267 | M7: =IF(K7>432,4,IF(K7>=372,3,IF(K7>=300,2,1))) -> 1 | N7: =MIN(L7,200)*9555 -> 1911000 | O7: =IF(L7<=200,0,IF((L7-200)<=10,(L7-200)*35555,(10*35555)+((L7-200-10)*35555*110%))) -> 2584848.5 | P7: =MIN(3,H7)*(10%*N7) -> 573300 | Q7: =IF(G7="Belum Kawin",0,5%*N7) -> 95550 | R7: =HLOOKUP(M7,$I$28:$L$29,2,FALSE)*N7 -> 95550 | S7: {=_xlfn.XLOOKUP(M7,$H$33:$H$36,_xlfn.XLOOKUP(RIGHT(C7,2),$I$32:$L$32,$I$33:$L$36))*N7} -> 105105 | T7: =IF(I7="Islam",10%,IF(I7="Nasrani",10.2%,10.3%))*N7 -> 191100 | U7: =ROUNDUP(SUM(N7:T7)/1000,0)*1000 -> 5557000 | V7: =VLOOKUP(M7,$N$29:$O$33,2,0)*N7 -> 38220 | W7: =ROUNDDOWN((U7-V7)/1000,0)*1000 -> 5518000 | X7: =QUOTIENT(W7,$X$2) -> 55 | Y7: =QUOTIENT(W7-SUMPRODUCT(X7,$X$2),$Y$2) -> 0 | Z7: =QUOTIENT(W7-SUMPRODUCT(X7:Y7,$X$2:$Y$2),$Z$2) -> 0 | AA7: =QUOTIENT(W7-SUMPRODUCT(X7:Z7,$X$2:$Z$2),$AA$2) -> 1 | AB7: =QUOTIENT(W7-SUMPRODUCT(X7:AA7,$X$2:$AA$2),$AB$2) -> 1 | AC7: =QUOTIENT(W7-SUMPRODUCT(X7:AB7,$X$2:$AB$2),$AC$2) -> 3 | AD7: =SUMPRODUCT(X7:AC7,$X$2:$AC$2) -> 5518000
A8: 6 | B8: Yogi | C8: DL08081990-H14041988-0-AG | D8: =DATE(MID(Soal!C8,17,4),MID(Soal!C8,15,2),MID(Soal!C8,13,2)) -> 32247 | E8: =DATEDIF(D8,"04/04/2025","Y") -> 36 | F8: =IF(MID(C8,2,1)="C","Kontrak",IF(MID(Soal!C8,2,1)="T","Tetap","Lepas")) -> Lepas | G8: =IF(LEFT(C8,1)="K","Kawin",IF(LEFT(C8,1)="B","Belum Kawin",IF(LEFT(C8,1)="D","Duda","Janda"))) -> Duda | H8: =VALUE(MID(C8,22,1)) -> 0 | I8: =IF(MID(C8,12,1)="H","Hindu",IF(MID(C8,12,1)="I","Islam",IF(MID(C8,12,1)="N","Nasrani",IF(MID(C8,12,1)="B","Budha","Lainnya")))) -> Hindu | J8: =DATE(MID(Soal!C8,7,4),MID(Soal!C8,5,2),MID(Soal!C8,3,2)) -> 33093 | K8: =DATEDIF(J8,"04/04/2025","M") -> 415 | L8: 246 | M8: =IF(K8>432,4,IF(K8>=372,3,IF(K8>=300,2,1))) -> 3 | N8: =MIN(L8,200)*9555 -> 1911000 | O8: =IF(L8<=200,0,IF((L8-200)<=10,(L8-200)*35555,(10*35555)+((L8-200-10)*35555*110%))) -> 1763528 | P8: =MIN(3,H8)*(10%*N8) -> 0 | Q8: =IF(G8="Belum Kawin",0,5%*N8) -> 95550 | R8: =HLOOKUP(M8,$I$28:$L$29,2,FALSE)*N8 -> 171990 | S8: {=_xlfn.XLOOKUP(M8,$H$33:$H$36,_xlfn.XLOOKUP(RIGHT(C8,2),$I$32:$L$32,$I$33:$L$36))*N8} -> 200655 | T8: =IF(I8="Islam",10%,IF(I8="Nasrani",10.2%,10.3%))*N8 -> 196833 | U8: =ROUNDUP(SUM(N8:T8)/1000,0)*1000 -> 4340000 | V8: =VLOOKUP(M8,$N$29:$O$33,2,0)*N8 -> 76440 | W8: =ROUNDDOWN((U8-V8)/1000,0)*1000 -> 4263000 | X8: =QUOTIENT(W8,$X$2) -> 42 | Y8: =QUOTIENT(W8-SUMPRODUCT(X8,$X$2),$Y$2) -> 1 | Z8: =QUOTIENT(W8-SUMPRODUCT(X8:Y8,$X$2:$Y$2),$Z$2) -> 0 | AA8: =QUOTIENT(W8-SUMPRODUCT(X8:Z8,$X$2:$Z$2),$AA$2) -> 1 | AB8: =QUOTIENT(W8-SUMPRODUCT(X8:AA8,$X$2:$AA$2),$AB$2) -> 0 | AC8: =QUOTIENT(W8-SUMPRODUCT(X8:AB8,$X$2:$AB$2),$AC$2) -> 3 | AD8: =SUMPRODUCT(X8:AC8,$X$2:$AC$2) -> 4263000
A9: 7 | B9: Danu | C9: BC30102005-N08082003-2-KS | D9: =DATE(MID(Soal!C9,17,4),MID(Soal!C9,15,2),MID(Soal!C9,13,2)) -> 37841 | E9: =DATEDIF(D9,"04/04/2025","Y") -> 21 | F9: =IF(MID(C9,2,1)="C","Kontrak",IF(MID(Soal!C9,2,1)="T","Tetap","Lepas")) -> Kontrak | G9: =IF(LEFT(C9,1)="K","Kawin",IF(LEFT(C9,1)="B","Belum Kawin",IF(LEFT(C9,1)="D","Duda","Janda"))) -> Belum Kawin | H9: =VALUE(MID(C9,22,1)) -> 2 | I9: =IF(MID(C9,12,1)="H","Hindu",IF(MID(C9,12,1)="I","Islam",IF(MID(C9,12,1)="N","Nasrani",IF(MID(C9,12,1)="B","Budha","Lainnya")))) -> Nasrani | J9: =DATE(MID(Soal!C9,7,4),MID(Soal!C9,5,2),MID(Soal!C9,3,2)) -> 38655 | K9: =DATEDIF(J9,"04/04/2025","M") -> 233 | L9: 193 | M9: =IF(K9>432,4,IF(K9>=372,3,IF(K9>=300,2,1))) -> 1 | N9: =MIN(L9,200)*9555 -> 1844115 | O9: =IF(L9<=200,0,IF((L9-200)<=10,(L9-200)*35555,(10*35555)+((L9-200-10)*35555*110%))) -> 0 | P9: =MIN(3,H9)*(10%*N9) -> 368823 | Q9: =IF(G9="Belum Kawin",0,5%*N9) -> 0 | R9: =HLOOKUP(M9,$I$28:$L$29,2,FALSE)*N9 -> 92205.75 | S9: {=_xlfn.XLOOKUP(M9,$H$33:$H$36,_xlfn.XLOOKUP(RIGHT(C9,2),$I$32:$L$32,$I$33:$L$36))*N9} -> 110646.9 | T9: =IF(I9="Islam",10%,IF(I9="Nasrani",10.2%,10.3%))*N9 -> 188099.73 | U9: =ROUNDUP(SUM(N9:T9)/1000,0)*1000 -> 2604000 | V9: =VLOOKUP(M9,$N$29:$O$33,2,0)*N9 -> 36882.3 | W9: =ROUNDDOWN((U9-V9)/1000,0)*1000 -> 2567000 | X9: =QUOTIENT(W9,$X$2) -> 25 | Y9: =QUOTIENT(W9-SUMPRODUCT(X9,$X$2),$Y$2) -> 1 | Z9: =QUOTIENT(W9-SUMPRODUCT(X9:Y9,$X$2:$Y$2),$Z$2) -> 0 | AA9: =QUOTIENT(W9-SUMPRODUCT(X9:Z9,$X$2:$Z$2),$AA$2) -> 1 | AB9: =QUOTIENT(W9-SUMPRODUCT(X9:AA9,$X$2:$AA$2),$AB$2) -> 1 | AC9: =QUOTIENT(W9-SUMPRODUCT(X9:AB9,$X$2:$AB$2),$AC$2) -> 2 | AD9: =SUMPRODUCT(X9:AC9,$X$2:$AC$2) -> 2567000
A10: 8 | B10: Saraswati | C10: JC08061982-B19051980-3-KB | D10: =DATE(MID(Soal!C10,17,4),MID(Soal!C10,15,2),MID(Soal!C10,13,2)) -> 29360 | E10: =DATEDIF(D10,"04/04/2025","Y") -> 44 | F10: =IF(MID(C10,2,1)="C","Kontrak",IF(MID(Soal!C10,2,1)="T","Tetap","Lepas")) -> Kontrak | G10: =IF(LEFT(C10,1)="K","Kawin",IF(LEFT(C10,1)="B","Belum Kawin",IF(LEFT(C10,1)="D","Duda","Janda"))) -> Janda | H10: =VALUE(MID(C10,22,1)) -> 3 | I10: =IF(MID(C10,12,1)="H","Hindu",IF(MID(C10,12,1)="I","Islam",IF(MID(C10,12,1)="N","Nasrani",IF(MID(C10,12,1)="B","Budha","Lainnya")))) -> Budha | J10: =DATE(MID(Soal!C10,7,4),MID(Soal!C10,5,2),MID(Soal!C10,3,2)) -> 30110 | K10: =DATEDIF(J10,"04/04/2025","M") -> 513 | L10: 135 | M10: =IF(K10>432,4,IF(K10>=372,3,IF(K10>=300,2,1))) -> 4 | N10: =MIN(L10,200)*9555 -> 1289925 | O10: =IF(L10<=200,0,IF((L10-200)<=10,(L10-200)*35555,(10*35555)+((L10-200-10)*35555*110%))) -> 0 | P10: =MIN(3,H10)*(10%*N10) -> 386977.5 | Q10: =IF(G10="Belum Kawin",0,5%*N10) -> 64496.25 | R10: =HLOOKUP(M10,$I$28:$L$29,2,FALSE)*N10 -> 128992.5 | S10: {=_xlfn.XLOOKUP(M10,$H$33:$H$36,_xlfn.XLOOKUP(RIGHT(C10,2),$I$32:$L$32,$I$33:$L$36))*N10} -> 140601.83 | T10: =IF(I10="Islam",10%,IF(I10="Nasrani",10.2%,10.3%))*N10 -> 132862.28 | U10: =ROUNDUP(SUM(N10:T10)/1000,0)*1000 -> 2144000 | V10: =VLOOKUP(M10,$N$29:$O$33,2,0)*N10 -> 64496.25 | W10: =ROUNDDOWN((U10-V10)/1000,0)*1000 -> 2079000 | X10: =QUOTIENT(W10,$X$2) -> 20 | Y10: =QUOTIENT(W10-SUMPRODUCT(X10,$X$2),$Y$2) -> 1 | Z10: =QUOTIENT(W10-SUMPRODUCT(X10:Y10,$X$2:$Y$2),$Z$2) -> 1 | AA10: =QUOTIENT(W10-SUMPRODUCT(X10:Z10,$X$2:$Z$2),$AA$2) -> 0 | AB10: =QUOTIENT(W10-SUMPRODUCT(X10:AA10,$X$2:$AA$2),$AB$2) -> 1 | AC10: =QUOTIENT(W10-SUMPRODUCT(X10:AB10,$X$2:$AB$2),$AC$2) -> 4 | AD10: =SUMPRODUCT(X10:AC10,$X$2:$AC$2) -> 2079000
A11: 9 | B11: Nurlaela | C11: KT11121998-I15081996-4-DR | D11: =DATE(MID(Soal!C11,17,4),MID(Soal!C11,15,2),MID(Soal!C11,13,2)) -> 35292 | E11: =DATEDIF(D11,"04/04/2025","Y") -> 28 | F11: =IF(MID(C11,2,1)="C","Kontrak",IF(MID(Soal!C11,2,1)="T","Tetap","Lepas")) -> Tetap | G11: =IF(LEFT(C11,1)="K","Kawin",IF(LEFT(C11,1)="B","Belum Kawin",IF(LEFT(C11,1)="D","Duda","Janda"))) -> Kawin | H11: =VALUE(MID(C11,22,1)) -> 4 | I11: =IF(MID(C11,12,1)="H","Hindu",IF(MID(C11,12,1)="I","Islam",IF(MID(C11,12,1)="N","Nasrani",IF(MID(C11,12,1)="B","Budha","Lainnya")))) -> Islam | J11: =DATE(MID(Soal!C11,7,4),MID(Soal!C11,5,2),MID(Soal!C11,3,2)) -> 36140 | K11: =DATEDIF(J11,"04/04/2025","M") -> 315 | L11: 222 | M11: =IF(K11>432,4,IF(K11>=372,3,IF(K11>=300,2,1))) -> 2 | N11: =MIN(L11,200)*9555 -> 1911000 | O11: =IF(L11<=200,0,IF((L11-200)<=10,(L11-200)*35555,(10*35555)+((L11-200-10)*35555*110%))) -> 824876 | P11: =MIN(3,H11)*(10%*N11) -> 573300 | Q11: =IF(G11="Belum Kawin",0,5%*N11) -> 95550 | R11: =HLOOKUP(M11,$I$28:$L$29,2,FALSE)*N11 -> 152880 | S11: {=_xlfn.XLOOKUP(M11,$H$33:$H$36,_xlfn.XLOOKUP(RIGHT(C11,2),$I$32:$L$32,$I$33:$L$36))*N11} -> 133770 | T11: =IF(I11="Islam",10%,IF(I11="Nasrani",10.2%,10.3%))*N11 -> 191100 | U11: =ROUNDUP(SUM(N11:T11)/1000,0)*1000 -> 3883000 | V11: =VLOOKUP(M11,$N$29:$O$33,2,0)*N11 -> 57330 | W11: =ROUNDDOWN((U11-V11)/1000,0)*1000 -> 3825000 | X11: =QUOTIENT(W11,$X$2) -> 38 | Y11: =QUOTIENT(W11-SUMPRODUCT(X11,$X$2),$Y$2) -> 0 | Z11: =QUOTIENT(W11-SUMPRODUCT(X11:Y11,$X$2:$Y$2),$Z$2) -> 1 | AA11: =QUOTIENT(W11-SUMPRODUCT(X11:Z11,$X$2:$Z$2),$AA$2) -> 0 | AB11: =QUOTIENT(W11-SUMPRODUCT(X11:AA11,$X$2:$AA$2),$AB$2) -> 1 | AC11: =QUOTIENT(W11-SUMPRODUCT(X11:AB11,$X$2:$AB$2),$AC$2) -> 0 | AD11: =SUMPRODUCT(X11:AC11,$X$2:$AC$2) -> 3825000
A12: 10 | B12: Kanita | C12: BC01072003-H30032001-1-AG | D12: =DATE(MID(Soal!C12,17,4),MID(Soal!C12,15,2),MID(Soal!C12,13,2)) -> 36980 | E12: =DATEDIF(D12,"04/04/2025","Y") -> 24 | F12: =IF(MID(C12,2,1)="C","Kontrak",IF(MID(Soal!C12,2,1)="T","Tetap","Lepas")) -> Kontrak | G12: =IF(LEFT(C12,1)="K","Kawin",IF(LEFT(C12,1)="B","Belum Kawin",IF(LEFT(C12,1)="D","Duda","Janda"))) -> Belum Kawin | H12: =VALUE(MID(C12,22,1)) -> 1 | I12: =IF(MID(C12,12,1)="H","Hindu",IF(MID(C12,12,1)="I","Islam",IF(MID(C12,12,1)="N","Nasrani",IF(MID(C12,12,1)="B","Budha","Lainnya")))) -> Hindu | J12: =DATE(MID(Soal!C12,7,4),MID(Soal!C12,5,2),MID(Soal!C12,3,2)) -> 37803 | K12: =DATEDIF(J12,"04/04/2025","M") -> 261 | L12: 218 | M12: =IF(K12>432,4,IF(K12>=372,3,IF(K12>=300,2,1))) -> 1 | N12: =MIN(L12,200)*9555 -> 1911000 | O12: =IF(L12<=200,0,IF((L12-200)<=10,(L12-200)*35555,(10*35555)+((L12-200-10)*35555*110%))) -> 668434 | P12: =MIN(3,H12)*(10%*N12) -> 191100 | Q12: =IF(G12="Belum Kawin",0,5%*N12) -> 0 | R12: =HLOOKUP(M12,$I$28:$L$29,2,FALSE)*N12 -> 95550 | S12: {=_xlfn.XLOOKUP(M12,$H$33:$H$36,_xlfn.XLOOKUP(RIGHT(C12,2),$I$32:$L$32,$I$33:$L$36))*N12} -> 124215 | T12: =IF(I12="Islam",10%,IF(I12="Nasrani",10.2%,10.3%))*N12 -> 196833 | U12: =ROUNDUP(SUM(N12:T12)/1000,0)*1000 -> 3188000 | V12: =VLOOKUP(M12,$N$29:$O$33,2,0)*N12 -> 38220 | W12: =ROUNDDOWN((U12-V12)/1000,0)*1000 -> 3149000 | X12: =QUOTIENT(W12,$X$2) -> 31 | Y12: =QUOTIENT(W12-SUMPRODUCT(X12,$X$2),$Y$2) -> 0 | Z12: =QUOTIENT(W12-SUMPRODUCT(X12:Y12,$X$2:$Y$2),$Z$2) -> 2 | AA12: =QUOTIENT(W12-SUMPRODUCT(X12:Z12,$X$2:$Z$2),$AA$2) -> 0 | AB12: =QUOTIENT(W12-SUMPRODUCT(X12:AA12,$X$2:$AA$2),$AB$2) -> 1 | AC12: =QUOTIENT(W12-SUMPRODUCT(X12:AB12,$X$2:$AB$2),$AC$2) -> 4 | AD12: =SUMPRODUCT(X12:AC12,$X$2:$AC$2) -> 3149000
A13: 11 | B13: Anandara | C13: KC10071986-N22121984-5-KB | D13: =DATE(MID(Soal!C13,17,4),MID(Soal!C13,15,2),MID(Soal!C13,13,2)) -> 31038 | E13: =DATEDIF(D13,"04/04/2025","Y") -> 40 | F13: =IF(MID(C13,2,1)="C","Kontrak",IF(MID(Soal!C13,2,1)="T","Tetap","Lepas")) -> Kontrak | G13: =IF(LEFT(C13,1)="K","Kawin",IF(LEFT(C13,1)="B","Belum Kawin",IF(LEFT(C13,1)="D","Duda","Janda"))) -> Kawin | H13: =VALUE(MID(C13,22,1)) -> 5 | I13: =IF(MID(C13,12,1)="H","Hindu",IF(MID(C13,12,1)="I","Islam",IF(MID(C13,12,1)="N","Nasrani",IF(MID(C13,12,1)="B","Budha","Lainnya")))) -> Nasrani | J13: =DATE(MID(Soal!C13,7,4),MID(Soal!C13,5,2),MID(Soal!C13,3,2)) -> 31603 | K13: =DATEDIF(J13,"04/04/2025","M") -> 464 | L13: 237 | M13: =IF(K13>432,4,IF(K13>=372,3,IF(K13>=300,2,1))) -> 4 | N13: =MIN(L13,200)*9555 -> 1911000 | O13: =IF(L13<=200,0,IF((L13-200)<=10,(L13-200)*35555,(10*35555)+((L13-200-10)*35555*110%))) -> 1411533.5 | P13: =MIN(3,H13)*(10%*N13) -> 573300 | Q13: =IF(G13="Belum Kawin",0,5%*N13) -> 95550 | R13: =HLOOKUP(M13,$I$28:$L$29,2,FALSE)*N13 -> 191100 | S13: {=_xlfn.XLOOKUP(M13,$H$33:$H$36,_xlfn.XLOOKUP(RIGHT(C13,2),$I$32:$L$32,$I$33:$L$36))*N13} -> 208299 | T13: =IF(I13="Islam",10%,IF(I13="Nasrani",10.2%,10.3%))*N13 -> 194922 | U13: =ROUNDUP(SUM(N13:T13)/1000,0)*1000 -> 4586000 | V13: =VLOOKUP(M13,$N$29:$O$33,2,0)*N13 -> 95550 | W13: =ROUNDDOWN((U13-V13)/1000,0)*1000 -> 4490000 | X13: =QUOTIENT(W13,$X$2) -> 44 | Y13: =QUOTIENT(W13-SUMPRODUCT(X13,$X$2),$Y$2) -> 1 | Z13: =QUOTIENT(W13-SUMPRODUCT(X13:Y13,$X$2:$Y$2),$Z$2) -> 2 | AA13: =QUOTIENT(W13-SUMPRODUCT(X13:Z13,$X$2:$Z$2),$AA$2) -> 0 | AB13: =QUOTIENT(W13-SUMPRODUCT(X13:AA13,$X$2:$AA$2),$AB$2) -> 0 | AC13: =QUOTIENT(W13-SUMPRODUCT(X13:AB13,$X$2:$AB$2),$AC$2) -> 0 | AD13: =SUMPRODUCT(X13:AC13,$X$2:$AC$2) -> 4490000
A14: 12 | B14: Budianto | C14: DC28121994-L09101992-0-KS | D14: =DATE(MID(Soal!C14,17,4),MID(Soal!C14,15,2),MID(Soal!C14,13,2)) -> 33886 | E14: =DATEDIF(D14,"04/04/2025","Y") -> 32 | F14: =IF(MID(C14,2,1)="C","Kontrak",IF(MID(Soal!C14,2,1)="T","Tetap","Lepas")) -> Kontrak | G14: =IF(LEFT(C14,1)="K","Kawin",IF(LEFT(C14,1)="B","Belum Kawin",IF(LEFT(C14,1)="D","Duda","Janda"))) -> Duda | H14: =VALUE(MID(C14,22,1)) -> 0 | I14: =IF(MID(C14,12,1)="H","Hindu",IF(MID(C14,12,1)="I","Islam",IF(MID(C14,12,1)="N","Nasrani",IF(MID(C14,12,1)="B","Budha","Lainnya")))) -> Lainnya | J14: =DATE(MID(Soal!C14,7,4),MID(Soal!C14,5,2),MID(Soal!C14,3,2)) -> 34696 | K14: =DATEDIF(J14,"04/04/2025","M") -> 363 | L14: 156 | M14: =IF(K14>432,4,IF(K14>=372,3,IF(K14>=300,2,1))) -> 2 | N14: =MIN(L14,200)*9555 -> 1490580 | O14: =IF(L14<=200,0,IF((L14-200)<=10,(L14-200)*35555,(10*35555)+((L14-200-10)*35555*110%))) -> 0 | P14: =MIN(3,H14)*(10%*N14) -> 0 | Q14: =IF(G14="Belum Kawin",0,5%*N14) -> 74529 | R14: =HLOOKUP(M14,$I$28:$L$29,2,FALSE)*N14 -> 119246.4 | S14: {=_xlfn.XLOOKUP(M14,$H$33:$H$36,_xlfn.XLOOKUP(RIGHT(C14,2),$I$32:$L$32,$I$33:$L$36))*N14} -> 119246.4 | T14: =IF(I14="Islam",10%,IF(I14="Nasrani",10.2%,10.3%))*N14 -> 153529.74 | U14: =ROUNDUP(SUM(N14:T14)/1000,0)*1000 -> 1958000 | V14: =VLOOKUP(M14,$N$29:$O$33,2,0)*N14 -> 44717.4 | W14: =ROUNDDOWN((U14-V14)/1000,0)*1000 -> 1913000 | X14: =QUOTIENT(W14,$X$2) -> 19 | Y14: =QUOTIENT(W14-SUMPRODUCT(X14,$X$2),$Y$2) -> 0 | Z14: =QUOTIENT(W14-SUMPRODUCT(X14:Y14,$X$2:$Y$2),$Z$2) -> 0 | AA14: =QUOTIENT(W14-SUMPRODUCT(X14:Z14,$X$2:$Z$2),$AA$2) -> 1 | AB14: =QUOTIENT(W14-SUMPRODUCT(X14:AA14,$X$2:$AA$2),$AB$2) -> 0 | AC14: =QUOTIENT(W14-SUMPRODUCT(X14:AB14,$X$2:$AB$2),$AC$2) -> 3 | AD14: =SUMPRODUCT(X14:AC14,$X$2:$AC$2) -> 1913000
A15: 13 | B15: Somantri | C15: KL09021999-I31031997-2-DR | D15: =DATE(MID(Soal!C15,17,4),MID(Soal!C15,15,2),MID(Soal!C15,13,2)) -> 35520 | E15: =DATEDIF(D15,"04/04/2025","Y") -> 28 | F15: =IF(MID(C15,2,1)="C","Kontrak",IF(MID(Soal!C15,2,1)="T","Tetap","Lepas")) -> Lepas | G15: =IF(LEFT(C15,1)="K","Kawin",IF(LEFT(C15,1)="B","Belum Kawin",IF(LEFT(C15,1)="D","Duda","Janda"))) -> Kawin | H15: =VALUE(MID(C15,22,1)) -> 2 | I15: =IF(MID(C15,12,1)="H","Hindu",IF(MID(C15,12,1)="I","Islam",IF(MID(C15,12,1)="N","Nasrani",IF(MID(C15,12,1)="B","Budha","Lainnya")))) -> Islam | J15: =DATE(MID(Soal!C15,7,4),MID(Soal!C15,5,2),MID(Soal!C15,3,2)) -> 36200 | K15: =DATEDIF(J15,"04/04/2025","M") -> 313 | L15: 134 | M15: =IF(K15>432,4,IF(K15>=372,3,IF(K15>=300,2,1))) -> 2 | N15: =MIN(L15,200)*9555 -> 1280370 | O15: =IF(L15<=200,0,IF((L15-200)<=10,(L15-200)*35555,(10*35555)+((L15-200-10)*35555*110%))) -> 0 | P15: =MIN(3,H15)*(10%*N15) -> 256074 | Q15: =IF(G15="Belum Kawin",0,5%*N15) -> 64018.5 | R15: =HLOOKUP(M15,$I$28:$L$29,2,FALSE)*N15 -> 102429.6 | S15: {=_xlfn.XLOOKUP(M15,$H$33:$H$36,_xlfn.XLOOKUP(RIGHT(C15,2),$I$32:$L$32,$I$33:$L$36))*N15} -> 89625.9 | T15: =IF(I15="Islam",10%,IF(I15="Nasrani",10.2%,10.3%))*N15 -> 128037 | U15: =ROUNDUP(SUM(N15:T15)/1000,0)*1000 -> 1921000 | V15: =VLOOKUP(M15,$N$29:$O$33,2,0)*N15 -> 38411.1 | W15: =ROUNDDOWN((U15-V15)/1000,0)*1000 -> 1882000 | X15: =QUOTIENT(W15,$X$2) -> 18 | Y15: =QUOTIENT(W15-SUMPRODUCT(X15,$X$2),$Y$2) -> 1 | Z15: =QUOTIENT(W15-SUMPRODUCT(X15:Y15,$X$2:$Y$2),$Z$2) -> 1 | AA15: =QUOTIENT(W15-SUMPRODUCT(X15:Z15,$X$2:$Z$2),$AA$2) -> 1 | AB15: =QUOTIENT(W15-SUMPRODUCT(X15:AA15,$X$2:$AA$2),$AB$2) -> 0 | AC15: =QUOTIENT(W15-SUMPRODUCT(X15:AB15,$X$2:$AB$2),$AC$2) -> 2 | AD15: =SUMPRODUCT(X15:AC15,$X$2:$AC$2) -> 1882000
... A17: 15 | B17: Kosasih | C17: DC12091992-N20081990-4-AG | D17: =DATE(MID(Soal!C17,17,4),MID(Soal!C17,15,2),MID(Soal!C17,13,2)) -> 33105 | E17: =DATEDIF(D17,"04/04/2025","Y") -> 34 | F17: =IF(MID(C17,2,1)="C","Kontrak",IF(MID(Soal!C17,2,1)="T","Tetap","Lepas")) -> Kontrak | G17: =IF(LEFT(C17,1)="K","Kawin",IF(LEFT(C17,1)="B","Belum Kawin",IF(LEFT(C17,1)="D","Duda","Janda"))) -> Duda | H17: =VALUE(MID(C17,22,1)) -> 4 | I17: =IF(MID(C17,12,1)="H","Hindu",IF(MID(C17,12,1)="I","Islam",IF(MID(C17,12,1)="N","Nasrani",IF(MID(C17,12,1)="B","Budha","Lainnya")))) -> Nasrani | J17: =DATE(MID(Soal!C17,7,4),MID(Soal!C17,5,2),MID(Soal!C17,3,2)) -> 33859 | K17: =DATEDIF(J17,"04/04/2025","M") -> 390 | L17: 128 | M17: =IF(K17>432,4,IF(K17>=372,3,IF(K17>=300,2,1))) -> 3 | N17: =MIN(L17,200)*9555 -> 1223040 | O17: =IF(L17<=200,0,IF((L17-200)<=10,(L17-200)*35555,(10*35555)+((L17-200-10)*35555*110%))) -> 0 | P17: =MIN(3,H17)*(10%*N17) -> 366912 | Q17: =IF(G17="Belum Kawin",0,5%*N17) -> 61152 | R17: =HLOOKUP(M17,$I$28:$L$29,2,FALSE)*N17 -> 110073.6 | S17: {=_xlfn.XLOOKUP(M17,$H$33:$H$36,_xlfn.XLOOKUP(RIGHT(C17,2),$I$32:$L$32,$I$33:$L$36))*N17} -> 128419.2 | T17: =IF(I17="Islam",10%,IF(I17="Nasrani",10.2%,10.3%))*N17 -> 124750.08 | U17: =ROUNDUP(SUM(N17:T17)/1000,0)*1000 -> 2015000 | V17: =VLOOKUP(M17,$N$29:$O$33,2,0)*N17 -> 48921.6 | W17: =ROUNDDOWN((U17-V17)/1000,0)*1000 -> 1966000 | X17: =QUOTIENT(W17,$X$2) -> 19 | Y17: =QUOTIENT(W17-SUMPRODUCT(X17,$X$2),$Y$2) -> 1 | Z17: =QUOTIENT(W17-SUMPRODUCT(X17:Y17,$X$2:$Y$2),$Z$2) -> 0 | AA17: =QUOTIENT(W17-SUMPRODUCT(X17:Z17,$X$2:$Z$2),$AA$2) -> 1 | AB17: =QUOTIENT(W17-SUMPRODUCT(X17:AA17,$X$2:$AA$2),$AB$2) -> 1 | AC17: =QUOTIENT(W17-SUMPRODUCT(X17:AB17,$X$2:$AB$2),$AC$2) -> 1 | AD17: =SUMPRODUCT(X17:AC17,$X$2:$AC$2) -> 1966000
B20: KODE SOAL | C20: SBEM001 | D20: KODE JAWABAN | E20: =kode_jawaban -> AS2|C8-A42F;14-B59;1EF19-TPKK;3DEC8-KNJD;141-C9;C8-HUNH;1E-A428;28-B3F3;A-D7;14-AC275;10-BC7F;12-C2BAB;14-D61F;21-E176;24-E2B;1A-E1FD;1C-E785C80;2D-EA2;20-E75DFC8;228-Z591
B22: Cek hasil pengerjakan dengan mengirimkan Kode Soal dan Kode Jawaban diatas ke alamat : https://belajarexcel.id/xl-test/jawaban untuk mengecek hasil benar/salah
B26: SOAL : Excel
B27: 1 | C27: Isi Tanggal Lahir berdasarkan No Pegawai | H27: Table Bonus
B28: 2 | C28: isi Umur berdasarkan Tanggal lahir sampai 4 April 2025 | H28: Golongan | I28: 1 | J28: 2 | K28: 3 | L28: 4 | N28: Table Iuran Koperasi
B29: 3 | C29: Isi Status Karyawan berdasarkan No Pegawai | H29: Bonus | I29: 0.05 | J29: 0.08 | K29: 0.09 | L29: 0.1 | N29: Golongan | O29: Iuran
B30: 4 | C30: Isi Status Pernikahan berdasarkan No Pegawai | N30: 1 | O30: 0.02
B31: 5 | C31: Isi Jumlah Anak berdasarkan No Pegawai | H31: Table Tunjangan Lauk Pauk | N31: 2 | O31: 0.03
B32: 6 | C32: Isi Agama berdasarkan No Pegawai | H32: Golongan / Jab | I32: DR | J32: KB | K32: KS | L32: AG | N32: 3 | O32: 0.04
B33: 7 | C33: Isi Tanggal Masuk Kerja berdasarkan No Pegawai | H33: 1 | I33: 0.05 | J33: 0.055 | K33: 0.06 | L33: 0.065 | N33: 4 | O33: 0.05
B34: 8 | C34: isi Lama Bekerja berdasarkan Tanggal masuk kerja sampai 4 April 2025 (Dalam bulan) | H34: 2 | I34: 0.07 | J34: 0.075 | K34: 0.08 | L34: 0.085
B35: 9 | C35: Golongan ditentukan berdasarkan lama kerja sampai saat ini: | H35: 3 | I35: 0.09 | J35: 0.095 | K35: 0.1 | L35: 0.105
C36: - Jika masa kerja di atas 432 bulan adalah golongan 4 | H36: 4 | I36: 0.108 | J36: 0.109 | K36: 0.11 | L36: 0.115
C37: - Jika masa kerja di >=372 bulan dan <=432 bulan adalah golongan 3
C38: - Jika masa kerja di >=300 bulan dan <372 bulan adalah golongan 2
C39: -selain itu Golongan 1
C40: Jam kerja normal per bulan adalah 200 jam
B41: 10 | C41: Upah Normal (jam normal dikalikan tarif jam kerja normal Rp.9.555/jam)
B42: 11 | C42: Upah lembur (kelebihan dari jam kerja normal dikalikan dengan tarif lembur Rp.35.555/jam) dengan ketentuan sebagai berikut:
C43: - 10 Jam pertama adalah 100% dari tarif lembur
C44: - kelebihan di atas 10 jam dibayar 110% dari tarif lembur.
B45: 12 | C45: Tunjangan anak 10% dari Upah normal maksimal untuk 3 anak saja, selebihnya dari 3 anak tidak mendapat tunjangan
B46: 13 | C46: Tunjangan status 5% dari upah normal untuk Kawin, Duda dan Janda. Sedangkan yang belum kawin tidak mendapat tunjangan status
B47: 14 | C47: Tunjangan bonus dihitung prosentase dari dari upah normal (lihat Table Bonus)
...

Sheet Arti Kode Pagawai
B2: Arti Kode Pagawai
B5: 1 | C5: 2 | D5: 3 | E5: 4 | F5: 5 | G5: 6 | H5: 7 | I5: 8 | J5: 9 | K5: 10 | L5: 11 | M5: 12 | N5: 13 | O5: 14 | P5: 15 | Q5: 16 | R5: 17 | S5: 18 | T5: 19 | U5: 20 | V5: 21 | W5: 22 | X5: 23 | Y5: 24 | Z5: 25
B6: K | C6: C | D6: 2 | E6: 3 | F6: 0 | G6: 8 | H6: 1 | I6: 9 | J6: 8 | K6: 5 | L6: - | M6: H | N6: 1 | O6: 2 | P6: 0 | Q6: 7 | R6: 1 | S6: 9 | T6: 9 | U6: 0 | V6: - | W6: 2 | X6: - | Y6: K | Z6: S
AA99: DEF | AB99: Kode jawaban
AA100: AS2 | AB100: 1 | AC100: 2 | AD100: 3 | AE100: 4 | AF100: 5 | AG100: 6 | AH100: 7 | AI100: 8 | AJ100: 9 | AK100: 10 | AL100: 11 | AM100: 12 | AN100: 13 | AO100: 14 | AP100: 15 | AQ100: 16 | AR100: 17 | AS100: 18 | AT100: 19 | AU100: 20 | AV100: 21 | AW100: 22 | AX100: 23 | AY100: 24 | AZ100: 25 | BA100: 26
AB101: =Soal!D3 -> 33066 | AC101: =Soal!E3 -> 34 | AD101: =Soal!F4 -> Tetap | AE101: =Soal!G3 -> Kawin | AF101: =Soal!H3 -> 2 | AG101: =Soal!I3 -> Hindu | AH101: =Soal!J3 -> 33915 | AI101: =Soal!K3 -> 388 | AJ101: =Soal!M3 -> 3 | AK101: =Soal!N3 -> 1911000 | AL101: =Soal!O3 -> 319995 | AM101: =Soal!P3 -> 382200 | AN101: =Soal!Q3 -> 95550 | AO101: =Soal!R3 -> 171990 | AP101: =Soal!S3 -> 191100 | AQ101: =Soal!T3 -> 196833 | ... BA101: =Soal!AD3 -> 3192000
AB102: =Soal!D9 -> 37841 | AC102: =Soal!E9 -> 21 | AD102: =Soal!F10 -> Kontrak | AE102: =Soal!G10 -> Janda | AF102: =Soal!H10 -> 3 | AG102: =Soal!I9 -> Nasrani | AH102: =Soal!J9 -> 38655 | AI102: =Soal!K9 -> 233 | AJ102: =Soal!M9 -> 1 | AK102: =Soal!N9 -> 1844115 | AL102: =Soal!O9 -> 0 | AM102: =Soal!P9 -> 368823 | AN102: =Soal!Q9 -> 0 | AO102: =Soal!R9 -> 92205.75 | AP102: =Soal!S9 -> 110646.9 | AQ102: =Soal!T9 -> 188099.73 | ... BA102: =Soal!AD9 -> 2567000
AB103: =Soal!D16 -> 36255 | AC103: =Soal!E17 -> 34 | AD103: =Soal!F16 -> Kontrak | AE103: =Soal!G17 -> Duda | AF103: =Soal!H17 -> 4 | AG103: =Soal!I16 -> Hindu | AH103: =Soal!J17 -> 33859 | AI103: =Soal!K17 -> 390 | AJ103: =Soal!M17 -> 3 | AK103: =Soal!N17 -> 1223040 | AL103: =Soal!O17 -> 0 | AM103: =Soal!P17 -> 366912 | AN103: =Soal!Q17 -> 61152 | AO103: =Soal!R17 -> 110073.6 | AP103: =Soal!S17 -> 128419.2 | AQ103: =Soal!T17 -> 124750.08 | ... BA103: =Soal!AD17 -> 1966000
AB105: ="A"&IFERROR(DEC2HEX((AB101+AB102+AB103)/100),"AAA") -> A42F | AC105: ="B"&IFERROR(DEC2HEX(AC101+AC102+AC103),"AAA") -> B59 | AD105: =UPPER(LEFT(AD101)&RIGHT(AD101)&LEFT(AD102)&LEFT(AD103)) -> TPKK | AE105: =UPPER(LEFT(AE101)&RIGHT(AE101)&LEFT(AE102)&LEFT(AE103)) -> KNJD | AF105: ="C"&IFERROR(DEC2HEX(AF101+AF102+AF103),"AA") -> C9 | AG105: =UPPER(LEFT(AG101)&RIGHT(AG101)&LEFT(AG102)&LEFT(AG103)) -> HUNH | AH105: ="A"&IFERROR(DEC2HEX((AH101+AH102+AH103)/100),"AAA") -> A428 | AI105: ="B"&IFERROR(DEC2HEX(AI101+AI102+AI103),"AA") -> B3F3 | AJ105: ="D"&IFERROR(DEC2HEX(AJ101+AJ102+AJ103),"AAA") -> D7 | AK105: ="A"&IFERROR(DEC2HEX((AK101+AK102+AK103)/100),"AAA") -> AC275 | AL105: ="B"&IFERROR(DEC2HEX((AL101+AL102+AL103)/100),"AAA") -> BC7F | AM105: ="C"&IFERROR(DEC2HEX((AM101+AM102+AM103)/100),"AAA") -> C2BAB | AN105: ="D"&IFERROR(DEC2HEX((AN101+AN102+AN103)/100),"AAA") -> D61F | AO105: ="E"&IFERROR(DEC2HEX((AO101+AO102+AO103)/1000),"AAA") -> E176 | AP105: ="E"&IFERROR(DEC2HEX((AP101+AP102+AP103)/10000),"AAA") -> E2B | AQ105: ="E"&IFERROR(DEC2HEX((AQ101+AQ102+AQ103)/1000),"AAA") -> E1FD | AR105: ="E"&IFERROR(DEC2HEX((AR101+AR102+AR103)),"AAA") -> E785C80 | AS105: ="E"&IFERROR(DEC2HEX((AS101+AS102+AS103)/1000),"AAA") -> EA2 | AT105: ="E"&IFERROR(DEC2HEX((AT101+AT102+AT103)),"AAA") -> E75DFC8 | AU105: ="Z"&IFERROR(DEC2HEX(SUM(AU101:AZ103)),"CFD")&--(AT101=BA101) -> Z591
AB106: =DEC2HEX(IFERROR(SEARCH("DAT",_xlfn.FORMULATEXT(Soal!D3)),99)*100) -> C8 | AC106: =DEC2HEX(IFERROR(SEARCH("DAT",_xlfn.FORMULATEXT(Soal!E3)),99)*10) -> 14 | AD106: =DEC2HEX(IF(OR(ISERROR(SEARCH("IF",_xlfn.FORMULATEXT(Soal!F3))),ISERROR(SEARCH("SW",_xlfn.FORMULATEXT(Soal!F3)))),99,2)*5)&DEC2HEX(IF(ISERROR(SEARCH("MI",_xlfn.FORMULATEXT(Soal!F3))),99,5)*5) -> 1EF19 | AE106: =DEC2HEX(IF(OR(ISERROR(SEARCH("IF",_xlfn.FORMULATEXT(Soal!G3))),ISERROR(SEARCH("SW",_xlfn.FORMULATEXT(Soal!G3)))),99,1)*10)&DEC2HEX(IF(ISERROR(SEARCH("LEF",_xlfn.FORMULATEXT(Soal!G3))),99,2)*100) -> 3DEC8 | AF106: =DEC2HEX(IF(ISERROR(SEARCH("MID",_xlfn.FORMULATEXT(Soal!H3))),99,2)*10)&--ISNUMBER('Arti Kode Pagawai'!AF101) -> 141 | AG106: =DEC2HEX(IF(ISERROR(SEARCH("MID",_xlfn.FORMULATEXT(Soal!I3))),99,2)*100) -> C8 | AH106: =DEC2HEX(IF(ISERROR(SEARCH("DAT",_xlfn.FORMULATEXT(Soal!J3))),99,2)*15) -> 1E | AI106: =DEC2HEX(IFERROR(SEARCH("DAT",_xlfn.FORMULATEXT(Soal!K3)),99)*20) -> 28 | AJ106: =DEC2HEX(IF(ISERROR(SEARCH("IF",_xlfn.FORMULATEXT(Soal!M3))),99,2)*5) -> A | AK106: =DEC2HEX(IF(ISERROR(SEARCH("MI",_xlfn.FORMULATEXT(Soal!N3))),99,2)*10) -> 14 | AL106: =DEC2HEX(IF(ISERROR(SEARCH("IF",_xlfn.FORMULATEXT(Soal!O3))),99,2)*8) -> 10 | AM106: =DEC2HEX(IF(ISERROR(SEARCH("IN",_xlfn.FORMULATEXT(Soal!P3))),99,2)*9) -> 12 | AN106: =DEC2HEX(IF(ISERROR(SEARCH("IF",_xlfn.FORMULATEXT(Soal!Q3))),99,2)*10) -> 14 | AO106: =DEC2HEX(IF(ISERROR(SEARCH("LOOK",_xlfn.FORMULATEXT(Soal!R3))),99,3)*11) -> 21 | AP106: =DEC2HEX(IF(ISERROR(SEARCH("LOOK",_xlfn.FORMULATEXT(Soal!S3))),99,3)*12) -> 24 | AQ106: =DEC2HEX(IF(ISERROR(SEARCH("IF",_xlfn.FORMULATEXT(Soal!T3))),99,2)*13) -> 1A | AR106: =DEC2HEX(IF(ISERROR(SEARCH("ROUND",_xlfn.FORMULATEXT(Soal!U3))),99,2)*14) -> 1C | AS106: =DEC2HEX(IF(ISERROR(SEARCH("LOOK",_xlfn.FORMULATEXT(Soal!V3))),99,3)*15) -> 2D | AT106: =DEC2HEX(IF(ISERROR(SEARCH("ROUND",_xlfn.FORMULATEXT(Soal!W3))),99,2)*16) -> 20 | AU106: =DEC2HEX(IF(ISERROR(SEARCH("QUO",_xlfn.FORMULATEXT(Soal!X3))),99,2)*17)&DEC2HEX(IF(ISERROR(SEARCH("SUM",_xlfn.FORMULATEXT(Soal!Z3))),99,4)*2) -> 228
AB107: =AA100&"|"&AB106&"-"&AB105&";"&AC106&"-"&AC105&";"&AD106&"-"&AD105&";"&AE106&"-"&AE105&";"&AF106&"-"&AF105&";"&AG106&"-"&AG105&";"&AH106&"-"&AH105&";"&AI106&"-"&AI105&";"&AJ106&"-"&AJ105&";"&AK106&"-"&AK105&";"&AL106&"-"&AL105&";"&AM106&"-"&AM105&";"&AN106&"-"&AN105&";"&AO106&"-"&AO105&";"&AP106&"-"&AP105&";"&AQ106&"-"&AQ105&";"&AR106&"-"&AR105&";"&AS106&"-"&AS105&";"&AT106&"-"&AT105&";"&AU106&"-"&AU105 -> AS2|C8-A42F;14-B59;1EF19-TPKK;3DEC8-KNJD;141-C9;C8-HUNH;1E-A428;28-B3F3;A-D7;14-AC275;10-BC7F;12-C2BAB;14-D61F;21-E176;24-E2B;1A-E1FD;1C-E785C80;2D-EA2;20-E75DFC8;228-Z591

Sheet Penjelasan Kode
B2: Arti Kode Pagawai
B5: 1 | C5: 2 | D5: 3 | E5: 4 | F5: 5 | G5: 6 | H5: 7 | I5: 8 | J5: 9 | K5: 10 | L5: 11 | M5: 12 | N5: 13 | O5: 14 | P5: 15 | Q5: 16 | R5: 17 | S5: 18 | T5: 19 | U5: 20 | V5: 21 | W5: 22 | X5: 23 | Y5: 24 | Z5: 25
B6: K | C6: C | D6: 2 | E6: 3 | F6: 0 | G6: 8 | H6: 1 | I6: 9 | J6: 8 | K6: 5 | L6: - | M6: H | N6: 1 | O6: 2 | P6: 0 | Q6: 7 | R6: 1 | S6: 9 | T6: 9 | U6: 0 | V6: - | W6: 2 | X6: - | Y6: K | Z6: S

Sheet XL-Test
J3: XL-TEST
J4: (Automatic Excel Testing) By BelajarExcel.id
J11: https://belajarexcel.id/xl-test/
