Workbook
Name Baris: DF!$M$1
Name jmlAND: DF!$X$13
Name jmlIF: DF!$X$12
Name jmlNOT: DF!$X$15
Name jmlOR: DF!$X$14
Name kode_jawaban: DF!$C$34

Sheet XL-Test
A17: KODE SOAL | C17: SBEM015 | E17: KODE JAWABAN | G17: =kode_jawaban -> MO1|39-165D;2E-17D4;47-1980;10-178E;5B-18B4;11-17C1;3C-176F
A19: Intruksi
B21: Medium Level - Soal Latihan Logika IF , AND dan OR
B22: Soal: | C22: Selsaikan Kasus dibawah ini menggunakan Fungsi Excel. Tantangan kali ini kamu diberikan batas penggunaan Fungsi yang bisa digunakan | J22: Fungsi | K22: Batas | L22: Terpakai
C23: Kamu memiliki Jatah batas penggunaan IF sebanyak 7x, AND 5x , OR 1x dan NOT 1x, Manfaatkan Fungsi-fungsi tersebut dengan Baik. | J23: IF | K23: 7 | L23: =jmlIF -> 7
C24: Jika Pengunaan Fungsi melebihi batas yang disediakan, maka jawaban selanjutnya akan dianggap salah walaupun hasil jawaban benar! | J24: AND | K24: 5 | L24: =jmlAND -> 5
C25: Soal dengan tanda ⭐, wajib menggunakan salah satu fungsi AND atau OR, jika tidak ada jawaban akan diangap salah! | J25: OR | K25: 1 | L25: =jmlOR -> 1
J26: NOT | K26: 1 | L26: =jmlNOT -> 1
B27: 1 ⭐ | C27: Isi Ket. Nilai dengan "Baik" atau "Kurang Baik"
C28: Isi dengan "Baik" Jika semua Nilai (Tugas, UTS, UAS) lebih besar atau sama dengan 50 (50 Termasuk) selain itu isi "Kurang Baik"
B29: 2 ⭐ | C29: isi ket. Tugas Tambahan dengan "Tambahan" atau "Tidak Perlu"
C30: Isi dengan "Tambahan" Jika Nilai Tugas dibawah 70 atau Nilai UTS dibawah 70 selain itu isi "Tidak Perlu" (70 Masuk Tidak Perlu)
B31: 3 ⭐ | C31: isi ket. Lulus dengan "Lulus" atau "Tidak Lulus"
C32: Isi dengan "Lulus" Jika Nilai Tugas, Nilai UTS dan Nilai UAS semua >= 75 (75 Termasuk) selain kondisi itu isi dengan "Tidak Lulus"
B33: 4 ⭐ | C33: isi ket. Nilai Istimewa dengan "Nilai Istimewa" atau "Nilai Asli"
C34: Isi dengan "Nilai Istimewa" Jika Nilai UTS lebih besar 80 atau Nilai UAS lebih besar 80 (80 Tidak Termasuk) , jika tidak ada isi dengan "Nilai Asli"
B35: 5 | C35: isi ket. Perbaikan dengan "Perbaikan" atau "Sudah Bagus"
C36: Isi dengan "Perbaikan" Jika Nilai UTS dibawah 75 atau Nilai UAS dibawah 70 selain kondisi itu isi dengan "Sudah Bagus"
B37: 6 | C37: isi ket. Kehadiran dengan "Rajin" atau "Kurang"
C38: Isi dengan "Rajin" Jika Nilai UAS >= 80 (80 Termasuk) dan Kehadiran diatas 80% (80% termasuk) selain kondisi itu isi dengan "Kurang"
B39: 7 ⭐ | C39: isi ket. Beasiswa dengan "Beasiswa" dan "Umum"
C40: Isi dengan "Beasiswa" Jika Perempuan dan Nilai UTS > 75 dan UAS >78 atau Laki-laki dan Nilai UTS > 68 dan UAS > 70 , selain kondisi tersebut isi "Umum"
B42: Sudah selesai mengerjakan? kirim Kode Soal dan Kode Jawaban diatas ke alamat : https://belajarexcel.id/xl-test/jawaban untuk mengecek hasilnya
B43: atau klik tombol disamping
H48: ⭐ | I48: ⭐ | J48: ⭐ | K48: ⭐ | N48: ⭐
G49: Status Jawaban | H49: =DF!O34 -> 1 | I49: =DF!P34 -> 1 | J49: =DF!Q34 -> 1 | K49: =DF!R34 -> 1 | L49: =DF!S34 -> 1 | M49: =DF!T34 -> 1 | N49: =DF!U34 -> 1
H51: 1 | I51: 2 | J51: 3 | K51: 4 | L51: 5 | M51: 6 | N51: 7
A52: No Soal | B52: Nama | C52: Jenis Kelamin | D52: Nilai Tugas | E52: Nilai UTS | F52: Nilai UAS | G52: Kehadiran | H52: Ket Nilai | I52: Ket. Tugas Tambahan | J52: Ket. Lulus | K52: Ket. Nilai Istimewa | L52: Ket. Perbaikan | M52: Ket. Kehadarian | N52: Ket. Beasiswa
A53: Contoh | B53: Andi | C53: Laki-laki | D53: 95 | E53: 81 | F53: 82 | G53: 0.8 | H53: Baik | I53: Tidak Perlu | J53: Lulus | K53: Nilai Istimewa | L53: Sudah Bagus | M53: Rajin | N53: Beasiswa
A55: #1 | B55: Ani | C55: Perempuan | D55: 75 | E55: 82 | F55: 84 | G55: 0.88 | H55: =IF(AND(D55>=50,E55>=50,F55>=50),"Baik","Kurang Baik") -> Baik | I55: =IF(OR(D55<70,E55<70),"Tambahan","Tidak Perlu") -> Tidak Perlu | J55: =IF(AND(D55>=75,E55>=75,F55>=75),"Lulus","Tidak Lulus") -> Lulus | K55: =IF(NOT(AND(E55<=80, F55<=80)), "Nilai Istimewa", "Nilai Asli") -> Nilai Istimewa | L55: =IF((E55<75)+(F55<70)>=1,"Perbaikan","Sudah Bagus") -> Sudah Bagus | M55: =IF((F55>=80)*(G55>=80%)>0,"Rajin","Kurang") -> Rajin | N55: =IF(AND(C55="Perempuan",E55>75,F55>78)+AND(C55="Laki-laki",E55>68,F55>70)>0,"Beasiswa","Umum") -> Beasiswa
A56: #2 | B56: Budi | C56: Laki-laki | D56: 57 | E56: 43 | F56: 48 | G56: 0.89 | H56: =IF(AND(D56>=50,E56>=50,F56>=50),"Baik","Kurang Baik") -> Kurang Baik | I56: =IF(OR(D56<70,E56<70),"Tambahan","Tidak Perlu") -> Tambahan | J56: =IF(AND(D56>=75,E56>=75,F56>=75),"Lulus","Tidak Lulus") -> Tidak Lulus | K56: =IF(NOT(AND(E56<=80, F56<=80)), "Nilai Istimewa", "Nilai Asli") -> Nilai Asli | L56: =IF((E56<75)+(F56<70)>=1,"Perbaikan","Sudah Bagus") -> Perbaikan | M56: =IF((F56>=80)*(G56>=80%)>0,"Rajin","Kurang") -> Kurang | N56: =IF(AND(C56="Perempuan",E56>75,F56>78)+AND(C56="Laki-laki",E56>68,F56>70)>0,"Beasiswa","Umum") -> Umum
A57: #3 | B57: Cici | C57: Perempuan | D57: 51 | E57: 76 | F57: 51 | G57: 0.76 | H57: =IF(AND(D57>=50,E57>=50,F57>=50),"Baik","Kurang Baik") -> Baik | I57: =IF(OR(D57<70,E57<70),"Tambahan","Tidak Perlu") -> Tambahan | J57: =IF(AND(D57>=75,E57>=75,F57>=75),"Lulus","Tidak Lulus") -> Tidak Lulus | K57: =IF(NOT(AND(E57<=80, F57<=80)), "Nilai Istimewa", "Nilai Asli") -> Nilai Asli | L57: =IF((E57<75)+(F57<70)>=1,"Perbaikan","Sudah Bagus") -> Perbaikan | M57: =IF((F57>=80)*(G57>=80%)>0,"Rajin","Kurang") -> Kurang | N57: =IF(AND(C57="Perempuan",E57>75,F57>78)+AND(C57="Laki-laki",E57>68,F57>70)>0,"Beasiswa","Umum") -> Umum
A58: #4 | B58: Dodi | C58: Laki-laki | D58: 80 | E58: 75 | F58: 83 | G58: 0.96 | H58: =IF(AND(D58>=50,E58>=50,F58>=50),"Baik","Kurang Baik") -> Baik | I58: =IF(OR(D58<70,E58<70),"Tambahan","Tidak Perlu") -> Tidak Perlu | J58: =IF(AND(D58>=75,E58>=75,F58>=75),"Lulus","Tidak Lulus") -> Lulus | K58: =IF(NOT(AND(E58<=80, F58<=80)), "Nilai Istimewa", "Nilai Asli") -> Nilai Istimewa | L58: =IF((E58<75)+(F58<70)>=1,"Perbaikan","Sudah Bagus") -> Sudah Bagus | M58: =IF((F58>=80)*(G58>=80%)>0,"Rajin","Kurang") -> Rajin | N58: =IF(AND(C58="Perempuan",E58>75,F58>78)+AND(C58="Laki-laki",E58>68,F58>70)>0,"Beasiswa","Umum") -> Beasiswa
A59: #5 | B59: Eka | C59: Laki-laki | D59: 95 | E59: 73 | F59: 78 | G59: 0.88 | H59: =IF(AND(D59>=50,E59>=50,F59>=50),"Baik","Kurang Baik") -> Baik | I59: =IF(OR(D59<70,E59<70),"Tambahan","Tidak Perlu") -> Tidak Perlu | J59: =IF(AND(D59>=75,E59>=75,F59>=75),"Lulus","Tidak Lulus") -> Tidak Lulus | K59: =IF(NOT(AND(E59<=80, F59<=80)), "Nilai Istimewa", "Nilai Asli") -> Nilai Asli | L59: =IF((E59<75)+(F59<70)>=1,"Perbaikan","Sudah Bagus") -> Perbaikan | M59: =IF((F59>=80)*(G59>=80%)>0,"Rajin","Kurang") -> Kurang | N59: =IF(AND(C59="Perempuan",E59>75,F59>78)+AND(C59="Laki-laki",E59>68,F59>70)>0,"Beasiswa","Umum") -> Beasiswa
A60: #6 | B60: Fina | C60: Perempuan | D60: 42 | E60: 73 | F60: 54 | G60: 0.91 | H60: =IF(AND(D60>=50,E60>=50,F60>=50),"Baik","Kurang Baik") -> Kurang Baik | I60: =IF(OR(D60<70,E60<70),"Tambahan","Tidak Perlu") -> Tambahan | J60: =IF(AND(D60>=75,E60>=75,F60>=75),"Lulus","Tidak Lulus") -> Tidak Lulus | K60: =IF(NOT(AND(E60<=80, F60<=80)), "Nilai Istimewa", "Nilai Asli") -> Nilai Asli | L60: =IF((E60<75)+(F60<70)>=1,"Perbaikan","Sudah Bagus") -> Perbaikan | M60: =IF((F60>=80)*(G60>=80%)>0,"Rajin","Kurang") -> Kurang | N60: =IF(AND(C60="Perempuan",E60>75,F60>78)+AND(C60="Laki-laki",E60>68,F60>70)>0,"Beasiswa","Umum") -> Umum
A61: #7 | B61: Gina | C61: Perempuan | D61: 94 | E61: 79 | F61: 79 | G61: 0.9 | H61: =IF(AND(D61>=50,E61>=50,F61>=50),"Baik","Kurang Baik") -> Baik | I61: =IF(OR(D61<70,E61<70),"Tambahan","Tidak Perlu") -> Tidak Perlu | J61: =IF(AND(D61>=75,E61>=75,F61>=75),"Lulus","Tidak Lulus") -> Lulus | K61: =IF(NOT(AND(E61<=80, F61<=80)), "Nilai Istimewa", "Nilai Asli") -> Nilai Asli | L61: =IF((E61<75)+(F61<70)>=1,"Perbaikan","Sudah Bagus") -> Sudah Bagus | M61: =IF((F61>=80)*(G61>=80%)>0,"Rajin","Kurang") -> Kurang | N61: =IF(AND(C61="Perempuan",E61>75,F61>78)+AND(C61="Laki-laki",E61>68,F61>70)>0,"Beasiswa","Umum") -> Beasiswa
A62: #8 | B62: Hadi | C62: Laki-laki | D62: 44 | E62: 70 | F62: 81 | G62: 0.89 | H62: =IF(AND(D62>=50,E62>=50,F62>=50),"Baik","Kurang Baik") -> Kurang Baik | I62: =IF(OR(D62<70,E62<70),"Tambahan","Tidak Perlu") -> Tambahan | J62: =IF(AND(D62>=75,E62>=75,F62>=75),"Lulus","Tidak Lulus") -> Tidak Lulus | K62: =IF(NOT(AND(E62<=80, F62<=80)), "Nilai Istimewa", "Nilai Asli") -> Nilai Istimewa | L62: =IF((E62<75)+(F62<70)>=1,"Perbaikan","Sudah Bagus") -> Perbaikan | M62: =IF((F62>=80)*(G62>=80%)>0,"Rajin","Kurang") -> Rajin | N62: =IF(AND(C62="Perempuan",E62>75,F62>78)+AND(C62="Laki-laki",E62>68,F62>70)>0,"Beasiswa","Umum") -> Beasiswa
A63: #9 | B63: Indra | C63: Laki-laki | D63: 93 | E63: 85 | F63: 82 | G63: 0.85 | H63: =IF(AND(D63>=50,E63>=50,F63>=50),"Baik","Kurang Baik") -> Baik | I63: =IF(OR(D63<70,E63<70),"Tambahan","Tidak Perlu") -> Tidak Perlu | J63: =IF(AND(D63>=75,E63>=75,F63>=75),"Lulus","Tidak Lulus") -> Lulus | K63: =IF(NOT(AND(E63<=80, F63<=80)), "Nilai Istimewa", "Nilai Asli") -> Nilai Istimewa | L63: =IF((E63<75)+(F63<70)>=1,"Perbaikan","Sudah Bagus") -> Sudah Bagus | M63: =IF((F63>=80)*(G63>=80%)>0,"Rajin","Kurang") -> Rajin | N63: =IF(AND(C63="Perempuan",E63>75,F63>78)+AND(C63="Laki-laki",E63>68,F63>70)>0,"Beasiswa","Umum") -> Beasiswa
A64: #10 | B64: Joko | C64: Laki-laki | D64: 69 | E64: 56 | F64: 96 | G64: 0.92 | H64: =IF(AND(D64>=50,E64>=50,F64>=50),"Baik","Kurang Baik") -> Baik | I64: =IF(OR(D64<70,E64<70),"Tambahan","Tidak Perlu") -> Tambahan | J64: =IF(AND(D64>=75,E64>=75,F64>=75),"Lulus","Tidak Lulus") -> Tidak Lulus | K64: =IF(NOT(AND(E64<=80, F64<=80)), "Nilai Istimewa", "Nilai Asli") -> Nilai Istimewa | L64: =IF((E64<75)+(F64<70)>=1,"Perbaikan","Sudah Bagus") -> Perbaikan | M64: =IF((F64>=80)*(G64>=80%)>0,"Rajin","Kurang") -> Rajin | N64: =IF(AND(C64="Perempuan",E64>75,F64>78)+AND(C64="Laki-laki",E64>68,F64>70)>0,"Beasiswa","Umum") -> Umum
A65: #11 | B65: Udin | C65: Laki-laki | D65: 51 | E65: 92 | F65: 74 | G65: 0.85 | H65: =IF(AND(D65>=50,E65>=50,F65>=50),"Baik","Kurang Baik") -> Baik | I65: =IF(OR(D65<70,E65<70),"Tambahan","Tidak Perlu") -> Tambahan | J65: =IF(AND(D65>=75,E65>=75,F65>=75),"Lulus","Tidak Lulus") -> Tidak Lulus | K65: =IF(NOT(AND(E65<=80, F65<=80)), "Nilai Istimewa", "Nilai Asli") -> Nilai Istimewa | L65: =IF((E65<75)+(F65<70)>=1,"Perbaikan","Sudah Bagus") -> Sudah Bagus | M65: =IF((F65>=80)*(G65>=80%)>0,"Rajin","Kurang") -> Kurang | N65: =IF(AND(C65="Perempuan",E65>75,F65>78)+AND(C65="Laki-laki",E65>68,F65>70)>0,"Beasiswa","Umum") -> Beasiswa
...

Sheet About
I6: XL-TEST adalah platform inovatif yang menyediakan latihan Excel interaktif dengan pemeriksaan otomatis,
I7: sehingga pengguna dapat langsung mengetahui jawaban yang benar maupun salah.
I10: Terdapat 5 Level soal :
J12: Easy Level | L12: (⭐)
J13: Medium Level | L13: (⭐⭐)
J14: Hard Level | L14: (⭐⭐⭐)
J15: Extreme Level | L15: (⭐⭐⭐⭐)
J16: Championship Level | L16: (⭐⭐⭐⭐⭐)
B17: Saya adalah seorang Excel Holic yang percaya bahwa setiap angka memiliki cerita yang bisa ditemukan dengan cara yang tepat. | I17: Free Access
B18: “Excel bukan cuma soal kerjaan tapi juga hobi yang aku nikmati.” | I18: https://belajarexcel.id/xl-test/
B19: Contact :
B20: 🌐 Web | C20: https://setiadi.me
B21: 🪡threads | C21: https://www.threads.com/@andisetiadi
D27: Perlu Video Penjelasan atau Kunci Jawaban ?
D28: Scan barcode atau kunjungi
D29: https://lynk.id/setiadi/page/jawaban-xl-test

Sheet DF
C1: 1 | D1: 2 | E1: 3 | F1: 4 | G1: 5 | H1: 6 | I1: 7 | J1: 8 | L1: 169 | M1: =SUM(L4:L8) -> 32 | O1: 1 | P1: 2 | Q1: 3 | R1: 4 | S1: 5 | T1: 6 | U1: 7
A2: DF | B2: 1 | C2: =UPPER('XL-Test'!H55) -> BAIK | D2: =UPPER('XL-Test'!I55) -> TIDAK PERLU | E2: =UPPER('XL-Test'!J55) -> LULUS | F2: =UPPER('XL-Test'!K55) -> NILAI ISTIMEWA | G2: =UPPER('XL-Test'!L55) -> SUDAH BAGUS | H2: =UPPER('XL-Test'!M55) -> RAJIN | I2: =UPPER('XL-Test'!N55) -> BEASISWA | J2: ='XL-Test'!O55 -> 0 | N2: 1 | O2: =_xlfn.FORMULATEXT('XL-Test'!H55) -> =IF(AND(D55>=50;E55>=50;F55>=50);"Baik";"Kurang Baik") | P2: =_xlfn.FORMULATEXT('XL-Test'!I55) -> =IF(OR(D55<70;E55<70);"Tambahan";"Tidak Perlu") | Q2: =_xlfn.FORMULATEXT('XL-Test'!J55) -> =IF(AND(D55>=75;E55>=75;F55>=75);"Lulus";"Tidak Lulus") | R2: =_xlfn.FORMULATEXT('XL-Test'!K55) -> =IF(NOT(AND(E55<=80; F55<=80)); "Nilai Istimewa"; "Nilai Asli") | S2: =_xlfn.FORMULATEXT('XL-Test'!L55) -> =IF((E55<75)+(F55<70)>=1;"Perbaikan";"Sudah Bagus") | T2: =_xlfn.FORMULATEXT('XL-Test'!M55) -> =IF((F55>=80)*(G55>=80%)>0;"Rajin";"Kurang") | U2: =_xlfn.FORMULATEXT('XL-Test'!N55) -> =IF(AND(C55="Perempuan";E55>75;F55>78)+AND(C55="Laki-laki";E55>68;F55>70)>0;"Beasiswa";"Umum")
A3: MO1 | B3: 2 | C3: =UPPER('XL-Test'!H56) -> KURANG BAIK | D3: =UPPER('XL-Test'!I56) -> TAMBAHAN | E3: =UPPER('XL-Test'!J56) -> TIDAK LULUS | F3: =UPPER('XL-Test'!K56) -> NILAI ASLI | G3: =UPPER('XL-Test'!L56) -> PERBAIKAN | H3: =UPPER('XL-Test'!M56) -> KURANG | I3: =UPPER('XL-Test'!N56) -> UMUM | J3: ='XL-Test'!O56 -> 0 | N3: 2 | O3: =P2 -> =IF(OR(D55<70;E55<70);"Tambahan";"Tidak Perlu")
B4: 3 | C4: =UPPER('XL-Test'!H57) -> BAIK | D4: =UPPER('XL-Test'!I57) -> TAMBAHAN | E4: =UPPER('XL-Test'!J57) -> TIDAK LULUS | F4: =UPPER('XL-Test'!K57) -> NILAI ASLI | G4: =UPPER('XL-Test'!L57) -> PERBAIKAN | H4: =UPPER('XL-Test'!M57) -> KURANG | I4: =UPPER('XL-Test'!N57) -> UMUM | J4: ='XL-Test'!O57 -> 0 | L4: 1 | N4: 3 | O4: =Q2 -> =IF(AND(D55>=75;E55>=75;F55>=75);"Lulus";"Tidak Lulus")
B5: 4 | C5: =UPPER('XL-Test'!H58) -> BAIK | D5: =UPPER('XL-Test'!I58) -> TIDAK PERLU | E5: =UPPER('XL-Test'!J58) -> LULUS | F5: =UPPER('XL-Test'!K58) -> NILAI ISTIMEWA | G5: =UPPER('XL-Test'!L58) -> SUDAH BAGUS | H5: =UPPER('XL-Test'!M58) -> RAJIN | I5: =UPPER('XL-Test'!N58) -> BEASISWA | J5: ='XL-Test'!O58 -> 0 | L5: 2 | N5: 4 | O5: =R2 -> =IF(NOT(AND(E55<=80; F55<=80)); "Nilai Istimewa"; "Nilai Asli")
B6: 5 | C6: =UPPER('XL-Test'!H59) -> BAIK | D6: =UPPER('XL-Test'!I59) -> TIDAK PERLU | E6: =UPPER('XL-Test'!J59) -> TIDAK LULUS | F6: =UPPER('XL-Test'!K59) -> NILAI ASLI | G6: =UPPER('XL-Test'!L59) -> PERBAIKAN | H6: =UPPER('XL-Test'!M59) -> KURANG | I6: =UPPER('XL-Test'!N59) -> BEASISWA | J6: ='XL-Test'!O59 -> 0 | L6: 3 | N6: 5 | O6: =S2 -> =IF((E55<75)+(F55<70)>=1;"Perbaikan";"Sudah Bagus")
B7: 6 | C7: =UPPER('XL-Test'!H60) -> KURANG BAIK | D7: =UPPER('XL-Test'!I60) -> TAMBAHAN | E7: =UPPER('XL-Test'!J60) -> TIDAK LULUS | F7: =UPPER('XL-Test'!K60) -> NILAI ASLI | G7: =UPPER('XL-Test'!L60) -> PERBAIKAN | H7: =UPPER('XL-Test'!M60) -> KURANG | I7: =UPPER('XL-Test'!N60) -> UMUM | J7: ='XL-Test'!O60 -> 0 | L7: 29 | N7: 6 | O7: =T2 -> =IF((F55>=80)*(G55>=80%)>0;"Rajin";"Kurang")
B8: 7 | C8: =UPPER('XL-Test'!H61) -> BAIK | D8: =UPPER('XL-Test'!I61) -> TIDAK PERLU | E8: =UPPER('XL-Test'!J61) -> LULUS | F8: =UPPER('XL-Test'!K61) -> NILAI ASLI | G8: =UPPER('XL-Test'!L61) -> SUDAH BAGUS | H8: =UPPER('XL-Test'!M61) -> KURANG | I8: =UPPER('XL-Test'!N61) -> BEASISWA | J8: ='XL-Test'!O61 -> 0 | L8: -3 | N8: 7 | O8: =U2 -> =IF(AND(C55="Perempuan";E55>75;F55>78)+AND(C55="Laki-laki";E55>68;F55>70)>0;"Beasiswa";"Umum")
B9: 8 | C9: =UPPER('XL-Test'!H62) -> KURANG BAIK | D9: =UPPER('XL-Test'!I62) -> TAMBAHAN | E9: =UPPER('XL-Test'!J62) -> TIDAK LULUS | F9: =UPPER('XL-Test'!K62) -> NILAI ISTIMEWA | G9: =UPPER('XL-Test'!L62) -> PERBAIKAN | H9: =UPPER('XL-Test'!M62) -> RAJIN | I9: =UPPER('XL-Test'!N62) -> BEASISWA | J9: ='XL-Test'!O62 -> 0
B10: 9 | C10: =UPPER('XL-Test'!H63) -> BAIK | D10: =UPPER('XL-Test'!I63) -> TIDAK PERLU | E10: =UPPER('XL-Test'!J63) -> LULUS | F10: =UPPER('XL-Test'!K63) -> NILAI ISTIMEWA | G10: =UPPER('XL-Test'!L63) -> SUDAH BAGUS | H10: =UPPER('XL-Test'!M63) -> RAJIN | I10: =UPPER('XL-Test'!N63) -> BEASISWA | J10: ='XL-Test'!O63 -> 0
B11: 10 | C11: =UPPER('XL-Test'!H64) -> BAIK | D11: =UPPER('XL-Test'!I64) -> TAMBAHAN | E11: =UPPER('XL-Test'!J64) -> TIDAK LULUS | F11: =UPPER('XL-Test'!K64) -> NILAI ISTIMEWA | G11: =UPPER('XL-Test'!L64) -> PERBAIKAN | H11: =UPPER('XL-Test'!M64) -> RAJIN | I11: =UPPER('XL-Test'!N64) -> UMUM | J11: ='XL-Test'!O64 -> 0
B12: 11 | C12: =UPPER('XL-Test'!H65) -> BAIK | D12: =UPPER('XL-Test'!I65) -> TAMBAHAN | E12: =UPPER('XL-Test'!J65) -> TIDAK LULUS | F12: =UPPER('XL-Test'!K65) -> NILAI ISTIMEWA | G12: =UPPER('XL-Test'!L65) -> SUDAH BAGUS | H12: =UPPER('XL-Test'!M65) -> KURANG | I12: =UPPER('XL-Test'!N65) -> BEASISWA | J12: ='XL-Test'!O65 -> 0 | N12: IF | O12: =IFERROR((LEN(O2)-LEN(SUBSTITUTE(O2,"IF(","")))/3,0) -> 1 | P12: =IFERROR((LEN(P2)-LEN(SUBSTITUTE(P2,"IF(","")))/3,0) -> 1 | Q12: =IFERROR((LEN(Q2)-LEN(SUBSTITUTE(Q2,"IF(","")))/3,0) -> 1 | R12: =IFERROR((LEN(R2)-LEN(SUBSTITUTE(R2,"IF(","")))/3,0) -> 1 | S12: =IFERROR((LEN(S2)-LEN(SUBSTITUTE(S2,"IF(","")))/3,0) -> 1 | T12: =IFERROR((LEN(T2)-LEN(SUBSTITUTE(T2,"IF(","")))/3,0) -> 1 | U12: =IFERROR((LEN(U2)-LEN(SUBSTITUTE(U2,"IF(","")))/3,0) -> 1 | X12: =SUM(O12:V12) -> 7
B13: 12 | C13: =UPPER('XL-Test'!H66) -> KURANG BAIK | D13: =UPPER('XL-Test'!I66) -> TAMBAHAN | E13: =UPPER('XL-Test'!J66) -> TIDAK LULUS | F13: =UPPER('XL-Test'!K66) -> NILAI ASLI | G13: =UPPER('XL-Test'!L66) -> PERBAIKAN | H13: =UPPER('XL-Test'!M66) -> KURANG | I13: =UPPER('XL-Test'!N66) -> UMUM | J13: ='XL-Test'!O66 -> 0 | N13: AND | O13: =IFERROR((LEN(O2)-LEN(SUBSTITUTE(O2,"AND(","")))/4,0) -> 1 | P13: =IFERROR((LEN(P2)-LEN(SUBSTITUTE(P2,"AND(","")))/4,0) -> 0 | Q13: =IFERROR((LEN(Q2)-LEN(SUBSTITUTE(Q2,"AND(","")))/4,0) -> 1 | R13: =IFERROR((LEN(R2)-LEN(SUBSTITUTE(R2,"AND(","")))/4,0) -> 1 | S13: =IFERROR((LEN(S2)-LEN(SUBSTITUTE(S2,"AND(","")))/4,0) -> 0 | T13: =IFERROR((LEN(T2)-LEN(SUBSTITUTE(T2,"AND(","")))/4,0) -> 0 | U13: =IFERROR((LEN(U2)-LEN(SUBSTITUTE(U2,"AND(","")))/4,0) -> 2 | X13: =SUM(O13:V13) -> 5
B14: 13 | C14: =UPPER('XL-Test'!H67) -> BAIK | D14: =UPPER('XL-Test'!I67) -> TIDAK PERLU | E14: =UPPER('XL-Test'!J67) -> TIDAK LULUS | F14: =UPPER('XL-Test'!K67) -> NILAI ASLI | G14: =UPPER('XL-Test'!L67) -> SUDAH BAGUS | H14: =UPPER('XL-Test'!M67) -> RAJIN | I14: =UPPER('XL-Test'!N67) -> BEASISWA | J14: ='XL-Test'!O67 -> 0 | N14: OR | O14: =IFERROR((LEN(O2)-LEN(SUBSTITUTE(O2,"OR(","")))/3,0) -> 0 | P14: =IFERROR((LEN(P2)-LEN(SUBSTITUTE(P2,"OR(","")))/3,0) -> 1 | Q14: =IFERROR((LEN(Q2)-LEN(SUBSTITUTE(Q2,"OR(","")))/3,0) -> 0 | R14: =IFERROR((LEN(R2)-LEN(SUBSTITUTE(R2,"OR(","")))/3,0) -> 0 | S14: =IFERROR((LEN(S2)-LEN(SUBSTITUTE(S2,"OR(","")))/3,0) -> 0 | T14: =IFERROR((LEN(T2)-LEN(SUBSTITUTE(T2,"OR(","")))/3,0) -> 0 | U14: =IFERROR((LEN(U2)-LEN(SUBSTITUTE(U2,"OR(","")))/3,0) -> 0 | X14: =SUM(O14:V14) -> 1
B15: 14 | C15: =UPPER('XL-Test'!H68) -> BAIK | D15: =UPPER('XL-Test'!I68) -> TIDAK PERLU | E15: =UPPER('XL-Test'!J68) -> LULUS | F15: =UPPER('XL-Test'!K68) -> NILAI ISTIMEWA | G15: =UPPER('XL-Test'!L68) -> SUDAH BAGUS | H15: =UPPER('XL-Test'!M68) -> KURANG | I15: =UPPER('XL-Test'!N68) -> BEASISWA | J15: ='XL-Test'!O68 -> 0 | N15: NOT | O15: =IFERROR((LEN(O2)-LEN(SUBSTITUTE(O2,"NOT(","")))/4,0) -> 0 | P15: =IFERROR((LEN(P2)-LEN(SUBSTITUTE(P2,"NOT(","")))/4,0) -> 0 | Q15: =IFERROR((LEN(Q2)-LEN(SUBSTITUTE(Q2,"NOT(","")))/4,0) -> 0 | R15: =IFERROR((LEN(R2)-LEN(SUBSTITUTE(R2,"NOT(","")))/4,0) -> 1 | S15: =IFERROR((LEN(S2)-LEN(SUBSTITUTE(S2,"NOT(","")))/4,0) -> 0 | T15: =IFERROR((LEN(T2)-LEN(SUBSTITUTE(T2,"NOT(","")))/4,0) -> 0 | U15: =IFERROR((LEN(U2)-LEN(SUBSTITUTE(U2,"NOT(","")))/4,0) -> 0 | X15: =SUM(O15:V15) -> 1
C17: =(SUM(C58:C71)+C60+C63+C66+C68+C70+C58) -> 5725 | D17: =(SUM(D58:D71)+D60+D63+D66+D68+D70+D58) -> 6100 | E17: =(SUM(E58:E71)+E60+E63+E66+E68+E70+E58) -> 6528 | F17: =(SUM(F58:F71)+F60+F63+F66+F68+F70+F58) -> 6030 | G17: =(SUM(G58:G71)+G60+G63+G66+G68+G70+G58) -> 6324 | H17: =(SUM(H58:H71)+H60+H63+H66+H68+H70+H58) -> 6081 | I17: =(SUM(I58:I71)+I60+I63+I66+I68+I70+I58) -> 5999
C18: =DEC2HEX(C17) -> 165D | D18: =DEC2HEX(D17) -> 17D4 | E18: =DEC2HEX(E17) -> 1980 | F18: =DEC2HEX(F17) -> 178E | G18: =DEC2HEX(G17) -> 18B4 | H18: =DEC2HEX(H17) -> 17C1 | I18: =DEC2HEX(I17) -> 176F
B19: RND | C19: 5054 | D19: 1542 | E19: 8966 | F19: 1610 | G19: 6984 | H19: 2809 | I19: 3651 | O19: 125 | P19: X
C20: =IFERROR(DEC2HEX(IF(AND(NOT(OR(C2=0,C2="")),C74),C17,C19)),"EEE") -> 165D | D20: =IFERROR(DEC2HEX(IF(AND(NOT(OR(D2=0,D2="")),D74),D17,D19)),"EEE") -> 17D4 | E20: =IFERROR(DEC2HEX(IF(AND(NOT(OR(E2=0,E2="")),E74),E17,E19)),"EEE") -> 1980 | F20: =IFERROR(DEC2HEX(IF(AND(NOT(OR(F2=0,F2="")),F74),F17,F19)),"EEE") -> 178E | G20: =IFERROR(DEC2HEX(IF(AND(NOT(OR(G2=0,G2="")),G74),G17,G19)),"EEE") -> 18B4 | H20: =IFERROR(DEC2HEX(IF(AND(NOT(OR(H2=0,H2="")),H74),H17,H19)),"EEE") -> 17C1 | I20: =IFERROR(DEC2HEX(IF(AND(NOT(OR(I2=0,I2="")),I74),I17,I19)),"EEE") -> 176F | O20: 146 | P20: Y
O21: 169 | P21: C
B22: TRUE | C22: =DEC2HEX(RIGHT(C19,2)+COLUMN()) -> 39 | D22: =DEC2HEX(RIGHT(D19,2)+COLUMN()) -> 2E | E22: =DEC2HEX(RIGHT(E19,2)+COLUMN()) -> 47 | F22: =DEC2HEX(RIGHT(F19,2)+COLUMN()) -> 10 | G22: =DEC2HEX(RIGHT(G19,2)+COLUMN()) -> 5B | H22: =DEC2HEX(RIGHT(H19,2)+COLUMN()) -> 11 | I22: =DEC2HEX(RIGHT(I19,2)+COLUMN()) -> 3C | O22: 148 | P22: B
B23: FALSE | C23: =DEC2HEX(LEFT(C19,2)+COLUMN()) -> 35 | D23: =DEC2HEX(LEFT(D19,2)+COLUMN()) -> 13 | E23: =DEC2HEX(LEFT(E19,2)+COLUMN()) -> 5E | F23: =DEC2HEX(LEFT(F19,2)+COLUMN()) -> 16 | G23: =DEC2HEX(LEFT(G19,2)+COLUMN()) -> 4C | H23: =DEC2HEX(LEFT(H19,2)+COLUMN()) -> 24 | I23: =DEC2HEX(LEFT(I19,2)+COLUMN()) -> 2D
N24: IF | O24: =SUM($O12:O12) -> 1 | P24: =SUM($O12:P12) -> 2 | Q24: =SUM($O12:Q12) -> 3 | R24: =SUM($O12:R12) -> 4 | S24: =SUM($O12:S12) -> 5 | T24: =SUM($O12:T12) -> 6 | U24: =SUM($O12:U12) -> 7 | X24: 7
B25: Cek Manual | C25: =AND(ISNUMBER(FIND("=",O2)),ISNUMBER(FIND("IF(",O2))) -> TRUE | D25: =AND(ISNUMBER(FIND("=",P2)),ISNUMBER(FIND("IF(",P2))) -> TRUE | E25: =AND(ISNUMBER(FIND("=",Q2)),ISNUMBER(FIND("IF(",Q2))) -> TRUE | F25: =AND(ISNUMBER(FIND("=",R2)),ISNUMBER(FIND("IF(",R2))) -> TRUE | G25: =AND(ISNUMBER(FIND("=",S2)),ISNUMBER(FIND("IF(",S2))) -> TRUE | H25: =AND(ISNUMBER(FIND("=",T2)),ISNUMBER(FIND("IF(",T2))) -> TRUE | I25: =AND(ISNUMBER(FIND("=",U2)),ISNUMBER(FIND("IF(",U2))) -> TRUE | N25: AND | O25: =SUM($O13:O13) -> 1 | P25: =SUM($O13:P13) -> 1 | Q25: =SUM($O13:Q13) -> 2 | R25: =SUM($O13:R13) -> 3 | S25: =SUM($O13:S13) -> 3 | T25: =SUM($O13:T13) -> 3 | U25: =SUM($O13:U13) -> 5 | X25: 5
B26: Cek Formula | C26: =ISNUMBER(FIND("IF(",SUBSTITUTE(O2,"$",""))) -> TRUE | D26: =ISNUMBER(FIND("IF(",SUBSTITUTE(P2,"$",""))) -> TRUE | E26: =ISNUMBER(FIND("IF(",SUBSTITUTE(Q2,"$",""))) -> TRUE | F26: =ISNUMBER(FIND("IF(",SUBSTITUTE(R2,"$",""))) -> TRUE | G26: =ISNUMBER(FIND("IF(",SUBSTITUTE(S2,"$",""))) -> TRUE | H26: =ISNUMBER(FIND("IF(",SUBSTITUTE(T2,"$",""))) -> TRUE | I26: =ISNUMBER(FIND("IF(",SUBSTITUTE(U2,"$",""))) -> TRUE | N26: OR | O26: =SUM($O14:O14) -> 0 | P26: =SUM($O14:P14) -> 1 | Q26: =SUM($O14:Q14) -> 1 | R26: =SUM($O14:R14) -> 1 | S26: =SUM($O14:S14) -> 1 | T26: =SUM($O14:T14) -> 1 | U26: =SUM($O14:U14) -> 1 | X26: 1
N27: NOT | O27: =SUM($O15:O15) -> 0 | P27: =SUM($O15:P15) -> 0 | Q27: =SUM($O15:Q15) -> 0 | R27: =SUM($O15:R15) -> 1 | S27: =SUM($O15:S15) -> 1 | T27: =SUM($O15:T15) -> 1 | U27: =SUM($O15:U15) -> 1 | X27: 1
C28: =IF(C26,C22,C23)&"-"&C20&";" -> 39-165D; | D28: =IF(D26,D22,D23)&"-"&D20&";" -> 2E-17D4; | E28: =IF(E26,E22,E23)&"-"&E20&";" -> 47-1980; | F28: =IF(F26,F22,F23)&"-"&F20&";" -> 10-178E; | G28: =IF(G26,G22,G23)&"-"&G20&";" -> 5B-18B4; | H28: =IF(H26,H22,H23)&"-"&H20&";" -> 11-17C1; | I28: =IF(I26,I22,I23)&"-"&I20 -> 3C-176F | O28: =O24<=$X24 -> TRUE | P28: =P24<=$X24 -> TRUE | Q28: =Q24<=$X24 -> TRUE | R28: =R24<=$X24 -> TRUE | S28: =S24<=$X24 -> TRUE | T28: =T24<=$X24 -> TRUE | U28: =U24<=$X24 -> TRUE
O29: =O25<=$X25 -> TRUE | P29: =P25<=$X25 -> TRUE | Q29: =Q25<=$X25 -> TRUE | R29: =R25<=$X25 -> TRUE | S29: =S25<=$X25 -> TRUE | T29: =T25<=$X25 -> TRUE | U29: =U25<=$X25 -> TRUE
C30: =A3&"|"&C28&D28&E28&F28&G28&H28&I28&J28 -> MO1|39-165D;2E-17D4;47-1980;10-178E;5B-18B4;11-17C1;3C-176F | O30: =O26<=$X26 -> TRUE | P30: =P26<=$X26 -> TRUE | Q30: =Q26<=$X26 -> TRUE | R30: =R26<=$X26 -> TRUE | S30: =S26<=$X26 -> TRUE | T30: =T26<=$X26 -> TRUE | U30: =U26<=$X26 -> TRUE
O31: =O27<=$X27 -> TRUE | P31: =P27<=$X27 -> TRUE | Q31: =Q27<=$X27 -> TRUE | R31: =R27<=$X27 -> TRUE | S31: =S27<=$X27 -> TRUE | T31: =T27<=$X27 -> TRUE | U31: =U27<=$X27 -> TRUE
C32: =C30 -> MO1|39-165D;2E-17D4;47-1980;10-178E;5B-18B4;11-17C1;3C-176F
O33: =AND(O28:O31,O38) -> TRUE | P33: =AND(P28:P31,P38) -> TRUE | Q33: =AND(Q28:Q31,Q38) -> TRUE | R33: =AND(R28:R31,R38) -> TRUE | S33: =AND(S28:S31,S38) -> TRUE | T33: =AND(T28:T31,T38) -> TRUE | U33: =AND(U28:U31,U38) -> TRUE
C34: {=INDIRECT(VLOOKUP(L1,O19:P22,2,0)&Baris)} -> MO1|39-165D;2E-17D4;47-1980;10-178E;5B-18B4;11-17C1;3C-176F | O34: =O33+0 -> 1 | P34: =P33+0 -> 1 | Q34: =Q33+0 -> 1 | R34: =R33+0 -> 1 | S34: =S33+0 -> 1 | T34: =T33+0 -> 1 | U34: =U33+0 -> 1
O36: =SUM(O13:O14) -> 1 | P36: =SUM(P13:P14) -> 1 | Q36: =SUM(Q13:Q14) -> 1 | R36: =SUM(R13:R14) -> 1 | S36: =SUM(S13:S14) -> 0 | T36: =SUM(T13:T14) -> 0 | U36: =SUM(U13:U14) -> 2
C37: 1 | D37: 2 | E37: 3 | F37: 4 | G37: 5 | H37: 6 | I37: 7 | O37: 1 | P37: 1 | Q37: 1 | R37: 1 | S37: 0 | T37: 0 | U37: 1
B38: 1 | C38: =IFERROR(LEN(_xlfn.FORMULATEXT('XL-Test'!H55)),0) -> 54 | D38: =IFERROR(LEN(_xlfn.FORMULATEXT('XL-Test'!I55)),0) -> 47 | E38: =IFERROR(LEN(_xlfn.FORMULATEXT('XL-Test'!J55)),0) -> 55 | F38: =IFERROR(LEN(_xlfn.FORMULATEXT('XL-Test'!K55)),0) -> 63 | G38: =IFERROR(LEN(_xlfn.FORMULATEXT('XL-Test'!L55)),0) -> 51 | H38: =IFERROR(LEN(_xlfn.FORMULATEXT('XL-Test'!M55)),0) -> 44 | I38: =IFERROR(LEN(_xlfn.FORMULATEXT('XL-Test'!N55)),0) -> 94 | J38: =IFERROR(LEN(_xlfn.FORMULATEXT('XL-Test'!O55)),0) -> 0 | O38: =IF(C2="",TRUE,O36>=O37) -> TRUE | P38: =IF(D2="",TRUE,P36>=P37) -> TRUE | Q38: =IF(E2="",TRUE,Q36>=Q37) -> TRUE | R38: =IF(F2="",TRUE,R36>=R37) -> TRUE | S38: =IF(G2="",TRUE,S36>=S37) -> TRUE | T38: =IF(H2="",TRUE,T36>=T37) -> TRUE | U38: =IF(I2="",TRUE,U36>=U37) -> TRUE
B39: 2 | C39: =IFERROR(LEN(_xlfn.FORMULATEXT('XL-Test'!H56)),0) -> 54 | D39: =IFERROR(LEN(_xlfn.FORMULATEXT('XL-Test'!I56)),0) -> 47 | E39: =IFERROR(LEN(_xlfn.FORMULATEXT('XL-Test'!J56)),0) -> 55 | F39: =IFERROR(LEN(_xlfn.FORMULATEXT('XL-Test'!K56)),0) -> 63 | G39: =IFERROR(LEN(_xlfn.FORMULATEXT('XL-Test'!L56)),0) -> 51 | H39: =IFERROR(LEN(_xlfn.FORMULATEXT('XL-Test'!M56)),0) -> 44 | I39: =IFERROR(LEN(_xlfn.FORMULATEXT('XL-Test'!N56)),0) -> 94 | J39: =IFERROR(LEN(_xlfn.FORMULATEXT('XL-Test'!O56)),0) -> 0
B40: 3 | C40: =IFERROR(LEN(_xlfn.FORMULATEXT('XL-Test'!H57)),0) -> 54 | D40: =IFERROR(LEN(_xlfn.FORMULATEXT('XL-Test'!I57)),0) -> 47 | E40: =IFERROR(LEN(_xlfn.FORMULATEXT('XL-Test'!J57)),0) -> 55 | F40: =IFERROR(LEN(_xlfn.FORMULATEXT('XL-Test'!K57)),0) -> 63 | G40: =IFERROR(LEN(_xlfn.FORMULATEXT('XL-Test'!L57)),0) -> 51 | H40: =IFERROR(LEN(_xlfn.FORMULATEXT('XL-Test'!M57)),0) -> 44 | I40: =IFERROR(LEN(_xlfn.FORMULATEXT('XL-Test'!N57)),0) -> 94 | J40: =IFERROR(LEN(_xlfn.FORMULATEXT('XL-Test'!O57)),0) -> 0
B41: 4 | C41: =IFERROR(LEN(_xlfn.FORMULATEXT('XL-Test'!H58)),0) -> 54 | D41: =IFERROR(LEN(_xlfn.FORMULATEXT('XL-Test'!I58)),0) -> 47 | E41: =IFERROR(LEN(_xlfn.FORMULATEXT('XL-Test'!J58)),0) -> 55 | F41: =IFERROR(LEN(_xlfn.FORMULATEXT('XL-Test'!K58)),0) -> 63 | G41: =IFERROR(LEN(_xlfn.FORMULATEXT('XL-Test'!L58)),0) -> 51 | H41: =IFERROR(LEN(_xlfn.FORMULATEXT('XL-Test'!M58)),0) -> 44 | I41: =IFERROR(LEN(_xlfn.FORMULATEXT('XL-Test'!N58)),0) -> 94 | J41: =IFERROR(LEN(_xlfn.FORMULATEXT('XL-Test'!O58)),0) -> 0
B42: 5 | C42: =IFERROR(LEN(_xlfn.FORMULATEXT('XL-Test'!H59)),0) -> 54 | D42: =IFERROR(LEN(_xlfn.FORMULATEXT('XL-Test'!I59)),0) -> 47 | E42: =IFERROR(LEN(_xlfn.FORMULATEXT('XL-Test'!J59)),0) -> 55 | F42: =IFERROR(LEN(_xlfn.FORMULATEXT('XL-Test'!K59)),0) -> 63 | G42: =IFERROR(LEN(_xlfn.FORMULATEXT('XL-Test'!L59)),0) -> 51 | H42: =IFERROR(LEN(_xlfn.FORMULATEXT('XL-Test'!M59)),0) -> 44 | I42: =IFERROR(LEN(_xlfn.FORMULATEXT('XL-Test'!N59)),0) -> 94 | J42: =IFERROR(LEN(_xlfn.FORMULATEXT('XL-Test'!O59)),0) -> 0
...
