Workbook
Name kode_jawaban: DF!$C$37
Name old: [1]DF!$C$66

Sheet XL-Test
A18: KODE SOAL | C18: SBEM008 | E18: KODE JAWABAN | G18: =kode_jawaban -> MH2|52-416;24-1A2;36-72;5D-123;58-A;5E-9;26-10CA;4F-2EF;60-4C;2E-12FBDC;59-13000B;39-FDD;5F-12F7B8;39-12FF6B;6C-130ACA
A20: Intruksi
B22: Medium Level - Latihan Soal Management Proyek
B24: Soal : | C24: Gunakan Fungsi Excel (Function) untuk menyelsaikan kasus dibawah ini
C25: Penjelasan soal ada di setiap nomor soal pada baris 46 dan 71, kata "Hari ini" mengacu pada data di cell D44
B27: 6 | C27: ketentuan pembulatan disoal nomor 6 sebagai berikut;
C28: Durasi kerja dibulatkan ke jam terdekat, jika lebih dari 30 Menit dibulatan ke Jam berikutnya jika kurang 30 menit dibulatkan kebawah
C29: misal jika Total Durasi adalah 8:21 maka Total Durasi menjadi 08:00
C30: sedangkan jika Total Durasi adalah 8:43 maka Total durasi menjadi 09:00
B31: 12 | C31: ketentuan soal nomor 12:
C32: Jika Tanggal Selesai Proyek sudah melewati hari ini (D45), maka "Selesai"
C33: Jika Tanggal Proyek Mulai masih di masa depan dari hari ini (D45), maka "Akan Datang"
C34: Selain kondisi diatas maka "Sedang Berjalan"
C36: Sudah selesai mengerjakan? kirim Kode Soal dan Kode Jawaban diatas ke alamat : https://belajarexcel.id/xl-test/jawaban untuk mengecek hasilnya
C37: atau klik tombol disamping
B43: Rekapitulasi Data Karyawan, Waktu Kerja, dan Proyek
C45: Hari Ini | D45: 45886
G46: Soal >> | H46: 1 | I46: 2 | J46: 3 | K46: 4 | N46: 5 | O46: 6
B47: NO | C47: ID KARYAWAN | D47: NAMA KARYAWAN | E47: JABATAN | F47: TANGGAL LAHIR | G47: TANGGAL MASUK (Gabung Perusahaan) | H47: USIA KARYAWAN (Tahun) | I47: LAMA KERJA (Tahun) | J47: LAMA KERJA (Sisa Bulan) | K47: LAMA KERJA (Sisa Hari) | L47: JAM MASUK | M47: JAM PULANG | N47: TOTAL DURASI KERJA (Normal) | O47: TOTAL DURASI KERJA (Pembulatan)
B48: 1 | C48: ID-PM-001 | D48: LOKA WIRANTA | E48: Project Manager | F48: 29092 | G48: 35970 | H48: =DATEDIF(F48,$D$45,"Y") -> 45 | I48: =DATEDIF(G48,$D$45,"Y") -> 27 | J48: =DATEDIF(G48,$D$45,"YM") -> 1 | K48: =DATEDIF(G48,$D$45,"MD") -> 24 | L48: 0.39261574 | M48: 0.79148148 | N48: =M48-L48 -> 0.39886574 | O48: =MROUND(N48,"1:00") -> 0.41666667
B49: 2 | C49: ID-CE-002 | D49: HANA LIN | E49: Civil Engineer | F49: 36535 | G49: 45429 | H49: =DATEDIF(F49,$D$45,"Y") -> 25 | I49: =DATEDIF(G49,$D$45,"Y") -> 1 | J49: =DATEDIF(G49,$D$45,"YM") -> 3 | K49: =DATEDIF(G49,$D$45,"MD") -> 0 | L49: 0.37457176 | M49: 0.7193287 | N49: =M49-L49 -> 0.34475694 | O49: =MROUND(N49,"1:00") -> 0.33333333
B50: 3 | C50: ID-QS-003 | D50: SANITA VELORA | E50: Quantity Surveyor | F50: 28555 | G50: 38239 | H50: =DATEDIF(F50,$D$45,"Y") -> 47 | I50: =DATEDIF(G50,$D$45,"Y") -> 20 | J50: =DATEDIF(G50,$D$45,"YM") -> 11 | K50: =DATEDIF(G50,$D$45,"MD") -> 8 | L50: 0.36206019 | M50: 0.69539352 | N50: =M50-L50 -> 0.33333333 | O50: =MROUND(N50,"1:00") -> 0.33333333
B51: 4 | C51: ID-CE-004 | D51: VANYA RUSELINA | E51: Civil Engineer | F51: 27551 | G51: 38464 | H51: =DATEDIF(F51,$D$45,"Y") -> 50 | I51: =DATEDIF(G51,$D$45,"Y") -> 20 | J51: =DATEDIF(G51,$D$45,"YM") -> 3 | K51: =DATEDIF(G51,$D$45,"MD") -> 26 | L51: 0.30946759 | M51: 0.76178241 | N51: =M51-L51 -> 0.45231481 | O51: =MROUND(N51,"1:00") -> 0.45833333
B52: 5 | C52: ID-CE-005 | D52: REZA TARMOKO | E52: Civil Engineer | F52: 26177 | G52: 33340 | H52: =DATEDIF(F52,$D$45,"Y") -> 53 | I52: =DATEDIF(G52,$D$45,"Y") -> 34 | J52: =DATEDIF(G52,$D$45,"YM") -> 4 | K52: =DATEDIF(G52,$D$45,"MD") -> 5 | L52: 0.37892361 | M52: 0.77350694 | N52: =M52-L52 -> 0.39458333 | O52: =MROUND(N52,"1:00") -> 0.375
B53: 6 | C53: ID-QS-006 | D53: DARGO MAWESTA | E53: Quantity Surveyor | F53: 36187 | G53: 43875 | H53: =DATEDIF(F53,$D$45,"Y") -> 26 | I53: =DATEDIF(G53,$D$45,"Y") -> 5 | J53: =DATEDIF(G53,$D$45,"YM") -> 6 | K53: =DATEDIF(G53,$D$45,"MD") -> 3 | L53: 0.36125 | M53: 0.69458333 | N53: =M53-L53 -> 0.33333333 | O53: =MROUND(N53,"1:00") -> 0.33333333
B54: 7 | C54: ID-PM-007 | D54: TISYA AVENDRA | E54: Project Manager | F54: 34976 | G54: 41975 | H54: =DATEDIF(F54,$D$45,"Y") -> 29 | I54: =DATEDIF(G54,$D$45,"Y") -> 10 | J54: =DATEDIF(G54,$D$45,"YM") -> 8 | K54: =DATEDIF(G54,$D$45,"MD") -> 15 | L54: 0.3737963 | M54: 0.70712963 | N54: =M54-L54 -> 0.33333333 | O54: =MROUND(N54,"1:00") -> 0.33333333
B55: 8 | C55: ID-QS-008 | D55: KARYO LIMANTARA | E55: Quantity Surveyor | F55: 36472 | G55: 45152 | H55: =DATEDIF(F55,$D$45,"Y") -> 25 | I55: =DATEDIF(G55,$D$45,"Y") -> 2 | J55: =DATEDIF(G55,$D$45,"YM") -> 0 | K55: =DATEDIF(G55,$D$45,"MD") -> 3 | L55: 0.39804398 | M55: 0.73137731 | N55: =M55-L55 -> 0.33333333 | O55: =MROUND(N55,"1:00") -> 0.33333333
B56: 9 | C56: ID-PM-009 | D56: JEFRO MALANTARA | E56: Project Manager | F56: 24458 | G56: 34837 | H56: =DATEDIF(F56,$D$45,"Y") -> 58 | I56: =DATEDIF(G56,$D$45,"Y") -> 30 | J56: =DATEDIF(G56,$D$45,"YM") -> 2 | K56: =DATEDIF(G56,$D$45,"MD") -> 30 | L56: 0.3928588 | M56: 0.78831019 | N56: =M56-L56 -> 0.39545139 | O56: =MROUND(N56,"1:00") -> 0.375
B57: 10 | C57: ID-PM-010 | D57: BINAR KENDARTA | E57: Project Manager | F57: 23840 | G57: 30702 | H57: =DATEDIF(F57,$D$45,"Y") -> 60 | I57: =DATEDIF(G57,$D$45,"Y") -> 41 | J57: =DATEDIF(G57,$D$45,"YM") -> 6 | K57: =DATEDIF(G57,$D$45,"MD") -> 27 | L57: 0.41079861 | M57: 0.74413194 | N57: =M57-L57 -> 0.33333333 | O57: =MROUND(N57,"1:00") -> 0.33333333
B58: 11 | C58: ID-CE-011 | D58: CHIKA YURESTA | E58: Civil Engineer | F58: 36610 | G58: 45729 | H58: =DATEDIF(F58,$D$45,"Y") -> 25 | I58: =DATEDIF(G58,$D$45,"Y") -> 0 | J58: =DATEDIF(G58,$D$45,"YM") -> 5 | K58: =DATEDIF(G58,$D$45,"MD") -> 4 | L58: 0.36091435 | M58: 0.78273148 | N58: =M58-L58 -> 0.42181713 | O58: =MROUND(N58,"1:00") -> 0.41666667
B59: 12 | C59: ID-PM-012 | D59: MEI ZHANG | E59: Project Manager | F59: 34278 | G59: 41462 | H59: =DATEDIF(F59,$D$45,"Y") -> 31 | I59: =DATEDIF(G59,$D$45,"Y") -> 12 | J59: =DATEDIF(G59,$D$45,"YM") -> 1 | K59: =DATEDIF(G59,$D$45,"MD") -> 10 | L59: 0.34413194 | M59: 0.77375 | N59: =M59-L59 -> 0.42961806 | O59: =MROUND(N59,"1:00") -> 0.41666667
... B67: 20 | C67: ID-CE-020 | D67: SELVI MAHARENTIYA | E67: Civil Engineer | F67: 36790 | G67: 44992 | H67: =DATEDIF(F67,$D$45,"Y") -> 24 | I67: =DATEDIF(G67,$D$45,"Y") -> 2 | J67: =DATEDIF(G67,$D$45,"YM") -> 5 | K67: =DATEDIF(G67,$D$45,"MD") -> 10 | L67: 0.33103009 | M67: 0.76408565 | N67: =M67-L67 -> 0.43305556 | O67: =MROUND(N67,"1:00") -> 0.41666667
D71: Soal >> | E71: 7 | F71: 8 | G71: 9 | H71: 10 | I71: 11 | J71: 12 | K71: 13 | L71: 14 | M71: 15
B72: NO | C72: TANGGAL MULAI PROYEK | D72: ESTIMASI DURASI PROYEK (Hari Kerja) | E72: HARI MULAI PROYEK | F72: NOMOR MINGGU PROYEK | G72: NOMOR MINGGU PROYEK (Bulan berjalan) | H72: TANGGAL SELESAI PROYEK | I72: TANGGAL INVOICE | J72: STATUS PROYEK | K72: TANGGAL REVIEW PROYEK 1 (Tanggal 1 Bulan Pertama) | L72: TANGGAL REVIEW PROYEK 2 (3 Bulan Setelah Mulai) | M72: TANGGAL REVIEW PROYEK 3 (6 Bulan di akhir bulan)
B73: 1 | C73: 45664 | D73: 86 | E73: =TEXT(C73,"[$-421]dddd") -> Selasa | F73: =WEEKNUM(C73) -> 2 | G73: =WEEKNUM(C73)-WEEKNUM(EOMONTH(C73,-1)+1)+1 -> 2 | H73: =WORKDAY.INTL(C73,D73,11) -> 45764 | I73: =WORKDAY.INTL(EOMONTH(H73,0)+26,-1,11) -> 45801 | J73: =IF(H73<$D$45,"Selesai",IF(C73>$D$45,"Akan Datang","Sedang Berjalan")) -> Selesai | K73: =EOMONTH(C73,0)+1 -> 45689 | L73: =EDATE(C73,3) -> 45754 | M73: =EOMONTH(C73,6) -> 45869
B74: 2 | C74: 45870 | D74: 65 | E74: =TEXT(C74,"[$-421]dddd") -> Jumat | F74: =WEEKNUM(C74) -> 31 | G74: =WEEKNUM(C74)-WEEKNUM(EOMONTH(C74,-1)+1)+1 -> 1 | H74: =WORKDAY.INTL(C74,D74,11) -> 45946 | I74: =WORKDAY.INTL(EOMONTH(H74,0)+26,-1,11) -> 45986 | J74: =IF(H74<$D$45,"Selesai",IF(C74>$D$45,"Akan Datang","Sedang Berjalan")) -> Sedang Berjalan | K74: =EOMONTH(C74,0)+1 -> 45901 | L74: =EDATE(C74,3) -> 45962 | M74: =EOMONTH(C74,6) -> 46081
B75: 3 | C75: 46365 | D75: 51 | E75: =TEXT(C75,"[$-421]dddd") -> Rabu | F75: =WEEKNUM(C75) -> 50 | G75: =WEEKNUM(C75)-WEEKNUM(EOMONTH(C75,-1)+1)+1 -> 2 | H75: =WORKDAY.INTL(C75,D75,11) -> 46424 | I75: =WORKDAY.INTL(EOMONTH(H75,0)+26,-1,11) -> 46471 | J75: =IF(H75<$D$45,"Selesai",IF(C75>$D$45,"Akan Datang","Sedang Berjalan")) -> Akan Datang | K75: =EOMONTH(C75,0)+1 -> 46388 | L75: =EDATE(C75,3) -> 46455 | M75: =EOMONTH(C75,6) -> 46568
B76: 4 | C76: 45709 | D76: 34 | E76: =TEXT(C76,"[$-421]dddd") -> Jumat | F76: =WEEKNUM(C76) -> 8 | G76: =WEEKNUM(C76)-WEEKNUM(EOMONTH(C76,-1)+1)+1 -> 4 | H76: =WORKDAY.INTL(C76,D76,11) -> 45749 | I76: =WORKDAY.INTL(EOMONTH(H76,0)+26,-1,11) -> 45801 | J76: =IF(H76<$D$45,"Selesai",IF(C76>$D$45,"Akan Datang","Sedang Berjalan")) -> Selesai | K76: =EOMONTH(C76,0)+1 -> 45717 | L76: =EDATE(C76,3) -> 45798 | M76: =EOMONTH(C76,6) -> 45900
B77: 5 | C77: 46013 | D77: 16 | E77: =TEXT(C77,"[$-421]dddd") -> Senin | F77: =WEEKNUM(C77) -> 52 | G77: =WEEKNUM(C77)-WEEKNUM(EOMONTH(C77,-1)+1)+1 -> 4 | H77: =WORKDAY.INTL(C77,D77,11) -> 46031 | I77: =WORKDAY.INTL(EOMONTH(H77,0)+26,-1,11) -> 46078 | J77: =IF(H77<$D$45,"Selesai",IF(C77>$D$45,"Akan Datang","Sedang Berjalan")) -> Akan Datang | K77: =EOMONTH(C77,0)+1 -> 46023 | L77: =EDATE(C77,3) -> 46103 | M77: =EOMONTH(C77,6) -> 46203
B78: 6 | C78: 45863 | D78: 32 | E78: =TEXT(C78,"[$-421]dddd") -> Jumat | F78: =WEEKNUM(C78) -> 30 | G78: =WEEKNUM(C78)-WEEKNUM(EOMONTH(C78,-1)+1)+1 -> 4 | H78: =WORKDAY.INTL(C78,D78,11) -> 45901 | I78: =WORKDAY.INTL(EOMONTH(H78,0)+26,-1,11) -> 45955 | J78: =IF(H78<$D$45,"Selesai",IF(C78>$D$45,"Akan Datang","Sedang Berjalan")) -> Sedang Berjalan | K78: =EOMONTH(C78,0)+1 -> 45870 | L78: =EDATE(C78,3) -> 45955 | M78: =EOMONTH(C78,6) -> 46053
...

Sheet About
I6: XL-TEST adalah platform inovatif yang menyediakan latihan Excel interaktif dengan pemeriksaan otomatis,
I7: sehingga pengguna dapat langsung mengetahui jawaban yang benar maupun salah.
I10: Terdapat 5 Level soal :
J12: Easy Level | L12: (⭐)
J13: Medium Level | L13: (⭐⭐)
J14: Hard Level | L14: (⭐⭐⭐)
J15: Extreme Level | L15: (⭐⭐⭐⭐)
J16: Championship Level | L16: (⭐⭐⭐⭐⭐)
B17: Saya adalah seorang Excel Holic yang percaya bahwa setiap angka memiliki cerita yang bisa ditemukan dengan cara yang tepat. | I17: Free Access
B18: “Excel bukan cuma soal kerjaan tapi juga hobi yang aku nikmati.” | I18: https://belajarexcel.id/xl-test/
B19: Contact :
B20: 🌐 Web | C20: https://setiadi.me
B21: 🪡threads | C21: https://www.threads.com/@andisetiadi
D27: Perlu Video Penjelasan atau Kunci Jawaban ?
D28: Scan barcode atau kunjungi
D29: https://lynk.id/setiadi/page/jawaban-xl-test

Sheet DF
A1: DEF | C1: 1 | D1: 2 | E1: 3 | F1: 4 | G1: 5 | H1: 6 | I1: 7 | J1: 8 | K1: 9 | L1: 10 | M1: 11 | N1: 12 | O1: 13 | P1: 14 | Q1: 15
A2: MH2 | B2: 1 | C2: ='XL-Test'!H48 -> 45 | D2: ='XL-Test'!I48 -> 27 | E2: ='XL-Test'!J48 -> 1 | F2: ='XL-Test'!K48 -> 24 | G2: ='XL-Test'!N48 -> 0.39886574 | H2: ='XL-Test'!O48 -> 0.41666667 | I2: ='XL-Test'!E73 -> Selasa | J2: ='XL-Test'!F73 -> 2 | K2: ='XL-Test'!G73 -> 2 | L2: ='XL-Test'!H73 -> 45764 | M2: ='XL-Test'!I73 -> 45801 | N2: ='XL-Test'!J73 -> Selesai | O2: ='XL-Test'!K73 -> 45689 | P2: ='XL-Test'!L73 -> 45754 | Q2: ='XL-Test'!M73 -> 45869
B3: 2 | C3: ='XL-Test'!H49 -> 25 | D3: ='XL-Test'!I49 -> 1 | E3: ='XL-Test'!J49 -> 3 | F3: ='XL-Test'!K49 -> 0 | G3: ='XL-Test'!N49 -> 0.34475694 | H3: ='XL-Test'!O49 -> 0.33333333 | I3: ='XL-Test'!E74 -> Jumat | J3: ='XL-Test'!F74 -> 31 | K3: ='XL-Test'!G74 -> 1 | L3: ='XL-Test'!H74 -> 45946 | M3: ='XL-Test'!I74 -> 45986 | N3: ='XL-Test'!J74 -> Sedang Berjalan | O3: ='XL-Test'!K74 -> 45901 | P3: ='XL-Test'!L74 -> 45962 | Q3: ='XL-Test'!M74 -> 46081
B4: 3 | C4: ='XL-Test'!H50 -> 47 | D4: ='XL-Test'!I50 -> 20 | E4: ='XL-Test'!J50 -> 11 | F4: ='XL-Test'!K50 -> 8 | G4: ='XL-Test'!N50 -> 0.33333333 | H4: ='XL-Test'!O50 -> 0.33333333 | I4: ='XL-Test'!E75 -> Rabu | J4: ='XL-Test'!F75 -> 50 | K4: ='XL-Test'!G75 -> 2 | L4: ='XL-Test'!H75 -> 46424 | M4: ='XL-Test'!I75 -> 46471 | N4: ='XL-Test'!J75 -> Akan Datang | O4: ='XL-Test'!K75 -> 46388 | P4: ='XL-Test'!L75 -> 46455 | Q4: ='XL-Test'!M75 -> 46568
B5: 4 | C5: ='XL-Test'!H51 -> 50 | D5: ='XL-Test'!I51 -> 20 | E5: ='XL-Test'!J51 -> 3 | F5: ='XL-Test'!K51 -> 26 | G5: ='XL-Test'!N51 -> 0.45231481 | H5: ='XL-Test'!O51 -> 0.45833333 | I5: ='XL-Test'!E76 -> Jumat | J5: ='XL-Test'!F76 -> 8 | K5: ='XL-Test'!G76 -> 4 | L5: ='XL-Test'!H76 -> 45749 | M5: ='XL-Test'!I76 -> 45801 | N5: ='XL-Test'!J76 -> Selesai | O5: ='XL-Test'!K76 -> 45717 | P5: ='XL-Test'!L76 -> 45798 | Q5: ='XL-Test'!M76 -> 45900
B6: 5 | C6: ='XL-Test'!H52 -> 53 | D6: ='XL-Test'!I52 -> 34 | E6: ='XL-Test'!J52 -> 4 | F6: ='XL-Test'!K52 -> 5 | G6: ='XL-Test'!N52 -> 0.39458333 | H6: ='XL-Test'!O52 -> 0.375 | I6: ='XL-Test'!E77 -> Senin | J6: ='XL-Test'!F77 -> 52 | K6: ='XL-Test'!G77 -> 4 | L6: ='XL-Test'!H77 -> 46031 | M6: ='XL-Test'!I77 -> 46078 | N6: ='XL-Test'!J77 -> Akan Datang | O6: ='XL-Test'!K77 -> 46023 | P6: ='XL-Test'!L77 -> 46103 | Q6: ='XL-Test'!M77 -> 46203
B7: 6 | C7: ='XL-Test'!H53 -> 26 | D7: ='XL-Test'!I53 -> 5 | E7: ='XL-Test'!J53 -> 6 | F7: ='XL-Test'!K53 -> 3 | G7: ='XL-Test'!N53 -> 0.33333333 | H7: ='XL-Test'!O53 -> 0.33333333 | I7: ='XL-Test'!E78 -> Jumat | J7: ='XL-Test'!F78 -> 30 | K7: ='XL-Test'!G78 -> 4 | L7: ='XL-Test'!H78 -> 45901 | M7: ='XL-Test'!I78 -> 45955 | N7: ='XL-Test'!J78 -> Sedang Berjalan | O7: ='XL-Test'!K78 -> 45870 | P7: ='XL-Test'!L78 -> 45955 | Q7: ='XL-Test'!M78 -> 46053
B8: 7 | C8: ='XL-Test'!H54 -> 29 | D8: ='XL-Test'!I54 -> 10 | E8: ='XL-Test'!J54 -> 8 | F8: ='XL-Test'!K54 -> 15 | G8: ='XL-Test'!N54 -> 0.33333333 | H8: ='XL-Test'!O54 -> 0.33333333 | I8: ='XL-Test'!E79 -> Jumat | J8: ='XL-Test'!F79 -> 9 | K8: ='XL-Test'!G79 -> 4 | L8: ='XL-Test'!H79 -> 46153 | M8: ='XL-Test'!I79 -> 46198 | N8: ='XL-Test'!J79 -> Akan Datang | O8: ='XL-Test'!K79 -> 46082 | P8: ='XL-Test'!L79 -> 46169 | Q8: ='XL-Test'!M79 -> 46265
B9: 8 | C9: ='XL-Test'!H55 -> 25 | D9: ='XL-Test'!I55 -> 2 | E9: ='XL-Test'!J55 -> 0 | F9: ='XL-Test'!K55 -> 3 | G9: ='XL-Test'!N55 -> 0.33333333 | H9: ='XL-Test'!O55 -> 0.33333333 | I9: ='XL-Test'!E80 -> Senin | J9: ='XL-Test'!F80 -> 12 | K9: ='XL-Test'!G80 -> 3 | L9: ='XL-Test'!H80 -> 46136 | M9: ='XL-Test'!I80 -> 46167 | N9: ='XL-Test'!J80 -> Akan Datang | O9: ='XL-Test'!K80 -> 46113 | P9: ='XL-Test'!L80 -> 46189 | Q9: ='XL-Test'!M80 -> 46295
B10: 9 | C10: ='XL-Test'!H56 -> 58 | D10: ='XL-Test'!I56 -> 30 | E10: ='XL-Test'!J56 -> 2 | F10: ='XL-Test'!K56 -> 30 | G10: ='XL-Test'!N56 -> 0.39545139 | H10: ='XL-Test'!O56 -> 0.375 | I10: ='XL-Test'!E81 -> Rabu | J10: ='XL-Test'!F81 -> 22 | K10: ='XL-Test'!G81 -> 5 | L10: ='XL-Test'!H81 -> 45852 | M10: ='XL-Test'!I81 -> 45894 | N10: ='XL-Test'!J81 -> Selesai | O10: ='XL-Test'!K81 -> 45809 | P10: ='XL-Test'!L81 -> 45897 | Q10: ='XL-Test'!M81 -> 45991
B11: 10 | C11: ='XL-Test'!H57 -> 60 | D11: ='XL-Test'!I57 -> 41 | E11: ='XL-Test'!J57 -> 6 | F11: ='XL-Test'!K57 -> 27 | G11: ='XL-Test'!N57 -> 0.33333333 | H11: ='XL-Test'!O57 -> 0.33333333 | I11: ='XL-Test'!E82 -> Kamis | J11: ='XL-Test'!F82 -> 40 | K11: ='XL-Test'!G82 -> 1 | L11: ='XL-Test'!H82 -> 46310 | M11: ='XL-Test'!I82 -> 46351 | N11: ='XL-Test'!J82 -> Akan Datang | O11: ='XL-Test'!K82 -> 46327 | P11: ='XL-Test'!L82 -> 46388 | Q11: ='XL-Test'!M82 -> 46507
B12: 11 | C12: ='XL-Test'!H58 -> 25 | D12: ='XL-Test'!I58 -> 0 | E12: ='XL-Test'!J58 -> 5 | F12: ='XL-Test'!K58 -> 4 | G12: ='XL-Test'!N58 -> 0.42181713 | H12: ='XL-Test'!O58 -> 0.41666667 | I12: ='XL-Test'!E83 -> Kamis | J12: ='XL-Test'!F83 -> 32 | K12: ='XL-Test'!G83 -> 2 | L12: ='XL-Test'!H83 -> 45930 | M12: ='XL-Test'!I83 -> 45955 | N12: ='XL-Test'!J83 -> Sedang Berjalan | O12: ='XL-Test'!K83 -> 45901 | P12: ='XL-Test'!L83 -> 45968 | Q12: ='XL-Test'!M83 -> 46081
B13: 12 | C13: ='XL-Test'!H59 -> 31 | D13: ='XL-Test'!I59 -> 12 | E13: ='XL-Test'!J59 -> 1 | F13: ='XL-Test'!K59 -> 10 | G13: ='XL-Test'!N59 -> 0.42961806 | H13: ='XL-Test'!O59 -> 0.41666667 | I13: ='XL-Test'!E84 -> Selasa | J13: ='XL-Test'!F84 -> 51 | K13: ='XL-Test'!G84 -> 3 | L13: ='XL-Test'!H84 -> 46416 | M13: ='XL-Test'!I84 -> 46443 | N13: ='XL-Test'!J84 -> Akan Datang | O13: ='XL-Test'!K84 -> 46388 | P13: ='XL-Test'!L84 -> 46461 | Q13: ='XL-Test'!M84 -> 46568
B14: 13 | C14: ='XL-Test'!H60 -> 37 | D14: ='XL-Test'!I60 -> 11 | E14: ='XL-Test'!J60 -> 1 | F14: ='XL-Test'!K60 -> 9 | G14: ='XL-Test'!N60 -> 0.39797454 | H14: ='XL-Test'!O60 -> 0.41666667 | I14: ='XL-Test'!E85 -> Jumat | J14: ='XL-Test'!F85 -> 1 | K14: ='XL-Test'!G85 -> 1 | L14: ='XL-Test'!H85 -> 46062 | M14: ='XL-Test'!I85 -> 46106 | N14: ='XL-Test'!J85 -> Akan Datang | O14: ='XL-Test'!K85 -> 46054 | P14: ='XL-Test'!L85 -> 46114 | Q14: ='XL-Test'!M85 -> 46234
... B21: 20 | C21: ='XL-Test'!H67 -> 24 | D21: ='XL-Test'!I67 -> 2 | E21: ='XL-Test'!J67 -> 5 | F21: ='XL-Test'!K67 -> 10 | G21: ='XL-Test'!N67 -> 0.43305556 | H21: ='XL-Test'!O67 -> 0.41666667 | I21: ='XL-Test'!E92 -> Jumat | J21: ='XL-Test'!F92 -> 12 | K21: ='XL-Test'!G92 -> 4 | L21: ='XL-Test'!H92 -> 45817 | M21: ='XL-Test'!I92 -> 45863 | N21: ='XL-Test'!J92 -> Selesai | O21: ='XL-Test'!K92 -> 45748 | P21: ='XL-Test'!L92 -> 45829 | Q21: ='XL-Test'!M92 -> 45930
B23: SUM | C23: =SUM(C2:C21)+C3+C6+C9+C12+C16+C19+C21 -> 1046 | D23: =SUM(D2:D21)+D3+D6+D9+D12+D16+D19+D21 -> 418 | E23: =SUM(E2:E21)+E3+E6+E9+E12+E16+E19+E21 -> 114 | F23: =SUM(F2:F21)+F3+F6+F9+F12+F16+F19+F21 -> 291 | G23: =SUM(G2:G21)+G3+G6+G9+G12+G16+G19+G21 -> 10.077153 | H23: =SUM(H2:H21)+H3+H6+H9+H12+H16+H19+H21 -> 9.9166667 | I23: =CODE(LEFT(I2))+CODE(LEFT(I3))+CODE(LEFT(I4))+CODE(LEFT(I5))+CODE(LEFT(I6))+CODE(LEFT(I7))+CODE(LEFT(I8))+CODE(LEFT(I9))+CODE(LEFT(I10))+CODE(LEFT(I11))+CODE(LEFT(I12))+CODE(LEFT(I13))+CODE(LEFT(I14))+CODE(LEFT(I15))+CODE(LEFT(I16))+CODE(LEFT(I17))+CODE(LEFT(I18))+CODE(LEFT(I19))+CODE(LEFT(I20))+CODE(LEFT(I21))+ CODE(RIGHT(I2))+CODE(RIGHT(I3))+CODE(RIGHT(I4))+CODE(RIGHT(I5))+CODE(RIGHT(I6))+CODE(RIGHT(I7))+CODE(RIGHT(I8))+CODE(RIGHT(I9))+CODE(RIGHT(I10))+CODE(RIGHT(I11))+CODE(RIGHT(I12))+CODE(RIGHT(I13))+CODE(RIGHT(I14))+CODE(RIGHT(I15))+CODE(RIGHT(I16))+CODE(RIGHT(I17))+CODE(RIGHT(I18))+CODE(RIGHT(I19))+CODE(RIGHT(I20))+CODE(RIGHT(I21))+CODE(MID(I3,4,1))+CODE(MID(I5,4,1))+CODE(MID(I3,4,1))+CODE(MID(I21,4,1))+CODE(MID(I13,4,1)) -> 4298 | J23: =SUM(J2:J21)+J3+J6+J9+J12+J16+J19+J21 -> 751 | K23: =SUM(K2:K21)+K3+K6+K9+K12+K16+K19+K21 -> 76 | L23: =SUM(L2:L21)+L3+L6+L9+L12+L16+L19+L21 -> 1244124 | M23: =SUM(M2:M21)+M3+M6+M9+M12+M16+M19+M21 -> 1245195 | N23: =CODE(LEFT(N2))+CODE(LEFT(N3))+CODE(LEFT(N4))+CODE(LEFT(N5))+CODE(LEFT(N6))+CODE(LEFT(N7))+CODE(LEFT(N8))+CODE(LEFT(N9))+CODE(LEFT(N10))+CODE(LEFT(N11))+CODE(LEFT(N12))+CODE(LEFT(N13))+CODE(LEFT(N14))+CODE(LEFT(N15))+CODE(LEFT(N16))+CODE(LEFT(N17))+CODE(LEFT(N18))+CODE(LEFT(N19))+CODE(LEFT(N20))+CODE(LEFT(N21))+ CODE(RIGHT(N2))+CODE(RIGHT(N3))+CODE(RIGHT(N4))+CODE(RIGHT(N5))+CODE(RIGHT(N6))+CODE(RIGHT(N7))+CODE(RIGHT(N8))+CODE(RIGHT(N9))+CODE(RIGHT(N10))+CODE(RIGHT(N11))+CODE(RIGHT(N12))+CODE(RIGHT(N13))+CODE(RIGHT(N14))+CODE(RIGHT(N15))+CODE(RIGHT(N16))+CODE(RIGHT(N17))+CODE(RIGHT(N18))+CODE(RIGHT(N19))+CODE(RIGHT(N20))+CODE(RIGHT(N21))+CODE(MID(N3,4,1))+CODE(MID(N5,4,1))+CODE(MID(N3,4,1))+CODE(MID(N21,4,1))+CODE(MID(N13,4,1)) -> 4061 | O23: =SUM(O2:O21)+O3+O6+O9+O12+O16+O19+O21 -> 1243064 | P23: =SUM(P2:P21)+P3+P6+P9+P12+P16+P19+P21 -> 1245035 | Q23: =SUM(Q2:Q21)+Q3+Q6+Q9+Q12+Q16+Q19+Q21 -> 1247946
B24: rand | C24: 7923 | D24: 3272 | E24: 4937 | F24: 8725 | G24: 8115 | H24: 8614 | I24: 2951 | J24: 6949 | K24: 8517 | L24: 3419 | M24: 7646 | N24: 4352 | O24: 8066 | P24: 4154 | Q24: 9148
B25: Cek Manual | C25: =AND(ISNUMBER(FIND("(",C40)),ISNUMBER(FIND("D",C40))) -> TRUE | D25: =AND(ISNUMBER(FIND("(",D40)),ISNUMBER(FIND("D",D40))) -> TRUE | E25: =AND(ISNUMBER(FIND("(",E40)),ISNUMBER(FIND("D",E40))) -> TRUE | F25: =AND(ISNUMBER(FIND("(",F40)),ISNUMBER(FIND("D",F40))) -> TRUE | G25: =AND(ISNUMBER(FIND("-",G40)),ISNUMBER(FIND("=",G40))) -> TRUE | H25: =AND(ISNUMBER(FIND("(",H40)),ISNUMBER(FIND("=",H40))) -> TRUE | I25: =AND(ISNUMBER(FIND("(",I40)),ISNUMBER(FIND("=",I40))) -> TRUE | J25: =AND(ISNUMBER(FIND("(",J40)),ISNUMBER(FIND("=",J40))) -> TRUE | K25: =AND(ISNUMBER(FIND("(",K40)),ISNUMBER(FIND("=",K40))) -> TRUE | L25: =AND(ISNUMBER(FIND("(",L40)),ISNUMBER(FIND("=",L40))) -> TRUE | M25: =AND(ISNUMBER(FIND("(",M40)),ISNUMBER(FIND("=",M40))) -> TRUE | N25: =AND(ISNUMBER(FIND("(",N40)),ISNUMBER(FIND("=",N40))) -> TRUE | O25: =AND(ISNUMBER(FIND("(",O40)),ISNUMBER(FIND("=",O40))) -> TRUE | ... Q25: =AND(ISNUMBER(FIND("(",Q40)),ISNUMBER(FIND("=",Q40))) -> TRUE
B26: cek kosong | C26: =NOT(OR(C2="",C2=0)) -> TRUE | D26: =NOT(OR(D2="",D2=0)) -> TRUE | E26: =NOT(OR(E2="",E2=0)) -> TRUE | F26: =NOT(OR(F2="",F2=0)) -> TRUE | G26: =NOT(OR(G2="",G2=0)) -> TRUE | H26: =NOT(OR(H2="",H2=0)) -> TRUE | I26: =NOT(OR(I2="",I2=0)) -> TRUE | J26: =NOT(OR(J2="",J2=0)) -> TRUE | ... Q26: =NOT(OR(Q2="",Q2=0)) -> TRUE
B27: Cek konsi | C27: =C90 -> TRUE | D27: =D90 -> TRUE | E27: =E90 -> TRUE | F27: =F90 -> TRUE | G27: =G90 -> TRUE | H27: =H90 -> TRUE | I27: =I90 -> TRUE | J27: =J90 -> TRUE | ... Q27: =Q90 -> TRUE
B28: Value | C28: =IFERROR(DEC2HEX(IF(AND(C25:C27),C23,C24)),"eee") -> 416 | D28: =IFERROR(DEC2HEX(IF(AND(D25:D27),D23,D24)),"eee") -> 1A2 | E28: =IFERROR(DEC2HEX(IF(AND(E25:E27),E23,E24)),"eee") -> 72 | F28: =IFERROR(DEC2HEX(IF(AND(F25:F27),F23,F24)),"eee") -> 123 | G28: =IFERROR(DEC2HEX(IF(AND(G25:G27),G23,G24)),"eee") -> A | H28: =IFERROR(DEC2HEX(IF(AND(H25:H27),H23,H24)),"eee") -> 9 | I28: =IFERROR(DEC2HEX(IF(AND(I25:I27),I23,I24)),"eee") -> 10CA | J28: =IFERROR(DEC2HEX(IF(AND(J25:J27),J23,J24)),"eee") -> 2EF | ... Q28: =IFERROR(DEC2HEX(IF(AND(Q25:Q27),Q23,Q24)),"eee") -> 130ACA
B30: TRUE | C30: =DEC2HEX(LEFT(C24,2)+COLUMN()) -> 52 | D30: =DEC2HEX(LEFT(D24,2)+COLUMN()) -> 24 | E30: =DEC2HEX(LEFT(E24,2)+COLUMN()) -> 36 | F30: =DEC2HEX(LEFT(F24,2)+COLUMN()) -> 5D | G30: =DEC2HEX(LEFT(G24,2)+COLUMN()) -> 58 | H30: =DEC2HEX(LEFT(H24,2)+COLUMN()) -> 5E | I30: =DEC2HEX(LEFT(I24,2)+COLUMN()) -> 26 | J30: =DEC2HEX(LEFT(J24,2)+COLUMN()) -> 4F | ... Q30: =DEC2HEX(LEFT(Q24,2)+COLUMN()) -> 6C
B31: FALSE | C31: =DEC2HEX(RIGHT(C24,2)+COLUMN()) -> 1A | D31: =DEC2HEX(RIGHT(D24,2)+COLUMN()) -> 4C | E31: =DEC2HEX(RIGHT(E24,2)+COLUMN()) -> 2A | F31: =DEC2HEX(RIGHT(F24,2)+COLUMN()) -> 1F | G31: =DEC2HEX(RIGHT(G24,2)+COLUMN()) -> 16 | H31: =DEC2HEX(RIGHT(H24,2)+COLUMN()) -> 16 | I31: =DEC2HEX(RIGHT(I24,2)+COLUMN()) -> 3C | J31: =DEC2HEX(RIGHT(J24,2)+COLUMN()) -> 3B | ... Q31: =DEC2HEX(RIGHT(Q24,2)+COLUMN()) -> 41
B33: Cek Rumus | C33: =AND(ISNUMBER(FIND("DIF",C40)),ISNUMBER(FIND("Y",C40))) -> TRUE | D33: =AND(ISNUMBER(FIND("DIF",D40)),ISNUMBER(FIND("Y",D40))) -> TRUE | E33: =AND(ISNUMBER(FIND("DIF",E40)),ISNUMBER(FIND("YM",E40))) -> TRUE | F33: =AND(ISNUMBER(FIND("DIF",F40)),ISNUMBER(FIND("MD",F40))) -> TRUE | G33: =ISNUMBER(FIND("-",G40)) -> TRUE | H33: =ISNUMBER(FIND("MRO",H40)) -> TRUE | I33: =ISNUMBER(FIND("EXT",I40)) -> TRUE | J33: =ISNUMBER(FIND("KNUM",J40)) -> TRUE | K33: =AND(ISNUMBER(FIND("KNUM",K40)),ISNUMBER(FIND("OMO",K40))) -> TRUE | L33: =ISNUMBER(FIND("RKDA",L40)) -> TRUE | M33: =AND(ISNUMBER(FIND("RKDA",M40)),ISNUMBER(FIND("OMO",M40))) -> TRUE | N33: =OR(ISNUMBER(FIND("IF",N40)),ISNUMBER(FIND("SWI",N40))) -> TRUE | O33: =ISNUMBER(FIND("OMO",O40)) -> TRUE | P33: =ISNUMBER(FIND("EDA",P40)) -> TRUE | Q33: =ISNUMBER(FIND("OMO",Q40)) -> TRUE
B34: cek jml | C34: =C61 -> TRUE | D34: =D61 -> TRUE | E34: =E61 -> TRUE | F34: =F61 -> TRUE | G34: =G61 -> TRUE | H34: =H61 -> TRUE | I34: =I61 -> TRUE | J34: =J61 -> TRUE | ... Q34: =Q61 -> TRUE
B35: Formula | C35: =IF(AND(C33,C34),C30,C31)&"-"&C28&";" -> 52-416; | D35: =IF(AND(D33,D34),D30,D31)&"-"&D28&";" -> 24-1A2; | E35: =IF(AND(E33,E34),E30,E31)&"-"&E28&";" -> 36-72; | F35: =IF(AND(F33,F34),F30,F31)&"-"&F28&";" -> 5D-123; | G35: =IF(AND(G33,G34),G30,G31)&"-"&G28&";" -> 58-A; | H35: =IF(AND(H33,H34),H30,H31)&"-"&H28&";" -> 5E-9; | I35: =IF(AND(I33,I34),I30,I31)&"-"&I28&";" -> 26-10CA; | J35: =IF(AND(J33,J34),J30,J31)&"-"&J28&";" -> 4F-2EF; | ... P35: =IF(AND(P33,P34),P30,P31)&"-"&P28&";" -> 39-12FF6B; | Q35: =IF(AND(Q33,Q34),Q30,Q31)&"-"&Q28 -> 6C-130ACA
C37: =A2&"|"&C35&D35&E35&F35&G35&H35&I35&J35&K35&L35&M35&N35&O35&P35&Q35 -> MH2|52-416;24-1A2;36-72;5D-123;58-A;5E-9;26-10CA;4F-2EF;60-4C;2E-12FBDC;59-13000B;39-FDD;5F-12F7B8;39-12FF6B;6C-130ACA
C40: =SUBSTITUTE(C41,"$","") -> =DATEDIF(F48;D45;"Y") | D40: =SUBSTITUTE(D41,"$","") -> =DATEDIF(G48;D45;"Y") | E40: =SUBSTITUTE(E41,"$","") -> =DATEDIF(G48;D45;"YM") | F40: =SUBSTITUTE(F41,"$","") -> =DATEDIF(G48;D45;"MD") | G40: =SUBSTITUTE(G41,"$","") -> =M48-L48 | H40: =SUBSTITUTE(H41,"$","") -> =MROUND(N48;"1:00") | I40: =SUBSTITUTE(I41,"$","") -> =TEXT(C73;"[-421]dddd") | J40: =SUBSTITUTE(J41,"$","") -> =WEEKNUM(C73) | ... Q40: =SUBSTITUTE(Q41,"$","") -> =EOMONTH(C73;6)
C41: {=_xlfn.FORMULATEXT(INDIRECT(MID(_xlfn.FORMULATEXT(C2),2,300)))} -> =DATEDIF(F48;$D$45;"Y") | D41: {=_xlfn.FORMULATEXT(INDIRECT(MID(_xlfn.FORMULATEXT(D2),2,300)))} -> =DATEDIF(G48;$D$45;"Y") | E41: {=_xlfn.FORMULATEXT(INDIRECT(MID(_xlfn.FORMULATEXT(E2),2,300)))} -> =DATEDIF(G48;$D$45;"YM") | F41: {=_xlfn.FORMULATEXT(INDIRECT(MID(_xlfn.FORMULATEXT(F2),2,300)))} -> =DATEDIF(G48;$D$45;"MD") | G41: {=_xlfn.FORMULATEXT(INDIRECT(MID(_xlfn.FORMULATEXT(G2),2,300)))} -> =M48-L48 | H41: {=_xlfn.FORMULATEXT(INDIRECT(MID(_xlfn.FORMULATEXT(H2),2,300)))} -> =MROUND(N48;"1:00") | I41: {=_xlfn.FORMULATEXT(INDIRECT(MID(_xlfn.FORMULATEXT(I2),2,300)))} -> =TEXT(C73;"[$-421]dddd") | J41: {=_xlfn.FORMULATEXT(INDIRECT(MID(_xlfn.FORMULATEXT(J2),2,300)))} -> =WEEKNUM(C73) | ... Q41: {=_xlfn.FORMULATEXT(INDIRECT(MID(_xlfn.FORMULATEXT(Q2),2,300)))} -> =EOMONTH(C73;6)
D43: =D41 -> =DATEDIF(G48;$D$45;"Y") | K43: =K41 -> =WEEKNUM(C73)-WEEKNUM(EOMONTH(C73;-1)+1)+1
E45: =E41 -> =DATEDIF(G48;$D$45;"YM") | L45: =L41 -> =WORKDAY.INTL(C73;D73;11)
C46: =C41 -> =DATEDIF(F48;$D$45;"Y")
F47: =F41 -> =DATEDIF(G48;$D$45;"MD") | M47: =M41 -> =WORKDAY.INTL(EOMONTH(H73;0)+26;-1;11)
G49: =G41 -> =M48-L48 | N49: =N41 -> =IF(H73<$D$45;"Selesai";IF(C73>$D$45;"Akan Datang";"Sedang Berjalan"))
H51: =H41 -> =MROUND(N48;"1:00") | O51: =O41 -> =EOMONTH(C73;0)+1
I53: =I41 -> =TEXT(C73;"[$-421]dddd") | P53: =P41 -> =EDATE(C73;3)
J55: =J41 -> =WEEKNUM(C73) | Q55: =Q41 -> =EOMONTH(C73;6)
B59: Cek Fungsi | C59: =IFERROR(LEN(C40)-LEN(SUBSTITUTE(C40,"(","")),99) -> 1 | D59: =IFERROR(LEN(D40)-LEN(SUBSTITUTE(D40,"(","")),99) -> 1 | E59: =IFERROR(LEN(E40)-LEN(SUBSTITUTE(E40,"(","")),99) -> 1 | F59: =IFERROR(LEN(F40)-LEN(SUBSTITUTE(F40,"(","")),99) -> 1 | G59: =IFERROR(LEN(G40)-LEN(SUBSTITUTE(G40,"(","")),99) -> 0 | H59: =IFERROR(LEN(H40)-LEN(SUBSTITUTE(H40,"(","")),99) -> 1 | I59: =IFERROR(LEN(I40)-LEN(SUBSTITUTE(I40,"(","")),99) -> 1 | J59: =IFERROR(LEN(J40)-LEN(SUBSTITUTE(J40,"(","")),99) -> 1 | ... Q59: =IFERROR(LEN(Q40)-LEN(SUBSTITUTE(Q40,"(","")),99) -> 1
C60: 1 | D60: 1 | E60: 1 | F60: 1 | G60: 1 | H60: 1 | I60: 1 | J60: 1 | K60: 3 | L60: 1 | M60: 2 | N60: 2 | O60: 1 | P60: 1 | Q60: 1
C61: =C59<=C60 -> TRUE | D61: =D59<=D60 -> TRUE | E61: =E59<=E60 -> TRUE | F61: =F59<=F60 -> TRUE | G61: =G59<=G60 -> TRUE | H61: =H59<=H60 -> TRUE | I61: =I59<=I60 -> TRUE | J61: =J59<=J60 -> TRUE | ... Q61: =Q59<=Q60 -> TRUE
...
