Workbook
Name Kode_jawaban: DF!$C$60
Name saya: DF!$C$56

Sheet Case
A17: KODE SOAL | C17: SBEM002 | E17: KODE JAWABAN | G17: =Kode_jawaban -> MB2|61-1184;66-B2282;51-407;5B-181D;41-1656;63-664B8;27-73A0;36-5F118;45-AAC50;37-9D1;4B-5C2;53-80F7A
A19: Intruksi
B21: Medium Level - Latihan Soal Excel Admin Toko Roti
B23: Soal : | C23: Gunakan Fungsi Excel (Function) untuk menyelsaikan kasus dibawah ini, tidak disarankan menggunakan cara manual
B24: 1 | C24: Isi kolom pembeli dengan MA= Mahasiswa, UM=Umum atau PE=Pelajar Berdasarkan Kode VOUCHER Hurup 1 dan 2
B25: 2 | C25: Isi Tanggal VOUCHER berdasarkan Kode VOUCHER dari Hurup ke 7 sampai hurup Akhir
B26: 3 | C26: Isi Lama Tukar VOUCHER dari tanggal VOUCHER hingga VOUCHER tersebut di digunakan (Beli)
B27: 4 | C27: Isi Rasa Berdasarkan KODE VOUCHER hurup ke 5, dari tabel acuan Table.2
B28: 5 | C28: Isi Jenis Roti Berdasarkan KODE VOUCHER hurup ke 3, Jika T = Tawar, G = Gandum dan B = Bakar
B29: 6 | C29: Isi Harga Roti sesuai dengan Table.1
B30: 7 | C30: Isi Diskon sesuai dengan Table.2 diskon didapatkan dari Harga Roti
B31: 8 | C31: Isi Total Bayar dari Harga roti dikurangi Diskon
B32: 9 | C32: Isi Jumlah Total, Total Bayar Tertingi, Terendah dan juga Total Bayar Rata-rata
B33: 10 | C33: Isi rata-rata lama penggunaan Voucher Berdasarkan rasa roti
B34: 11 | C34: Isi banyak roti terjual berdasarkan rasa roti
B35: 12 | C35: Isi Jumlah Total bayar sesuai dengan rasa roti
C37: Sudah selesai mengerjakan? kirim Kode Soal dan Kode Jawaban diatas ke alamat : https://belajarexcel.id/xl-test/jawaban untuk mengecek hasilnya
C38: atau klik tombol disamping
D43: 1 | E43: 2 | G43: 3 | H43: 4 | I43: 5 | J43: 6 | K43: 7 | L43: 8
A44: NO | B44: NAMA PELANGGAN | C44: KODE | D44: GOLONGAN | E44: TANGGAL | F44: TANGGAL | G44: LAMA TUKAR | H44: RASA | I44: JENIS ROTI | J44: HARGA ROTI | K44: DISKON | L44: TOTAL BAYAR
C45: VOUCHER | D45: PEMBELI | E45: VOUCHER | F45: BELI | G45: VOUCHER
A46: 1 | B46: Donny Donna | C46: MAT/1/01/11/24 | D46: =IF(LEFT(C46,2)="MA","MAHASISWA",IF(LEFT(C46,2)="PE","PELAJAR","UMUM")) -> MAHASISWA | E46: =DATE(2000+RIGHT(C46,2),MID(C46,10,2),MID(C46,7,2)) -> 45597 | F46: 45601 | G46: =F46-E46 -> 4 | H46: =VLOOKUP(MID(C46,5,1)*1,$F$73:$H$76,2,0) -> Keju | I46: {=_xlfn.SWITCH(MID(C46,3,1),"T","TAWAR","G","GANDUM","B","BAKAR")} -> TAWAR | J46: {=INDEX($D$73:$D$84, MATCH(I46, $B$73:$B$84, 0) + MATCH(H46,$C$73:$C$76,0) - 1)} -> 25000 | K46: =VLOOKUP(H46,$G$73:$H$76,2,0)*J46 -> 2500 | L46: =J46-K46 -> 22500
A47: 2 | B47: Stella Meriana | C47: UMG/2/04/11/24 | D47: =IF(LEFT(C47,2)="MA","MAHASISWA",IF(LEFT(C47,2)="PE","PELAJAR","UMUM")) -> UMUM | E47: =DATE(2000+RIGHT(C47,2),MID(C47,10,2),MID(C47,7,2)) -> 45600 | F47: 45606 | G47: =F47-E47 -> 6 | H47: =VLOOKUP(MID(C47,5,1)*1,$F$73:$H$76,2,0) -> Coklat | I47: {=_xlfn.SWITCH(MID(C47,3,1),"T","TAWAR","G","GANDUM","B","BAKAR")} -> GANDUM | J47: {=INDEX($D$73:$D$84, MATCH(I47, $B$73:$B$84, 0) + MATCH(H47,$C$73:$C$76,0) - 1)} -> 25000 | K47: =VLOOKUP(H47,$G$73:$H$76,2,0)*J47 -> 1875 | L47: =J47-K47 -> 23125
A48: 3 | B48: Wallace Firdaus | C48: PEB/1/03/11/24 | D48: =IF(LEFT(C48,2)="MA","MAHASISWA",IF(LEFT(C48,2)="PE","PELAJAR","UMUM")) -> PELAJAR | E48: =DATE(2000+RIGHT(C48,2),MID(C48,10,2),MID(C48,7,2)) -> 45599 | F48: 45608 | G48: =F48-E48 -> 9 | H48: =VLOOKUP(MID(C48,5,1)*1,$F$73:$H$76,2,0) -> Keju | I48: {=_xlfn.SWITCH(MID(C48,3,1),"T","TAWAR","G","GANDUM","B","BAKAR")} -> BAKAR | J48: {=INDEX($D$73:$D$84, MATCH(I48, $B$73:$B$84, 0) + MATCH(H48,$C$73:$C$76,0) - 1)} -> 28000 | K48: =VLOOKUP(H48,$G$73:$H$76,2,0)*J48 -> 2800 | L48: =J48-K48 -> 25200
A49: 4 | B49: Penny Hidayat | C49: MAT/3/09/11/24 | D49: =IF(LEFT(C49,2)="MA","MAHASISWA",IF(LEFT(C49,2)="PE","PELAJAR","UMUM")) -> MAHASISWA | E49: =DATE(2000+RIGHT(C49,2),MID(C49,10,2),MID(C49,7,2)) -> 45605 | F49: 45613 | G49: =F49-E49 -> 8 | H49: =VLOOKUP(MID(C49,5,1)*1,$F$73:$H$76,2,0) -> Stroberi | I49: {=_xlfn.SWITCH(MID(C49,3,1),"T","TAWAR","G","GANDUM","B","BAKAR")} -> TAWAR | J49: {=INDEX($D$73:$D$84, MATCH(I49, $B$73:$B$84, 0) + MATCH(H49,$C$73:$C$76,0) - 1)} -> 22000 | K49: =VLOOKUP(H49,$G$73:$H$76,2,0)*J49 -> 1100 | L49: =J49-K49 -> 20900
A50: 5 | B50: Angela Mursyid | C50: PEG/4/17/11/24 | D50: =IF(LEFT(C50,2)="MA","MAHASISWA",IF(LEFT(C50,2)="PE","PELAJAR","UMUM")) -> PELAJAR | E50: =DATE(2000+RIGHT(C50,2),MID(C50,10,2),MID(C50,7,2)) -> 45613 | F50: 45616 | G50: =F50-E50 -> 3 | H50: =VLOOKUP(MID(C50,5,1)*1,$F$73:$H$76,2,0) -> Susu | I50: {=_xlfn.SWITCH(MID(C50,3,1),"T","TAWAR","G","GANDUM","B","BAKAR")} -> GANDUM | J50: {=INDEX($D$73:$D$84, MATCH(I50, $B$73:$B$84, 0) + MATCH(H50,$C$73:$C$76,0) - 1)} -> 28000 | K50: =VLOOKUP(H50,$G$73:$H$76,2,0)*J50 -> 700 | L50: =J50-K50 -> 27300
A51: 6 | B51: Rubby Batubara | C51: UMG/2/12/11/24 | D51: =IF(LEFT(C51,2)="MA","MAHASISWA",IF(LEFT(C51,2)="PE","PELAJAR","UMUM")) -> UMUM | E51: =DATE(2000+RIGHT(C51,2),MID(C51,10,2),MID(C51,7,2)) -> 45608 | F51: 45616 | G51: =F51-E51 -> 8 | H51: =VLOOKUP(MID(C51,5,1)*1,$F$73:$H$76,2,0) -> Coklat | I51: {=_xlfn.SWITCH(MID(C51,3,1),"T","TAWAR","G","GANDUM","B","BAKAR")} -> GANDUM | J51: {=INDEX($D$73:$D$84, MATCH(I51, $B$73:$B$84, 0) + MATCH(H51,$C$73:$C$76,0) - 1)} -> 25000 | K51: =VLOOKUP(H51,$G$73:$H$76,2,0)*J51 -> 1875 | L51: =J51-K51 -> 23125
A52: 7 | B52: Arie Sujadnorwanto | C52: MAB/3/20/11/24 | D52: =IF(LEFT(C52,2)="MA","MAHASISWA",IF(LEFT(C52,2)="PE","PELAJAR","UMUM")) -> MAHASISWA | E52: =DATE(2000+RIGHT(C52,2),MID(C52,10,2),MID(C52,7,2)) -> 45616 | F52: 45618 | G52: =F52-E52 -> 2 | H52: =VLOOKUP(MID(C52,5,1)*1,$F$73:$H$76,2,0) -> Stroberi | I52: {=_xlfn.SWITCH(MID(C52,3,1),"T","TAWAR","G","GANDUM","B","BAKAR")} -> BAKAR | J52: {=INDEX($D$73:$D$84, MATCH(I52, $B$73:$B$84, 0) + MATCH(H52,$C$73:$C$76,0) - 1)} -> 27000 | K52: =VLOOKUP(H52,$G$73:$H$76,2,0)*J52 -> 1350 | L52: =J52-K52 -> 25650
A53: 8 | B53: Cristalia Muriah | C53: MAG/1/13/11/24 | D53: =IF(LEFT(C53,2)="MA","MAHASISWA",IF(LEFT(C53,2)="PE","PELAJAR","UMUM")) -> MAHASISWA | E53: =DATE(2000+RIGHT(C53,2),MID(C53,10,2),MID(C53,7,2)) -> 45609 | F53: 45619 | G53: =F53-E53 -> 10 | H53: =VLOOKUP(MID(C53,5,1)*1,$F$73:$H$76,2,0) -> Keju | I53: {=_xlfn.SWITCH(MID(C53,3,1),"T","TAWAR","G","GANDUM","B","BAKAR")} -> GANDUM | J53: {=INDEX($D$73:$D$84, MATCH(I53, $B$73:$B$84, 0) + MATCH(H53,$C$73:$C$76,0) - 1)} -> 30000 | K53: =VLOOKUP(H53,$G$73:$H$76,2,0)*J53 -> 3000 | L53: =J53-K53 -> 27000
A54: 9 | B54: Jesica Iskandar | C54: PET/4/10/11/24 | D54: =IF(LEFT(C54,2)="MA","MAHASISWA",IF(LEFT(C54,2)="PE","PELAJAR","UMUM")) -> PELAJAR | E54: =DATE(2000+RIGHT(C54,2),MID(C54,10,2),MID(C54,7,2)) -> 45606 | F54: 45621 | G54: =F54-E54 -> 15 | H54: =VLOOKUP(MID(C54,5,1)*1,$F$73:$H$76,2,0) -> Susu | I54: {=_xlfn.SWITCH(MID(C54,3,1),"T","TAWAR","G","GANDUM","B","BAKAR")} -> TAWAR | J54: {=INDEX($D$73:$D$84, MATCH(I54, $B$73:$B$84, 0) + MATCH(H54,$C$73:$C$76,0) - 1)} -> 24000 | K54: =VLOOKUP(H54,$G$73:$H$76,2,0)*J54 -> 600 | L54: =J54-K54 -> 23400
A55: 10 | B55: Kawoko Hendrik | C55: UMB/3/13/11/24 | D55: =IF(LEFT(C55,2)="MA","MAHASISWA",IF(LEFT(C55,2)="PE","PELAJAR","UMUM")) -> UMUM | E55: =DATE(2000+RIGHT(C55,2),MID(C55,10,2),MID(C55,7,2)) -> 45609 | F55: 45624 | G55: =F55-E55 -> 15 | H55: =VLOOKUP(MID(C55,5,1)*1,$F$73:$H$76,2,0) -> Stroberi | I55: {=_xlfn.SWITCH(MID(C55,3,1),"T","TAWAR","G","GANDUM","B","BAKAR")} -> BAKAR | J55: {=INDEX($D$73:$D$84, MATCH(I55, $B$73:$B$84, 0) + MATCH(H55,$C$73:$C$76,0) - 1)} -> 27000 | K55: =VLOOKUP(H55,$G$73:$H$76,2,0)*J55 -> 1350 | L55: =J55-K55 -> 25650
A56: 11 | B56: Sinar Untari | C56: UMT/1/17/11/24 | D56: =IF(LEFT(C56,2)="MA","MAHASISWA",IF(LEFT(C56,2)="PE","PELAJAR","UMUM")) -> UMUM | E56: =DATE(2000+RIGHT(C56,2),MID(C56,10,2),MID(C56,7,2)) -> 45613 | F56: 45626 | G56: =F56-E56 -> 13 | H56: =VLOOKUP(MID(C56,5,1)*1,$F$73:$H$76,2,0) -> Keju | I56: {=_xlfn.SWITCH(MID(C56,3,1),"T","TAWAR","G","GANDUM","B","BAKAR")} -> TAWAR | J56: {=INDEX($D$73:$D$84, MATCH(I56, $B$73:$B$84, 0) + MATCH(H56,$C$73:$C$76,0) - 1)} -> 25000 | K56: =VLOOKUP(H56,$G$73:$H$76,2,0)*J56 -> 2500 | L56: =J56-K56 -> 22500
A57: 12 | B57: Jajat Nuhasyim | C57: PEB/2/24/11/24 | D57: =IF(LEFT(C57,2)="MA","MAHASISWA",IF(LEFT(C57,2)="PE","PELAJAR","UMUM")) -> PELAJAR | E57: =DATE(2000+RIGHT(C57,2),MID(C57,10,2),MID(C57,7,2)) -> 45620 | F57: 45626 | G57: =F57-E57 -> 6 | H57: =VLOOKUP(MID(C57,5,1)*1,$F$73:$H$76,2,0) -> Coklat | I57: {=_xlfn.SWITCH(MID(C57,3,1),"T","TAWAR","G","GANDUM","B","BAKAR")} -> BAKAR | J57: {=INDEX($D$73:$D$84, MATCH(I57, $B$73:$B$84, 0) + MATCH(H57,$C$73:$C$76,0) - 1)} -> 25000 | K57: =VLOOKUP(H57,$G$73:$H$76,2,0)*J57 -> 1875 | L57: =J57-K57 -> 23125
J58: JUMLAH TOTAL BAYAR | L58: =SUM($L$46:$L$57) -> 289475 | M58: 9
D59: 10 | E59: 11 | F59: 12 | J59: TOTAL BAYAR TERTINGGI | L59: =MAX($L$46:$L$57) -> 27300 | M59: 9
C60: REKAPITULASI RASA ROTI | D60: Rata-rata lama Voucher | E60: Banyak Terjual | F60: JUMLAH TOTAL | J60: TOTAL BAYAR TERENDAH | L60: =MIN($L$46:$L$57) -> 20900 | M60: 9
J61: RATA-RATA TOTAL BAYAR | L61: =AVERAGE($L$46:$L$57) -> 24122.917 | M61: 9
C62: Keju | D62: =AVERAGEIF($H$46:$H$57,C62,$G$46:$G$57) -> 9 | E62: =COUNTIF($H$46:$H$57,C62) -> 4 | F62: =SUMIF($H$46:$H$57,C62,$L$46:$L$57) -> 97200
C63: Coklat | D63: =AVERAGEIF($H$46:$H$57,C63,$G$46:$G$57) -> 6.6666667 | E63: =COUNTIF($H$46:$H$57,C63) -> 3 | F63: =SUMIF($H$46:$H$57,C63,$L$46:$L$57) -> 69375
C64: Stroberi | D64: =AVERAGEIF($H$46:$H$57,C64,$G$46:$G$57) -> 8.3333333 | E64: =COUNTIF($H$46:$H$57,C64) -> 3 | F64: =SUMIF($H$46:$H$57,C64,$L$46:$L$57) -> 72200
...

Sheet About
I6: XL-TEST adalah platform inovatif yang menyediakan latihan Excel interaktif dengan pemeriksaan otomatis,
I7: sehingga pengguna dapat langsung mengetahui jawaban yang benar maupun salah.
I10: Terdapat 5 Level soal :
J12: Easy Level | L12: (⭐)
J13: Medium Level | L13: (⭐⭐)
J14: Hard Level | L14: (⭐⭐⭐)
J15: Extreme Level | L15: (⭐⭐⭐⭐)
J16: Championship Level | L16: (⭐⭐⭐⭐⭐)
B17: Saya adalah seorang Excel Holic yang percaya bahwa setiap angka memiliki cerita yang bisa ditemukan dengan cara yang tepat. | I17: Free Access
B18: “Excel bukan cuma soal kerjaan tapi juga hobi yang aku nikmati.” | I18: https://belajarexcel.id/xl-test/
B19: Contact :
B20: 🌐 Web | C20: https://setiadi.me
B21: 🪡threads | C21: https://www.threads.com/@andisetiadi
D27: Perlu Video Penjelasan atau Kunci Jawaban ?
D28: Scan barcode atau kunjungi
D29: https://lynk.id/setiadi/page/jawaban-xl-test

Sheet DF
A1: DF | C1: 1 | D1: 2 | E1: 3 | F1: 4 | G1: 5 | H1: 6 | I1: 7 | J1: 8 | K1: 9 | L1: 10 | M1: 11 | N1: 12 | Q1: 1 | R1: 2 | S1: 3 | T1: 4 | U1: 5 | V1: 6 | W1: 7 | X1: 8 | Y1: 9 | Z1: 10 | AA1: 11 | AB1: 12
A2: MB2 | B2: 1 | C2: =UPPER(Case!D46) -> MAHASISWA | D2: =Case!E46 -> 45597 | E2: =Case!G46 -> 4 | F2: =Case!H46 -> Keju | G2: =PROPER(Case!I46) -> Tawar | H2: =Case!J46 -> 25000 | I2: =Case!K46 -> 2500 | J2: =Case!L46 -> 22500 | K2: =Case!L58 -> 289475 | L2: =Case!D62 -> 9 | M2: =Case!E62 -> 4 | N2: =Case!F62 -> 97200 | Q2: =LEN(_xlfn.FORMULATEXT(Case!D46)) -> 71 | R2: =LEN(_xlfn.FORMULATEXT(Case!E46)) -> 51 | S2: =LEN(_xlfn.FORMULATEXT(Case!G46)) -> 8 | T2: =LEN(_xlfn.FORMULATEXT(Case!H46)) -> 40 | U2: =LEN(_xlfn.FORMULATEXT(Case!I46)) -> 58 | V2: =LEN(_xlfn.FORMULATEXT(Case!J46)) -> 78 | W2: =LEN(_xlfn.FORMULATEXT(Case!K46)) -> 33 | X2: =LEN(_xlfn.FORMULATEXT(Case!L46)) -> 8 | Z2: =LEN(_xlfn.FORMULATEXT(Case!D62)) -> 39 | AA2: =LEN(_xlfn.FORMULATEXT(Case!E62)) -> 25 | AB2: =LEN(_xlfn.FORMULATEXT(Case!F62)) -> 35
B3: 2 | C3: =UPPER(Case!D47) -> UMUM | D3: =Case!E47 -> 45600 | E3: =Case!G47 -> 6 | F3: =Case!H47 -> Coklat | G3: =PROPER(Case!I47) -> Gandum | H3: =Case!J47 -> 25000 | I3: =Case!K47 -> 1875 | J3: =Case!L47 -> 23125 | K3: =Case!L59 -> 27300 | L3: =Case!D63 -> 6.6666667 | M3: =Case!E63 -> 3 | N3: =Case!F63 -> 69375 | Q3: =LEN(_xlfn.FORMULATEXT(Case!D47)) -> 71 | R3: =LEN(_xlfn.FORMULATEXT(Case!E47)) -> 51 | S3: =LEN(_xlfn.FORMULATEXT(Case!G47)) -> 8 | T3: =LEN(_xlfn.FORMULATEXT(Case!H47)) -> 40 | U3: =LEN(_xlfn.FORMULATEXT(Case!I47)) -> 58 | V3: =LEN(_xlfn.FORMULATEXT(Case!J47)) -> 78 | W3: =LEN(_xlfn.FORMULATEXT(Case!K47)) -> 33 | X3: =LEN(_xlfn.FORMULATEXT(Case!L47)) -> 8 | Z3: =LEN(_xlfn.FORMULATEXT(Case!D63)) -> 39 | AA3: =LEN(_xlfn.FORMULATEXT(Case!E63)) -> 25 | AB3: =LEN(_xlfn.FORMULATEXT(Case!F63)) -> 35
B4: 3 | C4: =UPPER(Case!D48) -> PELAJAR | D4: =Case!E48 -> 45599 | E4: =Case!G48 -> 9 | F4: =Case!H48 -> Keju | G4: =PROPER(Case!I48) -> Bakar | H4: =Case!J48 -> 28000 | I4: =Case!K48 -> 2800 | J4: =Case!L48 -> 25200 | K4: =Case!L60 -> 20900 | L4: =Case!D64 -> 8.3333333 | M4: =Case!E64 -> 3 | N4: =Case!F64 -> 72200 | Q4: =LEN(_xlfn.FORMULATEXT(Case!D48)) -> 71 | R4: =LEN(_xlfn.FORMULATEXT(Case!E48)) -> 51 | S4: =LEN(_xlfn.FORMULATEXT(Case!G48)) -> 8 | T4: =LEN(_xlfn.FORMULATEXT(Case!H48)) -> 40 | U4: =LEN(_xlfn.FORMULATEXT(Case!I48)) -> 58 | V4: =LEN(_xlfn.FORMULATEXT(Case!J48)) -> 78 | W4: =LEN(_xlfn.FORMULATEXT(Case!K48)) -> 33 | X4: =LEN(_xlfn.FORMULATEXT(Case!L48)) -> 8 | Z4: =LEN(_xlfn.FORMULATEXT(Case!D64)) -> 39 | AA4: =LEN(_xlfn.FORMULATEXT(Case!E64)) -> 25 | AB4: =LEN(_xlfn.FORMULATEXT(Case!F64)) -> 35
B5: 4 | C5: =UPPER(Case!D49) -> MAHASISWA | D5: =Case!E49 -> 45605 | E5: =Case!G49 -> 8 | F5: =Case!H49 -> Stroberi | G5: =PROPER(Case!I49) -> Tawar | H5: =Case!J49 -> 22000 | I5: =Case!K49 -> 1100 | J5: =Case!L49 -> 20900 | K5: =Case!L61 -> 24122.917 | L5: =Case!D65 -> 9 | M5: =Case!E65 -> 2 | N5: =Case!F65 -> 50700 | Q5: =LEN(_xlfn.FORMULATEXT(Case!D49)) -> 71 | R5: =LEN(_xlfn.FORMULATEXT(Case!E49)) -> 51 | S5: =LEN(_xlfn.FORMULATEXT(Case!G49)) -> 8 | T5: =LEN(_xlfn.FORMULATEXT(Case!H49)) -> 40 | U5: =LEN(_xlfn.FORMULATEXT(Case!I49)) -> 58 | V5: =LEN(_xlfn.FORMULATEXT(Case!J49)) -> 78 | W5: =LEN(_xlfn.FORMULATEXT(Case!K49)) -> 33 | X5: =LEN(_xlfn.FORMULATEXT(Case!L49)) -> 8 | Z5: =LEN(_xlfn.FORMULATEXT(Case!D65)) -> 39 | AA5: =LEN(_xlfn.FORMULATEXT(Case!E65)) -> 25 | AB5: =LEN(_xlfn.FORMULATEXT(Case!F65)) -> 35
B6: 5 | C6: =UPPER(Case!D50) -> PELAJAR | D6: =Case!E50 -> 45613 | E6: =Case!G50 -> 3 | F6: =Case!H50 -> Susu | G6: =PROPER(Case!I50) -> Gandum | H6: =Case!J50 -> 28000 | I6: =Case!K50 -> 700 | J6: =Case!L50 -> 27300 | Q6: =LEN(_xlfn.FORMULATEXT(Case!D50)) -> 71 | R6: =LEN(_xlfn.FORMULATEXT(Case!E50)) -> 51 | S6: =LEN(_xlfn.FORMULATEXT(Case!G50)) -> 8 | T6: =LEN(_xlfn.FORMULATEXT(Case!H50)) -> 40 | U6: =LEN(_xlfn.FORMULATEXT(Case!I50)) -> 58 | V6: =LEN(_xlfn.FORMULATEXT(Case!J50)) -> 78 | W6: =LEN(_xlfn.FORMULATEXT(Case!K50)) -> 33 | X6: =LEN(_xlfn.FORMULATEXT(Case!L50)) -> 8
B7: 6 | C7: =UPPER(Case!D51) -> UMUM | D7: =Case!E51 -> 45608 | E7: =Case!G51 -> 8 | F7: =Case!H51 -> Coklat | G7: =PROPER(Case!I51) -> Gandum | H7: =Case!J51 -> 25000 | I7: =Case!K51 -> 1875 | J7: =Case!L51 -> 23125 | Q7: =LEN(_xlfn.FORMULATEXT(Case!D51)) -> 71 | R7: =LEN(_xlfn.FORMULATEXT(Case!E51)) -> 51 | S7: =LEN(_xlfn.FORMULATEXT(Case!G51)) -> 8 | T7: =LEN(_xlfn.FORMULATEXT(Case!H51)) -> 40 | U7: =LEN(_xlfn.FORMULATEXT(Case!I51)) -> 58 | V7: =LEN(_xlfn.FORMULATEXT(Case!J51)) -> 78 | W7: =LEN(_xlfn.FORMULATEXT(Case!K51)) -> 33 | X7: =LEN(_xlfn.FORMULATEXT(Case!L51)) -> 8
B8: 7 | C8: =UPPER(Case!D52) -> MAHASISWA | D8: =Case!E52 -> 45616 | E8: =Case!G52 -> 2 | F8: =Case!H52 -> Stroberi | G8: =PROPER(Case!I52) -> Bakar | H8: =Case!J52 -> 27000 | I8: =Case!K52 -> 1350 | J8: =Case!L52 -> 25650 | Q8: =LEN(_xlfn.FORMULATEXT(Case!D52)) -> 71 | R8: =LEN(_xlfn.FORMULATEXT(Case!E52)) -> 51 | S8: =LEN(_xlfn.FORMULATEXT(Case!G52)) -> 8 | T8: =LEN(_xlfn.FORMULATEXT(Case!H52)) -> 40 | U8: =LEN(_xlfn.FORMULATEXT(Case!I52)) -> 58 | V8: =LEN(_xlfn.FORMULATEXT(Case!J52)) -> 78 | W8: =LEN(_xlfn.FORMULATEXT(Case!K52)) -> 33 | X8: =LEN(_xlfn.FORMULATEXT(Case!L52)) -> 8
B9: 8 | C9: =UPPER(Case!D53) -> MAHASISWA | D9: =Case!E53 -> 45609 | E9: =Case!G53 -> 10 | F9: =Case!H53 -> Keju | G9: =PROPER(Case!I53) -> Gandum | H9: =Case!J53 -> 30000 | I9: =Case!K53 -> 3000 | J9: =Case!L53 -> 27000 | Q9: =LEN(_xlfn.FORMULATEXT(Case!D53)) -> 71 | R9: =LEN(_xlfn.FORMULATEXT(Case!E53)) -> 51 | S9: =LEN(_xlfn.FORMULATEXT(Case!G53)) -> 8 | T9: =LEN(_xlfn.FORMULATEXT(Case!H53)) -> 40 | U9: =LEN(_xlfn.FORMULATEXT(Case!I53)) -> 58 | V9: =LEN(_xlfn.FORMULATEXT(Case!J53)) -> 78 | W9: =LEN(_xlfn.FORMULATEXT(Case!K53)) -> 33 | X9: =LEN(_xlfn.FORMULATEXT(Case!L53)) -> 8
B10: 9 | C10: =UPPER(Case!D54) -> PELAJAR | D10: =Case!E54 -> 45606 | E10: =Case!G54 -> 15 | F10: =Case!H54 -> Susu | G10: =PROPER(Case!I54) -> Tawar | H10: =Case!J54 -> 24000 | I10: =Case!K54 -> 600 | J10: =Case!L54 -> 23400 | Q10: =LEN(_xlfn.FORMULATEXT(Case!D54)) -> 71 | R10: =LEN(_xlfn.FORMULATEXT(Case!E54)) -> 51 | S10: =LEN(_xlfn.FORMULATEXT(Case!G54)) -> 8 | T10: =LEN(_xlfn.FORMULATEXT(Case!H54)) -> 40 | U10: =LEN(_xlfn.FORMULATEXT(Case!I54)) -> 58 | V10: =LEN(_xlfn.FORMULATEXT(Case!J54)) -> 78 | W10: =LEN(_xlfn.FORMULATEXT(Case!K54)) -> 33 | X10: =LEN(_xlfn.FORMULATEXT(Case!L54)) -> 8
B11: 10 | C11: =UPPER(Case!D55) -> UMUM | D11: =Case!E55 -> 45609 | E11: =Case!G55 -> 15 | F11: =Case!H55 -> Stroberi | G11: =PROPER(Case!I55) -> Bakar | H11: =Case!J55 -> 27000 | I11: =Case!K55 -> 1350 | J11: =Case!L55 -> 25650 | Q11: =LEN(_xlfn.FORMULATEXT(Case!D55)) -> 71 | R11: =LEN(_xlfn.FORMULATEXT(Case!E55)) -> 51 | S11: =LEN(_xlfn.FORMULATEXT(Case!G55)) -> 8 | T11: =LEN(_xlfn.FORMULATEXT(Case!H55)) -> 40 | U11: =LEN(_xlfn.FORMULATEXT(Case!I55)) -> 58 | V11: =LEN(_xlfn.FORMULATEXT(Case!J55)) -> 78 | W11: =LEN(_xlfn.FORMULATEXT(Case!K55)) -> 33 | X11: =LEN(_xlfn.FORMULATEXT(Case!L55)) -> 8
B12: 11 | C12: =UPPER(Case!D56) -> UMUM | D12: =Case!E56 -> 45613 | E12: =Case!G56 -> 13 | F12: =Case!H56 -> Keju | G12: =PROPER(Case!I56) -> Tawar | H12: =Case!J56 -> 25000 | I12: =Case!K56 -> 2500 | J12: =Case!L56 -> 22500 | Q12: =LEN(_xlfn.FORMULATEXT(Case!D56)) -> 71 | R12: =LEN(_xlfn.FORMULATEXT(Case!E56)) -> 51 | S12: =LEN(_xlfn.FORMULATEXT(Case!G56)) -> 8 | T12: =LEN(_xlfn.FORMULATEXT(Case!H56)) -> 40 | U12: =LEN(_xlfn.FORMULATEXT(Case!I56)) -> 58 | V12: =LEN(_xlfn.FORMULATEXT(Case!J56)) -> 78 | W12: =LEN(_xlfn.FORMULATEXT(Case!K56)) -> 33 | X12: =LEN(_xlfn.FORMULATEXT(Case!L56)) -> 8
B13: 12 | C13: =UPPER(Case!D57) -> PELAJAR | D13: =Case!E57 -> 45620 | E13: =Case!G57 -> 6 | F13: =Case!H57 -> Coklat | G13: =PROPER(Case!I57) -> Bakar | H13: =Case!J57 -> 25000 | I13: =Case!K57 -> 1875 | J13: =Case!L57 -> 23125 | Q13: =LEN(_xlfn.FORMULATEXT(Case!D57)) -> 71 | R13: =LEN(_xlfn.FORMULATEXT(Case!E57)) -> 51 | S13: =LEN(_xlfn.FORMULATEXT(Case!G57)) -> 8 | T13: =LEN(_xlfn.FORMULATEXT(Case!H57)) -> 40 | U13: =LEN(_xlfn.FORMULATEXT(Case!I57)) -> 58 | V13: =LEN(_xlfn.FORMULATEXT(Case!J57)) -> 78 | W13: =LEN(_xlfn.FORMULATEXT(Case!K57)) -> 33 | X13: =LEN(_xlfn.FORMULATEXT(Case!L57)) -> 8
B16: 1 | C16: =CODE(MID(C2,2,1))+CODE(MID(C2,4,1))+CODE(LEFT(C2,1))+CODE(RIGHT(C2)) -> 272 | F16: =CODE(MID(F2,2,1))+CODE(MID(F2,4,1))+CODE(LEFT(F2,1))+CODE(RIGHT(F2)) -> 410 | G16: =CODE(MID(G2,2,1))+CODE(MID(G2,4,1))+CODE(LEFT(G2,1))+CODE(RIGHT(G2)) -> 392 | Q16: =AVERAGE(Q2:Q13)=Q2 -> TRUE | R16: =AVERAGE(R2:R13)=R2 -> TRUE | S16: =AVERAGE(S2:S13)=S2 -> TRUE | T16: =AVERAGE(T2:T13)=T2 -> TRUE | U16: =AVERAGE(U2:U13)=U2 -> TRUE | V16: =AVERAGE(V2:V13)=V2 -> TRUE | W16: =AVERAGE(W2:W13)=W2 -> TRUE | X16: =AVERAGE(X2:X13)=X2 -> TRUE | Y16: TRUE | Z16: =AVERAGE(Z2:Z5)=Z2 -> TRUE | AA16: =AVERAGE(AA2:AA5)=AA2 -> TRUE | AB16: =AVERAGE(AB2:AB5)=AB2 -> TRUE
B17: 2 | C17: =CODE(MID(C3,2,1))+CODE(MID(C3,4,1))+CODE(LEFT(C3,1))+CODE(RIGHT(C3)) -> 316 | F17: =CODE(MID(F3,2,1))+CODE(MID(F3,4,1))+CODE(LEFT(F3,1))+CODE(RIGHT(F3)) -> 402 | G17: =CODE(MID(G3,2,1))+CODE(MID(G3,4,1))+CODE(LEFT(G3,1))+CODE(RIGHT(G3)) -> 377 | Q17: =AND(Q2>0,Q6=0,C6>0) -> FALSE | R17: =AND(R2>0,R6=0,D6>0) -> FALSE | S17: =AND(S2>0,S6=0,E6>0) -> FALSE | T17: =AND(T2>0,T6=0,F6>0) -> FALSE | U17: =AND(U2>0,U6=0,G6>0) -> FALSE | V17: =AND(V2>0,V6=0,H6>0) -> FALSE | W17: =AND(W2>0,W6=0,I6>0) -> FALSE | X17: =AND(X2>0,X6=0,J6>0) -> FALSE | Y17: TRUE | Z17: =AND(Z2>0,Z5=0,L5>0) -> FALSE | AA17: =AND(AA2>0,AA5=0,M5>0) -> FALSE | AB17: =AND(AB2>0,AB5=0,N5>0) -> FALSE
B18: 3 | C18: =CODE(MID(C4,2,1))+CODE(MID(C4,4,1))+CODE(LEFT(C4,1))+CODE(RIGHT(C4)) -> 296 | F18: =CODE(MID(F4,2,1))+CODE(MID(F4,4,1))+CODE(LEFT(F4,1))+CODE(RIGHT(F4)) -> 410 | G18: =CODE(MID(G4,2,1))+CODE(MID(G4,4,1))+CODE(LEFT(G4,1))+CODE(RIGHT(G4)) -> 374
B19: 4 | C19: =CODE(MID(C5,2,1))+CODE(MID(C5,4,1))+CODE(LEFT(C5,1))+CODE(RIGHT(C5)) -> 272 | F19: =CODE(MID(F5,2,1))+CODE(MID(F5,4,1))+CODE(LEFT(F5,1))+CODE(RIGHT(F5)) -> 415 | G19: =CODE(MID(G5,2,1))+CODE(MID(G5,4,1))+CODE(LEFT(G5,1))+CODE(RIGHT(G5)) -> 392 | Q19: =IFERROR(OR(Q16:Q17),FALSE) -> TRUE | R19: =IFERROR(OR(R16:R17),FALSE) -> TRUE | S19: =IFERROR(OR(S16:S17),FALSE) -> TRUE | T19: =IFERROR(OR(T16:T17),FALSE) -> TRUE | U19: =IFERROR(OR(U16:U17),FALSE) -> TRUE | V19: =IFERROR(OR(V16:V17),FALSE) -> TRUE | W19: =IFERROR(OR(W16:W17),FALSE) -> TRUE | X19: =IFERROR(OR(X16:X17),FALSE) -> TRUE | ... AB19: =IFERROR(OR(AB16:AB17),FALSE) -> TRUE
B20: 5 | C20: =CODE(MID(C6,2,1))+CODE(MID(C6,4,1))+CODE(LEFT(C6,1))+CODE(RIGHT(C6)) -> 296 | F20: =CODE(MID(F6,2,1))+CODE(MID(F6,4,1))+CODE(LEFT(F6,1))+CODE(RIGHT(F6)) -> 434 | G20: =CODE(MID(G6,2,1))+CODE(MID(G6,4,1))+CODE(LEFT(G6,1))+CODE(RIGHT(G6)) -> 377
B21: 6 | C21: =CODE(MID(C7,2,1))+CODE(MID(C7,4,1))+CODE(LEFT(C7,1))+CODE(RIGHT(C7)) -> 316 | F21: =CODE(MID(F7,2,1))+CODE(MID(F7,4,1))+CODE(LEFT(F7,1))+CODE(RIGHT(F7)) -> 402 | G21: =CODE(MID(G7,2,1))+CODE(MID(G7,4,1))+CODE(LEFT(G7,1))+CODE(RIGHT(G7)) -> 377
B22: 7 | C22: =CODE(MID(C8,2,1))+CODE(MID(C8,4,1))+CODE(LEFT(C8,1))+CODE(RIGHT(C8)) -> 272 | F22: =CODE(MID(F8,2,1))+CODE(MID(F8,4,1))+CODE(LEFT(F8,1))+CODE(RIGHT(F8)) -> 415 | G22: =CODE(MID(G8,2,1))+CODE(MID(G8,4,1))+CODE(LEFT(G8,1))+CODE(RIGHT(G8)) -> 374
B23: 8 | C23: =CODE(MID(C9,2,1))+CODE(MID(C9,4,1))+CODE(LEFT(C9,1))+CODE(RIGHT(C9)) -> 272 | F23: =CODE(MID(F9,2,1))+CODE(MID(F9,4,1))+CODE(LEFT(F9,1))+CODE(RIGHT(F9)) -> 410 | G23: =CODE(MID(G9,2,1))+CODE(MID(G9,4,1))+CODE(LEFT(G9,1))+CODE(RIGHT(G9)) -> 377
B24: 9 | C24: =CODE(MID(C10,2,1))+CODE(MID(C10,4,1))+CODE(LEFT(C10,1))+CODE(RIGHT(C10)) -> 296 | F24: =CODE(MID(F10,2,1))+CODE(MID(F10,4,1))+CODE(LEFT(F10,1))+CODE(RIGHT(F10)) -> 434 | G24: =CODE(MID(G10,2,1))+CODE(MID(G10,4,1))+CODE(LEFT(G10,1))+CODE(RIGHT(G10)) -> 392
B25: 10 | C25: =CODE(MID(C11,2,1))+CODE(MID(C11,4,1))+CODE(LEFT(C11,1))+CODE(RIGHT(C11)) -> 316 | F25: =CODE(MID(F11,2,1))+CODE(MID(F11,4,1))+CODE(LEFT(F11,1))+CODE(RIGHT(F11)) -> 415 | G25: =CODE(MID(G11,2,1))+CODE(MID(G11,4,1))+CODE(LEFT(G11,1))+CODE(RIGHT(G11)) -> 374
B26: 11 | C26: =CODE(MID(C12,2,1))+CODE(MID(C12,4,1))+CODE(LEFT(C12,1))+CODE(RIGHT(C12)) -> 316 | F26: =CODE(MID(F12,2,1))+CODE(MID(F12,4,1))+CODE(LEFT(F12,1))+CODE(RIGHT(F12)) -> 410 | G26: =CODE(MID(G12,2,1))+CODE(MID(G12,4,1))+CODE(LEFT(G12,1))+CODE(RIGHT(G12)) -> 392
B27: 12 | C27: =CODE(MID(C13,2,1))+CODE(MID(C13,4,1))+CODE(LEFT(C13,1))+CODE(RIGHT(C13)) -> 296 | F27: =CODE(MID(F13,2,1))+CODE(MID(F13,4,1))+CODE(LEFT(F13,1))+CODE(RIGHT(F13)) -> 402 | G27: =CODE(MID(G13,2,1))+CODE(MID(G13,4,1))+CODE(LEFT(G13,1))+CODE(RIGHT(G13)) -> 374 | R27: 1 | S27: 2 | T27: 3 | U27: 4 | V27: 5 | W27: 6 | X27: 7 | Y27: 8 | Z27: 9 | AA27: 10 | AB27: 11 | AC27: 12
Q28: 1 | R28: =_xlfn.FORMULATEXT(Case!D46) -> =IF(LEFT(C46;2)="MA";"MAHASISWA";IF(LEFT(C46;2)="PE";"PELAJAR";"UMUM")) | S28: =_xlfn.FORMULATEXT(Case!E46) -> =DATE(2000+RIGHT(C46;2);MID(C46;10;2);MID(C46;7;2)) | T28: =_xlfn.FORMULATEXT(Case!G46) -> =F46-E46 | U28: =_xlfn.FORMULATEXT(Case!H46) -> =VLOOKUP(MID(C46;5;1)*1;$F$73:$H$76;2;0) | V28: =_xlfn.FORMULATEXT(Case!I46) -> =SWITCH(MID(C46;3;1);"T";"TAWAR";"G";"GANDUM";"B";"BAKAR") | W28: =_xlfn.FORMULATEXT(Case!J46) -> =INDEX($D$73:$D$84; MATCH(I46; $B$73:$B$84; 0) + MATCH(H46;$C$73:$C$76;0) - 1) | X28: =_xlfn.FORMULATEXT(Case!K46) -> =VLOOKUP(H46;$G$73:$H$76;2;0)*J46 | Y28: =_xlfn.FORMULATEXT(Case!L46) -> =J46-K46 | AA28: =_xlfn.FORMULATEXT(Case!D62) -> =AVERAGEIF($H$46:$H$57;C62;$G$46:$G$57) | AB28: =_xlfn.FORMULATEXT(Case!E62) -> =COUNTIF($H$46:$H$57;C62) | AC28: =_xlfn.FORMULATEXT(Case!F62) -> =SUMIF($H$46:$H$57;C62;$L$46:$L$57)
Q29: 2 | R29: =_xlfn.FORMULATEXT(Case!E46) -> =DATE(2000+RIGHT(C46;2);MID(C46;10;2);MID(C46;7;2))
C30: =IFERROR(SUM(C16:C27)+C26+C21+C17,0) -> 4484 | D30: =SUM(D2:D13)+D3+D6+D9+D12 -> 729730 | E30: =(SUM(E2:E13)+E3+E6+E9+E12)+900 -> 1031 | F30: =IFERROR(SUM(F16:F27)+F26+F21+F17,0) -> 6173 | G30: =IFERROR(SUM(G16:G27)+G26+G21+G17,0) -> 5718 | H30: =SUM(H2:H13)+H3+H6+H9+H12 -> 419000 | I30: =SUM(I2:I13)+I3+I6+I9+I12 -> 29600 | J30: =SUM(J2:J13)+J3+J6+J9+J12 -> 389400 | K30: =SUM(K2:K5)+K3+K4+K2 -> 699472.92 | L30: =(SUM(L2:L5)+L3+L4+L2)+2456 -> 2513 | M30: =(SUM(M2:M5)+M3+M4+M2)+1452 -> 1474 | N30: =SUM(N2:N5)+N3+N4+N2 -> 528250 | Q30: 3 | R30: =_xlfn.FORMULATEXT(Case!G46) -> =F46-E46
Q31: 4 | R31: =_xlfn.FORMULATEXT(Case!H46) -> =VLOOKUP(MID(C46;5;1)*1;$F$73:$H$76;2;0)
B32: Rand | C32: 9286 | D32: 9637 | E32: 7414 | F32: 8331 | G32: 5671 | H32: 8942 | I32: 2872 | J32: 4268 | K32: 5604 | L32: 4104 | M32: 6071 | N32: 6720 | Q32: 5 | R32: =_xlfn.FORMULATEXT(Case!I46) -> =SWITCH(MID(C46;3;1);"T";"TAWAR";"G";"GANDUM";"B";"BAKAR")
Q33: 6 | R33: =_xlfn.FORMULATEXT(Case!J46) -> =INDEX($D$73:$D$84; MATCH(I46; $B$73:$B$84; 0) + MATCH(H46;$C$73:$C$76;0) - 1)
B34: TRUE | C34: =DEC2HEX(LEFT(C32,2)+COLUMN()+2) -> 61 | D34: =DEC2HEX(LEFT(D32,2)+COLUMN()+2) -> 66 | E34: =DEC2HEX(LEFT(E32,2)+COLUMN()+2) -> 51 | F34: =DEC2HEX(LEFT(F32,2)+COLUMN()+2) -> 5B | G34: =DEC2HEX(LEFT(G32,2)+COLUMN()+2) -> 41 | H34: =DEC2HEX(LEFT(H32,2)+COLUMN()+2) -> 63 | I34: =DEC2HEX(LEFT(I32,2)+COLUMN()+2) -> 27 | J34: =DEC2HEX(LEFT(J32,2)+COLUMN()+2) -> 36 | ... N34: =DEC2HEX(LEFT(N32,2)+COLUMN()+2) -> 53 | Q34: 7 | R34: =_xlfn.FORMULATEXT(Case!K46) -> =VLOOKUP(H46;$G$73:$H$76;2;0)*J46
B35: FALSE | C35: =DEC2HEX(RIGHT(C32,2)+COLUMN()+2) -> 5B | D35: =DEC2HEX(RIGHT(D32,2)+COLUMN()+2) -> 2B | E35: =DEC2HEX(RIGHT(E32,2)+COLUMN()+2) -> 15 | F35: =DEC2HEX(RIGHT(F32,2)+COLUMN()+2) -> 27 | G35: =DEC2HEX(RIGHT(G32,2)+COLUMN()+2) -> 50 | H35: =DEC2HEX(RIGHT(H32,2)+COLUMN()+2) -> 34 | I35: =DEC2HEX(RIGHT(I32,2)+COLUMN()+2) -> 53 | J35: =DEC2HEX(RIGHT(J32,2)+COLUMN()+2) -> 50 | ... N35: =DEC2HEX(RIGHT(N32,2)+COLUMN()+2) -> 24 | Q35: 8 | R35: =_xlfn.FORMULATEXT(Case!L46) -> =J46-K46
Q36: 9
Q37: 10 | R37: =_xlfn.FORMULATEXT(Case!D62) -> =AVERAGEIF($H$46:$H$57;C62;$G$46:$G$57)
B38: Cek Manual | C38: =AND(ISNUMBER(FIND("=",R28)),ISNUMBER(FIND("(",R28))) -> TRUE | D38: =AND(ISNUMBER(FIND("=",S28)),ISNUMBER(FIND("(",S28))) -> TRUE | E38: =AND(ISNUMBER(FIND("=",T28))) -> TRUE | F38: =AND(ISNUMBER(FIND("=",U28)),ISNUMBER(FIND("(",U28))) -> TRUE | G38: =AND(ISNUMBER(FIND("=",V28)),ISNUMBER(FIND("(",V28))) -> TRUE | H38: =AND(ISNUMBER(FIND("=",W28)),ISNUMBER(FIND("(",W28))) -> TRUE | I38: =AND(ISNUMBER(FIND("=",X28)),ISNUMBER(FIND("(",X28))) -> TRUE | J38: =AND(ISNUMBER(FIND("=",Y28))) -> TRUE | K38: =AND(R45:U45) -> TRUE | L38: =AND(ISNUMBER(FIND("=",AA28)),ISNUMBER(FIND("(",AA28))) -> TRUE | M38: =AND(ISNUMBER(FIND("=",AB28)),ISNUMBER(FIND("(",AB28))) -> TRUE | N38: =AND(ISNUMBER(FIND("=",AC28)),ISNUMBER(FIND("(",AC28))) -> TRUE | Q38: 11 | R38: =_xlfn.FORMULATEXT(Case!E62) -> =COUNTIF($H$46:$H$57;C62)
B39: Cek Kosong | C39: =NOT(OR(C2="",C2=0)) -> TRUE | D39: =NOT(OR(D2="",D2=0)) -> TRUE | E39: =NOT(OR(E2="",E2=0)) -> TRUE | F39: =NOT(OR(F2="",F2=0)) -> TRUE | G39: =NOT(OR(G2="",G2=0)) -> TRUE | H39: =NOT(OR(H2="",H2=0)) -> TRUE | I39: =NOT(OR(I2="",I2=0)) -> TRUE | J39: =NOT(OR(J2="",J2=0)) -> TRUE | ... N39: =NOT(OR(N2="",N2=0)) -> TRUE | Q39: 12 | R39: =_xlfn.FORMULATEXT(Case!F62) -> =SUMIF($H$46:$H$57;C62;$L$46:$L$57)
B40: Cek Drag | C40: =Q19 -> TRUE | D40: =R19 -> TRUE | E40: =S19 -> TRUE | F40: =T19 -> TRUE | G40: =U19 -> TRUE | H40: =V19 -> TRUE | I40: =W19 -> TRUE | J40: =X19 -> TRUE | ... N40: =AB19 -> TRUE
B42: Final Hasil | C42: =AND(C38:C40) -> TRUE | D42: =AND(D38:D40) -> TRUE | E42: =AND(E38:E40) -> TRUE | F42: =AND(F38:F40) -> TRUE | G42: =AND(G38:G40) -> TRUE | H42: =AND(H38:H40) -> TRUE | I42: =AND(I38:I40) -> TRUE | J42: =AND(J38:J40) -> TRUE | ... N42: =AND(N38:N40) -> TRUE | R42: 91 | S42: 92 | T42: 93 | U42: 94
R43: =_xlfn.FORMULATEXT(Case!L58) -> =SUM($L$46:$L$57) | S43: =_xlfn.FORMULATEXT(Case!L59) -> =MAX($L$46:$L$57) | T43: =_xlfn.FORMULATEXT(Case!L60) -> =MIN($L$46:$L$57) | U43: =_xlfn.FORMULATEXT(Case!L61) -> =AVERAGE($L$46:$L$57)
...
