Workbook
Name _15_AJEH: DF!$D$89
Name _41_DAC0: DF!$D$87
Name kode_jawaban: DF!$D$91

Sheet XL-Test
B1: Medium Level (⭐⭐)
B2: KODE SOAL | C2: SBEM012 | E2: KODE JAWABAN | F2: =kode_jawaban -> ML2|41-DAC0;18-1ACB;2C-3310E;4E-93D3A;20-19CEC6;3E-1A7043
B4: Hari ini | C4: 45960
E5: 1 | F5: 2 | G5: 3 | H5: 4 | I5: 5 | J5: 6
B6: Nama | C6: Tempat Lahir | D6: Tanggal Lahir | E6: Umur (Dalam Tahun) | F6: Umur (Dalam Bulan) | G6: Umur (Dalam Hari) | H6: Umur Lengkap | I6: Ulang Tahun Ke 60th | J6: Dana Pensiun
B7: Adi Pratama | C7: Jakarta | D7: 36537 | E7: =DATEDIF(D7,$C$4,"Y") -> 25 | F7: =DATEDIF(D7,$C$4,"M") -> 309 | G7: =DATEDIF(D7,$C$4,"D") -> 9423 | H7: {=_xlfn.TEXTJOIN(" ",1,TEXT(DATEDIF(D7,$C$4,{"Y";"YM";"MD"}),{"[>0]0 ""Tahun"";;";"[>0]0 ""Bulan"";;";"[>0]0 ""Hari"";;"}))} -> 25 Tahun 9 Bulan 18 Hari | I7: =EDATE(D7,60*12) -> 58452 | J7: =EOMONTH(I7,4*12)+1 -> 59933
B8: Budi Santoso | C8: Bandung | D8: 39591 | E8: =DATEDIF(D8,$C$4,"Y") -> 17 | F8: =DATEDIF(D8,$C$4,"M") -> 209 | G8: =DATEDIF(D8,$C$4,"D") -> 6369 | H8: {=_xlfn.TEXTJOIN(" ",1,TEXT(DATEDIF(D8,$C$4,{"Y";"YM";"MD"}),{"[>0]0 ""Tahun"";;";"[>0]0 ""Bulan"";;";"[>0]0 ""Hari"";;"}))} -> 17 Tahun 5 Bulan 7 Hari | I8: =EDATE(D8,60*12) -> 61506 | J8: =EOMONTH(I8,4*12)+1 -> 62976
B9: Citra Wulandari | C9: Surabaya | D9: 34897 | E9: =DATEDIF(D9,$C$4,"Y") -> 30 | F9: =DATEDIF(D9,$C$4,"M") -> 363 | G9: =DATEDIF(D9,$C$4,"D") -> 11063 | H9: {=_xlfn.TEXTJOIN(" ",1,TEXT(DATEDIF(D9,$C$4,{"Y";"YM";"MD"}),{"[>0]0 ""Tahun"";;";"[>0]0 ""Bulan"";;";"[>0]0 ""Hari"";;"}))} -> 30 Tahun 3 Bulan 13 Hari | I9: =EDATE(D9,60*12) -> 56812 | J9: =EOMONTH(I9,4*12)+1 -> 58288
B10: Dewi Lestari | C10: Medan | D10: 33888 | E10: =DATEDIF(D10,$C$4,"Y") -> 33 | F10: =DATEDIF(D10,$C$4,"M") -> 396 | G10: =DATEDIF(D10,$C$4,"D") -> 12072 | H10: {=_xlfn.TEXTJOIN(" ",1,TEXT(DATEDIF(D10,$C$4,{"Y";"YM";"MD"}),{"[>0]0 ""Tahun"";;";"[>0]0 ""Bulan"";;";"[>0]0 ""Hari"";;"}))} -> 33 Tahun 19 Hari | I10: =EDATE(D10,60*12) -> 55803 | J10: =EOMONTH(I10,4*12)+1 -> 57285
B11: Eko Saputra | C11: Semarang | D11: 45010 | E11: =DATEDIF(D11,$C$4,"Y") -> 2 | F11: =DATEDIF(D11,$C$4,"M") -> 31 | G11: =DATEDIF(D11,$C$4,"D") -> 950 | H11: {=_xlfn.TEXTJOIN(" ",1,TEXT(DATEDIF(D11,$C$4,{"Y";"YM";"MD"}),{"[>0]0 ""Tahun"";;";"[>0]0 ""Bulan"";;";"[>0]0 ""Hari"";;"}))} -> 2 Tahun 7 Bulan 5 Hari | I11: =EDATE(D11,60*12) -> 66925 | J11: =EOMONTH(I11,4*12)+1 -> 68393
B12: Fajar Nugroho | C12: Makassar | D12: 45628 | E12: =DATEDIF(D12,$C$4,"Y") -> 0 | F12: =DATEDIF(D12,$C$4,"M") -> 10 | G12: =DATEDIF(D12,$C$4,"D") -> 332 | H12: {=_xlfn.TEXTJOIN(" ",1,TEXT(DATEDIF(D12,$C$4,{"Y";"YM";"MD"}),{"[>0]0 ""Tahun"";;";"[>0]0 ""Bulan"";;";"[>0]0 ""Hari"";;"}))} -> 10 Bulan 28 Hari | I12: =EDATE(D12,60*12) -> 67543 | J12: =EOMONTH(I12,4*12)+1 -> 69034
B13: Gita Sari | C13: Palembang | D13: 38168 | E13: =DATEDIF(D13,$C$4,"Y") -> 21 | F13: =DATEDIF(D13,$C$4,"M") -> 256 | G13: =DATEDIF(D13,$C$4,"D") -> 7792 | H13: {=_xlfn.TEXTJOIN(" ",1,TEXT(DATEDIF(D13,$C$4,{"Y";"YM";"MD"}),{"[>0]0 ""Tahun"";;";"[>0]0 ""Bulan"";;";"[>0]0 ""Hari"";;"}))} -> 21 Tahun 4 Bulan | I13: =EDATE(D13,60*12) -> 60083 | J13: =EOMONTH(I13,4*12)+1 -> 61545
B14: Hadi Wijaya | C14: Bogor | D14: 44812 | E14: =DATEDIF(D14,$C$4,"Y") -> 3 | F14: =DATEDIF(D14,$C$4,"M") -> 37 | G14: =DATEDIF(D14,$C$4,"D") -> 1148 | H14: {=_xlfn.TEXTJOIN(" ",1,TEXT(DATEDIF(D14,$C$4,{"Y";"YM";"MD"}),{"[>0]0 ""Tahun"";;";"[>0]0 ""Bulan"";;";"[>0]0 ""Hari"";;"}))} -> 3 Tahun 1 Bulan 22 Hari | I14: =EDATE(D14,60*12) -> 66727 | J14: =EOMONTH(I14,4*12)+1 -> 68211
B15: Indah Permata | C15: Depok | D15: 35114 | E15: =DATEDIF(D15,$C$4,"Y") -> 29 | F15: =DATEDIF(D15,$C$4,"M") -> 356 | G15: =DATEDIF(D15,$C$4,"D") -> 10846 | H15: {=_xlfn.TEXTJOIN(" ",1,TEXT(DATEDIF(D15,$C$4,{"Y";"YM";"MD"}),{"[>0]0 ""Tahun"";;";"[>0]0 ""Bulan"";;";"[>0]0 ""Hari"";;"}))} -> 29 Tahun 8 Bulan 11 Hari | I15: =EDATE(D15,60*12) -> 57029 | J15: =EOMONTH(I15,4*12)+1 -> 58501
B16: Joko Prabowo | C16: Bekasi | D16: 33182 | E16: =DATEDIF(D16,$C$4,"Y") -> 34 | F16: =DATEDIF(D16,$C$4,"M") -> 419 | G16: =DATEDIF(D16,$C$4,"D") -> 12778 | H16: {=_xlfn.TEXTJOIN(" ",1,TEXT(DATEDIF(D16,$C$4,{"Y";"YM";"MD"}),{"[>0]0 ""Tahun"";;";"[>0]0 ""Bulan"";;";"[>0]0 ""Hari"";;"}))} -> 34 Tahun 11 Bulan 25 Hari | I16: =EDATE(D16,60*12) -> 55097 | J16: =EOMONTH(I16,4*12)+1 -> 56584
B17: Kiki Amalia | C17: Yogyakarta | D17: 35550 | E17: =DATEDIF(D17,$C$4,"Y") -> 28 | F17: =DATEDIF(D17,$C$4,"M") -> 342 | G17: =DATEDIF(D17,$C$4,"D") -> 10410 | H17: {=_xlfn.TEXTJOIN(" ",1,TEXT(DATEDIF(D17,$C$4,{"Y";"YM";"MD"}),{"[>0]0 ""Tahun"";;";"[>0]0 ""Bulan"";;";"[>0]0 ""Hari"";;"}))} -> 28 Tahun 6 Bulan | I17: =EDATE(D17,60*12) -> 57465 | J17: =EOMONTH(I17,4*12)+1 -> 58927
B18: Lia Kusuma | C18: Malang | D18: 34202 | E18: =DATEDIF(D18,$C$4,"Y") -> 32 | F18: =DATEDIF(D18,$C$4,"M") -> 386 | G18: =DATEDIF(D18,$C$4,"D") -> 11758 | H18: {=_xlfn.TEXTJOIN(" ",1,TEXT(DATEDIF(D18,$C$4,{"Y";"YM";"MD"}),{"[>0]0 ""Tahun"";;";"[>0]0 ""Bulan"";;";"[>0]0 ""Hari"";;"}))} -> 32 Tahun 2 Bulan 9 Hari | I18: =EDATE(D18,60*12) -> 56117 | J18: =EOMONTH(I18,4*12)+1 -> 57589
... B26: Wulan Sari | C26: Kupang | D26: 40655 | E26: =DATEDIF(D26,$C$4,"Y") -> 14 | F26: =DATEDIF(D26,$C$4,"M") -> 174 | G26: =DATEDIF(D26,$C$4,"D") -> 5305 | H26: {=_xlfn.TEXTJOIN(" ",1,TEXT(DATEDIF(D26,$C$4,{"Y";"YM";"MD"}),{"[>0]0 ""Tahun"";;";"[>0]0 ""Bulan"";;";"[>0]0 ""Hari"";;"}))} -> 14 Tahun 6 Bulan 8 Hari | I26: =EDATE(D26,60*12) -> 62570 | J26: =EOMONTH(I26,4*12)+1 -> 64040
B29: Soal
B30: 1 | C30: Isi kolom Umur (Dalam Tahun) berdasarkan Tanggal Lahir sampai hari ini (C4)
C31: Misal Tanggal lahir 12 Jan 2000 maka hasilnya 25 Tahun
B33: 2 | C33: Isi kolom Umur (Dalam Bulan) berdasarkan Tanggal Lahir sampai hari ini (C4)
C34: Misal Tanggal lahir 12 Jan 2000 maka hasilnya 309 Bulan
B36: 3 | C36: Isi kolom Umur (Dalam Hari) berdasarkan Tanggal Lahir sampai hari ini (C4)
C37: Misal Tanggal lahir 12 Jan 2000 maka hasilnya 9423 hari
B39: 4 | C39: Isi kolom Umur lengkap berdasarkan Tanggal Lahir sampai hari ini (C4) tanpa menampilkan 0
C40: Misal Tanggal lahir 2 Des 2024 maka hasilnya 10 Bulan 25 Hari
C41: Misal Tanggal lahir 30 Mar 2025 maka hasilnya 7 Bulan
B43: 5 | C43: Kapan Tanggal Ulang Tahun yang ke 60
C44: Misal Tanggal lahir 12 Jan 2000 maka hasilnya 12 Jan 2060
B46: 6 | C46: Dana Pensiun diberikan 4 Tahun setelah Ulang Tahun yang ke 60 di Tanggal 1 berikutnya
C47: Misal Tanggal lahir 12 Jan 2000 dan Umur 60 di 12 Jan 2060, maka dana pensiun diberikan 1 Feb 2064
C49: Selesai mengerjakan?
C50: kirimkan Kode Soal dan Kode Jawaban diatas ke alamat : https://belajarexcel.id/xl-test/jawaban untuk mengecek hasil benar/salah

Sheet DF
A1: DF | D1: 1 | E1: 2 | F1: 3 | G1: 4 | H1: 5 | I1: 6 | P1: 1 | Q1: 2 | R1: 3 | S1: 4 | T1: 5 | U1: 6
A2: ML2 | C2: 1 | D2: ='XL-Test'!E7 -> 25 | E2: ='XL-Test'!F7 -> 309 | F2: ='XL-Test'!G7 -> 9423 | G2: =TRIM('XL-Test'!H7) -> 25 Tahun 9 Bulan 18 Hari | H2: ='XL-Test'!I7 -> 58452 | I2: ='XL-Test'!J7 -> 59933 | K2: =IFERROR(SUBSTITUTE(SUBSTITUTE(SUBSTITUTE(SUBSTITUTE(LOWER(G2),"tahun",""),"bulan",""),"hari","")," ","")*1,0)+L2+M2+N2 -> 26073 | L2: =CODE(LEFT(G2)) -> 50 | M2: =CODE(LEFT(RIGHT(G2,6))) -> 56 | N2: =CODE(LEFT(RIGHT(G2,7))) -> 49 | O2: 1 | P2: =_xlfn.FORMULATEXT('XL-Test'!E7) -> =DATEDIF(D7;$C$4;"Y") | Q2: =_xlfn.FORMULATEXT('XL-Test'!F7) -> =DATEDIF(D7;$C$4;"M") | R2: =_xlfn.FORMULATEXT('XL-Test'!G7) -> =DATEDIF(D7;$C$4;"D") | S2: =_xlfn.FORMULATEXT('XL-Test'!H7) -> =TEXTJOIN(" ";1;TEXT(DATEDIF(D7;$C$4;{"Y";"YM";"MD"});{"[>0]0 ""Tahun"";;";"[>0]0 ""Bulan"";;";"[>0]0 ""Hari"";;"})) | T2: =_xlfn.FORMULATEXT('XL-Test'!I7) -> =EDATE(D7;60*12) | U2: =_xlfn.FORMULATEXT('XL-Test'!J7) -> =EOMONTH(I7;4*12)+1
C3: 2 | D3: ='XL-Test'!E8 -> 17 | E3: ='XL-Test'!F8 -> 209 | F3: ='XL-Test'!G8 -> 6369 | G3: =TRIM('XL-Test'!H8) -> 17 Tahun 5 Bulan 7 Hari | H3: ='XL-Test'!I8 -> 61506 | I3: ='XL-Test'!J8 -> 62976 | K3: =IFERROR(SUBSTITUTE(SUBSTITUTE(SUBSTITUTE(SUBSTITUTE(LOWER(G3),"tahun",""),"bulan",""),"hari","")," ","")*1,0)+L3+M3+N3 -> 1893 | L3: =CODE(LEFT(G3)) -> 49 | M3: =CODE(LEFT(RIGHT(G3,6))) -> 55 | N3: =CODE(LEFT(RIGHT(G3,7))) -> 32 | O3: 2 | P3: =Q2 -> =DATEDIF(D7;$C$4;"M")
C4: 3 | D4: ='XL-Test'!E9 -> 30 | E4: ='XL-Test'!F9 -> 363 | F4: ='XL-Test'!G9 -> 11063 | G4: =TRIM('XL-Test'!H9) -> 30 Tahun 3 Bulan 13 Hari | H4: ='XL-Test'!I9 -> 56812 | I4: ='XL-Test'!J9 -> 58288 | K4: =IFERROR(SUBSTITUTE(SUBSTITUTE(SUBSTITUTE(SUBSTITUTE(LOWER(G4),"tahun",""),"bulan",""),"hari","")," ","")*1,0)+L4+M4+N4 -> 30464 | L4: =CODE(LEFT(G4)) -> 51 | M4: =CODE(LEFT(RIGHT(G4,6))) -> 51 | N4: =CODE(LEFT(RIGHT(G4,7))) -> 49 | O4: 3 | P4: =R2 -> =DATEDIF(D7;$C$4;"D")
C5: 4 | D5: ='XL-Test'!E10 -> 33 | E5: ='XL-Test'!F10 -> 396 | F5: ='XL-Test'!G10 -> 12072 | G5: =TRIM('XL-Test'!H10) -> 33 Tahun 19 Hari | H5: ='XL-Test'!I10 -> 55803 | I5: ='XL-Test'!J10 -> 57285 | K5: =IFERROR(SUBSTITUTE(SUBSTITUTE(SUBSTITUTE(SUBSTITUTE(LOWER(G5),"tahun",""),"bulan",""),"hari","")," ","")*1,0)+L5+M5+N5 -> 3476 | L5: =CODE(LEFT(G5)) -> 51 | M5: =CODE(LEFT(RIGHT(G5,6))) -> 57 | N5: =CODE(LEFT(RIGHT(G5,7))) -> 49 | O5: 4 | P5: =S2 -> =TEXTJOIN(" ";1;TEXT(DATEDIF(D7;$C$4;{"Y";"YM";"MD"});{"[>0]0 ""Tahun"";;";"[>0]0 ""Bulan"";;";"[>0]0 ""Hari"";;"}))
C6: 5 | D6: ='XL-Test'!E11 -> 2 | E6: ='XL-Test'!F11 -> 31 | F6: ='XL-Test'!G11 -> 950 | G6: =TRIM('XL-Test'!H11) -> 2 Tahun 7 Bulan 5 Hari | H6: ='XL-Test'!I11 -> 66925 | I6: ='XL-Test'!J11 -> 68393 | K6: =IFERROR(SUBSTITUTE(SUBSTITUTE(SUBSTITUTE(SUBSTITUTE(LOWER(G6),"tahun",""),"bulan",""),"hari","")," ","")*1,0)+L6+M6+N6 -> 410 | L6: =CODE(LEFT(G6)) -> 50 | M6: =CODE(LEFT(RIGHT(G6,6))) -> 53 | N6: =CODE(LEFT(RIGHT(G6,7))) -> 32 | O6: 5 | P6: =T2 -> =EDATE(D7;60*12)
C7: 6 | D7: ='XL-Test'!E12 -> 0 | E7: ='XL-Test'!F12 -> 10 | F7: ='XL-Test'!G12 -> 332 | G7: =TRIM('XL-Test'!H12) -> 10 Bulan 28 Hari | H7: ='XL-Test'!I12 -> 67543 | I7: ='XL-Test'!J12 -> 69034 | K7: =IFERROR(SUBSTITUTE(SUBSTITUTE(SUBSTITUTE(SUBSTITUTE(LOWER(G7),"tahun",""),"bulan",""),"hari","")," ","")*1,0)+L7+M7+N7 -> 1183 | L7: =CODE(LEFT(G7)) -> 49 | M7: =CODE(LEFT(RIGHT(G7,6))) -> 56 | N7: =CODE(LEFT(RIGHT(G7,7))) -> 50 | O7: 6 | P7: =U2 -> =EOMONTH(I7;4*12)+1
C8: 7 | D8: ='XL-Test'!E13 -> 21 | E8: ='XL-Test'!F13 -> 256 | F8: ='XL-Test'!G13 -> 7792 | G8: =TRIM('XL-Test'!H13) -> 21 Tahun 4 Bulan | H8: ='XL-Test'!I13 -> 60083 | I8: ='XL-Test'!J13 -> 61545 | K8: =IFERROR(SUBSTITUTE(SUBSTITUTE(SUBSTITUTE(SUBSTITUTE(LOWER(G8),"tahun",""),"bulan",""),"hari","")," ","")*1,0)+L8+M8+N8 -> 348 | L8: =CODE(LEFT(G8)) -> 50 | M8: =CODE(LEFT(RIGHT(G8,6))) -> 32 | N8: =CODE(LEFT(RIGHT(G8,7))) -> 52
C9: 8 | D9: ='XL-Test'!E14 -> 3 | E9: ='XL-Test'!F14 -> 37 | F9: ='XL-Test'!G14 -> 1148 | G9: =TRIM('XL-Test'!H14) -> 3 Tahun 1 Bulan 22 Hari | H9: ='XL-Test'!I14 -> 66727 | I9: ='XL-Test'!J14 -> 68211 | K9: =IFERROR(SUBSTITUTE(SUBSTITUTE(SUBSTITUTE(SUBSTITUTE(LOWER(G9),"tahun",""),"bulan",""),"hari","")," ","")*1,0)+L9+M9+N9 -> 3273 | L9: =CODE(LEFT(G9)) -> 51 | M9: =CODE(LEFT(RIGHT(G9,6))) -> 50 | N9: =CODE(LEFT(RIGHT(G9,7))) -> 50
C10: 9 | D10: ='XL-Test'!E15 -> 29 | E10: ='XL-Test'!F15 -> 356 | F10: ='XL-Test'!G15 -> 10846 | G10: =TRIM('XL-Test'!H15) -> 29 Tahun 8 Bulan 11 Hari | H10: ='XL-Test'!I15 -> 57029 | I10: ='XL-Test'!J15 -> 58501 | K10: =IFERROR(SUBSTITUTE(SUBSTITUTE(SUBSTITUTE(SUBSTITUTE(LOWER(G10),"tahun",""),"bulan",""),"hari","")," ","")*1,0)+L10+M10+N10 -> 29959 | L10: =CODE(LEFT(G10)) -> 50 | M10: =CODE(LEFT(RIGHT(G10,6))) -> 49 | N10: =CODE(LEFT(RIGHT(G10,7))) -> 49
C11: 10 | D11: ='XL-Test'!E16 -> 34 | E11: ='XL-Test'!F16 -> 419 | F11: ='XL-Test'!G16 -> 12778 | G11: =TRIM('XL-Test'!H16) -> 34 Tahun 11 Bulan 25 Hari | H11: ='XL-Test'!I16 -> 55097 | I11: ='XL-Test'!J16 -> 56584 | K11: =IFERROR(SUBSTITUTE(SUBSTITUTE(SUBSTITUTE(SUBSTITUTE(LOWER(G11),"tahun",""),"bulan",""),"hari","")," ","")*1,0)+L11+M11+N11 -> 341279 | L11: =CODE(LEFT(G11)) -> 51 | M11: =CODE(LEFT(RIGHT(G11,6))) -> 53 | N11: =CODE(LEFT(RIGHT(G11,7))) -> 50
C12: 11 | D12: ='XL-Test'!E17 -> 28 | E12: ='XL-Test'!F17 -> 342 | F12: ='XL-Test'!G17 -> 10410 | G12: =TRIM('XL-Test'!H17) -> 28 Tahun 6 Bulan | H12: ='XL-Test'!I17 -> 57465 | I12: ='XL-Test'!J17 -> 58927 | K12: =IFERROR(SUBSTITUTE(SUBSTITUTE(SUBSTITUTE(SUBSTITUTE(LOWER(G12),"tahun",""),"bulan",""),"hari","")," ","")*1,0)+L12+M12+N12 -> 422 | L12: =CODE(LEFT(G12)) -> 50 | M12: =CODE(LEFT(RIGHT(G12,6))) -> 32 | N12: =CODE(LEFT(RIGHT(G12,7))) -> 54
C13: 12 | D13: ='XL-Test'!E18 -> 32 | E13: ='XL-Test'!F18 -> 386 | F13: ='XL-Test'!G18 -> 11758 | G13: =TRIM('XL-Test'!H18) -> 32 Tahun 2 Bulan 9 Hari | H13: ='XL-Test'!I18 -> 56117 | I13: ='XL-Test'!J18 -> 57589 | K13: =IFERROR(SUBSTITUTE(SUBSTITUTE(SUBSTITUTE(SUBSTITUTE(LOWER(G13),"tahun",""),"bulan",""),"hari","")," ","")*1,0)+L13+M13+N13 -> 3369 | L13: =CODE(LEFT(G13)) -> 51 | M13: =CODE(LEFT(RIGHT(G13,6))) -> 57 | N13: =CODE(LEFT(RIGHT(G13,7))) -> 32
C14: 13 | D14: ='XL-Test'!E19 -> 33 | E14: ='XL-Test'!F19 -> 399 | F14: ='XL-Test'!G19 -> 12174 | G14: =TRIM('XL-Test'!H19) -> 33 Tahun 3 Bulan 29 Hari | H14: ='XL-Test'!I19 -> 55701 | I14: ='XL-Test'!J19 -> 57193 | K14: =IFERROR(SUBSTITUTE(SUBSTITUTE(SUBSTITUTE(SUBSTITUTE(LOWER(G14),"tahun",""),"bulan",""),"hari","")," ","")*1,0)+L14+M14+N14 -> 33487 | L14: =CODE(LEFT(G14)) -> 51 | M14: =CODE(LEFT(RIGHT(G14,6))) -> 57 | N14: =CODE(LEFT(RIGHT(G14,7))) -> 50
C15: 14 | D15: ='XL-Test'!E20 -> 30 | E15: ='XL-Test'!F20 -> 360 | F15: ='XL-Test'!G20 -> 10973 | G15: =TRIM('XL-Test'!H20) -> 30 Tahun 15 Hari | H15: ='XL-Test'!I20 -> 56902 | I15: ='XL-Test'!J20 -> 58380 | K15: =IFERROR(SUBSTITUTE(SUBSTITUTE(SUBSTITUTE(SUBSTITUTE(LOWER(G15),"tahun",""),"bulan",""),"hari","")," ","")*1,0)+L15+M15+N15 -> 3168 | L15: =CODE(LEFT(G15)) -> 51 | M15: =CODE(LEFT(RIGHT(G15,6))) -> 53 | N15: =CODE(LEFT(RIGHT(G15,7))) -> 49
C16: 15 | D16: ='XL-Test'!E21 -> 35 | E16: ='XL-Test'!F21 -> 424 | F16: ='XL-Test'!G21 -> 12930 | G16: =TRIM('XL-Test'!H21) -> 35 Tahun 4 Bulan 24 Hari | H16: ='XL-Test'!I21 -> 54945 | I16: ='XL-Test'!J21 -> 56431 | K16: =IFERROR(SUBSTITUTE(SUBSTITUTE(SUBSTITUTE(SUBSTITUTE(LOWER(G16),"tahun",""),"bulan",""),"hari","")," ","")*1,0)+L16+M16+N16 -> 35577 | L16: =CODE(LEFT(G16)) -> 51 | M16: =CODE(LEFT(RIGHT(G16,6))) -> 52 | N16: =CODE(LEFT(RIGHT(G16,7))) -> 50
C17: 16 | D17: ='XL-Test'!E22 -> 0 | E17: ='XL-Test'!F22 -> 1 | F17: ='XL-Test'!G22 -> 51 | G17: =TRIM('XL-Test'!H22) -> 1 Bulan 21 Hari | H17: ='XL-Test'!I22 -> 67824 | I17: ='XL-Test'!J22 -> 69307 | K17: =IFERROR(SUBSTITUTE(SUBSTITUTE(SUBSTITUTE(SUBSTITUTE(LOWER(G17),"tahun",""),"bulan",""),"hari","")," ","")*1,0)+L17+M17+N17 -> 269 | L17: =CODE(LEFT(G17)) -> 49 | M17: =CODE(LEFT(RIGHT(G17,6))) -> 49 | N17: =CODE(LEFT(RIGHT(G17,7))) -> 50
C18: 17 | D18: ='XL-Test'!E23 -> 0 | E18: ='XL-Test'!F23 -> 7 | F18: ='XL-Test'!G23 -> 214 | G18: =TRIM('XL-Test'!H23) -> 7 Bulan | H18: ='XL-Test'!I23 -> 67661 | I18: ='XL-Test'!J23 -> 69124 | K18: =IFERROR(SUBSTITUTE(SUBSTITUTE(SUBSTITUTE(SUBSTITUTE(LOWER(G18),"tahun",""),"bulan",""),"hari","")," ","")*1,0)+L18+M18+N18 -> 149 | L18: =CODE(LEFT(G18)) -> 55 | M18: =CODE(LEFT(RIGHT(G18,6))) -> 32 | N18: =CODE(LEFT(RIGHT(G18,7))) -> 55
C19: 18 | D19: ='XL-Test'!E24 -> 29 | E19: ='XL-Test'!F24 -> 353 | F19: ='XL-Test'!G24 -> 10746 | G19: =TRIM('XL-Test'!H24) -> 29 Tahun 5 Bulan 1 Hari | H19: ='XL-Test'!I24 -> 57129 | I19: ='XL-Test'!J24 -> 58593 | K19: =IFERROR(SUBSTITUTE(SUBSTITUTE(SUBSTITUTE(SUBSTITUTE(LOWER(G19),"tahun",""),"bulan",""),"hari","")," ","")*1,0)+L19+M19+N19 -> 3082 | L19: =CODE(LEFT(G19)) -> 50 | M19: =CODE(LEFT(RIGHT(G19,6))) -> 49 | N19: =CODE(LEFT(RIGHT(G19,7))) -> 32
... C21: 20 | D21: ='XL-Test'!E26 -> 14 | E21: ='XL-Test'!F26 -> 174 | F21: ='XL-Test'!G26 -> 5305 | G21: =TRIM('XL-Test'!H26) -> 14 Tahun 6 Bulan 8 Hari | H21: ='XL-Test'!I26 -> 62570 | I21: ='XL-Test'!J26 -> 64040 | K21: =IFERROR(SUBSTITUTE(SUBSTITUTE(SUBSTITUTE(SUBSTITUTE(LOWER(G21),"tahun",""),"bulan",""),"hari","")," ","")*1,0)+L21+M21+N21 -> 1605 | L21: =CODE(LEFT(G21)) -> 49 | M21: =CODE(LEFT(RIGHT(G21,6))) -> 56 | N21: =CODE(LEFT(RIGHT(G21,7))) -> 32
C24: Value | D24: =(SUM(D2:D21)+D3+D5+D7+D10+D14+D17+D19+D21)*100 -> 56000 | E24: =SUM(E2:E21)+E3+E5+E7+E10+E14+E17+E19+E21 -> 6859 | F24: =SUM(F2:F21)+F3+F5+F7+F10+F14+F17+F19+F21 -> 209166 | G24: =K24 -> 605498 | H24: =SUM(H2:H21)+H3+H5+H7+H10+H14+H17+H19+H21 -> 1691334 | I24: =SUM(I2:I21)+I3+I5+I7+I10+I14+I17+I19+I21 -> 1732675 | K24: =SUM(K2:K21)+K3+K5+K7+K10+K14+K17+K19+K21 -> 605498
D25: =DEC2HEX(D24) -> DAC0 | E25: =DEC2HEX(E24) -> 1ACB | F25: =DEC2HEX(F24) -> 3310E | G25: =DEC2HEX(G24) -> 93D3A | H25: =DEC2HEX(H24) -> 19CEC6 | I25: =DEC2HEX(I24) -> 1A7043
C27: Random | D27: 6150 | E27: 1991 | F27: 3871 | G27: 7181 | H27: 2455 | I27: 5363
D28: =DEC2HEX(D27) -> 1806 | E28: =DEC2HEX(E27) -> 7C7 | F28: =DEC2HEX(F27) -> F1F | G28: =DEC2HEX(G27) -> 1C0D | H28: =DEC2HEX(H27) -> 997 | I28: =DEC2HEX(I27) -> 14F3
C30: TRUE | D30: =DEC2HEX(LEFT(D27,2)+COLUMN()) -> 41 | E30: =DEC2HEX(LEFT(E27,2)+COLUMN()) -> 18 | F30: =DEC2HEX(LEFT(F27,2)+COLUMN()) -> 2C | G30: =DEC2HEX(LEFT(G27,2)+COLUMN()) -> 4E | H30: =DEC2HEX(LEFT(H27,2)+COLUMN()) -> 20 | I30: =DEC2HEX(LEFT(I27,2)+COLUMN()) -> 3E
C31: FALSE | D31: =DEC2HEX(RIGHT(D27,2)+COLUMN()) -> 36 | E31: =DEC2HEX(RIGHT(E27,2)+COLUMN()) -> 60 | F31: =DEC2HEX(RIGHT(F27,2)+COLUMN()) -> 4D | G31: =DEC2HEX(RIGHT(G27,2)+COLUMN()) -> 58 | H31: =DEC2HEX(RIGHT(H27,2)+COLUMN()) -> 3F | I31: =DEC2HEX(RIGHT(I27,2)+COLUMN()) -> 48
C34: Cek Man1 | D34: =NOT(OR(D2=0,D2="")) -> TRUE | E34: =NOT(OR(E2=0,E2="")) -> TRUE | F34: =NOT(OR(F2=0,F2="")) -> TRUE | G34: =NOT(OR(G2=0,G2="")) -> TRUE | H34: =NOT(OR(H2=0,H2="")) -> TRUE | I34: =NOT(OR(I2=0,I2="")) -> TRUE
C35: Cek Man2 | D35: =AND(ISNUMBER(FIND("=",P2)),ISNUMBER(FIND("(",P2))) -> TRUE | E35: =AND(ISNUMBER(FIND("=",Q2)),ISNUMBER(FIND("(",Q2))) -> TRUE | F35: =AND(ISNUMBER(FIND("=",R2)),ISNUMBER(FIND("(",R2))) -> TRUE | G35: =AND(ISNUMBER(FIND("=",S2)),ISNUMBER(FIND("(",S2))) -> TRUE | H35: =AND(ISNUMBER(FIND("=",T2)),ISNUMBER(FIND("(",T2))) -> TRUE | I35: =AND(ISNUMBER(FIND("=",U2)),ISNUMBER(FIND("(",U2))) -> TRUE
C36: Cek Drag | D36: =D80 -> TRUE | E36: =E80 -> TRUE | F36: =F80 -> TRUE | G36: =G80 -> TRUE | H36: =H80 -> TRUE | I36: =I80 -> TRUE
C37: ** | D37: =AND(D34:D36) -> TRUE | E37: =AND(E34:E36) -> TRUE | F37: =AND(F34:F36) -> TRUE | G37: =AND(G34:G36) -> TRUE | H37: =AND(H34:H36) -> TRUE | I37: =AND(I34:I36) -> TRUE
C39: Cek Fung | D39: =IFERROR(LEN(P2)-LEN(SUBSTITUTE(P2,"(","")),99) -> 1 | E39: =IFERROR(LEN(Q2)-LEN(SUBSTITUTE(Q2,"(","")),99) -> 1 | F39: =IFERROR(LEN(R2)-LEN(SUBSTITUTE(R2,"(","")),99) -> 1 | G39: =IFERROR(LEN(S2)-LEN(SUBSTITUTE(S2,"(","")),99) -> 3 | H39: =IFERROR(LEN(T2)-LEN(SUBSTITUTE(T2,"(","")),99) -> 1 | I39: =IFERROR(LEN(U2)-LEN(SUBSTITUTE(U2,"(","")),99) -> 1
D40: 1 | E40: 1 | F40: 1 | G40: 6 | H40: 1 | I40: 1
D41: =D39<=D40 -> TRUE | E41: =E39<=E40 -> TRUE | F41: =F39<=F40 -> TRUE | G41: =G39<=G40 -> TRUE | H41: =H39<=H40 -> TRUE | I41: =I39<=I40 -> TRUE
C43: Cek Formula | D43: =IFERROR((LEN(P2)-LEN(SUBSTITUTE(P2,"DATEDIF","")))/7,99) -> 1 | E43: =IFERROR((LEN(Q2)-LEN(SUBSTITUTE(Q2,"DATEDIF","")))/7,99) -> 1 | F43: =IFERROR((LEN(R2)-LEN(SUBSTITUTE(R2,"DATEDIF","")))/7,99) -> 1 | G43: =IFERROR((LEN(S2)-LEN(SUBSTITUTE(S2,"DATEDIF","")))/7,99) -> 1 | H43: =IFERROR((LEN(T2)-LEN(SUBSTITUTE(T2,"DATEDIF","")))/7,99) -> 0 | I43: =IFERROR((LEN(U2)-LEN(SUBSTITUTE(U2,"DATEDIF","")))/7,99) -> 0
D44: 1 | E44: 1 | F44: 1 | G44: 3
D45: =D43<=D44 -> TRUE | E45: =E43<=E44 -> TRUE | F45: =F43<=F44 -> TRUE | G45: =G43<=G44 -> TRUE | H45: =H43<=H44 -> TRUE | I45: =I43<=I44 -> TRUE
C46: cek ff | D46: =ISNUMBER(FIND("DATEDIF",P2)) -> TRUE | E46: =ISNUMBER(FIND("DATEDIF",Q2)) -> TRUE | F46: =ISNUMBER(FIND("DATEDIF",R2)) -> TRUE | G46: =AND(ISNUMBER(FIND("DATEDIF",S2)),ISNUMBER(FIND("EXT",S2))) -> TRUE | H46: =ISNUMBER(FIND("EDA",T2)) -> TRUE | I46: =ISNUMBER(FIND("OMON",U2)) -> TRUE
C48: ** | D48: =AND(D46,D45,D41) -> TRUE | E48: =AND(E46,E45,E41) -> TRUE | F48: =AND(F46,F45,F41) -> TRUE | G48: =AND(G46,G45,G41) -> TRUE | H48: =AND(H46,H45,H41) -> TRUE | I48: =AND(I46,I45,I41) -> TRUE
B51: 7 | C51: 1 | D51: =IFERROR(LEN(_xlfn.FORMULATEXT('XL-Test'!E7)),0) -> 21 | E51: =IFERROR(LEN(_xlfn.FORMULATEXT('XL-Test'!F7)),0) -> 21 | F51: =IFERROR(LEN(_xlfn.FORMULATEXT('XL-Test'!G7)),0) -> 21 | G51: =IFERROR(LEN(_xlfn.FORMULATEXT('XL-Test'!H7)),0) -> 116 | H51: =IFERROR(LEN(_xlfn.FORMULATEXT('XL-Test'!I7)),0) -> 16 | I51: =IFERROR(LEN(_xlfn.FORMULATEXT('XL-Test'!J7)),0) -> 19
B52: 8 | C52: 2 | D52: =IFERROR(LEN(_xlfn.FORMULATEXT('XL-Test'!E8)),0) -> 21 | E52: =IFERROR(LEN(_xlfn.FORMULATEXT('XL-Test'!F8)),0) -> 21 | F52: =IFERROR(LEN(_xlfn.FORMULATEXT('XL-Test'!G8)),0) -> 21 | G52: =IFERROR(LEN(_xlfn.FORMULATEXT('XL-Test'!H8)),0) -> 116 | H52: =IFERROR(LEN(_xlfn.FORMULATEXT('XL-Test'!I8)),0) -> 16 | I52: =IFERROR(LEN(_xlfn.FORMULATEXT('XL-Test'!J8)),0) -> 19
...

Sheet About
C6: XL-TEST adalah platform inovatif yang menyediakan latihan Excel interaktif dengan pemeriksaan otomatis,
C7: sehingga pengguna dapat langsung mengetahui jawaban yang benar maupun salah.
C10: Terdapat 5 Level soal :
D12: Easy Level | F12: (⭐)
D13: Medium Level | F13: (⭐⭐)
D14: Hard Level | F14: (⭐⭐⭐)
D15: Extreme Level | F15: (⭐⭐⭐⭐)
D16: Championship Level | F16: (⭐⭐⭐⭐⭐)
C19: Free Access
C20: https://belajarexcel.id/xl-test/
