Workbook
Name kode_jawaban: DF!$D$56

Sheet XL-Test
C1: Medium Level (⭐⭐)
C2: KODE SOAL | D2: SBEM009 | E2: KODE JAWABAN | F2: =kode_jawaban -> MI2|1C1-1BBA1;B41-27EA1;111-F3C1;151-559E1;201-C631;C21-CBF1;1F1-C301;211-CC61
B5: Daftar Karyawan & Kontak | F5: 1 | G5: 2 | H5: 3 | I5: 4 | J5: 5 | K5: 6 | L5: 7 | M5: 8
B6: NO | C6: NAMA LENGKAP | D6: EMAIL | E6: JABATAN | F6: Posisi huruf "A/a" (kecil atau besar) | G6: Posisi huruf "a" (huruf kecil) | H6: Posisi huruf "A" (huruf besar) | I6: Jumlah Karakter Username | J6: Username | K6: Domain | L6: TLD | M6: Level Jabatan
B8: 1 | C8: Loka Wiranta | D8: loka.wiranta@maildummy.com | E8: Staff Admin | F8: =IFERROR(SEARCH("a",C8),0) -> 4 | G8: =IFERROR(FIND("a",C8),0) -> 4 | H8: =IFERROR(FIND("A",C8),0) -> 0 | I8: =FIND("@",D8,1)-1 -> 12 | J8: =LEFT(D8,I8) -> loka.wiranta | K8: =RIGHT(D8,LEN(D8)-FIND("@",D8)) -> maildummy.com | L8: =RIGHT(K8,LEN(K8)-FIND(".",K8)) -> com | M8: =IF(ISNUMBER(SEARCH("Manager",E8)),"Manajerial","Staff") -> Staff
B9: 2 | C9: Hana Lin | D9: hana.lin@techdummy.com | E9: Marketing Officer | F9: =IFERROR(SEARCH("a",C9),0) -> 2 | G9: =IFERROR(FIND("a",C9),0) -> 2 | H9: =IFERROR(FIND("A",C9),0) -> 0 | I9: =FIND("@",D9,1)-1 -> 8 | J9: =LEFT(D9,I9) -> hana.lin | K9: =RIGHT(D9,LEN(D9)-FIND("@",D9)) -> techdummy.com | L9: =RIGHT(K9,LEN(K9)-FIND(".",K9)) -> com | M9: =IF(ISNUMBER(SEARCH("Manager",E9)),"Manajerial","Staff") -> Staff
B10: 3 | C10: Antonio Maheswara | D10: antonio.maheswara@ruyitech.id | E10: Data Analyst | F10: =IFERROR(SEARCH("a",C10),0) -> 1 | G10: =IFERROR(FIND("a",C10),0) -> 10 | H10: =IFERROR(FIND("A",C10),0) -> 1 | I10: =FIND("@",D10,1)-1 -> 17 | J10: =LEFT(D10,I10) -> antonio.maheswara | K10: =RIGHT(D10,LEN(D10)-FIND("@",D10)) -> ruyitech.id | L10: =RIGHT(K10,LEN(K10)-FIND(".",K10)) -> id | M10: =IF(ISNUMBER(SEARCH("Manager",E10)),"Manajerial","Staff") -> Staff
B11: 4 | C11: Vanya Ruselina | D11: vanyareselina@techdummy.co.id | E11: Staff Keuangan | F11: =IFERROR(SEARCH("a",C11),0) -> 2 | G11: =IFERROR(FIND("a",C11),0) -> 2 | H11: =IFERROR(FIND("A",C11),0) -> 0 | I11: =FIND("@",D11,1)-1 -> 13 | J11: =LEFT(D11,I11) -> vanyareselina | K11: =RIGHT(D11,LEN(D11)-FIND("@",D11)) -> techdummy.co.id | L11: =RIGHT(K11,LEN(K11)-FIND(".",K11)) -> co.id | M11: =IF(ISNUMBER(SEARCH("Manager",E11)),"Manajerial","Staff") -> Staff
B12: 5 | C12: Reza Tarmoko | D12: reza.tarmoko@dummymail.com | E12: HR Manager | F12: =IFERROR(SEARCH("a",C12),0) -> 4 | G12: =IFERROR(FIND("a",C12),0) -> 4 | H12: =IFERROR(FIND("A",C12),0) -> 0 | I12: =FIND("@",D12,1)-1 -> 12 | J12: =LEFT(D12,I12) -> reza.tarmoko | K12: =RIGHT(D12,LEN(D12)-FIND("@",D12)) -> dummymail.com | L12: =RIGHT(K12,LEN(K12)-FIND(".",K12)) -> com | M12: =IF(ISNUMBER(SEARCH("Manager",E12)),"Manajerial","Staff") -> Manajerial
B13: 6 | C13: Dargo Mawesta | D13: dargo.mawesta@dummy.com | E13: Software Engineer | F13: =IFERROR(SEARCH("a",C13),0) -> 2 | G13: =IFERROR(FIND("a",C13),0) -> 2 | H13: =IFERROR(FIND("A",C13),0) -> 0 | I13: =FIND("@",D13,1)-1 -> 13 | J13: =LEFT(D13,I13) -> dargo.mawesta | K13: =RIGHT(D13,LEN(D13)-FIND("@",D13)) -> dummy.com | L13: =RIGHT(K13,LEN(K13)-FIND(".",K13)) -> com | M13: =IF(ISNUMBER(SEARCH("Manager",E13)),"Manajerial","Staff") -> Staff
B14: 7 | C14: Tisye Avendra | D14: tisyeavendra@mailtech.co.id | E14: Marketing Manager | F14: =IFERROR(SEARCH("a",C14),0) -> 7 | G14: =IFERROR(FIND("a",C14),0) -> 13 | H14: =IFERROR(FIND("A",C14),0) -> 7 | I14: =FIND("@",D14,1)-1 -> 12 | J14: =LEFT(D14,I14) -> tisyeavendra | K14: =RIGHT(D14,LEN(D14)-FIND("@",D14)) -> mailtech.co.id | L14: =RIGHT(K14,LEN(K14)-FIND(".",K14)) -> co.id | M14: =IF(ISNUMBER(SEARCH("Manager",E14)),"Manajerial","Staff") -> Manajerial
B15: 8 | C15: Erik Reno | D15: erik.reno@techdummy.com | E15: Staff Admin | F15: =IFERROR(SEARCH("a",C15),0) -> 0 | G15: =IFERROR(FIND("a",C15),0) -> 0 | H15: =IFERROR(FIND("A",C15),0) -> 0 | I15: =FIND("@",D15,1)-1 -> 9 | J15: =LEFT(D15,I15) -> erik.reno | K15: =RIGHT(D15,LEN(D15)-FIND("@",D15)) -> techdummy.com | L15: =RIGHT(K15,LEN(K15)-FIND(".",K15)) -> com | M15: =IF(ISNUMBER(SEARCH("Manager",E15)),"Manajerial","Staff") -> Staff
B16: 9 | C16: Jefro Malantara | D16: jefro.malantara@dummy.org | E16: Financial Analyst | F16: =IFERROR(SEARCH("a",C16),0) -> 8 | G16: =IFERROR(FIND("a",C16),0) -> 8 | H16: =IFERROR(FIND("A",C16),0) -> 0 | I16: =FIND("@",D16,1)-1 -> 15 | J16: =LEFT(D16,I16) -> jefro.malantara | K16: =RIGHT(D16,LEN(D16)-FIND("@",D16)) -> dummy.org | L16: =RIGHT(K16,LEN(K16)-FIND(".",K16)) -> org | M16: =IF(ISNUMBER(SEARCH("Manager",E16)),"Manajerial","Staff") -> Staff
B17: 10 | C17: Binar Kendarta Amesti | D17: binarkendarta.amesti@maildummy.net | E17: IT Support | F17: =IFERROR(SEARCH("a",C17),0) -> 4 | G17: =IFERROR(FIND("a",C17),0) -> 4 | H17: =IFERROR(FIND("A",C17),0) -> 16 | I17: =FIND("@",D17,1)-1 -> 20 | J17: =LEFT(D17,I17) -> binarkendarta.amesti | K17: =RIGHT(D17,LEN(D17)-FIND("@",D17)) -> maildummy.net | L17: =RIGHT(K17,LEN(K17)-FIND(".",K17)) -> net | M17: =IF(ISNUMBER(SEARCH("Manager",E17)),"Manajerial","Staff") -> Staff
B18: 11 | C18: Chika Yuresta | D18: chika.yuresta@maildummy.co.id | E18: Financial Manager | F18: =IFERROR(SEARCH("a",C18),0) -> 5 | G18: =IFERROR(FIND("a",C18),0) -> 5 | H18: =IFERROR(FIND("A",C18),0) -> 0 | I18: =FIND("@",D18,1)-1 -> 13 | J18: =LEFT(D18,I18) -> chika.yuresta | K18: =RIGHT(D18,LEN(D18)-FIND("@",D18)) -> maildummy.co.id | L18: =RIGHT(K18,LEN(K18)-FIND(".",K18)) -> co.id | M18: =IF(ISNUMBER(SEARCH("Manager",E18)),"Manajerial","Staff") -> Manajerial
B19: 12 | C19: Anitha Mei Zhang | D19: anitha.meizhang@yahootech.co.id | E19: Marketing Officer | F19: =IFERROR(SEARCH("a",C19),0) -> 1 | G19: =IFERROR(FIND("a",C19),0) -> 6 | H19: =IFERROR(FIND("A",C19),0) -> 1 | I19: =FIND("@",D19,1)-1 -> 15 | J19: =LEFT(D19,I19) -> anitha.meizhang | K19: =RIGHT(D19,LEN(D19)-FIND("@",D19)) -> yahootech.co.id | L19: =RIGHT(K19,LEN(K19)-FIND(".",K19)) -> co.id | M19: =IF(ISNUMBER(SEARCH("Manager",E19)),"Manajerial","Staff") -> Staff
... B22: 15 | C22: Song Zuer Yang | D22: songzueryang@yahoomy.com | E22: Staff Keuangan | F22: =IFERROR(SEARCH("a",C22),0) -> 12 | G22: =IFERROR(FIND("a",C22),0) -> 12 | H22: =IFERROR(FIND("A",C22),0) -> 0 | I22: =FIND("@",D22,1)-1 -> 12 | J22: =LEFT(D22,I22) -> songzueryang | K22: =RIGHT(D22,LEN(D22)-FIND("@",D22)) -> yahoomy.com | L22: =RIGHT(K22,LEN(K22)-FIND(".",K22)) -> com | M22: =IF(ISNUMBER(SEARCH("Manager",E22)),"Manajerial","Staff") -> Staff
C24: Sudah selesai mengerjakan?
C25: Kirimkan Kode Soal dan Kode Jawaban ke alamat : https://belajarexcel.id/xl-test/jawaban untuk mengecek hasil benar/salah
C27: Soal
B28: 1 | C28: Isi Posisi Hurup A (baik besar ataupun kecil) pertama di Nama Lengkap jika tidak ada, isi dengan 0
B29: 2 | C29: Isi Posisi Hurup a (Hurup Kecil) pertama di Nama Lengkap jika tidak ada, isi dengan 0
B30: 3 | C30: Isi Posisi Hurup A (Hurup Besar) pertama di Nama Lengkap jika tidak ada, isi dengan 0
B31: 4 | C31: Berapa Jumlah Karakter Username Email
B32: 5 | C32: Isi Kolom Username dengan Username Email
B33: 6 | C33: Isi Kolom Domain dengan Domain Email
B34: 7 | C34: Isi Kolom TLD dengan TLD Domain Email
B35: 8 | C35: Isi kolom Lebel Jabatan jika Jabatan yang mengandung kata "Manager", maka tampilkan "Manajerial", jika tidak tampilkan "Staff"

Sheet DF
A1: DEF | D1: 1 | E1: 2 | F1: 3 | G1: 4 | H1: 5 | I1: 6 | J1: 7 | K1: 8 | T1: 1 | U1: 2 | V1: 3 | W1: 4 | X1: 5 | Y1: 6 | Z1: 7 | AA1: 8
A2: MI2 | C2: 1 | D2: ='XL-Test'!F8 -> 4 | E2: ='XL-Test'!G8 -> 4 | F2: ='XL-Test'!H8 -> 0 | G2: ='XL-Test'!I8 -> 12 | H2: =LOWER('XL-Test'!J8) -> loka.wiranta | I2: =LOWER('XL-Test'!K8) -> maildummy.com | J2: =LOWER('XL-Test'!L8) -> com | K2: =LOWER('XL-Test'!M8) -> staff | S2: 1 | T2: =_xlfn.FORMULATEXT('XL-Test'!F8) -> =IFERROR(SEARCH("a";C8);0) | U2: =_xlfn.FORMULATEXT('XL-Test'!G8) -> =IFERROR(FIND("a";C8);0) | V2: =_xlfn.FORMULATEXT('XL-Test'!H8) -> =IFERROR(FIND("A";C8);0) | W2: =_xlfn.FORMULATEXT('XL-Test'!I8) -> =FIND("@";D8;1)-1 | X2: =_xlfn.FORMULATEXT('XL-Test'!J8) -> =LEFT(D8;I8) | Y2: =_xlfn.FORMULATEXT('XL-Test'!K8) -> =RIGHT(D8;LEN(D8)-FIND("@";D8)) | Z2: =_xlfn.FORMULATEXT('XL-Test'!L8) -> =RIGHT(K8;LEN(K8)-FIND(".";K8)) | AA2: =_xlfn.FORMULATEXT('XL-Test'!M8) -> =IF(ISNUMBER(SEARCH("Manager";E8));"Manajerial";"Staff")
A3: =A2&"|" -> MI2| | C3: 2 | D3: ='XL-Test'!F9 -> 2 | E3: ='XL-Test'!G9 -> 2 | F3: ='XL-Test'!H9 -> 0 | G3: ='XL-Test'!I9 -> 8 | H3: =LOWER('XL-Test'!J9) -> hana.lin | I3: =LOWER('XL-Test'!K9) -> techdummy.com | J3: =LOWER('XL-Test'!L9) -> com | K3: =LOWER('XL-Test'!M9) -> staff | S3: 2 | T3: =_xlfn.FORMULATEXT('XL-Test'!G8) -> =IFERROR(FIND("a";C8);0)
C4: 3 | D4: ='XL-Test'!F10 -> 1 | E4: ='XL-Test'!G10 -> 10 | F4: ='XL-Test'!H10 -> 1 | G4: ='XL-Test'!I10 -> 17 | H4: =LOWER('XL-Test'!J10) -> antonio.maheswara | I4: =LOWER('XL-Test'!K10) -> ruyitech.id | J4: =LOWER('XL-Test'!L10) -> id | K4: =LOWER('XL-Test'!M10) -> staff | S4: 3 | T4: =_xlfn.FORMULATEXT('XL-Test'!H8) -> =IFERROR(FIND("A";C8);0)
C5: 4 | D5: ='XL-Test'!F11 -> 2 | E5: ='XL-Test'!G11 -> 2 | F5: ='XL-Test'!H11 -> 0 | G5: ='XL-Test'!I11 -> 13 | H5: =LOWER('XL-Test'!J11) -> vanyareselina | I5: =LOWER('XL-Test'!K11) -> techdummy.co.id | J5: =LOWER('XL-Test'!L11) -> co.id | K5: =LOWER('XL-Test'!M11) -> staff | S5: 4 | T5: =_xlfn.FORMULATEXT('XL-Test'!I8) -> =FIND("@";D8;1)-1
C6: 5 | D6: ='XL-Test'!F12 -> 4 | E6: ='XL-Test'!G12 -> 4 | F6: ='XL-Test'!H12 -> 0 | G6: ='XL-Test'!I12 -> 12 | H6: =LOWER('XL-Test'!J12) -> reza.tarmoko | I6: =LOWER('XL-Test'!K12) -> dummymail.com | J6: =LOWER('XL-Test'!L12) -> com | K6: =LOWER('XL-Test'!M12) -> manajerial | S6: 5 | T6: =_xlfn.FORMULATEXT('XL-Test'!J8) -> =LEFT(D8;I8)
C7: 6 | D7: ='XL-Test'!F13 -> 2 | E7: ='XL-Test'!G13 -> 2 | F7: ='XL-Test'!H13 -> 0 | G7: ='XL-Test'!I13 -> 13 | H7: =LOWER('XL-Test'!J13) -> dargo.mawesta | I7: =LOWER('XL-Test'!K13) -> dummy.com | J7: =LOWER('XL-Test'!L13) -> com | K7: =LOWER('XL-Test'!M13) -> staff | S7: 6 | T7: =_xlfn.FORMULATEXT('XL-Test'!K8) -> =RIGHT(D8;LEN(D8)-FIND("@";D8))
C8: 7 | D8: ='XL-Test'!F14 -> 7 | E8: ='XL-Test'!G14 -> 13 | F8: ='XL-Test'!H14 -> 7 | G8: ='XL-Test'!I14 -> 12 | H8: =LOWER('XL-Test'!J14) -> tisyeavendra | I8: =LOWER('XL-Test'!K14) -> mailtech.co.id | J8: =LOWER('XL-Test'!L14) -> co.id | K8: =LOWER('XL-Test'!M14) -> manajerial | S8: 7 | T8: =_xlfn.FORMULATEXT('XL-Test'!L8) -> =RIGHT(K8;LEN(K8)-FIND(".";K8))
C9: 8 | D9: ='XL-Test'!F15 -> 0 | E9: ='XL-Test'!G15 -> 0 | F9: ='XL-Test'!H15 -> 0 | G9: ='XL-Test'!I15 -> 9 | H9: =LOWER('XL-Test'!J15) -> erik.reno | I9: =LOWER('XL-Test'!K15) -> techdummy.com | J9: =LOWER('XL-Test'!L15) -> com | K9: =LOWER('XL-Test'!M15) -> staff | S9: 8 | T9: =_xlfn.FORMULATEXT('XL-Test'!M8) -> =IF(ISNUMBER(SEARCH("Manager";E8));"Manajerial";"Staff")
C10: 9 | D10: ='XL-Test'!F16 -> 8 | E10: ='XL-Test'!G16 -> 8 | F10: ='XL-Test'!H16 -> 0 | G10: ='XL-Test'!I16 -> 15 | H10: =LOWER('XL-Test'!J16) -> jefro.malantara | I10: =LOWER('XL-Test'!K16) -> dummy.org | J10: =LOWER('XL-Test'!L16) -> org | K10: =LOWER('XL-Test'!M16) -> staff
C11: 10 | D11: ='XL-Test'!F17 -> 4 | E11: ='XL-Test'!G17 -> 4 | F11: ='XL-Test'!H17 -> 16 | G11: ='XL-Test'!I17 -> 20 | H11: =LOWER('XL-Test'!J17) -> binarkendarta.amesti | I11: =LOWER('XL-Test'!K17) -> maildummy.net | J11: =LOWER('XL-Test'!L17) -> net | K11: =LOWER('XL-Test'!M17) -> staff
C12: 11 | D12: ='XL-Test'!F18 -> 5 | E12: ='XL-Test'!G18 -> 5 | F12: ='XL-Test'!H18 -> 0 | G12: ='XL-Test'!I18 -> 13 | H12: =LOWER('XL-Test'!J18) -> chika.yuresta | I12: =LOWER('XL-Test'!K18) -> maildummy.co.id | J12: =LOWER('XL-Test'!L18) -> co.id | K12: =LOWER('XL-Test'!M18) -> manajerial
C13: 12 | D13: ='XL-Test'!F19 -> 1 | E13: ='XL-Test'!G19 -> 6 | F13: ='XL-Test'!H19 -> 1 | G13: ='XL-Test'!I19 -> 15 | H13: =LOWER('XL-Test'!J19) -> anitha.meizhang | I13: =LOWER('XL-Test'!K19) -> yahootech.co.id | J13: =LOWER('XL-Test'!L19) -> co.id | K13: =LOWER('XL-Test'!M19) -> staff
C14: 13 | D14: ='XL-Test'!F20 -> 7 | E14: ='XL-Test'!G20 -> 7 | F14: ='XL-Test'!H20 -> 0 | G14: ='XL-Test'!I20 -> 10 | H14: =LOWER('XL-Test'!J20) -> liu.shasha | I14: =LOWER('XL-Test'!K20) -> domaindummy.com | J14: =LOWER('XL-Test'!L20) -> com | K14: =LOWER('XL-Test'!M20) -> manajerial
C15: 14 | D15: ='XL-Test'!F21 -> 3 | E15: ='XL-Test'!G21 -> 3 | F15: ='XL-Test'!H21 -> 0 | G15: ='XL-Test'!I21 -> 12 | H15: =LOWER('XL-Test'!J21) -> zhang.rounan | I15: =LOWER('XL-Test'!K21) -> fakedomain.org | J15: =LOWER('XL-Test'!L21) -> org | K15: =LOWER('XL-Test'!M21) -> staff
C16: 15 | D16: ='XL-Test'!F22 -> 12 | E16: ='XL-Test'!G22 -> 12 | F16: ='XL-Test'!H22 -> 0 | G16: ='XL-Test'!I22 -> 12 | H16: =LOWER('XL-Test'!J22) -> songzueryang | I16: =LOWER('XL-Test'!K22) -> yahoomy.com | J16: =LOWER('XL-Test'!L22) -> com | K16: =LOWER('XL-Test'!M22) -> staff
C18: value | D18: =(SUM(D2:D16)+D2+D4+D8+D11+D13+D16)*78 -> 7098 | E18: =(SUM(E2:E16)+E2+E4+E8+E11+E13+E16)*78 -> 10218 | F18: =(SUM(F2:F16)+F2+F4+F8+F11+F13+F16)*78 -> 3900 | G18: =(SUM(G2:G16)+G2+G4+G8+G11+G13+G16)*78 -> 21918 | H18: =CODE(LEFT(H2))+CODE(RIGHT(H2))+CODE(LEFT(H3))+CODE(RIGHT(H3))+CODE(LEFT(H4))+CODE(RIGHT(H4))+CODE(LEFT(H5))+CODE(RIGHT(H5))+CODE(LEFT(H6))+CODE(RIGHT(H6))+CODE(LEFT(H7))+CODE(RIGHT(H7))+CODE(LEFT(H8))+CODE(RIGHT(H8))+CODE(LEFT(H9))+CODE(RIGHT(H9))+CODE(LEFT(H10))+CODE(RIGHT(H10))+CODE(LEFT(H11))+CODE(RIGHT(H11))+CODE(LEFT(H12))+CODE(RIGHT(H12))+CODE(LEFT(H13))+CODE(RIGHT(H13))+CODE(LEFT(H14))+CODE(RIGHT(H14))+CODE(LEFT(H15))+CODE(RIGHT(H15))+CODE(LEFT(H16))+CODE(RIGHT(H16))+LEN(H2)+LEN(H10)+LEN(H15) -> 3171 | I18: =CODE(LEFT(I2))+CODE(RIGHT(I2))+CODE(LEFT(I3))+CODE(RIGHT(I3))+CODE(LEFT(I4))+CODE(RIGHT(I4))+CODE(LEFT(I5))+CODE(RIGHT(I5))+CODE(LEFT(I6))+CODE(RIGHT(I6))+CODE(LEFT(I7))+CODE(RIGHT(I7))+CODE(LEFT(I8))+CODE(RIGHT(I8))+CODE(LEFT(I9))+CODE(RIGHT(I9))+CODE(LEFT(I10))+CODE(RIGHT(I10))+CODE(LEFT(I11))+CODE(RIGHT(I11))+CODE(LEFT(I12))+CODE(RIGHT(I12))+CODE(LEFT(I13))+CODE(RIGHT(I13))+CODE(LEFT(I14))+CODE(RIGHT(I14))+CODE(LEFT(I15))+CODE(RIGHT(I15))+CODE(LEFT(I16))+CODE(RIGHT(I16))+LEN(I2)+LEN(I10)+LEN(I15) -> 3263 | J18: =CODE(LEFT(J2))+CODE(RIGHT(J2))+CODE(LEFT(J3))+CODE(RIGHT(J3))+CODE(LEFT(J4))+CODE(RIGHT(J4))+CODE(LEFT(J5))+CODE(RIGHT(J5))+CODE(LEFT(J6))+CODE(RIGHT(J6))+CODE(LEFT(J7))+CODE(RIGHT(J7))+CODE(LEFT(J8))+CODE(RIGHT(J8))+CODE(LEFT(J9))+CODE(RIGHT(J9))+CODE(LEFT(J10))+CODE(RIGHT(J10))+CODE(LEFT(J11))+CODE(RIGHT(J11))+CODE(LEFT(J12))+CODE(RIGHT(J12))+CODE(LEFT(J13))+CODE(RIGHT(J13))+CODE(LEFT(J14))+CODE(RIGHT(J14))+CODE(LEFT(J15))+CODE(RIGHT(J15))+CODE(LEFT(J16))+CODE(RIGHT(J16))+LEN(J2)+LEN(J10)+LEN(J15) -> 3120 | K18: =CODE(LEFT(K2))+CODE(RIGHT(K2))+CODE(LEFT(K3))+CODE(RIGHT(K3))+CODE(LEFT(K4))+CODE(RIGHT(K4))+CODE(LEFT(K5))+CODE(RIGHT(K5))+CODE(LEFT(K6))+CODE(RIGHT(K6))+CODE(LEFT(K7))+CODE(RIGHT(K7))+CODE(LEFT(K8))+CODE(RIGHT(K8))+CODE(LEFT(K9))+CODE(RIGHT(K9))+CODE(LEFT(K10))+CODE(RIGHT(K10))+CODE(LEFT(K11))+CODE(RIGHT(K11))+CODE(LEFT(K12))+CODE(RIGHT(K12))+CODE(LEFT(K13))+CODE(RIGHT(K13))+CODE(LEFT(K14))+CODE(RIGHT(K14))+CODE(LEFT(K15))+CODE(RIGHT(K15))+CODE(LEFT(K16))+CODE(RIGHT(K16))+LEN(K2)+LEN(K10)+LEN(K15) -> 3270
B19: ** | D19: =IFERROR(DEC2HEX(IF(OR(D2=0,D2=""),D21,D18)),"EEEE")&D52 -> 1BBA1 | E19: =IFERROR(DEC2HEX(IF(OR(E2=0,E2=""),E21,E18)),"EEEE")&E52 -> 27EA1 | F19: =IFERROR(DEC2HEX(IF(OR(F4=0,F4=""),F21,F18)),"EEEE")&F52 -> F3C1 | G19: =IFERROR(DEC2HEX(IF(OR(G2=0,G2=""),G21,G18)),"EEEE")&G52 -> 559E1 | H19: =IFERROR(DEC2HEX(IF(OR(H2=0,H2=""),H21,H18)),"EEEE")&H52 -> C631 | I19: =IFERROR(DEC2HEX(IF(OR(I2=0,I2=""),I21,I18)),"EEEE")&I52 -> CBF1 | J19: =IFERROR(DEC2HEX(IF(OR(J2=0,J2=""),J21,J18)),"EEEE")&J52 -> C301 | K19: =IFERROR(DEC2HEX(IF(OR(K2=0,K2=""),K21,K18)),"EEEE")&K52 -> CC61
C21: Random | D21: 7275 | E21: 2890 | F21: 4509 | G21: 5435 | H21: 8218 | I21: 3106 | J21: 8164 | K21: 8558
C23: TRUE | D23: =LEFT(DEC2HEX(D21),2) -> 1C | E23: =LEFT(DEC2HEX(E21),2) -> B4 | F23: =LEFT(DEC2HEX(F21),2) -> 11 | G23: =LEFT(DEC2HEX(G21),2) -> 15 | H23: =LEFT(DEC2HEX(H21),2) -> 20 | I23: =LEFT(DEC2HEX(I21),2) -> C2 | J23: =LEFT(DEC2HEX(J21),2) -> 1F | K23: =LEFT(DEC2HEX(K21),2) -> 21
C24: FALSE | D24: =RIGHT(DEC2HEX(D21),2) -> 6B | E24: =RIGHT(DEC2HEX(E21),2) -> 4A | F24: =RIGHT(DEC2HEX(F21),2) -> 9D | G24: =RIGHT(DEC2HEX(G21),2) -> 3B | H24: =RIGHT(DEC2HEX(H21),2) -> 1A | I24: =RIGHT(DEC2HEX(I21),2) -> 22 | J24: =RIGHT(DEC2HEX(J21),2) -> E4 | K24: =RIGHT(DEC2HEX(K21),2) -> 6E
C27: Manual | D27: =AND(ISNUMBER(FIND("=",T2)),ISNUMBER(FIND("(",T2))) -> TRUE | E27: =AND(ISNUMBER(FIND("=",U2)),ISNUMBER(FIND("(",U2))) -> TRUE | F27: =AND(ISNUMBER(FIND("=",V2)),ISNUMBER(FIND("(",V2))) -> TRUE | G27: =AND(ISNUMBER(FIND("=",W2)),ISNUMBER(FIND("(",W2))) -> TRUE | H27: =AND(ISNUMBER(FIND("=",X2)),ISNUMBER(FIND("(",X2))) -> TRUE | I27: =AND(ISNUMBER(FIND("=",Y2)),ISNUMBER(FIND("(",Y2))) -> TRUE | J27: =AND(ISNUMBER(FIND("=",Z2)),ISNUMBER(FIND("(",Z2))) -> TRUE | K27: =AND(ISNUMBER(FIND("=",AA2)),ISNUMBER(FIND("(",AA2))) -> TRUE
C29: Cek Banyak | D29: =IFERROR(LEN(T2)-LEN(SUBSTITUTE(T2,"(","")),99) -> 2 | E29: =IFERROR(LEN(U2)-LEN(SUBSTITUTE(U2,"(","")),99) -> 2 | F29: =IFERROR(LEN(V2)-LEN(SUBSTITUTE(V2,"(","")),99) -> 2 | G29: =IFERROR(LEN(W2)-LEN(SUBSTITUTE(W2,"(","")),99) -> 1 | H29: =IFERROR(LEN(X2)-LEN(SUBSTITUTE(X2,"(","")),99) -> 1 | I29: =IFERROR(LEN(Y2)-LEN(SUBSTITUTE(Y2,"(","")),99) -> 3 | J29: =IFERROR(LEN(Z2)-LEN(SUBSTITUTE(Z2,"(","")),99) -> 3 | K29: =IFERROR(LEN(AA2)-LEN(SUBSTITUTE(AA2,"(","")),99) -> 3
D30: 2 | E30: 2 | F30: 2 | G30: 1 | H30: 1 | I30: 3 | J30: 3 | K30: 3
C31: Bol | D31: =(D29<=D30)+0 -> 1 | E31: =(E29<=E30)+0 -> 1 | F31: =(F29<=F30)+0 -> 1 | G31: =(G29<=G30)+0 -> 1 | H31: =(H29<=H30)+0 -> 1 | I31: =(I29<=I30)+0 -> 1 | J31: =(J29<=J30)+0 -> 1 | K31: =(K29<=K30)+0 -> 1
C33: Cek rumus | D33: =AND(ISNUMBER(FIND("IFER",T2)),ISNUMBER(FIND("SEAR",T2))) -> TRUE | E33: =AND(ISNUMBER(FIND("IFER",U2)),ISNUMBER(FIND("FIN",U2))) -> TRUE | F33: =AND(ISNUMBER(FIND("IFER",V2)),ISNUMBER(FIND("FIN",V2))) -> TRUE | G33: =AND(ISNUMBER(FIND("@",W2)),ISNUMBER(FIND("FIN",W2))) -> TRUE | H33: =AND(ISNUMBER(FIND("LEFT",X2))) -> TRUE | I33: =AND(OR(ISNUMBER(FIND("FIND",Y2)),ISNUMBER(FIND("SEAR",Y2))),ISNUMBER(FIND("RIGH",Y2))) -> TRUE | J33: =AND(OR(ISNUMBER(FIND("FIND",Z2)),ISNUMBER(FIND("SEAR",Z2))),ISNUMBER(FIND("RIGH",Z2))) -> TRUE | K33: =AND(OR(ISNUMBER(FIND("FIND",AA2)),ISNUMBER(FIND("SEAR",AA2))),ISNUMBER(FIND("IF",AA2)),ISNUMBER(FIND("IS",AA2))) -> TRUE
B34: ** | D34: =IF(D33,D23,D24)&D31 -> 1C1 | E34: =IF(E33,E23,E24)&E31 -> B41 | F34: =IF(F33,F23,F24)&F31 -> 111 | G34: =IF(G33,G23,G24)&G31 -> 151 | H34: =IF(H33,H23,H24)&H31 -> 201 | I34: =IF(I33,I23,I24)&I31 -> C21 | J34: =IF(J33,J23,J24)&J31 -> 1F1 | K34: =IF(K33,K23,K24)&K31 -> 211
C36: 10 | D36: =LEN(_xlfn.FORMULATEXT('XL-Test'!F10)) -> 27 | E36: =LEN(_xlfn.FORMULATEXT('XL-Test'!G10)) -> 25 | F36: =LEN(_xlfn.FORMULATEXT('XL-Test'!H10)) -> 25 | G36: =LEN(_xlfn.FORMULATEXT('XL-Test'!I10)) -> 18 | H36: =LEN(_xlfn.FORMULATEXT('XL-Test'!J10)) -> 14 | I36: =LEN(_xlfn.FORMULATEXT('XL-Test'!K10)) -> 34 | J36: =LEN(_xlfn.FORMULATEXT('XL-Test'!L10)) -> 34 | K36: =LEN(_xlfn.FORMULATEXT('XL-Test'!M10)) -> 57
C37: 11 | D37: =LEN(_xlfn.FORMULATEXT('XL-Test'!F11)) -> 27 | E37: =LEN(_xlfn.FORMULATEXT('XL-Test'!G11)) -> 25 | F37: =LEN(_xlfn.FORMULATEXT('XL-Test'!H11)) -> 25 | G37: =LEN(_xlfn.FORMULATEXT('XL-Test'!I11)) -> 18 | H37: =LEN(_xlfn.FORMULATEXT('XL-Test'!J11)) -> 14 | I37: =LEN(_xlfn.FORMULATEXT('XL-Test'!K11)) -> 34 | J37: =LEN(_xlfn.FORMULATEXT('XL-Test'!L11)) -> 34 | K37: =LEN(_xlfn.FORMULATEXT('XL-Test'!M11)) -> 57
C38: 12 | D38: =LEN(_xlfn.FORMULATEXT('XL-Test'!F12)) -> 27 | E38: =LEN(_xlfn.FORMULATEXT('XL-Test'!G12)) -> 25 | F38: =LEN(_xlfn.FORMULATEXT('XL-Test'!H12)) -> 25 | G38: =LEN(_xlfn.FORMULATEXT('XL-Test'!I12)) -> 18 | H38: =LEN(_xlfn.FORMULATEXT('XL-Test'!J12)) -> 14 | I38: =LEN(_xlfn.FORMULATEXT('XL-Test'!K12)) -> 34 | J38: =LEN(_xlfn.FORMULATEXT('XL-Test'!L12)) -> 34 | K38: =LEN(_xlfn.FORMULATEXT('XL-Test'!M12)) -> 57
C39: 13 | D39: =LEN(_xlfn.FORMULATEXT('XL-Test'!F13)) -> 27 | E39: =LEN(_xlfn.FORMULATEXT('XL-Test'!G13)) -> 25 | F39: =LEN(_xlfn.FORMULATEXT('XL-Test'!H13)) -> 25 | G39: =LEN(_xlfn.FORMULATEXT('XL-Test'!I13)) -> 18 | H39: =LEN(_xlfn.FORMULATEXT('XL-Test'!J13)) -> 14 | I39: =LEN(_xlfn.FORMULATEXT('XL-Test'!K13)) -> 34 | J39: =LEN(_xlfn.FORMULATEXT('XL-Test'!L13)) -> 34 | K39: =LEN(_xlfn.FORMULATEXT('XL-Test'!M13)) -> 57
C40: 14 | D40: =LEN(_xlfn.FORMULATEXT('XL-Test'!F14)) -> 27 | E40: =LEN(_xlfn.FORMULATEXT('XL-Test'!G14)) -> 25 | F40: =LEN(_xlfn.FORMULATEXT('XL-Test'!H14)) -> 25 | G40: =LEN(_xlfn.FORMULATEXT('XL-Test'!I14)) -> 18 | H40: =LEN(_xlfn.FORMULATEXT('XL-Test'!J14)) -> 14 | I40: =LEN(_xlfn.FORMULATEXT('XL-Test'!K14)) -> 34 | J40: =LEN(_xlfn.FORMULATEXT('XL-Test'!L14)) -> 34 | K40: =LEN(_xlfn.FORMULATEXT('XL-Test'!M14)) -> 57
C41: 15 | D41: =LEN(_xlfn.FORMULATEXT('XL-Test'!F15)) -> 27 | E41: =LEN(_xlfn.FORMULATEXT('XL-Test'!G15)) -> 25 | F41: =LEN(_xlfn.FORMULATEXT('XL-Test'!H15)) -> 25 | G41: =LEN(_xlfn.FORMULATEXT('XL-Test'!I15)) -> 18 | H41: =LEN(_xlfn.FORMULATEXT('XL-Test'!J15)) -> 14 | I41: =LEN(_xlfn.FORMULATEXT('XL-Test'!K15)) -> 34 | J41: =LEN(_xlfn.FORMULATEXT('XL-Test'!L15)) -> 34 | K41: =LEN(_xlfn.FORMULATEXT('XL-Test'!M15)) -> 57
C42: 16 | D42: =LEN(_xlfn.FORMULATEXT('XL-Test'!F16)) -> 27 | E42: =LEN(_xlfn.FORMULATEXT('XL-Test'!G16)) -> 25 | F42: =LEN(_xlfn.FORMULATEXT('XL-Test'!H16)) -> 25 | G42: =LEN(_xlfn.FORMULATEXT('XL-Test'!I16)) -> 18 | H42: =LEN(_xlfn.FORMULATEXT('XL-Test'!J16)) -> 14 | I42: =LEN(_xlfn.FORMULATEXT('XL-Test'!K16)) -> 34 | J42: =LEN(_xlfn.FORMULATEXT('XL-Test'!L16)) -> 34 | K42: =LEN(_xlfn.FORMULATEXT('XL-Test'!M16)) -> 57
C43: 17 | D43: =LEN(_xlfn.FORMULATEXT('XL-Test'!F17)) -> 27 | E43: =LEN(_xlfn.FORMULATEXT('XL-Test'!G17)) -> 25 | F43: =LEN(_xlfn.FORMULATEXT('XL-Test'!H17)) -> 25 | G43: =LEN(_xlfn.FORMULATEXT('XL-Test'!I17)) -> 18 | H43: =LEN(_xlfn.FORMULATEXT('XL-Test'!J17)) -> 14 | I43: =LEN(_xlfn.FORMULATEXT('XL-Test'!K17)) -> 34 | J43: =LEN(_xlfn.FORMULATEXT('XL-Test'!L17)) -> 34 | K43: =LEN(_xlfn.FORMULATEXT('XL-Test'!M17)) -> 57
C44: 18 | D44: =LEN(_xlfn.FORMULATEXT('XL-Test'!F18)) -> 27 | E44: =LEN(_xlfn.FORMULATEXT('XL-Test'!G18)) -> 25 | F44: =LEN(_xlfn.FORMULATEXT('XL-Test'!H18)) -> 25 | G44: =LEN(_xlfn.FORMULATEXT('XL-Test'!I18)) -> 18 | H44: =LEN(_xlfn.FORMULATEXT('XL-Test'!J18)) -> 14 | I44: =LEN(_xlfn.FORMULATEXT('XL-Test'!K18)) -> 34 | J44: =LEN(_xlfn.FORMULATEXT('XL-Test'!L18)) -> 34 | K44: =LEN(_xlfn.FORMULATEXT('XL-Test'!M18)) -> 57
C45: 19 | D45: =LEN(_xlfn.FORMULATEXT('XL-Test'!F19)) -> 27 | E45: =LEN(_xlfn.FORMULATEXT('XL-Test'!G19)) -> 25 | F45: =LEN(_xlfn.FORMULATEXT('XL-Test'!H19)) -> 25 | G45: =LEN(_xlfn.FORMULATEXT('XL-Test'!I19)) -> 18 | H45: =LEN(_xlfn.FORMULATEXT('XL-Test'!J19)) -> 14 | I45: =LEN(_xlfn.FORMULATEXT('XL-Test'!K19)) -> 34 | J45: =LEN(_xlfn.FORMULATEXT('XL-Test'!L19)) -> 34 | K45: =LEN(_xlfn.FORMULATEXT('XL-Test'!M19)) -> 57
C46: 20 | D46: =LEN(_xlfn.FORMULATEXT('XL-Test'!F20)) -> 27 | E46: =LEN(_xlfn.FORMULATEXT('XL-Test'!G20)) -> 25 | F46: =LEN(_xlfn.FORMULATEXT('XL-Test'!H20)) -> 25 | G46: =LEN(_xlfn.FORMULATEXT('XL-Test'!I20)) -> 18 | H46: =LEN(_xlfn.FORMULATEXT('XL-Test'!J20)) -> 14 | I46: =LEN(_xlfn.FORMULATEXT('XL-Test'!K20)) -> 34 | J46: =LEN(_xlfn.FORMULATEXT('XL-Test'!L20)) -> 34 | K46: =LEN(_xlfn.FORMULATEXT('XL-Test'!M20)) -> 57
C47: 21 | D47: =LEN(_xlfn.FORMULATEXT('XL-Test'!F21)) -> 27 | E47: =LEN(_xlfn.FORMULATEXT('XL-Test'!G21)) -> 25 | F47: =LEN(_xlfn.FORMULATEXT('XL-Test'!H21)) -> 25 | G47: =LEN(_xlfn.FORMULATEXT('XL-Test'!I21)) -> 18 | H47: =LEN(_xlfn.FORMULATEXT('XL-Test'!J21)) -> 14 | I47: =LEN(_xlfn.FORMULATEXT('XL-Test'!K21)) -> 34 | J47: =LEN(_xlfn.FORMULATEXT('XL-Test'!L21)) -> 34 | K47: =LEN(_xlfn.FORMULATEXT('XL-Test'!M21)) -> 57
C48: 22 | D48: =LEN(_xlfn.FORMULATEXT('XL-Test'!F22)) -> 27 | E48: =LEN(_xlfn.FORMULATEXT('XL-Test'!G22)) -> 25 | F48: =LEN(_xlfn.FORMULATEXT('XL-Test'!H22)) -> 25 | G48: =LEN(_xlfn.FORMULATEXT('XL-Test'!I22)) -> 18 | H48: =LEN(_xlfn.FORMULATEXT('XL-Test'!J22)) -> 14 | I48: =LEN(_xlfn.FORMULATEXT('XL-Test'!K22)) -> 34 | J48: =LEN(_xlfn.FORMULATEXT('XL-Test'!L22)) -> 34 | K48: =LEN(_xlfn.FORMULATEXT('XL-Test'!M22)) -> 57
...

Sheet About
C6: XL-TEST adalah platform inovatif yang menyediakan latihan Excel interaktif dengan pemeriksaan otomatis,
C7: sehingga pengguna dapat langsung mengetahui jawaban yang benar maupun salah.
C10: Terdapat 5 Level soal :
D12: Easy Level | F12: (⭐)
D13: Medium Level | F13: (⭐⭐)
D14: Hard Level | F14: (⭐⭐⭐)
D15: Extreme Level | F15: (⭐⭐⭐⭐)
D16: Championship Level | F16: (⭐⭐⭐⭐⭐)
C19: Free Access
C20: https://belajarexcel.id/xl-test/
