Workbook
Name kode_jawaban: DF!$C$13

Sheet XL-Test
B1: Medium Level (⭐⭐)
B2: KODE SOAL | D2: SBEM007 | F2: KODE JAWABAN | H2: =kode_jawaban -> MG1|D1-CE1;15-11EF4;16-117B;E7-E17;30-29F9D;1C-1461A;47-3E553;20-16B98;33-284A2F
B5: NO | C5: TICKET | D5: FLIGHT TYPE 1 | E5: TAKE OFF | F5: LANDING 2 | G5: FLIGHT AREA 3 | H5: JUMLAH TIKET | J5: Flight Class 4 | K5: HARGA TIKET | M5: TOTAL 7 | N5: PSC AGEN 8 | O5: TOTAL BAYAR 9
H6: DEWASA-1 | I6: ANAK-1 | K6: DEWASA-2 5 | L6: ANAK-2 6
B7: 1 | C7: 3ZBEP | D7: =HLOOKUP(MID(C7,2,1), $L$23:$N$26, LEFT(C7,1)+1, TRUE) -> Turbo N-125 | E7: 0.6875 | F7: =E7 + IF(MID(C7,4,1)="C", 3/24, IF(MID(C7,4,1)="D", 2/24, IF(MID(C7,4,1)="E", 1/24, 0))) -> 0.72916667 | G7: =VLOOKUP(MID(C7,3,1),$P$31:$Q$32,2,0) &"-"& VLOOKUP(MID(C7,4,1),$P$24:$Q$26,2,0) -> Bali-Brunei | H7: 2 | I7: 3 | J7: =IF(RIGHT(C7,1)="P","First Class",IF(RIGHT(C7,1)="B","Bisnis","Ekonomi")) -> First Class | K7: =H7 * HLOOKUP(J7, $L$30:$N$32, 2, FALSE) -> 16000000 | L7: =I7 * HLOOKUP(J7, $L$30:$N$32, 3, FALSE) -> 21000000 | M7: =SUM(K7:L7) -> 37000000 | N7: =IF(M7>30000000,4%*M7,IF(M7>15000000,3.5%*M7,IF(M7>5000000,3%*M7,2.5%*M7))) -> 1480000 | O7: =SUM(M7:N7) -> 38480000
B8: 2 | C8: 1YBDB | D8: =HLOOKUP(MID(C8,2,1), $L$23:$N$26, LEFT(C8,1)+1, TRUE) -> Boeing 737 | E8: 0.70833333 | F8: =E8 + IF(MID(C8,4,1)="C", 3/24, IF(MID(C8,4,1)="D", 2/24, IF(MID(C8,4,1)="E", 1/24, 0))) -> 0.79166667 | G8: =VLOOKUP(MID(C8,3,1),$P$31:$Q$32,2,0) &"-"& VLOOKUP(MID(C8,4,1),$P$24:$Q$26,2,0) -> Bali-Malaysia | H8: 3 | I8: 0 | J8: =IF(RIGHT(C8,1)="P","First Class",IF(RIGHT(C8,1)="B","Bisnis","Ekonomi")) -> Bisnis | K8: =H8 * HLOOKUP(J8, $L$30:$N$32, 2, FALSE) -> 13500000 | L8: =I8 * HLOOKUP(J8, $L$30:$N$32, 3, FALSE) -> 0 | M8: =SUM(K8:L8) -> 13500000 | N8: =IF(M8>30000000,4%*M8,IF(M8>15000000,3.5%*M8,IF(M8>5000000,3%*M8,2.5%*M8))) -> 405000 | O8: =SUM(M8:N8) -> 13905000
B9: 3 | C9: 2YAEP | D9: =HLOOKUP(MID(C9,2,1), $L$23:$N$26, LEFT(C9,1)+1, TRUE) -> DC-10 | E9: 0.5 | F9: =E9 + IF(MID(C9,4,1)="C", 3/24, IF(MID(C9,4,1)="D", 2/24, IF(MID(C9,4,1)="E", 1/24, 0))) -> 0.54166667 | G9: =VLOOKUP(MID(C9,3,1),$P$31:$Q$32,2,0) &"-"& VLOOKUP(MID(C9,4,1),$P$24:$Q$26,2,0) -> Jakarta-Brunei | H9: 3 | I9: 2 | J9: =IF(RIGHT(C9,1)="P","First Class",IF(RIGHT(C9,1)="B","Bisnis","Ekonomi")) -> First Class | K9: =H9 * HLOOKUP(J9, $L$30:$N$32, 2, FALSE) -> 24000000 | L9: =I9 * HLOOKUP(J9, $L$30:$N$32, 3, FALSE) -> 14000000 | M9: =SUM(K9:L9) -> 38000000 | N9: =IF(M9>30000000,4%*M9,IF(M9>15000000,3.5%*M9,IF(M9>5000000,3%*M9,2.5%*M9))) -> 1520000 | O9: =SUM(M9:N9) -> 39520000
B10: 4 | C10: 1ZADE | D10: =HLOOKUP(MID(C10,2,1), $L$23:$N$26, LEFT(C10,1)+1, TRUE) -> Sukhoi SJ 100 | E10: 0.70833333 | F10: =E10 + IF(MID(C10,4,1)="C", 3/24, IF(MID(C10,4,1)="D", 2/24, IF(MID(C10,4,1)="E", 1/24, 0))) -> 0.79166667 | G10: =VLOOKUP(MID(C10,3,1),$P$31:$Q$32,2,0) &"-"& VLOOKUP(MID(C10,4,1),$P$24:$Q$26,2,0) -> Jakarta-Malaysia | H10: 4 | I10: 2 | J10: =IF(RIGHT(C10,1)="P","First Class",IF(RIGHT(C10,1)="B","Bisnis","Ekonomi")) -> Ekonomi | K10: =H10 * HLOOKUP(J10, $L$30:$N$32, 2, FALSE) -> 6000000 | L10: =I10 * HLOOKUP(J10, $L$30:$N$32, 3, FALSE) -> 2400000 | M10: =SUM(K10:L10) -> 8400000 | N10: =IF(M10>30000000,4%*M10,IF(M10>15000000,3.5%*M10,IF(M10>5000000,3%*M10,2.5%*M10))) -> 252000 | O10: =SUM(M10:N10) -> 8652000
B11: 5 | C11: 3XBCB | D11: =HLOOKUP(MID(C11,2,1), $L$23:$N$26, LEFT(C11,1)+1, TRUE) -> Boeing 747 | E11: 0.39583333 | F11: =E11 + IF(MID(C11,4,1)="C", 3/24, IF(MID(C11,4,1)="D", 2/24, IF(MID(C11,4,1)="E", 1/24, 0))) -> 0.52083333 | G11: =VLOOKUP(MID(C11,3,1),$P$31:$Q$32,2,0) &"-"& VLOOKUP(MID(C11,4,1),$P$24:$Q$26,2,0) -> Bali-Singapore | H11: 1 | I11: 1 | J11: =IF(RIGHT(C11,1)="P","First Class",IF(RIGHT(C11,1)="B","Bisnis","Ekonomi")) -> Bisnis | K11: =H11 * HLOOKUP(J11, $L$30:$N$32, 2, FALSE) -> 4500000 | L11: =I11 * HLOOKUP(J11, $L$30:$N$32, 3, FALSE) -> 4000000 | M11: =SUM(K11:L11) -> 8500000 | N11: =IF(M11>30000000,4%*M11,IF(M11>15000000,3.5%*M11,IF(M11>5000000,3%*M11,2.5%*M11))) -> 255000 | O11: =SUM(M11:N11) -> 8755000
B12: 6 | C12: 3ZBEP | D12: =HLOOKUP(MID(C12,2,1), $L$23:$N$26, LEFT(C12,1)+1, TRUE) -> Turbo N-125 | E12: 0.47916667 | F12: =E12 + IF(MID(C12,4,1)="C", 3/24, IF(MID(C12,4,1)="D", 2/24, IF(MID(C12,4,1)="E", 1/24, 0))) -> 0.52083333 | G12: =VLOOKUP(MID(C12,3,1),$P$31:$Q$32,2,0) &"-"& VLOOKUP(MID(C12,4,1),$P$24:$Q$26,2,0) -> Bali-Brunei | H12: 3 | I12: 0 | J12: =IF(RIGHT(C12,1)="P","First Class",IF(RIGHT(C12,1)="B","Bisnis","Ekonomi")) -> First Class | K12: =H12 * HLOOKUP(J12, $L$30:$N$32, 2, FALSE) -> 24000000 | L12: =I12 * HLOOKUP(J12, $L$30:$N$32, 3, FALSE) -> 0 | M12: =SUM(K12:L12) -> 24000000 | N12: =IF(M12>30000000,4%*M12,IF(M12>15000000,3.5%*M12,IF(M12>5000000,3%*M12,2.5%*M12))) -> 840000 | O12: =SUM(M12:N12) -> 24840000
B13: 7 | C13: 1YACE | D13: =HLOOKUP(MID(C13,2,1), $L$23:$N$26, LEFT(C13,1)+1, TRUE) -> Boeing 737 | E13: 0.3125 | F13: =E13 + IF(MID(C13,4,1)="C", 3/24, IF(MID(C13,4,1)="D", 2/24, IF(MID(C13,4,1)="E", 1/24, 0))) -> 0.4375 | G13: =VLOOKUP(MID(C13,3,1),$P$31:$Q$32,2,0) &"-"& VLOOKUP(MID(C13,4,1),$P$24:$Q$26,2,0) -> Jakarta-Singapore | H13: 5 | I13: 3 | J13: =IF(RIGHT(C13,1)="P","First Class",IF(RIGHT(C13,1)="B","Bisnis","Ekonomi")) -> Ekonomi | K13: =H13 * HLOOKUP(J13, $L$30:$N$32, 2, FALSE) -> 7500000 | L13: =I13 * HLOOKUP(J13, $L$30:$N$32, 3, FALSE) -> 3600000 | M13: =SUM(K13:L13) -> 11100000 | N13: =IF(M13>30000000,4%*M13,IF(M13>15000000,3.5%*M13,IF(M13>5000000,3%*M13,2.5%*M13))) -> 333000 | O13: =SUM(M13:N13) -> 11433000
B14: 8 | C14: 2XAEB | D14: =HLOOKUP(MID(C14,2,1), $L$23:$N$26, LEFT(C14,1)+1, TRUE) -> Air Bus 3 | E14: 0.39583333 | F14: =E14 + IF(MID(C14,4,1)="C", 3/24, IF(MID(C14,4,1)="D", 2/24, IF(MID(C14,4,1)="E", 1/24, 0))) -> 0.4375 | G14: =VLOOKUP(MID(C14,3,1),$P$31:$Q$32,2,0) &"-"& VLOOKUP(MID(C14,4,1),$P$24:$Q$26,2,0) -> Jakarta-Brunei | H14: 4 | I14: 2 | J14: =IF(RIGHT(C14,1)="P","First Class",IF(RIGHT(C14,1)="B","Bisnis","Ekonomi")) -> Bisnis | K14: =H14 * HLOOKUP(J14, $L$30:$N$32, 2, FALSE) -> 18000000 | L14: =I14 * HLOOKUP(J14, $L$30:$N$32, 3, FALSE) -> 8000000 | M14: =SUM(K14:L14) -> 26000000 | N14: =IF(M14>30000000,4%*M14,IF(M14>15000000,3.5%*M14,IF(M14>5000000,3%*M14,2.5%*M14))) -> 910000 | O14: =SUM(M14:N14) -> 26910000
B15: 9 | C15: 2ZBDP | D15: =HLOOKUP(MID(C15,2,1), $L$23:$N$26, LEFT(C15,1)+1, TRUE) -> CN 250 | E15: 0.47916667 | F15: =E15 + IF(MID(C15,4,1)="C", 3/24, IF(MID(C15,4,1)="D", 2/24, IF(MID(C15,4,1)="E", 1/24, 0))) -> 0.5625 | G15: =VLOOKUP(MID(C15,3,1),$P$31:$Q$32,2,0) &"-"& VLOOKUP(MID(C15,4,1),$P$24:$Q$26,2,0) -> Bali-Malaysia | H15: 2 | I15: 0 | J15: =IF(RIGHT(C15,1)="P","First Class",IF(RIGHT(C15,1)="B","Bisnis","Ekonomi")) -> First Class | K15: =H15 * HLOOKUP(J15, $L$30:$N$32, 2, FALSE) -> 16000000 | L15: =I15 * HLOOKUP(J15, $L$30:$N$32, 3, FALSE) -> 0 | M15: =SUM(K15:L15) -> 16000000 | N15: =IF(M15>30000000,4%*M15,IF(M15>15000000,3.5%*M15,IF(M15>5000000,3%*M15,2.5%*M15))) -> 560000 | O15: =SUM(M15:N15) -> 16560000
B16: 10 | C16: 3XBDE | D16: =HLOOKUP(MID(C16,2,1), $L$23:$N$26, LEFT(C16,1)+1, TRUE) -> Boeing 747 | E16: 0.3125 | F16: =E16 + IF(MID(C16,4,1)="C", 3/24, IF(MID(C16,4,1)="D", 2/24, IF(MID(C16,4,1)="E", 1/24, 0))) -> 0.39583333 | G16: =VLOOKUP(MID(C16,3,1),$P$31:$Q$32,2,0) &"-"& VLOOKUP(MID(C16,4,1),$P$24:$Q$26,2,0) -> Bali-Malaysia | H16: 3 | I16: 1 | J16: =IF(RIGHT(C16,1)="P","First Class",IF(RIGHT(C16,1)="B","Bisnis","Ekonomi")) -> Ekonomi | K16: =H16 * HLOOKUP(J16, $L$30:$N$32, 2, FALSE) -> 4500000 | L16: =I16 * HLOOKUP(J16, $L$30:$N$32, 3, FALSE) -> 1200000 | M16: =SUM(K16:L16) -> 5700000 | N16: =IF(M16>30000000,4%*M16,IF(M16>15000000,3.5%*M16,IF(M16>5000000,3%*M16,2.5%*M16))) -> 171000 | O16: =SUM(M16:N16) -> 5871000
B17: 11 | C17: 1ZBCB | D17: =HLOOKUP(MID(C17,2,1), $L$23:$N$26, LEFT(C17,1)+1, TRUE) -> Sukhoi SJ 100 | E17: 0.67708333 | F17: =E17 + IF(MID(C17,4,1)="C", 3/24, IF(MID(C17,4,1)="D", 2/24, IF(MID(C17,4,1)="E", 1/24, 0))) -> 0.80208333 | G17: =VLOOKUP(MID(C17,3,1),$P$31:$Q$32,2,0) &"-"& VLOOKUP(MID(C17,4,1),$P$24:$Q$26,2,0) -> Bali-Singapore | H17: 3 | I17: 2 | J17: =IF(RIGHT(C17,1)="P","First Class",IF(RIGHT(C17,1)="B","Bisnis","Ekonomi")) -> Bisnis | K17: =H17 * HLOOKUP(J17, $L$30:$N$32, 2, FALSE) -> 13500000 | L17: =I17 * HLOOKUP(J17, $L$30:$N$32, 3, FALSE) -> 8000000 | M17: =SUM(K17:L17) -> 21500000 | N17: =IF(M17>30000000,4%*M17,IF(M17>15000000,3.5%*M17,IF(M17>5000000,3%*M17,2.5%*M17))) -> 752500 | O17: =SUM(M17:N17) -> 22252500
B18: 12 | C18: 2YADP | D18: =HLOOKUP(MID(C18,2,1), $L$23:$N$26, LEFT(C18,1)+1, TRUE) -> DC-10 | E18: 0.69791667 | F18: =E18 + IF(MID(C18,4,1)="C", 3/24, IF(MID(C18,4,1)="D", 2/24, IF(MID(C18,4,1)="E", 1/24, 0))) -> 0.78125 | G18: =VLOOKUP(MID(C18,3,1),$P$31:$Q$32,2,0) &"-"& VLOOKUP(MID(C18,4,1),$P$24:$Q$26,2,0) -> Jakarta-Malaysia | H18: 3 | I18: 3 | J18: =IF(RIGHT(C18,1)="P","First Class",IF(RIGHT(C18,1)="B","Bisnis","Ekonomi")) -> First Class | K18: =H18 * HLOOKUP(J18, $L$30:$N$32, 2, FALSE) -> 24000000 | L18: =I18 * HLOOKUP(J18, $L$30:$N$32, 3, FALSE) -> 21000000 | M18: =SUM(K18:L18) -> 45000000 | N18: =IF(M18>30000000,4%*M18,IF(M18>15000000,3.5%*M18,IF(M18>5000000,3%*M18,2.5%*M18))) -> 1800000 | O18: =SUM(M18:N18) -> 46800000
K21: Tabel Flight Type
B22: Ticket : Karakter ke-1 : Kode Pesawat, ke-2 : Kode Nama Pesawat, ke-3 : Kode Awal Pemberangkatan, ke-4 : Kode Tujuan, ke-5 : Kode Kelas | K22: Kode Pesawat | L22: Kode Flight Type | P22: Tabel Tujuan
L23: X | M23: Y | N23: Z | P23: Kode Tujuan | Q23: Daerah
B24: Soal | K24: 1 | L24: DC-9 | M24: Boeing 737 | N24: Sukhoi SJ 100 | P24: C | Q24: Singapore
B25: 1 | C25: Flight Type berasal dari Tabel Flight Type, berdasarkan Kode Pesawat dan Kode Nama Pesawat | K25: 2 | L25: Air Bus 3 | M25: DC-10 | N25: CN 250 | P25: D | Q25: Malaysia
B26: 2 | C26: Landing di dapat dari Jam Berangkat ditambah dengan Lama Perjalanan | K26: 3 | L26: Boeing 747 | M26: DC-11 | N26: Turbo N-125 | P26: E | Q26: Brunei
C27: (Tujuan ke Singapore : 3 Jam, Malaysia : 2 Jam, Brunei : 1 Jam)
B28: 3 | C28: Flight Area berdasarkan Kode Awal Pemberangkatan & Kode Tujuan | K28: Tabel Harga Tiket
C29: (misal : Jakarta-Malaysia) | K29: Golongan | L29: Kelas | P29: Tabel Pemberangkatan
B30: 4 | C30: Flight Class berdasarkan Kode Kelas, | L30: Ekonomi | M30: Bisnis | N30: First Class | P30: Kode Awal | Q30: Daerah
C31: Jika Kode Kelas E :Ekonomi, Kode Kelas B : Bisnis, Kode Kelas P : First Class | K31: Dewasa | L31: 1500000 | M31: 4500000 | N31: 8000000 | P31: A | Q31: Jakarta
B32: 5,6 | C32: Harga Tiket didapatkan dari perkalian antara Jumlah Tiket masing-masing dengan Harga Tiket satuan | K32: Anak - Anak | L32: 1200000 | M32: 4000000 | N32: 7000000 | P32: B | Q32: Bali
B33: 7 | C33: Total merupakan penjumlahan antara Harga Tiket Dewasa dan Harga Tiket Anak
B34: 8 | C34: PSC Agen : Jika Total Kurang dari atau sama dengan 5.000.000 : 2,5% dari Total
C35: Jika Total 5.000.001 s.d. 15.000.000 : 3% dari Total
C36: Jika Total 15.000.001 s.d. 30.000.000 : 3,5% dari Total, selain itu 4%
B37: 9 | C37: Total Bayar merupakan penjumlahan antara Total dan PSC Agen
K38: https://belajarexcel.id/xl-test/
B40: Kirimkan Kode Soal dan Kode Jawaban ke alamat : https://belajarexcel.id/xl-test/jawaban untuk mengecek hasil benar/salah

Sheet About
C6: XL-TEST adalah platform inovatif yang menyediakan latihan Excel interaktif dengan pemeriksaan otomatis,
C7: sehingga pengguna dapat langsung mengetahui jawaban yang benar maupun salah.
C10: Terdapat 5 Level soal :
D12: Easy Level | F12: (⭐)
D13: Medium Level | F13: (⭐⭐)
D14: Hard Level | F14: (⭐⭐⭐)
D15: Extreme Level | F15: (⭐⭐⭐⭐)
D16: Championship Level | F16: (⭐⭐⭐⭐⭐)
C19: Free Access
C20: https://belajarexcel.id/xl-test/

Sheet DF
C1: V1 | D1: V2 | E1: V3 | F1: V4 | G1: V5 | H1: VF | I1: Empty | J1: Cek | K1: Cek F | L1: TRUE | M1: FALSE | V1: 1 | W1: 2 | X1: 3 | Y1: 4 | Z1: 5 | AA1: 6 | AB1: 7 | AC1: 8 | AD1: 9
A2: DEF | B2: 1 | C2: =MID('XL-Test'!D7,3,2) -> rb | D2: =MID('XL-Test'!D13,3,2) -> ei | E2: =LEFT('XL-Test'!D18,2) -> DC | F2: =LEFT('XL-Test'!D8)&LEFT('XL-Test'!D9)&LEFT('XL-Test'!D10)&LEFT('XL-Test'!D11)&LEFT('XL-Test'!D16) -> BDSBB | G2: =UPPER(C2&D2&E2&F2) -> RBEIDCBDSBB | H2: =IF(OR(C2="",C2=0),I2&J2,G2&J2) -> RBEIDCBDSBB1 | I2: ANSH15 | J2: =AND(ISNUMBER(FIND("(",V2)),ISNUMBER(FIND("L",V2)))+0 -> 1 | K2: =IF(AND(ISNUMBER(FIND("HLOOKUP",V2)),ISNUMBER(FIND("LEF",V2))),L2,M2) -> BB | L2: =RIGHT(G2,2) -> BB | M2: =RIGHT(I2,2) -> 15 | N2: =K2&"-"&H2&";" -> BB-RBEIDCBDSBB1; | U2: 1 | V2: =_xlfn.FORMULATEXT('XL-Test'!D7) -> =HLOOKUP(MID(C7;2;1); $L$23:$N$26; LEFT(C7;1)+1; TRUE) | W2: =_xlfn.FORMULATEXT('XL-Test'!F7) -> =E7 + IF(MID(C7;4;1)="C"; 3/24; IF(MID(C7;4;1)="D"; 2/24; IF(MID(C7;4;1)="E"; 1/24; 0))) | X2: =_xlfn.FORMULATEXT('XL-Test'!G7) -> =VLOOKUP(MID(C7;3;1);$P$31:$Q$32;2;0) &"-"& VLOOKUP(MID(C7;4;1);$P$24:$Q$26;2;0) | Y2: =_xlfn.FORMULATEXT('XL-Test'!J7) -> =IF(RIGHT(C7;1)="P";"First Class";IF(RIGHT(C7;1)="B";"Bisnis";"Ekonomi")) | Z2: =_xlfn.FORMULATEXT('XL-Test'!K7) -> =H7 * HLOOKUP(J7; $L$30:$N$32; 2; FALSE) | AA2: =_xlfn.FORMULATEXT('XL-Test'!L7) -> =I7 * HLOOKUP(J7; $L$30:$N$32; 3; FALSE) | AB2: =_xlfn.FORMULATEXT('XL-Test'!M7) -> =SUM(K7:L7) | AC2: =_xlfn.FORMULATEXT('XL-Test'!N7) -> =IF(M7>30000000;4%*M7;IF(M7>15000000;3,5%*M7;IF(M7>5000000;3%*M7;2,5%*M7))) | AD2: =_xlfn.FORMULATEXT('XL-Test'!O7) -> =SUM(M7:N7)
A3: MG1 | B3: 2 | C3: ='XL-Test'!F7*100 -> 72.916667 | D3: ='XL-Test'!F12*100 -> 52.083333 | E3: ='XL-Test'!F18*100 -> 78.125 | F3: =SUM('XL-Test'!F7:F18)*100 -> 731.25 | G3: =DEC2HEX(SUM(C3:F3)) -> 3A6 | H3: =IF(OR(C3="",C3=0),I3&J3,G3&J3) -> 3A61 | I3: RFERW | J3: =AND(ISNUMBER(FIND("(",V3)),ISNUMBER(FIND("C",V3)))+0 -> 1 | K3: =IF(OR(ISNUMBER(FIND("IF(",V3)),ISNUMBER(FIND("IFS(",V3)),ISNUMBER(FIND("SWI",V3))),L3,M3) -> A6 | L3: =RIGHT(G3,2) -> A6 | M3: =RIGHT(I3,2) -> RW | N3: =K3&"-"&H3&";" -> A6-3A61; | U3: 2 | V3: =_xlfn.FORMULATEXT('XL-Test'!F7) -> =E7 + IF(MID(C7;4;1)="C"; 3/24; IF(MID(C7;4;1)="D"; 2/24; IF(MID(C7;4;1)="E"; 1/24; 0)))
B4: 3 | C4: =MID('XL-Test'!G7,3,2) -> li | D4: =MID('XL-Test'!G13,3,2) -> ka | E4: =LEFT('XL-Test'!G18,2) -> Ja | F4: =LEFT('XL-Test'!G8)&RIGHT('XL-Test'!G9)&LEFT('XL-Test'!G10)&RIGHT('XL-Test'!G11)&LEFT('XL-Test'!G17)&RIGHT('XL-Test'!G17) -> BiJeBe | G4: =UPPER(C4&D4&E4&F4) -> LIKAJABIJEBE | H4: =IF(OR(C4="",C4=0),I4&J4,G4&J4) -> LIKAJABIJEBE1 | I4: ABSH56 | J4: =AND(ISNUMBER(FIND("(",V4)),ISNUMBER(FIND("C",V4)))+0 -> 1 | K4: =IF(AND(ISNUMBER(FIND("VLOOKUP",V4)),ISNUMBER(FIND("-",V4))),L4,M4) -> BE | L4: =RIGHT(G4,2) -> BE | M4: =RIGHT(I4,2) -> 56 | N4: =K4&"-"&H4&";" -> BE-LIKAJABIJEBE1; | U4: 3 | V4: =_xlfn.FORMULATEXT('XL-Test'!G7) -> =VLOOKUP(MID(C7;3;1);$P$31:$Q$32;2;0) &"-"& VLOOKUP(MID(C7;4;1);$P$24:$Q$26;2;0)
B5: 4 | C5: =MID('XL-Test'!J7,3,2) -> rs | D5: =MID('XL-Test'!J13,3,2) -> on | E5: =LEFT('XL-Test'!J18,2) -> Fi | F5: =LEFT('XL-Test'!J8)&LEFT('XL-Test'!J10)&LEFT('XL-Test'!J14)&LEFT('XL-Test'!J11)&RIGHT('XL-Test'!J16)&RIGHT('XL-Test'!J17) -> BEBBis | G5: =UPPER(C5&D5&E5&F5) -> RSONFIBEBBIS | H5: =IF(OR(C5="",C5=0),I5&J5,G5&J5) -> RSONFIBEBBIS1 | I5: AGR123 | J5: =AND(ISNUMBER(FIND("(",V5)),ISNUMBER(FIND("C",V5)))+0 -> 1 | K5: =IF(OR(ISNUMBER(FIND("IF(",V5)),ISNUMBER(FIND("IFS(",V5)),ISNUMBER(FIND("SWI",V5))),L5,M5) -> IS | L5: =RIGHT(G5,2) -> IS | M5: =RIGHT(I5,2) -> 23 | N5: =K5&"-"&H5&";" -> IS-RSONFIBEBBIS1; | U5: 4 | V5: =_xlfn.FORMULATEXT('XL-Test'!J7) -> =IF(RIGHT(C7;1)="P";"First Class";IF(RIGHT(C7;1)="B";"Bisnis";"Ekonomi"))
B6: 5 | C6: ='XL-Test'!K7 -> 16000000 | D6: ='XL-Test'!K12 -> 24000000 | E6: ='XL-Test'!K18 -> 24000000 | F6: =SUM('XL-Test'!K7:K18) -> 171500000 | G6: =DEC2HEX(SUM(C6:F6)/10000) -> 5BFE | H6: =IF(OR(C6="",C6=0),I6&J6,G6&J6) -> 5BFE1 | I6: BSF142 | J6: =AND(ISNUMBER(FIND("(",V6)),ISNUMBER(FIND("L",V6)))+0 -> 1 | K6: =IF(AND(ISNUMBER(FIND("HLOOKUP",V6)),ISNUMBER(FIND("2",V6))),L6,M6) -> FE | L6: =RIGHT(G6,2) -> FE | M6: =RIGHT(I6,2) -> 42 | N6: =K6&"-"&H6&";" -> FE-5BFE1; | U6: 5 | V6: =_xlfn.FORMULATEXT('XL-Test'!K7) -> =H7 * HLOOKUP(J7; $L$30:$N$32; 2; FALSE)
B7: 6 | C7: ='XL-Test'!L7 -> 21000000 | D7: ='XL-Test'!L13 -> 3600000 | E7: ='XL-Test'!L18 -> 21000000 | F7: =SUM('XL-Test'!L7:L18) -> 83200000 | G7: =DEC2HEX(SUM(C7:F7)/10000) -> 3250 | H7: =IF(OR(C7="",C7=0),I7&J7,G7&J7) -> 32501 | I7: G231SV | J7: =AND(ISNUMBER(FIND("(",V7)),ISNUMBER(FIND("L",V7)))+0 -> 1 | K7: =IF(AND(ISNUMBER(FIND("HLOOKUP",V7)),ISNUMBER(FIND("3",V7))),L7,M7) -> 50 | L7: =RIGHT(G7,2) -> 50 | M7: =RIGHT(I7,2) -> SV | N7: =K7&"-"&H7&";" -> 50-32501; | U7: 6 | V7: =_xlfn.FORMULATEXT('XL-Test'!L7) -> =I7 * HLOOKUP(J7; $L$30:$N$32; 3; FALSE)
B8: 7 | C8: ='XL-Test'!M7 -> 37000000 | D8: ='XL-Test'!M12 -> 24000000 | E8: ='XL-Test'!M18 -> 45000000 | F8: =SUM('XL-Test'!M7:M18) -> 254700000 | G8: =DEC2HEX(SUM(C8:F8)/10000) -> 8CE6 | H8: =IF(OR(C8="",C8=0),I8&J8,G8&J8) -> 8CE61 | I8: BS122 | J8: =AND(ISNUMBER(FIND("L",V8)),ISNUMBER(FIND("K",V8)))+0 -> 1 | K8: =IF(OR(ISNUMBER(FIND("SUM",V8)),ISNUMBER(FIND("+",V8))),L8,M8) -> E6 | L8: =RIGHT(G8,2) -> E6 | M8: =RIGHT(I8,2) -> 22 | N8: =K8&"-"&H8&";" -> E6-8CE61; | U8: 7 | V8: =_xlfn.FORMULATEXT('XL-Test'!M7) -> =SUM(K7:L7)
B9: 8 | C9: ='XL-Test'!N7 -> 1480000 | D9: ='XL-Test'!N12 -> 840000 | E9: ='XL-Test'!N18 -> 1800000 | F9: =SUM('XL-Test'!N7:N18) -> 9278500 | G9: =DEC2HEX(SUM(C9:F9)/10000) -> 53B | H9: =IF(OR(C9="",C9=0),I9&J9,G9&J9) -> 53B1 | I9: HJE1548 | J9: =AND(ISNUMBER(FIND("(",V9)),ISNUMBER(FIND("M",V9)))+0 -> 1 | K9: =IF(OR(ISNUMBER(FIND("IF(",V9)),ISNUMBER(FIND("IFS(",V9)),ISNUMBER(FIND("SWI",V9))),L9,M9) -> 3B | L9: =RIGHT(G9,2) -> 3B | M9: =RIGHT(I9,2) -> 48 | N9: =K9&"-"&H9&";" -> 3B-53B1; | U9: 8 | V9: =_xlfn.FORMULATEXT('XL-Test'!N7) -> =IF(M7>30000000;4%*M7;IF(M7>15000000;3,5%*M7;IF(M7>5000000;3%*M7;2,5%*M7)))
B10: 9 | C10: ='XL-Test'!O7 -> 38480000 | D10: ='XL-Test'!O12 -> 24840000 | E10: ='XL-Test'!O17 -> 22252500 | F10: =SUM('XL-Test'!O7:O18) -> 263978500 | G10: =DEC2HEX(SUM(C10:F10)/10000) -> 888B | H10: =IF(OR(C10="",C10=0),I10&J10,G10&J10) -> 888B1 | I10: AHBN123 | J10: =AND(ISNUMBER(FIND("N",V10)),ISNUMBER(FIND("M",V10)))+0 -> 1 | K10: =IF(OR(ISNUMBER(FIND("SUM",V10)),ISNUMBER(FIND("+",V10))),L10,M10) -> 8B | L10: =RIGHT(G10,2) -> 8B | M10: =RIGHT(I10,2) -> 23 | N10: =K10&"-"&H10 -> 8B-888B1 | U10: 9 | V10: =_xlfn.FORMULATEXT('XL-Test'!O7) -> =SUM(M7:N7)
C13: =A3&"|"&C82 -> MG1|D1-CE1;15-11EF4;16-117B;E7-E17;30-29F9D;1C-1461A;47-3E553;20-16B98;33-284A2F
C16: 1 | D16: 2 | E16: 3 | F16: 4 | G16: 5 | H16: 6 | I16: 7 | J16: 8 | K16: 9
B17: 1 | C17: ='XL-Test'!D7 -> Turbo N-125 | D17: ='XL-Test'!F7 -> 0.72916667 | E17: ='XL-Test'!G7 -> Bali-Brunei | F17: =UPPER('XL-Test'!J7) -> FIRST CLASS | G17: ='XL-Test'!K7 -> 16000000 | H17: ='XL-Test'!L7 -> 21000000 | I17: ='XL-Test'!M7 -> 37000000 | J17: ='XL-Test'!N7 -> 1480000 | K17: ='XL-Test'!O7 -> 38480000 | N17: 1 | O17: =V2 -> =HLOOKUP(MID(C7;2;1); $L$23:$N$26; LEFT(C7;1)+1; TRUE)
B18: 2 | C18: ='XL-Test'!D8 -> Boeing 737 | D18: ='XL-Test'!F8 -> 0.79166667 | E18: ='XL-Test'!G8 -> Bali-Malaysia | F18: =UPPER('XL-Test'!J8) -> BISNIS | G18: ='XL-Test'!K8 -> 13500000 | H18: ='XL-Test'!L8 -> 0 | I18: ='XL-Test'!M8 -> 13500000 | J18: ='XL-Test'!N8 -> 405000 | K18: ='XL-Test'!O8 -> 13905000 | N18: 2 | O18: =V3 -> =E7 + IF(MID(C7;4;1)="C"; 3/24; IF(MID(C7;4;1)="D"; 2/24; IF(MID(C7;4;1)="E"; 1/24; 0)))
B19: 3 | C19: ='XL-Test'!D9 -> DC-10 | D19: ='XL-Test'!F9 -> 0.54166667 | E19: ='XL-Test'!G9 -> Jakarta-Brunei | F19: =UPPER('XL-Test'!J9) -> FIRST CLASS | G19: ='XL-Test'!K9 -> 24000000 | H19: ='XL-Test'!L9 -> 14000000 | I19: ='XL-Test'!M9 -> 38000000 | J19: ='XL-Test'!N9 -> 1520000 | K19: ='XL-Test'!O9 -> 39520000 | N19: 3 | O19: =V4 -> =VLOOKUP(MID(C7;3;1);$P$31:$Q$32;2;0) &"-"& VLOOKUP(MID(C7;4;1);$P$24:$Q$26;2;0)
B20: 4 | C20: ='XL-Test'!D10 -> Sukhoi SJ 100 | D20: ='XL-Test'!F10 -> 0.79166667 | E20: ='XL-Test'!G10 -> Jakarta-Malaysia | F20: =UPPER('XL-Test'!J10) -> EKONOMI | G20: ='XL-Test'!K10 -> 6000000 | H20: ='XL-Test'!L10 -> 2400000 | I20: ='XL-Test'!M10 -> 8400000 | J20: ='XL-Test'!N10 -> 252000 | K20: ='XL-Test'!O10 -> 8652000 | N20: 4 | O20: =V5 -> =IF(RIGHT(C7;1)="P";"First Class";IF(RIGHT(C7;1)="B";"Bisnis";"Ekonomi"))
B21: 5 | C21: ='XL-Test'!D11 -> Boeing 747 | D21: ='XL-Test'!F11 -> 0.52083333 | E21: ='XL-Test'!G11 -> Bali-Singapore | F21: =UPPER('XL-Test'!J11) -> BISNIS | G21: ='XL-Test'!K11 -> 4500000 | H21: ='XL-Test'!L11 -> 4000000 | I21: ='XL-Test'!M11 -> 8500000 | J21: ='XL-Test'!N11 -> 255000 | K21: ='XL-Test'!O11 -> 8755000 | N21: 5 | O21: =V6 -> =H7 * HLOOKUP(J7; $L$30:$N$32; 2; FALSE)
B22: 6 | C22: ='XL-Test'!D12 -> Turbo N-125 | D22: ='XL-Test'!F12 -> 0.52083333 | E22: ='XL-Test'!G12 -> Bali-Brunei | F22: =UPPER('XL-Test'!J12) -> FIRST CLASS | G22: ='XL-Test'!K12 -> 24000000 | H22: ='XL-Test'!L12 -> 0 | I22: ='XL-Test'!M12 -> 24000000 | J22: ='XL-Test'!N12 -> 840000 | K22: ='XL-Test'!O12 -> 24840000 | N22: 6 | O22: =V7 -> =I7 * HLOOKUP(J7; $L$30:$N$32; 3; FALSE)
B23: 7 | C23: ='XL-Test'!D13 -> Boeing 737 | D23: ='XL-Test'!F13 -> 0.4375 | E23: ='XL-Test'!G13 -> Jakarta-Singapore | F23: =UPPER('XL-Test'!J13) -> EKONOMI | G23: ='XL-Test'!K13 -> 7500000 | H23: ='XL-Test'!L13 -> 3600000 | I23: ='XL-Test'!M13 -> 11100000 | J23: ='XL-Test'!N13 -> 333000 | K23: ='XL-Test'!O13 -> 11433000 | N23: 7 | O23: =V8 -> =SUM(K7:L7)
B24: 8 | C24: ='XL-Test'!D14 -> Air Bus 3 | D24: ='XL-Test'!F14 -> 0.4375 | E24: ='XL-Test'!G14 -> Jakarta-Brunei | F24: =UPPER('XL-Test'!J14) -> BISNIS | G24: ='XL-Test'!K14 -> 18000000 | H24: ='XL-Test'!L14 -> 8000000 | I24: ='XL-Test'!M14 -> 26000000 | J24: ='XL-Test'!N14 -> 910000 | K24: ='XL-Test'!O14 -> 26910000 | N24: 8 | O24: =V9 -> =IF(M7>30000000;4%*M7;IF(M7>15000000;3,5%*M7;IF(M7>5000000;3%*M7;2,5%*M7)))
B25: 9 | C25: ='XL-Test'!D15 -> CN 250 | D25: ='XL-Test'!F15 -> 0.5625 | E25: ='XL-Test'!G15 -> Bali-Malaysia | F25: =UPPER('XL-Test'!J15) -> FIRST CLASS | G25: ='XL-Test'!K15 -> 16000000 | H25: ='XL-Test'!L15 -> 0 | I25: ='XL-Test'!M15 -> 16000000 | J25: ='XL-Test'!N15 -> 560000 | K25: ='XL-Test'!O15 -> 16560000 | N25: 9 | O25: =V10 -> =SUM(M7:N7)
B26: 10 | C26: ='XL-Test'!D16 -> Boeing 747 | D26: ='XL-Test'!F16 -> 0.39583333 | E26: ='XL-Test'!G16 -> Bali-Malaysia | F26: =UPPER('XL-Test'!J16) -> EKONOMI | G26: ='XL-Test'!K16 -> 4500000 | H26: ='XL-Test'!L16 -> 1200000 | I26: ='XL-Test'!M16 -> 5700000 | J26: ='XL-Test'!N16 -> 171000 | K26: ='XL-Test'!O16 -> 5871000
B27: 11 | C27: ='XL-Test'!D17 -> Sukhoi SJ 100 | D27: ='XL-Test'!F17 -> 0.80208333 | E27: ='XL-Test'!G17 -> Bali-Singapore | F27: =UPPER('XL-Test'!J17) -> BISNIS | G27: ='XL-Test'!K17 -> 13500000 | H27: ='XL-Test'!L17 -> 8000000 | I27: ='XL-Test'!M17 -> 21500000 | J27: ='XL-Test'!N17 -> 752500 | K27: ='XL-Test'!O17 -> 22252500
B28: 12 | C28: ='XL-Test'!D18 -> DC-10 | D28: ='XL-Test'!F18 -> 0.78125 | E28: ='XL-Test'!G18 -> Jakarta-Malaysia | F28: =UPPER('XL-Test'!J18) -> FIRST CLASS | G28: ='XL-Test'!K18 -> 24000000 | H28: ='XL-Test'!L18 -> 21000000 | I28: ='XL-Test'!M18 -> 45000000 | J28: ='XL-Test'!N18 -> 1800000 | K28: ='XL-Test'!O18 -> 46800000
B31: V1 | C31: =CODE(LEFT(C17))+CODE(LEFT(C18))+CODE(LEFT(C19))+CODE(LEFT(C20))+CODE(LEFT(C21))+CODE(LEFT(C22))+CODE(LEFT(C23))+CODE(LEFT(C24))+CODE(LEFT(C25))+CODE(LEFT(C26))+CODE(LEFT(C27))+CODE(LEFT(C28))+ CODE(RIGHT(C17))+CODE(RIGHT(C18))+CODE(RIGHT(C19))+CODE(RIGHT(C20))+CODE(RIGHT(C21))+CODE(RIGHT(C22))+CODE(RIGHT(C23))+CODE(RIGHT(C24))+CODE(RIGHT(C25))+CODE(RIGHT(C26))+CODE(RIGHT(C27))+CODE(RIGHT(C28))+ CODE(LEFT(RIGHT(C17,2)))+CODE(LEFT(RIGHT(C18,2)))+CODE(LEFT(RIGHT(C19,2)))+CODE(LEFT(RIGHT(C20,2)))+CODE(LEFT(RIGHT(C21,2)))+CODE(LEFT(RIGHT(C22,2)))+CODE(LEFT(RIGHT(C23,2)))+CODE(LEFT(RIGHT(C24,2)))+CODE(LEFT(RIGHT(C25,2)))+CODE(LEFT(RIGHT(C26,2)))+CODE(LEFT(RIGHT(C27,2)))+CODE(LEFT(RIGHT(C28,2)))+ CODE(MID(C17,2,1))+CODE(MID(C18,2,1))+CODE(MID(C19,2,1))+CODE(MID(C20,2,1))+CODE(MID(C21,2,1))+CODE(MID(C22,2,1))+CODE(MID(C23,2,1))+CODE(MID(C24,2,1))+CODE(MID(C25,2,1))+CODE(MID(C26,2,1))+CODE(MID(C27,2,1))+CODE(MID(C28,2,1)) -> 3297 | D31: =(SUM(D17:D28)*10000)+INT(D18*100)+INT(D20*100)+INT(D25*100)+INT(D23*100)+INT(D28*100) -> 73460 | E31: =CODE(LEFT(E17))+CODE(LEFT(E18))+CODE(LEFT(E19))+CODE(LEFT(E20))+CODE(LEFT(E21))+CODE(LEFT(E22))+CODE(LEFT(E23))+CODE(LEFT(E24))+CODE(LEFT(E25))+CODE(LEFT(E26))+CODE(LEFT(E27))+CODE(LEFT(E28))+ CODE(RIGHT(E17))+CODE(RIGHT(E18))+CODE(RIGHT(E19))+CODE(RIGHT(E20))+CODE(RIGHT(E21))+CODE(RIGHT(E22))+CODE(RIGHT(E23))+CODE(RIGHT(E24))+CODE(RIGHT(E25))+CODE(RIGHT(E26))+CODE(RIGHT(E27))+CODE(RIGHT(E28))+ CODE(LEFT(RIGHT(E17,2)))+CODE(LEFT(RIGHT(E18,2)))+CODE(LEFT(RIGHT(E19,2)))+CODE(LEFT(RIGHT(E20,2)))+CODE(LEFT(RIGHT(E21,2)))+CODE(LEFT(RIGHT(E22,2)))+CODE(LEFT(RIGHT(E23,2)))+CODE(LEFT(RIGHT(E24,2)))+CODE(LEFT(RIGHT(E25,2)))+CODE(LEFT(RIGHT(E26,2)))+CODE(LEFT(RIGHT(E27,2)))+CODE(LEFT(RIGHT(E28,2)))+ CODE(MID(E17,2,1))+CODE(MID(E18,2,1))+CODE(MID(E19,2,1))+CODE(MID(E20,2,1))+CODE(MID(E21,2,1))+CODE(MID(E22,2,1))+CODE(MID(E23,2,1))+CODE(MID(E24,2,1))+CODE(MID(E25,2,1))+CODE(MID(E26,2,1))+CODE(MID(E27,2,1))+CODE(MID(E28,2,1)) -> 4475 | F31: =CODE(LEFT(F17))+CODE(LEFT(F18))+CODE(LEFT(F19))+CODE(LEFT(F20))+CODE(LEFT(F21))+CODE(LEFT(F22))+CODE(LEFT(F23))+CODE(LEFT(F24))+CODE(LEFT(F25))+CODE(LEFT(F26))+CODE(LEFT(F27))+CODE(LEFT(F28))+ CODE(RIGHT(F17))+CODE(RIGHT(F18))+CODE(RIGHT(F19))+CODE(RIGHT(F20))+CODE(RIGHT(F21))+CODE(RIGHT(F22))+CODE(RIGHT(F23))+CODE(RIGHT(F24))+CODE(RIGHT(F25))+CODE(RIGHT(F26))+CODE(RIGHT(F27))+CODE(RIGHT(F28))+ CODE(LEFT(RIGHT(F17,2)))+CODE(LEFT(RIGHT(F18,2)))+CODE(LEFT(RIGHT(F19,2)))+CODE(LEFT(RIGHT(F20,2)))+CODE(LEFT(RIGHT(F21,2)))+CODE(LEFT(RIGHT(F22,2)))+CODE(LEFT(RIGHT(F23,2)))+CODE(LEFT(RIGHT(F24,2)))+CODE(LEFT(RIGHT(F25,2)))+CODE(LEFT(RIGHT(F26,2)))+CODE(LEFT(RIGHT(F27,2)))+CODE(LEFT(RIGHT(F28,2)))+ CODE(MID(F17,2,1))+CODE(MID(F18,2,1))+CODE(MID(F19,2,1))+CODE(MID(F20,2,1))+CODE(MID(F21,2,1))+CODE(MID(F22,2,1))+CODE(MID(F23,2,1))+CODE(MID(F24,2,1))+CODE(MID(F25,2,1))+CODE(MID(F26,2,1))+CODE(MID(F27,2,1))+CODE(MID(F28,2,1)) -> 3607 | G31: =(SUM(G17:G28)/1000)+LEFT(G18,2)+LEFT(G20,2)+LEFT(G26,2)+LEFT(G23,2)+LEFT(G28,3) -> 171933 | H31: =(SUM(H17:H28)/1000)+LEFT(H18,2)+LEFT(H20,2)+LEFT(H26,2)+LEFT(H23,2)+LEFT(H28,3) -> 83482 | I31: =(SUM(I17:I28)/1000)+LEFT(I18,2)+LEFT(I20,2)+LEFT(I26,2)+LEFT(I23,2)+LEFT(I28,3) -> 255315 | J31: =(SUM(J17:J28)/100)+LEFT(J18,2)+LEFT(J20,2)+LEFT(J26,2)+LEFT(J23,2)+LEFT(J28,3) -> 93080 | K31: =(SUM(K17:K28)/100)+LEFT(K18,2)+LEFT(K20,2)+LEFT(K26,2)+LEFT(K23,2)+LEFT(K28,3)+10 -> 2640431
B32: Vrand | C32: 3401 | D32: 2294 | E32: 5299 | F32: 5552 | G32: 4503 | H32: 7376 | I32: 4712 | J32: 3174 | K32: 8910
A34: ** | B34: Cek Manual | C34: =AND(ISNUMBER(FIND("=",V2)),ISNUMBER(FIND("(",V2))) -> TRUE | D34: =AND(ISNUMBER(FIND("=",W2)),ISNUMBER(FIND("(",W2))) -> TRUE | E34: =AND(ISNUMBER(FIND("=",X2)),ISNUMBER(FIND("(",X2))) -> TRUE | F34: =AND(ISNUMBER(FIND("=",Y2)),ISNUMBER(FIND("(",Y2))) -> TRUE | G34: =AND(ISNUMBER(FIND("=",Z2)),ISNUMBER(FIND("(",Z2))) -> TRUE | H34: =AND(ISNUMBER(FIND("=",AA2)),ISNUMBER(FIND("(",AA2))) -> TRUE | I34: =AND(ISNUMBER(FIND("=",AB2))) -> TRUE | J34: =AND(ISNUMBER(FIND("=",AC2)),ISNUMBER(FIND("(",AC2))) -> TRUE | K34: =AND(ISNUMBER(FIND("=",AD2))) -> TRUE
A37: 1 | B37: 7 | C37: =LEN(_xlfn.FORMULATEXT('XL-Test'!D7)) -> 54 | D37: =LEN(_xlfn.FORMULATEXT('XL-Test'!F7)) -> 88 | E37: =LEN(_xlfn.FORMULATEXT('XL-Test'!G7)) -> 80 | F37: =LEN(_xlfn.FORMULATEXT('XL-Test'!J7)) -> 73 | G37: =LEN(_xlfn.FORMULATEXT('XL-Test'!K7)) -> 40 | H37: =LEN(_xlfn.FORMULATEXT('XL-Test'!L7)) -> 40 | I37: =LEN(_xlfn.FORMULATEXT('XL-Test'!M7)) -> 11 | J37: =LEN(_xlfn.FORMULATEXT('XL-Test'!N7)) -> 75 | K37: =LEN(_xlfn.FORMULATEXT('XL-Test'!O7)) -> 11
A38: 2 | B38: 8 | C38: =LEN(_xlfn.FORMULATEXT('XL-Test'!D8)) -> 54 | D38: =LEN(_xlfn.FORMULATEXT('XL-Test'!F8)) -> 88 | E38: =LEN(_xlfn.FORMULATEXT('XL-Test'!G8)) -> 80 | F38: =LEN(_xlfn.FORMULATEXT('XL-Test'!J8)) -> 73 | G38: =LEN(_xlfn.FORMULATEXT('XL-Test'!K8)) -> 40 | H38: =LEN(_xlfn.FORMULATEXT('XL-Test'!L8)) -> 40 | I38: =LEN(_xlfn.FORMULATEXT('XL-Test'!M8)) -> 11 | J38: =LEN(_xlfn.FORMULATEXT('XL-Test'!N8)) -> 75 | K38: =LEN(_xlfn.FORMULATEXT('XL-Test'!O8)) -> 11
A39: 3 | B39: 9 | C39: =LEN(_xlfn.FORMULATEXT('XL-Test'!D9)) -> 54 | D39: =LEN(_xlfn.FORMULATEXT('XL-Test'!F9)) -> 88 | E39: =LEN(_xlfn.FORMULATEXT('XL-Test'!G9)) -> 80 | F39: =LEN(_xlfn.FORMULATEXT('XL-Test'!J9)) -> 73 | G39: =LEN(_xlfn.FORMULATEXT('XL-Test'!K9)) -> 40 | H39: =LEN(_xlfn.FORMULATEXT('XL-Test'!L9)) -> 40 | I39: =LEN(_xlfn.FORMULATEXT('XL-Test'!M9)) -> 11 | J39: =LEN(_xlfn.FORMULATEXT('XL-Test'!N9)) -> 75 | K39: =LEN(_xlfn.FORMULATEXT('XL-Test'!O9)) -> 11
A40: 4 | B40: 10 | C40: =LEN(_xlfn.FORMULATEXT('XL-Test'!D10)) -> 56 | D40: =LEN(_xlfn.FORMULATEXT('XL-Test'!F10)) -> 92 | E40: =LEN(_xlfn.FORMULATEXT('XL-Test'!G10)) -> 82 | F40: =LEN(_xlfn.FORMULATEXT('XL-Test'!J10)) -> 75 | G40: =LEN(_xlfn.FORMULATEXT('XL-Test'!K10)) -> 42 | H40: =LEN(_xlfn.FORMULATEXT('XL-Test'!L10)) -> 42 | I40: =LEN(_xlfn.FORMULATEXT('XL-Test'!M10)) -> 13 | J40: =LEN(_xlfn.FORMULATEXT('XL-Test'!N10)) -> 82 | K40: =LEN(_xlfn.FORMULATEXT('XL-Test'!O10)) -> 13
A41: 5 | B41: 11 | C41: =LEN(_xlfn.FORMULATEXT('XL-Test'!D11)) -> 56 | D41: =LEN(_xlfn.FORMULATEXT('XL-Test'!F11)) -> 92 | E41: =LEN(_xlfn.FORMULATEXT('XL-Test'!G11)) -> 82 | F41: =LEN(_xlfn.FORMULATEXT('XL-Test'!J11)) -> 75 | G41: =LEN(_xlfn.FORMULATEXT('XL-Test'!K11)) -> 42 | H41: =LEN(_xlfn.FORMULATEXT('XL-Test'!L11)) -> 42 | I41: =LEN(_xlfn.FORMULATEXT('XL-Test'!M11)) -> 13 | J41: =LEN(_xlfn.FORMULATEXT('XL-Test'!N11)) -> 82 | K41: =LEN(_xlfn.FORMULATEXT('XL-Test'!O11)) -> 13
A42: 6 | B42: 12 | C42: =LEN(_xlfn.FORMULATEXT('XL-Test'!D12)) -> 56 | D42: =LEN(_xlfn.FORMULATEXT('XL-Test'!F12)) -> 92 | E42: =LEN(_xlfn.FORMULATEXT('XL-Test'!G12)) -> 82 | F42: =LEN(_xlfn.FORMULATEXT('XL-Test'!J12)) -> 75 | G42: =LEN(_xlfn.FORMULATEXT('XL-Test'!K12)) -> 42 | H42: =LEN(_xlfn.FORMULATEXT('XL-Test'!L12)) -> 42 | I42: =LEN(_xlfn.FORMULATEXT('XL-Test'!M12)) -> 13 | J42: =LEN(_xlfn.FORMULATEXT('XL-Test'!N12)) -> 82 | K42: =LEN(_xlfn.FORMULATEXT('XL-Test'!O12)) -> 13
A43: 7 | B43: 13 | C43: =LEN(_xlfn.FORMULATEXT('XL-Test'!D13)) -> 56 | D43: =LEN(_xlfn.FORMULATEXT('XL-Test'!F13)) -> 92 | E43: =LEN(_xlfn.FORMULATEXT('XL-Test'!G13)) -> 82 | F43: =LEN(_xlfn.FORMULATEXT('XL-Test'!J13)) -> 75 | G43: =LEN(_xlfn.FORMULATEXT('XL-Test'!K13)) -> 42 | H43: =LEN(_xlfn.FORMULATEXT('XL-Test'!L13)) -> 42 | I43: =LEN(_xlfn.FORMULATEXT('XL-Test'!M13)) -> 13 | J43: =LEN(_xlfn.FORMULATEXT('XL-Test'!N13)) -> 82 | K43: =LEN(_xlfn.FORMULATEXT('XL-Test'!O13)) -> 13
A44: 8 | B44: 14 | C44: =LEN(_xlfn.FORMULATEXT('XL-Test'!D14)) -> 56 | D44: =LEN(_xlfn.FORMULATEXT('XL-Test'!F14)) -> 92 | E44: =LEN(_xlfn.FORMULATEXT('XL-Test'!G14)) -> 82 | F44: =LEN(_xlfn.FORMULATEXT('XL-Test'!J14)) -> 75 | G44: =LEN(_xlfn.FORMULATEXT('XL-Test'!K14)) -> 42 | H44: =LEN(_xlfn.FORMULATEXT('XL-Test'!L14)) -> 42 | I44: =LEN(_xlfn.FORMULATEXT('XL-Test'!M14)) -> 13 | J44: =LEN(_xlfn.FORMULATEXT('XL-Test'!N14)) -> 82 | K44: =LEN(_xlfn.FORMULATEXT('XL-Test'!O14)) -> 13
A45: 9 | B45: 15 | C45: =LEN(_xlfn.FORMULATEXT('XL-Test'!D15)) -> 56 | D45: =LEN(_xlfn.FORMULATEXT('XL-Test'!F15)) -> 92 | E45: =LEN(_xlfn.FORMULATEXT('XL-Test'!G15)) -> 82 | F45: =LEN(_xlfn.FORMULATEXT('XL-Test'!J15)) -> 75 | G45: =LEN(_xlfn.FORMULATEXT('XL-Test'!K15)) -> 42 | H45: =LEN(_xlfn.FORMULATEXT('XL-Test'!L15)) -> 42 | I45: =LEN(_xlfn.FORMULATEXT('XL-Test'!M15)) -> 13 | J45: =LEN(_xlfn.FORMULATEXT('XL-Test'!N15)) -> 82 | K45: =LEN(_xlfn.FORMULATEXT('XL-Test'!O15)) -> 13
A46: 10 | B46: 16 | C46: =LEN(_xlfn.FORMULATEXT('XL-Test'!D16)) -> 56 | D46: =LEN(_xlfn.FORMULATEXT('XL-Test'!F16)) -> 92 | E46: =LEN(_xlfn.FORMULATEXT('XL-Test'!G16)) -> 82 | F46: =LEN(_xlfn.FORMULATEXT('XL-Test'!J16)) -> 75 | G46: =LEN(_xlfn.FORMULATEXT('XL-Test'!K16)) -> 42 | H46: =LEN(_xlfn.FORMULATEXT('XL-Test'!L16)) -> 42 | I46: =LEN(_xlfn.FORMULATEXT('XL-Test'!M16)) -> 13 | J46: =LEN(_xlfn.FORMULATEXT('XL-Test'!N16)) -> 82 | K46: =LEN(_xlfn.FORMULATEXT('XL-Test'!O16)) -> 13
A47: 11 | B47: 17 | C47: =LEN(_xlfn.FORMULATEXT('XL-Test'!D17)) -> 56 | D47: =LEN(_xlfn.FORMULATEXT('XL-Test'!F17)) -> 92 | E47: =LEN(_xlfn.FORMULATEXT('XL-Test'!G17)) -> 82 | F47: =LEN(_xlfn.FORMULATEXT('XL-Test'!J17)) -> 75 | G47: =LEN(_xlfn.FORMULATEXT('XL-Test'!K17)) -> 42 | H47: =LEN(_xlfn.FORMULATEXT('XL-Test'!L17)) -> 42 | I47: =LEN(_xlfn.FORMULATEXT('XL-Test'!M17)) -> 13 | J47: =LEN(_xlfn.FORMULATEXT('XL-Test'!N17)) -> 82 | K47: =LEN(_xlfn.FORMULATEXT('XL-Test'!O17)) -> 13
A48: 12 | B48: 18 | C48: =LEN(_xlfn.FORMULATEXT('XL-Test'!D18)) -> 56 | D48: =LEN(_xlfn.FORMULATEXT('XL-Test'!F18)) -> 92 | E48: =LEN(_xlfn.FORMULATEXT('XL-Test'!G18)) -> 82 | F48: =LEN(_xlfn.FORMULATEXT('XL-Test'!J18)) -> 75 | G48: =LEN(_xlfn.FORMULATEXT('XL-Test'!K18)) -> 42 | H48: =LEN(_xlfn.FORMULATEXT('XL-Test'!L18)) -> 42 | I48: =LEN(_xlfn.FORMULATEXT('XL-Test'!M18)) -> 13 | J48: =LEN(_xlfn.FORMULATEXT('XL-Test'!N18)) -> 82 | K48: =LEN(_xlfn.FORMULATEXT('XL-Test'!O18)) -> 13
B51: AVG 1 | C51: =AVERAGE(C37:C39) -> 54 | D51: =AVERAGE(D37:D39) -> 88 | E51: =AVERAGE(E37:E39) -> 80 | F51: =AVERAGE(F37:F39) -> 73 | G51: =AVERAGE(G37:G39) -> 40 | H51: =AVERAGE(H37:H39) -> 40 | I51: =AVERAGE(I37:I39) -> 11 | J51: =AVERAGE(J37:J39) -> 75 | K51: =AVERAGE(K37:K39) -> 11
...
