Workbook
Name darisini: DF!$J$34
Name kode_jawaban: DF!$J$36

Sheet XL-Test
A17: KODE SOAL | C17: SBEE006 | E17: KODE JAWABAN | G17: =kode_jawaban -> EF4|2C-C60;32-BA8;DF-C2D;2E-5C8D;32-2616;6B-5D87;2F-4B776
A19: Intruksi
B21: Easy Level - Latihan Soal Excel Gaji Sederhana
B23: Soal : | C23: Gunakan Fungsi Excel (Function) untuk menyelsaikan kasus dibawah ini, tidak disarankan menggunakan cara manual
B24: 1 | C24: Isi kolom Jabatan diambil 1 karakter dari karakter ke-3 Kolom Kode (Tidak ada Table Bantu)
D25: Kode=1, maka "Kepala"
D26: Kode=2, maka "Staff"
D27: Kode=3, maka "Operator"
B28: 2 | C28: Isi Kolom Status : Diambil 1 karakter terakhir. (Tidak ada Table Bantu)
D29: Kode="S", maka "Single"
D30: Kode="M", maka "Married" | H30: Table Bantu:
B31: 3 | C31: isi Kolom Divisi diambil 1 Karakter pertama dan Divisi berdasarkan Table Bantu disamping | H31: KODE | I31: DIVISI | J31: GAJI POKOK
B32: 4 | C32: isi kolom Gaji Pokok diisi berdasarkan Table Bantu | H32: A | I32: Distributor | J32: 2500000
B33: 5 | C33: isi kolom Tunj. Anak : Jika Status = Menikah dan mempunyai anak, | H33: B | I33: Engineering | J33: 2300000
D34: maka masing-masing anak mendapat Rp. 25,000 | H34: C | I34: Produksi | J34: 2000000
D35: jika single dan tidak memiliki anak maka Rp. 0 | H35: D | I35: Quality Control | J35: 2600000
B36: 6 | C36: Isi kolom Total Gaji berdasarkan Gaji Pokok ditambah Tunj. Anak
B37: 7 | C37: isi Total Seluruh Gaji, Gaji Terbesar, Gaji Terendah, Gaji Rata-rata dan Banyaknya Data (Tidak termasuk contoh)
C39: Sudah selesai mengerjakan? kirim Kode Soal dan Kode Jawaban diatas ke alamat : https://belajarexcel.id/xl-test/jawaban untuk mengecek hasilnya
C40: atau klik tombol disamping
B45: Laporan Gaji Pegawai
B46: PT. BelajarExcel.ID Property
B47: Jakarta
E49: 1 | F49: 2 | G49: 3 | H49: 4 | J49: 5 | K49: 6
B50: NO | C50: KODE | D50: NAMA | E50: JABATAN | F50: STATUS | G50: DIVISI | H50: GAJI POKOK | I50: JMLH ANAK | J50: TUNJ. ANAK | K50: TOTAL GAJI
B51: Contoh | C51: C-3-M | D51: Agus Mulyono | E51: Operator | F51: Married | G51: Produksi | H51: 2000000 | I51: 2 | J51: 50000 | K51: 2050000
B53: 1 | C53: A-1-M | D53: Dewi Anugrah | E53: =IF(MID(C53,3,1)="1","Kepala",IF(MID(C53,3,1)="2","Staff","Operator")) -> Kepala | F53: =IF(RIGHT(C53,1)="M","Married","Single") -> Married | G53: =VLOOKUP(LEFT(C53,1),$H$32:$J$35,2,0) -> Distributor | H53: =VLOOKUP(LEFT(C53,1),$H$32:$J$35,3,0) -> 2500000 | I53: 2 | J53: =IF(F53="Married",I53*25000,I53*0) -> 50000 | K53: =H53+J53 -> 2550000
B54: 2 | C54: A-2-M | D54: Anton Susilo | E54: =IF(MID(C54,3,1)="1","Kepala",IF(MID(C54,3,1)="2","Staff","Operator")) -> Staff | F54: =IF(RIGHT(C54,1)="M","Married","Single") -> Married | G54: =VLOOKUP(LEFT(C54,1),$H$32:$J$35,2,0) -> Distributor | H54: =VLOOKUP(LEFT(C54,1),$H$32:$J$35,3,0) -> 2500000 | I54: 3 | J54: =IF(F54="Married",I54*25000,I54*0) -> 75000 | K54: =H54+J54 -> 2575000
B55: 3 | C55: B-1-S | D55: Wulan Sari | E55: =IF(MID(C55,3,1)="1","Kepala",IF(MID(C55,3,1)="2","Staff","Operator")) -> Kepala | F55: =IF(RIGHT(C55,1)="M","Married","Single") -> Single | G55: =VLOOKUP(LEFT(C55,1),$H$32:$J$35,2,0) -> Engineering | H55: =VLOOKUP(LEFT(C55,1),$H$32:$J$35,3,0) -> 2300000 | I55: 0 | J55: =IF(F55="Married",I55*25000,I55*0) -> 0 | K55: =H55+J55 -> 2300000
B56: 4 | C56: B-3-M | D56: Toni Sutisna | E56: =IF(MID(C56,3,1)="1","Kepala",IF(MID(C56,3,1)="2","Staff","Operator")) -> Operator | F56: =IF(RIGHT(C56,1)="M","Married","Single") -> Married | G56: =VLOOKUP(LEFT(C56,1),$H$32:$J$35,2,0) -> Engineering | H56: =VLOOKUP(LEFT(C56,1),$H$32:$J$35,3,0) -> 2300000 | I56: 1 | J56: =IF(F56="Married",I56*25000,I56*0) -> 25000 | K56: =H56+J56 -> 2325000
B57: 5 | C57: A-3-S | D57: Didik Wahyudi | E57: =IF(MID(C57,3,1)="1","Kepala",IF(MID(C57,3,1)="2","Staff","Operator")) -> Operator | F57: =IF(RIGHT(C57,1)="M","Married","Single") -> Single | G57: =VLOOKUP(LEFT(C57,1),$H$32:$J$35,2,0) -> Distributor | H57: =VLOOKUP(LEFT(C57,1),$H$32:$J$35,3,0) -> 2500000 | I57: 0 | J57: =IF(F57="Married",I57*25000,I57*0) -> 0 | K57: =H57+J57 -> 2500000
B58: 6 | C58: D-3-M | D58: Tono Hendra | E58: =IF(MID(C58,3,1)="1","Kepala",IF(MID(C58,3,1)="2","Staff","Operator")) -> Operator | F58: =IF(RIGHT(C58,1)="M","Married","Single") -> Married | G58: =VLOOKUP(LEFT(C58,1),$H$32:$J$35,2,0) -> Quality Control | H58: =VLOOKUP(LEFT(C58,1),$H$32:$J$35,3,0) -> 2600000 | I58: 3 | J58: =IF(F58="Married",I58*25000,I58*0) -> 75000 | K58: =H58+J58 -> 2675000
B59: 7 | C59: D-2-S | D59: Bayu Aji | E59: =IF(MID(C59,3,1)="1","Kepala",IF(MID(C59,3,1)="2","Staff","Operator")) -> Staff | F59: =IF(RIGHT(C59,1)="M","Married","Single") -> Single | G59: =VLOOKUP(LEFT(C59,1),$H$32:$J$35,2,0) -> Quality Control | H59: =VLOOKUP(LEFT(C59,1),$H$32:$J$35,3,0) -> 2600000 | I59: 0 | J59: =IF(F59="Married",I59*25000,I59*0) -> 0 | K59: =H59+J59 -> 2600000
B60: 8 | C60: B-2-S | D60: Andi Setiadi | E60: =IF(MID(C60,3,1)="1","Kepala",IF(MID(C60,3,1)="2","Staff","Operator")) -> Staff | F60: =IF(RIGHT(C60,1)="M","Married","Single") -> Single | G60: =VLOOKUP(LEFT(C60,1),$H$32:$J$35,2,0) -> Engineering | H60: =VLOOKUP(LEFT(C60,1),$H$32:$J$35,3,0) -> 2300000 | I60: 0 | J60: =IF(F60="Married",I60*25000,I60*0) -> 0 | K60: =H60+J60 -> 2300000
B61: 9 | C61: C-2-M | D61: Ananda Putra | E61: =IF(MID(C61,3,1)="1","Kepala",IF(MID(C61,3,1)="2","Staff","Operator")) -> Staff | F61: =IF(RIGHT(C61,1)="M","Married","Single") -> Married | G61: =VLOOKUP(LEFT(C61,1),$H$32:$J$35,2,0) -> Produksi | H61: =VLOOKUP(LEFT(C61,1),$H$32:$J$35,3,0) -> 2000000 | I61: 1 | J61: =IF(F61="Married",I61*25000,I61*0) -> 25000 | K61: =H61+J61 -> 2025000
B62: 10 | C62: C-1-M | D62: Rina Nurmalasari | E62: =IF(MID(C62,3,1)="1","Kepala",IF(MID(C62,3,1)="2","Staff","Operator")) -> Kepala | F62: =IF(RIGHT(C62,1)="M","Married","Single") -> Married | G62: =VLOOKUP(LEFT(C62,1),$H$32:$J$35,2,0) -> Produksi | H62: =VLOOKUP(LEFT(C62,1),$H$32:$J$35,3,0) -> 2000000 | I62: 0 | J62: =IF(F62="Married",I62*25000,I62*0) -> 0 | K62: =H62+J62 -> 2000000
J63: Total Seluruh Gaji | K63: =SUM(K53:K62) -> 23850000 | L63: 7
J64: Gaji Terbesar | K64: =MAX(K53:K62) -> 2675000 | L64: 7
J65: Gaji Terendah | K65: =MIN(K53:K62) -> 2000000 | L65: 7
J66: Gaji Rata-Rata | K66: =AVERAGE(K53:K62) -> 2385000 | L66: 7
...

Sheet About
I6: XL-TEST adalah platform inovatif yang menyediakan latihan Excel interaktif dengan pemeriksaan otomatis,
I7: sehingga pengguna dapat langsung mengetahui jawaban yang benar maupun salah.
I10: Terdapat 5 Level soal :
J12: Easy Level | L12: (⭐)
J13: Medium Level | L13: (⭐⭐)
J14: Hard Level | L14: (⭐⭐⭐)
J15: Extreme Level | L15: (⭐⭐⭐⭐)
J16: Championship Level | L16: (⭐⭐⭐⭐⭐)
B17: Saya adalah seorang Excel Holic yang percaya bahwa setiap angka memiliki cerita yang bisa ditemukan dengan cara yang tepat. | I17: Free Access
B18: “Excel bukan cuma soal kerjaan tapi juga hobi yang aku nikmati.” | I18: https://belajarexcel.id/xl-test/
B19: Contact :
B20: 🌐 Web | C20: https://setiadi.me
B21: 🪡threads | C21: https://www.threads.com/@andisetiadi
D27: Perlu Video Penjelasan atau Kunci Jawaban ?
D28: Scan barcode atau kunjungi
D29: https://lynk.id/setiadi/page/jawaban-xl-test

Sheet DF
A1: DEF | C1: 1 | D1: 2 | E1: 3 | F1: 4 | G1: 5 | H1: 6 | I1: 7
A2: EF4 | B2: 1 | C2: =UPPER('XL-Test'!E53) -> KEPALA | D2: =UPPER('XL-Test'!F53) -> MARRIED | E2: =UPPER('XL-Test'!G53) -> DISTRIBUTOR | F2: ='XL-Test'!H53 -> 2500000 | G2: ='XL-Test'!J53 -> 50000 | H2: ='XL-Test'!K53 -> 2550000 | I2: ='XL-Test'!K63 -> 23850000 | L2: 1 | M2: =_xlfn.FORMULATEXT('XL-Test'!E53) -> =IF(MID(C53;3;1)="1";"Kepala";IF(MID(C53;3;1)="2";"Staff";"Operator")) | N2: =_xlfn.FORMULATEXT('XL-Test'!F53) -> =IF(RIGHT(C53;1)="M";"Married";"Single") | O2: =_xlfn.FORMULATEXT('XL-Test'!G53) -> =VLOOKUP(LEFT(C53;1);$H$32:$J$35;2;0) | P2: =_xlfn.FORMULATEXT('XL-Test'!H53) -> =VLOOKUP(LEFT(C53;1);$H$32:$J$35;3;0) | Q2: =_xlfn.FORMULATEXT('XL-Test'!J53) -> =IF(F53="Married";I53*25000;I53*0) | R2: =_xlfn.FORMULATEXT('XL-Test'!K53) -> =H53+J53
B3: 2 | C3: =UPPER('XL-Test'!E54) -> STAFF | D3: =UPPER('XL-Test'!F54) -> MARRIED | E3: =UPPER('XL-Test'!G54) -> DISTRIBUTOR | F3: ='XL-Test'!H54 -> 2500000 | G3: ='XL-Test'!J54 -> 75000 | H3: ='XL-Test'!K54 -> 2575000 | I3: ='XL-Test'!K64 -> 2675000 | L3: 2 | M3: =_xlfn.FORMULATEXT('XL-Test'!F53) -> =IF(RIGHT(C53;1)="M";"Married";"Single")
B4: 3 | C4: =UPPER('XL-Test'!E55) -> KEPALA | D4: =UPPER('XL-Test'!F55) -> SINGLE | E4: =UPPER('XL-Test'!G55) -> ENGINEERING | F4: ='XL-Test'!H55 -> 2300000 | G4: ='XL-Test'!J55 -> 0 | H4: ='XL-Test'!K55 -> 2300000 | I4: ='XL-Test'!K65 -> 2000000 | L4: 3 | M4: =_xlfn.FORMULATEXT('XL-Test'!G53) -> =VLOOKUP(LEFT(C53;1);$H$32:$J$35;2;0)
B5: 4 | C5: =UPPER('XL-Test'!E56) -> OPERATOR | D5: =UPPER('XL-Test'!F56) -> MARRIED | E5: =UPPER('XL-Test'!G56) -> ENGINEERING | F5: ='XL-Test'!H56 -> 2300000 | G5: ='XL-Test'!J56 -> 25000 | H5: ='XL-Test'!K56 -> 2325000 | I5: ='XL-Test'!K66 -> 2385000 | L5: 4 | M5: =_xlfn.FORMULATEXT('XL-Test'!H53) -> =VLOOKUP(LEFT(C53;1);$H$32:$J$35;3;0)
B6: 5 | C6: =UPPER('XL-Test'!E57) -> OPERATOR | D6: =UPPER('XL-Test'!F57) -> SINGLE | E6: =UPPER('XL-Test'!G57) -> DISTRIBUTOR | F6: ='XL-Test'!H57 -> 2500000 | G6: ='XL-Test'!J57 -> 0 | H6: ='XL-Test'!K57 -> 2500000 | I6: ='XL-Test'!K67 -> 10 | L6: 5 | M6: =_xlfn.FORMULATEXT('XL-Test'!J53) -> =IF(F53="Married";I53*25000;I53*0)
B7: 6 | C7: =UPPER('XL-Test'!E58) -> OPERATOR | D7: =UPPER('XL-Test'!F58) -> MARRIED | E7: =UPPER('XL-Test'!G58) -> QUALITY CONTROL | F7: ='XL-Test'!H58 -> 2600000 | G7: ='XL-Test'!J58 -> 75000 | H7: ='XL-Test'!K58 -> 2675000 | L7: 6 | M7: =_xlfn.FORMULATEXT('XL-Test'!K53) -> =H53+J53
B8: 7 | C8: =UPPER('XL-Test'!E59) -> STAFF | D8: =UPPER('XL-Test'!F59) -> SINGLE | E8: =UPPER('XL-Test'!G59) -> QUALITY CONTROL | F8: ='XL-Test'!H59 -> 2600000 | G8: ='XL-Test'!J59 -> 0 | H8: ='XL-Test'!K59 -> 2600000 | J8: =AND(ISNUMBER(FIND("SUM",M8)),ISNUMBER(FIND("(",M8))) -> TRUE | K8: =AND(ISNUMBER(FIND("=",M8)),ISNUMBER(FIND("(",M8))) -> TRUE | L8: 7 | M8: =_xlfn.FORMULATEXT('XL-Test'!K63) -> =SUM(K53:K62)
B9: 8 | C9: =UPPER('XL-Test'!E60) -> STAFF | D9: =UPPER('XL-Test'!F60) -> SINGLE | E9: =UPPER('XL-Test'!G60) -> ENGINEERING | F9: ='XL-Test'!H60 -> 2300000 | G9: ='XL-Test'!J60 -> 0 | H9: ='XL-Test'!K60 -> 2300000 | J9: =AND(ISNUMBER(FIND("MAX",M9)),ISNUMBER(FIND("(",M9))) -> TRUE | K9: =AND(ISNUMBER(FIND("=",M9)),ISNUMBER(FIND("(",M9))) -> TRUE | L9: 7 | M9: =_xlfn.FORMULATEXT('XL-Test'!K64) -> =MAX(K53:K62)
B10: 9 | C10: =UPPER('XL-Test'!E61) -> STAFF | D10: =UPPER('XL-Test'!F61) -> MARRIED | E10: =UPPER('XL-Test'!G61) -> PRODUKSI | F10: ='XL-Test'!H61 -> 2000000 | G10: ='XL-Test'!J61 -> 25000 | H10: ='XL-Test'!K61 -> 2025000 | J10: =AND(ISNUMBER(FIND("MIN",M10)),ISNUMBER(FIND("(",M10))) -> TRUE | K10: =AND(ISNUMBER(FIND("=",M10)),ISNUMBER(FIND("(",M10))) -> TRUE | L10: 7 | M10: =_xlfn.FORMULATEXT('XL-Test'!K65) -> =MIN(K53:K62)
B11: 10 | C11: =UPPER('XL-Test'!E62) -> KEPALA | D11: =UPPER('XL-Test'!F62) -> MARRIED | E11: =UPPER('XL-Test'!G62) -> PRODUKSI | F11: ='XL-Test'!H62 -> 2000000 | G11: ='XL-Test'!J62 -> 0 | H11: ='XL-Test'!K62 -> 2000000 | J11: =AND(ISNUMBER(FIND("AVER",M11)),ISNUMBER(FIND("(",M11))) -> TRUE | K11: =AND(ISNUMBER(FIND("=",M11)),ISNUMBER(FIND("(",M11))) -> TRUE | L11: 7 | M11: =_xlfn.FORMULATEXT('XL-Test'!K66) -> =AVERAGE(K53:K62)
J12: =AND(ISNUMBER(FIND("COUN",M12)),ISNUMBER(FIND("(",M12))) -> TRUE | K12: =AND(ISNUMBER(FIND("=",M12)),ISNUMBER(FIND("(",M12))) -> TRUE | L12: 7 | M12: =_xlfn.FORMULATEXT('XL-Test'!K67) -> =COUNT(K53:K62)
B13: Value | C13: =CODE(LEFT(C2))+(CODE(LEFT(C3))*2)+CODE(LEFT(C4))+CODE(LEFT(C5))+(CODE(LEFT(C6))*3)+CODE(LEFT(C7))+CODE(LEFT(C8))+CODE(LEFT(C9))+(CODE(LEFT(C10))*4)+CODE(LEFT(C11)) +(CODE(RIGHT(C2))*3)+CODE(RIGHT(C3))+CODE(RIGHT(C4))+CODE(RIGHT(C5))+CODE(RIGHT(C6))+(CODE(RIGHT(C7))*2)+CODE(RIGHT(C8))+CODE(RIGHT(C9))+CODE(RIGHT(C10))+CODE(RIGHT(C11)) +CODE(MID(C2,2,1))+CODE(MID(C3,2,1))+CODE(MID(C4,2,1))+CODE(MID(C5,2,1))+CODE(MID(C6,2,1))+CODE(MID(C7,2,1))+CODE(MID(C8,2,1))+(CODE(MID(C9,2,1))*3)+CODE(MID(C10,2,1))+CODE(MID(C11,2,1)) -> 3168 | D13: =CODE(LEFT(D2))+(CODE(LEFT(D3))*2)+CODE(LEFT(D4))+CODE(LEFT(D5))+(CODE(LEFT(D6))*3)+CODE(LEFT(D7))+CODE(LEFT(D8))+CODE(LEFT(D9))+(CODE(LEFT(D10))*4)+CODE(LEFT(D11)) +(CODE(RIGHT(D2))*3)+CODE(RIGHT(D3))+CODE(RIGHT(D4))+CODE(RIGHT(D5))+CODE(RIGHT(D6))+(CODE(RIGHT(D7))*2)+CODE(RIGHT(D8))+CODE(RIGHT(D9))+CODE(RIGHT(D10))+CODE(RIGHT(D11)) +CODE(MID(D2,2,1))+CODE(MID(D3,2,1))+CODE(MID(D4,2,1))+CODE(MID(D5,2,1))+CODE(MID(D6,2,1))+CODE(MID(D7,2,1))+CODE(MID(D8,2,1))+(CODE(MID(D9,2,1))*3)+CODE(MID(D10,2,1))+CODE(MID(D11,2,1)) -> 2984 | E13: =CODE(LEFT(E2))+(CODE(LEFT(E3))*2)+CODE(LEFT(E4))+CODE(LEFT(E5))+(CODE(LEFT(E6))*3)+CODE(LEFT(E7))+CODE(LEFT(E8))+CODE(LEFT(E9))+(CODE(LEFT(E10))*4)+CODE(LEFT(E11)) +(CODE(RIGHT(E2))*3)+CODE(RIGHT(E3))+CODE(RIGHT(E4))+CODE(RIGHT(E5))+CODE(RIGHT(E6))+(CODE(RIGHT(E7))*2)+CODE(RIGHT(E8))+CODE(RIGHT(E9))+CODE(RIGHT(E10))+CODE(RIGHT(E11)) +CODE(MID(E2,2,1))+CODE(MID(E3,2,1))+CODE(MID(E4,2,1))+CODE(MID(E5,2,1))+CODE(MID(E6,2,1))+CODE(MID(E7,2,1))+CODE(MID(E8,2,1))+(CODE(MID(E9,2,1))*3)+CODE(MID(E10,2,1))+CODE(MID(E11,2,1)) -> 3117 | F13: =(SUM(F2:F11)/1000)+LEFT(F2,2)+LEFT(F6,2)+LEFT(F9,2)+LEFT(F11,2) -> 23693 | G13: =SUMPRODUCT(G2:G11,B2:B11)/100 -> 9750 | H13: =(SUM(H2:H11)/1000)+LEFT(H2,2)+LEFT(H6,2)+LEFT(H9,2)+LEFT(H11,2) -> 23943 | I13: =((I2+I3+I4+I5)/100)+I6 -> 309110
C14: =IFERROR(DEC2HEX(IF(OR(C2="",C2=0),C16,C13)),"EEE") -> C60 | D14: =IFERROR(DEC2HEX(IF(OR(D2="",D2=0),D16,D13)),"EEE") -> BA8 | E14: =IFERROR(DEC2HEX(IF(OR(E2="",E2=0),E16,E13)),"EEE") -> C2D | F14: =IFERROR(DEC2HEX(IF(OR(F2="",F2=0),F16,F13)),"EEE") -> 5C8D | G14: =IFERROR(DEC2HEX(IF(OR(G2="",G2=0),G16,G13)),"EEE") -> 2616 | H14: =IFERROR(DEC2HEX(IF(OR(H2="",H2=0),H16,H13)),"EEE") -> 5D87 | I14: =IFERROR(DEC2HEX(IF(OR(I2="",I2=0),I16,I13)),"EEE") -> 4B776 | M14: 1 | N14: 2 | O14: 3 | P14: 4 | Q14: 5 | R14: 6
B16: Rand | C16: 7621 | D16: 8884 | E16: 3308 | F16: 7227 | G16: 8113 | H16: 1400 | I16: 6771
B18: Cek Manual | C18: =AND(ISNUMBER(FIND("=",M2)),ISNUMBER(FIND("(",M2))) -> TRUE | D18: =AND(ISNUMBER(FIND("=",N2)),ISNUMBER(FIND("(",N2))) -> TRUE | E18: =AND(ISNUMBER(FIND("=",O2)),ISNUMBER(FIND("(",O2))) -> TRUE | F18: =AND(ISNUMBER(FIND("=",P2)),ISNUMBER(FIND("(",P2))) -> TRUE | G18: =AND(ISNUMBER(FIND("=",Q2)),ISNUMBER(FIND("(",Q2))) -> TRUE | H18: =AND(ISNUMBER(FIND("=",R2))) -> TRUE | I18: =AND(K8,K9,K10,K11,K12) -> TRUE
C19: =NOT(OR(C2="",C2=0)) -> TRUE | D19: =NOT(OR(D2="",D2=0)) -> TRUE | E19: =NOT(OR(E2="",E2=0)) -> TRUE | F19: =NOT(OR(F2="",F2=0)) -> TRUE | G19: =NOT(OR(G2="",G2=0)) -> TRUE | H19: =NOT(OR(H2="",H2=0)) -> TRUE | I19: =NOT(OR(I2="",I2=0)) -> TRUE
B20: ** | C20: =IFERROR(DEC2HEX(IF(AND(C18,C19,C53),C13,C16)),"EEE") -> C60 | D20: =IFERROR(DEC2HEX(IF(AND(D18,D19,D53),D13,D16)),"EEE") -> BA8 | E20: =IFERROR(DEC2HEX(IF(AND(E18,E19,E53),E13,E16)),"EEE") -> C2D | F20: =IFERROR(DEC2HEX(IF(AND(F18,F19,F53),F13,F16)),"EEE") -> 5C8D | G20: =IFERROR(DEC2HEX(IF(AND(G18,G19,G53),G13,G16)),"EEE") -> 2616 | H20: =IFERROR(DEC2HEX(IF(AND(H18,H19,H53),H13,H16)),"EEE") -> 5D87 | I20: =IFERROR(DEC2HEX(IF(AND(I18,I19,I50),I13,I16)),"EEE") -> 4B776
B23: Formula | C23: =AND(ISNUMBER(FIND("MID",M2)),OR(ISNUMBER(FIND("IF",M2)),ISNUMBER(FIND("SWI",M2)),ISNUMBER(FIND("CHO",M2)),ISNUMBER(FIND("LOOK",M2)))) -> TRUE | D23: =AND(ISNUMBER(FIND("RIGH",N2)),OR(ISNUMBER(FIND("IF",N2)),ISNUMBER(FIND("SWI",N2)))) -> TRUE | E23: =AND(ISNUMBER(FIND("LEFT",O2)),ISNUMBER(FIND("LOOK",O2))) -> TRUE | F23: =AND(ISNUMBER(FIND("LOOK",P2)),OR(ISNUMBER(FIND("G5",P2)),ISNUMBER(FIND("LEFT",P2)))) -> TRUE | G23: =AND(ISNUMBER(FIND("IF",Q2)),OR(ISNUMBER(FIND("*",Q2)),ISNUMBER(FIND("PRODUCT",Q2)))) -> TRUE | H23: =OR(ISNUMBER(FIND("+",R2)),ISNUMBER(FIND("SUM",R2))) -> TRUE | I23: =AND(J8,J9,J10,J11,J12) -> TRUE
B24: Cek banyak | C24: =IFERROR(LEN(M2)-LEN(SUBSTITUTE(M2,"(","")),99) -> 4 | D24: =IFERROR(LEN(N2)-LEN(SUBSTITUTE(N2,"(","")),99) -> 2 | E24: =IFERROR(LEN(O2)-LEN(SUBSTITUTE(O2,"(","")),99) -> 2 | F24: =IFERROR(LEN(P2)-LEN(SUBSTITUTE(P2,"(","")),99) -> 2 | G24: =IFERROR(LEN(Q2)-LEN(SUBSTITUTE(Q2,"(","")),99) -> 1 | H24: =IFERROR(LEN(R2)-LEN(SUBSTITUTE(R2,"(","")),99) -> 0
C25: 6 | D25: 4 | E25: 2 | F25: 2 | G25: 2 | H25: 1 | I25: 1
C26: =C24<=C25 -> TRUE | D26: =D24<=D25 -> TRUE | E26: =E24<=E25 -> TRUE | F26: =F24<=F25 -> TRUE | G26: =G24<=G25 -> TRUE | H26: TRUE | I26: TRUE
B28: TRUE | C28: =DEC2HEX(HEX2DEC(LEFT(DEC2HEX(C16),2))+12+COLUMN()) -> 2C | D28: =DEC2HEX(HEX2DEC(LEFT(DEC2HEX(D16),2))+12+COLUMN()) -> 32 | E28: =DEC2HEX(HEX2DEC(LEFT(DEC2HEX(E16),2))+12+COLUMN()) -> DF | F28: =DEC2HEX(HEX2DEC(LEFT(DEC2HEX(F16),2))+12+COLUMN()) -> 2E | G28: =DEC2HEX(HEX2DEC(LEFT(DEC2HEX(G16),2))+12+COLUMN()) -> 32 | H28: =DEC2HEX(HEX2DEC(LEFT(DEC2HEX(H16),2))+12+COLUMN()) -> 6B | I28: =DEC2HEX(HEX2DEC(LEFT(DEC2HEX(I16),2))+12+COLUMN()) -> 2F
B29: FALSE | C29: =DEC2HEX(HEX2DEC(RIGHT(DEC2HEX(C16),2))+COLUMN()) -> C8 | D29: =DEC2HEX(HEX2DEC(RIGHT(DEC2HEX(D16),2))+COLUMN()) -> B8 | E29: =DEC2HEX(HEX2DEC(RIGHT(DEC2HEX(E16),2))+COLUMN()) -> F1 | F29: =DEC2HEX(HEX2DEC(RIGHT(DEC2HEX(F16),2))+COLUMN()) -> 41 | G29: =DEC2HEX(HEX2DEC(RIGHT(DEC2HEX(G16),2))+COLUMN()) -> B8 | H29: =DEC2HEX(HEX2DEC(RIGHT(DEC2HEX(H16),2))+COLUMN()) -> 80 | I29: =DEC2HEX(HEX2DEC(RIGHT(DEC2HEX(I16),2))+COLUMN()) -> 7C | K29: dari | L29: sini
B31: ** | C31: =IF(AND(C23,C26),C28,C29) -> 2C | D31: =IF(AND(D23,D26),D28,D29) -> 32 | E31: =IF(AND(E23,E26),E28,E29) -> DF | F31: =IF(AND(F23,F26),F28,F29) -> 2E | G31: =IF(AND(G23,G26),G28,G29) -> 32 | H31: =IF(AND(H23,H26),H28,H29) -> 6B | I31: =IF(AND(I23,I26),I28,I29) -> 2F
B32: *** | C32: =C31&"-"&C20&";" -> 2C-C60; | D32: =D31&"-"&D20&";" -> 32-BA8; | E32: =E31&"-"&E20&";" -> DF-C2D; | F32: =F31&"-"&F20&";" -> 2E-5C8D; | G32: =G31&"-"&G20&";" -> 32-2616; | H32: =H31&"-"&H20&";" -> 6B-5D87; | I32: =I31&"-"&I20 -> 2F-4B776
C34: =A2&"|"&C32&D32&E32&F32&G32&H32&I32 -> EF4|2C-C60;32-BA8;DF-C2D;2E-5C8D;32-2616;6B-5D87;2F-4B776 | J34: =C34 -> EF4|2C-C60;32-BA8;DF-C2D;2E-5C8D;32-2616;6B-5D87;2F-4B776
J36: {=INDIRECT(K29&L29)} -> EF4|2C-C60;32-BA8;DF-C2D;2E-5C8D;32-2616;6B-5D87;2F-4B776
A37: 10 | B37: 1 | C37: =LEN(_xlfn.FORMULATEXT('XL-Test'!E53)) -> 70 | D37: =LEN(_xlfn.FORMULATEXT('XL-Test'!F53)) -> 40 | E37: =LEN(_xlfn.FORMULATEXT('XL-Test'!G53)) -> 37 | F37: =LEN(_xlfn.FORMULATEXT('XL-Test'!H53)) -> 37 | G37: =LEN(_xlfn.FORMULATEXT('XL-Test'!J53)) -> 34 | H37: =LEN(_xlfn.FORMULATEXT('XL-Test'!K53)) -> 8
A38: 11 | B38: 2 | C38: =LEN(_xlfn.FORMULATEXT('XL-Test'!E54)) -> 70 | D38: =LEN(_xlfn.FORMULATEXT('XL-Test'!F54)) -> 40 | E38: =LEN(_xlfn.FORMULATEXT('XL-Test'!G54)) -> 37 | F38: =LEN(_xlfn.FORMULATEXT('XL-Test'!H54)) -> 37 | G38: =LEN(_xlfn.FORMULATEXT('XL-Test'!J54)) -> 34 | H38: =LEN(_xlfn.FORMULATEXT('XL-Test'!K54)) -> 8
A39: 12 | B39: 3 | C39: =LEN(_xlfn.FORMULATEXT('XL-Test'!E55)) -> 70 | D39: =LEN(_xlfn.FORMULATEXT('XL-Test'!F55)) -> 40 | E39: =LEN(_xlfn.FORMULATEXT('XL-Test'!G55)) -> 37 | F39: =LEN(_xlfn.FORMULATEXT('XL-Test'!H55)) -> 37 | G39: =LEN(_xlfn.FORMULATEXT('XL-Test'!J55)) -> 34 | H39: =LEN(_xlfn.FORMULATEXT('XL-Test'!K55)) -> 8
A40: 13 | B40: 4 | C40: =LEN(_xlfn.FORMULATEXT('XL-Test'!E56)) -> 70 | D40: =LEN(_xlfn.FORMULATEXT('XL-Test'!F56)) -> 40 | E40: =LEN(_xlfn.FORMULATEXT('XL-Test'!G56)) -> 37 | F40: =LEN(_xlfn.FORMULATEXT('XL-Test'!H56)) -> 37 | G40: =LEN(_xlfn.FORMULATEXT('XL-Test'!J56)) -> 34 | H40: =LEN(_xlfn.FORMULATEXT('XL-Test'!K56)) -> 8
A41: 14 | B41: 5 | C41: =LEN(_xlfn.FORMULATEXT('XL-Test'!E57)) -> 70 | D41: =LEN(_xlfn.FORMULATEXT('XL-Test'!F57)) -> 40 | E41: =LEN(_xlfn.FORMULATEXT('XL-Test'!G57)) -> 37 | F41: =LEN(_xlfn.FORMULATEXT('XL-Test'!H57)) -> 37 | G41: =LEN(_xlfn.FORMULATEXT('XL-Test'!J57)) -> 34 | H41: =LEN(_xlfn.FORMULATEXT('XL-Test'!K57)) -> 8
A42: 15 | B42: 6 | C42: =LEN(_xlfn.FORMULATEXT('XL-Test'!E58)) -> 70 | D42: =LEN(_xlfn.FORMULATEXT('XL-Test'!F58)) -> 40 | E42: =LEN(_xlfn.FORMULATEXT('XL-Test'!G58)) -> 37 | F42: =LEN(_xlfn.FORMULATEXT('XL-Test'!H58)) -> 37 | G42: =LEN(_xlfn.FORMULATEXT('XL-Test'!J58)) -> 34 | H42: =LEN(_xlfn.FORMULATEXT('XL-Test'!K58)) -> 8
A43: 16 | B43: 7 | C43: =LEN(_xlfn.FORMULATEXT('XL-Test'!E59)) -> 70 | D43: =LEN(_xlfn.FORMULATEXT('XL-Test'!F59)) -> 40 | E43: =LEN(_xlfn.FORMULATEXT('XL-Test'!G59)) -> 37 | F43: =LEN(_xlfn.FORMULATEXT('XL-Test'!H59)) -> 37 | G43: =LEN(_xlfn.FORMULATEXT('XL-Test'!J59)) -> 34 | H43: =LEN(_xlfn.FORMULATEXT('XL-Test'!K59)) -> 8
A44: 17 | B44: 8 | C44: =LEN(_xlfn.FORMULATEXT('XL-Test'!E60)) -> 70 | D44: =LEN(_xlfn.FORMULATEXT('XL-Test'!F60)) -> 40 | E44: =LEN(_xlfn.FORMULATEXT('XL-Test'!G60)) -> 37 | F44: =LEN(_xlfn.FORMULATEXT('XL-Test'!H60)) -> 37 | G44: =LEN(_xlfn.FORMULATEXT('XL-Test'!J60)) -> 34 | H44: =LEN(_xlfn.FORMULATEXT('XL-Test'!K60)) -> 8
A45: 18 | B45: 9 | C45: =LEN(_xlfn.FORMULATEXT('XL-Test'!E61)) -> 70 | D45: =LEN(_xlfn.FORMULATEXT('XL-Test'!F61)) -> 40 | E45: =LEN(_xlfn.FORMULATEXT('XL-Test'!G61)) -> 37 | F45: =LEN(_xlfn.FORMULATEXT('XL-Test'!H61)) -> 37 | G45: =LEN(_xlfn.FORMULATEXT('XL-Test'!J61)) -> 34 | H45: =LEN(_xlfn.FORMULATEXT('XL-Test'!K61)) -> 8
A46: 19 | B46: 10 | C46: =LEN(_xlfn.FORMULATEXT('XL-Test'!E62)) -> 70 | D46: =LEN(_xlfn.FORMULATEXT('XL-Test'!F62)) -> 40 | E46: =LEN(_xlfn.FORMULATEXT('XL-Test'!G62)) -> 37 | F46: =LEN(_xlfn.FORMULATEXT('XL-Test'!H62)) -> 37 | G46: =LEN(_xlfn.FORMULATEXT('XL-Test'!J62)) -> 34 | H46: =LEN(_xlfn.FORMULATEXT('XL-Test'!K62)) -> 8
C48: =AVERAGE(C37:C46) -> 70 | D48: =AVERAGE(D37:D46) -> 40 | E48: =AVERAGE(E37:E46) -> 37 | F48: =AVERAGE(F37:F46) -> 37 | G48: =AVERAGE(G37:G46) -> 34 | H48: =AVERAGE(H37:H46) -> 8
C50: =IFERROR(C48=C37,FALSE) -> TRUE | D50: =IFERROR(D48=D37,FALSE) -> TRUE | E50: =IFERROR(E48=E37,FALSE) -> TRUE | F50: =IFERROR(F48=F37,FALSE) -> TRUE | G50: =IFERROR(G48=G37,FALSE) -> TRUE | H50: =IFERROR(H48=H37,FALSE) -> TRUE | I50: TRUE
...
