Workbook
Name kode_jawaban: DF!$O$40
Name sayaa: DF!$O$36

Sheet XL-Test
A19: KODE SOAL | C19: SBEE010 | E19: KODE JAWABAN | F19: =kode_jawaban -> EJ5|13-7E6;1C-866B;19-16DA;3F-1743;5C-D36CD;51-112F;2B-1403;32-1B7B;50-826;5C-1485
A21: Intruksi
B23: Easy Level - Latihan Soal Fungsi Text dan String
B25: Soal : | C25: Gunakan Fungsi Excel (Function) untuk menyelsaikan kasus dibawah ini, tidak disarankan menggunakan cara manual
B26: 1 | C26: Status Jenis Surat diisi berdasarkan hurup pertama kode surat, jika B = Biasa; R = Rahasia; S=Segera
B27: 2 | C27: Isi kolom Tahun Surat berdasarkan kode surat diambil dari karakter ke 7 sampai karakter ke 10
B28: 3 | C28: Isi kolom Bulan Surat berdasarkan kode surat diambil dari karakter ke 12 sampai karakter ke 13
B29: 4 | C29: Isi kolom Tanggal Surat berdasarkan kode surat diambil dari 2 karakter ke terakhir
B30: 5 | C30: Isi Tanggal dengan Tangal yang valid didapat dari gabungan Tahun surat, bulan surat dan tanggal surat dengan FormatCells dd-mmm-yyyy
B31: 6 | C31: Isi kolom Kode Surat Final yang diambil dari kode surat dengan ketentuan setelah nomor tambahkan huruf FL
B32: 7 | C32: isi kolom Nama Peserta dengan nama peserta raw yang sudah dirapihkan dalam bentuk Proper Case (Hurup Pertama Hurup Besar)
B33: 8 | C33: Isi kolom Panjang Karakter dengan jumlah hurup yang ada pada nama peserta termasuk sepasi diantara nama
B34: 9 | C34: Isi Kolom Inisial Nama dengan Inisial dari Nama Peserta yang diambil dari hurup pertama, contoh: AS untuk Andi Saputra
B35: 10 | C35: Gabungkan Inisial dan juga tanggal dalam format Inisial-DDMMMYYYY dimana bulan harus berbahasa Indonesia, contoh : AS-19AGU2024
C37: Sudah selesai mengerjakan? kirim Kode Soal dan Kode Jawaban diatas ke alamat : https://belajarexcel.id/xl-test/jawaban untuk mengecek hasilnya
C38: atau klik tombol disamping
D44: 1 | E44: 2 | F44: 3 | G44: 4 | H44: 5 | I44: 6 | J44: 7 | K44: 8 | L44: 9 | M44: 10
A45: No | B45: Kode Surat | C45: Nama Peserta Raw | D45: Status Jenis Surat | E45: Tahun Surat | F45: Bulan Surat | G45: Tanggal Surat | H45: Tanggal | I45: Kode Surat Final | J45: Nama Peserta | K45: Panjang Karakter | L45: Inisial Nama | M45: Inisial & Tanggal
A46: Contoh | B46: S-099/2024/11/25 | C46: rIzKA NuGRaHa | D46: Segera | E46: 2024 | F46: 11 | G46: 25 | H46: 45621 | I46: S-099FL/2024/11/25 | J46: Rizka Nugraha | K46: 13 | L46: RN | M46: RN-25NOV2024
A48: 1 | B48: B-001/2023/08/19 | C48: aNdi sApUtRa | D48: {=_xlfn.IFS(UPPER(LEFT(TRIM(B48),1))="B", "Biasa", UPPER(LEFT(TRIM(B48),1))="R", "Rahasia", TRUE, "Segera")} -> Biasa | E48: =MID(TRIM(B48),7,4) -> 2023 | F48: =MID(TRIM(B48),12,2) -> 08 | G48: =RIGHT(TRIM(B48),2) -> 19 | H48: =DATE(E48,F48,G48) -> 45157 | I48: =REPLACE(TRIM(B48),6,0,"FL") -> B-001FL/2023/08/19 | J48: =PROPER(TRIM(C48)) -> Andi Saputra | K48: =LEN(J48) -> 12 | L48: =LEFT(J48,1)&MID(J48,FIND(" ",J48,1)+1,1) -> AS | M48: =L48&"-"&UPPER(TEXT(H48,"[$-id-ID]ddmmmyyyy")) -> AS-19AGU2023
A49: 2 | B49: R-002/2023/04/20 | C49: bUDi sANtoSo | D49: {=_xlfn.IFS(UPPER(LEFT(TRIM(B49),1))="B", "Biasa", UPPER(LEFT(TRIM(B49),1))="R", "Rahasia", TRUE, "Segera")} -> Rahasia | E49: =MID(TRIM(B49),7,4) -> 2023 | F49: =MID(TRIM(B49),12,2) -> 04 | G49: =RIGHT(TRIM(B49),2) -> 20 | H49: =DATE(E49,F49,G49) -> 45036 | I49: =REPLACE(TRIM(B49),6,0,"FL") -> R-002FL/2023/04/20 | J49: =PROPER(TRIM(C49)) -> Budi Santoso | K49: =LEN(J49) -> 12 | L49: =LEFT(J49,1)&MID(J49,FIND(" ",J49,1)+1,1) -> BS | M49: =L49&"-"&UPPER(TEXT(H49,"[$-id-ID]ddmmmyyyy")) -> BS-20APR2023
A50: 3 | B50: B-003/2024/08/21 | C50: CiTra dEwi | D50: {=_xlfn.IFS(UPPER(LEFT(TRIM(B50),1))="B", "Biasa", UPPER(LEFT(TRIM(B50),1))="R", "Rahasia", TRUE, "Segera")} -> Biasa | E50: =MID(TRIM(B50),7,4) -> 2024 | F50: =MID(TRIM(B50),12,2) -> 08 | G50: =RIGHT(TRIM(B50),2) -> 21 | H50: =DATE(E50,F50,G50) -> 45525 | I50: =REPLACE(TRIM(B50),6,0,"FL") -> B-003FL/2024/08/21 | J50: =PROPER(TRIM(C50)) -> Citra Dewi | K50: =LEN(J50) -> 10 | L50: =LEFT(J50,1)&MID(J50,FIND(" ",J50,1)+1,1) -> CD | M50: =L50&"-"&UPPER(TEXT(H50,"[$-id-ID]ddmmmyyyy")) -> CD-21AGU2024
A51: 4 | B51: B-004/2024/08/22 | C51: dIaN prAseTyo | D51: {=_xlfn.IFS(UPPER(LEFT(TRIM(B51),1))="B", "Biasa", UPPER(LEFT(TRIM(B51),1))="R", "Rahasia", TRUE, "Segera")} -> Biasa | E51: =MID(TRIM(B51),7,4) -> 2024 | F51: =MID(TRIM(B51),12,2) -> 08 | G51: =RIGHT(TRIM(B51),2) -> 22 | H51: =DATE(E51,F51,G51) -> 45526 | I51: =REPLACE(TRIM(B51),6,0,"FL") -> B-004FL/2024/08/22 | J51: =PROPER(TRIM(C51)) -> Dian Prasetyo | K51: =LEN(J51) -> 13 | L51: =LEFT(J51,1)&MID(J51,FIND(" ",J51,1)+1,1) -> DP | M51: =L51&"-"&UPPER(TEXT(H51,"[$-id-ID]ddmmmyyyy")) -> DP-22AGU2024
A52: 5 | B52: S-005/2024/07/23 | C52: ekO waHyUdi | D52: {=_xlfn.IFS(UPPER(LEFT(TRIM(B52),1))="B", "Biasa", UPPER(LEFT(TRIM(B52),1))="R", "Rahasia", TRUE, "Segera")} -> Segera | E52: =MID(TRIM(B52),7,4) -> 2024 | F52: =MID(TRIM(B52),12,2) -> 07 | G52: =RIGHT(TRIM(B52),2) -> 23 | H52: =DATE(E52,F52,G52) -> 45496 | I52: =REPLACE(TRIM(B52),6,0,"FL") -> S-005FL/2024/07/23 | J52: =PROPER(TRIM(C52)) -> Eko Wahyudi | K52: =LEN(J52) -> 11 | L52: =LEFT(J52,1)&MID(J52,FIND(" ",J52,1)+1,1) -> EW | M52: =L52&"-"&UPPER(TEXT(H52,"[$-id-ID]ddmmmyyyy")) -> EW-23JUL2024
A53: 6 | B53: B-006/2024/08/24 | C53: fiTRi aNJaNi | D53: {=_xlfn.IFS(UPPER(LEFT(TRIM(B53),1))="B", "Biasa", UPPER(LEFT(TRIM(B53),1))="R", "Rahasia", TRUE, "Segera")} -> Biasa | E53: =MID(TRIM(B53),7,4) -> 2024 | F53: =MID(TRIM(B53),12,2) -> 08 | G53: =RIGHT(TRIM(B53),2) -> 24 | H53: =DATE(E53,F53,G53) -> 45528 | I53: =REPLACE(TRIM(B53),6,0,"FL") -> B-006FL/2024/08/24 | J53: =PROPER(TRIM(C53)) -> Fitri Anjani | K53: =LEN(J53) -> 12 | L53: =LEFT(J53,1)&MID(J53,FIND(" ",J53,1)+1,1) -> FA | M53: =L53&"-"&UPPER(TEXT(H53,"[$-id-ID]ddmmmyyyy")) -> FA-24AGU2024
A54: 7 | B54: B-007/2024/08/25 | C54: gAlIh pErMAnA | D54: {=_xlfn.IFS(UPPER(LEFT(TRIM(B54),1))="B", "Biasa", UPPER(LEFT(TRIM(B54),1))="R", "Rahasia", TRUE, "Segera")} -> Biasa | E54: =MID(TRIM(B54),7,4) -> 2024 | F54: =MID(TRIM(B54),12,2) -> 08 | G54: =RIGHT(TRIM(B54),2) -> 25 | H54: =DATE(E54,F54,G54) -> 45529 | I54: =REPLACE(TRIM(B54),6,0,"FL") -> B-007FL/2024/08/25 | J54: =PROPER(TRIM(C54)) -> Galih Permana | K54: =LEN(J54) -> 13 | L54: =LEFT(J54,1)&MID(J54,FIND(" ",J54,1)+1,1) -> GP | M54: =L54&"-"&UPPER(TEXT(H54,"[$-id-ID]ddmmmyyyy")) -> GP-25AGU2024
A55: 8 | B55: R-008/2024/08/02 | C55: heNdRA gUnAwAn | D55: {=_xlfn.IFS(UPPER(LEFT(TRIM(B55),1))="B", "Biasa", UPPER(LEFT(TRIM(B55),1))="R", "Rahasia", TRUE, "Segera")} -> Rahasia | E55: =MID(TRIM(B55),7,4) -> 2024 | F55: =MID(TRIM(B55),12,2) -> 08 | G55: =RIGHT(TRIM(B55),2) -> 02 | H55: =DATE(E55,F55,G55) -> 45506 | I55: =REPLACE(TRIM(B55),6,0,"FL") -> R-008FL/2024/08/02 | J55: =PROPER(TRIM(C55)) -> Hendra Gunawan | K55: =LEN(J55) -> 14 | L55: =LEFT(J55,1)&MID(J55,FIND(" ",J55,1)+1,1) -> HG | M55: =L55&"-"&UPPER(TEXT(H55,"[$-id-ID]ddmmmyyyy")) -> HG-02AGU2024
A56: 9 | B56: S-009/2024/08/27 | C56: iNdAh sARi | D56: {=_xlfn.IFS(UPPER(LEFT(TRIM(B56),1))="B", "Biasa", UPPER(LEFT(TRIM(B56),1))="R", "Rahasia", TRUE, "Segera")} -> Segera | E56: =MID(TRIM(B56),7,4) -> 2024 | F56: =MID(TRIM(B56),12,2) -> 08 | G56: =RIGHT(TRIM(B56),2) -> 27 | H56: =DATE(E56,F56,G56) -> 45531 | I56: =REPLACE(TRIM(B56),6,0,"FL") -> S-009FL/2024/08/27 | J56: =PROPER(TRIM(C56)) -> Indah Sari | K56: =LEN(J56) -> 10 | L56: =LEFT(J56,1)&MID(J56,FIND(" ",J56,1)+1,1) -> IS | M56: =L56&"-"&UPPER(TEXT(H56,"[$-id-ID]ddmmmyyyy")) -> IS-27AGU2024
A57: 10 | B57: B-010/2025/06/28 | C57: joKo sUSiLo | D57: {=_xlfn.IFS(UPPER(LEFT(TRIM(B57),1))="B", "Biasa", UPPER(LEFT(TRIM(B57),1))="R", "Rahasia", TRUE, "Segera")} -> Biasa | E57: =MID(TRIM(B57),7,4) -> 2025 | F57: =MID(TRIM(B57),12,2) -> 06 | G57: =RIGHT(TRIM(B57),2) -> 28 | H57: =DATE(E57,F57,G57) -> 45836 | I57: =REPLACE(TRIM(B57),6,0,"FL") -> B-010FL/2025/06/28 | J57: =PROPER(TRIM(C57)) -> Joko Susilo | K57: =LEN(J57) -> 11 | L57: =LEFT(J57,1)&MID(J57,FIND(" ",J57,1)+1,1) -> JS | M57: =L57&"-"&UPPER(TEXT(H57,"[$-id-ID]ddmmmyyyy")) -> JS-28JUN2025
A58: 11 | B58: B-011/2025/08/29 | C58: KaRTiKa pUtRi | D58: {=_xlfn.IFS(UPPER(LEFT(TRIM(B58),1))="B", "Biasa", UPPER(LEFT(TRIM(B58),1))="R", "Rahasia", TRUE, "Segera")} -> Biasa | E58: =MID(TRIM(B58),7,4) -> 2025 | F58: =MID(TRIM(B58),12,2) -> 08 | G58: =RIGHT(TRIM(B58),2) -> 29 | H58: =DATE(E58,F58,G58) -> 45898 | I58: =REPLACE(TRIM(B58),6,0,"FL") -> B-011FL/2025/08/29 | J58: =PROPER(TRIM(C58)) -> Kartika Putri | K58: =LEN(J58) -> 13 | L58: =LEFT(J58,1)&MID(J58,FIND(" ",J58,1)+1,1) -> KP | M58: =L58&"-"&UPPER(TEXT(H58,"[$-id-ID]ddmmmyyyy")) -> KP-29AGU2025
A59: 12 | B59: R-012/2025/08/29 | C59: lEstAri AyU | D59: {=_xlfn.IFS(UPPER(LEFT(TRIM(B59),1))="B", "Biasa", UPPER(LEFT(TRIM(B59),1))="R", "Rahasia", TRUE, "Segera")} -> Rahasia | E59: =MID(TRIM(B59),7,4) -> 2025 | F59: =MID(TRIM(B59),12,2) -> 08 | G59: =RIGHT(TRIM(B59),2) -> 29 | H59: =DATE(E59,F59,G59) -> 45898 | I59: =REPLACE(TRIM(B59),6,0,"FL") -> R-012FL/2025/08/29 | J59: =PROPER(TRIM(C59)) -> Lestari Ayu | K59: =LEN(J59) -> 11 | L59: =LEFT(J59,1)&MID(J59,FIND(" ",J59,1)+1,1) -> LA | M59: =L59&"-"&UPPER(TEXT(H59,"[$-id-ID]ddmmmyyyy")) -> LA-29AGU2025
... A61: 14 | B61: S-014/2025/11/30 | C61: naDiA kUsUmA | D61: {=_xlfn.IFS(UPPER(LEFT(TRIM(B61),1))="B", "Biasa", UPPER(LEFT(TRIM(B61),1))="R", "Rahasia", TRUE, "Segera")} -> Segera | E61: =MID(TRIM(B61),7,4) -> 2025 | F61: =MID(TRIM(B61),12,2) -> 11 | G61: =RIGHT(TRIM(B61),2) -> 30 | H61: =DATE(E61,F61,G61) -> 45991 | I61: =REPLACE(TRIM(B61),6,0,"FL") -> S-014FL/2025/11/30 | J61: =PROPER(TRIM(C61)) -> Nadia Kusuma | K61: =LEN(J61) -> 12 | L61: =LEFT(J61,1)&MID(J61,FIND(" ",J61,1)+1,1) -> NK | M61: =L61&"-"&UPPER(TEXT(H61,"[$-id-ID]ddmmmyyyy")) -> NK-30NOV2025
B62: Jangan diubah | C62: Jangan diubah
A64: Dilarang mengubah Table atau Menambah Table Baru!!, Gunakan Table seperti yang sudah di sediakan soal, tidak ada kesalahan pada Table soal!!.

Sheet About
I6: XL-TEST adalah platform inovatif yang menyediakan latihan Excel interaktif dengan pemeriksaan otomatis,
I7: sehingga pengguna dapat langsung mengetahui jawaban yang benar maupun salah.
I10: Terdapat 5 Level soal :
J12: Easy Level | L12: (⭐)
J13: Medium Level | L13: (⭐⭐)
J14: Hard Level | L14: (⭐⭐⭐)
J15: Extreme Level | L15: (⭐⭐⭐⭐)
J16: Championship Level | L16: (⭐⭐⭐⭐⭐)
B17: Saya adalah seorang Excel Holic yang percaya bahwa setiap angka memiliki cerita yang bisa ditemukan dengan cara yang tepat. | I17: Free Access
B18: “Excel bukan cuma soal kerjaan tapi juga hobi yang aku nikmati.” | I18: https://belajarexcel.id/xl-test/
B19: Contact :
B20: 🌐 Web | C20: https://setiadi.me
B21: 🪡threads | C21: https://www.threads.com/@andisetiadi
D27: Perlu Video Penjelasan atau Kunci Jawaban ?
D28: Scan barcode atau kunjungi
D29: https://lynk.id/setiadi/page/jawaban-xl-test

Sheet DF
A1: DF | B1: 1 | C1: =UPPER('XL-Test'!D48) -> BIASA | D1: ='XL-Test'!E48 -> 2023 | E1: ='XL-Test'!F48 -> 08 | F1: ='XL-Test'!G48 -> 19 | G1: ='XL-Test'!H48 -> 45157 | H1: ='XL-Test'!I48 -> B-001FL/2023/08/19 | I1: ='XL-Test'!J48 -> Andi Saputra | J1: ='XL-Test'!K48 -> 12 | K1: ='XL-Test'!L48 -> AS | L1: ='XL-Test'!M48 -> AS-19AGU2023 | N1: 1 | O1: =_xlfn.FORMULATEXT('XL-Test'!D48) -> =IFS(UPPER(LEFT(TRIM(B48);1))="B"; "Biasa"; UPPER(LEFT(TRIM(B48);1))="R"; "Rahasia"; TRUE; "Segera") | P1: =_xlfn.FORMULATEXT('XL-Test'!E48) -> =MID(TRIM(B48);7;4) | Q1: =_xlfn.FORMULATEXT('XL-Test'!F48) -> =MID(TRIM(B48);12;2) | R1: =_xlfn.FORMULATEXT('XL-Test'!G48) -> =RIGHT(TRIM(B48);2) | S1: =_xlfn.FORMULATEXT('XL-Test'!H48) -> =DATE(E48;F48;G48) | T1: =_xlfn.FORMULATEXT('XL-Test'!I48) -> =REPLACE(TRIM(B48);6;0;"FL") | U1: =_xlfn.FORMULATEXT('XL-Test'!J48) -> =PROPER(TRIM(C48)) | V1: =_xlfn.FORMULATEXT('XL-Test'!K48) -> =LEN(J48) | ... X1: =_xlfn.FORMULATEXT('XL-Test'!M48) -> =L48&"-"&UPPER(TEXT(H48;"[$-id-ID]ddmmmyyyy"))
A2: EJ5 | B2: 2 | C2: =UPPER('XL-Test'!D49) -> RAHASIA | D2: ='XL-Test'!E49 -> 2023 | E2: ='XL-Test'!F49 -> 04 | F2: ='XL-Test'!G49 -> 20 | G2: ='XL-Test'!H49 -> 45036 | H2: ='XL-Test'!I49 -> R-002FL/2023/04/20 | I2: ='XL-Test'!J49 -> Budi Santoso | J2: ='XL-Test'!K49 -> 12 | K2: ='XL-Test'!L49 -> BS | L2: ='XL-Test'!M49 -> BS-20APR2023 | N2: 2 | O2: =_xlfn.FORMULATEXT('XL-Test'!E48) -> =MID(TRIM(B48);7;4)
B3: 3 | C3: =UPPER('XL-Test'!D50) -> BIASA | D3: ='XL-Test'!E50 -> 2024 | E3: ='XL-Test'!F50 -> 08 | F3: ='XL-Test'!G50 -> 21 | G3: ='XL-Test'!H50 -> 45525 | H3: ='XL-Test'!I50 -> B-003FL/2024/08/21 | I3: ='XL-Test'!J50 -> Citra Dewi | J3: ='XL-Test'!K50 -> 10 | K3: ='XL-Test'!L50 -> CD | L3: ='XL-Test'!M50 -> CD-21AGU2024 | N3: 3 | O3: =_xlfn.FORMULATEXT('XL-Test'!F48) -> =MID(TRIM(B48);12;2)
B4: 4 | C4: =UPPER('XL-Test'!D51) -> BIASA | D4: ='XL-Test'!E51 -> 2024 | E4: ='XL-Test'!F51 -> 08 | F4: ='XL-Test'!G51 -> 22 | G4: ='XL-Test'!H51 -> 45526 | H4: ='XL-Test'!I51 -> B-004FL/2024/08/22 | I4: ='XL-Test'!J51 -> Dian Prasetyo | J4: ='XL-Test'!K51 -> 13 | K4: ='XL-Test'!L51 -> DP | L4: ='XL-Test'!M51 -> DP-22AGU2024 | N4: 4 | O4: =_xlfn.FORMULATEXT('XL-Test'!G48) -> =RIGHT(TRIM(B48);2)
B5: 5 | C5: =UPPER('XL-Test'!D52) -> SEGERA | D5: ='XL-Test'!E52 -> 2024 | E5: ='XL-Test'!F52 -> 07 | F5: ='XL-Test'!G52 -> 23 | G5: ='XL-Test'!H52 -> 45496 | H5: ='XL-Test'!I52 -> S-005FL/2024/07/23 | I5: ='XL-Test'!J52 -> Eko Wahyudi | J5: ='XL-Test'!K52 -> 11 | K5: ='XL-Test'!L52 -> EW | L5: ='XL-Test'!M52 -> EW-23JUL2024 | N5: 5 | O5: =_xlfn.FORMULATEXT('XL-Test'!H48) -> =DATE(E48;F48;G48)
B6: 6 | C6: =UPPER('XL-Test'!D53) -> BIASA | D6: ='XL-Test'!E53 -> 2024 | E6: ='XL-Test'!F53 -> 08 | F6: ='XL-Test'!G53 -> 24 | G6: ='XL-Test'!H53 -> 45528 | H6: ='XL-Test'!I53 -> B-006FL/2024/08/24 | I6: ='XL-Test'!J53 -> Fitri Anjani | J6: ='XL-Test'!K53 -> 12 | K6: ='XL-Test'!L53 -> FA | L6: ='XL-Test'!M53 -> FA-24AGU2024 | N6: 6 | O6: =_xlfn.FORMULATEXT('XL-Test'!I48) -> =REPLACE(TRIM(B48);6;0;"FL")
B7: 7 | C7: =UPPER('XL-Test'!D54) -> BIASA | D7: ='XL-Test'!E54 -> 2024 | E7: ='XL-Test'!F54 -> 08 | F7: ='XL-Test'!G54 -> 25 | G7: ='XL-Test'!H54 -> 45529 | H7: ='XL-Test'!I54 -> B-007FL/2024/08/25 | I7: ='XL-Test'!J54 -> Galih Permana | J7: ='XL-Test'!K54 -> 13 | K7: ='XL-Test'!L54 -> GP | L7: ='XL-Test'!M54 -> GP-25AGU2024 | N7: 7 | O7: =_xlfn.FORMULATEXT('XL-Test'!J48) -> =PROPER(TRIM(C48))
B8: 8 | C8: =UPPER('XL-Test'!D55) -> RAHASIA | D8: ='XL-Test'!E55 -> 2024 | E8: ='XL-Test'!F55 -> 08 | F8: ='XL-Test'!G55 -> 02 | G8: ='XL-Test'!H55 -> 45506 | H8: ='XL-Test'!I55 -> R-008FL/2024/08/02 | I8: ='XL-Test'!J55 -> Hendra Gunawan | J8: ='XL-Test'!K55 -> 14 | K8: ='XL-Test'!L55 -> HG | L8: ='XL-Test'!M55 -> HG-02AGU2024 | N8: 8 | O8: =_xlfn.FORMULATEXT('XL-Test'!K48) -> =LEN(J48)
B9: 9 | C9: =UPPER('XL-Test'!D56) -> SEGERA | D9: ='XL-Test'!E56 -> 2024 | E9: ='XL-Test'!F56 -> 08 | F9: ='XL-Test'!G56 -> 27 | G9: ='XL-Test'!H56 -> 45531 | H9: ='XL-Test'!I56 -> S-009FL/2024/08/27 | I9: ='XL-Test'!J56 -> Indah Sari | J9: ='XL-Test'!K56 -> 10 | K9: ='XL-Test'!L56 -> IS | L9: ='XL-Test'!M56 -> IS-27AGU2024 | N9: 9 | O9: =_xlfn.FORMULATEXT('XL-Test'!L48) -> =LEFT(J48;1)&MID(J48;FIND(" ";J48;1)+1;1)
B10: 10 | C10: =UPPER('XL-Test'!D57) -> BIASA | D10: ='XL-Test'!E57 -> 2025 | E10: ='XL-Test'!F57 -> 06 | F10: ='XL-Test'!G57 -> 28 | G10: ='XL-Test'!H57 -> 45836 | H10: ='XL-Test'!I57 -> B-010FL/2025/06/28 | I10: ='XL-Test'!J57 -> Joko Susilo | J10: ='XL-Test'!K57 -> 11 | K10: ='XL-Test'!L57 -> JS | L10: ='XL-Test'!M57 -> JS-28JUN2025 | N10: 10 | O10: =_xlfn.FORMULATEXT('XL-Test'!M48) -> =L48&"-"&UPPER(TEXT(H48;"[$-id-ID]ddmmmyyyy"))
B11: 11 | C11: =UPPER('XL-Test'!D58) -> BIASA | D11: ='XL-Test'!E58 -> 2025 | E11: ='XL-Test'!F58 -> 08 | F11: ='XL-Test'!G58 -> 29 | G11: ='XL-Test'!H58 -> 45898 | H11: ='XL-Test'!I58 -> B-011FL/2025/08/29 | I11: ='XL-Test'!J58 -> Kartika Putri | J11: ='XL-Test'!K58 -> 13 | K11: ='XL-Test'!L58 -> KP | L11: ='XL-Test'!M58 -> KP-29AGU2025
B12: 12 | C12: =UPPER('XL-Test'!D59) -> RAHASIA | D12: ='XL-Test'!E59 -> 2025 | E12: ='XL-Test'!F59 -> 08 | F12: ='XL-Test'!G59 -> 29 | G12: ='XL-Test'!H59 -> 45898 | H12: ='XL-Test'!I59 -> R-012FL/2025/08/29 | I12: ='XL-Test'!J59 -> Lestari Ayu | J12: ='XL-Test'!K59 -> 11 | K12: ='XL-Test'!L59 -> LA | L12: ='XL-Test'!M59 -> LA-29AGU2025 | O12: 1 | P12: 2 | Q12: 3 | R12: 4 | S12: 5 | T12: 6 | U12: 7 | V12: 8 | W12: 9 | X12: 10
B13: 13 | C13: =UPPER('XL-Test'!D60) -> SEGERA | D13: ='XL-Test'!E60 -> 2025 | E13: ='XL-Test'!F60 -> 08 | F13: ='XL-Test'!G60 -> 30 | G13: ='XL-Test'!H60 -> 45899 | H13: ='XL-Test'!I60 -> S-013FL/2025/08/30 | I13: ='XL-Test'!J60 -> Muhammad Rizky | J13: ='XL-Test'!K60 -> 14 | K13: ='XL-Test'!L60 -> MR | L13: ='XL-Test'!M60 -> MR-30AGU2025
B14: 14 | C14: =UPPER('XL-Test'!D61) -> SEGERA | D14: ='XL-Test'!E61 -> 2025 | E14: ='XL-Test'!F61 -> 11 | F14: ='XL-Test'!G61 -> 30 | G14: ='XL-Test'!H61 -> 45991 | H14: ='XL-Test'!I61 -> S-014FL/2025/11/30 | I14: ='XL-Test'!J61 -> Nadia Kusuma | J14: ='XL-Test'!K61 -> 12 | K14: ='XL-Test'!L61 -> NK | L14: ='XL-Test'!M61 -> NK-30NOV2025
B17: Value | C17: =CODE(LEFT(C1))+CODE(LEFT(C2))+CODE(LEFT(C3))+CODE(LEFT(C4))+CODE(LEFT(C5))+CODE(LEFT(C6))+CODE(LEFT(C7))+CODE(LEFT(C8))+CODE(LEFT(C9))+CODE(LEFT(C10))+CODE(LEFT(C11))+CODE(LEFT(C12))+CODE(LEFT(C13))+CODE(LEFT(C14)) +CODE(MID(C1,2,1))+CODE(MID(C2,2,1))+CODE(MID(C3,2,1))+CODE(MID(C4,2,1))+CODE(MID(C5,2,1))+CODE(MID(C6,2,1))+CODE(MID(C7,2,1))+CODE(MID(C8,2,1))+CODE(MID(C9,2,1))+CODE(MID(C10,2,1))+CODE(MID(C11,2,1))+CODE(MID(C12,2,1))+CODE(MID(C13,2,1))+CODE(MID(C14,2,1)) -> 2022 | D17: =D1+D2+D3+D4+D5+D6+D7+D8+D9+D10+D11+D12+D13+D14+D3+D10+D1 -> 34411 | E17: =(E1+E2+E3+E4+E5+E6+E7+E8+E9+E10+E11+E12+E13+E14+E3+E10+E1)*45 -> 5850 | F17: =(F1+F2+F3+F4+F5+F6+F7+F8+F9+F10+F11+F12+F13+F14+F3+F10+F1)*15 -> 5955 | G17: =SUM(G1:G14)+G1+G4+G7+G9+G12 -> 865997 | H17: =CODE(LEFT(H1))+CODE(LEFT(H2))+CODE(LEFT(H3))+CODE(LEFT(H4))+CODE(LEFT(H5))+CODE(LEFT(H6))+CODE(LEFT(H7))+CODE(LEFT(H8))+CODE(LEFT(H9))+CODE(LEFT(H10))+CODE(LEFT(H11))+CODE(LEFT(H12))+CODE(LEFT(H13))+CODE(LEFT(H14)) +CODE(MID(H1,2,1))+CODE(MID(H2,2,1))+CODE(MID(H3,2,1))+CODE(MID(H4,2,1))+CODE(MID(H5,2,1))+CODE(MID(H6,2,1))+CODE(MID(H7,2,1))+CODE(MID(H8,2,1))+CODE(MID(H9,2,1))+CODE(MID(H10,2,1))+CODE(MID(H11,2,1))+CODE(MID(H12,2,1))+CODE(MID(H13,2,1))+CODE(MID(H14,2,1)) +CODE(RIGHT(H1))+CODE(RIGHT(H2))+CODE(RIGHT(H3))+CODE(RIGHT(H4))+CODE(RIGHT(H5))+CODE(RIGHT(H6))+CODE(RIGHT(H7))+CODE(RIGHT(H8))+CODE(RIGHT(H9))+CODE(RIGHT(H10))+CODE(RIGHT(H11))+CODE(RIGHT(H12))+CODE(RIGHT(H13))+CODE(RIGHT(H14)) +CODE(MID(H1,7,1))+CODE(MID(H2,7,1))+CODE(MID(H3,7,1))+CODE(MID(H4,7,1))+CODE(MID(H5,7,1))+CODE(MID(H6,7,1))+CODE(MID(H7,7,1))+CODE(MID(H8,7,1))+CODE(MID(H9,7,1))+CODE(MID(H10,7,1))+CODE(MID(H11,7,1))+CODE(MID(H12,7,1))+CODE(MID(H13,7,1))+CODE(MID(H14,7,1)) +CODE(MID(H1,6,1))+CODE(MID(H2,6,1))+CODE(MID(H3,6,1))+CODE(MID(H4,6,1))+CODE(MID(H5,6,1))+CODE(MID(H6,6,1))+CODE(MID(H7,6,1))+CODE(MID(H8,6,1))+CODE(MID(H9,6,1))+CODE(MID(H10,6,1))+CODE(MID(H11,6,1))+CODE(MID(H12,6,1))+CODE(MID(H13,8,1))+CODE(MID(H14,8,1)) -> 4399 | I17: =CODE(LEFT(I1))+CODE(LEFT(I2))+CODE(LEFT(I3))+CODE(LEFT(I4))+CODE(LEFT(I5))+CODE(LEFT(I6))+CODE(LEFT(I7))+CODE(LEFT(I8))+CODE(LEFT(I9))+CODE(LEFT(I10))+CODE(LEFT(I11))+CODE(LEFT(I12))+CODE(LEFT(I13))+CODE(LEFT(I14)) +CODE(MID(I1,2,1))+CODE(MID(I2,2,1))+CODE(MID(I3,2,1))+CODE(MID(I4,2,1))+CODE(MID(I5,2,1))+CODE(MID(I6,2,1))+CODE(MID(I7,2,1))+CODE(MID(I8,2,1))+CODE(MID(I9,2,1))+CODE(MID(I10,2,1))+CODE(MID(I11,2,1))+CODE(MID(I12,2,1))+CODE(MID(I13,2,1))+CODE(MID(I14,2,1)) +CODE(RIGHT(I1))+CODE(RIGHT(I2))+CODE(RIGHT(I3))+CODE(RIGHT(I4))+CODE(RIGHT(I5))+CODE(RIGHT(I6))+CODE(RIGHT(I7))+CODE(RIGHT(I8))+CODE(RIGHT(I9))+CODE(RIGHT(I10))+CODE(RIGHT(I11))+CODE(RIGHT(I12))+CODE(RIGHT(I13))+CODE(RIGHT(I14)) +CODE(MID(I1,6,1))+CODE(MID(I2,6,1))+CODE(MID(I3,7,1))+CODE(MID(I4,6,1))+CODE(MID(I5,5,1))+CODE(MID(I6,7,1))+CODE(MID(I7,7,1))+CODE(MID(I8,8,1))+CODE(MID(I9,7,1))+CODE(MID(I10,6,1))+CODE(MID(I11,10,1))+CODE(MID(I12,9,1))+CODE(MID(I13,11,1))+CODE(MID(I14,7,1)) -> 5123 | J17: =(J1+J2+J3+J4+J5+J6+J7+J8+J9+J10+J11+J12+J13+J14+J3+J10+J1)*35 -> 7035 | K17: =CODE(LEFT(K1))+CODE(LEFT(K2))+CODE(LEFT(K3))+CODE(LEFT(K4))+CODE(LEFT(K5))+CODE(LEFT(K6))+CODE(LEFT(K7))+CODE(LEFT(K8))+CODE(LEFT(K9))+CODE(LEFT(K10))+CODE(LEFT(K11))+CODE(LEFT(K12))+CODE(LEFT(K13))+CODE(LEFT(K14)) +CODE(MID(K1,2,1))+CODE(MID(K2,2,1))+CODE(MID(K3,2,1))+CODE(MID(K4,2,1))+CODE(MID(K5,2,1))+CODE(MID(K6,2,1))+CODE(MID(K7,2,1))+CODE(MID(K8,2,1))+CODE(MID(K9,2,1))+CODE(MID(K10,2,1))+CODE(MID(K11,2,1))+CODE(MID(K12,2,1))+CODE(MID(K13,2,1))+CODE(MID(K14,2,1)) -> 2086 | L17: =CODE(LEFT(L1))+CODE(LEFT(L2))+CODE(LEFT(L3))+CODE(LEFT(L4))+CODE(LEFT(L5))+CODE(LEFT(L6))+CODE(LEFT(L7))+CODE(LEFT(L8))+CODE(LEFT(L9))+CODE(LEFT(L10))+CODE(LEFT(L11))+CODE(LEFT(L12))+CODE(LEFT(L13))+CODE(LEFT(L14)) +CODE(MID(L1,2,1))+CODE(MID(L2,2,1))+CODE(MID(L3,2,1))+CODE(MID(L4,2,1))+CODE(MID(L5,2,1))+CODE(MID(L6,2,1))+CODE(MID(L7,2,1))+CODE(MID(L8,2,1))+CODE(MID(L9,2,1))+CODE(MID(L10,2,1))+CODE(MID(L11,2,1))+CODE(MID(L12,2,1))+CODE(MID(L13,2,1))+CODE(MID(L14,2,1)) +CODE(RIGHT(L1))+CODE(RIGHT(L2))+CODE(RIGHT(L3))+CODE(RIGHT(L4))+CODE(RIGHT(L5))+CODE(RIGHT(L6))+CODE(RIGHT(L7))+CODE(RIGHT(L8))+CODE(RIGHT(L9))+CODE(RIGHT(L10))+CODE(RIGHT(L11))+CODE(RIGHT(L12))+CODE(RIGHT(L13))+CODE(RIGHT(L14)) +CODE(MID(L1,7,1))+CODE(MID(L2,7,1))+CODE(MID(L3,7,1))+CODE(MID(L4,7,1))+CODE(MID(L5,7,1))+CODE(MID(L6,7,1))+CODE(MID(L7,7,1))+CODE(MID(L8,7,1))+CODE(MID(L9,7,1))+CODE(MID(L10,7,1))+CODE(MID(L11,7,1))+CODE(MID(L12,7,1))+CODE(MID(L13,7,1))+CODE(MID(L14,7,1)) +CODE(MID(L1,8,1))+CODE(MID(L2,8,1))+CODE(MID(L3,8,1))+CODE(MID(L4,8,1))+CODE(MID(L5,8,1))+CODE(MID(L6,8,1))+CODE(MID(L7,8,1))+CODE(MID(L8,8,1))+CODE(MID(L9,8,1))+CODE(MID(L10,8,1))+CODE(MID(L11,8,1))+CODE(MID(L12,8,1))+CODE(MID(L13,8,1))+CODE(MID(L14,8,1))+CODE(MID(L14,3,1))+CODE(MID(L13,3,1))+CODE(MID(L10,3,1))+CODE(MID(L2,3,1))+CODE(MID(L5,3,1)) -> 5253
B19: RND | C19: 1736 | D19: 2545 | E19: 2064 | F19: 5862 | G19: 8495 | H19: 7763 | I19: 3888 | J19: 4375 | K19: 7893 | L19: 8797
A20: *** | B20: F Value | C20: =IFERROR(DEC2HEX(IF(AND(C25:C27),C17,C19)),"EEE") -> 7E6 | D20: =IFERROR(DEC2HEX(IF(AND(D25:D27),D17,D19)),"EEE") -> 866B | E20: =IFERROR(DEC2HEX(IF(AND(E25:E27),E17,E19)),"EEE") -> 16DA | F20: =IFERROR(DEC2HEX(IF(AND(F25:F27),F17,F19)),"EEE") -> 1743 | G20: =IFERROR(DEC2HEX(IF(AND(G25:G27),G17,G19)),"EEE") -> D36CD | H20: =IFERROR(DEC2HEX(IF(AND(H25:H27),H17,H19)),"EEE") -> 112F | I20: =IFERROR(DEC2HEX(IF(AND(I25:I27),I17,I19)),"EEE") -> 1403 | J20: =IFERROR(DEC2HEX(IF(AND(J25:J27),J17,J19)),"EEE") -> 1B7B | ... L20: =IFERROR(DEC2HEX(IF(AND(L25:L27),L17,L19)),"EEE") -> 1485
B22: TRUE | C22: =DEC2HEX(LEFT(C19,2)+IFERROR(LEFT(C17),COLUMN())) -> 13 | D22: =DEC2HEX(LEFT(D19,2)+IFERROR(LEFT(D17),COLUMN())) -> 1C | E22: =DEC2HEX(LEFT(E19,2)+IFERROR(LEFT(E17),COLUMN())) -> 19 | F22: =DEC2HEX(LEFT(F19,2)+IFERROR(LEFT(F17),COLUMN())) -> 3F | G22: =DEC2HEX(LEFT(G19,2)+IFERROR(LEFT(G17),COLUMN())) -> 5C | H22: =DEC2HEX(LEFT(H19,2)+IFERROR(LEFT(H17),COLUMN())) -> 51 | I22: =DEC2HEX(LEFT(I19,2)+IFERROR(LEFT(I17),COLUMN())) -> 2B | J22: =DEC2HEX(LEFT(J19,2)+IFERROR(LEFT(J17),COLUMN())) -> 32 | ... L22: =DEC2HEX(LEFT(L19,2)+IFERROR(LEFT(L17),COLUMN())) -> 5C
B23: FALSE | C23: =DEC2HEX(RIGHT(C19,2)+IFERROR(RIGHT(C17),COLUMN())) -> 26 | D23: =DEC2HEX(RIGHT(D19,2)+IFERROR(RIGHT(D17),COLUMN())) -> 2E | E23: =DEC2HEX(RIGHT(E19,2)+IFERROR(RIGHT(E17),COLUMN())) -> 40 | F23: =DEC2HEX(RIGHT(F19,2)+IFERROR(RIGHT(F17),COLUMN())) -> 43 | G23: =DEC2HEX(RIGHT(G19,2)+IFERROR(RIGHT(G17),COLUMN())) -> 66 | H23: =DEC2HEX(RIGHT(H19,2)+IFERROR(RIGHT(H17),COLUMN())) -> 48 | I23: =DEC2HEX(RIGHT(I19,2)+IFERROR(RIGHT(I17),COLUMN())) -> 5B | J23: =DEC2HEX(RIGHT(J19,2)+IFERROR(RIGHT(J17),COLUMN())) -> 50 | ... L23: =DEC2HEX(RIGHT(L19,2)+IFERROR(RIGHT(L17),COLUMN())) -> 64
B25: Cek kosong | C25: =NOT(OR(C1=0,C1="")) -> TRUE | D25: =NOT(OR(D1=0,D1="")) -> TRUE | E25: =NOT(OR(E1=0,E1="")) -> TRUE | F25: =NOT(OR(F1=0,F1="")) -> TRUE | G25: =NOT(OR(G1=0,G1="")) -> TRUE | H25: =NOT(OR(H1=0,H1="")) -> TRUE | I25: =NOT(OR(I1=0,I1="")) -> TRUE | J25: =NOT(OR(J1=0,J1="")) -> TRUE | ... L25: =NOT(OR(L1=0,L1="")) -> TRUE
B26: Cek Tarik | C26: =C66 -> TRUE | D26: =D66 -> TRUE | E26: =E66 -> TRUE | F26: =F66 -> TRUE | G26: =G66 -> TRUE | H26: =H66 -> TRUE | I26: =I66 -> TRUE | J26: =J66 -> TRUE | ... L26: =L66 -> TRUE
B27: Cek Manual | C27: =AND(ISNUMBER(FIND("=",O1)),ISNUMBER(FIND("(",O1)),C40) -> TRUE | D27: =AND(ISNUMBER(FIND("=",P1)),ISNUMBER(FIND("(",P1)),D40) -> TRUE | E27: =AND(ISNUMBER(FIND("=",Q1)),ISNUMBER(FIND("(",Q1)),E40) -> TRUE | F27: =AND(ISNUMBER(FIND("=",R1)),ISNUMBER(FIND("(",R1)),F40) -> TRUE | G27: =AND(ISNUMBER(FIND("=",S1)),ISNUMBER(FIND("(",S1)),G40) -> TRUE | H27: =AND(ISNUMBER(FIND("=",T1)),ISNUMBER(FIND("(",T1)),H40) -> TRUE | I27: =AND(ISNUMBER(FIND("=",U1)),ISNUMBER(FIND("(",U1)),I40) -> TRUE | J27: =AND(ISNUMBER(FIND("=",V1)),ISNUMBER(FIND("(",V1)),J40) -> TRUE | ... L27: =AND(ISNUMBER(FIND("=",X1)),ISNUMBER(FIND("(",X1)),L40) -> TRUE
B29: Cek Formula | C29: =OR(AND(ISNUMBER(FIND("RIM",SUBSTITUTE(O1,"$",""))),ISNUMBER(FIND("EFT",SUBSTITUTE(O1,"$",""))),ISNUMBER(FIND("IF",SUBSTITUTE(O1,"$","")))),AND(ISNUMBER(FIND("SW",SUBSTITUTE(O1,"$",""))),ISNUMBER(FIND("RIM",SUBSTITUTE(O1,"$",""))))) -> TRUE | D29: =AND(ISNUMBER(FIND("TR",SUBSTITUTE(O2,"$",""))),ISNUMBER(FIND("ID",SUBSTITUTE(O2,"$","")))) -> TRUE | E29: =AND(ISNUMBER(FIND("TR",SUBSTITUTE(O3,"$",""))),ISNUMBER(FIND("ID",SUBSTITUTE(O3,"$","")))) -> TRUE | F29: =AND(ISNUMBER(FIND("TR",SUBSTITUTE(O4,"$",""))),ISNUMBER(FIND("GH",SUBSTITUTE(O4,"$","")))) -> TRUE | G29: =OR(ISNUMBER(FIND("ATE",SUBSTITUTE(O5,"$",""))),ISNUMBER(FIND("VAL",SUBSTITUTE(O5,"$","")))) -> TRUE | H29: =AND(ISNUMBER(FIND("PLA",SUBSTITUTE(O6,"$",""))),ISNUMBER(FIND("TR",SUBSTITUTE(O6,"$","")))) -> TRUE | I29: =AND(ISNUMBER(FIND("OP",SUBSTITUTE(O7,"$",""))),ISNUMBER(FIND("TR",SUBSTITUTE(O7,"$","")))) -> TRUE | J29: =AND(ISNUMBER(FIND("EN",SUBSTITUTE(O8,"$",""))),ISNUMBER(FIND("LE",SUBSTITUTE(O8,"$","")))) -> TRUE | K29: =OR(AND(ISNUMBER(FIND("EFT",SUBSTITUTE(O9,"$",""))),ISNUMBER(FIND("IND",SUBSTITUTE(O9,"$","")))),AND(ISNUMBER(FIND("EFT",SUBSTITUTE(O9,"$",""))),ISNUMBER(FIND("SP",SUBSTITUTE(O9,"$",""))))) -> TRUE | L29: =AND(ISNUMBER(FIND("EXT",SUBSTITUTE(O10,"$",""))),OR(ISNUMBER(FIND("&",SUBSTITUTE(O10,"$",""))),ISNUMBER(FIND("ON",SUBSTITUTE(O10,"$",""))))) -> TRUE
B31: V | C31: =IF(AND(C29,C38),C22,C23)&"-"&C20&";" -> 13-7E6; | D31: =IF(AND(D29,D38),D22,D23)&"-"&D20&";" -> 1C-866B; | E31: =IF(AND(E29,E38),E22,E23)&"-"&E20&";" -> 19-16DA; | F31: =IF(AND(F29,F38),F22,F23)&"-"&F20&";" -> 3F-1743; | G31: =IF(AND(G29,G38),G22,G23)&"-"&G20&";" -> 5C-D36CD; | H31: =IF(AND(H29,H38),H22,H23)&"-"&H20&";" -> 51-112F; | I31: =IF(AND(I29,I38),I22,I23)&"-"&I20&";" -> 2B-1403; | J31: =IF(AND(J29,J38),J22,J23)&"-"&J20&";" -> 32-1B7B; | K31: =IF(AND(K29,K38),K22,K23)&"-"&K20&";" -> 50-826; | L31: =IF(AND(L29,L38),L22,L23)&"-"&L20 -> 5C-1485
B33: =CODE(LEFT('XL-Test'!B49)) -> 32 | C33: =IF(AND(B33=32,B34=32),A2&"|"&C31&D31&E31&F31&G31&H31&I31&J31&K31&L31,"Data Soal berubah!Silahkan kembalikan seperti semula") -> EJ5|13-7E6;1C-866B;19-16DA;3F-1743;5C-D36CD;51-112F;2B-1403;32-1B7B;50-826;5C-1485 | O33: say | P33: aa
B34: =CODE(LEFT('XL-Test'!C48)) -> 32
C35: 1 | D35: 2 | E35: 3 | F35: 4 | G35: 5 | H35: 6 | I35: 7 | J35: 8 | K35: 9 | L35: 10
B36: Cek Fungsi | C36: =IFERROR(LEN(O1)-LEN(SUBSTITUTE(O1,"(","")),99) -> 7 | D36: =IFERROR(LEN(P1)-LEN(SUBSTITUTE(P1,"(","")),99) -> 2 | E36: =IFERROR(LEN(Q1)-LEN(SUBSTITUTE(Q1,"(","")),99) -> 2 | F36: =IFERROR(LEN(R1)-LEN(SUBSTITUTE(R1,"(","")),99) -> 2 | G36: =IFERROR(LEN(S1)-LEN(SUBSTITUTE(S1,"(","")),99) -> 1 | H36: =IFERROR(LEN(T1)-LEN(SUBSTITUTE(T1,"(","")),99) -> 2 | I36: =IFERROR(LEN(U1)-LEN(SUBSTITUTE(U1,"(","")),99) -> 2 | J36: =IFERROR(LEN(V1)-LEN(SUBSTITUTE(V1,"(","")),99) -> 1 | ... L36: =IFERROR(LEN(X1)-LEN(SUBSTITUTE(X1,"(","")),99) -> 2 | O36: =C33 -> EJ5|13-7E6;1C-866B;19-16DA;3F-1743;5C-D36CD;51-112F;2B-1403;32-1B7B;50-826;5C-1485
B37: Harusnya | C37: 9 | D37: 2 | E37: 2 | F37: 2 | G37: 1 | H37: 2 | I37: 2 | J37: 2 | K37: 3 | L37: 2
B38: ** | C38: =(C36<=C37) -> TRUE | D38: =(D36<=D37) -> TRUE | E38: =(E36<=E37) -> TRUE | F38: =(F36<=F37) -> TRUE | G38: =(G36<=G37) -> TRUE | H38: =(H36<=H37) -> TRUE | I38: =(I36<=I37) -> TRUE | J38: =(J36<=J37) -> TRUE | ... L38: =(L36<=L37) -> TRUE
B40: Cek Wajib | C40: =AND(ISNUMBER(FIND("TRI",O1)),ISTEXT(C1)) -> TRUE | D40: =ISNUMBER(FIND("TRI",P1)) -> TRUE | E40: =ISNUMBER(FIND("TRI",Q1)) -> TRUE | F40: =ISNUMBER(FIND("TRI",R1)) -> TRUE | G40: =ISNUMBER(G1) -> TRUE | H40: =ISNUMBER(FIND("TRI",T1)) -> TRUE | I40: =ISNUMBER(FIND("TRI",U1)) -> TRUE | J40: =ISNUMBER(J1) -> TRUE | K40: =ISTEXT(K1) -> TRUE | L40: TRUE | O40: {=INDIRECT(O33&P33)} -> EJ5|13-7E6;1C-866B;19-16DA;3F-1743;5C-D36CD;51-112F;2B-1403;32-1B7B;50-826;5C-1485
B41: **
A43: 7 | B43: 1 | C43: =IFERROR(LEN(_xlfn.FORMULATEXT('XL-Test'!D48)),0) -> 100 | D43: =IFERROR(LEN(_xlfn.FORMULATEXT('XL-Test'!E48)),0) -> 19 | E43: =IFERROR(LEN(_xlfn.FORMULATEXT('XL-Test'!F48)),0) -> 20 | F43: =IFERROR(LEN(_xlfn.FORMULATEXT('XL-Test'!G48)),0) -> 19 | G43: =IFERROR(LEN(_xlfn.FORMULATEXT('XL-Test'!H48)),0) -> 18 | H43: =IFERROR(LEN(_xlfn.FORMULATEXT('XL-Test'!I48)),0) -> 28 | I43: =IFERROR(LEN(_xlfn.FORMULATEXT('XL-Test'!J48)),0) -> 18 | J43: =IFERROR(LEN(_xlfn.FORMULATEXT('XL-Test'!K48)),0) -> 9 | ... L43: =IFERROR(LEN(_xlfn.FORMULATEXT('XL-Test'!M48)),0) -> 46
A44: 8 | B44: 2 | C44: =IFERROR(LEN(_xlfn.FORMULATEXT('XL-Test'!D49)),0) -> 100 | D44: =IFERROR(LEN(_xlfn.FORMULATEXT('XL-Test'!E49)),0) -> 19 | E44: =IFERROR(LEN(_xlfn.FORMULATEXT('XL-Test'!F49)),0) -> 20 | F44: =IFERROR(LEN(_xlfn.FORMULATEXT('XL-Test'!G49)),0) -> 19 | G44: =IFERROR(LEN(_xlfn.FORMULATEXT('XL-Test'!H49)),0) -> 18 | H44: =IFERROR(LEN(_xlfn.FORMULATEXT('XL-Test'!I49)),0) -> 28 | I44: =IFERROR(LEN(_xlfn.FORMULATEXT('XL-Test'!J49)),0) -> 18 | J44: =IFERROR(LEN(_xlfn.FORMULATEXT('XL-Test'!K49)),0) -> 9 | ... L44: =IFERROR(LEN(_xlfn.FORMULATEXT('XL-Test'!M49)),0) -> 46
A45: 9 | B45: 3 | C45: =IFERROR(LEN(_xlfn.FORMULATEXT('XL-Test'!D50)),0) -> 100 | D45: =IFERROR(LEN(_xlfn.FORMULATEXT('XL-Test'!E50)),0) -> 19 | E45: =IFERROR(LEN(_xlfn.FORMULATEXT('XL-Test'!F50)),0) -> 20 | F45: =IFERROR(LEN(_xlfn.FORMULATEXT('XL-Test'!G50)),0) -> 19 | G45: =IFERROR(LEN(_xlfn.FORMULATEXT('XL-Test'!H50)),0) -> 18 | H45: =IFERROR(LEN(_xlfn.FORMULATEXT('XL-Test'!I50)),0) -> 28 | I45: =IFERROR(LEN(_xlfn.FORMULATEXT('XL-Test'!J50)),0) -> 18 | J45: =IFERROR(LEN(_xlfn.FORMULATEXT('XL-Test'!K50)),0) -> 9 | ... L45: =IFERROR(LEN(_xlfn.FORMULATEXT('XL-Test'!M50)),0) -> 46
A46: 10 | B46: 4 | C46: =IFERROR(LEN(_xlfn.FORMULATEXT('XL-Test'!D51)),0) -> 100 | D46: =IFERROR(LEN(_xlfn.FORMULATEXT('XL-Test'!E51)),0) -> 19 | E46: =IFERROR(LEN(_xlfn.FORMULATEXT('XL-Test'!F51)),0) -> 20 | F46: =IFERROR(LEN(_xlfn.FORMULATEXT('XL-Test'!G51)),0) -> 19 | G46: =IFERROR(LEN(_xlfn.FORMULATEXT('XL-Test'!H51)),0) -> 18 | H46: =IFERROR(LEN(_xlfn.FORMULATEXT('XL-Test'!I51)),0) -> 28 | I46: =IFERROR(LEN(_xlfn.FORMULATEXT('XL-Test'!J51)),0) -> 18 | J46: =IFERROR(LEN(_xlfn.FORMULATEXT('XL-Test'!K51)),0) -> 9 | ... L46: =IFERROR(LEN(_xlfn.FORMULATEXT('XL-Test'!M51)),0) -> 46
A47: 11 | B47: 5 | C47: =IFERROR(LEN(_xlfn.FORMULATEXT('XL-Test'!D52)),0) -> 100 | D47: =IFERROR(LEN(_xlfn.FORMULATEXT('XL-Test'!E52)),0) -> 19 | E47: =IFERROR(LEN(_xlfn.FORMULATEXT('XL-Test'!F52)),0) -> 20 | F47: =IFERROR(LEN(_xlfn.FORMULATEXT('XL-Test'!G52)),0) -> 19 | G47: =IFERROR(LEN(_xlfn.FORMULATEXT('XL-Test'!H52)),0) -> 18 | H47: =IFERROR(LEN(_xlfn.FORMULATEXT('XL-Test'!I52)),0) -> 28 | I47: =IFERROR(LEN(_xlfn.FORMULATEXT('XL-Test'!J52)),0) -> 18 | J47: =IFERROR(LEN(_xlfn.FORMULATEXT('XL-Test'!K52)),0) -> 9 | ... L47: =IFERROR(LEN(_xlfn.FORMULATEXT('XL-Test'!M52)),0) -> 46
A48: 12 | B48: 6 | C48: =IFERROR(LEN(_xlfn.FORMULATEXT('XL-Test'!D53)),0) -> 100 | D48: =IFERROR(LEN(_xlfn.FORMULATEXT('XL-Test'!E53)),0) -> 19 | E48: =IFERROR(LEN(_xlfn.FORMULATEXT('XL-Test'!F53)),0) -> 20 | F48: =IFERROR(LEN(_xlfn.FORMULATEXT('XL-Test'!G53)),0) -> 19 | G48: =IFERROR(LEN(_xlfn.FORMULATEXT('XL-Test'!H53)),0) -> 18 | H48: =IFERROR(LEN(_xlfn.FORMULATEXT('XL-Test'!I53)),0) -> 28 | I48: =IFERROR(LEN(_xlfn.FORMULATEXT('XL-Test'!J53)),0) -> 18 | J48: =IFERROR(LEN(_xlfn.FORMULATEXT('XL-Test'!K53)),0) -> 9 | ... L48: =IFERROR(LEN(_xlfn.FORMULATEXT('XL-Test'!M53)),0) -> 46
A49: 13 | B49: 7 | C49: =IFERROR(LEN(_xlfn.FORMULATEXT('XL-Test'!D54)),0) -> 100 | D49: =IFERROR(LEN(_xlfn.FORMULATEXT('XL-Test'!E54)),0) -> 19 | E49: =IFERROR(LEN(_xlfn.FORMULATEXT('XL-Test'!F54)),0) -> 20 | F49: =IFERROR(LEN(_xlfn.FORMULATEXT('XL-Test'!G54)),0) -> 19 | G49: =IFERROR(LEN(_xlfn.FORMULATEXT('XL-Test'!H54)),0) -> 18 | H49: =IFERROR(LEN(_xlfn.FORMULATEXT('XL-Test'!I54)),0) -> 28 | I49: =IFERROR(LEN(_xlfn.FORMULATEXT('XL-Test'!J54)),0) -> 18 | J49: =IFERROR(LEN(_xlfn.FORMULATEXT('XL-Test'!K54)),0) -> 9 | ... L49: =IFERROR(LEN(_xlfn.FORMULATEXT('XL-Test'!M54)),0) -> 46
A50: 14 | B50: 8 | C50: =IFERROR(LEN(_xlfn.FORMULATEXT('XL-Test'!D55)),0) -> 100 | D50: =IFERROR(LEN(_xlfn.FORMULATEXT('XL-Test'!E55)),0) -> 19 | E50: =IFERROR(LEN(_xlfn.FORMULATEXT('XL-Test'!F55)),0) -> 20 | F50: =IFERROR(LEN(_xlfn.FORMULATEXT('XL-Test'!G55)),0) -> 19 | G50: =IFERROR(LEN(_xlfn.FORMULATEXT('XL-Test'!H55)),0) -> 18 | H50: =IFERROR(LEN(_xlfn.FORMULATEXT('XL-Test'!I55)),0) -> 28 | I50: =IFERROR(LEN(_xlfn.FORMULATEXT('XL-Test'!J55)),0) -> 18 | J50: =IFERROR(LEN(_xlfn.FORMULATEXT('XL-Test'!K55)),0) -> 9 | ... L50: =IFERROR(LEN(_xlfn.FORMULATEXT('XL-Test'!M55)),0) -> 46
...
