Workbook
Name kode_jawaban: DF!$N$31
Name sayad: DF!$M$35

Sheet XL-Test
A18: KODE SOAL | C18: SBEE007 | E18: KODE JAWABAN | G18: =kode_jawaban -> EG3|131-9841;171-1F6061;161-BD9251;ED1-E688681;CD1-6B11;1D1-3BA4A0C1;1A-4E95F121
A20: Intruksi
B22: Easy Level - Latihan Soal Admin Penjualan
B24: Soal : | C24: Gunakan Fungsi Excel (Function) untuk menyelsaikan kasus dibawah ini, tidak disarankan menggunakan cara manual
B25: 1 | C25: Nama Barang-Merk diisi Dari data Table Bantu Barang dan Merk. * Nama Barang : Diambil 2 karakter pertama dari kode, Merek : Diambil 2 karakter terakhir dari Kode,
B26: 2 | C26: Harga Pokok : Diambil 2 karakter dari karakter ke-4, * Dikalikan dengan Harga Rate, berdasarkan Table Rate mata uang dari 3 hurup setelahnya
B27: 3 | C27: Harga Jual : (Harga Pokok ditambah 25%) dikali dengan Terjual
B28: 4 | C28: Discount : Jika | F28: 5 | G28: Bonus : Jika
C29: Total Harga Jual >=10,000,000, maka 25% dari Total Harga Jual | G29: Total Harga Jual>=5,000,000 dan Discount>=2,000,000, maka "PowerBank"
C30: Total Harga Jual >=8,000,000, maka 20% dari Total Harga Jual | G30: Total Harga Jual>=2,000,000 dan Discount>=500,000, maka "TWS"
C31: Total Harga Jual >=5,000,000, maka 15% dari Total Harga Jual | G31: Total Harga Jual<2,000,000 dan Discount<500,000, Maka "Voucher"
C32: Total Harga Jual >=3,000,000, maka 10% dari Total Harga Jual | G32: Selain kriteria diatas, maka ""
C33: Total Harga Jual >=2,000,000, maka 5% dari Total Harga Jual
C34: Total Harga Jual <2,000,000, maka 0% dari Total Harga Jual
B35: 6 | C35: Total adalah Total Harga Jual dikurangi Discount
B36: 7 | C36: Isi Total Seluruh, Nilai Terbesar , Terendah, Rata-rata dan Jumlah Data (tidak termasuk contoh)
C38: Sudah selesai mengerjakan? kirim Kode Soal dan Kode Jawaban diatas ke alamat : https://belajarexcel.id/xl-test/jawaban untuk mengecek hasilnya
C39: atau klik tombol disamping
B45: Laporan Keuntungan Mingguan
B46: TOKO ILMU BELAJAREXCEL.ID
B47: Tasikmalaya
E49: 1 | F49: 2 | G49: 3 | H49: 4 | I49: 5 | J49: 6
B50: NO | C50: KODE | D50: TERJUAL | E50: NAMA BARANG-MERK | F50: HARGA POKOK | G50: TOTAL HARGA JUAL | H50: DISCOUNT | I50: BONUS | J50: TOTAL
B51: Contoh | C51: AC-96-AUD-M1 | D51: 7 | E51: AC-Samsung | F51: 1152000 | G51: 10080000 | H51: 2520000 | I51: PowerBank | J51: 7560000
B53: 1 | C53: TV-99-EUR-M2 | D53: 7 | E53: =VLOOKUP(LEFT(C53,FIND("-",C53)-1),$B$65:$C$73,2,0)&"-"&HLOOKUP(RIGHT(C53,2),$C$75:$I$76,2,0) -> Televisi-LG | F53: =MID(C53,4,2)*VLOOKUP(MID(C53,7,3),$E$66:$G$70,3,FALSE) -> 1980000 | G53: =(F53+(F53*25%))*D53 -> 17325000 | H53: {=IF(G53>=10000000,25%,_xlfn.SWITCH(TRUE,G53>=8000000,20%,G53>=5000000,15%,G53>=3000000,10%,G53>=2000000,5%,0))*G53} -> 4331250 | I53: =IF(AND(G53>=5000000, H53>=2000000), "PowerBank", IF(AND(G53>=2000000, H53>=500000), "TWS", IF(AND(G53<2000000, H53<500000), "Voucher", ""))) -> PowerBank | J53: =G53-H53 -> 12993750
B54: 2 | C54: HP-90-CAD-M1 | D54: 6 | E54: =VLOOKUP(LEFT(C54,FIND("-",C54)-1),$B$65:$C$73,2,0)&"-"&HLOOKUP(RIGHT(C54,2),$C$75:$I$76,2,0) -> Handphone-Samsung | F54: =MID(C54,4,2)*VLOOKUP(MID(C54,7,3),$E$66:$G$70,3,FALSE) -> 1125000 | G54: =(F54+(F54*25%))*D54 -> 8437500 | H54: {=IF(G54>=10000000,25%,_xlfn.SWITCH(TRUE,G54>=8000000,20%,G54>=5000000,15%,G54>=3000000,10%,G54>=2000000,5%,0))*G54} -> 1687500 | I54: =IF(AND(G54>=5000000, H54>=2000000), "PowerBank", IF(AND(G54>=2000000, H54>=500000), "TWS", IF(AND(G54<2000000, H54<500000), "Voucher", ""))) -> TWS | J54: =G54-H54 -> 6750000
B55: 3 | C55: TV-88-USD-M4 | D55: 4 | E55: =VLOOKUP(LEFT(C55,FIND("-",C55)-1),$B$65:$C$73,2,0)&"-"&HLOOKUP(RIGHT(C55,2),$C$75:$I$76,2,0) -> Televisi-Panasonic | F55: =MID(C55,4,2)*VLOOKUP(MID(C55,7,3),$E$66:$G$70,3,FALSE) -> 1478400 | G55: =(F55+(F55*25%))*D55 -> 7392000 | H55: {=IF(G55>=10000000,25%,_xlfn.SWITCH(TRUE,G55>=8000000,20%,G55>=5000000,15%,G55>=3000000,10%,G55>=2000000,5%,0))*G55} -> 1108800 | I55: =IF(AND(G55>=5000000, H55>=2000000), "PowerBank", IF(AND(G55>=2000000, H55>=500000), "TWS", IF(AND(G55<2000000, H55<500000), "Voucher", ""))) -> TWS | J55: =G55-H55 -> 6283200
B56: 4 | C56: AC-73-EUR-M4 | D56: 5 | E56: =VLOOKUP(LEFT(C56,FIND("-",C56)-1),$B$65:$C$73,2,0)&"-"&HLOOKUP(RIGHT(C56,2),$C$75:$I$76,2,0) -> AC-Panasonic | F56: =MID(C56,4,2)*VLOOKUP(MID(C56,7,3),$E$66:$G$70,3,FALSE) -> 1460000 | G56: =(F56+(F56*25%))*D56 -> 9125000 | H56: {=IF(G56>=10000000,25%,_xlfn.SWITCH(TRUE,G56>=8000000,20%,G56>=5000000,15%,G56>=3000000,10%,G56>=2000000,5%,0))*G56} -> 1825000 | I56: =IF(AND(G56>=5000000, H56>=2000000), "PowerBank", IF(AND(G56>=2000000, H56>=500000), "TWS", IF(AND(G56<2000000, H56<500000), "Voucher", ""))) -> TWS | J56: =G56-H56 -> 7300000
B57: 5 | C57: KL-73-USD-M5 | D57: 3 | E57: =VLOOKUP(LEFT(C57,FIND("-",C57)-1),$B$65:$C$73,2,0)&"-"&HLOOKUP(RIGHT(C57,2),$C$75:$I$76,2,0) -> Kulkas-Philips | F57: =MID(C57,4,2)*VLOOKUP(MID(C57,7,3),$E$66:$G$70,3,FALSE) -> 1226400 | G57: =(F57+(F57*25%))*D57 -> 4599000 | H57: {=IF(G57>=10000000,25%,_xlfn.SWITCH(TRUE,G57>=8000000,20%,G57>=5000000,15%,G57>=3000000,10%,G57>=2000000,5%,0))*G57} -> 459900 | I57: =IF(AND(G57>=5000000, H57>=2000000), "PowerBank", IF(AND(G57>=2000000, H57>=500000), "TWS", IF(AND(G57<2000000, H57<500000), "Voucher", ""))) | J57: =G57-H57 -> 4139100
B58: 6 | C58: LP-85-SGD-M3 | D58: 2 | E58: =VLOOKUP(LEFT(C58,FIND("-",C58)-1),$B$65:$C$73,2,0)&"-"&HLOOKUP(RIGHT(C58,2),$C$75:$I$76,2,0) -> Laptop-Sony | F58: =MID(C58,4,2)*VLOOKUP(MID(C58,7,3),$E$66:$G$70,3,FALSE) -> 1190000 | G58: =(F58+(F58*25%))*D58 -> 2975000 | H58: {=IF(G58>=10000000,25%,_xlfn.SWITCH(TRUE,G58>=8000000,20%,G58>=5000000,15%,G58>=3000000,10%,G58>=2000000,5%,0))*G58} -> 148750 | I58: =IF(AND(G58>=5000000, H58>=2000000), "PowerBank", IF(AND(G58>=2000000, H58>=500000), "TWS", IF(AND(G58<2000000, H58<500000), "Voucher", ""))) | J58: =G58-H58 -> 2826250
B59: 7 | C59: KL-93-AUD-M6 | D59: 4 | E59: =VLOOKUP(LEFT(C59,FIND("-",C59)-1),$B$65:$C$73,2,0)&"-"&HLOOKUP(RIGHT(C59,2),$C$75:$I$76,2,0) -> Kulkas-Sharp | F59: =MID(C59,4,2)*VLOOKUP(MID(C59,7,3),$E$66:$G$70,3,FALSE) -> 1116000 | G59: =(F59+(F59*25%))*D59 -> 5580000 | H59: {=IF(G59>=10000000,25%,_xlfn.SWITCH(TRUE,G59>=8000000,20%,G59>=5000000,15%,G59>=3000000,10%,G59>=2000000,5%,0))*G59} -> 837000 | I59: =IF(AND(G59>=5000000, H59>=2000000), "PowerBank", IF(AND(G59>=2000000, H59>=500000), "TWS", IF(AND(G59<2000000, H59<500000), "Voucher", ""))) -> TWS | J59: =G59-H59 -> 4743000
B60: 8 | C60: KP-41-AUD-M5 | D60: 1 | E60: =VLOOKUP(LEFT(C60,FIND("-",C60)-1),$B$65:$C$73,2,0)&"-"&HLOOKUP(RIGHT(C60,2),$C$75:$I$76,2,0) -> Kipas-Philips | F60: =MID(C60,4,2)*VLOOKUP(MID(C60,7,3),$E$66:$G$70,3,FALSE) -> 492000 | G60: =(F60+(F60*25%))*D60 -> 615000 | H60: {=IF(G60>=10000000,25%,_xlfn.SWITCH(TRUE,G60>=8000000,20%,G60>=5000000,15%,G60>=3000000,10%,G60>=2000000,5%,0))*G60} -> 0 | I60: =IF(AND(G60>=5000000, H60>=2000000), "PowerBank", IF(AND(G60>=2000000, H60>=500000), "TWS", IF(AND(G60<2000000, H60<500000), "Voucher", ""))) -> Voucher | J60: =G60-H60 -> 615000
B61: 9 | C61: MC-84-EUR-M5 | D61: 7 | E61: =VLOOKUP(LEFT(C61,FIND("-",C61)-1),$B$65:$C$73,2,0)&"-"&HLOOKUP(RIGHT(C61,2),$C$75:$I$76,2,0) -> Mesin Cuci-Philips | F61: =MID(C61,4,2)*VLOOKUP(MID(C61,7,3),$E$66:$G$70,3,FALSE) -> 1680000 | G61: =(F61+(F61*25%))*D61 -> 14700000 | H61: {=IF(G61>=10000000,25%,_xlfn.SWITCH(TRUE,G61>=8000000,20%,G61>=5000000,15%,G61>=3000000,10%,G61>=2000000,5%,0))*G61} -> 3675000 | I61: =IF(AND(G61>=5000000, H61>=2000000), "PowerBank", IF(AND(G61>=2000000, H61>=500000), "TWS", IF(AND(G61<2000000, H61<500000), "Voucher", ""))) -> PowerBank | J61: =G61-H61 -> 11025000
B62: 10 | C62: TB-92-AUD-M1 | D62: 5 | E62: =VLOOKUP(LEFT(C62,FIND("-",C62)-1),$B$65:$C$73,2,0)&"-"&HLOOKUP(RIGHT(C62,2),$C$75:$I$76,2,0) -> Tablet-Samsung | F62: =MID(C62,4,2)*VLOOKUP(MID(C62,7,3),$E$66:$G$70,3,FALSE) -> 1104000 | G62: =(F62+(F62*25%))*D62 -> 6900000 | H62: {=IF(G62>=10000000,25%,_xlfn.SWITCH(TRUE,G62>=8000000,20%,G62>=5000000,15%,G62>=3000000,10%,G62>=2000000,5%,0))*G62} -> 1035000 | I62: =IF(AND(G62>=5000000, H62>=2000000), "PowerBank", IF(AND(G62>=2000000, H62>=500000), "TWS", IF(AND(G62<2000000, H62<500000), "Voucher", ""))) -> TWS | J62: =G62-H62 -> 5865000
I63: Total seluruh nilai | J63: =SUM(J53:J62) -> 62540300 | K63: 7
B64: Kode Barang | C64: Nama Barang | I64: Nilai terbesar | J64: =MAX(J53:J62) -> 12993750 | K64: 7
B65: TV | C65: Televisi | E65: 💵 Rate Mata Uang | I65: Nilai terrendah | J65: =MIN(J53:J62) -> 615000 | K65: 7
B66: KP | C66: Kipas | E66: USD | F66: US Dollar | G66: 16800 | I66: Nilai rata-rata | J66: =AVERAGE(J53:J62) -> 6254030 | K66: 7
B67: KL | C67: Kulkas | E67: AUD | F67: Australian Dollar | G67: 12000 | I67: Jumlah Data Barang | J67: =COUNTA(E53:E62) -> 10 | K67: 7
B68: MC | C68: Mesin Cuci | E68: CAD | F68: Canadian Dollar | G68: 12500
...

Sheet About
I6: XL-TEST adalah platform inovatif yang menyediakan latihan Excel interaktif dengan pemeriksaan otomatis,
I7: sehingga pengguna dapat langsung mengetahui jawaban yang benar maupun salah.
I10: Terdapat 5 Level soal :
J12: Easy Level | L12: (⭐)
J13: Medium Level | L13: (⭐⭐)
J14: Hard Level | L14: (⭐⭐⭐)
J15: Extreme Level | L15: (⭐⭐⭐⭐)
J16: Championship Level | L16: (⭐⭐⭐⭐⭐)
B17: Saya adalah seorang Excel Holic yang percaya bahwa setiap angka memiliki cerita yang bisa ditemukan dengan cara yang tepat. | I17: Free Access
B18: “Excel bukan cuma soal kerjaan tapi juga hobi yang aku nikmati.” | I18: https://belajarexcel.id/xl-test/
B19: Contact :
B20: 🌐 Web | C20: https://setiadi.me
B21: 🪡threads | C21: https://www.threads.com/@andisetiadi
D27: Perlu Video Penjelasan atau Kunci Jawaban ?
D28: Scan barcode atau kunjungi
D29: https://lynk.id/setiadi/page/jawaban-xl-test

Sheet DF
A1: DEF | D1: 1 | E1: 2 | F1: 3 | G1: 4 | H1: 5 | I1: 6 | J1: 7 | T1: 1 | U1: 2 | V1: 3 | W1: 4 | X1: 5 | Y1: 6
A2: EG3 | C2: 1 | D2: ='XL-Test'!E53 -> Televisi-LG | E2: ='XL-Test'!F53 -> 1980000 | F2: ='XL-Test'!G53 -> 17325000 | G2: ='XL-Test'!H53 -> 4331250 | H2: ='XL-Test'!I53 -> PowerBank | I2: ='XL-Test'!J53 -> 12993750 | J2: ='XL-Test'!J63 -> 62540300 | S2: 1 | T2: =_xlfn.FORMULATEXT('XL-Test'!E53) -> =VLOOKUP(LEFT(C53;FIND("-";C53)-1);$B$65:$C$73;2;0)&"-"&HLOOKUP(RIGHT(C53;2);$C$75:$I$76;2;0) | U2: =_xlfn.FORMULATEXT('XL-Test'!F53) -> =MID(C53;4;2)*VLOOKUP(MID(C53;7;3);$E$66:$G$70;3;FALSE) | V2: =_xlfn.FORMULATEXT('XL-Test'!G53) -> =(F53+(F53*25%))*D53 | W2: =_xlfn.FORMULATEXT('XL-Test'!H53) -> =IF(G53>=10000000;25%;SWITCH(TRUE;G53>=8000000;20%;G53>=5000000;15%;G53>=3000000;10%;G53>=2000000;5%;0))*G53 | X2: =_xlfn.FORMULATEXT('XL-Test'!I53) -> =IF(AND(G53>=5000000; H53>=2000000); "PowerBank"; IF(AND(G53>=2000000; H53>=500000); "TWS"; IF(AND(G53<2000000; H53<500000); "Voucher"; ""))) | Y2: =_xlfn.FORMULATEXT('XL-Test'!J53) -> =G53-H53
C3: 2 | D3: ='XL-Test'!E54 -> Handphone-Samsung | E3: ='XL-Test'!F54 -> 1125000 | F3: ='XL-Test'!G54 -> 8437500 | G3: ='XL-Test'!H54 -> 1687500 | H3: ='XL-Test'!I54 -> TWS | I3: ='XL-Test'!J54 -> 6750000 | J3: ='XL-Test'!J64 -> 12993750 | S3: 2 | T3: =_xlfn.FORMULATEXT('XL-Test'!F53) -> =MID(C53;4;2)*VLOOKUP(MID(C53;7;3);$E$66:$G$70;3;FALSE)
C4: 3 | D4: ='XL-Test'!E55 -> Televisi-Panasonic | E4: ='XL-Test'!F55 -> 1478400 | F4: ='XL-Test'!G55 -> 7392000 | G4: ='XL-Test'!H55 -> 1108800 | H4: ='XL-Test'!I55 -> TWS | I4: ='XL-Test'!J55 -> 6283200 | J4: ='XL-Test'!J65 -> 615000 | S4: 3 | T4: =_xlfn.FORMULATEXT('XL-Test'!G53) -> =(F53+(F53*25%))*D53
C5: 4 | D5: ='XL-Test'!E56 -> AC-Panasonic | E5: ='XL-Test'!F56 -> 1460000 | F5: ='XL-Test'!G56 -> 9125000 | G5: ='XL-Test'!H56 -> 1825000 | H5: ='XL-Test'!I56 -> TWS | I5: ='XL-Test'!J56 -> 7300000 | J5: ='XL-Test'!J66 -> 6254030 | S5: 4 | T5: =_xlfn.FORMULATEXT('XL-Test'!H53) -> =IF(G53>=10000000;25%;SWITCH(TRUE;G53>=8000000;20%;G53>=5000000;15%;G53>=3000000;10%;G53>=2000000;5%;0))*G53
C6: 5 | D6: ='XL-Test'!E57 -> Kulkas-Philips | E6: ='XL-Test'!F57 -> 1226400 | F6: ='XL-Test'!G57 -> 4599000 | G6: ='XL-Test'!H57 -> 459900 | H6: ='XL-Test'!I57 | I6: ='XL-Test'!J57 -> 4139100 | J6: ='XL-Test'!J67 -> 10 | S6: 5 | T6: =_xlfn.FORMULATEXT('XL-Test'!I53) -> =IF(AND(G53>=5000000; H53>=2000000); "PowerBank"; IF(AND(G53>=2000000; H53>=500000); "TWS"; IF(AND(G53<2000000; H53<500000); "Voucher"; "")))
C7: 6 | D7: ='XL-Test'!E58 -> Laptop-Sony | E7: ='XL-Test'!F58 -> 1190000 | F7: ='XL-Test'!G58 -> 2975000 | G7: ='XL-Test'!H58 -> 148750 | H7: ='XL-Test'!I58 | I7: ='XL-Test'!J58 -> 2826250 | S7: 6 | T7: =_xlfn.FORMULATEXT('XL-Test'!J53) -> =G53-H53
C8: 7 | D8: ='XL-Test'!E59 -> Kulkas-Sharp | E8: ='XL-Test'!F59 -> 1116000 | F8: ='XL-Test'!G59 -> 5580000 | G8: ='XL-Test'!H59 -> 837000 | H8: ='XL-Test'!I59 -> TWS | I8: ='XL-Test'!J59 -> 4743000 | P8: =AND(ISNUMBER(FIND("=",T8)),ISNUMBER(FIND("(",T8))) -> TRUE | Q8: =ISNUMBER(FIND("SUM",T8)) -> TRUE | S8: 71 | T8: =_xlfn.FORMULATEXT('XL-Test'!J63) -> =SUM(J53:J62)
C9: 8 | D9: ='XL-Test'!E60 -> Kipas-Philips | E9: ='XL-Test'!F60 -> 492000 | F9: ='XL-Test'!G60 -> 615000 | G9: ='XL-Test'!H60 -> 0 | H9: ='XL-Test'!I60 -> Voucher | I9: ='XL-Test'!J60 -> 615000 | P9: =AND(ISNUMBER(FIND("=",T9)),ISNUMBER(FIND("(",T9))) -> TRUE | Q9: =ISNUMBER(FIND("MAX",T9)) -> TRUE | S9: 71 | T9: =_xlfn.FORMULATEXT('XL-Test'!J64) -> =MAX(J53:J62)
C10: 9 | D10: ='XL-Test'!E61 -> Mesin Cuci-Philips | E10: ='XL-Test'!F61 -> 1680000 | F10: ='XL-Test'!G61 -> 14700000 | G10: ='XL-Test'!H61 -> 3675000 | H10: ='XL-Test'!I61 -> PowerBank | I10: ='XL-Test'!J61 -> 11025000 | P10: =AND(ISNUMBER(FIND("=",T10)),ISNUMBER(FIND("(",T10))) -> TRUE | Q10: =ISNUMBER(FIND("MIN",T10)) -> TRUE | S10: 71 | T10: =_xlfn.FORMULATEXT('XL-Test'!J65) -> =MIN(J53:J62)
C11: 10 | D11: ='XL-Test'!E62 -> Tablet-Samsung | E11: ='XL-Test'!F62 -> 1104000 | F11: ='XL-Test'!G62 -> 6900000 | G11: ='XL-Test'!H62 -> 1035000 | H11: ='XL-Test'!I62 -> TWS | I11: ='XL-Test'!J62 -> 5865000 | P11: =AND(ISNUMBER(FIND("=",T11)),ISNUMBER(FIND("(",T11))) -> TRUE | Q11: =ISNUMBER(FIND("AVE",T11)) -> TRUE | S11: 71 | T11: =_xlfn.FORMULATEXT('XL-Test'!J66) -> =AVERAGE(J53:J62)
P12: =AND(ISNUMBER(FIND("=",T12)),ISNUMBER(FIND("(",T12))) -> TRUE | Q12: =ISNUMBER(FIND("COU",T12)) -> TRUE | S12: 71 | T12: =_xlfn.FORMULATEXT('XL-Test'!J67) -> =COUNTA(E53:E62)
C13: Value | D13: =CODE(LEFT(D2))+CODE(RIGHT(D2))+CODE(LEFT(D3))+CODE(RIGHT(D3))+CODE(LEFT(D4))+CODE(RIGHT(D4))+CODE(LEFT(D5))+CODE(RIGHT(D5))+CODE(LEFT(D6))+CODE(RIGHT(D6))+CODE(LEFT(D6))+CODE(RIGHT(D6))+CODE(LEFT(D7))+CODE(RIGHT(D7))+CODE(LEFT(D8))+CODE(RIGHT(D8))+CODE(LEFT(D9))+CODE(RIGHT(D9))+CODE(LEFT(D10))+CODE(RIGHT(D10))+CODE(LEFT(D11))+CODE(RIGHT(D11))+CODE(MID(D2,3,1))+CODE(MID(D3,14,1))+CODE(MID(D11,3,1))+CODE(LEFT(RIGHT(D9,3))) -> 2436 | E13: =SUM(E2:E11)/100 -> 128518 | F13: =SUM(F2:F11)/100 -> 776485 | G13: =SUM(G2:G11) -> 15108200 | H13: =CODE(LEFT(H2))+CODE(RIGHT(H2))+CODE(LEFT(H3))+CODE(RIGHT(H3))+CODE(LEFT(H4))+CODE(RIGHT(H4))+CODE(LEFT(H5))+CODE(RIGHT(H5))+IF(H6="",1,0)+IF(H7="",1,0)+CODE(LEFT(H9))+CODE(RIGHT(H9))+CODE(LEFT(H10))+CODE(RIGHT(H10))+CODE(LEFT(H11))+CODE(RIGHT(H11))+CODE(MID(H2,2,1))+CODE(MID(H3,2,1))+CODE(MID(H11,3,1))+CODE(LEFT(RIGHT(H9,3)))+CODE(LEFT(H8)) -> 1713 | I13: =SUM(I2:I11) -> 62540300 | J13: =SUM(J2:J11) -> 82403090
C14: VF | D14: =IFERROR(DEC2HEX(IF(OR(D2="",D2=0),D15,D13))&D20,"FFFF") -> 9841 | E14: =IFERROR(DEC2HEX(IF(OR(E2="",E2=0),E15,E13))&E20,"FFFF") -> 1F6061 | F14: =IFERROR(DEC2HEX(IF(OR(F2="",F2=0),F15,F13))&F20,"FFFF") -> BD9251 | G14: =IFERROR(DEC2HEX(IF(OR(G2="",G2=0),G15,G13))&G20,"FFFF") -> E688681 | H14: =IFERROR(DEC2HEX(IF(OR(H2="",H2=0),H15,H13))&H20,"FFFF") -> 6B11 | I14: =IFERROR(DEC2HEX(IF(OR(I2="",I2=0),I15,I13))&I20,"FFFF") -> 3BA4A0C1 | J14: =IFERROR(DEC2HEX(IF(OR(J2="",J2=0),J15,J13))&J20,"FFFF") -> 4E95F121
C15: Random | D15: 4939 | E15: 5969 | F15: 5674 | G15: 3794 | H15: 3289 | I15: 7644 | J15: 6815
C17: TRUE | D17: =LEFT(DEC2HEX(D15),2) -> 13 | E17: =LEFT(DEC2HEX(E15),2) -> 17 | F17: =LEFT(DEC2HEX(F15),2) -> 16 | G17: =LEFT(DEC2HEX(G15),2) -> ED | H17: =LEFT(DEC2HEX(H15),2) -> CD | I17: =LEFT(DEC2HEX(I15),2) -> 1D | J17: =LEFT(DEC2HEX(J15),2) -> 1A
C18: FALSE | D18: =RIGHT(DEC2HEX(D15),2) -> 4B | E18: =RIGHT(DEC2HEX(E15),2) -> 51 | F18: =RIGHT(DEC2HEX(F15),2) -> 2A | G18: =RIGHT(DEC2HEX(G15),2) -> D2 | H18: =RIGHT(DEC2HEX(H15),2) -> D9 | I18: =RIGHT(DEC2HEX(I15),2) -> DC | J18: =RIGHT(DEC2HEX(J15),2) -> 9F
C20: Cek Input | D20: =AND(ISNUMBER(FIND("=",T2)),ISNUMBER(FIND("(",T2)))+0 -> 1 | E20: =AND(ISNUMBER(FIND("=",U2)),ISNUMBER(FIND("(",U2)))+0 -> 1 | F20: =AND(ISNUMBER(FIND("=",V2)),ISNUMBER(FIND("*",V2)))+0 -> 1 | G20: =AND(ISNUMBER(FIND("=",W2)),ISNUMBER(FIND("(",W2)))+0 -> 1 | H20: =AND(ISNUMBER(FIND("=",X2)),ISNUMBER(FIND("(",X2)))+0 -> 1 | I20: =AND(ISNUMBER(FIND("=",Y2)),ISNUMBER(FIND("-",Y2)))+0 -> 1 | J20: =AND(P8,P9,P10,P11,P12)+0 -> 1
C22: Cek rumus | D22: =AND(ISNUMBER(FIND("VLO",T2)),ISNUMBER(FIND("HLO",T2))) -> TRUE | E22: =AND(ISNUMBER(FIND("MID",U2)),ISNUMBER(FIND("LOOK",U2))) -> TRUE | F22: =AND(ISNUMBER(FIND("*",V2)),ISNUMBER(FIND("25",V2))) -> TRUE | G22: =OR(ISNUMBER(FIND("IF",W2)),ISNUMBER(FIND("SW",W2))) -> TRUE | H22: =OR(ISNUMBER(FIND("IF",X2)),ISNUMBER(FIND("SW",X2))) -> TRUE | I22: =ISNUMBER(FIND("-",Y2)) -> TRUE | J22: =AND(Q8,Q9,Q10,Q11,Q12) -> TRUE
C24: Cek Kurung | D24: =IFERROR(LEN(T2)-LEN(SUBSTITUTE(T2,"(","")),99) -> 5 | E24: =IFERROR(LEN(U2)-LEN(SUBSTITUTE(U2,"(","")),99) -> 3 | F24: =IFERROR(LEN(V2)-LEN(SUBSTITUTE(V2,"(","")),99) -> 2 | G24: =IFERROR(LEN(W2)-LEN(SUBSTITUTE(W2,"(","")),99) -> 2 | H24: =IFERROR(LEN(X2)-LEN(SUBSTITUTE(X2,"(","")),99) -> 6 | I24: =IFERROR(LEN(Y2)-LEN(SUBSTITUTE(Y2,"(","")),99) -> 0
C25: Nilai | D25: 5 | E25: 3 | F25: 2 | G25: 5 | H25: 6 | I25: 1
C27: Hasil | D27: =AND(D24<=D25,D51)+0 -> 1 | E27: =AND(E24<=E25,E51)+0 -> 1 | F27: =AND(F24<=F25,F51)+0 -> 1 | G27: =AND(G24<=G25,G51)+0 -> 1 | H27: =AND(H24<=H25,H51)+0 -> 1 | I27: =AND(I24<=I25,I51)+0 -> 1 | N27: sa | O27: ya
C29: RF | D29: =IF(D22,D17,D18)&D27 -> 131 | E29: =IF(E22,E17,E18)&E27 -> 171 | F29: =IF(F22,F17,F18)&F27 -> 161 | G29: =IF(G22,G17,G18)&G27 -> ED1 | H29: =IF(H22,H17,H18)&H27 -> CD1 | I29: =IF(I22,I17,I18)&I27 -> 1D1 | J29: =IF(J22,J17,J18)&J27 -> 1A
C30: Gabung | D30: =D29&"-"&D14&";" -> 131-9841; | E30: =E29&"-"&E14&";" -> 171-1F6061; | F30: =F29&"-"&F14&";" -> 161-BD9251; | G30: =G29&"-"&G14&";" -> ED1-E688681; | H30: =H29&"-"&H14&";" -> CD1-6B11; | I30: =I29&"-"&I14&";" -> 1D1-3BA4A0C1; | J30: =J29&"-"&J14 -> 1A-4E95F121
N31: {=INDIRECT(N27&O27&"d")} -> EG3|131-9841;171-1F6061;161-BD9251;ED1-E688681;CD1-6B11;1D1-3BA4A0C1;1A-4E95F121
D32: =A2&"|"&D30&E30&F30&G30&H30&I30&J30 -> EG3|131-9841;171-1F6061;161-BD9251;ED1-E688681;CD1-6B11;1D1-3BA4A0C1;1A-4E95F121
C35: 1 | D35: =LEN(_xlfn.FORMULATEXT('XL-Test'!E53)) -> 93 | E35: =LEN(_xlfn.FORMULATEXT('XL-Test'!F53)) -> 55 | F35: =LEN(_xlfn.FORMULATEXT('XL-Test'!G53)) -> 20 | G35: =LEN(_xlfn.FORMULATEXT('XL-Test'!H53)) -> 108 | H35: =LEN(_xlfn.FORMULATEXT('XL-Test'!I53)) -> 141 | I35: =LEN(_xlfn.FORMULATEXT('XL-Test'!J53)) -> 8 | M35: =D32 -> EG3|131-9841;171-1F6061;161-BD9251;ED1-E688681;CD1-6B11;1D1-3BA4A0C1;1A-4E95F121
C36: 2 | D36: =LEN(_xlfn.FORMULATEXT('XL-Test'!E54)) -> 93 | E36: =LEN(_xlfn.FORMULATEXT('XL-Test'!F54)) -> 55 | F36: =LEN(_xlfn.FORMULATEXT('XL-Test'!G54)) -> 20 | G36: =LEN(_xlfn.FORMULATEXT('XL-Test'!H54)) -> 108 | H36: =LEN(_xlfn.FORMULATEXT('XL-Test'!I54)) -> 141 | I36: =LEN(_xlfn.FORMULATEXT('XL-Test'!J54)) -> 8
C37: 3 | D37: =LEN(_xlfn.FORMULATEXT('XL-Test'!E55)) -> 93 | E37: =LEN(_xlfn.FORMULATEXT('XL-Test'!F55)) -> 55 | F37: =LEN(_xlfn.FORMULATEXT('XL-Test'!G55)) -> 20 | G37: =LEN(_xlfn.FORMULATEXT('XL-Test'!H55)) -> 108 | H37: =LEN(_xlfn.FORMULATEXT('XL-Test'!I55)) -> 141 | I37: =LEN(_xlfn.FORMULATEXT('XL-Test'!J55)) -> 8
C38: 4 | D38: =LEN(_xlfn.FORMULATEXT('XL-Test'!E56)) -> 93 | E38: =LEN(_xlfn.FORMULATEXT('XL-Test'!F56)) -> 55 | F38: =LEN(_xlfn.FORMULATEXT('XL-Test'!G56)) -> 20 | G38: =LEN(_xlfn.FORMULATEXT('XL-Test'!H56)) -> 108 | H38: =LEN(_xlfn.FORMULATEXT('XL-Test'!I56)) -> 141 | I38: =LEN(_xlfn.FORMULATEXT('XL-Test'!J56)) -> 8
C39: 5 | D39: =LEN(_xlfn.FORMULATEXT('XL-Test'!E57)) -> 93 | E39: =LEN(_xlfn.FORMULATEXT('XL-Test'!F57)) -> 55 | F39: =LEN(_xlfn.FORMULATEXT('XL-Test'!G57)) -> 20 | G39: =LEN(_xlfn.FORMULATEXT('XL-Test'!H57)) -> 108 | H39: =LEN(_xlfn.FORMULATEXT('XL-Test'!I57)) -> 141 | I39: =LEN(_xlfn.FORMULATEXT('XL-Test'!J57)) -> 8
C40: 6 | D40: =LEN(_xlfn.FORMULATEXT('XL-Test'!E58)) -> 93 | E40: =LEN(_xlfn.FORMULATEXT('XL-Test'!F58)) -> 55 | F40: =LEN(_xlfn.FORMULATEXT('XL-Test'!G58)) -> 20 | G40: =LEN(_xlfn.FORMULATEXT('XL-Test'!H58)) -> 108 | H40: =LEN(_xlfn.FORMULATEXT('XL-Test'!I58)) -> 141 | I40: =LEN(_xlfn.FORMULATEXT('XL-Test'!J58)) -> 8
C41: 7 | D41: =LEN(_xlfn.FORMULATEXT('XL-Test'!E59)) -> 93 | E41: =LEN(_xlfn.FORMULATEXT('XL-Test'!F59)) -> 55 | F41: =LEN(_xlfn.FORMULATEXT('XL-Test'!G59)) -> 20 | G41: =LEN(_xlfn.FORMULATEXT('XL-Test'!H59)) -> 108 | H41: =LEN(_xlfn.FORMULATEXT('XL-Test'!I59)) -> 141 | I41: =LEN(_xlfn.FORMULATEXT('XL-Test'!J59)) -> 8
C42: 8 | D42: =LEN(_xlfn.FORMULATEXT('XL-Test'!E60)) -> 93 | E42: =LEN(_xlfn.FORMULATEXT('XL-Test'!F60)) -> 55 | F42: =LEN(_xlfn.FORMULATEXT('XL-Test'!G60)) -> 20 | G42: =LEN(_xlfn.FORMULATEXT('XL-Test'!H60)) -> 108 | H42: =LEN(_xlfn.FORMULATEXT('XL-Test'!I60)) -> 141 | I42: =LEN(_xlfn.FORMULATEXT('XL-Test'!J60)) -> 8
C43: 9 | D43: =LEN(_xlfn.FORMULATEXT('XL-Test'!E61)) -> 93 | E43: =LEN(_xlfn.FORMULATEXT('XL-Test'!F61)) -> 55 | F43: =LEN(_xlfn.FORMULATEXT('XL-Test'!G61)) -> 20 | G43: =LEN(_xlfn.FORMULATEXT('XL-Test'!H61)) -> 108 | H43: =LEN(_xlfn.FORMULATEXT('XL-Test'!I61)) -> 141 | I43: =LEN(_xlfn.FORMULATEXT('XL-Test'!J61)) -> 8
C44: 10 | D44: =LEN(_xlfn.FORMULATEXT('XL-Test'!E62)) -> 93 | E44: =LEN(_xlfn.FORMULATEXT('XL-Test'!F62)) -> 55 | F44: =LEN(_xlfn.FORMULATEXT('XL-Test'!G62)) -> 20 | G44: =LEN(_xlfn.FORMULATEXT('XL-Test'!H62)) -> 108 | H44: =LEN(_xlfn.FORMULATEXT('XL-Test'!I62)) -> 141 | I44: =LEN(_xlfn.FORMULATEXT('XL-Test'!J62)) -> 8
D46: =AVERAGE(D35:D44) -> 93 | E46: =AVERAGE(E35:E44) -> 55 | F46: =AVERAGE(F35:F44) -> 20 | G46: =AVERAGE(G35:G44) -> 108 | H46: =AVERAGE(H35:H44) -> 141 | I46: =AVERAGE(I35:I44) -> 8
D48: =D46=D35 -> TRUE | E48: =E46=E35 -> TRUE | F48: =F46=F35 -> TRUE | G48: =G46=G35 -> TRUE | H48: =H46=H35 -> TRUE | I48: =I46=I35 -> TRUE | J48: TRUE
C49: arr | D49: =AND(D35>0,D38=0,D5>0) -> FALSE | E49: =AND(E35>0,E38=0,E5>0) -> FALSE | F49: =AND(F35>0,F38=0,F5>0) -> FALSE | G49: =AND(G35>0,G38=0,G5>0) -> FALSE | H49: =AND(H35>0,H38=0,H5>0) -> FALSE | I49: =AND(I35>0,I38=0,I5>0) -> FALSE | J49: =AND(J35>0,J38=0,J5>0) -> FALSE
D51: =IFERROR(OR(D48,D49),FALSE) -> TRUE | E51: =IFERROR(OR(E48,E49),FALSE) -> TRUE | F51: =IFERROR(OR(F48,F49),FALSE) -> TRUE | G51: =IFERROR(OR(G48,G49),FALSE) -> TRUE | H51: =IFERROR(OR(H48,H49),FALSE) -> TRUE | I51: =IFERROR(OR(I48,I49),FALSE) -> TRUE | J51: =IFERROR(OR(J48,J49),FALSE) -> TRUE
