Workbook
Name amb: DF!$C$35
Name Kode_jawaban: DF!$C$36

Sheet XL-Test
A18: KODE SOAL | C18: SBEE012 | E18: KODE JAWABAN | F18: =Kode_jawaban -> EL3|49-B70;27-1070;60-DF0;3C-E70;22-E36;5B-C50;34-1176
A20: Intruksi
B22: Easy Level - Latihan Soal Excel Huruf Besar dan Huruf Kecil
B24: Soal : | C24: Gunakan Fungsi Excel (Function) untuk menyelsaikan kasus dibawah ini, tidak disarankan menggunakan cara manual
B25: 1 | C25: Ubah Nama Peserta Raw menjadi Hurup Besar semua, contoh andi menjadi ANDI
B26: 2 | C26: Ubah Nama Peserta Raw menjadi Hurup kecil semua, contoh ANDI menjadi andi
B27: 3 | C27: Ubah Nama Peserta Raw menjadi Hurup Besar diawal, Contoh andi menjadi Andi
B28: 4 | C28: Ubah Nama Peserta Raw menjadi Hurup Besar diawal saja, Contoh andi menjadi Andi
B29: 5 | C29: Tentukan Jenis Huruf berdasarkan Jenis huruf di Nama Peserta Raw
C30: Jika kecil semua maka "Huruf Kecil", Jika besar semua maka "Huruf Besar", Jika campur huruf kecil dan hurup besar maka "Huruf Campur"
B31: 6 | C31: Ubah Nama Peserta Raw menjadi Hurup Besar diawal dan di akhir, Contoh rEja menjadi RejA
B32: 7 | C32: Ubah Sekolah Raw Menjadi Hurup Besar Untuk Tingkat Sekolah (SD, SMP, SMA) dan Besar diawal pada Nama Sekolah
C33: Contoh sD mAJu pRataMa menjadi SD Maju Pratama
C35: Sudah selesai mengerjakan? kirim Kode Soal dan Kode Jawaban diatas ke alamat : https://belajarexcel.id/xl-test/jawaban untuk mengecek hasilnya
C36: atau klik tombol disamping
D42: 1 | E42: 2 | F42: 3 | G42: 4 | H42: 5 | I42: 6 | K42: 7
B43: No | C43: Nama Peserta Raw | D43: Hurup Besar (Semua) | E43: Hurup Kecil (Semua) | F43: Hurup Besar diawal | G43: Sentences Case | H43: Jenis Huruf | I43: Hurup Besar (Awal dan Akhir) | J43: Data Sekolah Raw | K43: Sekolah
B44: Contoh | C44: aNdi Setiadi | D44: ANDI SETIADI | E44: andi setiadi | F44: Andi Setiadi | G44: Andi setiadi | H44: Huruf Campur | I44: Andi setiadI | J44: sD SiNdanGgalih | K44: SD Sindanggalih
B46: 1 | C46: andi saputra | D46: =UPPER(C46) -> ANDI SAPUTRA | E46: =LOWER(C46) -> andi saputra | F46: =PROPER(C46) -> Andi Saputra | G46: =REPLACE(LOWER(C46),1,1,UPPER(LEFT(C46,1))) -> Andi saputra | H46: =IF(EXACT(C46,LOWER(C46)),"Huruf Kecil", IF(EXACT(C46,UPPER(C46)),"Huruf Besar","Huruf Campur")) -> Huruf Kecil | I46: =REPLACE(REPLACE(LOWER(TRIM(C46)), 1, 1, UPPER(LEFT(TRIM(C46), 1))), LEN(TRIM(C46)), 1, UPPER(RIGHT(TRIM(C46), 1))) -> Andi saputrA | J46: sD nUsAnTaRa cEmErLaNg | K46: =REPLACE(PROPER(TRIM(J46)),1,3,UPPER(LEFT(TRIM(J46),3))) -> SD Nusantara Cemerlang
B47: 2 | C47: bUDi sANtoSo | D47: =UPPER(C47) -> BUDI SANTOSO | E47: =LOWER(C47) -> budi santoso | F47: =PROPER(C47) -> Budi Santoso | G47: =REPLACE(LOWER(C47),1,1,UPPER(LEFT(C47,1))) -> Budi santoso | H47: =IF(EXACT(C47,LOWER(C47)),"Huruf Kecil", IF(EXACT(C47,UPPER(C47)),"Huruf Besar","Huruf Campur")) -> Huruf Campur | I47: =REPLACE(REPLACE(LOWER(TRIM(C47)), 1, 1, UPPER(LEFT(TRIM(C47), 1))), LEN(TRIM(C47)), 1, UPPER(RIGHT(TRIM(C47), 1))) -> Budi santosO | J47: SmP bInA kArYa uTaMa | K47: =REPLACE(PROPER(TRIM(J47)),1,3,UPPER(LEFT(TRIM(J47),3))) -> SMP Bina Karya Utama
B48: 3 | C48: CITRA DEWI | D48: =UPPER(C48) -> CITRA DEWI | E48: =LOWER(C48) -> citra dewi | F48: =PROPER(C48) -> Citra Dewi | G48: =REPLACE(LOWER(C48),1,1,UPPER(LEFT(C48,1))) -> Citra dewi | H48: =IF(EXACT(C48,LOWER(C48)),"Huruf Kecil", IF(EXACT(C48,UPPER(C48)),"Huruf Besar","Huruf Campur")) -> Huruf Besar | I48: =REPLACE(REPLACE(LOWER(TRIM(C48)), 1, 1, UPPER(LEFT(TRIM(C48), 1))), LEN(TRIM(C48)), 1, UPPER(RIGHT(TRIM(C48), 1))) -> Citra dewI | J48: sMa gLoBaL pReStAsI | K48: =REPLACE(PROPER(TRIM(J48)),1,3,UPPER(LEFT(TRIM(J48),3))) -> SMA Global Prestasi
B49: 4 | C49: dIaN prAseTyo | D49: =UPPER(C49) -> DIAN PRASETYO | E49: =LOWER(C49) -> dian prasetyo | F49: =PROPER(C49) -> Dian Prasetyo | G49: =REPLACE(LOWER(C49),1,1,UPPER(LEFT(C49,1))) -> Dian prasetyo | H49: =IF(EXACT(C49,LOWER(C49)),"Huruf Kecil", IF(EXACT(C49,UPPER(C49)),"Huruf Besar","Huruf Campur")) -> Huruf Campur | I49: =REPLACE(REPLACE(LOWER(TRIM(C49)), 1, 1, UPPER(LEFT(TRIM(C49), 1))), LEN(TRIM(C49)), 1, UPPER(RIGHT(TRIM(C49), 1))) -> Dian prasetyO | J49: Sd pElItA iNsAn mUlIa | K49: =REPLACE(PROPER(TRIM(J49)),1,3,UPPER(LEFT(TRIM(J49),3))) -> SD Pelita Insan Mulia
B50: 5 | C50: EKO WAHYUDI | D50: =UPPER(C50) -> EKO WAHYUDI | E50: =LOWER(C50) -> eko wahyudi | F50: =PROPER(C50) -> Eko Wahyudi | G50: =REPLACE(LOWER(C50),1,1,UPPER(LEFT(C50,1))) -> Eko wahyudi | H50: =IF(EXACT(C50,LOWER(C50)),"Huruf Kecil", IF(EXACT(C50,UPPER(C50)),"Huruf Besar","Huruf Campur")) -> Huruf Besar | I50: =REPLACE(REPLACE(LOWER(TRIM(C50)), 1, 1, UPPER(LEFT(TRIM(C50), 1))), LEN(TRIM(C50)), 1, UPPER(RIGHT(TRIM(C50), 1))) -> Eko wahyudI | J50: SmA sInAr aBuDi | K50: =REPLACE(PROPER(TRIM(J50)),1,3,UPPER(LEFT(TRIM(J50),3))) -> SMA Sinar Abudi
B51: 6 | C51: fitri anjani | D51: =UPPER(C51) -> FITRI ANJANI | E51: =LOWER(C51) -> fitri anjani | F51: =PROPER(C51) -> Fitri Anjani | G51: =REPLACE(LOWER(C51),1,1,UPPER(LEFT(C51,1))) -> Fitri anjani | H51: =IF(EXACT(C51,LOWER(C51)),"Huruf Kecil", IF(EXACT(C51,UPPER(C51)),"Huruf Besar","Huruf Campur")) -> Huruf Kecil | I51: =REPLACE(REPLACE(LOWER(TRIM(C51)), 1, 1, UPPER(LEFT(TRIM(C51), 1))), LEN(TRIM(C51)), 1, UPPER(RIGHT(TRIM(C51), 1))) -> Fitri anjanI | J51: sMp tUnAs bAnGsA | K51: =REPLACE(PROPER(TRIM(J51)),1,3,UPPER(LEFT(TRIM(J51),3))) -> SMP Tunas Bangsa
B52: 7 | C52: gAlIh pErMAnA | D52: =UPPER(C52) -> GALIH PERMANA | E52: =LOWER(C52) -> galih permana | F52: =PROPER(C52) -> Galih Permana | G52: =REPLACE(LOWER(C52),1,1,UPPER(LEFT(C52,1))) -> Galih permana | H52: =IF(EXACT(C52,LOWER(C52)),"Huruf Kecil", IF(EXACT(C52,UPPER(C52)),"Huruf Besar","Huruf Campur")) -> Huruf Campur | I52: =REPLACE(REPLACE(LOWER(TRIM(C52)), 1, 1, UPPER(LEFT(TRIM(C52), 1))), LEN(TRIM(C52)), 1, UPPER(RIGHT(TRIM(C52), 1))) -> Galih permanA | J52: SmA cEnDeKiA mAnDiRi | K52: =REPLACE(PROPER(TRIM(J52)),1,3,UPPER(LEFT(TRIM(J52),3))) -> SMA Cendekia Mandiri
B53: 8 | C53: heNdRA gUnAwAn | D53: =UPPER(C53) -> HENDRA GUNAWAN | E53: =LOWER(C53) -> hendra gunawan | F53: =PROPER(C53) -> Hendra Gunawan | G53: =REPLACE(LOWER(C53),1,1,UPPER(LEFT(C53,1))) -> Hendra gunawan | H53: =IF(EXACT(C53,LOWER(C53)),"Huruf Kecil", IF(EXACT(C53,UPPER(C53)),"Huruf Besar","Huruf Campur")) -> Huruf Campur | I53: =REPLACE(REPLACE(LOWER(TRIM(C53)), 1, 1, UPPER(LEFT(TRIM(C53), 1))), LEN(TRIM(C53)), 1, UPPER(RIGHT(TRIM(C53), 1))) -> Hendra gunawaN | J53: sD bHaKtI pErTiWi | K53: =REPLACE(PROPER(TRIM(J53)),1,3,UPPER(LEFT(TRIM(J53),3))) -> SD Bhakti Pertiwi
B54: 9 | C54: indah sari | D54: =UPPER(C54) -> INDAH SARI | E54: =LOWER(C54) -> indah sari | F54: =PROPER(C54) -> Indah Sari | G54: =REPLACE(LOWER(C54),1,1,UPPER(LEFT(C54,1))) -> Indah sari | H54: =IF(EXACT(C54,LOWER(C54)),"Huruf Kecil", IF(EXACT(C54,UPPER(C54)),"Huruf Besar","Huruf Campur")) -> Huruf Kecil | I54: =REPLACE(REPLACE(LOWER(TRIM(C54)), 1, 1, UPPER(LEFT(TRIM(C54), 1))), LEN(TRIM(C54)), 1, UPPER(RIGHT(TRIM(C54), 1))) -> Indah sarI | J54: sMp mEkAr jAyA aBaDi | K54: =REPLACE(PROPER(TRIM(J54)),1,3,UPPER(LEFT(TRIM(J54),3))) -> SMP Mekar Jaya Abadi
B55: 10 | C55: JOKO SUSILO | D55: =UPPER(C55) -> JOKO SUSILO | E55: =LOWER(C55) -> joko susilo | F55: =PROPER(C55) -> Joko Susilo | G55: =REPLACE(LOWER(C55),1,1,UPPER(LEFT(C55,1))) -> Joko susilo | H55: =IF(EXACT(C55,LOWER(C55)),"Huruf Kecil", IF(EXACT(C55,UPPER(C55)),"Huruf Besar","Huruf Campur")) -> Huruf Besar | I55: =REPLACE(REPLACE(LOWER(TRIM(C55)), 1, 1, UPPER(LEFT(TRIM(C55), 1))), LEN(TRIM(C55)), 1, UPPER(RIGHT(TRIM(C55), 1))) -> Joko susilO | J55: SmA pUsAkA nUsAnTaRa | K55: =REPLACE(PROPER(TRIM(J55)),1,3,UPPER(LEFT(TRIM(J55),3))) -> SMA Pusaka Nusantara
B56: 11 | C56: KaRTiKa pUtRi | D56: =UPPER(C56) -> KARTIKA PUTRI | E56: =LOWER(C56) -> kartika putri | F56: =PROPER(C56) -> Kartika Putri | G56: =REPLACE(LOWER(C56),1,1,UPPER(LEFT(C56,1))) -> Kartika putri | H56: =IF(EXACT(C56,LOWER(C56)),"Huruf Kecil", IF(EXACT(C56,UPPER(C56)),"Huruf Besar","Huruf Campur")) -> Huruf Campur | I56: =REPLACE(REPLACE(LOWER(TRIM(C56)), 1, 1, UPPER(LEFT(TRIM(C56), 1))), LEN(TRIM(C56)), 1, UPPER(RIGHT(TRIM(C56), 1))) -> Kartika putrI | J56: sD cItRa hArApAn | K56: =REPLACE(PROPER(TRIM(J56)),1,3,UPPER(LEFT(TRIM(J56),3))) -> SD Citra Harapan
B57: 12 | C57: LESTARI AYU | D57: =UPPER(C57) -> LESTARI AYU | E57: =LOWER(C57) -> lestari ayu | F57: =PROPER(C57) -> Lestari Ayu | G57: =REPLACE(LOWER(C57),1,1,UPPER(LEFT(C57,1))) -> Lestari ayu | H57: =IF(EXACT(C57,LOWER(C57)),"Huruf Kecil", IF(EXACT(C57,UPPER(C57)),"Huruf Besar","Huruf Campur")) -> Huruf Besar | I57: =REPLACE(REPLACE(LOWER(TRIM(C57)), 1, 1, UPPER(LEFT(TRIM(C57), 1))), LEN(TRIM(C57)), 1, UPPER(RIGHT(TRIM(C57), 1))) -> Lestari ayU | J57: sMp aRgA sEnToSa | K57: =REPLACE(PROPER(TRIM(J57)),1,3,UPPER(LEFT(TRIM(J57),3))) -> SMP Arga Sentosa
... B60: 15 | C60: Lusi atMAjaya | D60: =UPPER(C60) -> LUSI ATMAJAYA | E60: =LOWER(C60) -> lusi atmajaya | F60: =PROPER(C60) -> Lusi Atmajaya | G60: =REPLACE(LOWER(C60),1,1,UPPER(LEFT(C60,1))) -> Lusi atmajaya | H60: =IF(EXACT(C60,LOWER(C60)),"Huruf Kecil", IF(EXACT(C60,UPPER(C60)),"Huruf Besar","Huruf Campur")) -> Huruf Campur | I60: =REPLACE(REPLACE(LOWER(TRIM(C60)), 1, 1, UPPER(LEFT(TRIM(C60), 1))), LEN(TRIM(C60)), 1, UPPER(RIGHT(TRIM(C60), 1))) -> Lusi atmajayA | J60: sMp lEnSa iLmU | K60: =REPLACE(PROPER(TRIM(J60)),1,3,UPPER(LEFT(TRIM(J60),3))) -> SMP Lensa Ilmu
C77: Perlu Video Penjelasan atau Kunci Jawaban ?
C78: Scan barcode atau kunjungi
C79: https://lynk.id/setiadi/page/jawaban-xl-test

Sheet About
I6: XL-TEST adalah platform inovatif yang menyediakan latihan Excel interaktif dengan pemeriksaan otomatis,
I7: sehingga pengguna dapat langsung mengetahui jawaban yang benar maupun salah.
I10: Terdapat 5 Level soal :
J12: Easy Level | L12: (⭐)
J13: Medium Level | L13: (⭐⭐)
J14: Hard Level | L14: (⭐⭐⭐)
J15: Extreme Level | L15: (⭐⭐⭐⭐)
J16: Championship Level | L16: (⭐⭐⭐⭐⭐)
B17: Saya adalah seorang Excel Holic yang percaya bahwa setiap angka memiliki cerita yang bisa ditemukan dengan cara yang tepat. | I17: Free Access
B18: “Excel bukan cuma soal kerjaan tapi juga hobi yang aku nikmati.” | I18: https://belajarexcel.id/xl-test/
B19: Contact :
B20: 🌐 Web | C20: https://setiadi.me
B21: 🪡threads | C21: https://www.threads.com/@andisetiadi
D27: Perlu Video Penjelasan atau Kunci Jawaban ?
D28: Scan barcode atau kunjungi
D29: https://lynk.id/setiadi/page/jawaban-xl-test

Sheet DF
A1: Def | C1: 1 | D1: 2 | E1: 3 | F1: 4 | G1: 5 | H1: 6 | I1: 7 | N1: 1 | O1: 2 | P1: 3 | Q1: 4 | R1: 5 | S1: 6 | T1: 7
A2: EL3 | B2: 1 | C2: ='XL-Test'!D46 -> ANDI SAPUTRA | D2: ='XL-Test'!E46 -> andi saputra | E2: ='XL-Test'!F46 -> Andi Saputra | F2: ='XL-Test'!G46 -> Andi saputra | G2: ='XL-Test'!H46 -> Huruf Kecil | H2: ='XL-Test'!I46 -> Andi saputrA | I2: ='XL-Test'!K46 -> SD Nusantara Cemerlang | N2: =_xlfn.FORMULATEXT('XL-Test'!D46) -> =UPPER(C46) | O2: =_xlfn.FORMULATEXT('XL-Test'!E46) -> =LOWER(C46) | P2: =_xlfn.FORMULATEXT('XL-Test'!F46) -> =PROPER(C46) | Q2: =_xlfn.FORMULATEXT('XL-Test'!G46) -> =REPLACE(LOWER(C46);1;1;UPPER(LEFT(C46;1))) | R2: =_xlfn.FORMULATEXT('XL-Test'!H46) -> =IF(EXACT(C46;LOWER(C46));"Huruf Kecil"; IF(EXACT(C46;UPPER(C46));"Huruf Besar";"Huruf Campur")) | S2: =_xlfn.FORMULATEXT('XL-Test'!I46) -> =REPLACE(REPLACE(LOWER(TRIM(C46)); 1; 1; UPPER(LEFT(TRIM(C46); 1))); LEN(TRIM(C46)); 1; UPPER(RIGHT(TRIM(C46); 1))) | T2: =_xlfn.FORMULATEXT('XL-Test'!K46) -> =REPLACE(PROPER(TRIM(J46));1;3;UPPER(LEFT(TRIM(J46);3)))
B3: 2 | C3: ='XL-Test'!D47 -> BUDI SANTOSO | D3: ='XL-Test'!E47 -> budi santoso | E3: ='XL-Test'!F47 -> Budi Santoso | F3: ='XL-Test'!G47 -> Budi santoso | G3: ='XL-Test'!H47 -> Huruf Campur | H3: ='XL-Test'!I47 -> Budi santosO | I3: ='XL-Test'!K47 -> SMP Bina Karya Utama | N3: =_xlfn.FORMULATEXT('XL-Test'!E46) -> =LOWER(C46)
B4: 3 | C4: ='XL-Test'!D48 -> CITRA DEWI | D4: ='XL-Test'!E48 -> citra dewi | E4: ='XL-Test'!F48 -> Citra Dewi | F4: ='XL-Test'!G48 -> Citra dewi | G4: ='XL-Test'!H48 -> Huruf Besar | H4: ='XL-Test'!I48 -> Citra dewI | I4: ='XL-Test'!K48 -> SMA Global Prestasi | N4: =_xlfn.FORMULATEXT('XL-Test'!F46) -> =PROPER(C46)
B5: 4 | C5: ='XL-Test'!D49 -> DIAN PRASETYO | D5: ='XL-Test'!E49 -> dian prasetyo | E5: ='XL-Test'!F49 -> Dian Prasetyo | F5: ='XL-Test'!G49 -> Dian prasetyo | G5: ='XL-Test'!H49 -> Huruf Campur | H5: ='XL-Test'!I49 -> Dian prasetyO | I5: ='XL-Test'!K49 -> SD Pelita Insan Mulia | N5: =_xlfn.FORMULATEXT('XL-Test'!G46) -> =REPLACE(LOWER(C46);1;1;UPPER(LEFT(C46;1)))
B6: 5 | C6: ='XL-Test'!D50 -> EKO WAHYUDI | D6: ='XL-Test'!E50 -> eko wahyudi | E6: ='XL-Test'!F50 -> Eko Wahyudi | F6: ='XL-Test'!G50 -> Eko wahyudi | G6: ='XL-Test'!H50 -> Huruf Besar | H6: ='XL-Test'!I50 -> Eko wahyudI | I6: ='XL-Test'!K50 -> SMA Sinar Abudi | N6: =_xlfn.FORMULATEXT('XL-Test'!H46) -> =IF(EXACT(C46;LOWER(C46));"Huruf Kecil"; IF(EXACT(C46;UPPER(C46));"Huruf Besar";"Huruf Campur"))
B7: 6 | C7: ='XL-Test'!D51 -> FITRI ANJANI | D7: ='XL-Test'!E51 -> fitri anjani | E7: ='XL-Test'!F51 -> Fitri Anjani | F7: ='XL-Test'!G51 -> Fitri anjani | G7: ='XL-Test'!H51 -> Huruf Kecil | H7: ='XL-Test'!I51 -> Fitri anjanI | I7: ='XL-Test'!K51 -> SMP Tunas Bangsa | N7: =_xlfn.FORMULATEXT('XL-Test'!I46) -> =REPLACE(REPLACE(LOWER(TRIM(C46)); 1; 1; UPPER(LEFT(TRIM(C46); 1))); LEN(TRIM(C46)); 1; UPPER(RIGHT(TRIM(C46); 1)))
B8: 7 | C8: ='XL-Test'!D52 -> GALIH PERMANA | D8: ='XL-Test'!E52 -> galih permana | E8: ='XL-Test'!F52 -> Galih Permana | F8: ='XL-Test'!G52 -> Galih permana | G8: ='XL-Test'!H52 -> Huruf Campur | H8: ='XL-Test'!I52 -> Galih permanA | I8: ='XL-Test'!K52 -> SMA Cendekia Mandiri | N8: =_xlfn.FORMULATEXT('XL-Test'!K46) -> =REPLACE(PROPER(TRIM(J46));1;3;UPPER(LEFT(TRIM(J46);3)))
B9: 8 | C9: ='XL-Test'!D53 -> HENDRA GUNAWAN | D9: ='XL-Test'!E53 -> hendra gunawan | E9: ='XL-Test'!F53 -> Hendra Gunawan | F9: ='XL-Test'!G53 -> Hendra gunawan | G9: ='XL-Test'!H53 -> Huruf Campur | H9: ='XL-Test'!I53 -> Hendra gunawaN | I9: ='XL-Test'!K53 -> SD Bhakti Pertiwi
B10: 9 | C10: ='XL-Test'!D54 -> INDAH SARI | D10: ='XL-Test'!E54 -> indah sari | E10: ='XL-Test'!F54 -> Indah Sari | F10: ='XL-Test'!G54 -> Indah sari | G10: ='XL-Test'!H54 -> Huruf Kecil | H10: ='XL-Test'!I54 -> Indah sarI | I10: ='XL-Test'!K54 -> SMP Mekar Jaya Abadi
B11: 10 | C11: ='XL-Test'!D55 -> JOKO SUSILO | D11: ='XL-Test'!E55 -> joko susilo | E11: ='XL-Test'!F55 -> Joko Susilo | F11: ='XL-Test'!G55 -> Joko susilo | G11: ='XL-Test'!H55 -> Huruf Besar | H11: ='XL-Test'!I55 -> Joko susilO | I11: ='XL-Test'!K55 -> SMA Pusaka Nusantara
B12: 11 | C12: ='XL-Test'!D56 -> KARTIKA PUTRI | D12: ='XL-Test'!E56 -> kartika putri | E12: ='XL-Test'!F56 -> Kartika Putri | F12: ='XL-Test'!G56 -> Kartika putri | G12: ='XL-Test'!H56 -> Huruf Campur | H12: ='XL-Test'!I56 -> Kartika putrI | I12: ='XL-Test'!K56 -> SD Citra Harapan
B13: 12 | C13: ='XL-Test'!D57 -> LESTARI AYU | D13: ='XL-Test'!E57 -> lestari ayu | E13: ='XL-Test'!F57 -> Lestari Ayu | F13: ='XL-Test'!G57 -> Lestari ayu | G13: ='XL-Test'!H57 -> Huruf Besar | H13: ='XL-Test'!I57 -> Lestari ayU | I13: ='XL-Test'!K57 -> SMP Arga Sentosa
B14: 13 | C14: ='XL-Test'!D58 -> MUHAMMAD RIZKY | D14: ='XL-Test'!E58 -> muhammad rizky | E14: ='XL-Test'!F58 -> Muhammad Rizky | F14: ='XL-Test'!G58 -> Muhammad rizky | G14: ='XL-Test'!H58 -> Huruf Campur | H14: ='XL-Test'!I58 -> Muhammad rizkY | I14: ='XL-Test'!K58 -> SMA Bintang Timur
B15: 14 | C15: ='XL-Test'!D59 -> NADIA KUSUMA | D15: ='XL-Test'!E59 -> nadia kusuma | E15: ='XL-Test'!F59 -> Nadia Kusuma | F15: ='XL-Test'!G59 -> Nadia kusuma | G15: ='XL-Test'!H59 -> Huruf Besar | H15: ='XL-Test'!I59 -> Nadia kusumA | I15: ='XL-Test'!K59 -> SD Mutiara Hati
B16: 15 | C16: ='XL-Test'!D60 -> LUSI ATMAJAYA | D16: ='XL-Test'!E60 -> lusi atmajaya | E16: ='XL-Test'!F60 -> Lusi Atmajaya | F16: ='XL-Test'!G60 -> Lusi atmajaya | G16: ='XL-Test'!H60 -> Huruf Campur | H16: ='XL-Test'!I60 -> Lusi atmajayA | I16: ='XL-Test'!K60 -> SMP Lensa Ilmu
C18: =CODE(LEFT(C2))+CODE(RIGHT(C2))+CODE(LEFT(C3))+CODE(RIGHT(C3))+CODE(LEFT(C4))+CODE(RIGHT(C4))+CODE(LEFT(C5))+CODE(RIGHT(C5))+CODE(LEFT(C6))+CODE(RIGHT(C6))+CODE(LEFT(C6))+CODE(RIGHT(C6))+CODE(LEFT(C7))+CODE(RIGHT(C7))+CODE(LEFT(C8))+CODE(RIGHT(C8))+CODE(LEFT(C9))+CODE(RIGHT(C9))+CODE(LEFT(C10))+CODE(RIGHT(C10))+CODE(LEFT(C11))+CODE(RIGHT(C11))+CODE(MID(C2,3,1))+CODE(MID(C11,3,1))+CODE(LEFT(RIGHT(C9,3)))+CODE(LEFT(C12))+CODE(LEFT(C13))+CODE(LEFT(C14))+CODE(LEFT(C15))+CODE(LEFT(C16))+CODE(RIGHT(C2))+CODE(RIGHT(C4))+CODE(RIGHT(C6))+CODE(RIGHT(C8))+CODE(RIGHT(C12))+CODE(RIGHT(C15))+CODE(MID(C2,6,1))+CODE(MID(C6,5,1))+CODE(MID(C11,6,1))+CODE(MID(C15,7,1)) -> 2928 | D18: =CODE(LEFT(D2))+CODE(RIGHT(D2))+CODE(LEFT(D3))+CODE(RIGHT(D3))+CODE(LEFT(D4))+CODE(RIGHT(D4))+CODE(LEFT(D5))+CODE(RIGHT(D5))+CODE(LEFT(D6))+CODE(RIGHT(D6))+CODE(LEFT(D6))+CODE(RIGHT(D6))+CODE(LEFT(D7))+CODE(RIGHT(D7))+CODE(LEFT(D8))+CODE(RIGHT(D8))+CODE(LEFT(D9))+CODE(RIGHT(D9))+CODE(LEFT(D10))+CODE(RIGHT(D10))+CODE(LEFT(D11))+CODE(RIGHT(D11))+CODE(MID(D2,3,1))+CODE(MID(D11,3,1))+CODE(LEFT(RIGHT(D9,3)))+CODE(LEFT(D12))+CODE(LEFT(D13))+CODE(LEFT(D14))+CODE(LEFT(D15))+CODE(LEFT(D16))+CODE(RIGHT(D2))+CODE(RIGHT(D4))+CODE(RIGHT(D6))+CODE(RIGHT(D8))+CODE(RIGHT(D12))+CODE(RIGHT(D15))+CODE(MID(D2,6,1))+CODE(MID(D6,5,1))+CODE(MID(D11,6,1))+CODE(MID(D15,7,1)) -> 4208 | E18: =CODE(LEFT(E2))+CODE(RIGHT(E2))+CODE(LEFT(E3))+CODE(RIGHT(E3))+CODE(LEFT(E4))+CODE(RIGHT(E4))+CODE(LEFT(E5))+CODE(RIGHT(E5))+CODE(LEFT(E6))+CODE(RIGHT(E6))+CODE(LEFT(E6))+CODE(RIGHT(E6))+CODE(LEFT(E7))+CODE(RIGHT(E7))+CODE(LEFT(E8))+CODE(RIGHT(E8))+CODE(LEFT(E9))+CODE(RIGHT(E9))+CODE(LEFT(E10))+CODE(RIGHT(E10))+CODE(LEFT(E11))+CODE(RIGHT(E11))+CODE(MID(E2,3,1))+CODE(MID(E11,3,1))+CODE(LEFT(RIGHT(E9,3)))+CODE(LEFT(E12))+CODE(LEFT(E13))+CODE(LEFT(E14))+CODE(LEFT(E15))+CODE(LEFT(E16))+CODE(RIGHT(E2))+CODE(RIGHT(E4))+CODE(RIGHT(E6))+CODE(RIGHT(E8))+CODE(RIGHT(E12))+CODE(RIGHT(E15))+CODE(MID(E2,6,1))+CODE(MID(E6,5,1))+CODE(MID(E11,6,1))+CODE(MID(E15,7,1)) -> 3568 | F18: =CODE(LEFT(F2))+CODE(RIGHT(F2))+CODE(LEFT(F3))+CODE(RIGHT(F3))+CODE(LEFT(F4))+CODE(RIGHT(F4))+CODE(LEFT(F5))+CODE(RIGHT(F5))+CODE(LEFT(F6))+CODE(RIGHT(F6))+CODE(LEFT(F6))+CODE(RIGHT(F6))+CODE(LEFT(F7))+CODE(RIGHT(F7))+CODE(LEFT(F8))+CODE(RIGHT(F8))+CODE(LEFT(F9))+CODE(RIGHT(F9))+CODE(LEFT(F10))+CODE(RIGHT(F10))+CODE(LEFT(F11))+CODE(RIGHT(F11))+CODE(MID(F2,3,1))+CODE(MID(F11,3,1))+CODE(LEFT(RIGHT(F9,3)))+CODE(LEFT(F12))+CODE(LEFT(F13))+CODE(LEFT(F14))+CODE(LEFT(F15))+CODE(LEFT(F16))+CODE(RIGHT(F2))+CODE(RIGHT(F4))+CODE(RIGHT(F6))+CODE(RIGHT(F8))+CODE(RIGHT(F12))+CODE(RIGHT(F15))+CODE(MID(F2,6,1))+CODE(MID(F6,5,1))+CODE(MID(F11,6,1))+CODE(MID(F15,7,1)) -> 3696 | G18: =CODE(LEFT(G2))+CODE(RIGHT(G2))+CODE(LEFT(G3))+CODE(RIGHT(G3))+CODE(LEFT(G4))+CODE(RIGHT(G4))+CODE(LEFT(G5))+CODE(RIGHT(G5))+CODE(LEFT(G6))+CODE(RIGHT(G6))+CODE(LEFT(G6))+CODE(RIGHT(G6))+CODE(LEFT(G7))+CODE(RIGHT(G7))+CODE(LEFT(G8))+CODE(RIGHT(G8))+CODE(LEFT(G9))+CODE(RIGHT(G9))+CODE(LEFT(G10))+CODE(RIGHT(G10))+CODE(LEFT(G11))+CODE(RIGHT(G11))+CODE(MID(G2,3,1))+CODE(MID(G11,3,1))+CODE(LEFT(RIGHT(G9,3)))+CODE(LEFT(G12))+CODE(LEFT(G13))+CODE(LEFT(G14))+CODE(LEFT(G15))+CODE(LEFT(G16))+CODE(RIGHT(G2))+CODE(RIGHT(G4))+CODE(RIGHT(G6))+CODE(RIGHT(G8))+CODE(RIGHT(G12))+CODE(RIGHT(G15))+CODE(MID(G2,6,1))+CODE(MID(G6,5,1))+CODE(MID(G11,6,1))+CODE(MID(G15,7,1)) -> 3638 | H18: =CODE(LEFT(H2))+CODE(RIGHT(H2))+CODE(LEFT(H3))+CODE(RIGHT(H3))+CODE(LEFT(H4))+CODE(RIGHT(H4))+CODE(LEFT(H5))+CODE(RIGHT(H5))+CODE(LEFT(H6))+CODE(RIGHT(H6))+CODE(LEFT(H6))+CODE(RIGHT(H6))+CODE(LEFT(H7))+CODE(RIGHT(H7))+CODE(LEFT(H8))+CODE(RIGHT(H8))+CODE(LEFT(H9))+CODE(RIGHT(H9))+CODE(LEFT(H10))+CODE(RIGHT(H10))+CODE(LEFT(H11))+CODE(RIGHT(H11))+CODE(MID(H2,3,1))+CODE(MID(H11,3,1))+CODE(LEFT(RIGHT(H9,3)))+CODE(LEFT(H12))+CODE(LEFT(H13))+CODE(LEFT(H14))+CODE(LEFT(H15))+CODE(LEFT(H16))+CODE(RIGHT(H2))+CODE(RIGHT(H4))+CODE(RIGHT(H6))+CODE(RIGHT(H8))+CODE(RIGHT(H12))+CODE(RIGHT(H15))+CODE(MID(H2,6,1))+CODE(MID(H6,5,1))+CODE(MID(H11,6,1))+CODE(MID(H15,7,1)) -> 3152 | I18: =CODE(LEFT(I2))+CODE(RIGHT(I2))+CODE(LEFT(I3))+CODE(RIGHT(I3))+CODE(LEFT(I4))+CODE(RIGHT(I4))+CODE(LEFT(I5))+CODE(RIGHT(I5))+CODE(LEFT(I6))+CODE(RIGHT(I6))+CODE(LEFT(I6))+CODE(RIGHT(I6))+CODE(LEFT(I7))+CODE(RIGHT(I7))+CODE(LEFT(I8))+CODE(RIGHT(I8))+CODE(LEFT(I9))+CODE(RIGHT(I9))+CODE(LEFT(I10))+CODE(RIGHT(I10))+CODE(LEFT(I11))+CODE(RIGHT(I11))+CODE(MID(I2,3,1))+CODE(MID(I11,5,1))+CODE(LEFT(RIGHT(I9,3)))+CODE(LEFT(I12))+CODE(LEFT(I13))+CODE(LEFT(I14))+CODE(LEFT(I15))+CODE(LEFT(I16))+CODE(RIGHT(I2))+CODE(RIGHT(I4))+CODE(RIGHT(I6))+CODE(RIGHT(I8))+CODE(RIGHT(I12))+CODE(RIGHT(I15))+CODE(MID(I10,5,1))+CODE(MID(I2,2,1))+CODE(MID(I3,2,1))+CODE(MID(I4,2,1))+CODE(MID(I5,2,1))+CODE(MID(I6,2,1))+CODE(MID(I7,2,1))+CODE(MID(I14,5,1))+CODE(MID(I16,5,1))+CODE(MID(I8,3,1))+CODE(MID(I10,2,1))+CODE(MID(I6,11,1))+CODE(MID(I12,10,1))+CODE(MID(I2,6,1))+CODE(MID(I13,6,1)) -> 4470
B19: Rand | C19: 7039 | D19: 3577 | E19: 9117 | F19: 5463 | G19: 2763 | H19: 8357 | I19: 4351
B21: TRUE | C21: =DEC2HEX(LEFT(C19,2)+COLUMN()) -> 49 | D21: =DEC2HEX(LEFT(D19,2)+COLUMN()) -> 27 | E21: =DEC2HEX(LEFT(E19,2)+COLUMN()) -> 60 | F21: =DEC2HEX(LEFT(F19,2)+COLUMN()) -> 3C | G21: =DEC2HEX(LEFT(G19,2)+COLUMN()) -> 22 | H21: =DEC2HEX(LEFT(H19,2)+COLUMN()) -> 5B | I21: =DEC2HEX(LEFT(I19,2)+COLUMN()) -> 34
B22: FALSE | C22: =DEC2HEX(RIGHT(C19,2)+COLUMN()) -> 2A | D22: =DEC2HEX(RIGHT(D19,2)+COLUMN()) -> 51 | E22: =DEC2HEX(RIGHT(E19,2)+COLUMN()) -> 16 | F22: =DEC2HEX(RIGHT(F19,2)+COLUMN()) -> 45 | G22: =DEC2HEX(RIGHT(G19,2)+COLUMN()) -> 46 | H22: =DEC2HEX(RIGHT(H19,2)+COLUMN()) -> 41 | I22: =DEC2HEX(RIGHT(I19,2)+COLUMN()) -> 3C
B24: Cek Kosong | C24: =IF(OR(C2="",C2=0),FALSE,TRUE) -> TRUE | D24: =IF(OR(D2="",D2=0),FALSE,TRUE) -> TRUE | E24: =IF(OR(E2="",E2=0),FALSE,TRUE) -> TRUE | F24: =IF(OR(F2="",F2=0),FALSE,TRUE) -> TRUE | G24: =IF(OR(G2="",G2=0),FALSE,TRUE) -> TRUE | H24: =IF(OR(H2="",H2=0),FALSE,TRUE) -> TRUE | I24: =IF(OR(I2="",I2=0),FALSE,TRUE) -> TRUE
B25: Cek Fungsi | C25: =AND(ISNUMBER(FIND("=",N2)),ISNUMBER(FIND("(",N2))) -> TRUE | D25: =AND(ISNUMBER(FIND("=",O2)),ISNUMBER(FIND("(",O2))) -> TRUE | E25: =AND(ISNUMBER(FIND("=",P2)),ISNUMBER(FIND("(",P2))) -> TRUE | F25: =AND(ISNUMBER(FIND("=",Q2)),ISNUMBER(FIND("(",Q2))) -> TRUE | G25: =AND(ISNUMBER(FIND("=",R2)),ISNUMBER(FIND("(",R2))) -> TRUE | H25: =AND(ISNUMBER(FIND("=",S2)),ISNUMBER(FIND("(",S2))) -> TRUE | I25: =AND(ISNUMBER(FIND("=",T2)),ISNUMBER(FIND("(",T2))) -> TRUE
C27: =IFERROR(DEC2HEX(IF(AND(C24:C25,C58),C18,C19)),"EEE") -> B70 | D27: =IFERROR(DEC2HEX(IF(AND(D24:D25,D58),D18,D19)),"EEE") -> 1070 | E27: =IFERROR(DEC2HEX(IF(AND(E24:E25,E58),E18,E19)),"EEE") -> DF0 | F27: =IFERROR(DEC2HEX(IF(AND(F24:F25,F58),F18,F19)),"EEE") -> E70 | G27: =IFERROR(DEC2HEX(IF(AND(G24:G25,G58),G18,G19)),"EEE") -> E36 | H27: =IFERROR(DEC2HEX(IF(AND(H24:H25,H58),H18,H19)),"EEE") -> C50 | I27: =IFERROR(DEC2HEX(IF(AND(I24:I25,I58),I18,I19)),"EEE") -> 1176
B29: Cek Rumus | C29: =AND(ISNUMBER(FIND("UPP",N2)),ISNUMBER(FIND("(",N2))) -> TRUE | D29: =AND(ISNUMBER(FIND("OWE",O2)),ISNUMBER(FIND("(",O2))) -> TRUE | E29: =AND(ISNUMBER(FIND("ROPE",P2)),ISNUMBER(FIND("(",P2))) -> TRUE | F29: =AND(ISNUMBER(FIND("PPE",Q2)),ISNUMBER(FIND("EPLAC",Q2))) -> TRUE | G29: =AND(ISNUMBER(FIND("XACT",R2)),ISNUMBER(FIND("(",R2))) -> TRUE | H29: =AND(ISNUMBER(FIND("PLAC",S2)),ISNUMBER(FIND("PPE",S2))) -> TRUE | I29: =AND(ISNUMBER(FIND("EPL",T2)),ISNUMBER(FIND("PROP",T2))) -> TRUE
C31: =IF(C29,C21,C22)&"-"&C27&";" -> 49-B70; | D31: =IF(D29,D21,D22)&"-"&D27&";" -> 27-1070; | E31: =IF(E29,E21,E22)&"-"&E27&";" -> 60-DF0; | F31: =IF(F29,F21,F22)&"-"&F27&";" -> 3C-E70; | G31: =IF(G29,G21,G22)&"-"&G27&";" -> 22-E36; | H31: =IF(H29,H21,H22)&"-"&H27&";" -> 5B-C50; | I31: =IF(I29,I21,I22)&"-"&I27 -> 34-1176
C33: =A2&"|"&C31&D31&E31&F31&G31&H31&I31 -> EL3|49-B70;27-1070;60-DF0;3C-E70;22-E36;5B-C50;34-1176
C35: =C33 -> EL3|49-B70;27-1070;60-DF0;3C-E70;22-E36;5B-C50;34-1176 | E35: am | G35: b
C36: {=INDIRECT(E35&G35)} -> EL3|49-B70;27-1070;60-DF0;3C-E70;22-E36;5B-C50;34-1176
A39: Cek Tarik | B39: 1 | C39: =IFERROR(LEN(_xlfn.FORMULATEXT('XL-Test'!D46)),0) -> 11 | D39: =IFERROR(LEN(_xlfn.FORMULATEXT('XL-Test'!E46)),0) -> 11 | E39: =IFERROR(LEN(_xlfn.FORMULATEXT('XL-Test'!F46)),0) -> 12 | F39: =IFERROR(LEN(_xlfn.FORMULATEXT('XL-Test'!G46)),0) -> 43 | G39: =IFERROR(LEN(_xlfn.FORMULATEXT('XL-Test'!H46)),0) -> 96 | H39: =IFERROR(LEN(_xlfn.FORMULATEXT('XL-Test'!I46)),0) -> 115 | I39: =IFERROR(LEN(_xlfn.FORMULATEXT('XL-Test'!K46)),0) -> 56
B40: 2 | C40: =IFERROR(LEN(_xlfn.FORMULATEXT('XL-Test'!D47)),0) -> 11 | D40: =IFERROR(LEN(_xlfn.FORMULATEXT('XL-Test'!E47)),0) -> 11 | E40: =IFERROR(LEN(_xlfn.FORMULATEXT('XL-Test'!F47)),0) -> 12 | F40: =IFERROR(LEN(_xlfn.FORMULATEXT('XL-Test'!G47)),0) -> 43 | G40: =IFERROR(LEN(_xlfn.FORMULATEXT('XL-Test'!H47)),0) -> 96 | H40: =IFERROR(LEN(_xlfn.FORMULATEXT('XL-Test'!I47)),0) -> 115 | I40: =IFERROR(LEN(_xlfn.FORMULATEXT('XL-Test'!K47)),0) -> 56
B41: 3 | C41: =IFERROR(LEN(_xlfn.FORMULATEXT('XL-Test'!D48)),0) -> 11 | D41: =IFERROR(LEN(_xlfn.FORMULATEXT('XL-Test'!E48)),0) -> 11 | E41: =IFERROR(LEN(_xlfn.FORMULATEXT('XL-Test'!F48)),0) -> 12 | F41: =IFERROR(LEN(_xlfn.FORMULATEXT('XL-Test'!G48)),0) -> 43 | G41: =IFERROR(LEN(_xlfn.FORMULATEXT('XL-Test'!H48)),0) -> 96 | H41: =IFERROR(LEN(_xlfn.FORMULATEXT('XL-Test'!I48)),0) -> 115 | I41: =IFERROR(LEN(_xlfn.FORMULATEXT('XL-Test'!K48)),0) -> 56
B42: 4 | C42: =IFERROR(LEN(_xlfn.FORMULATEXT('XL-Test'!D49)),0) -> 11 | D42: =IFERROR(LEN(_xlfn.FORMULATEXT('XL-Test'!E49)),0) -> 11 | E42: =IFERROR(LEN(_xlfn.FORMULATEXT('XL-Test'!F49)),0) -> 12 | F42: =IFERROR(LEN(_xlfn.FORMULATEXT('XL-Test'!G49)),0) -> 43 | G42: =IFERROR(LEN(_xlfn.FORMULATEXT('XL-Test'!H49)),0) -> 96 | H42: =IFERROR(LEN(_xlfn.FORMULATEXT('XL-Test'!I49)),0) -> 115 | I42: =IFERROR(LEN(_xlfn.FORMULATEXT('XL-Test'!K49)),0) -> 56
B43: 5 | C43: =IFERROR(LEN(_xlfn.FORMULATEXT('XL-Test'!D50)),0) -> 11 | D43: =IFERROR(LEN(_xlfn.FORMULATEXT('XL-Test'!E50)),0) -> 11 | E43: =IFERROR(LEN(_xlfn.FORMULATEXT('XL-Test'!F50)),0) -> 12 | F43: =IFERROR(LEN(_xlfn.FORMULATEXT('XL-Test'!G50)),0) -> 43 | G43: =IFERROR(LEN(_xlfn.FORMULATEXT('XL-Test'!H50)),0) -> 96 | H43: =IFERROR(LEN(_xlfn.FORMULATEXT('XL-Test'!I50)),0) -> 115 | I43: =IFERROR(LEN(_xlfn.FORMULATEXT('XL-Test'!K50)),0) -> 56
B44: 6 | C44: =IFERROR(LEN(_xlfn.FORMULATEXT('XL-Test'!D51)),0) -> 11 | D44: =IFERROR(LEN(_xlfn.FORMULATEXT('XL-Test'!E51)),0) -> 11 | E44: =IFERROR(LEN(_xlfn.FORMULATEXT('XL-Test'!F51)),0) -> 12 | F44: =IFERROR(LEN(_xlfn.FORMULATEXT('XL-Test'!G51)),0) -> 43 | G44: =IFERROR(LEN(_xlfn.FORMULATEXT('XL-Test'!H51)),0) -> 96 | H44: =IFERROR(LEN(_xlfn.FORMULATEXT('XL-Test'!I51)),0) -> 115 | I44: =IFERROR(LEN(_xlfn.FORMULATEXT('XL-Test'!K51)),0) -> 56
B45: 7 | C45: =IFERROR(LEN(_xlfn.FORMULATEXT('XL-Test'!D52)),0) -> 11 | D45: =IFERROR(LEN(_xlfn.FORMULATEXT('XL-Test'!E52)),0) -> 11 | E45: =IFERROR(LEN(_xlfn.FORMULATEXT('XL-Test'!F52)),0) -> 12 | F45: =IFERROR(LEN(_xlfn.FORMULATEXT('XL-Test'!G52)),0) -> 43 | G45: =IFERROR(LEN(_xlfn.FORMULATEXT('XL-Test'!H52)),0) -> 96 | H45: =IFERROR(LEN(_xlfn.FORMULATEXT('XL-Test'!I52)),0) -> 115 | I45: =IFERROR(LEN(_xlfn.FORMULATEXT('XL-Test'!K52)),0) -> 56
B46: 8 | C46: =IFERROR(LEN(_xlfn.FORMULATEXT('XL-Test'!D53)),0) -> 11 | D46: =IFERROR(LEN(_xlfn.FORMULATEXT('XL-Test'!E53)),0) -> 11 | E46: =IFERROR(LEN(_xlfn.FORMULATEXT('XL-Test'!F53)),0) -> 12 | F46: =IFERROR(LEN(_xlfn.FORMULATEXT('XL-Test'!G53)),0) -> 43 | G46: =IFERROR(LEN(_xlfn.FORMULATEXT('XL-Test'!H53)),0) -> 96 | H46: =IFERROR(LEN(_xlfn.FORMULATEXT('XL-Test'!I53)),0) -> 115 | I46: =IFERROR(LEN(_xlfn.FORMULATEXT('XL-Test'!K53)),0) -> 56
B47: 9 | C47: =IFERROR(LEN(_xlfn.FORMULATEXT('XL-Test'!D54)),0) -> 11 | D47: =IFERROR(LEN(_xlfn.FORMULATEXT('XL-Test'!E54)),0) -> 11 | E47: =IFERROR(LEN(_xlfn.FORMULATEXT('XL-Test'!F54)),0) -> 12 | F47: =IFERROR(LEN(_xlfn.FORMULATEXT('XL-Test'!G54)),0) -> 43 | G47: =IFERROR(LEN(_xlfn.FORMULATEXT('XL-Test'!H54)),0) -> 96 | H47: =IFERROR(LEN(_xlfn.FORMULATEXT('XL-Test'!I54)),0) -> 115 | I47: =IFERROR(LEN(_xlfn.FORMULATEXT('XL-Test'!K54)),0) -> 56
B48: 10 | C48: =IFERROR(LEN(_xlfn.FORMULATEXT('XL-Test'!D55)),0) -> 11 | D48: =IFERROR(LEN(_xlfn.FORMULATEXT('XL-Test'!E55)),0) -> 11 | E48: =IFERROR(LEN(_xlfn.FORMULATEXT('XL-Test'!F55)),0) -> 12 | F48: =IFERROR(LEN(_xlfn.FORMULATEXT('XL-Test'!G55)),0) -> 43 | G48: =IFERROR(LEN(_xlfn.FORMULATEXT('XL-Test'!H55)),0) -> 96 | H48: =IFERROR(LEN(_xlfn.FORMULATEXT('XL-Test'!I55)),0) -> 115 | I48: =IFERROR(LEN(_xlfn.FORMULATEXT('XL-Test'!K55)),0) -> 56
B49: 11 | C49: =IFERROR(LEN(_xlfn.FORMULATEXT('XL-Test'!D56)),0) -> 11 | D49: =IFERROR(LEN(_xlfn.FORMULATEXT('XL-Test'!E56)),0) -> 11 | E49: =IFERROR(LEN(_xlfn.FORMULATEXT('XL-Test'!F56)),0) -> 12 | F49: =IFERROR(LEN(_xlfn.FORMULATEXT('XL-Test'!G56)),0) -> 43 | G49: =IFERROR(LEN(_xlfn.FORMULATEXT('XL-Test'!H56)),0) -> 96 | H49: =IFERROR(LEN(_xlfn.FORMULATEXT('XL-Test'!I56)),0) -> 115 | I49: =IFERROR(LEN(_xlfn.FORMULATEXT('XL-Test'!K56)),0) -> 56
B50: 12 | C50: =IFERROR(LEN(_xlfn.FORMULATEXT('XL-Test'!D57)),0) -> 11 | D50: =IFERROR(LEN(_xlfn.FORMULATEXT('XL-Test'!E57)),0) -> 11 | E50: =IFERROR(LEN(_xlfn.FORMULATEXT('XL-Test'!F57)),0) -> 12 | F50: =IFERROR(LEN(_xlfn.FORMULATEXT('XL-Test'!G57)),0) -> 43 | G50: =IFERROR(LEN(_xlfn.FORMULATEXT('XL-Test'!H57)),0) -> 96 | H50: =IFERROR(LEN(_xlfn.FORMULATEXT('XL-Test'!I57)),0) -> 115 | I50: =IFERROR(LEN(_xlfn.FORMULATEXT('XL-Test'!K57)),0) -> 56
...
