Workbook
Name Saya: DF!$C$47
Name kode_jawaban: DF!$C$48

Sheet XL-test
A17: KODE SOAL | C17: SBEE009 | E17: KODE JAWABAN | G17: =kode_jawaban -> EI1|38-A32;3E-31C4;5A-38C7;12-7706F;63-1F8B;5F-1BC6;1C-1168;58-2D2E;19-A9E59;25-3880
A19: Intruksi
B21: Easy Level - Latihan Soal Admin Kredir Perumahan
B23: Soal : | C23: Gunakan Fungsi Excel (Function) untuk menyelsaikan kasus dibawah ini, tidak disarankan menggunakan cara manual
B24: 1 | C24: Isi Luas Tanah berdasarkan Kode dari Table Rumah
B25: 2 | C25: isi Harga Jual berdasarkan Kode dari Table Rumah | H25: Table Kredit
B26: 3 | C26: isi Biaya Ppn berdasarkan Kode dari Table Rumah dikali Harga jual | H26: Kode | I26: RT60 | J26: RT80 | K26: R2L | L26: CL1 | M26: CL2
B27: 4 | C27: isi Total Harga Jual dari Harga Jual ditambah Biaya PPn | H27: Uang Muka | I27: 0.05 | J27: 0.1 | K27: 0.15 | L27: 0.2 | M27: 0.25
B28: 5 | C28: Isi Uang Muka berdasarkan kode dari Table Kredit dikali Harga Jual | H28: Bunga | I28: 0.01 | J28: 0.02 | K28: 0.03 | L28: 0.04 | M28: 0.05
B29: 6 | C29: Pokok Per Bulan didapat dari Harga Jual dikurangi Uang muka dibagi Lama Bulan
B30: 7 | C30: Bunga Per Bulan didapat dari Table Kredit dikali Harga Jual dibagi 12 Bulan | I30: Table Rumah
B31: 8 | C31: Setoran Per Bulan didapat dari Pokok ditambah Bunga | I31: Kode | J31: Luas Tanah | K31: Harga Jual | L31: Biaya PPn
B32: 9 | C32: Total Harga kredit adalah Uang Muka ditambah Biaya PPn ditambah Setoran Selama kredit | I32: RT60 | J32: 60 | K32: 160000000 | L32: 0.025
B33: 10 | C33: Tanggal Lunas didapatkan dari Tanggal Akad ditambah Lama bulan | I33: RT80 | J33: 80 | K33: 190000000 | L33: 0.025
I34: R2L | J34: 100 | K34: 210000000 | L34: 0.03
I35: CL1 | J35: 150 | K35: 250000000 | L35: 0.035
C36: Sudah selesai mengerjakan? | I36: CL2 | J36: 200 | K36: 350000000 | L36: 0.035
C37: kirim Kode Soal dan Kode Jawaban diatas ke alamat : https://belajarexcel.id/xl-test/jawaban untuk mengecek hasilnya
C38: atau klik tombol disamping
B42: DATA PENJUALAN KREDIT PERUMAHAN
B43: PT. BELAJAREXCEL.ID
D45: 1 | E45: 2 | F45: 3 | G45: 4 | I45: 5 | J45: 6 | K45: 7 | L45: 8 | M45: 9 | O45: 10
A46: No | B46: Nama | C46: Kode | D46: Luas Tanah | E46: Harga Jual | F46: Biaya Ppn | G46: Total Harga Jual | H46: Lama Bulan | I46: Uang Muka | J46: Pokok Per bulan | K46: Bunga Per Bulan | L46: Angsuran Per Bulan | M46: Total Harga Kredit | N46: Tanggal Akad | O46: Tanggal Lunas
A47: Contoh | B47: Leni Fitriani | C47: R2L | D47: 100 | E47: 210000000 | F47: 6300000 | G47: 216300000 | H47: 120 | I47: 31500000 | J47: 1487500 | K47: 525000 | L47: 2012500 | M47: 279300000 | N47: 44575 | O47: 48227
A48: 1 | B48: Indri Safitri | C48: CL2 | D48: =VLOOKUP(C48,$I$32:$L$36,2,0) -> 200 | E48: =VLOOKUP(C48,$I$32:$L$36,3,0) -> 350000000 | F48: =VLOOKUP(C48,$I$32:$L$36,4,0)*E48 -> 12250000 | G48: =E48+F48 -> 362250000 | H48: 60 | I48: =HLOOKUP(C48,$I$26:$M$28,2,0)*E48 -> 87500000 | J48: =(E48-I48)/H48 -> 4375000 | K48: =HLOOKUP(C48,$I$26:$M$28,3,0)*E48/12 -> 1458333.3 | L48: =J48+K48 -> 5833333.3 | M48: =sum(J48:K48)*H48+I48+F48 -> 449750000 | N48: 44585 | O48: =EDATE(N48,H48) -> 46411
A49: 2 | B49: Susi Susilawati | C49: RT60 | D49: =VLOOKUP(C49,$I$32:$L$36,2,0) -> 60 | E49: =VLOOKUP(C49,$I$32:$L$36,3,0) -> 160000000 | F49: =VLOOKUP(C49,$I$32:$L$36,4,0)*E49 -> 4000000 | G49: =E49+F49 -> 164000000 | H49: 180 | I49: =HLOOKUP(C49,$I$26:$M$28,2,0)*E49 -> 8000000 | J49: =(E49-I49)/H49 -> 844444.44 | K49: =HLOOKUP(C49,$I$26:$M$28,3,0)*E49/12 -> 133333.33 | L49: =J49+K49 -> 977777.78 | M49: =sum(J49:K49)*H49+I49+F49 -> 188000000 | N49: 44632 | O49: =EDATE(N49,H49) -> 50111
A50: 3 | B50: Hendra Nugraha | C50: CL1 | D50: =VLOOKUP(C50,$I$32:$L$36,2,0) -> 150 | E50: =VLOOKUP(C50,$I$32:$L$36,3,0) -> 250000000 | F50: =VLOOKUP(C50,$I$32:$L$36,4,0)*E50 -> 8750000 | G50: =E50+F50 -> 258750000 | H50: 132 | I50: =HLOOKUP(C50,$I$26:$M$28,2,0)*E50 -> 50000000 | J50: =(E50-I50)/H50 -> 1515151.5 | K50: =HLOOKUP(C50,$I$26:$M$28,3,0)*E50/12 -> 833333.33 | L50: =J50+K50 -> 2348484.8 | M50: =sum(J50:K50)*H50+I50+F50 -> 368750000 | N50: 44614 | O50: =EDATE(N50,H50) -> 48632
A51: 4 | B51: Silvia Ananda | C51: RT80 | D51: =VLOOKUP(C51,$I$32:$L$36,2,0) -> 80 | E51: =VLOOKUP(C51,$I$32:$L$36,3,0) -> 190000000 | F51: =VLOOKUP(C51,$I$32:$L$36,4,0)*E51 -> 4750000 | G51: =E51+F51 -> 194750000 | H51: 156 | I51: =HLOOKUP(C51,$I$26:$M$28,2,0)*E51 -> 19000000 | J51: =(E51-I51)/H51 -> 1096153.8 | K51: =HLOOKUP(C51,$I$26:$M$28,3,0)*E51/12 -> 316666.67 | L51: =J51+K51 -> 1412820.5 | M51: =sum(J51:K51)*H51+I51+F51 -> 244150000 | N51: 44678 | O51: =EDATE(N51,H51) -> 49426
A52: 5 | B52: Lina Nurlaela | C52: R2L | D52: =VLOOKUP(C52,$I$32:$L$36,2,0) -> 100 | E52: =VLOOKUP(C52,$I$32:$L$36,3,0) -> 210000000 | F52: =VLOOKUP(C52,$I$32:$L$36,4,0)*E52 -> 6300000 | G52: =E52+F52 -> 216300000 | H52: 144 | I52: =HLOOKUP(C52,$I$26:$M$28,2,0)*E52 -> 31500000 | J52: =(E52-I52)/H52 -> 1239583.3 | K52: =HLOOKUP(C52,$I$26:$M$28,3,0)*E52/12 -> 525000 | L52: =J52+K52 -> 1764583.3 | M52: =sum(J52:K52)*H52+I52+F52 -> 291900000 | N52: 44681 | O52: =EDATE(N52,H52) -> 49064
A53: 6 | B53: Sarah Iskandar | C53: RT60 | D53: =VLOOKUP(C53,$I$32:$L$36,2,0) -> 60 | E53: =VLOOKUP(C53,$I$32:$L$36,3,0) -> 160000000 | F53: =VLOOKUP(C53,$I$32:$L$36,4,0)*E53 -> 4000000 | G53: =E53+F53 -> 164000000 | H53: 48 | I53: =HLOOKUP(C53,$I$26:$M$28,2,0)*E53 -> 8000000 | J53: =(E53-I53)/H53 -> 3166666.7 | K53: =HLOOKUP(C53,$I$26:$M$28,3,0)*E53/12 -> 133333.33 | L53: =J53+K53 -> 3300000 | M53: =sum(J53:K53)*H53+I53+F53 -> 170400000 | N53: 44732 | O53: =EDATE(N53,H53) -> 46193
A54: 7 | B54: Erdian Angga | C54: RT80 | D54: =VLOOKUP(C54,$I$32:$L$36,2,0) -> 80 | E54: =VLOOKUP(C54,$I$32:$L$36,3,0) -> 190000000 | F54: =VLOOKUP(C54,$I$32:$L$36,4,0)*E54 -> 4750000 | G54: =E54+F54 -> 194750000 | H54: 96 | I54: =HLOOKUP(C54,$I$26:$M$28,2,0)*E54 -> 19000000 | J54: =(E54-I54)/H54 -> 1781250 | K54: =HLOOKUP(C54,$I$26:$M$28,3,0)*E54/12 -> 316666.67 | L54: =J54+K54 -> 2097916.7 | M54: =sum(J54:K54)*H54+I54+F54 -> 225150000 | N54: 44747 | O54: =EDATE(N54,H54) -> 47669
A55: 8 | B55: Novi Navisa | C55: CL2 | D55: =VLOOKUP(C55,$I$32:$L$36,2,0) -> 200 | E55: =VLOOKUP(C55,$I$32:$L$36,3,0) -> 350000000 | F55: =VLOOKUP(C55,$I$32:$L$36,4,0)*E55 -> 12250000 | G55: =E55+F55 -> 362250000 | H55: 168 | I55: =HLOOKUP(C55,$I$26:$M$28,2,0)*E55 -> 87500000 | J55: =(E55-I55)/H55 -> 1562500 | K55: =HLOOKUP(C55,$I$26:$M$28,3,0)*E55/12 -> 1458333.3 | L55: =J55+K55 -> 3020833.3 | M55: =sum(J55:K55)*H55+I55+F55 -> 607250000 | N55: 44801 | O55: =EDATE(N55,H55) -> 49915
A56: 9 | B56: Setiadi Budiman | C56: CL1 | D56: =VLOOKUP(C56,$I$32:$L$36,2,0) -> 150 | E56: =VLOOKUP(C56,$I$32:$L$36,3,0) -> 250000000 | F56: =VLOOKUP(C56,$I$32:$L$36,4,0)*E56 -> 8750000 | G56: =E56+F56 -> 258750000 | H56: 108 | I56: =HLOOKUP(C56,$I$26:$M$28,2,0)*E56 -> 50000000 | J56: =(E56-I56)/H56 -> 1851851.9 | K56: =HLOOKUP(C56,$I$26:$M$28,3,0)*E56/12 -> 833333.33 | L56: =J56+K56 -> 2685185.2 | M56: =sum(J56:K56)*H56+I56+F56 -> 348750000 | N56: 44809 | O56: =EDATE(N56,H56) -> 48096
A57: 10 | B57: Agus Somantri | C57: R2L | D57: =VLOOKUP(C57,$I$32:$L$36,2,0) -> 100 | E57: =VLOOKUP(C57,$I$32:$L$36,3,0) -> 210000000 | F57: =VLOOKUP(C57,$I$32:$L$36,4,0)*E57 -> 6300000 | G57: =E57+F57 -> 216300000 | H57: 77 | I57: =HLOOKUP(C57,$I$26:$M$28,2,0)*E57 -> 31500000 | J57: =(E57-I57)/H57 -> 2318181.8 | K57: =HLOOKUP(C57,$I$26:$M$28,3,0)*E57/12 -> 525000 | L57: =J57+K57 -> 2843181.8 | M57: =sum(J57:K57)*H57+I57+F57 -> 256725000 | N57: 44605 | O57: =EDATE(N57,H57) -> 46947
A58: 11 | B58: Indra Kurniawan | C58: RT80 | D58: =VLOOKUP(C58,$I$32:$L$36,2,0) -> 80 | E58: =VLOOKUP(C58,$I$32:$L$36,3,0) -> 190000000 | F58: =VLOOKUP(C58,$I$32:$L$36,4,0)*E58 -> 4750000 | G58: =E58+F58 -> 194750000 | H58: 150 | I58: =HLOOKUP(C58,$I$26:$M$28,2,0)*E58 -> 19000000 | J58: =(E58-I58)/H58 -> 1140000 | K58: =HLOOKUP(C58,$I$26:$M$28,3,0)*E58/12 -> 316666.67 | L58: =J58+K58 -> 1456666.7 | M58: =sum(J58:K58)*H58+I58+F58 -> 242250000 | N58: 44648 | O58: =EDATE(N58,H58) -> 49215
A59: 12 | B59: Jajang Suhendar | C59: RT80 | D59: =VLOOKUP(C59,$I$32:$L$36,2,0) -> 80 | E59: =VLOOKUP(C59,$I$32:$L$36,3,0) -> 190000000 | F59: =VLOOKUP(C59,$I$32:$L$36,4,0)*E59 -> 4750000 | G59: =E59+F59 -> 194750000 | H59: 240 | I59: =HLOOKUP(C59,$I$26:$M$28,2,0)*E59 -> 19000000 | J59: =(E59-I59)/H59 -> 712500 | K59: =HLOOKUP(C59,$I$26:$M$28,3,0)*E59/12 -> 316666.67 | L59: =J59+K59 -> 1029166.7 | M59: =sum(J59:K59)*H59+I59+F59 -> 270750000 | N59: 44619 | O59: =EDATE(N59,H59) -> 51924
... A63: 16 | B63: Yogas Akbar | C63: RT80 | D63: =VLOOKUP(C63,$I$32:$L$36,2,0) -> 80 | E63: =VLOOKUP(C63,$I$32:$L$36,3,0) -> 190000000 | F63: =VLOOKUP(C63,$I$32:$L$36,4,0)*E63 -> 4750000 | G63: =E63+F63 -> 194750000 | H63: 180 | I63: =HLOOKUP(C63,$I$26:$M$28,2,0)*E63 -> 19000000 | J63: =(E63-I63)/H63 -> 950000 | K63: =HLOOKUP(C63,$I$26:$M$28,3,0)*E63/12 -> 316666.67 | L63: =J63+K63 -> 1266666.7 | M63: =sum(J63:K63)*H63+I63+F63 -> 251750000 | N63: 44771 | O63: =EDATE(N63,H63) -> 50250
A68: Dilarang mengubah Table, Menambah Table Baru atau Menambah Kolom Bantuan !!, Gunakan Table seperti yang sudah di sediakan soal.

Sheet About
I6: XL-TEST adalah platform inovatif yang menyediakan latihan Excel interaktif dengan pemeriksaan otomatis,
I7: sehingga pengguna dapat langsung mengetahui jawaban yang benar maupun salah.
I10: Terdapat 5 Level soal :
J12: Easy Level | L12: (⭐)
J13: Medium Level | L13: (⭐⭐)
J14: Hard Level | L14: (⭐⭐⭐)
J15: Extreme Level | L15: (⭐⭐⭐⭐)
J16: Championship Level | L16: (⭐⭐⭐⭐⭐)
B17: Saya adalah seorang Excel Holic yang percaya bahwa setiap angka memiliki cerita yang bisa ditemukan dengan cara yang tepat. | I17: Free Access
B18: “Excel bukan cuma soal kerjaan tapi juga hobi yang aku nikmati.” | I18: https://belajarexcel.id/xl-test/
B19: Contact :
B20: 🌐 Web | C20: https://setiadi.me
B21: 🪡threads | C21: https://www.threads.com/@andisetiadi
D27: Perlu Video Penjelasan atau Kunci Jawaban ?
D28: Scan barcode atau kunjungi
D29: https://lynk.id/setiadi/page/jawaban-xl-test

Sheet DF
C1: 1 | D1: 2 | E1: 3 | F1: 4 | G1: 5 | H1: 6 | I1: 7 | J1: 8 | K1: 9 | L1: 10 | R1: 1 | S1: 2 | T1: 3 | U1: 4 | V1: 5 | W1: 6 | X1: 7 | Y1: 8 | Z1: 9 | AA1: 10
A2: DEF | B2: 1 | C2: =('XL-test'!D48) -> 200 | D2: =('XL-test'!E48) -> 350000000 | E2: =('XL-test'!F48) -> 12250000 | F2: =('XL-test'!G48) -> 362250000 | G2: =('XL-test'!I48) -> 87500000 | H2: =('XL-test'!J48) -> 4375000 | I2: =('XL-test'!K48) -> 1458333.3 | J2: =('XL-test'!L48) -> 5833333.3 | K2: =('XL-test'!M48) -> 449750000 | L2: =('XL-test'!O48) -> 46411 | Q2: 1 | R2: =FORMULATEXT('XL-test'!D48) -> =VLOOKUP(C48,$I$32:$L$36,2,0) | S2: =FORMULATEXT('XL-test'!E48) -> =VLOOKUP(C48,$I$32:$L$36,3,0) | T2: =FORMULATEXT('XL-test'!F48) -> =VLOOKUP(C48,$I$32:$L$36,4,0)*E48 | U2: =FORMULATEXT('XL-test'!G48) -> =E48+F48 | V2: =FORMULATEXT('XL-test'!I48) -> =HLOOKUP(C48,$I$26:$M$28,2,0)*E48 | W2: =FORMULATEXT('XL-test'!J48) -> =(E48-I48)/H48 | X2: =FORMULATEXT('XL-test'!K48) -> =HLOOKUP(C48,$I$26:$M$28,3,0)*E48/12 | Y2: =FORMULATEXT('XL-test'!L48) -> =J48+K48 | Z2: =FORMULATEXT('XL-test'!M48) -> =sum(J48:K48)*H48+I48+F48 | AA2: =FORMULATEXT('XL-test'!O48) -> =EDATE(N48,H48)
A3: EI1 | B3: 2 | C3: =('XL-test'!D49) -> 60 | D3: =('XL-test'!E49) -> 160000000 | E3: =('XL-test'!F49) -> 4000000 | F3: =('XL-test'!G49) -> 164000000 | G3: =('XL-test'!I49) -> 8000000 | H3: =('XL-test'!J49) -> 844444.44 | I3: =('XL-test'!K49) -> 133333.33 | J3: =('XL-test'!L49) -> 977777.78 | K3: =('XL-test'!M49) -> 188000000 | L3: =('XL-test'!O49) -> 50111 | Q3: 2 | R3: =FORMULATEXT('XL-test'!E48) -> =VLOOKUP(C48,$I$32:$L$36,3,0)
B4: 3 | C4: =('XL-test'!D50) -> 150 | D4: =('XL-test'!E50) -> 250000000 | E4: =('XL-test'!F50) -> 8750000 | F4: =('XL-test'!G50) -> 258750000 | G4: =('XL-test'!I50) -> 50000000 | H4: =('XL-test'!J50) -> 1515151.5 | I4: =('XL-test'!K50) -> 833333.33 | J4: =('XL-test'!L50) -> 2348484.8 | K4: =('XL-test'!M50) -> 368750000 | L4: =('XL-test'!O50) -> 48632 | Q4: 3 | R4: =FORMULATEXT('XL-test'!F48) -> =VLOOKUP(C48,$I$32:$L$36,4,0)*E48
B5: 4 | C5: =('XL-test'!D51) -> 80 | D5: =('XL-test'!E51) -> 190000000 | E5: =('XL-test'!F51) -> 4750000 | F5: =('XL-test'!G51) -> 194750000 | G5: =('XL-test'!I51) -> 19000000 | H5: =('XL-test'!J51) -> 1096153.8 | I5: =('XL-test'!K51) -> 316666.67 | J5: =('XL-test'!L51) -> 1412820.5 | K5: =('XL-test'!M51) -> 244150000 | L5: =('XL-test'!O51) -> 49426 | Q5: 4 | R5: =FORMULATEXT('XL-test'!G48) -> =E48+F48
B6: 5 | C6: =('XL-test'!D52) -> 100 | D6: =('XL-test'!E52) -> 210000000 | E6: =('XL-test'!F52) -> 6300000 | F6: =('XL-test'!G52) -> 216300000 | G6: =('XL-test'!I52) -> 31500000 | H6: =('XL-test'!J52) -> 1239583.3 | I6: =('XL-test'!K52) -> 525000 | J6: =('XL-test'!L52) -> 1764583.3 | K6: =('XL-test'!M52) -> 291900000 | L6: =('XL-test'!O52) -> 49064 | Q6: 5 | R6: =FORMULATEXT('XL-test'!I48) -> =HLOOKUP(C48,$I$26:$M$28,2,0)*E48
B7: 6 | C7: =('XL-test'!D53) -> 60 | D7: =('XL-test'!E53) -> 160000000 | E7: =('XL-test'!F53) -> 4000000 | F7: =('XL-test'!G53) -> 164000000 | G7: =('XL-test'!I53) -> 8000000 | H7: =('XL-test'!J53) -> 3166666.7 | I7: =('XL-test'!K53) -> 133333.33 | J7: =('XL-test'!L53) -> 3300000 | K7: =('XL-test'!M53) -> 170400000 | L7: =('XL-test'!O53) -> 46193 | Q7: 6 | R7: =FORMULATEXT('XL-test'!J48) -> =(E48-I48)/H48
B8: 7 | C8: =('XL-test'!D54) -> 80 | D8: =('XL-test'!E54) -> 190000000 | E8: =('XL-test'!F54) -> 4750000 | F8: =('XL-test'!G54) -> 194750000 | G8: =('XL-test'!I54) -> 19000000 | H8: =('XL-test'!J54) -> 1781250 | I8: =('XL-test'!K54) -> 316666.67 | J8: =('XL-test'!L54) -> 2097916.7 | K8: =('XL-test'!M54) -> 225150000 | L8: =('XL-test'!O54) -> 47669 | Q8: 7 | R8: =FORMULATEXT('XL-test'!K48) -> =HLOOKUP(C48,$I$26:$M$28,3,0)*E48/12
B9: 8 | C9: =('XL-test'!D55) -> 200 | D9: =('XL-test'!E55) -> 350000000 | E9: =('XL-test'!F55) -> 12250000 | F9: =('XL-test'!G55) -> 362250000 | G9: =('XL-test'!I55) -> 87500000 | H9: =('XL-test'!J55) -> 1562500 | I9: =('XL-test'!K55) -> 1458333.3 | J9: =('XL-test'!L55) -> 3020833.3 | K9: =('XL-test'!M55) -> 607250000 | L9: =('XL-test'!O55) -> 49915 | Q9: 8 | R9: =FORMULATEXT('XL-test'!L48) -> =J48+K48
B10: 9 | C10: =('XL-test'!D56) -> 150 | D10: =('XL-test'!E56) -> 250000000 | E10: =('XL-test'!F56) -> 8750000 | F10: =('XL-test'!G56) -> 258750000 | G10: =('XL-test'!I56) -> 50000000 | H10: =('XL-test'!J56) -> 1851851.9 | I10: =('XL-test'!K56) -> 833333.33 | J10: =('XL-test'!L56) -> 2685185.2 | K10: =('XL-test'!M56) -> 348750000 | L10: =('XL-test'!O56) -> 48096 | Q10: 9 | R10: =FORMULATEXT('XL-test'!M48) -> =sum(J48:K48)*H48+I48+F48
B11: 10 | C11: =('XL-test'!D57) -> 100 | D11: =('XL-test'!E57) -> 210000000 | E11: =('XL-test'!F57) -> 6300000 | F11: =('XL-test'!G57) -> 216300000 | G11: =('XL-test'!I57) -> 31500000 | H11: =('XL-test'!J57) -> 2318181.8 | I11: =('XL-test'!K57) -> 525000 | J11: =('XL-test'!L57) -> 2843181.8 | K11: =('XL-test'!M57) -> 256725000 | L11: =('XL-test'!O57) -> 46947 | Q11: 10 | R11: =FORMULATEXT('XL-test'!O48) -> =EDATE(N48,H48)
B12: 11 | C12: =('XL-test'!D58) -> 80 | D12: =('XL-test'!E58) -> 190000000 | E12: =('XL-test'!F58) -> 4750000 | F12: =('XL-test'!G58) -> 194750000 | G12: =('XL-test'!I58) -> 19000000 | H12: =('XL-test'!J58) -> 1140000 | I12: =('XL-test'!K58) -> 316666.67 | J12: =('XL-test'!L58) -> 1456666.7 | K12: =('XL-test'!M58) -> 242250000 | L12: =('XL-test'!O58) -> 49215
B13: 12 | C13: =('XL-test'!D59) -> 80 | D13: =('XL-test'!E59) -> 190000000 | E13: =('XL-test'!F59) -> 4750000 | F13: =('XL-test'!G59) -> 194750000 | G13: =('XL-test'!I59) -> 19000000 | H13: =('XL-test'!J59) -> 712500 | I13: =('XL-test'!K59) -> 316666.67 | J13: =('XL-test'!L59) -> 1029166.7 | K13: =('XL-test'!M59) -> 270750000 | L13: =('XL-test'!O59) -> 51924
B14: 13 | C14: =('XL-test'!D60) -> 150 | D14: =('XL-test'!E60) -> 250000000 | E14: =('XL-test'!F60) -> 8750000 | F14: =('XL-test'!G60) -> 258750000 | G14: =('XL-test'!I60) -> 50000000 | H14: =('XL-test'!J60) -> 877192.98 | I14: =('XL-test'!K60) -> 833333.33 | J14: =('XL-test'!L60) -> 1710526.3 | K14: =('XL-test'!M60) -> 448750000 | L14: =('XL-test'!O60) -> 51620
B15: 14 | C15: =('XL-test'!D61) -> 200 | D15: =('XL-test'!E61) -> 350000000 | E15: =('XL-test'!F61) -> 12250000 | F15: =('XL-test'!G61) -> 362250000 | G15: =('XL-test'!I61) -> 87500000 | H15: =('XL-test'!J61) -> 1151315.8 | I15: =('XL-test'!K61) -> 1458333.3 | J15: =('XL-test'!L61) -> 2609649.1 | K15: =('XL-test'!M61) -> 694750000 | L15: =('XL-test'!O61) -> 51633
B16: 15 | C16: =('XL-test'!D62) -> 200 | D16: =('XL-test'!E62) -> 350000000 | E16: =('XL-test'!F62) -> 12250000 | F16: =('XL-test'!G62) -> 362250000 | G16: =('XL-test'!I62) -> 87500000 | H16: =('XL-test'!J62) -> 1682692.3 | I16: =('XL-test'!K62) -> 1458333.3 | J16: =('XL-test'!L62) -> 3141025.6 | K16: =('XL-test'!M62) -> 589750000 | L16: =('XL-test'!O62) -> 49493
B17: 16 | C17: =('XL-test'!D63) -> 80 | D17: =('XL-test'!E63) -> 190000000 | E17: =('XL-test'!F63) -> 4750000 | F17: =('XL-test'!G63) -> 194750000 | G17: =('XL-test'!I63) -> 19000000 | H17: =('XL-test'!J63) -> 950000 | I17: =('XL-test'!K63) -> 316666.67 | J17: =('XL-test'!L63) -> 1266666.7 | K17: =('XL-test'!M63) -> 251750000 | L17: =('XL-test'!O63) -> 50250
C19: =SUM(C2:C17,C3,C6,C9,C12,C15) -> 2610 | D19: =SUM(D2:D17)/1000000+(D5/100000)+(D9/100000)+(D13/100000)+(D3/100000) -> 12740 | E19: =SUM(E2:E17)/10000+(E5/10000)+(E9/10000)+(E13/10000)+(E3/10000) -> 14535 | F19: =SUM(F2:F17)/10000+(F5/10000)+(F9/10000)+(F13/10000)+(F3/10000) -> 487535 | G19: =SUM(G2:G17)/100000+(G5/100000)+(G9/100000)+(G13/100000)+(G3/100000) -> 8075 | H19: =LEFT(INT(SUM(H2:H17)),4)+RIGHT(INT(SUM(H2:H17)),4) -> 7110 | I19: =LEFT(INT(SUM(I2:I17)),4)+RIGHT(INT(SUM(I2:I17)),4) -> 4456 | J19: =LEFT(INT(SUM(J2:J17)),4)+RIGHT(INT(SUM(J2:J17)),4) -> 11566 | K19: =INT(SUM(K2:K17)/10000+(K5/10000)+(K9/10000)+(K13/10000)+(K3/10000)) -> 695897 | L19: =LEFT(INT(SUM(L2:L17)),4)+RIGHT(INT(SUM(L2:L17)),4) -> 14464
B21: Rnd | C21: 5316 | D21: 5868 | E21: 8566 | F21: 1273 | G21: 9279 | H21: 8761 | I21: 1917 | J21: 7832 | K21: 1429 | L21: 2583
C23: =DEC2HEX(C19) -> A32 | D23: =DEC2HEX(D19) -> 31C4 | E23: =DEC2HEX(E19) -> 38C7 | F23: =DEC2HEX(F19) -> 7706F | G23: =DEC2HEX(G19) -> 1F8B | H23: =DEC2HEX(H19) -> 1BC6 | I23: =DEC2HEX(I19) -> 1168 | J23: =DEC2HEX(J19) -> 2D2E | ... L23: =DEC2HEX(L19) -> 3880
C24: =DEC2HEX(C21) -> 14C4 | D24: =DEC2HEX(D21) -> 16EC | E24: =DEC2HEX(E21) -> 2176 | F24: =DEC2HEX(F21) -> 4F9 | G24: =DEC2HEX(G21) -> 243F | H24: =DEC2HEX(H21) -> 2239 | I24: =DEC2HEX(I21) -> 77D | J24: =DEC2HEX(J21) -> 1E98 | ... L24: =DEC2HEX(L21) -> A17
B26: TRUE | C26: =DEC2HEX(LEFT(C21,2)+COLUMN()) -> 38 | D26: =DEC2HEX(LEFT(D21,2)+COLUMN()) -> 3E | E26: =DEC2HEX(LEFT(E21,2)+COLUMN()) -> 5A | F26: =DEC2HEX(LEFT(F21,2)+COLUMN()) -> 12 | G26: =DEC2HEX(LEFT(G21,2)+COLUMN()) -> 63 | H26: =DEC2HEX(LEFT(H21,2)+COLUMN()) -> 5F | I26: =DEC2HEX(LEFT(I21,2)+COLUMN()) -> 1C | J26: =DEC2HEX(LEFT(J21,2)+COLUMN()) -> 58 | ... L26: =DEC2HEX(LEFT(L21,2)+COLUMN()) -> 25
B27: FALSE | C27: =DEC2HEX(RIGHT(C21,2)+COLUMN()) -> 13 | D27: =DEC2HEX(RIGHT(D21,2)+COLUMN()) -> 48 | E27: =DEC2HEX(RIGHT(E21,2)+COLUMN()) -> 47 | F27: =DEC2HEX(RIGHT(F21,2)+COLUMN()) -> 4F | G27: =DEC2HEX(RIGHT(G21,2)+COLUMN()) -> 56 | H27: =DEC2HEX(RIGHT(H21,2)+COLUMN()) -> 45 | I27: =DEC2HEX(RIGHT(I21,2)+COLUMN()) -> 1A | J27: =DEC2HEX(RIGHT(J21,2)+COLUMN()) -> 2A | ... L27: =DEC2HEX(RIGHT(L21,2)+COLUMN()) -> 5F
B29: Cek Kosong | C29: =NOT(OR(C2=0,C2="")) -> TRUE | D29: =NOT(OR(D2=0,D2="")) -> TRUE | E29: =NOT(OR(E2=0,E2="")) -> TRUE | F29: =NOT(OR(F2=0,F2="")) -> TRUE | G29: =NOT(OR(G2=0,G2="")) -> TRUE | H29: =NOT(OR(H2=0,H2="")) -> TRUE | I29: =NOT(OR(I2=0,I2="")) -> TRUE | J29: =NOT(OR(J2=0,J2="")) -> TRUE | ... L29: =NOT(OR(L2=0,L2="")) -> TRUE
B30: Cek Manual | C30: =AND(ISNUMBER(FIND("=",R2)),ISNUMBER(FIND("(",R2))) -> TRUE | D30: =AND(ISNUMBER(FIND("=",S2)),ISNUMBER(FIND("(",S2))) -> TRUE | E30: =AND(ISNUMBER(FIND("=",T2)),ISNUMBER(FIND("(",T2))) -> TRUE | F30: =AND(ISNUMBER(FIND("=",U2)),ISNUMBER(FIND("+",U2))) -> TRUE | G30: =AND(ISNUMBER(FIND("=",V2)),ISNUMBER(FIND("(",V2))) -> TRUE | H30: =AND(ISNUMBER(FIND("=",W2)),ISNUMBER(FIND("(",W2))) -> TRUE | I30: =AND(ISNUMBER(FIND("=",X2)),ISNUMBER(FIND("(",X2))) -> TRUE | J30: =AND(ISNUMBER(FIND("=",Y2)),ISNUMBER(FIND("+",Y2))) -> TRUE | K30: =AND(ISNUMBER(FIND("=",Z2)),ISNUMBER(FIND("(",Z2))) -> TRUE | L30: =AND(ISNUMBER(FIND("=",AA2)),ISNUMBER(FIND("(",AA2))) -> TRUE
B31: Cek Drag | C31: =C72 -> TRUE | D31: =D72 -> TRUE | E31: =E72 -> TRUE | F31: =F72 -> TRUE | G31: =G72 -> TRUE | H31: =H72 -> TRUE | I31: =I72 -> TRUE | J31: =J72 -> TRUE | ... L31: =L72 -> TRUE
B33: ** V | C33: =AND(C29:C31) -> TRUE | D33: =AND(D29:D31) -> TRUE | E33: =AND(E29:E31) -> TRUE | F33: =AND(F29:F31) -> TRUE | G33: =AND(G29:G31) -> TRUE | H33: =AND(H29:H31) -> TRUE | I33: =AND(I29:I31) -> TRUE | J33: =AND(J29:J31) -> TRUE | ... L33: =AND(L29:L31) -> TRUE
B35: Formula | C35: =OR(ISNUMBER(FIND("LOOK",R2)),ISNUMBER(FIND("VLOOK",R2))) -> TRUE | D35: =OR(ISNUMBER(FIND("LOOK",S2)),ISNUMBER(FIND("VLOOK",S2))) -> TRUE | E35: =OR(ISNUMBER(FIND("LOOK",T2)),ISNUMBER(FIND("VLOOK",T2))) -> TRUE | F35: =OR(ISNUMBER(FIND("SUM",U2)),ISNUMBER(FIND("+",U2))) -> TRUE | G35: =OR(ISNUMBER(FIND("LOOK",V2)),ISNUMBER(FIND("HLOO",V2))) -> TRUE | H35: =AND(ISNUMBER(FIND("/",W2)),ISNUMBER(FIND("-",W2))) -> TRUE | I35: =OR(ISNUMBER(FIND("LOOK",X2)),ISNUMBER(FIND("HLOO",X2))) -> TRUE | J35: =OR(ISNUMBER(FIND("SUM",Y2)),ISNUMBER(FIND("+",Y2))) -> TRUE | K35: =AND(OR(ISNUMBER(FIND("SUM",Z2)),ISNUMBER(FIND("+",Z2))),ISNUMBER(FIND("*",Z2))) -> TRUE | L35: =ISNUMBER(FIND("EDA",AA2)) -> TRUE
B36: Kurung | C36: =IFERROR(LEN(R2)-LEN(SUBSTITUTE(R2,"(","")),99) -> 1 | D36: =IFERROR(LEN(S2)-LEN(SUBSTITUTE(S2,"(","")),99) -> 1 | E36: =IFERROR(LEN(T2)-LEN(SUBSTITUTE(T2,"(","")),99) -> 1 | F36: =IFERROR(LEN(U2)-LEN(SUBSTITUTE(U2,"(","")),99) -> 0 | G36: =IFERROR(LEN(V2)-LEN(SUBSTITUTE(V2,"(","")),99) -> 1 | H36: =IFERROR(LEN(W2)-LEN(SUBSTITUTE(W2,"(","")),99) -> 1 | I36: =IFERROR(LEN(X2)-LEN(SUBSTITUTE(X2,"(","")),99) -> 1 | J36: =IFERROR(LEN(Y2)-LEN(SUBSTITUTE(Y2,"(","")),99) -> 0 | ... L36: =IFERROR(LEN(AA2)-LEN(SUBSTITUTE(AA2,"(","")),99) -> 1
C37: 1 | D37: 1 | E37: 1 | F37: 1 | G37: 1 | H37: 1 | I37: 1 | J37: 1 | K37: 1 | L37: 1
C39: =C36<=C37 -> TRUE | D39: =D36<=D37 -> TRUE | E39: =E36<=E37 -> TRUE | F39: =F36<=F37 -> TRUE | G39: =G36<=G37 -> TRUE | H39: =H36<=H37 -> TRUE | I39: =I36<=I37 -> TRUE | J39: =J36<=J37 -> TRUE | ... L39: =L36<=L37 -> TRUE
B41: **F | C41: =AND(C39,C35) -> TRUE | D41: =AND(D39,D35) -> TRUE | E41: =AND(E39,E35) -> TRUE | F41: =AND(F39,F35) -> TRUE | G41: =AND(G39,G35) -> TRUE | H41: =AND(H39,H35) -> TRUE | I41: =AND(I39,I35) -> TRUE | J41: =AND(J39,J35) -> TRUE | ... L41: =AND(L39,L35) -> TRUE
P43: SA
B44: Nilai | C44: =IF(C41,C26,C27)&"-"&IF(C33,C23,C24)&";" -> 38-A32; | D44: =IF(D41,D26,D27)&"-"&IF(D33,D23,D24)&";" -> 3E-31C4; | E44: =IF(E41,E26,E27)&"-"&IF(E33,E23,E24)&";" -> 5A-38C7; | F44: =IF(F41,F26,F27)&"-"&IF(F33,F23,F24)&";" -> 12-7706F; | G44: =IF(G41,G26,G27)&"-"&IF(G33,G23,G24)&";" -> 63-1F8B; | H44: =IF(H41,H26,H27)&"-"&IF(H33,H23,H24)&";" -> 5F-1BC6; | I44: =IF(I41,I26,I27)&"-"&IF(I33,I23,I24)&";" -> 1C-1168; | J44: =IF(J41,J26,J27)&"-"&IF(J33,J23,J24)&";" -> 58-2D2E; | K44: =IF(K41,K26,K27)&"-"&IF(K33,K23,K24)&";" -> 19-A9E59; | L44: =IF(L41,L26,L27)&"-"&IF(L33,L23,L24) -> 25-3880
B46: Gabung' | C46: =A3&"|"&C44&D44&E44&F44&G44&H44&I44&J44&K44&L44 -> EI1|38-A32;3E-31C4;5A-38C7;12-7706F;63-1F8B;5F-1BC6;1C-1168;58-2D2E;19-A9E59;25-3880
C47: =C46 -> EI1|38-A32;3E-31C4;5A-38C7;12-7706F;63-1F8B;5F-1BC6;1C-1168;58-2D2E;19-A9E59;25-3880 | P47: YA
C48: {=INDIRECT(P43&P47)} -> EI1|38-A32;3E-31C4;5A-38C7;12-7706F;63-1F8B;5F-1BC6;1C-1168;58-2D2E;19-A9E59;25-3880
C50: 1 | D50: 2 | E50: 3 | F50: 4 | G50: 5 | H50: 6 | I50: 7 | J50: 8 | K50: 9 | L50: 10
B51: 1 | C51: =IFERROR(LEN(FORMULATEXT('XL-test'!D48)),0) -> 29 | D51: =IFERROR(LEN(FORMULATEXT('XL-test'!E48)),0) -> 29 | E51: =IFERROR(LEN(FORMULATEXT('XL-test'!F48)),0) -> 33 | F51: =IFERROR(LEN(FORMULATEXT('XL-test'!G48)),0) -> 8 | G51: =IFERROR(LEN(FORMULATEXT('XL-test'!I48)),0) -> 33 | H51: =IFERROR(LEN(FORMULATEXT('XL-test'!J48)),0) -> 14 | I51: =IFERROR(LEN(FORMULATEXT('XL-test'!K48)),0) -> 36 | J51: =IFERROR(LEN(FORMULATEXT('XL-test'!L48)),0) -> 8 | K51: =IFERROR(LEN(FORMULATEXT('XL-test'!M48)),0) -> 25 | L51: =IFERROR(LEN(FORMULATEXT('XL-test'!O48)),0) -> 15
B52: 2 | C52: =IFERROR(LEN(FORMULATEXT('XL-test'!D49)),0) -> 29 | D52: =IFERROR(LEN(FORMULATEXT('XL-test'!E49)),0) -> 29 | E52: =IFERROR(LEN(FORMULATEXT('XL-test'!F49)),0) -> 33 | F52: =IFERROR(LEN(FORMULATEXT('XL-test'!G49)),0) -> 8 | G52: =IFERROR(LEN(FORMULATEXT('XL-test'!I49)),0) -> 33 | H52: =IFERROR(LEN(FORMULATEXT('XL-test'!J49)),0) -> 14 | I52: =IFERROR(LEN(FORMULATEXT('XL-test'!K49)),0) -> 36 | J52: =IFERROR(LEN(FORMULATEXT('XL-test'!L49)),0) -> 8 | K52: =IFERROR(LEN(FORMULATEXT('XL-test'!M49)),0) -> 25 | L52: =IFERROR(LEN(FORMULATEXT('XL-test'!O49)),0) -> 15
...
