Workbook
Name Grid: 'Data Grid'!$C$3:$AF$32
Name HJKOKO: DF!$C$67
Name kode_jawaban: DF!$C$70

Sheet XL-Test
A17: KODE SOAL | C17: SBEX008 | E17: KODE JAWABAN | G17: =kode_jawaban -> XH2|6C-153C;D4-9C8;6F-8C1A;5D-891A;74-164;23-1CED;FE-5D57;10-3049
A19: Intruksi
B21: Extreme Level - Latihan Soal Data Grid
B23: Soal : | C23: Soal ini tidak membutuhkan kolom bantuan, silahkan gunakan fungsi-fungsi Dinamic Array Excel untuk menyelsaikan kasus dibawah ini | J23: Contoh Grid 2x2 dan 4x4
C24: 1 Formula untuk 1 soal, Range Data Grid sudah diberi nama "Grid" jika diperlukan
B25: 1 | C25: Berapa penjumlahan dari masing-masing nilai Dara Grid dari alamat pada kolom List Data gunakan dinamic array
B26: 2 | C26: Berapa pengurangan dari masing-masing nilai Dara Grid dari alamat pada kolom List Data gunakan dinamic array
B27: 3 | C27: Berdasarkan hasil penjumlahan setiap baris pada Data Grid, tampilkan 15 peringkat teratas dari nilai terbesar ke terkecil.
B28: 4 | C28: Berdasarkan hasil penjumlahan setiap kolom pada Data Grid, tampilkan 15 peringkat teratas dari nilai terbesar ke terkecil.
B29: 5 | C29: Hitung banyaknya bilangan genap pada tiap baris di Data Grid, lalu tampilkan 15 peringkat teratas dari jumlah terbanyak.
B30: 6 | C30: Berdasarkan hasil penjumlahan setiap Grid 2×2 Cells (seperti area berwarna pink ) di Data Grid, tampilkan 15 peringkat teratas dari nilai jumlah terbesar.
B31: 7 | C31: Berdasarkan hasil penjumlahan setiap Grid 4×4 Cells (seperti area berwarna hijau ) di Data Grid, tampilkan 15 peringkat teratas dari nilai jumlah terbesar.
B32: 8 | C32: Hitung jumlah nilai diagonal pada Data Grid dari D1 hingga D10 yang ditunjukkan dengan warna kuning.
C33: (Warna kuning hanya untuk mempermudah visual)
C35: Sudah selesai mengerjakan?
C36: kirim Kode Soal dan Kode Jawaban diatas ke alamat : https://belajarexcel.id/xl-test/jawaban untuk mengecek hasilnya
C37: atau klik tombol disamping
C43: Hanya untuk Soal 1 dan 2 | D43: 1 | E43: 2 | F43: 3 | G43: 4 | H43: 5 | I43: 6 | J43: 7 | K43: 8
B44: No | C44: List Data | D44: Penjumlahan | E44: Pengurangan | F44: Jumlah Terbesar (Baris) | G44: Jumlah Terbesar (Kolom) | H44: Banyak Genap (Baris) | I44: Jumlah Grid 2x2 | J44: Jumlah Grid 4x4 | K44: Jumlah Diagonal
B45: 1 | C45: U19;D6;L23;J12;N27;N25 | D45: {=_xlfn.BYROW(C45:C59,_xlfn.LAMBDA(_xlpm.a,SUM(INDIRECT("'Data Grid'!"&_xlfn.TEXTSPLIT(_xlpm.a,";")))))} -> 257 | E45: {=_xlfn.BYROW(C45:C59,_xlfn.LAMBDA(_xlpm.a,_xlfn.LET(_xlpm.v,INDIRECT("'Data Grid'!"&_xlfn.TEXTSPLIT(_xlpm.a,";")),2*INDEX(_xlpm.v,1)-SUM(_xlpm.v))))} -> -143 | F45: {=_xlfn.TAKE(_xlfn._xlws.SORT(_xlfn.BYROW(Grid,_xlfn.LAMBDA(_xlpm.r,SUM(_xlpm.r))),,-1),15)} -> 1768 | G45: {=LARGE(_xlfn.BYCOL(Grid,_xlfn.LAMBDA(_xlpm.k,SUM(_xlpm.k))),_xlfn.SEQUENCE(15))} -> 1839 | H45: {=LARGE(_xlfn.BYROW(Grid,_xlfn.LAMBDA(_xlpm.b,SUM(1-MOD(_xlpm.b,2)))),_xlfn.SEQUENCE(15))} -> 19 | I45: {=LARGE(_xlfn.MAKEARRAY(ROWS(Grid)-1,COLUMNS(Grid)-1,_xlfn.LAMBDA(_xlpm.r,_xlpm.c,SUM(INDEX(Grid,_xlpm.r,_xlpm.c):INDEX(Grid,_xlpm.r+1,_xlpm.c+1)))),_xlfn.SEQUENCE(15))} -> 367 | J45: {=LARGE(_xlfn.MAKEARRAY(ROWS(Grid)-3,COLUMNS(Grid)-3,_xlfn.LAMBDA(_xlpm.r,_xlpm.c,SUM(INDEX(Grid,_xlpm.r,_xlpm.c):INDEX(Grid,_xlpm.r+3,_xlpm.c+3)))),_xlfn.SEQUENCE(15))} -> 1154 | K45: {=_xlfn.MAP({1;2;3;4;5;6;7;8;9;10},_xlfn.LAMBDA(_xlpm.i,_xlfn.LET(_xlpm.r,_xlpm.i-1,_xlpm.s,30-_xlpm.r*3,SUM(_xlfn.TAKE(_xlfn.DROP(Grid,_xlpm.r*3),_xlpm.s,_xlpm.s)*_xlfn.MUNIT(_xlpm.s)))))} -> 1542 | L45: << Area Jawaban
B46: 2 | C46: AE8;W19;X11 | D46: 138 | E46: -22 | F46: 1701 | G46: 1765 | H46: 18 | I46: 361 | J46: 1109 | K46: 1341
B47: 3 | C47: AF4;I3;AB19;AB12 | D47: 355 | E47: -165 | F47: 1700 | G47: 1730 | H47: 18 | I47: 357 | J47: 1108 | K47: 1203
B48: 4 | C48: E29;D7;R12;AE26 | D48: 268 | E48: -94 | F48: 1686 | G48: 1659 | H48: 17 | I48: 349 | J48: 1104 | K48: 1022
B49: 5 | C49: J4;C25;W5;H24 | D49: 215 | E49: -89 | F49: 1676 | G49: 1639 | H49: 17 | I49: 347 | J49: 1102 | K49: 908
B50: 6 | C50: J30;N12;AF24;AB8;R16;O8 | D50: 195 | E50: -65 | F50: 1641 | G50: 1616 | H50: 16 | I50: 344 | J50: 1098 | K50: 688
B51: 7 | C51: AB6;W13;U8;D21;AE14 | D51: 327 | E51: -161 | F51: 1633 | G51: 1564 | H51: 16 | I51: 339 | J51: 1092 | K51: 607
B52: 8 | C52: H6;G14;M16;U29;P15 | D52: 230 | E52: -190 | F52: 1628 | G52: 1561 | H52: 16 | I52: 330 | J52: 1089 | K52: 376
B53: 9 | C53: U15;K13;AC6;H17;S17 | D53: 178 | E53: -104 | F53: 1617 | G53: 1555 | H53: 16 | I53: 329 | J53: 1082 | K53: 336
B54: 10 | C54: K15;AF12;O16;U23 | D54: 177 | E54: 7 | F54: 1614 | G54: 1543 | H54: 16 | I54: 327 | J54: 1074 | K54: 124
B55: 11 | C55: P14;K14;D7;Z16;F8 | D55: 316 | E55: -182 | F55: 1594 | G55: 1539 | H55: 15 | I55: 326 | J55: 1068
B56: 12 | C56: J19;O13;P11;AA23 | D56: 300 | E56: -116 | F56: 1593 | G56: 1528 | H56: 15 | I56: 324 | J56: 1068
B57: 13 | C57: D27;I22;E9;R11;M13;K29;V14 | D57: 289 | E57: -249 | F57: 1592 | G57: 1509 | H57: 15 | I57: 322 | J57: 1064
B58: 14 | C58: AE12;E21;E14;Y11;G26;P5;E17 | D58: 429 | E58: -245 | F58: 1554 | G58: 1494 | H58: 15 | I58: 321 | J58: 1056
B59: 15 | C59: U4;Z31;L10 | D59: 123 | E59: 63 | F59: 1523 | G59: 1483 | H59: 15 | I59: 318 | J59: 1054
A62: Dilarang mengubah Table atau Menambah Table Baru atau Menambah Kolom Bantuan !!, Gunakan Table seperti yang sudah di sediakan soal.

Sheet Data Grid
C1: =SUBSTITUTE(ADDRESS(1,COLUMN(C1),4),1,"") -> C | D1: =SUBSTITUTE(ADDRESS(1,COLUMN(D1),4),1,"") -> D | E1: =SUBSTITUTE(ADDRESS(1,COLUMN(E1),4),1,"") -> E | F1: =SUBSTITUTE(ADDRESS(1,COLUMN(F1),4),1,"") -> F | G1: =SUBSTITUTE(ADDRESS(1,COLUMN(G1),4),1,"") -> G | H1: =SUBSTITUTE(ADDRESS(1,COLUMN(H1),4),1,"") -> H | I1: =SUBSTITUTE(ADDRESS(1,COLUMN(I1),4),1,"") -> I | J1: =SUBSTITUTE(ADDRESS(1,COLUMN(J1),4),1,"") -> J | ... AF1: =SUBSTITUTE(ADDRESS(1,COLUMN(AF1),4),1,"") -> AF
A3: 3 | B3: D1 | C3: 43 | D3: 25 | E3: 41 | F3: 66 | G3: 58 | H3: 60 | I3: 90 | J3: 19 | K3: 33 | L3: 33 | M3: 50 | N3: 26 | O3: 66 | P3: 55 | Q3: 81 | R3: 11 | S3: 97 | T3: 93 | U3: 29 | V3: 60 | W3: 47 | X3: 76 | Y3: 15 | Z3: 47 | AA3: 15 | AB3: 27 | AC3: 58 | AD3: 49 | AE3: 94 | AF3: 35
A4: 4 | C4: 84 | D4: 46 | E4: 75 | F4: 30 | G4: 49 | H4: 16 | I4: 1 | J4: 63 | K4: 48 | L4: 21 | M4: 88 | N4: 76 | O4: 46 | P4: 52 | Q4: 89 | R4: 31 | S4: 39 | T4: 86 | U4: 93 | V4: 21 | W4: 74 | X4: 50 | Y4: 74 | Z4: 27 | AA4: 82 | AB4: 61 | AC4: 1 | AD4: 96 | AE4: 3 | AF4: 95
A5: 5 | C5: 37 | D5: 43 | E5: 86 | F5: 20 | G5: 19 | H5: 24 | I5: 89 | J5: 90 | K5: 43 | L5: 30 | M5: 73 | N5: 34 | O5: 2 | P5: 68 | Q5: 59 | R5: 36 | S5: 89 | T5: 88 | U5: 80 | V5: 15 | W5: 65 | X5: 78 | Y5: 31 | Z5: 60 | AA5: 24 | AB5: 4 | AC5: 73 | AD5: 96 | AE5: 35 | AF5: 32
A6: 6 | B6: D2 | C6: 18 | D6: 91 | E6: 83 | F6: 34 | G6: 26 | H6: 20 | I6: 88 | J6: 34 | K6: 77 | L6: 32 | M6: 25 | N6: 63 | O6: 46 | P6: 39 | Q6: 77 | R6: 14 | S6: 44 | T6: 95 | U6: 81 | V6: 1 | W6: 55 | X6: 2 | Y6: 44 | Z6: 45 | AA6: 65 | AB6: 83 | AC6: 26 | AD6: 17 | AE6: 63 | AF6: 22
A7: 7 | C7: 3 | D7: 42 | E7: 8 | F7: 49 | G7: 98 | H7: 25 | I7: 43 | J7: 78 | K7: 25 | L7: 49 | M7: 8 | N7: 90 | O7: 14 | P7: 44 | Q7: 2 | R7: 93 | S7: 38 | T7: 11 | U7: 94 | V7: 31 | W7: 26 | X7: 81 | Y7: 90 | Z7: 44 | AA7: 16 | AB7: 33 | AC7: 69 | AD7: 83 | AE7: 60 | AF7: 27
A8: 8 | C8: 69 | D8: 27 | E8: 8 | F8: 85 | G8: 69 | H8: 7 | I8: 83 | J8: 18 | K8: 98 | L8: 89 | M8: 40 | N8: 48 | O8: 25 | P8: 21 | Q8: 87 | R8: 43 | S8: 25 | T8: 46 | U8: 69 | V8: 36 | W8: 74 | X8: 58 | Y8: 95 | Z8: 89 | AA8: 26 | AB8: 56 | AC8: 82 | AD8: 50 | AE8: 58 | AF8: 12
A9: 9 | B9: D3 | C9: 95 | D9: 67 | E9: 24 | F9: 89 | G9: 43 | H9: 34 | I9: 27 | J9: 51 | K9: 35 | L9: 79 | M9: 1 | N9: 32 | O9: 33 | P9: 52 | Q9: 53 | R9: 16 | S9: 79 | T9: 51 | U9: 91 | V9: 8 | W9: 64 | X9: 3 | Y9: 35 | Z9: 63 | AA9: 39 | AB9: 48 | AC9: 63 | AD9: 86 | AE9: 42 | AF9: 17
A10: 10 | C10: 40 | D10: 54 | E10: 14 | F10: 33 | G10: 10 | H10: 83 | I10: 71 | J10: 26 | K10: 83 | L10: 23 | M10: 1 | N10: 77 | O10: 55 | P10: 61 | Q10: 93 | R10: 17 | S10: 21 | T10: 21 | U10: 40 | V10: 9 | W10: 3 | X10: 28 | Y10: 18 | Z10: 52 | AA10: 1 | AB10: 12 | AC10: 59 | AD10: 25 | AE10: 2 | AF10: 33
A11: 11 | C11: 52 | D11: 12 | E11: 6 | F11: 24 | G11: 63 | H11: 78 | I11: 10 | J11: 93 | K11: 53 | L11: 3 | M11: 41 | N11: 75 | O11: 89 | P11: 45 | Q11: 85 | R11: 13 | S11: 76 | T11: 51 | U11: 89 | V11: 30 | W11: 41 | X11: 44 | Y11: 63 | Z11: 36 | AA11: 26 | AB11: 26 | AC11: 95 | AD11: 8 | AE11: 8 | AF11: 37
A12: 12 | B12: D4 | C12: 72 | D12: 64 | E12: 57 | F12: 49 | G12: 81 | H12: 61 | I12: 1 | J12: 54 | K12: 25 | L12: 7 | M12: 73 | N12: 33 | O12: 71 | P12: 42 | Q12: 2 | R12: 53 | S12: 74 | T12: 61 | U12: 35 | V12: 84 | W12: 87 | X12: 89 | Y12: 90 | Z12: 47 | AA12: 46 | AB12: 85 | AC12: 1 | AD12: 18 | AE12: 92 | AF12: 40
A13: 13 | C13: 15 | D13: 35 | E13: 77 | F13: 11 | G13: 22 | H13: 33 | I13: 92 | J13: 10 | K13: 21 | L13: 56 | M13: 97 | N13: 18 | O13: 91 | P13: 68 | Q13: 59 | R13: 20 | S13: 5 | T13: 61 | U13: 15 | V13: 74 | W13: 34 | X13: 44 | Y13: 81 | Z13: 26 | AA13: 66 | AB13: 9 | AC13: 39 | AD13: 27 | AE13: 14 | AF13: 17
A14: 14 | C14: 11 | D14: 51 | E14: 31 | F14: 66 | G14: 77 | H14: 50 | I14: 51 | J14: 57 | K14: 24 | L14: 54 | M14: 46 | N14: 88 | O14: 88 | P14: 67 | Q14: 27 | R14: 65 | S14: 77 | T14: 82 | U14: 79 | V14: 40 | W14: 96 | X14: 70 | Y14: 43 | Z14: 1 | AA14: 77 | AB14: 68 | AC14: 74 | AD14: 19 | AE14: 60 | AF14: 61
A15: 15 | B15: D5 | C15: 10 | D15: 44 | E15: 98 | F15: 6 | G15: 52 | H15: 55 | I15: 49 | J15: 33 | K15: 92 | L15: 32 | M15: 37 | N15: 24 | O15: 67 | P15: 38 | Q15: 26 | R15: 43 | S15: 63 | T15: 75 | U15: 37 | V15: 87 | W15: 80 | X15: 30 | Y15: 79 | Z15: 87 | AA15: 89 | AB15: 42 | AC15: 41 | AD15: 58 | AE15: 76 | AF15: 91
A16: 16 | C16: 21 | D16: 74 | E16: 14 | F16: 73 | G16: 94 | H16: 79 | I16: 58 | J16: 28 | K16: 47 | L16: 10 | M16: 65 | N16: 33 | O16: 15 | P16: 80 | Q16: 7 | R16: 9 | S16: 67 | T16: 39 | U16: 68 | V16: 43 | W16: 41 | X16: 47 | Y16: 26 | Z16: 98 | AA16: 55 | AB16: 93 | AC16: 95 | AD16: 32 | AE16: 49 | AF16: 37
A17: 17 | C17: 62 | D17: 31 | E17: 27 | F17: 7 | G17: 82 | H17: 67 | I17: 69 | J17: 20 | K17: 56 | L17: 35 | M17: 34 | N17: 14 | O17: 94 | P17: 42 | Q17: 93 | R17: 52 | S17: 27 | T17: 95 | U17: 75 | V17: 94 | W17: 43 | X17: 77 | Y17: 43 | Z17: 46 | AA17: 81 | AB17: 17 | AC17: 86 | AD17: 59 | AE17: 11 | AF17: 94
A18: 18 | B18: D6 | C18: 44 | D18: 43 | E18: 29 | F18: 26 | G18: 42 | H18: 32 | I18: 17 | J18: 85 | K18: 57 | L18: 33 | M18: 57 | N18: 2 | O18: 91 | P18: 52 | Q18: 66 | R18: 61 | S18: 92 | T18: 92 | U18: 40 | V18: 95 | W18: 50 | X18: 78 | Y18: 27 | Z18: 58 | AA18: 74 | AB18: 68 | AC18: 52 | AD18: 70 | AE18: 3 | AF18: 56
A19: 19 | C19: 40 | D19: 66 | E19: 15 | F19: 20 | G19: 43 | H19: 14 | I19: 29 | J19: 92 | K19: 2 | L19: 65 | M19: 81 | N19: 51 | O19: 18 | P19: 75 | Q19: 31 | R19: 48 | S19: 71 | T19: 62 | U19: 57 | V19: 85 | W19: 36 | X19: 95 | Y19: 41 | Z19: 83 | AA19: 94 | AB19: 85 | AC19: 19 | AD19: 35 | AE19: 3 | AF19: 7
A20: 20 | C20: 88 | D20: 46 | E20: 83 | F20: 90 | G20: 19 | H20: 75 | I20: 72 | J20: 3 | K20: 4 | L20: 59 | M20: 73 | N20: 65 | O20: 61 | P20: 85 | Q20: 57 | R20: 72 | S20: 6 | T20: 38 | U20: 55 | V20: 84 | W20: 53 | X20: 11 | Y20: 96 | Z20: 62 | AA20: 70 | AB20: 54 | AC20: 80 | AD20: 68 | AE20: 38 | AF20: 19
A21: 21 | B21: D7 | C21: 14 | D21: 81 | E21: 66 | F21: 35 | G21: 19 | H21: 20 | I21: 95 | J21: 28 | K21: 52 | L21: 61 | M21: 56 | N21: 8 | O21: 60 | P21: 46 | Q21: 49 | R21: 55 | S21: 11 | T21: 84 | U21: 19 | V21: 41 | W21: 37 | X21: 1 | Y21: 99 | Z21: 82 | AA21: 85 | AB21: 76 | AC21: 26 | AD21: 77 | AE21: 58 | AF21: 30
A22: 22 | C22: 51 | D22: 1 | E22: 57 | F22: 89 | G22: 96 | H22: 33 | I22: 77 | J22: 88 | K22: 60 | L22: 16 | M22: 83 | N22: 88 | O22: 12 | P22: 4 | Q22: 95 | R22: 28 | S22: 65 | T22: 80 | U22: 97 | V22: 59 | W22: 79 | X22: 35 | Y22: 10 | Z22: 6 | AA22: 34 | AB22: 87 | AC22: 60 | AD22: 9 | AE22: 77 | AF22: 52
A23: 23 | C23: 68 | D23: 77 | E23: 96 | F23: 73 | G23: 41 | H23: 5 | I23: 89 | J23: 39 | K23: 77 | L23: 21 | M23: 70 | N23: 47 | O23: 95 | P23: 93 | Q23: 56 | R23: 8 | S23: 35 | T23: 86 | U23: 30 | V23: 90 | W23: 98 | X23: 38 | Y23: 13 | Z23: 8 | AA23: 72 | AB23: 16 | AC23: 16 | AD23: 38 | AE23: 35 | AF23: 24
A24: 24 | B24: D8 | C24: 20 | D24: 18 | E24: 90 | F24: 98 | G24: 96 | H24: 77 | I24: 35 | J24: 34 | K24: 3 | L24: 8 | M24: 44 | N24: 11 | O24: 59 | P24: 58 | Q24: 80 | R24: 30 | S24: 64 | T24: 27 | U24: 66 | V24: 43 | W24: 31 | X24: 13 | Y24: 34 | Z24: 23 | AA24: 39 | AB24: 87 | AC24: 5 | AD24: 85 | AE24: 45 | AF24: 7
A25: 25 | C25: 10 | D25: 65 | E25: 93 | F25: 86 | G25: 16 | H25: 52 | I25: 19 | J25: 9 | K25: 1 | L25: 47 | M25: 69 | N25: 2 | O25: 9 | P25: 99 | Q25: 47 | R25: 75 | S25: 73 | T25: 49 | U25: 69 | V25: 97 | W25: 12 | X25: 86 | Y25: 14 | Z25: 2 | AA25: 43 | AB25: 55 | AC25: 28 | AD25: 84 | AE25: 30 | AF25: 82
A26: 26 | C26: 54 | D26: 94 | E26: 11 | F26: 73 | G26: 82 | H26: 61 | I26: 82 | J26: 9 | K26: 73 | L26: 14 | M26: 38 | N26: 94 | O26: 78 | P26: 59 | Q26: 22 | R26: 96 | S26: 69 | T26: 82 | U26: 68 | V26: 17 | W26: 44 | X26: 95 | Y26: 31 | Z26: 7 | AA26: 71 | AB26: 44 | AC26: 69 | AD26: 64 | AE26: 86 | AF26: 81
A27: 27 | B27: D9 | C27: 23 | D27: 20 | E27: 82 | F27: 1 | G27: 55 | H27: 74 | I27: 80 | J27: 50 | K27: 87 | L27: 66 | M27: 10 | N27: 32 | O27: 56 | P27: 5 | Q27: 68 | R27: 51 | S27: 2 | T27: 36 | U27: 34 | V27: 59 | W27: 2 | X27: 83 | Y27: 82 | Z27: 57 | AA27: 12 | AB27: 26 | AC27: 16 | AD27: 23 | AE27: 50 | AF27: 95
A28: 28 | C28: 76 | D28: 77 | E28: 68 | F28: 38 | G28: 73 | H28: 46 | I28: 27 | J28: 2 | K28: 88 | L28: 89 | M28: 40 | N28: 47 | O28: 31 | P28: 2 | Q28: 63 | R28: 80 | S28: 45 | T28: 78 | U28: 89 | V28: 79 | W28: 34 | X28: 57 | Y28: 12 | Z28: 39 | AA28: 53 | AB28: 75 | AC28: 41 | AD28: 81 | AE28: 98 | AF28: 48
A29: 29 | C29: 58 | D29: 60 | E29: 87 | F29: 99 | G29: 26 | H29: 32 | I29: 96 | J29: 72 | K29: 18 | L29: 86 | M29: 66 | N29: 12 | O29: 35 | P29: 47 | Q29: 17 | R29: 85 | S29: 44 | T29: 27 | U29: 30 | V29: 89 | W29: 39 | X29: 78 | Y29: 95 | Z29: 80 | AA29: 69 | AB29: 35 | AC29: 1 | AD29: 61 | AE29: 61 | AF29: 96
A30: 30 | B30: D10 | C30: 87 | D30: 27 | E30: 43 | F30: 27 | G30: 83 | H30: 3 | I30: 94 | J30: 65 | K30: 24 | L30: 86 | M30: 28 | N30: 73 | O30: 76 | P30: 35 | Q30: 8 | R30: 36 | S30: 34 | T30: 73 | U30: 58 | V30: 3 | W30: 89 | X30: 94 | Y30: 94 | Z30: 80 | AA30: 29 | AB30: 74 | AC30: 46 | AD30: 93 | AE30: 44 | AF30: 8
A31: 31 | C31: 24 | D31: 36 | E31: 24 | F31: 19 | G31: 84 | H31: 3 | I31: 12 | J31: 54 | K31: 20 | L31: 11 | M31: 47 | N31: 14 | O31: 16 | P31: 15 | Q31: 32 | R31: 77 | S31: 86 | T31: 45 | U31: 16 | V31: 14 | W31: 11 | X31: 55 | Y31: 6 | Z31: 7 | AA31: 27 | AB31: 42 | AC31: 92 | AD31: 24 | AE31: 89 | AF31: 97
A32: 32 | C32: 13 | D32: 24 | E32: 1 | F32: 9 | G32: 21 | H32: 38 | I32: 84 | J32: 29 | K32: 26 | L32: 36 | M32: 14 | N32: 88 | O32: 62 | P32: 26 | Q32: 33 | R32: 32 | S32: 37 | T32: 25 | U32: 62 | V32: 40 | W32: 38 | X32: 63 | Y32: 62 | Z32: 58 | AA32: 29 | AB32: 51 | AC32: 68 | AD32: 81 | AE32: 64 | AF32: 40

Sheet About
I6: XL-TEST adalah platform inovatif yang menyediakan latihan Excel interaktif dengan pemeriksaan otomatis,
I7: sehingga pengguna dapat langsung mengetahui jawaban yang benar maupun salah.
I10: Terdapat 5 Level soal :
J12: Easy Level | L12: (⭐)
J13: Medium Level | L13: (⭐⭐)
J14: Hard Level | L14: (⭐⭐⭐)
J15: Extreme Level | L15: (⭐⭐⭐⭐)
J16: Championship Level | L16: (⭐⭐⭐⭐⭐)
B17: Saya adalah seorang Excel Holic yang percaya bahwa setiap angka memiliki cerita yang bisa ditemukan dengan cara yang tepat. | I17: Free Access
B18: “Excel bukan cuma soal kerjaan tapi juga hobi yang aku nikmati.” | I18: https://belajarexcel.id/xl-test/
B19: Contact :
B20: 🌐 Web | C20: https://setiadi.me
B21: 🪡threads | C21: https://www.threads.com/@andisetiadi
D27: Perlu Video Penjelasan atau Kunci Jawaban ?
D28: Scan barcode atau kunjungi
D29: https://lynk.id/setiadi/page/jawaban-xl-test

Sheet DF
A1: DF | C1: 1 | D1: 2 | E1: 3 | F1: 4 | G1: 5 | H1: 6 | I1: 7 | J1: 8 | O1: 1 | P1: 2 | Q1: 3 | R1: 4 | S1: 5 | T1: 6 | U1: 7 | V1: 8
A2: XH2 | B2: 1 | C2: ='XL-Test'!D45 -> 257 | D2: ='XL-Test'!E45 -> -143 | E2: ='XL-Test'!F45 -> 1768 | F2: ='XL-Test'!G45 -> 1839 | G2: ='XL-Test'!H45 -> 19 | H2: ='XL-Test'!I45 -> 367 | I2: ='XL-Test'!J45 -> 1154 | J2: ='XL-Test'!K45 -> 1542 | N2: 1 | O2: =_xlfn.FORMULATEXT('XL-Test'!D45) -> =BYROW(C45:C59;LAMBDA(a;SUM(INDIRECT("'Data Grid'!"&TEXTSPLIT(a;";"))))) | P2: =_xlfn.FORMULATEXT('XL-Test'!E45) -> =BYROW(C45:C59;LAMBDA(a;LET(v;INDIRECT("'Data Grid'!"&TEXTSPLIT(a;";"));2*INDEX(v;1)-SUM(v)))) | Q2: =_xlfn.FORMULATEXT('XL-Test'!F45) -> =TAKE(SORT(BYROW(Grid;LAMBDA(r;SUM(r)));;-1);15) | R2: =_xlfn.FORMULATEXT('XL-Test'!G45) -> =LARGE(BYCOL(Grid;LAMBDA(k;SUM(k)));SEQUENCE(15)) | S2: =_xlfn.FORMULATEXT('XL-Test'!H45) -> =LARGE(BYROW(Grid;LAMBDA(b;SUM(1-MOD(b;2))));SEQUENCE(15)) | T2: =_xlfn.FORMULATEXT('XL-Test'!I45) -> =LARGE(MAKEARRAY(ROWS(Grid)-1;COLUMNS(Grid)-1;LAMBDA(r;c;SUM(INDEX(Grid;r;c):INDEX(Grid;r+1;c+1))));SEQUENCE(15)) | U2: =_xlfn.FORMULATEXT('XL-Test'!J45) -> =LARGE(MAKEARRAY(ROWS(Grid)-3;COLUMNS(Grid)-3;LAMBDA(r;c;SUM(INDEX(Grid;r;c):INDEX(Grid;r+3;c+3))));SEQUENCE(15)) | V2: =_xlfn.FORMULATEXT('XL-Test'!K45) -> =MAP({1;2;3;4;5;6;7;8;9;10};LAMBDA(i;LET(r;i-1;s;30-r*3;SUM(TAKE(DROP(Grid;r*3);s;s)*MUNIT(s)))))
B3: 2 | C3: ='XL-Test'!D46 -> 138 | D3: ='XL-Test'!E46 -> -22 | E3: ='XL-Test'!F46 -> 1701 | F3: ='XL-Test'!G46 -> 1765 | G3: ='XL-Test'!H46 -> 18 | H3: ='XL-Test'!I46 -> 361 | I3: ='XL-Test'!J46 -> 1109 | J3: ='XL-Test'!K46 -> 1341 | N3: 2 | O3: =_xlfn.FORMULATEXT('XL-Test'!E45) -> =BYROW(C45:C59;LAMBDA(a;LET(v;INDIRECT("'Data Grid'!"&TEXTSPLIT(a;";"));2*INDEX(v;1)-SUM(v))))
B4: 3 | C4: ='XL-Test'!D47 -> 355 | D4: ='XL-Test'!E47 -> -165 | E4: ='XL-Test'!F47 -> 1700 | F4: ='XL-Test'!G47 -> 1730 | G4: ='XL-Test'!H47 -> 18 | H4: ='XL-Test'!I47 -> 357 | I4: ='XL-Test'!J47 -> 1108 | J4: ='XL-Test'!K47 -> 1203 | N4: 3 | O4: =_xlfn.FORMULATEXT('XL-Test'!F45) -> =TAKE(SORT(BYROW(Grid;LAMBDA(r;SUM(r)));;-1);15)
B5: 4 | C5: ='XL-Test'!D48 -> 268 | D5: ='XL-Test'!E48 -> -94 | E5: ='XL-Test'!F48 -> 1686 | F5: ='XL-Test'!G48 -> 1659 | G5: ='XL-Test'!H48 -> 17 | H5: ='XL-Test'!I48 -> 349 | I5: ='XL-Test'!J48 -> 1104 | J5: ='XL-Test'!K48 -> 1022 | N5: 4 | O5: =_xlfn.FORMULATEXT('XL-Test'!G45) -> =LARGE(BYCOL(Grid;LAMBDA(k;SUM(k)));SEQUENCE(15))
B6: 5 | C6: ='XL-Test'!D49 -> 215 | D6: ='XL-Test'!E49 -> -89 | E6: ='XL-Test'!F49 -> 1676 | F6: ='XL-Test'!G49 -> 1639 | G6: ='XL-Test'!H49 -> 17 | H6: ='XL-Test'!I49 -> 347 | I6: ='XL-Test'!J49 -> 1102 | J6: ='XL-Test'!K49 -> 908 | N6: 5 | O6: =_xlfn.FORMULATEXT('XL-Test'!H45) -> =LARGE(BYROW(Grid;LAMBDA(b;SUM(1-MOD(b;2))));SEQUENCE(15))
B7: 6 | C7: ='XL-Test'!D50 -> 195 | D7: ='XL-Test'!E50 -> -65 | E7: ='XL-Test'!F50 -> 1641 | F7: ='XL-Test'!G50 -> 1616 | G7: ='XL-Test'!H50 -> 16 | H7: ='XL-Test'!I50 -> 344 | I7: ='XL-Test'!J50 -> 1098 | J7: ='XL-Test'!K50 -> 688 | N7: 6 | O7: =_xlfn.FORMULATEXT('XL-Test'!I45) -> =LARGE(MAKEARRAY(ROWS(Grid)-1;COLUMNS(Grid)-1;LAMBDA(r;c;SUM(INDEX(Grid;r;c):INDEX(Grid;r+1;c+1))));SEQUENCE(15))
B8: 7 | C8: ='XL-Test'!D51 -> 327 | D8: ='XL-Test'!E51 -> -161 | E8: ='XL-Test'!F51 -> 1633 | F8: ='XL-Test'!G51 -> 1564 | G8: ='XL-Test'!H51 -> 16 | H8: ='XL-Test'!I51 -> 339 | I8: ='XL-Test'!J51 -> 1092 | J8: ='XL-Test'!K51 -> 607 | N8: 7 | O8: =_xlfn.FORMULATEXT('XL-Test'!J45) -> =LARGE(MAKEARRAY(ROWS(Grid)-3;COLUMNS(Grid)-3;LAMBDA(r;c;SUM(INDEX(Grid;r;c):INDEX(Grid;r+3;c+3))));SEQUENCE(15))
B9: 8 | C9: ='XL-Test'!D52 -> 230 | D9: ='XL-Test'!E52 -> -190 | E9: ='XL-Test'!F52 -> 1628 | F9: ='XL-Test'!G52 -> 1561 | G9: ='XL-Test'!H52 -> 16 | H9: ='XL-Test'!I52 -> 330 | I9: ='XL-Test'!J52 -> 1089 | J9: ='XL-Test'!K52 -> 376 | N9: 8 | O9: =_xlfn.FORMULATEXT('XL-Test'!K45) -> =MAP({1;2;3;4;5;6;7;8;9;10};LAMBDA(i;LET(r;i-1;s;30-r*3;SUM(TAKE(DROP(Grid;r*3);s;s)*MUNIT(s)))))
B10: 9 | C10: ='XL-Test'!D53 -> 178 | D10: ='XL-Test'!E53 -> -104 | E10: ='XL-Test'!F53 -> 1617 | F10: ='XL-Test'!G53 -> 1555 | G10: ='XL-Test'!H53 -> 16 | H10: ='XL-Test'!I53 -> 329 | I10: ='XL-Test'!J53 -> 1082 | J10: ='XL-Test'!K53 -> 336
B11: 10 | C11: ='XL-Test'!D54 -> 177 | D11: ='XL-Test'!E54 -> 7 | E11: ='XL-Test'!F54 -> 1614 | F11: ='XL-Test'!G54 -> 1543 | G11: ='XL-Test'!H54 -> 16 | H11: ='XL-Test'!I54 -> 327 | I11: ='XL-Test'!J54 -> 1074 | J11: ='XL-Test'!K54 -> 124
B12: 11 | C12: ='XL-Test'!D55 -> 316 | D12: ='XL-Test'!E55 -> -182 | E12: ='XL-Test'!F55 -> 1594 | F12: ='XL-Test'!G55 -> 1539 | G12: ='XL-Test'!H55 -> 15 | H12: ='XL-Test'!I55 -> 326 | I12: ='XL-Test'!J55 -> 1068 | J12: ='XL-Test'!K55 -> 0
B13: 12 | C13: ='XL-Test'!D56 -> 300 | D13: ='XL-Test'!E56 -> -116 | E13: ='XL-Test'!F56 -> 1593 | F13: ='XL-Test'!G56 -> 1528 | G13: ='XL-Test'!H56 -> 15 | H13: ='XL-Test'!I56 -> 324 | I13: ='XL-Test'!J56 -> 1068 | J13: ='XL-Test'!K56 -> 0
B14: 13 | C14: ='XL-Test'!D57 -> 289 | D14: ='XL-Test'!E57 -> -249 | E14: ='XL-Test'!F57 -> 1592 | F14: ='XL-Test'!G57 -> 1509 | G14: ='XL-Test'!H57 -> 15 | H14: ='XL-Test'!I57 -> 322 | I14: ='XL-Test'!J57 -> 1064 | J14: ='XL-Test'!K57 -> 0
B15: 14 | C15: ='XL-Test'!D58 -> 429 | D15: ='XL-Test'!E58 -> -245 | E15: ='XL-Test'!F58 -> 1554 | F15: ='XL-Test'!G58 -> 1494 | G15: ='XL-Test'!H58 -> 15 | H15: ='XL-Test'!I58 -> 321 | I15: ='XL-Test'!J58 -> 1056 | J15: ='XL-Test'!K58 -> 0
B16: 15 | C16: ='XL-Test'!D59 -> 123 | D16: ='XL-Test'!E59 -> 63 | E16: ='XL-Test'!F59 -> 1523 | F16: ='XL-Test'!G59 -> 1483 | G16: ='XL-Test'!H59 -> 15 | H16: ='XL-Test'!I59 -> 318 | I16: ='XL-Test'!J59 -> 1054 | J16: ='XL-Test'!K59 -> 0
C19: =SUM(C2:C17)+C3+C5+C8+C10+C12+C14+C16 -> 5436 | D19: =ABS(SUM(D2:D17)+D3+D5+D8+D10+D12+D14+D16) -> 2504 | E19: =SUM(E2:E17)+E3+E5+E8+E10+E12+E14+E16 -> 35866 | F19: =SUM(F2:F17)+F3+F5+F8+F10+F12+F14+F16 -> 35098 | G19: =SUM(G2:G17)+G3+G5+G8+G10+G12+G14+G16 -> 356 | H19: =SUM(H2:H17)+H3+H5+H8+H10+H12+H14+H16 -> 7405 | I19: =SUM(I2:I17)+I3+I5+I8+I10+I12+I14+I16 -> 23895 | J19: =SUM(J2:J17)+J3+J5+J8+J10+J12+J14+J16+J6 -> 12361
C20: =C19 -> 5436 | D20: =D19 -> 2504 | E20: =E19 -> 35866 | F20: =F19 -> 35098 | G20: =G19 -> 356 | H20: =H19 -> 7405 | I20: =I19 -> 23895 | J20: =J19 -> 12361
B22: x | C22: 1740 | D22: 3392 | E22: 1774 | F22: 1496 | G22: 1860 | H22: 9078 | I22: 4070 | J22: 4178
B24: TRUE | C24: =LEFT(DEC2HEX(C22+COLUMN()),2) -> 6C | D24: =LEFT(DEC2HEX(D22+COLUMN()),2) -> D4 | E24: =LEFT(DEC2HEX(E22+COLUMN()),2) -> 6F | F24: =LEFT(DEC2HEX(F22+COLUMN()),2) -> 5D | G24: =LEFT(DEC2HEX(G22+COLUMN()),2) -> 74 | H24: =LEFT(DEC2HEX(H22+COLUMN()),2) -> 23 | I24: =LEFT(DEC2HEX(I22+COLUMN()),2) -> FE | J24: =LEFT(DEC2HEX(J22+COLUMN()),2) -> 10
B25: FALSE | C25: =RIGHT(DEC2HEX(C22+COLUMN()),2) -> CF | D25: =RIGHT(DEC2HEX(D22+COLUMN()),2) -> 44 | E25: =RIGHT(DEC2HEX(E22+COLUMN()),2) -> F3 | F25: =RIGHT(DEC2HEX(F22+COLUMN()),2) -> DE | G25: =RIGHT(DEC2HEX(G22+COLUMN()),2) -> 4B | H25: =RIGHT(DEC2HEX(H22+COLUMN()),2) -> 7E | I25: =RIGHT(DEC2HEX(I22+COLUMN()),2) -> EF | J25: =RIGHT(DEC2HEX(J22+COLUMN()),2) -> 5C
B27: Cek Man | C27: =NOT(OR(C2=0,C2="")) -> TRUE | D27: =NOT(OR(D2=0,D2="")) -> TRUE | E27: =NOT(OR(E2=0,E2="")) -> TRUE | F27: =NOT(OR(F2=0,F2="")) -> TRUE | G27: =NOT(OR(G2=0,G2="")) -> TRUE | H27: =NOT(OR(H2=0,H2="")) -> TRUE | I27: =NOT(OR(I2=0,I2="")) -> TRUE | J27: =NOT(OR(J2=0,J2="")) -> TRUE
B28: Cek For | C28: =AND(ISNUMBER(FIND("=",O2)),ISNUMBER(FIND("(",O2)),ISNUMBER(FIND("Grid",O2))) -> TRUE | D28: =AND(ISNUMBER(FIND("=",P2)),ISNUMBER(FIND("(",P2)),ISNUMBER(FIND("Grid",P2))) -> TRUE | E28: =AND(ISNUMBER(FIND("=",Q2)),ISNUMBER(FIND("(",Q2)),ISNUMBER(FIND("Grid",Q2))) -> TRUE | F28: =AND(ISNUMBER(FIND("=",R2)),ISNUMBER(FIND("(",R2)),ISNUMBER(FIND("Grid",R2))) -> TRUE | G28: =AND(ISNUMBER(FIND("=",S2)),ISNUMBER(FIND("(",S2)),ISNUMBER(FIND("Grid",S2))) -> TRUE | H28: =AND(ISNUMBER(FIND("=",T2)),ISNUMBER(FIND("(",T2)),ISNUMBER(FIND("Grid",T2))) -> TRUE | I28: =AND(ISNUMBER(FIND("=",U2)),ISNUMBER(FIND("(",U2)),ISNUMBER(FIND("Grid",U2))) -> TRUE | J28: =AND(ISNUMBER(FIND("=",V2)),ISNUMBER(FIND("(",V2)),ISNUMBER(FIND("Grid",V2))) -> TRUE
B29: Cek Drag | C29: =C61 -> TRUE | D29: =D61 -> TRUE | E29: =E61 -> TRUE | F29: =F61 -> TRUE | G29: =G61 -> TRUE | H29: =H61 -> TRUE | I29: =I61 -> TRUE | J29: =J61 -> TRUE
B31: Fin** | C31: =AND(C27:C29) -> TRUE | D31: =AND(D27:D29) -> TRUE | E31: =AND(E27:E29) -> TRUE | F31: =AND(F27:F29) -> TRUE | G31: =AND(G27:G29) -> TRUE | H31: =AND(H27:H29) -> TRUE | I31: =AND(I27:I29) -> TRUE | J31: =AND(J27:J29) -> TRUE
B33: Cek F | C33: =AND(ISNUMBER(SEARCH("=",O2)),ISNUMBER(SEARCH("(",O2)),ISERROR(FIND(":F",SUBSTITUTE(O2,"$",""))),ISERROR(FIND(":G",SUBSTITUTE(O2,"$",""))),ISERROR(FIND(":H",SUBSTITUTE(O2,"$",""))),ISERROR(FIND(":M",SUBSTITUTE(O2,"$",""))),ISERROR(FIND(":N",SUBSTITUTE(O2,"$",""))),ISERROR(FIND(":O",SUBSTITUTE(O2,"$","")))) -> TRUE | D33: =AND(ISNUMBER(SEARCH("=",P2)),ISNUMBER(SEARCH("(",P2)),ISERROR(FIND(":F",SUBSTITUTE(P2,"$",""))),ISERROR(FIND(":G",SUBSTITUTE(P2,"$",""))),ISERROR(FIND(":H",SUBSTITUTE(P2,"$",""))),ISERROR(FIND(":M",SUBSTITUTE(P2,"$",""))),ISERROR(FIND(":N",SUBSTITUTE(P2,"$",""))),ISERROR(FIND(":O",SUBSTITUTE(P2,"$","")))) -> TRUE | E33: =AND(ISNUMBER(SEARCH("=",Q2)),ISNUMBER(SEARCH("(",Q2)),ISERROR(FIND(":F",SUBSTITUTE(Q2,"$",""))),ISERROR(FIND(":G",SUBSTITUTE(Q2,"$",""))),ISERROR(FIND(":H",SUBSTITUTE(Q2,"$",""))),ISERROR(FIND(":M",SUBSTITUTE(Q2,"$",""))),ISERROR(FIND(":N",SUBSTITUTE(Q2,"$",""))),ISERROR(FIND(":O",SUBSTITUTE(Q2,"$","")))) -> TRUE | F33: =AND(ISNUMBER(SEARCH("=",R2)),ISNUMBER(SEARCH("(",R2)),ISERROR(FIND(":F",SUBSTITUTE(R2,"$",""))),ISERROR(FIND(":G",SUBSTITUTE(R2,"$",""))),ISERROR(FIND(":H",SUBSTITUTE(R2,"$",""))),ISERROR(FIND(":M",SUBSTITUTE(R2,"$",""))),ISERROR(FIND(":N",SUBSTITUTE(R2,"$",""))),ISERROR(FIND(":O",SUBSTITUTE(R2,"$","")))) -> TRUE | G33: =AND(ISNUMBER(SEARCH("=",S2)),ISNUMBER(SEARCH("(",S2)),ISERROR(FIND(":F",SUBSTITUTE(S2,"$",""))),ISERROR(FIND(":G",SUBSTITUTE(S2,"$",""))),ISERROR(FIND(":H",SUBSTITUTE(S2,"$",""))),ISERROR(FIND(":M",SUBSTITUTE(S2,"$",""))),ISERROR(FIND(":N",SUBSTITUTE(S2,"$",""))),ISERROR(FIND(":O",SUBSTITUTE(S2,"$","")))) -> TRUE | H33: =AND(ISNUMBER(SEARCH("=",T2)),ISNUMBER(SEARCH("(",T2)),ISERROR(FIND(":F",SUBSTITUTE(T2,"$",""))),ISERROR(FIND(":G",SUBSTITUTE(T2,"$",""))),ISERROR(FIND(":H",SUBSTITUTE(T2,"$",""))),ISERROR(FIND(":M",SUBSTITUTE(T2,"$",""))),ISERROR(FIND(":N",SUBSTITUTE(T2,"$",""))),ISERROR(FIND(":O",SUBSTITUTE(T2,"$","")))) -> TRUE | I33: =AND(ISNUMBER(SEARCH("=",U2)),ISNUMBER(SEARCH("(",U2)),ISERROR(FIND(":F",SUBSTITUTE(U2,"$",""))),ISERROR(FIND(":G",SUBSTITUTE(U2,"$",""))),ISERROR(FIND(":H",SUBSTITUTE(U2,"$",""))),ISERROR(FIND(":M",SUBSTITUTE(U2,"$",""))),ISERROR(FIND(":N",SUBSTITUTE(U2,"$",""))),ISERROR(FIND(":O",SUBSTITUTE(U2,"$","")))) -> TRUE | J33: =AND(ISNUMBER(SEARCH("=",V2))) -> TRUE
B37: Cek F | C37: =AND(ISNUMBER(SEARCH("LAMBDA",O2)),ISNUMBER(SEARCH("GRID",O2)),ISNUMBER(FIND("SUM",O2))) -> TRUE | D37: =AND(ISNUMBER(SEARCH("LAMBDA",P2)),ISNUMBER(SEARCH("GRID",P2)),ISNUMBER(FIND("SUM",P2))) -> TRUE | E37: =AND(OR(ISNUMBER(SEARCH("TAKE",Q2)),ISNUMBER(SEARCH("LARGE",Q2)),ISNUMBER(SEARCH("DRO",Q2))),ISNUMBER(SEARCH("GRID",Q2)),ISNUMBER(FIND("SUM",Q2))) -> TRUE | F37: =AND(OR(ISNUMBER(SEARCH("TAKE",R2)),ISNUMBER(SEARCH("LARGE",R2)),ISNUMBER(SEARCH("DRO",R2))),ISNUMBER(SEARCH("GRID",R2)),ISNUMBER(FIND("SUM",R2))) -> TRUE | G37: =AND(OR(ISNUMBER(SEARCH("TAKE",S2)),ISNUMBER(SEARCH("LARGE",S2)),ISNUMBER(SEARCH("DRO",S2))),ISNUMBER(SEARCH("GRID",S2)),ISNUMBER(FIND("SUM",S2))) -> TRUE | H37: =AND(OR(ISNUMBER(SEARCH("TAKE",T2)),ISNUMBER(SEARCH("LARGE",T2)),ISNUMBER(SEARCH("DRO",T2))),ISNUMBER(SEARCH("GRID",T2)),ISNUMBER(FIND("SUM",T2))) -> TRUE | I37: =AND(OR(ISNUMBER(SEARCH("TAKE",U2)),ISNUMBER(SEARCH("LARGE",U2)),ISNUMBER(SEARCH("DRO",U2))),ISNUMBER(SEARCH("GRID",U2)),ISNUMBER(FIND("SUM",U2))) -> TRUE | J37: =AND(ISNUMBER(SEARCH("MUNIT",V2)),ISNUMBER(SEARCH("GRID",V2)),ISNUMBER(FIND("SUM",SUBSTITUTE(V2,"$","")))) -> TRUE
C38: =IFERROR(LEN(O2)-LEN(SUBSTITUTE(O2,"(","")),999) -> 5 | D38: =IFERROR(LEN(P2)-LEN(SUBSTITUTE(P2,"(","")),999) -> 7 | E38: =IFERROR(LEN(Q2)-LEN(SUBSTITUTE(Q2,"(","")),999) -> 5 | F38: =IFERROR(LEN(R2)-LEN(SUBSTITUTE(R2,"(","")),999) -> 5 | G38: =IFERROR(LEN(S2)-LEN(SUBSTITUTE(S2,"(","")),999) -> 6 | H38: =IFERROR(LEN(T2)-LEN(SUBSTITUTE(T2,"(","")),999) -> 9 | I38: =IFERROR(LEN(U2)-LEN(SUBSTITUTE(U2,"(","")),999) -> 9 | J38: =IFERROR(LEN(V2)-LEN(SUBSTITUTE(V2,"(","")),999) -> 7
C39: 9 | D39: 12 | E39: 5 | F39: 6 | G39: 6 | H39: 10 | I39: 10 | J39: 7
C40: =C38<=C39 -> TRUE | D40: =D38<=D39 -> TRUE | E40: =E38<=E39 -> TRUE | F40: =F38<=F39 -> TRUE | G40: =G38<=G39 -> TRUE | H40: =H38<=H39 -> TRUE | I40: =I38<=I39 -> TRUE | J40: =J38<=J39 -> TRUE
B41: ** | C41: =AND(C40,C37) -> TRUE | D41: =AND(D40,D37) -> TRUE | E41: =AND(E40,E37) -> TRUE | F41: =AND(F40,F37) -> TRUE | G41: =AND(G40,G37) -> TRUE | H41: =AND(H40,H37) -> TRUE | I41: =AND(I40,I37) -> TRUE | J41: =AND(J40,J37) -> TRUE
B44: 1 | C44: =IFERROR(LEN(_xlfn.FORMULATEXT('XL-Test'!D45)),0) -> 72 | D44: =IFERROR(LEN(_xlfn.FORMULATEXT('XL-Test'!E45)),0) -> 94 | E44: =IFERROR(LEN(_xlfn.FORMULATEXT('XL-Test'!F45)),0) -> 48 | F44: =IFERROR(LEN(_xlfn.FORMULATEXT('XL-Test'!G45)),0) -> 49 | G44: =IFERROR(LEN(_xlfn.FORMULATEXT('XL-Test'!H45)),0) -> 58 | H44: =IFERROR(LEN(_xlfn.FORMULATEXT('XL-Test'!I45)),0) -> 113 | I44: =IFERROR(LEN(_xlfn.FORMULATEXT('XL-Test'!J45)),0) -> 113 | J44: =IFERROR(LEN(_xlfn.FORMULATEXT('XL-Test'!K45)),0) -> 97
B45: 2 | C45: =IFERROR(LEN(_xlfn.FORMULATEXT('XL-Test'!D46)),0) -> 0 | D45: =IFERROR(LEN(_xlfn.FORMULATEXT('XL-Test'!E46)),0) -> 0 | E45: =IFERROR(LEN(_xlfn.FORMULATEXT('XL-Test'!F46)),0) -> 0 | F45: =IFERROR(LEN(_xlfn.FORMULATEXT('XL-Test'!G46)),0) -> 0 | G45: =IFERROR(LEN(_xlfn.FORMULATEXT('XL-Test'!H46)),0) -> 0 | H45: =IFERROR(LEN(_xlfn.FORMULATEXT('XL-Test'!I46)),0) -> 0 | I45: =IFERROR(LEN(_xlfn.FORMULATEXT('XL-Test'!J46)),0) -> 0 | J45: =IFERROR(LEN(_xlfn.FORMULATEXT('XL-Test'!K46)),0) -> 0
B46: 3 | C46: =IFERROR(LEN(_xlfn.FORMULATEXT('XL-Test'!D47)),0) -> 0 | D46: =IFERROR(LEN(_xlfn.FORMULATEXT('XL-Test'!E47)),0) -> 0 | E46: =IFERROR(LEN(_xlfn.FORMULATEXT('XL-Test'!F47)),0) -> 0 | F46: =IFERROR(LEN(_xlfn.FORMULATEXT('XL-Test'!G47)),0) -> 0 | G46: =IFERROR(LEN(_xlfn.FORMULATEXT('XL-Test'!H47)),0) -> 0 | H46: =IFERROR(LEN(_xlfn.FORMULATEXT('XL-Test'!I47)),0) -> 0 | I46: =IFERROR(LEN(_xlfn.FORMULATEXT('XL-Test'!J47)),0) -> 0 | J46: =IFERROR(LEN(_xlfn.FORMULATEXT('XL-Test'!K47)),0) -> 0
B47: 4 | C47: =IFERROR(LEN(_xlfn.FORMULATEXT('XL-Test'!D48)),0) -> 0 | D47: =IFERROR(LEN(_xlfn.FORMULATEXT('XL-Test'!E48)),0) -> 0 | E47: =IFERROR(LEN(_xlfn.FORMULATEXT('XL-Test'!F48)),0) -> 0 | F47: =IFERROR(LEN(_xlfn.FORMULATEXT('XL-Test'!G48)),0) -> 0 | G47: =IFERROR(LEN(_xlfn.FORMULATEXT('XL-Test'!H48)),0) -> 0 | H47: =IFERROR(LEN(_xlfn.FORMULATEXT('XL-Test'!I48)),0) -> 0 | I47: =IFERROR(LEN(_xlfn.FORMULATEXT('XL-Test'!J48)),0) -> 0 | J47: =IFERROR(LEN(_xlfn.FORMULATEXT('XL-Test'!K48)),0) -> 0
B48: 5 | C48: =IFERROR(LEN(_xlfn.FORMULATEXT('XL-Test'!D49)),0) -> 0 | D48: =IFERROR(LEN(_xlfn.FORMULATEXT('XL-Test'!E49)),0) -> 0 | E48: =IFERROR(LEN(_xlfn.FORMULATEXT('XL-Test'!F49)),0) -> 0 | F48: =IFERROR(LEN(_xlfn.FORMULATEXT('XL-Test'!G49)),0) -> 0 | G48: =IFERROR(LEN(_xlfn.FORMULATEXT('XL-Test'!H49)),0) -> 0 | H48: =IFERROR(LEN(_xlfn.FORMULATEXT('XL-Test'!I49)),0) -> 0 | I48: =IFERROR(LEN(_xlfn.FORMULATEXT('XL-Test'!J49)),0) -> 0 | J48: =IFERROR(LEN(_xlfn.FORMULATEXT('XL-Test'!K49)),0) -> 0
B49: 6 | C49: =IFERROR(LEN(_xlfn.FORMULATEXT('XL-Test'!D50)),0) -> 0 | D49: =IFERROR(LEN(_xlfn.FORMULATEXT('XL-Test'!E50)),0) -> 0 | E49: =IFERROR(LEN(_xlfn.FORMULATEXT('XL-Test'!F50)),0) -> 0 | F49: =IFERROR(LEN(_xlfn.FORMULATEXT('XL-Test'!G50)),0) -> 0 | G49: =IFERROR(LEN(_xlfn.FORMULATEXT('XL-Test'!H50)),0) -> 0 | H49: =IFERROR(LEN(_xlfn.FORMULATEXT('XL-Test'!I50)),0) -> 0 | I49: =IFERROR(LEN(_xlfn.FORMULATEXT('XL-Test'!J50)),0) -> 0 | J49: =IFERROR(LEN(_xlfn.FORMULATEXT('XL-Test'!K50)),0) -> 0
B50: 7 | C50: =IFERROR(LEN(_xlfn.FORMULATEXT('XL-Test'!D51)),0) -> 0 | D50: =IFERROR(LEN(_xlfn.FORMULATEXT('XL-Test'!E51)),0) -> 0 | E50: =IFERROR(LEN(_xlfn.FORMULATEXT('XL-Test'!F51)),0) -> 0 | F50: =IFERROR(LEN(_xlfn.FORMULATEXT('XL-Test'!G51)),0) -> 0 | G50: =IFERROR(LEN(_xlfn.FORMULATEXT('XL-Test'!H51)),0) -> 0 | H50: =IFERROR(LEN(_xlfn.FORMULATEXT('XL-Test'!I51)),0) -> 0 | I50: =IFERROR(LEN(_xlfn.FORMULATEXT('XL-Test'!J51)),0) -> 0 | J50: =IFERROR(LEN(_xlfn.FORMULATEXT('XL-Test'!K51)),0) -> 0 | N50: =HJKOKO -> XH2|6C-153C;D4-9C8;6F-8C1A;5D-891A;74-164;23-1CED;FE-5D57;10-3049
B51: 8 | C51: =IFERROR(LEN(_xlfn.FORMULATEXT('XL-Test'!D52)),0) -> 0 | D51: =IFERROR(LEN(_xlfn.FORMULATEXT('XL-Test'!E52)),0) -> 0 | E51: =IFERROR(LEN(_xlfn.FORMULATEXT('XL-Test'!F52)),0) -> 0 | F51: =IFERROR(LEN(_xlfn.FORMULATEXT('XL-Test'!G52)),0) -> 0 | G51: =IFERROR(LEN(_xlfn.FORMULATEXT('XL-Test'!H52)),0) -> 0 | H51: =IFERROR(LEN(_xlfn.FORMULATEXT('XL-Test'!I52)),0) -> 0 | I51: =IFERROR(LEN(_xlfn.FORMULATEXT('XL-Test'!J52)),0) -> 0 | J51: =IFERROR(LEN(_xlfn.FORMULATEXT('XL-Test'!K52)),0) -> 0
B52: 9 | C52: =IFERROR(LEN(_xlfn.FORMULATEXT('XL-Test'!D53)),0) -> 0 | D52: =IFERROR(LEN(_xlfn.FORMULATEXT('XL-Test'!E53)),0) -> 0 | E52: =IFERROR(LEN(_xlfn.FORMULATEXT('XL-Test'!F53)),0) -> 0 | F52: =IFERROR(LEN(_xlfn.FORMULATEXT('XL-Test'!G53)),0) -> 0 | G52: =IFERROR(LEN(_xlfn.FORMULATEXT('XL-Test'!H53)),0) -> 0 | H52: =IFERROR(LEN(_xlfn.FORMULATEXT('XL-Test'!I53)),0) -> 0 | I52: =IFERROR(LEN(_xlfn.FORMULATEXT('XL-Test'!J53)),0) -> 0 | J52: =IFERROR(LEN(_xlfn.FORMULATEXT('XL-Test'!K53)),0) -> 0
...
