Workbook
Name kode_jawaban: DF!$C$66
Name XGHJ: DF!$C$63

Sheet XL-Test
A17: KODE SOAL | C17: SBEX007 | E17: KODE JAWABAN | G17: =kode_jawaban -> XG2|25-748;21-C6178;1E-F4727;A8-68C;24-723;21-155CC;7F-157C;14-178F4
A19: Intruksi
B21: Extreme Level - Latihan Soal Data Karyawa dan Slip Gaji (Anagram)
H22: Contoh
B23: Soal : | C23: Gunakan Fungsi Excel (Function) untuk menyelsaikan kasus dibawah ini | H23: Normal | I23: Text Normal dari Nama farhan Akbar
B24: 1 | C24: Isi kolom Asal berdasarkan Anagram Nama karyawan dari table Data Pegawai | H24: Farhan Akbar
B25: 2 | C25: Isi kolom Tanggal Lahir berdasarkan Anagram Nama karyawan dari table Data Pegawai
B26: 3 | C26: Isi kolom Tanggal Join berdasarkan Anagram dari Nama karyawan dari table Data Pegawai | H26: Anagram | I26: Anagram adalah permainan kata dengan cara mengacak urutan huruf, tanpa menambah atau mengurangi huruf apa pun.
B27: 4 | C27: Isi kolom Jabatan berdasarkan Anagram dari Nama karyawan, Jabatan adalah sebuah anagram Caesar Cipher | H27: aaFhbArra kn
C28: dimana A menjadi B, B menjadi C dan seterusnya dengan menggeser 1 hurup
B29: 5 | C29: Isi kolom Kode jabatan berdasarkan Jabatan dari Table Gaji | H29: Caesar Cipher | I29: Caesar Cipher menggeeser 1 hurup dari hurup awal, misalnya A menjadi B, B menjdi C dan seterusnya sesuai dengan urutan Kode ANSI
B30: 6 | C30: Isi Gaji Pokok Berdasarkan Jabatan dari Table Gaji, Ubah ke nilai number jika Gaji masih berupa text Exponen | H30: bbGicBssb!lo
B31: 7 | C31: Isi Bonus Berdasarkan Jabatan dari table gaji, Ubah ke nilai number jika Bonus masih berupa text Exponen
B32: 8 | C32: isi kolom Total Gaji dari Gaji Pokok ditambah Bonus | H32: Exponen
H33: G2E5 | I33: G Merupakan Kode Gaji dan 2E5 adalah Exponen
C34: Gunakan table (data pegawai) yang disediakan! | H34: B2E5 | I34: B Merupakan Kode Bonus dan 2E5 adalah Exponen
C36: Sudah selesai mengerjakan? kirim Kode Soal dan Kode Jawaban diatas ke alamat : https://belajarexcel.id/xl-test/jawaban untuk mengecek hasilnya
C37: atau klik tombol disamping
D43: 1 | E43: 2 | F43: 3 | G43: 4 | H43: 5 | I43: 6 | J43: 7 | K43: 8
B44: No | C44: Nama Karyawan | D44: Asal | E44: Tanggal Lahir | F44: Tanggal Join | G44: Kode Jabatan | H44: Jabatan | I44: Gaji Pokok | J44: Bonus | K44: Total Gaji
B45: Contoh | C45: aaFhbArra kn | D45: Denpasar | E45: 31554 | F45: 44528 | G45: SPV | H45: Supervisor | I45: 5000000 | J45: 150000 | K45: 5150000
B47: 1 | C47: imuaPri etlA | D47: {=_xlfn.LET( _xlpm._src,SUBSTITUTE(C47," ",""), _xlpm._key,_xlfn.TEXTJOIN("",TRUE,_xlfn._xlws.SORT(MID(LOWER(_xlpm._src),_xlfn.SEQUENCE(LEN(_xlpm._src)),1))), _xlpm._names,'Data Pegawai'!$A$4:$A$53, _xlpm._keys,_xlfn.BYROW(_xlpm._names,_xlfn.LAMBDA(_xlpm.r,_xlfn.LET(_xlpm._s,SUBSTITUTE(_xlpm.r," ",""),_xlfn.TEXTJOIN("",TRUE,_xlfn._xlws.SORT(MID(LOWER(_xlpm._s),_xlfn.SEQUENCE(LEN(_xlpm._s)),1)))))), _xlfn.XLOOKUP(_xlpm._key,_xlpm._keys,'Data Pegawai'!$B$4:$B$53) )} -> Semarang | E47: {=_xlfn.LET( _xlpm._src,SUBSTITUTE(C47," ",""), _xlpm._key,_xlfn.TEXTJOIN("",TRUE,_xlfn._xlws.SORT(MID(LOWER(_xlpm._src),_xlfn.SEQUENCE(LEN(_xlpm._src)),1))), _xlpm._names,'Data Pegawai'!$A$4:$A$53, _xlpm._keys,_xlfn.BYROW(_xlpm._names,_xlfn.LAMBDA(_xlpm.r,_xlfn.LET(_xlpm._s,SUBSTITUTE(_xlpm.r," ",""),_xlfn.TEXTJOIN("",TRUE,_xlfn._xlws.SORT(MID(LOWER(_xlpm._s),_xlfn.SEQUENCE(LEN(_xlpm._s)),1)))))), _xlfn.XLOOKUP(_xlpm._key,_xlpm._keys,'Data Pegawai'!$C$4:$C$53) )} -> 38606 | F47: {=_xlfn.LET( _xlpm._src,SUBSTITUTE(C47," ",""), _xlpm._key,_xlfn.TEXTJOIN("",TRUE,_xlfn._xlws.SORT(MID(LOWER(_xlpm._src),_xlfn.SEQUENCE(LEN(_xlpm._src)),1))), _xlpm._names,'Data Pegawai'!$A$4:$A$53, _xlpm._keys,_xlfn.BYROW(_xlpm._names,_xlfn.LAMBDA(_xlpm.r,_xlfn.LET(_xlpm._s,SUBSTITUTE(_xlpm.r," ",""),_xlfn.TEXTJOIN("",TRUE,_xlfn._xlws.SORT(MID(LOWER(_xlpm._s),_xlfn.SEQUENCE(LEN(_xlpm._s)),1)))))), _xlfn.XLOOKUP(_xlpm._key,_xlpm._keys,'Data Pegawai'!$D$4:$D$53) )} -> 44871 | G47: {=_xlfn.LET( _xlpm._src,SUBSTITUTE(C47," ",""), _xlpm._key,_xlfn.TEXTJOIN("",TRUE,_xlfn._xlws.SORT(MID(LOWER(_xlpm._src),_xlfn.SEQUENCE(LEN(_xlpm._src)),1))), _xlpm._names,'Data Pegawai'!$A$4:$A$53, _xlpm._keys,_xlfn.BYROW(_xlpm._names,_xlfn.LAMBDA(_xlpm.r,_xlfn.LET(_xlpm._s,SUBSTITUTE(_xlpm.r," ",""),_xlfn.TEXTJOIN("",TRUE,_xlfn._xlws.SORT(MID(LOWER(_xlpm._s),_xlfn.SEQUENCE(LEN(_xlpm._s)),1)))))), _xlpm._cipher,_xlfn.XLOOKUP(_xlpm._key,_xlpm._keys,'Data Pegawai'!$E$4:$E$53), _xlpm._chars,MID(_xlpm._cipher,_xlfn.SEQUENCE(LEN(_xlpm._cipher)),1), _xlpm._decoded,_xlfn.TEXTJOIN("",TRUE,_xlfn.MAP(_xlpm._chars,_xlfn.LAMBDA(_xlpm.c,IF(CODE(_xlpm.c)=33," ",IF(CODE(_xlpm.c)=65,CHAR(90),IF(CODE(_xlpm.c)=97,CHAR(122),IF(OR(AND(CODE(_xlpm.c)>65,CODE(_xlpm.c)<=90),AND(CODE(_xlpm.c)>97,CODE(_xlpm.c)<=122)),CHAR(CODE(_xlpm.c)-1),_xlpm.c))))))), _xlpm._deckey,_xlfn.LET(_xlpm._d,SUBSTITUTE(_xlpm._decoded," ",""),_xlfn.TEXTJOIN("",TRUE,_xlfn._xlws.SORT(MID(LOWER(_xlpm._d),_xlfn.SEQUENCE(LEN(_xlpm._d)),1)))), _xlpm._jabatan,'Data Pegawai'!$J$4:$J$8, _xlpm._jabkeys,_xlfn.BYROW(_xlpm._jabatan,_xlfn.LAMBDA(_xlpm.j,_xlfn.LET(_xlpm._s,SUBSTITUTE(_xlpm.j," ",""),_xlfn.TEXTJOIN("",TRUE,_xlfn._xlws.SORT(MID(LOWER(_xlpm._s),_xlfn.SEQUENCE(LEN(_xlpm._s)),1)))))), _xlfn.XLOOKUP(_xlpm._deckey,_xlpm._jabkeys,'Data Pegawai'!$I$4:$I$8) )} -> ADM | H47: {=_xlfn.LET( _xlpm._src,SUBSTITUTE(C47," ",""), _xlpm._key,_xlfn.TEXTJOIN("",TRUE,_xlfn._xlws.SORT(MID(LOWER(_xlpm._src),_xlfn.SEQUENCE(LEN(_xlpm._src)),1))), _xlpm._names,'Data Pegawai'!$A$4:$A$53, _xlpm._keys,_xlfn.BYROW(_xlpm._names,_xlfn.LAMBDA(_xlpm.r,_xlfn.LET(_xlpm._s,SUBSTITUTE(_xlpm.r," ",""),_xlfn.TEXTJOIN("",TRUE,_xlfn._xlws.SORT(MID(LOWER(_xlpm._s),_xlfn.SEQUENCE(LEN(_xlpm._s)),1)))))), _xlpm._cipher,_xlfn.XLOOKUP(_xlpm._key,_xlpm._keys,'Data Pegawai'!$E$4:$E$53), _xlpm._chars,MID(_xlpm._cipher,_xlfn.SEQUENCE(LEN(_xlpm._cipher)),1), _xlpm._decoded,_xlfn.TEXTJOIN("",TRUE,_xlfn.MAP(_xlpm._chars,_xlfn.LAMBDA(_xlpm.c,IF(CODE(_xlpm.c)=33," ",IF(CODE(_xlpm.c)=65,CHAR(90),IF(CODE(_xlpm.c)=97,CHAR(122),IF(OR(AND(CODE(_xlpm.c)>65,CODE(_xlpm.c)<=90),AND(CODE(_xlpm.c)>97,CODE(_xlpm.c)<=122)),CHAR(CODE(_xlpm.c)-1),_xlpm.c))))))), _xlpm._deckey,_xlfn.LET(_xlpm._d,SUBSTITUTE(_xlpm._decoded," ",""),_xlfn.TEXTJOIN("",TRUE,_xlfn._xlws.SORT(MID(LOWER(_xlpm._d),_xlfn.SEQUENCE(LEN(_xlpm._d)),1)))), _xlpm._jabatan,'Data Pegawai'!$J$4:$J$8, _xlpm._jabkeys,_xlfn.BYROW(_xlpm._jabatan,_xlfn.LAMBDA(_xlpm.j,_xlfn.LET(_xlpm._s,SUBSTITUTE(_xlpm.j," ",""),_xlfn.TEXTJOIN("",TRUE,_xlfn._xlws.SORT(MID(LOWER(_xlpm._s),_xlfn.SEQUENCE(LEN(_xlpm._s)),1)))))), _xlfn.XLOOKUP(_xlpm._deckey,_xlpm._jabkeys,_xlpm._jabatan) )} -> Admin | I47: {=_xlfn.LET( _xlpm._raw,VLOOKUP(H47,'Data Pegawai'!$J$4:$L$8,2,0), _xlpm._e,FIND("E",_xlpm._raw), VALUE(MID(_xlpm._raw,2,_xlpm._e-2))*10^VALUE(RIGHT(_xlpm._raw,LEN(_xlpm._raw)-_xlpm._e)) )} -> 2500000 | J47: {=_xlfn.LET( _xlpm._raw,VLOOKUP(H47,'Data Pegawai'!$J$4:$L$8,3,0), _xlpm._e,FIND("E",_xlpm._raw), VALUE(MID(_xlpm._raw,2,_xlpm._e-2))*10^VALUE(RIGHT(_xlpm._raw,LEN(_xlpm._raw)-_xlpm._e)) )} -> 50000 | K47: =SUM(I47:J47) -> 2550000
B48: 2 | C48: si roAanQni | D48: {=_xlfn.LET( _xlpm._src,SUBSTITUTE(C48," ",""), _xlpm._key,_xlfn.TEXTJOIN("",TRUE,_xlfn._xlws.SORT(MID(LOWER(_xlpm._src),_xlfn.SEQUENCE(LEN(_xlpm._src)),1))), _xlpm._names,'Data Pegawai'!$A$4:$A$53, _xlpm._keys,_xlfn.BYROW(_xlpm._names,_xlfn.LAMBDA(_xlpm.r,_xlfn.LET(_xlpm._s,SUBSTITUTE(_xlpm.r," ",""),_xlfn.TEXTJOIN("",TRUE,_xlfn._xlws.SORT(MID(LOWER(_xlpm._s),_xlfn.SEQUENCE(LEN(_xlpm._s)),1)))))), _xlfn.XLOOKUP(_xlpm._key,_xlpm._keys,'Data Pegawai'!$B$4:$B$53) )} -> Palembang | E48: {=_xlfn.LET( _xlpm._src,SUBSTITUTE(C48," ",""), _xlpm._key,_xlfn.TEXTJOIN("",TRUE,_xlfn._xlws.SORT(MID(LOWER(_xlpm._src),_xlfn.SEQUENCE(LEN(_xlpm._src)),1))), _xlpm._names,'Data Pegawai'!$A$4:$A$53, _xlpm._keys,_xlfn.BYROW(_xlpm._names,_xlfn.LAMBDA(_xlpm.r,_xlfn.LET(_xlpm._s,SUBSTITUTE(_xlpm.r," ",""),_xlfn.TEXTJOIN("",TRUE,_xlfn._xlws.SORT(MID(LOWER(_xlpm._s),_xlfn.SEQUENCE(LEN(_xlpm._s)),1)))))), _xlfn.XLOOKUP(_xlpm._key,_xlpm._keys,'Data Pegawai'!$C$4:$C$53) )} -> 33862 | F48: {=_xlfn.LET( _xlpm._src,SUBSTITUTE(C48," ",""), _xlpm._key,_xlfn.TEXTJOIN("",TRUE,_xlfn._xlws.SORT(MID(LOWER(_xlpm._src),_xlfn.SEQUENCE(LEN(_xlpm._src)),1))), _xlpm._names,'Data Pegawai'!$A$4:$A$53, _xlpm._keys,_xlfn.BYROW(_xlpm._names,_xlfn.LAMBDA(_xlpm.r,_xlfn.LET(_xlpm._s,SUBSTITUTE(_xlpm.r," ",""),_xlfn.TEXTJOIN("",TRUE,_xlfn._xlws.SORT(MID(LOWER(_xlpm._s),_xlfn.SEQUENCE(LEN(_xlpm._s)),1)))))), _xlfn.XLOOKUP(_xlpm._key,_xlpm._keys,'Data Pegawai'!$D$4:$D$53) )} -> 42777 | G48: {=_xlfn.LET( _xlpm._src,SUBSTITUTE(C48," ",""), _xlpm._key,_xlfn.TEXTJOIN("",TRUE,_xlfn._xlws.SORT(MID(LOWER(_xlpm._src),_xlfn.SEQUENCE(LEN(_xlpm._src)),1))), _xlpm._names,'Data Pegawai'!$A$4:$A$53, _xlpm._keys,_xlfn.BYROW(_xlpm._names,_xlfn.LAMBDA(_xlpm.r,_xlfn.LET(_xlpm._s,SUBSTITUTE(_xlpm.r," ",""),_xlfn.TEXTJOIN("",TRUE,_xlfn._xlws.SORT(MID(LOWER(_xlpm._s),_xlfn.SEQUENCE(LEN(_xlpm._s)),1)))))), _xlpm._cipher,_xlfn.XLOOKUP(_xlpm._key,_xlpm._keys,'Data Pegawai'!$E$4:$E$53), _xlpm._chars,MID(_xlpm._cipher,_xlfn.SEQUENCE(LEN(_xlpm._cipher)),1), _xlpm._decoded,_xlfn.TEXTJOIN("",TRUE,_xlfn.MAP(_xlpm._chars,_xlfn.LAMBDA(_xlpm.c,IF(CODE(_xlpm.c)=33," ",IF(CODE(_xlpm.c)=65,CHAR(90),IF(CODE(_xlpm.c)=97,CHAR(122),IF(OR(AND(CODE(_xlpm.c)>65,CODE(_xlpm.c)<=90),AND(CODE(_xlpm.c)>97,CODE(_xlpm.c)<=122)),CHAR(CODE(_xlpm.c)-1),_xlpm.c))))))), _xlpm._deckey,_xlfn.LET(_xlpm._d,SUBSTITUTE(_xlpm._decoded," ",""),_xlfn.TEXTJOIN("",TRUE,_xlfn._xlws.SORT(MID(LOWER(_xlpm._d),_xlfn.SEQUENCE(LEN(_xlpm._d)),1)))), _xlpm._jabatan,'Data Pegawai'!$J$4:$J$8, _xlpm._jabkeys,_xlfn.BYROW(_xlpm._jabatan,_xlfn.LAMBDA(_xlpm.j,_xlfn.LET(_xlpm._s,SUBSTITUTE(_xlpm.j," ",""),_xlfn.TEXTJOIN("",TRUE,_xlfn._xlws.SORT(MID(LOWER(_xlpm._s),_xlfn.SEQUENCE(LEN(_xlpm._s)),1)))))), _xlfn.XLOOKUP(_xlpm._deckey,_xlpm._jabkeys,'Data Pegawai'!$I$4:$I$8) )} -> MKT | H48: {=_xlfn.LET( _xlpm._src,SUBSTITUTE(C48," ",""), _xlpm._key,_xlfn.TEXTJOIN("",TRUE,_xlfn._xlws.SORT(MID(LOWER(_xlpm._src),_xlfn.SEQUENCE(LEN(_xlpm._src)),1))), _xlpm._names,'Data Pegawai'!$A$4:$A$53, _xlpm._keys,_xlfn.BYROW(_xlpm._names,_xlfn.LAMBDA(_xlpm.r,_xlfn.LET(_xlpm._s,SUBSTITUTE(_xlpm.r," ",""),_xlfn.TEXTJOIN("",TRUE,_xlfn._xlws.SORT(MID(LOWER(_xlpm._s),_xlfn.SEQUENCE(LEN(_xlpm._s)),1)))))), _xlpm._cipher,_xlfn.XLOOKUP(_xlpm._key,_xlpm._keys,'Data Pegawai'!$E$4:$E$53), _xlpm._chars,MID(_xlpm._cipher,_xlfn.SEQUENCE(LEN(_xlpm._cipher)),1), _xlpm._decoded,_xlfn.TEXTJOIN("",TRUE,_xlfn.MAP(_xlpm._chars,_xlfn.LAMBDA(_xlpm.c,IF(CODE(_xlpm.c)=33," ",IF(CODE(_xlpm.c)=65,CHAR(90),IF(CODE(_xlpm.c)=97,CHAR(122),IF(OR(AND(CODE(_xlpm.c)>65,CODE(_xlpm.c)<=90),AND(CODE(_xlpm.c)>97,CODE(_xlpm.c)<=122)),CHAR(CODE(_xlpm.c)-1),_xlpm.c))))))), _xlpm._deckey,_xlfn.LET(_xlpm._d,SUBSTITUTE(_xlpm._decoded," ",""),_xlfn.TEXTJOIN("",TRUE,_xlfn._xlws.SORT(MID(LOWER(_xlpm._d),_xlfn.SEQUENCE(LEN(_xlpm._d)),1)))), _xlpm._jabatan,'Data Pegawai'!$J$4:$J$8, _xlpm._jabkeys,_xlfn.BYROW(_xlpm._jabatan,_xlfn.LAMBDA(_xlpm.j,_xlfn.LET(_xlpm._s,SUBSTITUTE(_xlpm.j," ",""),_xlfn.TEXTJOIN("",TRUE,_xlfn._xlws.SORT(MID(LOWER(_xlpm._s),_xlfn.SEQUENCE(LEN(_xlpm._s)),1)))))), _xlfn.XLOOKUP(_xlpm._deckey,_xlpm._jabkeys,_xlpm._jabatan) )} -> Marketing | I48: {=_xlfn.LET( _xlpm._raw,VLOOKUP(H48,'Data Pegawai'!$J$4:$L$8,2,0), _xlpm._e,FIND("E",_xlpm._raw), VALUE(MID(_xlpm._raw,2,_xlpm._e-2))*10^VALUE(RIGHT(_xlpm._raw,LEN(_xlpm._raw)-_xlpm._e)) )} -> 4500000 | J48: {=_xlfn.LET( _xlpm._raw,VLOOKUP(H48,'Data Pegawai'!$J$4:$L$8,3,0), _xlpm._e,FIND("E",_xlpm._raw), VALUE(MID(_xlpm._raw,2,_xlpm._e-2))*10^VALUE(RIGHT(_xlpm._raw,LEN(_xlpm._raw)-_xlpm._e)) )} -> 100000 | K48: =SUM(I48:J48) -> 4600000
B49: 3 | C49: arimtnA adPa | D49: {=_xlfn.LET( _xlpm._src,SUBSTITUTE(C49," ",""), _xlpm._key,_xlfn.TEXTJOIN("",TRUE,_xlfn._xlws.SORT(MID(LOWER(_xlpm._src),_xlfn.SEQUENCE(LEN(_xlpm._src)),1))), _xlpm._names,'Data Pegawai'!$A$4:$A$53, _xlpm._keys,_xlfn.BYROW(_xlpm._names,_xlfn.LAMBDA(_xlpm.r,_xlfn.LET(_xlpm._s,SUBSTITUTE(_xlpm.r," ",""),_xlfn.TEXTJOIN("",TRUE,_xlfn._xlws.SORT(MID(LOWER(_xlpm._s),_xlfn.SEQUENCE(LEN(_xlpm._s)),1)))))), _xlfn.XLOOKUP(_xlpm._key,_xlpm._keys,'Data Pegawai'!$B$4:$B$53) )} -> Surabaya | E49: {=_xlfn.LET( _xlpm._src,SUBSTITUTE(C49," ",""), _xlpm._key,_xlfn.TEXTJOIN("",TRUE,_xlfn._xlws.SORT(MID(LOWER(_xlpm._src),_xlfn.SEQUENCE(LEN(_xlpm._src)),1))), _xlpm._names,'Data Pegawai'!$A$4:$A$53, _xlpm._keys,_xlfn.BYROW(_xlpm._names,_xlfn.LAMBDA(_xlpm.r,_xlfn.LET(_xlpm._s,SUBSTITUTE(_xlpm.r," ",""),_xlfn.TEXTJOIN("",TRUE,_xlfn._xlws.SORT(MID(LOWER(_xlpm._s),_xlfn.SEQUENCE(LEN(_xlpm._s)),1)))))), _xlfn.XLOOKUP(_xlpm._key,_xlpm._keys,'Data Pegawai'!$C$4:$C$53) )} -> 36308 | F49: {=_xlfn.LET( _xlpm._src,SUBSTITUTE(C49," ",""), _xlpm._key,_xlfn.TEXTJOIN("",TRUE,_xlfn._xlws.SORT(MID(LOWER(_xlpm._src),_xlfn.SEQUENCE(LEN(_xlpm._src)),1))), _xlpm._names,'Data Pegawai'!$A$4:$A$53, _xlpm._keys,_xlfn.BYROW(_xlpm._names,_xlfn.LAMBDA(_xlpm.r,_xlfn.LET(_xlpm._s,SUBSTITUTE(_xlpm.r," ",""),_xlfn.TEXTJOIN("",TRUE,_xlfn._xlws.SORT(MID(LOWER(_xlpm._s),_xlfn.SEQUENCE(LEN(_xlpm._s)),1)))))), _xlfn.XLOOKUP(_xlpm._key,_xlpm._keys,'Data Pegawai'!$D$4:$D$53) )} -> 44626 | G49: {=_xlfn.LET( _xlpm._src,SUBSTITUTE(C49," ",""), _xlpm._key,_xlfn.TEXTJOIN("",TRUE,_xlfn._xlws.SORT(MID(LOWER(_xlpm._src),_xlfn.SEQUENCE(LEN(_xlpm._src)),1))), _xlpm._names,'Data Pegawai'!$A$4:$A$53, _xlpm._keys,_xlfn.BYROW(_xlpm._names,_xlfn.LAMBDA(_xlpm.r,_xlfn.LET(_xlpm._s,SUBSTITUTE(_xlpm.r," ",""),_xlfn.TEXTJOIN("",TRUE,_xlfn._xlws.SORT(MID(LOWER(_xlpm._s),_xlfn.SEQUENCE(LEN(_xlpm._s)),1)))))), _xlpm._cipher,_xlfn.XLOOKUP(_xlpm._key,_xlpm._keys,'Data Pegawai'!$E$4:$E$53), _xlpm._chars,MID(_xlpm._cipher,_xlfn.SEQUENCE(LEN(_xlpm._cipher)),1), _xlpm._decoded,_xlfn.TEXTJOIN("",TRUE,_xlfn.MAP(_xlpm._chars,_xlfn.LAMBDA(_xlpm.c,IF(CODE(_xlpm.c)=33," ",IF(CODE(_xlpm.c)=65,CHAR(90),IF(CODE(_xlpm.c)=97,CHAR(122),IF(OR(AND(CODE(_xlpm.c)>65,CODE(_xlpm.c)<=90),AND(CODE(_xlpm.c)>97,CODE(_xlpm.c)<=122)),CHAR(CODE(_xlpm.c)-1),_xlpm.c))))))), _xlpm._deckey,_xlfn.LET(_xlpm._d,SUBSTITUTE(_xlpm._decoded," ",""),_xlfn.TEXTJOIN("",TRUE,_xlfn._xlws.SORT(MID(LOWER(_xlpm._d),_xlfn.SEQUENCE(LEN(_xlpm._d)),1)))), _xlpm._jabatan,'Data Pegawai'!$J$4:$J$8, _xlpm._jabkeys,_xlfn.BYROW(_xlpm._jabatan,_xlfn.LAMBDA(_xlpm.j,_xlfn.LET(_xlpm._s,SUBSTITUTE(_xlpm.j," ",""),_xlfn.TEXTJOIN("",TRUE,_xlfn._xlws.SORT(MID(LOWER(_xlpm._s),_xlfn.SEQUENCE(LEN(_xlpm._s)),1)))))), _xlfn.XLOOKUP(_xlpm._deckey,_xlpm._jabkeys,'Data Pegawai'!$I$4:$I$8) )} -> IT | H49: {=_xlfn.LET( _xlpm._src,SUBSTITUTE(C49," ",""), _xlpm._key,_xlfn.TEXTJOIN("",TRUE,_xlfn._xlws.SORT(MID(LOWER(_xlpm._src),_xlfn.SEQUENCE(LEN(_xlpm._src)),1))), _xlpm._names,'Data Pegawai'!$A$4:$A$53, _xlpm._keys,_xlfn.BYROW(_xlpm._names,_xlfn.LAMBDA(_xlpm.r,_xlfn.LET(_xlpm._s,SUBSTITUTE(_xlpm.r," ",""),_xlfn.TEXTJOIN("",TRUE,_xlfn._xlws.SORT(MID(LOWER(_xlpm._s),_xlfn.SEQUENCE(LEN(_xlpm._s)),1)))))), _xlpm._cipher,_xlfn.XLOOKUP(_xlpm._key,_xlpm._keys,'Data Pegawai'!$E$4:$E$53), _xlpm._chars,MID(_xlpm._cipher,_xlfn.SEQUENCE(LEN(_xlpm._cipher)),1), _xlpm._decoded,_xlfn.TEXTJOIN("",TRUE,_xlfn.MAP(_xlpm._chars,_xlfn.LAMBDA(_xlpm.c,IF(CODE(_xlpm.c)=33," ",IF(CODE(_xlpm.c)=65,CHAR(90),IF(CODE(_xlpm.c)=97,CHAR(122),IF(OR(AND(CODE(_xlpm.c)>65,CODE(_xlpm.c)<=90),AND(CODE(_xlpm.c)>97,CODE(_xlpm.c)<=122)),CHAR(CODE(_xlpm.c)-1),_xlpm.c))))))), _xlpm._deckey,_xlfn.LET(_xlpm._d,SUBSTITUTE(_xlpm._decoded," ",""),_xlfn.TEXTJOIN("",TRUE,_xlfn._xlws.SORT(MID(LOWER(_xlpm._d),_xlfn.SEQUENCE(LEN(_xlpm._d)),1)))), _xlpm._jabatan,'Data Pegawai'!$J$4:$J$8, _xlpm._jabkeys,_xlfn.BYROW(_xlpm._jabatan,_xlfn.LAMBDA(_xlpm.j,_xlfn.LET(_xlpm._s,SUBSTITUTE(_xlpm.j," ",""),_xlfn.TEXTJOIN("",TRUE,_xlfn._xlws.SORT(MID(LOWER(_xlpm._s),_xlfn.SEQUENCE(LEN(_xlpm._s)),1)))))), _xlfn.XLOOKUP(_xlpm._deckey,_xlpm._jabkeys,_xlpm._jabatan) )} -> IT Support | I49: {=_xlfn.LET( _xlpm._raw,VLOOKUP(H49,'Data Pegawai'!$J$4:$L$8,2,0), _xlpm._e,FIND("E",_xlpm._raw), VALUE(MID(_xlpm._raw,2,_xlpm._e-2))*10^VALUE(RIGHT(_xlpm._raw,LEN(_xlpm._raw)-_xlpm._e)) )} -> 3000000 | J49: {=_xlfn.LET( _xlpm._raw,VLOOKUP(H49,'Data Pegawai'!$J$4:$L$8,3,0), _xlpm._e,FIND("E",_xlpm._raw), VALUE(MID(_xlpm._raw,2,_xlpm._e-2))*10^VALUE(RIGHT(_xlpm._raw,LEN(_xlpm._raw)-_xlpm._e)) )} -> 500000 | K49: =SUM(I49:J49) -> 3500000
B50: 4 | C50: him aotlroPaG | D50: {=_xlfn.LET( _xlpm._src,SUBSTITUTE(C50," ",""), _xlpm._key,_xlfn.TEXTJOIN("",TRUE,_xlfn._xlws.SORT(MID(LOWER(_xlpm._src),_xlfn.SEQUENCE(LEN(_xlpm._src)),1))), _xlpm._names,'Data Pegawai'!$A$4:$A$53, _xlpm._keys,_xlfn.BYROW(_xlpm._names,_xlfn.LAMBDA(_xlpm.r,_xlfn.LET(_xlpm._s,SUBSTITUTE(_xlpm.r," ",""),_xlfn.TEXTJOIN("",TRUE,_xlfn._xlws.SORT(MID(LOWER(_xlpm._s),_xlfn.SEQUENCE(LEN(_xlpm._s)),1)))))), _xlfn.XLOOKUP(_xlpm._key,_xlpm._keys,'Data Pegawai'!$B$4:$B$53) )} -> Bandung | E50: {=_xlfn.LET( _xlpm._src,SUBSTITUTE(C50," ",""), _xlpm._key,_xlfn.TEXTJOIN("",TRUE,_xlfn._xlws.SORT(MID(LOWER(_xlpm._src),_xlfn.SEQUENCE(LEN(_xlpm._src)),1))), _xlpm._names,'Data Pegawai'!$A$4:$A$53, _xlpm._keys,_xlfn.BYROW(_xlpm._names,_xlfn.LAMBDA(_xlpm.r,_xlfn.LET(_xlpm._s,SUBSTITUTE(_xlpm.r," ",""),_xlfn.TEXTJOIN("",TRUE,_xlfn._xlws.SORT(MID(LOWER(_xlpm._s),_xlfn.SEQUENCE(LEN(_xlpm._s)),1)))))), _xlfn.XLOOKUP(_xlpm._key,_xlpm._keys,'Data Pegawai'!$C$4:$C$53) )} -> 37155 | F50: {=_xlfn.LET( _xlpm._src,SUBSTITUTE(C50," ",""), _xlpm._key,_xlfn.TEXTJOIN("",TRUE,_xlfn._xlws.SORT(MID(LOWER(_xlpm._src),_xlfn.SEQUENCE(LEN(_xlpm._src)),1))), _xlpm._names,'Data Pegawai'!$A$4:$A$53, _xlpm._keys,_xlfn.BYROW(_xlpm._names,_xlfn.LAMBDA(_xlpm.r,_xlfn.LET(_xlpm._s,SUBSTITUTE(_xlpm.r," ",""),_xlfn.TEXTJOIN("",TRUE,_xlfn._xlws.SORT(MID(LOWER(_xlpm._s),_xlfn.SEQUENCE(LEN(_xlpm._s)),1)))))), _xlfn.XLOOKUP(_xlpm._key,_xlpm._keys,'Data Pegawai'!$D$4:$D$53) )} -> 44109 | G50: {=_xlfn.LET( _xlpm._src,SUBSTITUTE(C50," ",""), _xlpm._key,_xlfn.TEXTJOIN("",TRUE,_xlfn._xlws.SORT(MID(LOWER(_xlpm._src),_xlfn.SEQUENCE(LEN(_xlpm._src)),1))), _xlpm._names,'Data Pegawai'!$A$4:$A$53, _xlpm._keys,_xlfn.BYROW(_xlpm._names,_xlfn.LAMBDA(_xlpm.r,_xlfn.LET(_xlpm._s,SUBSTITUTE(_xlpm.r," ",""),_xlfn.TEXTJOIN("",TRUE,_xlfn._xlws.SORT(MID(LOWER(_xlpm._s),_xlfn.SEQUENCE(LEN(_xlpm._s)),1)))))), _xlpm._cipher,_xlfn.XLOOKUP(_xlpm._key,_xlpm._keys,'Data Pegawai'!$E$4:$E$53), _xlpm._chars,MID(_xlpm._cipher,_xlfn.SEQUENCE(LEN(_xlpm._cipher)),1), _xlpm._decoded,_xlfn.TEXTJOIN("",TRUE,_xlfn.MAP(_xlpm._chars,_xlfn.LAMBDA(_xlpm.c,IF(CODE(_xlpm.c)=33," ",IF(CODE(_xlpm.c)=65,CHAR(90),IF(CODE(_xlpm.c)=97,CHAR(122),IF(OR(AND(CODE(_xlpm.c)>65,CODE(_xlpm.c)<=90),AND(CODE(_xlpm.c)>97,CODE(_xlpm.c)<=122)),CHAR(CODE(_xlpm.c)-1),_xlpm.c))))))), _xlpm._deckey,_xlfn.LET(_xlpm._d,SUBSTITUTE(_xlpm._decoded," ",""),_xlfn.TEXTJOIN("",TRUE,_xlfn._xlws.SORT(MID(LOWER(_xlpm._d),_xlfn.SEQUENCE(LEN(_xlpm._d)),1)))), _xlpm._jabatan,'Data Pegawai'!$J$4:$J$8, _xlpm._jabkeys,_xlfn.BYROW(_xlpm._jabatan,_xlfn.LAMBDA(_xlpm.j,_xlfn.LET(_xlpm._s,SUBSTITUTE(_xlpm.j," ",""),_xlfn.TEXTJOIN("",TRUE,_xlfn._xlws.SORT(MID(LOWER(_xlpm._s),_xlfn.SEQUENCE(LEN(_xlpm._s)),1)))))), _xlfn.XLOOKUP(_xlpm._deckey,_xlpm._jabkeys,'Data Pegawai'!$I$4:$I$8) )} -> IT | H50: {=_xlfn.LET( _xlpm._src,SUBSTITUTE(C50," ",""), _xlpm._key,_xlfn.TEXTJOIN("",TRUE,_xlfn._xlws.SORT(MID(LOWER(_xlpm._src),_xlfn.SEQUENCE(LEN(_xlpm._src)),1))), _xlpm._names,'Data Pegawai'!$A$4:$A$53, _xlpm._keys,_xlfn.BYROW(_xlpm._names,_xlfn.LAMBDA(_xlpm.r,_xlfn.LET(_xlpm._s,SUBSTITUTE(_xlpm.r," ",""),_xlfn.TEXTJOIN("",TRUE,_xlfn._xlws.SORT(MID(LOWER(_xlpm._s),_xlfn.SEQUENCE(LEN(_xlpm._s)),1)))))), _xlpm._cipher,_xlfn.XLOOKUP(_xlpm._key,_xlpm._keys,'Data Pegawai'!$E$4:$E$53), _xlpm._chars,MID(_xlpm._cipher,_xlfn.SEQUENCE(LEN(_xlpm._cipher)),1), _xlpm._decoded,_xlfn.TEXTJOIN("",TRUE,_xlfn.MAP(_xlpm._chars,_xlfn.LAMBDA(_xlpm.c,IF(CODE(_xlpm.c)=33," ",IF(CODE(_xlpm.c)=65,CHAR(90),IF(CODE(_xlpm.c)=97,CHAR(122),IF(OR(AND(CODE(_xlpm.c)>65,CODE(_xlpm.c)<=90),AND(CODE(_xlpm.c)>97,CODE(_xlpm.c)<=122)),CHAR(CODE(_xlpm.c)-1),_xlpm.c))))))), _xlpm._deckey,_xlfn.LET(_xlpm._d,SUBSTITUTE(_xlpm._decoded," ",""),_xlfn.TEXTJOIN("",TRUE,_xlfn._xlws.SORT(MID(LOWER(_xlpm._d),_xlfn.SEQUENCE(LEN(_xlpm._d)),1)))), _xlpm._jabatan,'Data Pegawai'!$J$4:$J$8, _xlpm._jabkeys,_xlfn.BYROW(_xlpm._jabatan,_xlfn.LAMBDA(_xlpm.j,_xlfn.LET(_xlpm._s,SUBSTITUTE(_xlpm.j," ",""),_xlfn.TEXTJOIN("",TRUE,_xlfn._xlws.SORT(MID(LOWER(_xlpm._s),_xlfn.SEQUENCE(LEN(_xlpm._s)),1)))))), _xlfn.XLOOKUP(_xlpm._deckey,_xlpm._jabkeys,_xlpm._jabatan) )} -> IT Support | I50: {=_xlfn.LET( _xlpm._raw,VLOOKUP(H50,'Data Pegawai'!$J$4:$L$8,2,0), _xlpm._e,FIND("E",_xlpm._raw), VALUE(MID(_xlpm._raw,2,_xlpm._e-2))*10^VALUE(RIGHT(_xlpm._raw,LEN(_xlpm._raw)-_xlpm._e)) )} -> 3000000 | J50: {=_xlfn.LET( _xlpm._raw,VLOOKUP(H50,'Data Pegawai'!$J$4:$L$8,3,0), _xlpm._e,FIND("E",_xlpm._raw), VALUE(MID(_xlpm._raw,2,_xlpm._e-2))*10^VALUE(RIGHT(_xlpm._raw,LEN(_xlpm._raw)-_xlpm._e)) )} -> 500000 | K50: =SUM(I50:J50) -> 3500000
B51: 5 | C51: MnIula rfnaaa | D51: {=_xlfn.LET( _xlpm._src,SUBSTITUTE(C51," ",""), _xlpm._key,_xlfn.TEXTJOIN("",TRUE,_xlfn._xlws.SORT(MID(LOWER(_xlpm._src),_xlfn.SEQUENCE(LEN(_xlpm._src)),1))), _xlpm._names,'Data Pegawai'!$A$4:$A$53, _xlpm._keys,_xlfn.BYROW(_xlpm._names,_xlfn.LAMBDA(_xlpm.r,_xlfn.LET(_xlpm._s,SUBSTITUTE(_xlpm.r," ",""),_xlfn.TEXTJOIN("",TRUE,_xlfn._xlws.SORT(MID(LOWER(_xlpm._s),_xlfn.SEQUENCE(LEN(_xlpm._s)),1)))))), _xlfn.XLOOKUP(_xlpm._key,_xlpm._keys,'Data Pegawai'!$B$4:$B$53) )} -> Medan | E51: {=_xlfn.LET( _xlpm._src,SUBSTITUTE(C51," ",""), _xlpm._key,_xlfn.TEXTJOIN("",TRUE,_xlfn._xlws.SORT(MID(LOWER(_xlpm._src),_xlfn.SEQUENCE(LEN(_xlpm._src)),1))), _xlpm._names,'Data Pegawai'!$A$4:$A$53, _xlpm._keys,_xlfn.BYROW(_xlpm._names,_xlfn.LAMBDA(_xlpm.r,_xlfn.LET(_xlpm._s,SUBSTITUTE(_xlpm.r," ",""),_xlfn.TEXTJOIN("",TRUE,_xlfn._xlws.SORT(MID(LOWER(_xlpm._s),_xlfn.SEQUENCE(LEN(_xlpm._s)),1)))))), _xlfn.XLOOKUP(_xlpm._key,_xlpm._keys,'Data Pegawai'!$C$4:$C$53) )} -> 36381 | F51: {=_xlfn.LET( _xlpm._src,SUBSTITUTE(C51," ",""), _xlpm._key,_xlfn.TEXTJOIN("",TRUE,_xlfn._xlws.SORT(MID(LOWER(_xlpm._src),_xlfn.SEQUENCE(LEN(_xlpm._src)),1))), _xlpm._names,'Data Pegawai'!$A$4:$A$53, _xlpm._keys,_xlfn.BYROW(_xlpm._names,_xlfn.LAMBDA(_xlpm.r,_xlfn.LET(_xlpm._s,SUBSTITUTE(_xlpm.r," ",""),_xlfn.TEXTJOIN("",TRUE,_xlfn._xlws.SORT(MID(LOWER(_xlpm._s),_xlfn.SEQUENCE(LEN(_xlpm._s)),1)))))), _xlfn.XLOOKUP(_xlpm._key,_xlpm._keys,'Data Pegawai'!$D$4:$D$53) )} -> 42023 | G51: {=_xlfn.LET( _xlpm._src,SUBSTITUTE(C51," ",""), _xlpm._key,_xlfn.TEXTJOIN("",TRUE,_xlfn._xlws.SORT(MID(LOWER(_xlpm._src),_xlfn.SEQUENCE(LEN(_xlpm._src)),1))), _xlpm._names,'Data Pegawai'!$A$4:$A$53, _xlpm._keys,_xlfn.BYROW(_xlpm._names,_xlfn.LAMBDA(_xlpm.r,_xlfn.LET(_xlpm._s,SUBSTITUTE(_xlpm.r," ",""),_xlfn.TEXTJOIN("",TRUE,_xlfn._xlws.SORT(MID(LOWER(_xlpm._s),_xlfn.SEQUENCE(LEN(_xlpm._s)),1)))))), _xlpm._cipher,_xlfn.XLOOKUP(_xlpm._key,_xlpm._keys,'Data Pegawai'!$E$4:$E$53), _xlpm._chars,MID(_xlpm._cipher,_xlfn.SEQUENCE(LEN(_xlpm._cipher)),1), _xlpm._decoded,_xlfn.TEXTJOIN("",TRUE,_xlfn.MAP(_xlpm._chars,_xlfn.LAMBDA(_xlpm.c,IF(CODE(_xlpm.c)=33," ",IF(CODE(_xlpm.c)=65,CHAR(90),IF(CODE(_xlpm.c)=97,CHAR(122),IF(OR(AND(CODE(_xlpm.c)>65,CODE(_xlpm.c)<=90),AND(CODE(_xlpm.c)>97,CODE(_xlpm.c)<=122)),CHAR(CODE(_xlpm.c)-1),_xlpm.c))))))), _xlpm._deckey,_xlfn.LET(_xlpm._d,SUBSTITUTE(_xlpm._decoded," ",""),_xlfn.TEXTJOIN("",TRUE,_xlfn._xlws.SORT(MID(LOWER(_xlpm._d),_xlfn.SEQUENCE(LEN(_xlpm._d)),1)))), _xlpm._jabatan,'Data Pegawai'!$J$4:$J$8, _xlpm._jabkeys,_xlfn.BYROW(_xlpm._jabatan,_xlfn.LAMBDA(_xlpm.j,_xlfn.LET(_xlpm._s,SUBSTITUTE(_xlpm.j," ",""),_xlfn.TEXTJOIN("",TRUE,_xlfn._xlws.SORT(MID(LOWER(_xlpm._s),_xlfn.SEQUENCE(LEN(_xlpm._s)),1)))))), _xlfn.XLOOKUP(_xlpm._deckey,_xlpm._jabkeys,'Data Pegawai'!$I$4:$I$8) )} -> IT | H51: {=_xlfn.LET( _xlpm._src,SUBSTITUTE(C51," ",""), _xlpm._key,_xlfn.TEXTJOIN("",TRUE,_xlfn._xlws.SORT(MID(LOWER(_xlpm._src),_xlfn.SEQUENCE(LEN(_xlpm._src)),1))), _xlpm._names,'Data Pegawai'!$A$4:$A$53, _xlpm._keys,_xlfn.BYROW(_xlpm._names,_xlfn.LAMBDA(_xlpm.r,_xlfn.LET(_xlpm._s,SUBSTITUTE(_xlpm.r," ",""),_xlfn.TEXTJOIN("",TRUE,_xlfn._xlws.SORT(MID(LOWER(_xlpm._s),_xlfn.SEQUENCE(LEN(_xlpm._s)),1)))))), _xlpm._cipher,_xlfn.XLOOKUP(_xlpm._key,_xlpm._keys,'Data Pegawai'!$E$4:$E$53), _xlpm._chars,MID(_xlpm._cipher,_xlfn.SEQUENCE(LEN(_xlpm._cipher)),1), _xlpm._decoded,_xlfn.TEXTJOIN("",TRUE,_xlfn.MAP(_xlpm._chars,_xlfn.LAMBDA(_xlpm.c,IF(CODE(_xlpm.c)=33," ",IF(CODE(_xlpm.c)=65,CHAR(90),IF(CODE(_xlpm.c)=97,CHAR(122),IF(OR(AND(CODE(_xlpm.c)>65,CODE(_xlpm.c)<=90),AND(CODE(_xlpm.c)>97,CODE(_xlpm.c)<=122)),CHAR(CODE(_xlpm.c)-1),_xlpm.c))))))), _xlpm._deckey,_xlfn.LET(_xlpm._d,SUBSTITUTE(_xlpm._decoded," ",""),_xlfn.TEXTJOIN("",TRUE,_xlfn._xlws.SORT(MID(LOWER(_xlpm._d),_xlfn.SEQUENCE(LEN(_xlpm._d)),1)))), _xlpm._jabatan,'Data Pegawai'!$J$4:$J$8, _xlpm._jabkeys,_xlfn.BYROW(_xlpm._jabatan,_xlfn.LAMBDA(_xlpm.j,_xlfn.LET(_xlpm._s,SUBSTITUTE(_xlpm.j," ",""),_xlfn.TEXTJOIN("",TRUE,_xlfn._xlws.SORT(MID(LOWER(_xlpm._s),_xlfn.SEQUENCE(LEN(_xlpm._s)),1)))))), _xlfn.XLOOKUP(_xlpm._deckey,_xlpm._jabkeys,_xlpm._jabatan) )} -> IT Support | I51: {=_xlfn.LET( _xlpm._raw,VLOOKUP(H51,'Data Pegawai'!$J$4:$L$8,2,0), _xlpm._e,FIND("E",_xlpm._raw), VALUE(MID(_xlpm._raw,2,_xlpm._e-2))*10^VALUE(RIGHT(_xlpm._raw,LEN(_xlpm._raw)-_xlpm._e)) )} -> 3000000 | J51: {=_xlfn.LET( _xlpm._raw,VLOOKUP(H51,'Data Pegawai'!$J$4:$L$8,3,0), _xlpm._e,FIND("E",_xlpm._raw), VALUE(MID(_xlpm._raw,2,_xlpm._e-2))*10^VALUE(RIGHT(_xlpm._raw,LEN(_xlpm._raw)-_xlpm._e)) )} -> 500000 | K51: =SUM(I51:J51) -> 3500000
B52: 6 | C52: hAzar hzaJian | D52: {=_xlfn.LET( _xlpm._src,SUBSTITUTE(C52," ",""), _xlpm._key,_xlfn.TEXTJOIN("",TRUE,_xlfn._xlws.SORT(MID(LOWER(_xlpm._src),_xlfn.SEQUENCE(LEN(_xlpm._src)),1))), _xlpm._names,'Data Pegawai'!$A$4:$A$53, _xlpm._keys,_xlfn.BYROW(_xlpm._names,_xlfn.LAMBDA(_xlpm.r,_xlfn.LET(_xlpm._s,SUBSTITUTE(_xlpm.r," ",""),_xlfn.TEXTJOIN("",TRUE,_xlfn._xlws.SORT(MID(LOWER(_xlpm._s),_xlfn.SEQUENCE(LEN(_xlpm._s)),1)))))), _xlfn.XLOOKUP(_xlpm._key,_xlpm._keys,'Data Pegawai'!$B$4:$B$53) )} -> Makassar | E52: {=_xlfn.LET( _xlpm._src,SUBSTITUTE(C52," ",""), _xlpm._key,_xlfn.TEXTJOIN("",TRUE,_xlfn._xlws.SORT(MID(LOWER(_xlpm._src),_xlfn.SEQUENCE(LEN(_xlpm._src)),1))), _xlpm._names,'Data Pegawai'!$A$4:$A$53, _xlpm._keys,_xlfn.BYROW(_xlpm._names,_xlfn.LAMBDA(_xlpm.r,_xlfn.LET(_xlpm._s,SUBSTITUTE(_xlpm.r," ",""),_xlfn.TEXTJOIN("",TRUE,_xlfn._xlws.SORT(MID(LOWER(_xlpm._s),_xlfn.SEQUENCE(LEN(_xlpm._s)),1)))))), _xlfn.XLOOKUP(_xlpm._key,_xlpm._keys,'Data Pegawai'!$C$4:$C$53) )} -> 34830 | F52: {=_xlfn.LET( _xlpm._src,SUBSTITUTE(C52," ",""), _xlpm._key,_xlfn.TEXTJOIN("",TRUE,_xlfn._xlws.SORT(MID(LOWER(_xlpm._src),_xlfn.SEQUENCE(LEN(_xlpm._src)),1))), _xlpm._names,'Data Pegawai'!$A$4:$A$53, _xlpm._keys,_xlfn.BYROW(_xlpm._names,_xlfn.LAMBDA(_xlpm.r,_xlfn.LET(_xlpm._s,SUBSTITUTE(_xlpm.r," ",""),_xlfn.TEXTJOIN("",TRUE,_xlfn._xlws.SORT(MID(LOWER(_xlpm._s),_xlfn.SEQUENCE(LEN(_xlpm._s)),1)))))), _xlfn.XLOOKUP(_xlpm._key,_xlpm._keys,'Data Pegawai'!$D$4:$D$53) )} -> 43794 | G52: {=_xlfn.LET( _xlpm._src,SUBSTITUTE(C52," ",""), _xlpm._key,_xlfn.TEXTJOIN("",TRUE,_xlfn._xlws.SORT(MID(LOWER(_xlpm._src),_xlfn.SEQUENCE(LEN(_xlpm._src)),1))), _xlpm._names,'Data Pegawai'!$A$4:$A$53, _xlpm._keys,_xlfn.BYROW(_xlpm._names,_xlfn.LAMBDA(_xlpm.r,_xlfn.LET(_xlpm._s,SUBSTITUTE(_xlpm.r," ",""),_xlfn.TEXTJOIN("",TRUE,_xlfn._xlws.SORT(MID(LOWER(_xlpm._s),_xlfn.SEQUENCE(LEN(_xlpm._s)),1)))))), _xlpm._cipher,_xlfn.XLOOKUP(_xlpm._key,_xlpm._keys,'Data Pegawai'!$E$4:$E$53), _xlpm._chars,MID(_xlpm._cipher,_xlfn.SEQUENCE(LEN(_xlpm._cipher)),1), _xlpm._decoded,_xlfn.TEXTJOIN("",TRUE,_xlfn.MAP(_xlpm._chars,_xlfn.LAMBDA(_xlpm.c,IF(CODE(_xlpm.c)=33," ",IF(CODE(_xlpm.c)=65,CHAR(90),IF(CODE(_xlpm.c)=97,CHAR(122),IF(OR(AND(CODE(_xlpm.c)>65,CODE(_xlpm.c)<=90),AND(CODE(_xlpm.c)>97,CODE(_xlpm.c)<=122)),CHAR(CODE(_xlpm.c)-1),_xlpm.c))))))), _xlpm._deckey,_xlfn.LET(_xlpm._d,SUBSTITUTE(_xlpm._decoded," ",""),_xlfn.TEXTJOIN("",TRUE,_xlfn._xlws.SORT(MID(LOWER(_xlpm._d),_xlfn.SEQUENCE(LEN(_xlpm._d)),1)))), _xlpm._jabatan,'Data Pegawai'!$J$4:$J$8, _xlpm._jabkeys,_xlfn.BYROW(_xlpm._jabatan,_xlfn.LAMBDA(_xlpm.j,_xlfn.LET(_xlpm._s,SUBSTITUTE(_xlpm.j," ",""),_xlfn.TEXTJOIN("",TRUE,_xlfn._xlws.SORT(MID(LOWER(_xlpm._s),_xlfn.SEQUENCE(LEN(_xlpm._s)),1)))))), _xlfn.XLOOKUP(_xlpm._deckey,_xlpm._jabkeys,'Data Pegawai'!$I$4:$I$8) )} -> MKT | H52: {=_xlfn.LET( _xlpm._src,SUBSTITUTE(C52," ",""), _xlpm._key,_xlfn.TEXTJOIN("",TRUE,_xlfn._xlws.SORT(MID(LOWER(_xlpm._src),_xlfn.SEQUENCE(LEN(_xlpm._src)),1))), _xlpm._names,'Data Pegawai'!$A$4:$A$53, _xlpm._keys,_xlfn.BYROW(_xlpm._names,_xlfn.LAMBDA(_xlpm.r,_xlfn.LET(_xlpm._s,SUBSTITUTE(_xlpm.r," ",""),_xlfn.TEXTJOIN("",TRUE,_xlfn._xlws.SORT(MID(LOWER(_xlpm._s),_xlfn.SEQUENCE(LEN(_xlpm._s)),1)))))), _xlpm._cipher,_xlfn.XLOOKUP(_xlpm._key,_xlpm._keys,'Data Pegawai'!$E$4:$E$53), _xlpm._chars,MID(_xlpm._cipher,_xlfn.SEQUENCE(LEN(_xlpm._cipher)),1), _xlpm._decoded,_xlfn.TEXTJOIN("",TRUE,_xlfn.MAP(_xlpm._chars,_xlfn.LAMBDA(_xlpm.c,IF(CODE(_xlpm.c)=33," ",IF(CODE(_xlpm.c)=65,CHAR(90),IF(CODE(_xlpm.c)=97,CHAR(122),IF(OR(AND(CODE(_xlpm.c)>65,CODE(_xlpm.c)<=90),AND(CODE(_xlpm.c)>97,CODE(_xlpm.c)<=122)),CHAR(CODE(_xlpm.c)-1),_xlpm.c))))))), _xlpm._deckey,_xlfn.LET(_xlpm._d,SUBSTITUTE(_xlpm._decoded," ",""),_xlfn.TEXTJOIN("",TRUE,_xlfn._xlws.SORT(MID(LOWER(_xlpm._d),_xlfn.SEQUENCE(LEN(_xlpm._d)),1)))), _xlpm._jabatan,'Data Pegawai'!$J$4:$J$8, _xlpm._jabkeys,_xlfn.BYROW(_xlpm._jabatan,_xlfn.LAMBDA(_xlpm.j,_xlfn.LET(_xlpm._s,SUBSTITUTE(_xlpm.j," ",""),_xlfn.TEXTJOIN("",TRUE,_xlfn._xlws.SORT(MID(LOWER(_xlpm._s),_xlfn.SEQUENCE(LEN(_xlpm._s)),1)))))), _xlfn.XLOOKUP(_xlpm._deckey,_xlpm._jabkeys,_xlpm._jabatan) )} -> Marketing | I52: {=_xlfn.LET( _xlpm._raw,VLOOKUP(H52,'Data Pegawai'!$J$4:$L$8,2,0), _xlpm._e,FIND("E",_xlpm._raw), VALUE(MID(_xlpm._raw,2,_xlpm._e-2))*10^VALUE(RIGHT(_xlpm._raw,LEN(_xlpm._raw)-_xlpm._e)) )} -> 4500000 | J52: {=_xlfn.LET( _xlpm._raw,VLOOKUP(H52,'Data Pegawai'!$J$4:$L$8,3,0), _xlpm._e,FIND("E",_xlpm._raw), VALUE(MID(_xlpm._raw,2,_xlpm._e-2))*10^VALUE(RIGHT(_xlpm._raw,LEN(_xlpm._raw)-_xlpm._e)) )} -> 100000 | K52: =SUM(I52:J52) -> 4600000
B53: 7 | C53: aa URwmithail | D53: {=_xlfn.LET( _xlpm._src,SUBSTITUTE(C53," ",""), _xlpm._key,_xlfn.TEXTJOIN("",TRUE,_xlfn._xlws.SORT(MID(LOWER(_xlpm._src),_xlfn.SEQUENCE(LEN(_xlpm._src)),1))), _xlpm._names,'Data Pegawai'!$A$4:$A$53, _xlpm._keys,_xlfn.BYROW(_xlpm._names,_xlfn.LAMBDA(_xlpm.r,_xlfn.LET(_xlpm._s,SUBSTITUTE(_xlpm.r," ",""),_xlfn.TEXTJOIN("",TRUE,_xlfn._xlws.SORT(MID(LOWER(_xlpm._s),_xlfn.SEQUENCE(LEN(_xlpm._s)),1)))))), _xlfn.XLOOKUP(_xlpm._key,_xlpm._keys,'Data Pegawai'!$B$4:$B$53) )} -> Denpasar | E53: {=_xlfn.LET( _xlpm._src,SUBSTITUTE(C53," ",""), _xlpm._key,_xlfn.TEXTJOIN("",TRUE,_xlfn._xlws.SORT(MID(LOWER(_xlpm._src),_xlfn.SEQUENCE(LEN(_xlpm._src)),1))), _xlpm._names,'Data Pegawai'!$A$4:$A$53, _xlpm._keys,_xlfn.BYROW(_xlpm._names,_xlfn.LAMBDA(_xlpm.r,_xlfn.LET(_xlpm._s,SUBSTITUTE(_xlpm.r," ",""),_xlfn.TEXTJOIN("",TRUE,_xlfn._xlws.SORT(MID(LOWER(_xlpm._s),_xlfn.SEQUENCE(LEN(_xlpm._s)),1)))))), _xlfn.XLOOKUP(_xlpm._key,_xlpm._keys,'Data Pegawai'!$C$4:$C$53) )} -> 32287 | F53: {=_xlfn.LET( _xlpm._src,SUBSTITUTE(C53," ",""), _xlpm._key,_xlfn.TEXTJOIN("",TRUE,_xlfn._xlws.SORT(MID(LOWER(_xlpm._src),_xlfn.SEQUENCE(LEN(_xlpm._src)),1))), _xlpm._names,'Data Pegawai'!$A$4:$A$53, _xlpm._keys,_xlfn.BYROW(_xlpm._names,_xlfn.LAMBDA(_xlpm.r,_xlfn.LET(_xlpm._s,SUBSTITUTE(_xlpm.r," ",""),_xlfn.TEXTJOIN("",TRUE,_xlfn._xlws.SORT(MID(LOWER(_xlpm._s),_xlfn.SEQUENCE(LEN(_xlpm._s)),1)))))), _xlfn.XLOOKUP(_xlpm._key,_xlpm._keys,'Data Pegawai'!$D$4:$D$53) )} -> 42466 | G53: {=_xlfn.LET( _xlpm._src,SUBSTITUTE(C53," ",""), _xlpm._key,_xlfn.TEXTJOIN("",TRUE,_xlfn._xlws.SORT(MID(LOWER(_xlpm._src),_xlfn.SEQUENCE(LEN(_xlpm._src)),1))), _xlpm._names,'Data Pegawai'!$A$4:$A$53, _xlpm._keys,_xlfn.BYROW(_xlpm._names,_xlfn.LAMBDA(_xlpm.r,_xlfn.LET(_xlpm._s,SUBSTITUTE(_xlpm.r," ",""),_xlfn.TEXTJOIN("",TRUE,_xlfn._xlws.SORT(MID(LOWER(_xlpm._s),_xlfn.SEQUENCE(LEN(_xlpm._s)),1)))))), _xlpm._cipher,_xlfn.XLOOKUP(_xlpm._key,_xlpm._keys,'Data Pegawai'!$E$4:$E$53), _xlpm._chars,MID(_xlpm._cipher,_xlfn.SEQUENCE(LEN(_xlpm._cipher)),1), _xlpm._decoded,_xlfn.TEXTJOIN("",TRUE,_xlfn.MAP(_xlpm._chars,_xlfn.LAMBDA(_xlpm.c,IF(CODE(_xlpm.c)=33," ",IF(CODE(_xlpm.c)=65,CHAR(90),IF(CODE(_xlpm.c)=97,CHAR(122),IF(OR(AND(CODE(_xlpm.c)>65,CODE(_xlpm.c)<=90),AND(CODE(_xlpm.c)>97,CODE(_xlpm.c)<=122)),CHAR(CODE(_xlpm.c)-1),_xlpm.c))))))), _xlpm._deckey,_xlfn.LET(_xlpm._d,SUBSTITUTE(_xlpm._decoded," ",""),_xlfn.TEXTJOIN("",TRUE,_xlfn._xlws.SORT(MID(LOWER(_xlpm._d),_xlfn.SEQUENCE(LEN(_xlpm._d)),1)))), _xlpm._jabatan,'Data Pegawai'!$J$4:$J$8, _xlpm._jabkeys,_xlfn.BYROW(_xlpm._jabatan,_xlfn.LAMBDA(_xlpm.j,_xlfn.LET(_xlpm._s,SUBSTITUTE(_xlpm.j," ",""),_xlfn.TEXTJOIN("",TRUE,_xlfn._xlws.SORT(MID(LOWER(_xlpm._s),_xlfn.SEQUENCE(LEN(_xlpm._s)),1)))))), _xlfn.XLOOKUP(_xlpm._deckey,_xlpm._jabkeys,'Data Pegawai'!$I$4:$I$8) )} -> MKT | H53: {=_xlfn.LET( _xlpm._src,SUBSTITUTE(C53," ",""), _xlpm._key,_xlfn.TEXTJOIN("",TRUE,_xlfn._xlws.SORT(MID(LOWER(_xlpm._src),_xlfn.SEQUENCE(LEN(_xlpm._src)),1))), _xlpm._names,'Data Pegawai'!$A$4:$A$53, _xlpm._keys,_xlfn.BYROW(_xlpm._names,_xlfn.LAMBDA(_xlpm.r,_xlfn.LET(_xlpm._s,SUBSTITUTE(_xlpm.r," ",""),_xlfn.TEXTJOIN("",TRUE,_xlfn._xlws.SORT(MID(LOWER(_xlpm._s),_xlfn.SEQUENCE(LEN(_xlpm._s)),1)))))), _xlpm._cipher,_xlfn.XLOOKUP(_xlpm._key,_xlpm._keys,'Data Pegawai'!$E$4:$E$53), _xlpm._chars,MID(_xlpm._cipher,_xlfn.SEQUENCE(LEN(_xlpm._cipher)),1), _xlpm._decoded,_xlfn.TEXTJOIN("",TRUE,_xlfn.MAP(_xlpm._chars,_xlfn.LAMBDA(_xlpm.c,IF(CODE(_xlpm.c)=33," ",IF(CODE(_xlpm.c)=65,CHAR(90),IF(CODE(_xlpm.c)=97,CHAR(122),IF(OR(AND(CODE(_xlpm.c)>65,CODE(_xlpm.c)<=90),AND(CODE(_xlpm.c)>97,CODE(_xlpm.c)<=122)),CHAR(CODE(_xlpm.c)-1),_xlpm.c))))))), _xlpm._deckey,_xlfn.LET(_xlpm._d,SUBSTITUTE(_xlpm._decoded," ",""),_xlfn.TEXTJOIN("",TRUE,_xlfn._xlws.SORT(MID(LOWER(_xlpm._d),_xlfn.SEQUENCE(LEN(_xlpm._d)),1)))), _xlpm._jabatan,'Data Pegawai'!$J$4:$J$8, _xlpm._jabkeys,_xlfn.BYROW(_xlpm._jabatan,_xlfn.LAMBDA(_xlpm.j,_xlfn.LET(_xlpm._s,SUBSTITUTE(_xlpm.j," ",""),_xlfn.TEXTJOIN("",TRUE,_xlfn._xlws.SORT(MID(LOWER(_xlpm._s),_xlfn.SEQUENCE(LEN(_xlpm._s)),1)))))), _xlfn.XLOOKUP(_xlpm._deckey,_xlpm._jabkeys,_xlpm._jabatan) )} -> Marketing | I53: {=_xlfn.LET( _xlpm._raw,VLOOKUP(H53,'Data Pegawai'!$J$4:$L$8,2,0), _xlpm._e,FIND("E",_xlpm._raw), VALUE(MID(_xlpm._raw,2,_xlpm._e-2))*10^VALUE(RIGHT(_xlpm._raw,LEN(_xlpm._raw)-_xlpm._e)) )} -> 4500000 | J53: {=_xlfn.LET( _xlpm._raw,VLOOKUP(H53,'Data Pegawai'!$J$4:$L$8,3,0), _xlpm._e,FIND("E",_xlpm._raw), VALUE(MID(_xlpm._raw,2,_xlpm._e-2))*10^VALUE(RIGHT(_xlpm._raw,LEN(_xlpm._raw)-_xlpm._e)) )} -> 100000 | K53: =SUM(I53:J53) -> 4600000
B54: 8 | C54: laad mmhhMcImao | D54: {=_xlfn.LET( _xlpm._src,SUBSTITUTE(C54," ",""), _xlpm._key,_xlfn.TEXTJOIN("",TRUE,_xlfn._xlws.SORT(MID(LOWER(_xlpm._src),_xlfn.SEQUENCE(LEN(_xlpm._src)),1))), _xlpm._names,'Data Pegawai'!$A$4:$A$53, _xlpm._keys,_xlfn.BYROW(_xlpm._names,_xlfn.LAMBDA(_xlpm.r,_xlfn.LET(_xlpm._s,SUBSTITUTE(_xlpm.r," ",""),_xlfn.TEXTJOIN("",TRUE,_xlfn._xlws.SORT(MID(LOWER(_xlpm._s),_xlfn.SEQUENCE(LEN(_xlpm._s)),1)))))), _xlfn.XLOOKUP(_xlpm._key,_xlpm._keys,'Data Pegawai'!$B$4:$B$53) )} -> Medan | E54: {=_xlfn.LET( _xlpm._src,SUBSTITUTE(C54," ",""), _xlpm._key,_xlfn.TEXTJOIN("",TRUE,_xlfn._xlws.SORT(MID(LOWER(_xlpm._src),_xlfn.SEQUENCE(LEN(_xlpm._src)),1))), _xlpm._names,'Data Pegawai'!$A$4:$A$53, _xlpm._keys,_xlfn.BYROW(_xlpm._names,_xlfn.LAMBDA(_xlpm.r,_xlfn.LET(_xlpm._s,SUBSTITUTE(_xlpm.r," ",""),_xlfn.TEXTJOIN("",TRUE,_xlfn._xlws.SORT(MID(LOWER(_xlpm._s),_xlfn.SEQUENCE(LEN(_xlpm._s)),1)))))), _xlfn.XLOOKUP(_xlpm._key,_xlpm._keys,'Data Pegawai'!$C$4:$C$53) )} -> 36331 | F54: {=_xlfn.LET( _xlpm._src,SUBSTITUTE(C54," ",""), _xlpm._key,_xlfn.TEXTJOIN("",TRUE,_xlfn._xlws.SORT(MID(LOWER(_xlpm._src),_xlfn.SEQUENCE(LEN(_xlpm._src)),1))), _xlpm._names,'Data Pegawai'!$A$4:$A$53, _xlpm._keys,_xlfn.BYROW(_xlpm._names,_xlfn.LAMBDA(_xlpm.r,_xlfn.LET(_xlpm._s,SUBSTITUTE(_xlpm.r," ",""),_xlfn.TEXTJOIN("",TRUE,_xlfn._xlws.SORT(MID(LOWER(_xlpm._s),_xlfn.SEQUENCE(LEN(_xlpm._s)),1)))))), _xlfn.XLOOKUP(_xlpm._key,_xlpm._keys,'Data Pegawai'!$D$4:$D$53) )} -> 45147 | G54: {=_xlfn.LET( _xlpm._src,SUBSTITUTE(C54," ",""), _xlpm._key,_xlfn.TEXTJOIN("",TRUE,_xlfn._xlws.SORT(MID(LOWER(_xlpm._src),_xlfn.SEQUENCE(LEN(_xlpm._src)),1))), _xlpm._names,'Data Pegawai'!$A$4:$A$53, _xlpm._keys,_xlfn.BYROW(_xlpm._names,_xlfn.LAMBDA(_xlpm.r,_xlfn.LET(_xlpm._s,SUBSTITUTE(_xlpm.r," ",""),_xlfn.TEXTJOIN("",TRUE,_xlfn._xlws.SORT(MID(LOWER(_xlpm._s),_xlfn.SEQUENCE(LEN(_xlpm._s)),1)))))), _xlpm._cipher,_xlfn.XLOOKUP(_xlpm._key,_xlpm._keys,'Data Pegawai'!$E$4:$E$53), _xlpm._chars,MID(_xlpm._cipher,_xlfn.SEQUENCE(LEN(_xlpm._cipher)),1), _xlpm._decoded,_xlfn.TEXTJOIN("",TRUE,_xlfn.MAP(_xlpm._chars,_xlfn.LAMBDA(_xlpm.c,IF(CODE(_xlpm.c)=33," ",IF(CODE(_xlpm.c)=65,CHAR(90),IF(CODE(_xlpm.c)=97,CHAR(122),IF(OR(AND(CODE(_xlpm.c)>65,CODE(_xlpm.c)<=90),AND(CODE(_xlpm.c)>97,CODE(_xlpm.c)<=122)),CHAR(CODE(_xlpm.c)-1),_xlpm.c))))))), _xlpm._deckey,_xlfn.LET(_xlpm._d,SUBSTITUTE(_xlpm._decoded," ",""),_xlfn.TEXTJOIN("",TRUE,_xlfn._xlws.SORT(MID(LOWER(_xlpm._d),_xlfn.SEQUENCE(LEN(_xlpm._d)),1)))), _xlpm._jabatan,'Data Pegawai'!$J$4:$J$8, _xlpm._jabkeys,_xlfn.BYROW(_xlpm._jabatan,_xlfn.LAMBDA(_xlpm.j,_xlfn.LET(_xlpm._s,SUBSTITUTE(_xlpm.j," ",""),_xlfn.TEXTJOIN("",TRUE,_xlfn._xlws.SORT(MID(LOWER(_xlpm._s),_xlfn.SEQUENCE(LEN(_xlpm._s)),1)))))), _xlfn.XLOOKUP(_xlpm._deckey,_xlpm._jabkeys,'Data Pegawai'!$I$4:$I$8) )} -> IT | H54: {=_xlfn.LET( _xlpm._src,SUBSTITUTE(C54," ",""), _xlpm._key,_xlfn.TEXTJOIN("",TRUE,_xlfn._xlws.SORT(MID(LOWER(_xlpm._src),_xlfn.SEQUENCE(LEN(_xlpm._src)),1))), _xlpm._names,'Data Pegawai'!$A$4:$A$53, _xlpm._keys,_xlfn.BYROW(_xlpm._names,_xlfn.LAMBDA(_xlpm.r,_xlfn.LET(_xlpm._s,SUBSTITUTE(_xlpm.r," ",""),_xlfn.TEXTJOIN("",TRUE,_xlfn._xlws.SORT(MID(LOWER(_xlpm._s),_xlfn.SEQUENCE(LEN(_xlpm._s)),1)))))), _xlpm._cipher,_xlfn.XLOOKUP(_xlpm._key,_xlpm._keys,'Data Pegawai'!$E$4:$E$53), _xlpm._chars,MID(_xlpm._cipher,_xlfn.SEQUENCE(LEN(_xlpm._cipher)),1), _xlpm._decoded,_xlfn.TEXTJOIN("",TRUE,_xlfn.MAP(_xlpm._chars,_xlfn.LAMBDA(_xlpm.c,IF(CODE(_xlpm.c)=33," ",IF(CODE(_xlpm.c)=65,CHAR(90),IF(CODE(_xlpm.c)=97,CHAR(122),IF(OR(AND(CODE(_xlpm.c)>65,CODE(_xlpm.c)<=90),AND(CODE(_xlpm.c)>97,CODE(_xlpm.c)<=122)),CHAR(CODE(_xlpm.c)-1),_xlpm.c))))))), _xlpm._deckey,_xlfn.LET(_xlpm._d,SUBSTITUTE(_xlpm._decoded," ",""),_xlfn.TEXTJOIN("",TRUE,_xlfn._xlws.SORT(MID(LOWER(_xlpm._d),_xlfn.SEQUENCE(LEN(_xlpm._d)),1)))), _xlpm._jabatan,'Data Pegawai'!$J$4:$J$8, _xlpm._jabkeys,_xlfn.BYROW(_xlpm._jabatan,_xlfn.LAMBDA(_xlpm.j,_xlfn.LET(_xlpm._s,SUBSTITUTE(_xlpm.j," ",""),_xlfn.TEXTJOIN("",TRUE,_xlfn._xlws.SORT(MID(LOWER(_xlpm._s),_xlfn.SEQUENCE(LEN(_xlpm._s)),1)))))), _xlfn.XLOOKUP(_xlpm._deckey,_xlpm._jabkeys,_xlpm._jabatan) )} -> IT Support | I54: {=_xlfn.LET( _xlpm._raw,VLOOKUP(H54,'Data Pegawai'!$J$4:$L$8,2,0), _xlpm._e,FIND("E",_xlpm._raw), VALUE(MID(_xlpm._raw,2,_xlpm._e-2))*10^VALUE(RIGHT(_xlpm._raw,LEN(_xlpm._raw)-_xlpm._e)) )} -> 3000000 | J54: {=_xlfn.LET( _xlpm._raw,VLOOKUP(H54,'Data Pegawai'!$J$4:$L$8,3,0), _xlpm._e,FIND("E",_xlpm._raw), VALUE(MID(_xlpm._raw,2,_xlpm._e-2))*10^VALUE(RIGHT(_xlpm._raw,LEN(_xlpm._raw)-_xlpm._e)) )} -> 500000 | K54: =SUM(I54:J54) -> 3500000
B55: 9 | C55: liaa StferlBi | D55: {=_xlfn.LET( _xlpm._src,SUBSTITUTE(C55," ",""), _xlpm._key,_xlfn.TEXTJOIN("",TRUE,_xlfn._xlws.SORT(MID(LOWER(_xlpm._src),_xlfn.SEQUENCE(LEN(_xlpm._src)),1))), _xlpm._names,'Data Pegawai'!$A$4:$A$53, _xlpm._keys,_xlfn.BYROW(_xlpm._names,_xlfn.LAMBDA(_xlpm.r,_xlfn.LET(_xlpm._s,SUBSTITUTE(_xlpm.r," ",""),_xlfn.TEXTJOIN("",TRUE,_xlfn._xlws.SORT(MID(LOWER(_xlpm._s),_xlfn.SEQUENCE(LEN(_xlpm._s)),1)))))), _xlfn.XLOOKUP(_xlpm._key,_xlpm._keys,'Data Pegawai'!$B$4:$B$53) )} -> Semarang | E55: {=_xlfn.LET( _xlpm._src,SUBSTITUTE(C55," ",""), _xlpm._key,_xlfn.TEXTJOIN("",TRUE,_xlfn._xlws.SORT(MID(LOWER(_xlpm._src),_xlfn.SEQUENCE(LEN(_xlpm._src)),1))), _xlpm._names,'Data Pegawai'!$A$4:$A$53, _xlpm._keys,_xlfn.BYROW(_xlpm._names,_xlfn.LAMBDA(_xlpm.r,_xlfn.LET(_xlpm._s,SUBSTITUTE(_xlpm.r," ",""),_xlfn.TEXTJOIN("",TRUE,_xlfn._xlws.SORT(MID(LOWER(_xlpm._s),_xlfn.SEQUENCE(LEN(_xlpm._s)),1)))))), _xlfn.XLOOKUP(_xlpm._key,_xlpm._keys,'Data Pegawai'!$C$4:$C$53) )} -> 37890 | F55: {=_xlfn.LET( _xlpm._src,SUBSTITUTE(C55," ",""), _xlpm._key,_xlfn.TEXTJOIN("",TRUE,_xlfn._xlws.SORT(MID(LOWER(_xlpm._src),_xlfn.SEQUENCE(LEN(_xlpm._src)),1))), _xlpm._names,'Data Pegawai'!$A$4:$A$53, _xlpm._keys,_xlfn.BYROW(_xlpm._names,_xlfn.LAMBDA(_xlpm.r,_xlfn.LET(_xlpm._s,SUBSTITUTE(_xlpm.r," ",""),_xlfn.TEXTJOIN("",TRUE,_xlfn._xlws.SORT(MID(LOWER(_xlpm._s),_xlfn.SEQUENCE(LEN(_xlpm._s)),1)))))), _xlfn.XLOOKUP(_xlpm._key,_xlpm._keys,'Data Pegawai'!$D$4:$D$53) )} -> 43361 | G55: {=_xlfn.LET( _xlpm._src,SUBSTITUTE(C55," ",""), _xlpm._key,_xlfn.TEXTJOIN("",TRUE,_xlfn._xlws.SORT(MID(LOWER(_xlpm._src),_xlfn.SEQUENCE(LEN(_xlpm._src)),1))), _xlpm._names,'Data Pegawai'!$A$4:$A$53, _xlpm._keys,_xlfn.BYROW(_xlpm._names,_xlfn.LAMBDA(_xlpm.r,_xlfn.LET(_xlpm._s,SUBSTITUTE(_xlpm.r," ",""),_xlfn.TEXTJOIN("",TRUE,_xlfn._xlws.SORT(MID(LOWER(_xlpm._s),_xlfn.SEQUENCE(LEN(_xlpm._s)),1)))))), _xlpm._cipher,_xlfn.XLOOKUP(_xlpm._key,_xlpm._keys,'Data Pegawai'!$E$4:$E$53), _xlpm._chars,MID(_xlpm._cipher,_xlfn.SEQUENCE(LEN(_xlpm._cipher)),1), _xlpm._decoded,_xlfn.TEXTJOIN("",TRUE,_xlfn.MAP(_xlpm._chars,_xlfn.LAMBDA(_xlpm.c,IF(CODE(_xlpm.c)=33," ",IF(CODE(_xlpm.c)=65,CHAR(90),IF(CODE(_xlpm.c)=97,CHAR(122),IF(OR(AND(CODE(_xlpm.c)>65,CODE(_xlpm.c)<=90),AND(CODE(_xlpm.c)>97,CODE(_xlpm.c)<=122)),CHAR(CODE(_xlpm.c)-1),_xlpm.c))))))), _xlpm._deckey,_xlfn.LET(_xlpm._d,SUBSTITUTE(_xlpm._decoded," ",""),_xlfn.TEXTJOIN("",TRUE,_xlfn._xlws.SORT(MID(LOWER(_xlpm._d),_xlfn.SEQUENCE(LEN(_xlpm._d)),1)))), _xlpm._jabatan,'Data Pegawai'!$J$4:$J$8, _xlpm._jabkeys,_xlfn.BYROW(_xlpm._jabatan,_xlfn.LAMBDA(_xlpm.j,_xlfn.LET(_xlpm._s,SUBSTITUTE(_xlpm.j," ",""),_xlfn.TEXTJOIN("",TRUE,_xlfn._xlws.SORT(MID(LOWER(_xlpm._s),_xlfn.SEQUENCE(LEN(_xlpm._s)),1)))))), _xlfn.XLOOKUP(_xlpm._deckey,_xlpm._jabkeys,'Data Pegawai'!$I$4:$I$8) )} -> ADM | H55: {=_xlfn.LET( _xlpm._src,SUBSTITUTE(C55," ",""), _xlpm._key,_xlfn.TEXTJOIN("",TRUE,_xlfn._xlws.SORT(MID(LOWER(_xlpm._src),_xlfn.SEQUENCE(LEN(_xlpm._src)),1))), _xlpm._names,'Data Pegawai'!$A$4:$A$53, _xlpm._keys,_xlfn.BYROW(_xlpm._names,_xlfn.LAMBDA(_xlpm.r,_xlfn.LET(_xlpm._s,SUBSTITUTE(_xlpm.r," ",""),_xlfn.TEXTJOIN("",TRUE,_xlfn._xlws.SORT(MID(LOWER(_xlpm._s),_xlfn.SEQUENCE(LEN(_xlpm._s)),1)))))), _xlpm._cipher,_xlfn.XLOOKUP(_xlpm._key,_xlpm._keys,'Data Pegawai'!$E$4:$E$53), _xlpm._chars,MID(_xlpm._cipher,_xlfn.SEQUENCE(LEN(_xlpm._cipher)),1), _xlpm._decoded,_xlfn.TEXTJOIN("",TRUE,_xlfn.MAP(_xlpm._chars,_xlfn.LAMBDA(_xlpm.c,IF(CODE(_xlpm.c)=33," ",IF(CODE(_xlpm.c)=65,CHAR(90),IF(CODE(_xlpm.c)=97,CHAR(122),IF(OR(AND(CODE(_xlpm.c)>65,CODE(_xlpm.c)<=90),AND(CODE(_xlpm.c)>97,CODE(_xlpm.c)<=122)),CHAR(CODE(_xlpm.c)-1),_xlpm.c))))))), _xlpm._deckey,_xlfn.LET(_xlpm._d,SUBSTITUTE(_xlpm._decoded," ",""),_xlfn.TEXTJOIN("",TRUE,_xlfn._xlws.SORT(MID(LOWER(_xlpm._d),_xlfn.SEQUENCE(LEN(_xlpm._d)),1)))), _xlpm._jabatan,'Data Pegawai'!$J$4:$J$8, _xlpm._jabkeys,_xlfn.BYROW(_xlpm._jabatan,_xlfn.LAMBDA(_xlpm.j,_xlfn.LET(_xlpm._s,SUBSTITUTE(_xlpm.j," ",""),_xlfn.TEXTJOIN("",TRUE,_xlfn._xlws.SORT(MID(LOWER(_xlpm._s),_xlfn.SEQUENCE(LEN(_xlpm._s)),1)))))), _xlfn.XLOOKUP(_xlpm._deckey,_xlpm._jabkeys,_xlpm._jabatan) )} -> Admin | I55: {=_xlfn.LET( _xlpm._raw,VLOOKUP(H55,'Data Pegawai'!$J$4:$L$8,2,0), _xlpm._e,FIND("E",_xlpm._raw), VALUE(MID(_xlpm._raw,2,_xlpm._e-2))*10^VALUE(RIGHT(_xlpm._raw,LEN(_xlpm._raw)-_xlpm._e)) )} -> 2500000 | J55: {=_xlfn.LET( _xlpm._raw,VLOOKUP(H55,'Data Pegawai'!$J$4:$L$8,3,0), _xlpm._e,FIND("E",_xlpm._raw), VALUE(MID(_xlpm._raw,2,_xlpm._e-2))*10^VALUE(RIGHT(_xlpm._raw,LEN(_xlpm._raw)-_xlpm._e)) )} -> 50000 | K55: =SUM(I55:J55) -> 2550000
B56: 10 | C56: rud kisoPaYo | D56: {=_xlfn.LET( _xlpm._src,SUBSTITUTE(C56," ",""), _xlpm._key,_xlfn.TEXTJOIN("",TRUE,_xlfn._xlws.SORT(MID(LOWER(_xlpm._src),_xlfn.SEQUENCE(LEN(_xlpm._src)),1))), _xlpm._names,'Data Pegawai'!$A$4:$A$53, _xlpm._keys,_xlfn.BYROW(_xlpm._names,_xlfn.LAMBDA(_xlpm.r,_xlfn.LET(_xlpm._s,SUBSTITUTE(_xlpm.r," ",""),_xlfn.TEXTJOIN("",TRUE,_xlfn._xlws.SORT(MID(LOWER(_xlpm._s),_xlfn.SEQUENCE(LEN(_xlpm._s)),1)))))), _xlfn.XLOOKUP(_xlpm._key,_xlpm._keys,'Data Pegawai'!$B$4:$B$53) )} -> Semarang | E56: {=_xlfn.LET( _xlpm._src,SUBSTITUTE(C56," ",""), _xlpm._key,_xlfn.TEXTJOIN("",TRUE,_xlfn._xlws.SORT(MID(LOWER(_xlpm._src),_xlfn.SEQUENCE(LEN(_xlpm._src)),1))), _xlpm._names,'Data Pegawai'!$A$4:$A$53, _xlpm._keys,_xlfn.BYROW(_xlpm._names,_xlfn.LAMBDA(_xlpm.r,_xlfn.LET(_xlpm._s,SUBSTITUTE(_xlpm.r," ",""),_xlfn.TEXTJOIN("",TRUE,_xlfn._xlws.SORT(MID(LOWER(_xlpm._s),_xlfn.SEQUENCE(LEN(_xlpm._s)),1)))))), _xlfn.XLOOKUP(_xlpm._key,_xlpm._keys,'Data Pegawai'!$C$4:$C$53) )} -> 33236 | F56: {=_xlfn.LET( _xlpm._src,SUBSTITUTE(C56," ",""), _xlpm._key,_xlfn.TEXTJOIN("",TRUE,_xlfn._xlws.SORT(MID(LOWER(_xlpm._src),_xlfn.SEQUENCE(LEN(_xlpm._src)),1))), _xlpm._names,'Data Pegawai'!$A$4:$A$53, _xlpm._keys,_xlfn.BYROW(_xlpm._names,_xlfn.LAMBDA(_xlpm.r,_xlfn.LET(_xlpm._s,SUBSTITUTE(_xlpm.r," ",""),_xlfn.TEXTJOIN("",TRUE,_xlfn._xlws.SORT(MID(LOWER(_xlpm._s),_xlfn.SEQUENCE(LEN(_xlpm._s)),1)))))), _xlfn.XLOOKUP(_xlpm._key,_xlpm._keys,'Data Pegawai'!$D$4:$D$53) )} -> 44761 | G56: {=_xlfn.LET( _xlpm._src,SUBSTITUTE(C56," ",""), _xlpm._key,_xlfn.TEXTJOIN("",TRUE,_xlfn._xlws.SORT(MID(LOWER(_xlpm._src),_xlfn.SEQUENCE(LEN(_xlpm._src)),1))), _xlpm._names,'Data Pegawai'!$A$4:$A$53, _xlpm._keys,_xlfn.BYROW(_xlpm._names,_xlfn.LAMBDA(_xlpm.r,_xlfn.LET(_xlpm._s,SUBSTITUTE(_xlpm.r," ",""),_xlfn.TEXTJOIN("",TRUE,_xlfn._xlws.SORT(MID(LOWER(_xlpm._s),_xlfn.SEQUENCE(LEN(_xlpm._s)),1)))))), _xlpm._cipher,_xlfn.XLOOKUP(_xlpm._key,_xlpm._keys,'Data Pegawai'!$E$4:$E$53), _xlpm._chars,MID(_xlpm._cipher,_xlfn.SEQUENCE(LEN(_xlpm._cipher)),1), _xlpm._decoded,_xlfn.TEXTJOIN("",TRUE,_xlfn.MAP(_xlpm._chars,_xlfn.LAMBDA(_xlpm.c,IF(CODE(_xlpm.c)=33," ",IF(CODE(_xlpm.c)=65,CHAR(90),IF(CODE(_xlpm.c)=97,CHAR(122),IF(OR(AND(CODE(_xlpm.c)>65,CODE(_xlpm.c)<=90),AND(CODE(_xlpm.c)>97,CODE(_xlpm.c)<=122)),CHAR(CODE(_xlpm.c)-1),_xlpm.c))))))), _xlpm._deckey,_xlfn.LET(_xlpm._d,SUBSTITUTE(_xlpm._decoded," ",""),_xlfn.TEXTJOIN("",TRUE,_xlfn._xlws.SORT(MID(LOWER(_xlpm._d),_xlfn.SEQUENCE(LEN(_xlpm._d)),1)))), _xlpm._jabatan,'Data Pegawai'!$J$4:$J$8, _xlpm._jabkeys,_xlfn.BYROW(_xlpm._jabatan,_xlfn.LAMBDA(_xlpm.j,_xlfn.LET(_xlpm._s,SUBSTITUTE(_xlpm.j," ",""),_xlfn.TEXTJOIN("",TRUE,_xlfn._xlws.SORT(MID(LOWER(_xlpm._s),_xlfn.SEQUENCE(LEN(_xlpm._s)),1)))))), _xlfn.XLOOKUP(_xlpm._deckey,_xlpm._jabkeys,'Data Pegawai'!$I$4:$I$8) )} -> IT | H56: {=_xlfn.LET( _xlpm._src,SUBSTITUTE(C56," ",""), _xlpm._key,_xlfn.TEXTJOIN("",TRUE,_xlfn._xlws.SORT(MID(LOWER(_xlpm._src),_xlfn.SEQUENCE(LEN(_xlpm._src)),1))), _xlpm._names,'Data Pegawai'!$A$4:$A$53, _xlpm._keys,_xlfn.BYROW(_xlpm._names,_xlfn.LAMBDA(_xlpm.r,_xlfn.LET(_xlpm._s,SUBSTITUTE(_xlpm.r," ",""),_xlfn.TEXTJOIN("",TRUE,_xlfn._xlws.SORT(MID(LOWER(_xlpm._s),_xlfn.SEQUENCE(LEN(_xlpm._s)),1)))))), _xlpm._cipher,_xlfn.XLOOKUP(_xlpm._key,_xlpm._keys,'Data Pegawai'!$E$4:$E$53), _xlpm._chars,MID(_xlpm._cipher,_xlfn.SEQUENCE(LEN(_xlpm._cipher)),1), _xlpm._decoded,_xlfn.TEXTJOIN("",TRUE,_xlfn.MAP(_xlpm._chars,_xlfn.LAMBDA(_xlpm.c,IF(CODE(_xlpm.c)=33," ",IF(CODE(_xlpm.c)=65,CHAR(90),IF(CODE(_xlpm.c)=97,CHAR(122),IF(OR(AND(CODE(_xlpm.c)>65,CODE(_xlpm.c)<=90),AND(CODE(_xlpm.c)>97,CODE(_xlpm.c)<=122)),CHAR(CODE(_xlpm.c)-1),_xlpm.c))))))), _xlpm._deckey,_xlfn.LET(_xlpm._d,SUBSTITUTE(_xlpm._decoded," ",""),_xlfn.TEXTJOIN("",TRUE,_xlfn._xlws.SORT(MID(LOWER(_xlpm._d),_xlfn.SEQUENCE(LEN(_xlpm._d)),1)))), _xlpm._jabatan,'Data Pegawai'!$J$4:$J$8, _xlpm._jabkeys,_xlfn.BYROW(_xlpm._jabatan,_xlfn.LAMBDA(_xlpm.j,_xlfn.LET(_xlpm._s,SUBSTITUTE(_xlpm.j," ",""),_xlfn.TEXTJOIN("",TRUE,_xlfn._xlws.SORT(MID(LOWER(_xlpm._s),_xlfn.SEQUENCE(LEN(_xlpm._s)),1)))))), _xlfn.XLOOKUP(_xlpm._deckey,_xlpm._jabkeys,_xlpm._jabatan) )} -> IT Support | I56: {=_xlfn.LET( _xlpm._raw,VLOOKUP(H56,'Data Pegawai'!$J$4:$L$8,2,0), _xlpm._e,FIND("E",_xlpm._raw), VALUE(MID(_xlpm._raw,2,_xlpm._e-2))*10^VALUE(RIGHT(_xlpm._raw,LEN(_xlpm._raw)-_xlpm._e)) )} -> 3000000 | J56: {=_xlfn.LET( _xlpm._raw,VLOOKUP(H56,'Data Pegawai'!$J$4:$L$8,3,0), _xlpm._e,FIND("E",_xlpm._raw), VALUE(MID(_xlpm._raw,2,_xlpm._e-2))*10^VALUE(RIGHT(_xlpm._raw,LEN(_xlpm._raw)-_xlpm._e)) )} -> 500000 | K56: =SUM(I56:J56) -> 3500000
B57: 11 | C57: aWi iSnrlaardu | D57: {=_xlfn.LET( _xlpm._src,SUBSTITUTE(C57," ",""), _xlpm._key,_xlfn.TEXTJOIN("",TRUE,_xlfn._xlws.SORT(MID(LOWER(_xlpm._src),_xlfn.SEQUENCE(LEN(_xlpm._src)),1))), _xlpm._names,'Data Pegawai'!$A$4:$A$53, _xlpm._keys,_xlfn.BYROW(_xlpm._names,_xlfn.LAMBDA(_xlpm.r,_xlfn.LET(_xlpm._s,SUBSTITUTE(_xlpm.r," ",""),_xlfn.TEXTJOIN("",TRUE,_xlfn._xlws.SORT(MID(LOWER(_xlpm._s),_xlfn.SEQUENCE(LEN(_xlpm._s)),1)))))), _xlfn.XLOOKUP(_xlpm._key,_xlpm._keys,'Data Pegawai'!$B$4:$B$53) )} -> Palembang | E57: {=_xlfn.LET( _xlpm._src,SUBSTITUTE(C57," ",""), _xlpm._key,_xlfn.TEXTJOIN("",TRUE,_xlfn._xlws.SORT(MID(LOWER(_xlpm._src),_xlfn.SEQUENCE(LEN(_xlpm._src)),1))), _xlpm._names,'Data Pegawai'!$A$4:$A$53, _xlpm._keys,_xlfn.BYROW(_xlpm._names,_xlfn.LAMBDA(_xlpm.r,_xlfn.LET(_xlpm._s,SUBSTITUTE(_xlpm.r," ",""),_xlfn.TEXTJOIN("",TRUE,_xlfn._xlws.SORT(MID(LOWER(_xlpm._s),_xlfn.SEQUENCE(LEN(_xlpm._s)),1)))))), _xlfn.XLOOKUP(_xlpm._key,_xlpm._keys,'Data Pegawai'!$C$4:$C$53) )} -> 33698 | F57: {=_xlfn.LET( _xlpm._src,SUBSTITUTE(C57," ",""), _xlpm._key,_xlfn.TEXTJOIN("",TRUE,_xlfn._xlws.SORT(MID(LOWER(_xlpm._src),_xlfn.SEQUENCE(LEN(_xlpm._src)),1))), _xlpm._names,'Data Pegawai'!$A$4:$A$53, _xlpm._keys,_xlfn.BYROW(_xlpm._names,_xlfn.LAMBDA(_xlpm.r,_xlfn.LET(_xlpm._s,SUBSTITUTE(_xlpm.r," ",""),_xlfn.TEXTJOIN("",TRUE,_xlfn._xlws.SORT(MID(LOWER(_xlpm._s),_xlfn.SEQUENCE(LEN(_xlpm._s)),1)))))), _xlfn.XLOOKUP(_xlpm._key,_xlpm._keys,'Data Pegawai'!$D$4:$D$53) )} -> 45148 | G57: {=_xlfn.LET( _xlpm._src,SUBSTITUTE(C57," ",""), _xlpm._key,_xlfn.TEXTJOIN("",TRUE,_xlfn._xlws.SORT(MID(LOWER(_xlpm._src),_xlfn.SEQUENCE(LEN(_xlpm._src)),1))), _xlpm._names,'Data Pegawai'!$A$4:$A$53, _xlpm._keys,_xlfn.BYROW(_xlpm._names,_xlfn.LAMBDA(_xlpm.r,_xlfn.LET(_xlpm._s,SUBSTITUTE(_xlpm.r," ",""),_xlfn.TEXTJOIN("",TRUE,_xlfn._xlws.SORT(MID(LOWER(_xlpm._s),_xlfn.SEQUENCE(LEN(_xlpm._s)),1)))))), _xlpm._cipher,_xlfn.XLOOKUP(_xlpm._key,_xlpm._keys,'Data Pegawai'!$E$4:$E$53), _xlpm._chars,MID(_xlpm._cipher,_xlfn.SEQUENCE(LEN(_xlpm._cipher)),1), _xlpm._decoded,_xlfn.TEXTJOIN("",TRUE,_xlfn.MAP(_xlpm._chars,_xlfn.LAMBDA(_xlpm.c,IF(CODE(_xlpm.c)=33," ",IF(CODE(_xlpm.c)=65,CHAR(90),IF(CODE(_xlpm.c)=97,CHAR(122),IF(OR(AND(CODE(_xlpm.c)>65,CODE(_xlpm.c)<=90),AND(CODE(_xlpm.c)>97,CODE(_xlpm.c)<=122)),CHAR(CODE(_xlpm.c)-1),_xlpm.c))))))), _xlpm._deckey,_xlfn.LET(_xlpm._d,SUBSTITUTE(_xlpm._decoded," ",""),_xlfn.TEXTJOIN("",TRUE,_xlfn._xlws.SORT(MID(LOWER(_xlpm._d),_xlfn.SEQUENCE(LEN(_xlpm._d)),1)))), _xlpm._jabatan,'Data Pegawai'!$J$4:$J$8, _xlpm._jabkeys,_xlfn.BYROW(_xlpm._jabatan,_xlfn.LAMBDA(_xlpm.j,_xlfn.LET(_xlpm._s,SUBSTITUTE(_xlpm.j," ",""),_xlfn.TEXTJOIN("",TRUE,_xlfn._xlws.SORT(MID(LOWER(_xlpm._s),_xlfn.SEQUENCE(LEN(_xlpm._s)),1)))))), _xlfn.XLOOKUP(_xlpm._deckey,_xlpm._jabkeys,'Data Pegawai'!$I$4:$I$8) )} -> MKT | H57: {=_xlfn.LET( _xlpm._src,SUBSTITUTE(C57," ",""), _xlpm._key,_xlfn.TEXTJOIN("",TRUE,_xlfn._xlws.SORT(MID(LOWER(_xlpm._src),_xlfn.SEQUENCE(LEN(_xlpm._src)),1))), _xlpm._names,'Data Pegawai'!$A$4:$A$53, _xlpm._keys,_xlfn.BYROW(_xlpm._names,_xlfn.LAMBDA(_xlpm.r,_xlfn.LET(_xlpm._s,SUBSTITUTE(_xlpm.r," ",""),_xlfn.TEXTJOIN("",TRUE,_xlfn._xlws.SORT(MID(LOWER(_xlpm._s),_xlfn.SEQUENCE(LEN(_xlpm._s)),1)))))), _xlpm._cipher,_xlfn.XLOOKUP(_xlpm._key,_xlpm._keys,'Data Pegawai'!$E$4:$E$53), _xlpm._chars,MID(_xlpm._cipher,_xlfn.SEQUENCE(LEN(_xlpm._cipher)),1), _xlpm._decoded,_xlfn.TEXTJOIN("",TRUE,_xlfn.MAP(_xlpm._chars,_xlfn.LAMBDA(_xlpm.c,IF(CODE(_xlpm.c)=33," ",IF(CODE(_xlpm.c)=65,CHAR(90),IF(CODE(_xlpm.c)=97,CHAR(122),IF(OR(AND(CODE(_xlpm.c)>65,CODE(_xlpm.c)<=90),AND(CODE(_xlpm.c)>97,CODE(_xlpm.c)<=122)),CHAR(CODE(_xlpm.c)-1),_xlpm.c))))))), _xlpm._deckey,_xlfn.LET(_xlpm._d,SUBSTITUTE(_xlpm._decoded," ",""),_xlfn.TEXTJOIN("",TRUE,_xlfn._xlws.SORT(MID(LOWER(_xlpm._d),_xlfn.SEQUENCE(LEN(_xlpm._d)),1)))), _xlpm._jabatan,'Data Pegawai'!$J$4:$J$8, _xlpm._jabkeys,_xlfn.BYROW(_xlpm._jabatan,_xlfn.LAMBDA(_xlpm.j,_xlfn.LET(_xlpm._s,SUBSTITUTE(_xlpm.j," ",""),_xlfn.TEXTJOIN("",TRUE,_xlfn._xlws.SORT(MID(LOWER(_xlpm._s),_xlfn.SEQUENCE(LEN(_xlpm._s)),1)))))), _xlfn.XLOOKUP(_xlpm._deckey,_xlpm._jabkeys,_xlpm._jabatan) )} -> Marketing | I57: {=_xlfn.LET( _xlpm._raw,VLOOKUP(H57,'Data Pegawai'!$J$4:$L$8,2,0), _xlpm._e,FIND("E",_xlpm._raw), VALUE(MID(_xlpm._raw,2,_xlpm._e-2))*10^VALUE(RIGHT(_xlpm._raw,LEN(_xlpm._raw)-_xlpm._e)) )} -> 4500000 | J57: {=_xlfn.LET( _xlpm._raw,VLOOKUP(H57,'Data Pegawai'!$J$4:$L$8,3,0), _xlpm._e,FIND("E",_xlpm._raw), VALUE(MID(_xlpm._raw,2,_xlpm._e-2))*10^VALUE(RIGHT(_xlpm._raw,LEN(_xlpm._raw)-_xlpm._e)) )} -> 100000 | K57: =SUM(I57:J57) -> 4600000
B58: 12 | C58: rnaD tikaaiK | D58: {=_xlfn.LET( _xlpm._src,SUBSTITUTE(C58," ",""), _xlpm._key,_xlfn.TEXTJOIN("",TRUE,_xlfn._xlws.SORT(MID(LOWER(_xlpm._src),_xlfn.SEQUENCE(LEN(_xlpm._src)),1))), _xlpm._names,'Data Pegawai'!$A$4:$A$53, _xlpm._keys,_xlfn.BYROW(_xlpm._names,_xlfn.LAMBDA(_xlpm.r,_xlfn.LET(_xlpm._s,SUBSTITUTE(_xlpm.r," ",""),_xlfn.TEXTJOIN("",TRUE,_xlfn._xlws.SORT(MID(LOWER(_xlpm._s),_xlfn.SEQUENCE(LEN(_xlpm._s)),1)))))), _xlfn.XLOOKUP(_xlpm._key,_xlpm._keys,'Data Pegawai'!$B$4:$B$53) )} -> Medan | E58: {=_xlfn.LET( _xlpm._src,SUBSTITUTE(C58," ",""), _xlpm._key,_xlfn.TEXTJOIN("",TRUE,_xlfn._xlws.SORT(MID(LOWER(_xlpm._src),_xlfn.SEQUENCE(LEN(_xlpm._src)),1))), _xlpm._names,'Data Pegawai'!$A$4:$A$53, _xlpm._keys,_xlfn.BYROW(_xlpm._names,_xlfn.LAMBDA(_xlpm.r,_xlfn.LET(_xlpm._s,SUBSTITUTE(_xlpm.r," ",""),_xlfn.TEXTJOIN("",TRUE,_xlfn._xlws.SORT(MID(LOWER(_xlpm._s),_xlfn.SEQUENCE(LEN(_xlpm._s)),1)))))), _xlfn.XLOOKUP(_xlpm._key,_xlpm._keys,'Data Pegawai'!$C$4:$C$53) )} -> 31930 | F58: {=_xlfn.LET( _xlpm._src,SUBSTITUTE(C58," ",""), _xlpm._key,_xlfn.TEXTJOIN("",TRUE,_xlfn._xlws.SORT(MID(LOWER(_xlpm._src),_xlfn.SEQUENCE(LEN(_xlpm._src)),1))), _xlpm._names,'Data Pegawai'!$A$4:$A$53, _xlpm._keys,_xlfn.BYROW(_xlpm._names,_xlfn.LAMBDA(_xlpm.r,_xlfn.LET(_xlpm._s,SUBSTITUTE(_xlpm.r," ",""),_xlfn.TEXTJOIN("",TRUE,_xlfn._xlws.SORT(MID(LOWER(_xlpm._s),_xlfn.SEQUENCE(LEN(_xlpm._s)),1)))))), _xlfn.XLOOKUP(_xlpm._key,_xlpm._keys,'Data Pegawai'!$D$4:$D$53) )} -> 42136 | G58: {=_xlfn.LET( _xlpm._src,SUBSTITUTE(C58," ",""), _xlpm._key,_xlfn.TEXTJOIN("",TRUE,_xlfn._xlws.SORT(MID(LOWER(_xlpm._src),_xlfn.SEQUENCE(LEN(_xlpm._src)),1))), _xlpm._names,'Data Pegawai'!$A$4:$A$53, _xlpm._keys,_xlfn.BYROW(_xlpm._names,_xlfn.LAMBDA(_xlpm.r,_xlfn.LET(_xlpm._s,SUBSTITUTE(_xlpm.r," ",""),_xlfn.TEXTJOIN("",TRUE,_xlfn._xlws.SORT(MID(LOWER(_xlpm._s),_xlfn.SEQUENCE(LEN(_xlpm._s)),1)))))), _xlpm._cipher,_xlfn.XLOOKUP(_xlpm._key,_xlpm._keys,'Data Pegawai'!$E$4:$E$53), _xlpm._chars,MID(_xlpm._cipher,_xlfn.SEQUENCE(LEN(_xlpm._cipher)),1), _xlpm._decoded,_xlfn.TEXTJOIN("",TRUE,_xlfn.MAP(_xlpm._chars,_xlfn.LAMBDA(_xlpm.c,IF(CODE(_xlpm.c)=33," ",IF(CODE(_xlpm.c)=65,CHAR(90),IF(CODE(_xlpm.c)=97,CHAR(122),IF(OR(AND(CODE(_xlpm.c)>65,CODE(_xlpm.c)<=90),AND(CODE(_xlpm.c)>97,CODE(_xlpm.c)<=122)),CHAR(CODE(_xlpm.c)-1),_xlpm.c))))))), _xlpm._deckey,_xlfn.LET(_xlpm._d,SUBSTITUTE(_xlpm._decoded," ",""),_xlfn.TEXTJOIN("",TRUE,_xlfn._xlws.SORT(MID(LOWER(_xlpm._d),_xlfn.SEQUENCE(LEN(_xlpm._d)),1)))), _xlpm._jabatan,'Data Pegawai'!$J$4:$J$8, _xlpm._jabkeys,_xlfn.BYROW(_xlpm._jabatan,_xlfn.LAMBDA(_xlpm.j,_xlfn.LET(_xlpm._s,SUBSTITUTE(_xlpm.j," ",""),_xlfn.TEXTJOIN("",TRUE,_xlfn._xlws.SORT(MID(LOWER(_xlpm._s),_xlfn.SEQUENCE(LEN(_xlpm._s)),1)))))), _xlfn.XLOOKUP(_xlpm._deckey,_xlpm._jabkeys,'Data Pegawai'!$I$4:$I$8) )} -> SPV | H58: {=_xlfn.LET( _xlpm._src,SUBSTITUTE(C58," ",""), _xlpm._key,_xlfn.TEXTJOIN("",TRUE,_xlfn._xlws.SORT(MID(LOWER(_xlpm._src),_xlfn.SEQUENCE(LEN(_xlpm._src)),1))), _xlpm._names,'Data Pegawai'!$A$4:$A$53, _xlpm._keys,_xlfn.BYROW(_xlpm._names,_xlfn.LAMBDA(_xlpm.r,_xlfn.LET(_xlpm._s,SUBSTITUTE(_xlpm.r," ",""),_xlfn.TEXTJOIN("",TRUE,_xlfn._xlws.SORT(MID(LOWER(_xlpm._s),_xlfn.SEQUENCE(LEN(_xlpm._s)),1)))))), _xlpm._cipher,_xlfn.XLOOKUP(_xlpm._key,_xlpm._keys,'Data Pegawai'!$E$4:$E$53), _xlpm._chars,MID(_xlpm._cipher,_xlfn.SEQUENCE(LEN(_xlpm._cipher)),1), _xlpm._decoded,_xlfn.TEXTJOIN("",TRUE,_xlfn.MAP(_xlpm._chars,_xlfn.LAMBDA(_xlpm.c,IF(CODE(_xlpm.c)=33," ",IF(CODE(_xlpm.c)=65,CHAR(90),IF(CODE(_xlpm.c)=97,CHAR(122),IF(OR(AND(CODE(_xlpm.c)>65,CODE(_xlpm.c)<=90),AND(CODE(_xlpm.c)>97,CODE(_xlpm.c)<=122)),CHAR(CODE(_xlpm.c)-1),_xlpm.c))))))), _xlpm._deckey,_xlfn.LET(_xlpm._d,SUBSTITUTE(_xlpm._decoded," ",""),_xlfn.TEXTJOIN("",TRUE,_xlfn._xlws.SORT(MID(LOWER(_xlpm._d),_xlfn.SEQUENCE(LEN(_xlpm._d)),1)))), _xlpm._jabatan,'Data Pegawai'!$J$4:$J$8, _xlpm._jabkeys,_xlfn.BYROW(_xlpm._jabatan,_xlfn.LAMBDA(_xlpm.j,_xlfn.LET(_xlpm._s,SUBSTITUTE(_xlpm.j," ",""),_xlfn.TEXTJOIN("",TRUE,_xlfn._xlws.SORT(MID(LOWER(_xlpm._s),_xlfn.SEQUENCE(LEN(_xlpm._s)),1)))))), _xlfn.XLOOKUP(_xlpm._deckey,_xlpm._jabkeys,_xlpm._jabatan) )} -> Supervisor | I58: {=_xlfn.LET( _xlpm._raw,VLOOKUP(H58,'Data Pegawai'!$J$4:$L$8,2,0), _xlpm._e,FIND("E",_xlpm._raw), VALUE(MID(_xlpm._raw,2,_xlpm._e-2))*10^VALUE(RIGHT(_xlpm._raw,LEN(_xlpm._raw)-_xlpm._e)) )} -> 5000000 | J58: {=_xlfn.LET( _xlpm._raw,VLOOKUP(H58,'Data Pegawai'!$J$4:$L$8,3,0), _xlpm._e,FIND("E",_xlpm._raw), VALUE(MID(_xlpm._raw,2,_xlpm._e-2))*10^VALUE(RIGHT(_xlpm._raw,LEN(_xlpm._raw)-_xlpm._e)) )} -> 150000 | K58: =SUM(I58:J58) -> 5150000
