Workbook
Name kode_jawaban: DF!$D$68

Sheet XL-Test
A17: KODE SOAL | C17: SBEX001 | E17: KODE JAWABAN | F17: =kode_jawaban -> XA3|151-95F1;211-87F1;681-824C41;BC1-53DA041;801-FD3DB1;111-78C1;1D1-169541;1B1-4BBED21;261-3C514F1;121-19067C61
A19: Intruksi
B21: Extreme Level - Latihan Soal VLOOKUP dan HLOOKUP Extreme
B23: Soal : | C23: Gunakan Fungsi Excel (Function) untuk menyelsaikan kasus dibawah ini sesuai petunjuk soal, dan dilarang mengubah Table yang sudah ada
B24: 1 | C24: Isi Nama Pelanggan berdasarkan Tabel Daftar Pelanggan dengan fungsi VLOOKUP
B25: 2 | C25: Isi Nama Produk berdasarkan Tabel Daftar Produk Dengan fungsi VLOOKUP
B26: 3 | C26: Isi Harga Satuan berdasarkan tabel Daftar Produk Dengan fungsi VLOOKUP
B27: 4 | C27: Total Penjualan adalah Qty dikali Harga Satuan
B28: 5 | C28: Isi Diskon berdasarkan table diskon dengan HLOOKUP dan dikali Total Penjualan
B29: 6 | C29: Isi Item Bonus, Jika QTY 0-10 Bonus "iPhone XR", jika QTY 11-15 Bonus "Samsung S20",
C30: Jika Lebih dari 15 Bonus , "Mendoan", dan gunakan rumus VLOOKUP
B31: 7 | C31: Harga Bonus diambil dari Table Harga Bonus Gunakan VLOOKUP
B32: 8 | C32: Penjualan Bersih adalah Total Penjualan dikurangi Diskon dikurangi Harga Bonus
B33: 9 | C33: Totalkan semua Qty dan Penjualan Bersih
B34: 10 | C34: Rata-Ratakan semua Qty dan Penjualan Bersih
C36: Sudah selesai mengerjakan? kirim Kode Soal dan Kode Jawaban diatas ke alamat : https://belajarexcel.id/xl-test/jawaban untuk mengecek hasilnya
C37: atau klik tombol disamping
A42: DAFTAR PENJUALAN
E44: 1 | G44: 2 | I44: 3 | J44: 4 | K44: 5 | L44: 6 | M44: 7 | N44: 8
A45: No | C45: Tanggal | D45: Kode Pelanggan | E45: Nama Pelanggan | F45: Kode Produk | G45: Nama Produk | H45: Qty | I45: Harga Satuan | J45: Total Penjualan | K45: Diskon | L45: Item Bonus | M45: Harga Bonus | N45: Penjualan Bersih
A46: 1 | C46: 45139 | D46: P-002 | E46: {=VLOOKUP(D46,TRANSPOSE($B$67:$E$68),2,0)} -> Toko Bagus | F46: B003 | G46: =MID(VLOOKUP("*"&F46&"*",$G$68:$I$72,1,FALSE),6,100) -> Pembersih Lantai | H46: 2 | I46: =VLOOKUP("*"&F46&"*",$G$68:$I$72,3,FALSE) -> 30200 | J46: =SUMPRODUCT(H46,I46) -> 60400 | K46: {=HLOOKUP(H46,TRANSPOSE($K$67:$M$70),3,TRUE)*J46} -> 3020 | L46: =VLOOKUP(H46,{0,"iPhone XR";11,"Samsung S20";16,"Mendoan"},2,1) -> iPhone XR | M46: =VLOOKUP(L46,IF({1,0},$E$73:$E$75,$D$73:$D$75),2,0) -> 4500 | N46: =J46-K46-M46 -> 52880
A47: 2 | C47: 45139 | D47: P-001 | E47: {=VLOOKUP(D47,TRANSPOSE($B$67:$E$68),2,0)} -> Toko Cemerlang | F47: B004 | G47: =MID(VLOOKUP("*"&F47&"*",$G$68:$I$72,1,FALSE),6,100) -> Pewangi Pakaian | H47: 7 | I47: =VLOOKUP("*"&F47&"*",$G$68:$I$72,3,FALSE) -> 32500 | J47: =SUMPRODUCT(H47,I47) -> 227500 | K47: {=HLOOKUP(H47,TRANSPOSE($K$67:$M$70),3,TRUE)*J47} -> 11375 | L47: =VLOOKUP(H47,{0,"iPhone XR";11,"Samsung S20";16,"Mendoan"},2,1) -> iPhone XR | M47: =VLOOKUP(L47,IF({1,0},$E$73:$E$75,$D$73:$D$75),2,0) -> 4500 | N47: =J47-K47-M47 -> 211625
A48: 3 | C48: 45140 | D48: P-003 | E48: {=VLOOKUP(D48,TRANSPOSE($B$67:$E$68),2,0)} -> Toko Bahagia | F48: B002 | G48: =MID(VLOOKUP("*"&F48&"*",$G$68:$I$72,1,FALSE),6,100) -> Sabun Cuci Piring | H48: 17 | I48: =VLOOKUP("*"&F48&"*",$G$68:$I$72,3,FALSE) -> 19900 | J48: =SUMPRODUCT(H48,I48) -> 338300 | K48: {=HLOOKUP(H48,TRANSPOSE($K$67:$M$70),3,TRUE)*J48} -> 84575 | L48: =VLOOKUP(H48,{0,"iPhone XR";11,"Samsung S20";16,"Mendoan"},2,1) -> Mendoan | M48: =VLOOKUP(L48,IF({1,0},$E$73:$E$75,$D$73:$D$75),2,0) -> 7500 | N48: =J48-K48-M48 -> 246225
A49: 4 | C49: 45140 | D49: P-002 | E49: {=VLOOKUP(D49,TRANSPOSE($B$67:$E$68),2,0)} -> Toko Bagus | F49: B003 | G49: =MID(VLOOKUP("*"&F49&"*",$G$68:$I$72,1,FALSE),6,100) -> Pembersih Lantai | H49: 9 | I49: =VLOOKUP("*"&F49&"*",$G$68:$I$72,3,FALSE) -> 30200 | J49: =SUMPRODUCT(H49,I49) -> 271800 | K49: {=HLOOKUP(H49,TRANSPOSE($K$67:$M$70),3,TRUE)*J49} -> 13590 | L49: =VLOOKUP(H49,{0,"iPhone XR";11,"Samsung S20";16,"Mendoan"},2,1) -> iPhone XR | M49: =VLOOKUP(L49,IF({1,0},$E$73:$E$75,$D$73:$D$75),2,0) -> 4500 | N49: =J49-K49-M49 -> 253710
A50: 5 | C50: 45141 | D50: P-001 | E50: {=VLOOKUP(D50,TRANSPOSE($B$67:$E$68),2,0)} -> Toko Cemerlang | F50: B003 | G50: =MID(VLOOKUP("*"&F50&"*",$G$68:$I$72,1,FALSE),6,100) -> Pembersih Lantai | H50: 14 | I50: =VLOOKUP("*"&F50&"*",$G$68:$I$72,3,FALSE) -> 30200 | J50: =SUMPRODUCT(H50,I50) -> 422800 | K50: {=HLOOKUP(H50,TRANSPOSE($K$67:$M$70),3,TRUE)*J50} -> 42280 | L50: =VLOOKUP(H50,{0,"iPhone XR";11,"Samsung S20";16,"Mendoan"},2,1) -> Samsung S20 | M50: =VLOOKUP(L50,IF({1,0},$E$73:$E$75,$D$73:$D$75),2,0) -> 3500 | N50: =J50-K50-M50 -> 377020
A51: 6 | C51: 45142 | D51: P-002 | E51: {=VLOOKUP(D51,TRANSPOSE($B$67:$E$68),2,0)} -> Toko Bagus | F51: B002 | G51: =MID(VLOOKUP("*"&F51&"*",$G$68:$I$72,1,FALSE),6,100) -> Sabun Cuci Piring | H51: 7 | I51: =VLOOKUP("*"&F51&"*",$G$68:$I$72,3,FALSE) -> 19900 | J51: =SUMPRODUCT(H51,I51) -> 139300 | K51: {=HLOOKUP(H51,TRANSPOSE($K$67:$M$70),3,TRUE)*J51} -> 6965 | L51: =VLOOKUP(H51,{0,"iPhone XR";11,"Samsung S20";16,"Mendoan"},2,1) -> iPhone XR | M51: =VLOOKUP(L51,IF({1,0},$E$73:$E$75,$D$73:$D$75),2,0) -> 4500 | N51: =J51-K51-M51 -> 127835
A52: 7 | C52: 45143 | D52: P-001 | E52: {=VLOOKUP(D52,TRANSPOSE($B$67:$E$68),2,0)} -> Toko Cemerlang | F52: B005 | G52: =MID(VLOOKUP("*"&F52&"*",$G$68:$I$72,1,FALSE),6,100) -> Minyak Goreng | H52: 10 | I52: =VLOOKUP("*"&F52&"*",$G$68:$I$72,3,FALSE) -> 23600 | J52: =SUMPRODUCT(H52,I52) -> 236000 | K52: {=HLOOKUP(H52,TRANSPOSE($K$67:$M$70),3,TRUE)*J52} -> 11800 | L52: =VLOOKUP(H52,{0,"iPhone XR";11,"Samsung S20";16,"Mendoan"},2,1) -> iPhone XR | M52: =VLOOKUP(L52,IF({1,0},$E$73:$E$75,$D$73:$D$75),2,0) -> 4500 | N52: =J52-K52-M52 -> 219700
A53: 8 | C53: 45144 | D53: P-002 | E53: {=VLOOKUP(D53,TRANSPOSE($B$67:$E$68),2,0)} -> Toko Bagus | F53: B003 | G53: =MID(VLOOKUP("*"&F53&"*",$G$68:$I$72,1,FALSE),6,100) -> Pembersih Lantai | H53: 24 | I53: =VLOOKUP("*"&F53&"*",$G$68:$I$72,3,FALSE) -> 30200 | J53: =SUMPRODUCT(H53,I53) -> 724800 | K53: {=HLOOKUP(H53,TRANSPOSE($K$67:$M$70),3,TRUE)*J53} -> 181200 | L53: =VLOOKUP(H53,{0,"iPhone XR";11,"Samsung S20";16,"Mendoan"},2,1) -> Mendoan | M53: =VLOOKUP(L53,IF({1,0},$E$73:$E$75,$D$73:$D$75),2,0) -> 7500 | N53: =J53-K53-M53 -> 536100
A54: 9 | C54: 45145 | D54: P-001 | E54: {=VLOOKUP(D54,TRANSPOSE($B$67:$E$68),2,0)} -> Toko Cemerlang | F54: B005 | G54: =MID(VLOOKUP("*"&F54&"*",$G$68:$I$72,1,FALSE),6,100) -> Minyak Goreng | H54: 11 | I54: =VLOOKUP("*"&F54&"*",$G$68:$I$72,3,FALSE) -> 23600 | J54: =SUMPRODUCT(H54,I54) -> 259600 | K54: {=HLOOKUP(H54,TRANSPOSE($K$67:$M$70),3,TRUE)*J54} -> 25960 | L54: =VLOOKUP(H54,{0,"iPhone XR";11,"Samsung S20";16,"Mendoan"},2,1) -> Samsung S20 | M54: =VLOOKUP(L54,IF({1,0},$E$73:$E$75,$D$73:$D$75),2,0) -> 3500 | N54: =J54-K54-M54 -> 230140
A55: 10 | C55: 45146 | D55: P-002 | E55: {=VLOOKUP(D55,TRANSPOSE($B$67:$E$68),2,0)} -> Toko Bagus | F55: B003 | G55: =MID(VLOOKUP("*"&F55&"*",$G$68:$I$72,1,FALSE),6,100) -> Pembersih Lantai | H55: 7 | I55: =VLOOKUP("*"&F55&"*",$G$68:$I$72,3,FALSE) -> 30200 | J55: =SUMPRODUCT(H55,I55) -> 211400 | K55: {=HLOOKUP(H55,TRANSPOSE($K$67:$M$70),3,TRUE)*J55} -> 10570 | L55: =VLOOKUP(H55,{0,"iPhone XR";11,"Samsung S20";16,"Mendoan"},2,1) -> iPhone XR | M55: =VLOOKUP(L55,IF({1,0},$E$73:$E$75,$D$73:$D$75),2,0) -> 4500 | N55: =J55-K55-M55 -> 196330
A56: 11 | C56: 45146 | D56: P-003 | E56: {=VLOOKUP(D56,TRANSPOSE($B$67:$E$68),2,0)} -> Toko Bahagia | F56: B004 | G56: =MID(VLOOKUP("*"&F56&"*",$G$68:$I$72,1,FALSE),6,100) -> Pewangi Pakaian | H56: 24 | I56: =VLOOKUP("*"&F56&"*",$G$68:$I$72,3,FALSE) -> 32500 | J56: =SUMPRODUCT(H56,I56) -> 780000 | K56: {=HLOOKUP(H56,TRANSPOSE($K$67:$M$70),3,TRUE)*J56} -> 195000 | L56: =VLOOKUP(H56,{0,"iPhone XR";11,"Samsung S20";16,"Mendoan"},2,1) -> Mendoan | M56: =VLOOKUP(L56,IF({1,0},$E$73:$E$75,$D$73:$D$75),2,0) -> 7500 | N56: =J56-K56-M56 -> 577500
A57: 12 | C57: 45147 | D57: P-002 | E57: {=VLOOKUP(D57,TRANSPOSE($B$67:$E$68),2,0)} -> Toko Bagus | F57: B001 | G57: =MID(VLOOKUP("*"&F57&"*",$G$68:$I$72,1,FALSE),6,100) -> Detergen | H57: 2 | I57: =VLOOKUP("*"&F57&"*",$G$68:$I$72,3,FALSE) -> 28000 | J57: =SUMPRODUCT(H57,I57) -> 56000 | K57: {=HLOOKUP(H57,TRANSPOSE($K$67:$M$70),3,TRUE)*J57} -> 2800 | L57: =VLOOKUP(H57,{0,"iPhone XR";11,"Samsung S20";16,"Mendoan"},2,1) -> iPhone XR | M57: =VLOOKUP(L57,IF({1,0},$E$73:$E$75,$D$73:$D$75),2,0) -> 4500 | N57: =J57-K57-M57 -> 48700
... A60: 15 | C60: 45149 | D60: P-003 | E60: {=VLOOKUP(D60,TRANSPOSE($B$67:$E$68),2,0)} -> Toko Bahagia | F60: B003 | G60: =MID(VLOOKUP("*"&F60&"*",$G$68:$I$72,1,FALSE),6,100) -> Pembersih Lantai | H60: 23 | I60: =VLOOKUP("*"&F60&"*",$G$68:$I$72,3,FALSE) -> 30200 | J60: =SUMPRODUCT(H60,I60) -> 694600 | K60: {=HLOOKUP(H60,TRANSPOSE($K$67:$M$70),3,TRUE)*J60} -> 173650 | L60: =VLOOKUP(H60,{0,"iPhone XR";11,"Samsung S20";16,"Mendoan"},2,1) -> Mendoan | M60: =VLOOKUP(L60,IF({1,0},$E$73:$E$75,$D$73:$D$75),2,0) -> 7500 | N60: =J60-K60-M60 -> 513450
F61: 9 | G61: Total | H61: =SUM(H46:H60) -> 170 | L61: 9 | M61: Total | N61: =SUM(N46:N60) -> 3935975
F62: 10 | G62: Rata-Rata | H62: =AVERAGE(H46:H60) -> 11.333333 | L62: 10 | M62: Rata-Rata | N62: =AVERAGE(N46:N60) -> 262398.33
B66: Daftar Pelanggan | G66: Daftar Produk | K66: Total Diskon
B67: Kode | C67: P-001 | D67: P-002 | E67: P-003 | G67: Kode | I67: Harga Satuan | K67: QTY Min | L67: QTY Max | M67: Diskon
B68: Nama | C68: Toko Cemerlang | D68: Toko Bagus | E68: Toko Bahagia | G68: B001-Detergen | I68: 28000 | K68: 0 | L68: 10 | M68: 0.05
G69: B002-Sabun Cuci Piring | I69: 19900 | K69: 11 | L69: 15 | M69: 0.1
G70: B003-Pembersih Lantai | I70: 30200 | K70: 16 | L70: dst | M70: 0.25
...

Sheet About
I6: XL-TEST adalah platform inovatif yang menyediakan latihan Excel interaktif dengan pemeriksaan otomatis,
I7: sehingga pengguna dapat langsung mengetahui jawaban yang benar maupun salah.
I10: Terdapat 5 Level soal :
J12: Easy Level | L12: (⭐)
J13: Medium Level | L13: (⭐⭐)
J14: Hard Level | L14: (⭐⭐⭐)
J15: Extreme Level | L15: (⭐⭐⭐⭐)
J16: Championship Level | L16: (⭐⭐⭐⭐⭐)
B17: Saya adalah seorang Excel Holic yang percaya bahwa setiap angka memiliki cerita yang bisa ditemukan dengan cara yang tepat. | I17: Free Access
B18: “Excel bukan cuma soal kerjaan tapi juga hobi yang aku nikmati.” | I18: https://belajarexcel.id/xl-test/
B19: Contact :
B20: 🌐 Web | C20: https://setiadi.me
B21: 🪡threads | C21: https://www.threads.com/@andisetiadi
D27: Perlu Video Penjelasan atau Kunci Jawaban ?
D28: Scan barcode atau kunjungi
D29: https://lynk.id/setiadi/page/jawaban-xl-test

Sheet DF
A1: DEC | D1: 1 | E1: 2 | F1: 3 | G1: 4 | H1: 5 | I1: 6 | J1: 7 | K1: 8 | U1: 1 | V1: 2 | W1: 3 | X1: 4 | Y1: 5 | Z1: 6 | AA1: 7 | AB1: 8 | AC1: 9 | AD1: 10
A2: XA3 | C2: 1 | D2: ='XL-Test'!E46 -> Toko Bagus | E2: ='XL-Test'!G46 -> Pembersih Lantai | F2: ='XL-Test'!I46 -> 30200 | G2: ='XL-Test'!J46 -> 60400 | H2: ='XL-Test'!K46 -> 3020 | I2: ='XL-Test'!L46 -> iPhone XR | J2: ='XL-Test'!M46 -> 4500 | K2: ='XL-Test'!N46 -> 52880 | L2: ='XL-Test'!H61 -> 170 | M2: ='XL-Test'!H62 -> 11.333333 | T2: 1 | U2: =SUBSTITUTE(_xlfn.FORMULATEXT('XL-Test'!E46),"$","") -> =VLOOKUP(D46;TRANSPOSE(B67:E68);2;0) | V2: =SUBSTITUTE(_xlfn.FORMULATEXT('XL-Test'!G46),"$","") -> =MID(VLOOKUP("*"&F46&"*";G68:I72;1;FALSE);6;100) | W2: =SUBSTITUTE(_xlfn.FORMULATEXT('XL-Test'!I46),"$","") -> =VLOOKUP("*"&F46&"*";G68:I72;3;FALSE) | X2: =SUBSTITUTE(_xlfn.FORMULATEXT('XL-Test'!J46),"$","") -> =SUMPRODUCT(H46;I46) | Y2: =SUBSTITUTE(_xlfn.FORMULATEXT('XL-Test'!K46),"$","") -> =HLOOKUP(H46;TRANSPOSE(K67:M70);3;TRUE)*J46 | Z2: =SUBSTITUTE(_xlfn.FORMULATEXT('XL-Test'!L46),"$","") -> =VLOOKUP(H46;{0\"iPhone XR";11\"Samsung S20";16\"Mendoan"};2;1) | AA2: =SUBSTITUTE(_xlfn.FORMULATEXT('XL-Test'!M46),"$","") -> =VLOOKUP(L46;IF({1\0};E73:E75;D73:D75);2;0) | AB2: =SUBSTITUTE(_xlfn.FORMULATEXT('XL-Test'!N46),"$","") -> =J46-K46-M46 | AC2: =_xlfn.FORMULATEXT('XL-Test'!H61) -> =SUM(H46:H60) | AD2: =_xlfn.FORMULATEXT('XL-Test'!N62) -> =AVERAGE(N46:N60)
A3: =A2&"|" -> XA3| | C3: 2 | D3: ='XL-Test'!E47 -> Toko Cemerlang | E3: ='XL-Test'!G47 -> Pewangi Pakaian | F3: ='XL-Test'!I47 -> 32500 | G3: ='XL-Test'!J47 -> 227500 | H3: ='XL-Test'!K47 -> 11375 | I3: ='XL-Test'!L47 -> iPhone XR | J3: ='XL-Test'!M47 -> 4500 | K3: ='XL-Test'!N47 -> 211625 | L3: ='XL-Test'!N61 -> 3935975 | M3: ='XL-Test'!N62 -> 262398.33 | T3: 2 | U3: =SUBSTITUTE(_xlfn.FORMULATEXT('XL-Test'!G46),"$","") -> =MID(VLOOKUP("*"&F46&"*";G68:I72;1;FALSE);6;100)
C4: 3 | D4: ='XL-Test'!E48 -> Toko Bahagia | E4: ='XL-Test'!G48 -> Sabun Cuci Piring | F4: ='XL-Test'!I48 -> 19900 | G4: ='XL-Test'!J48 -> 338300 | H4: ='XL-Test'!K48 -> 84575 | I4: ='XL-Test'!L48 -> Mendoan | J4: ='XL-Test'!M48 -> 7500 | K4: ='XL-Test'!N48 -> 246225 | M4: =M2*100 -> 1133.3333 | T4: 3 | U4: =SUBSTITUTE(_xlfn.FORMULATEXT('XL-Test'!I46),"$","") -> =VLOOKUP("*"&F46&"*";G68:I72;3;FALSE)
C5: 4 | D5: ='XL-Test'!E49 -> Toko Bagus | E5: ='XL-Test'!G49 -> Pembersih Lantai | F5: ='XL-Test'!I49 -> 30200 | G5: ='XL-Test'!J49 -> 271800 | H5: ='XL-Test'!K49 -> 13590 | I5: ='XL-Test'!L49 -> iPhone XR | J5: ='XL-Test'!M49 -> 4500 | K5: ='XL-Test'!N49 -> 253710 | M5: =M3*100 -> 26239833 | T5: 4 | U5: =SUBSTITUTE(_xlfn.FORMULATEXT('XL-Test'!J46),"$","") -> =SUMPRODUCT(H46;I46)
C6: 5 | D6: ='XL-Test'!E50 -> Toko Cemerlang | E6: ='XL-Test'!G50 -> Pembersih Lantai | F6: ='XL-Test'!I50 -> 30200 | G6: ='XL-Test'!J50 -> 422800 | H6: ='XL-Test'!K50 -> 42280 | I6: ='XL-Test'!L50 -> Samsung S20 | J6: ='XL-Test'!M50 -> 3500 | K6: ='XL-Test'!N50 -> 377020 | T6: 5 | U6: =SUBSTITUTE(_xlfn.FORMULATEXT('XL-Test'!K46),"$","") -> =HLOOKUP(H46;TRANSPOSE(K67:M70);3;TRUE)*J46
C7: 6 | D7: ='XL-Test'!E51 -> Toko Bagus | E7: ='XL-Test'!G51 -> Sabun Cuci Piring | F7: ='XL-Test'!I51 -> 19900 | G7: ='XL-Test'!J51 -> 139300 | H7: ='XL-Test'!K51 -> 6965 | I7: ='XL-Test'!L51 -> iPhone XR | J7: ='XL-Test'!M51 -> 4500 | K7: ='XL-Test'!N51 -> 127835 | T7: 6 | U7: =SUBSTITUTE(_xlfn.FORMULATEXT('XL-Test'!L46),"$","") -> =VLOOKUP(H46;{0\"iPhone XR";11\"Samsung S20";16\"Mendoan"};2;1)
C8: 7 | D8: ='XL-Test'!E52 -> Toko Cemerlang | E8: ='XL-Test'!G52 -> Minyak Goreng | F8: ='XL-Test'!I52 -> 23600 | G8: ='XL-Test'!J52 -> 236000 | H8: ='XL-Test'!K52 -> 11800 | I8: ='XL-Test'!L52 -> iPhone XR | J8: ='XL-Test'!M52 -> 4500 | K8: ='XL-Test'!N52 -> 219700 | T8: 7 | U8: =SUBSTITUTE(_xlfn.FORMULATEXT('XL-Test'!M46),"$","") -> =VLOOKUP(L46;IF({1\0};E73:E75;D73:D75);2;0)
C9: 8 | D9: ='XL-Test'!E53 -> Toko Bagus | E9: ='XL-Test'!G53 -> Pembersih Lantai | F9: ='XL-Test'!I53 -> 30200 | G9: ='XL-Test'!J53 -> 724800 | H9: ='XL-Test'!K53 -> 181200 | I9: ='XL-Test'!L53 -> Mendoan | J9: ='XL-Test'!M53 -> 7500 | K9: ='XL-Test'!N53 -> 536100 | T9: 8 | U9: =SUBSTITUTE(_xlfn.FORMULATEXT('XL-Test'!N46),"$","") -> =J46-K46-M46
C10: 9 | D10: ='XL-Test'!E54 -> Toko Cemerlang | E10: ='XL-Test'!G54 -> Minyak Goreng | F10: ='XL-Test'!I54 -> 23600 | G10: ='XL-Test'!J54 -> 259600 | H10: ='XL-Test'!K54 -> 25960 | I10: ='XL-Test'!L54 -> Samsung S20 | J10: ='XL-Test'!M54 -> 3500 | K10: ='XL-Test'!N54 -> 230140 | T10: 9
C11: 10 | D11: ='XL-Test'!E55 -> Toko Bagus | E11: ='XL-Test'!G55 -> Pembersih Lantai | F11: ='XL-Test'!I55 -> 30200 | G11: ='XL-Test'!J55 -> 211400 | H11: ='XL-Test'!K55 -> 10570 | I11: ='XL-Test'!L55 -> iPhone XR | J11: ='XL-Test'!M55 -> 4500 | K11: ='XL-Test'!N55 -> 196330 | T11: 10
C12: 11 | D12: ='XL-Test'!E56 -> Toko Bahagia | E12: ='XL-Test'!G56 -> Pewangi Pakaian | F12: ='XL-Test'!I56 -> 32500 | G12: ='XL-Test'!J56 -> 780000 | H12: ='XL-Test'!K56 -> 195000 | I12: ='XL-Test'!L56 -> Mendoan | J12: ='XL-Test'!M56 -> 7500 | K12: ='XL-Test'!N56 -> 577500
C13: 12 | D13: ='XL-Test'!E57 -> Toko Bagus | E13: ='XL-Test'!G57 -> Detergen | F13: ='XL-Test'!I57 -> 28000 | G13: ='XL-Test'!J57 -> 56000 | H13: ='XL-Test'!K57 -> 2800 | I13: ='XL-Test'!L57 -> iPhone XR | J13: ='XL-Test'!M57 -> 4500 | K13: ='XL-Test'!N57 -> 48700
C14: 13 | D14: ='XL-Test'!E58 -> Toko Bahagia | E14: ='XL-Test'!G58 -> Detergen | F14: ='XL-Test'!I58 -> 28000 | G14: ='XL-Test'!J58 -> 28000 | H14: ='XL-Test'!K58 -> 1400 | I14: ='XL-Test'!L58 -> iPhone XR | J14: ='XL-Test'!M58 -> 4500 | K14: ='XL-Test'!N58 -> 22100
C15: 14 | D15: ='XL-Test'!E59 -> Toko Bagus | E15: ='XL-Test'!G59 -> Pembersih Lantai | F15: ='XL-Test'!I59 -> 30200 | G15: ='XL-Test'!J59 -> 362400 | H15: ='XL-Test'!K59 -> 36240 | I15: ='XL-Test'!L59 -> Samsung S20 | J15: ='XL-Test'!M59 -> 3500 | K15: ='XL-Test'!N59 -> 322660
C16: 15 | D16: ='XL-Test'!E60 -> Toko Bahagia | E16: ='XL-Test'!G60 -> Pembersih Lantai | F16: ='XL-Test'!I60 -> 30200 | G16: ='XL-Test'!J60 -> 694600 | H16: ='XL-Test'!K60 -> 173650 | I16: ='XL-Test'!L60 -> Mendoan | J16: ='XL-Test'!M60 -> 7500 | K16: ='XL-Test'!N60 -> 513450
C18: Value | D18: =CODE(RIGHT(D3))+CODE(RIGHT(D2))+CODE(RIGHT(D4))+CODE(RIGHT(D5))+CODE(RIGHT(D6))+CODE(RIGHT(D6))+CODE(RIGHT(D7))+CODE(RIGHT(D8))+CODE(RIGHT(D9))+CODE(RIGHT(D10))+CODE(RIGHT(D11))+CODE(RIGHT(D12))+CODE(RIGHT(D13))+CODE(RIGHT(D14))+CODE(RIGHT(D15))+CODE(RIGHT(D16))+CODE(MID(D2,7,1))+CODE(MID(D3,7,1))+CODE(MID(D4,7,1))+CODE(MID(D5,7,1))+CODE(MID(D6,7,1))+CODE(MID(D7,7,1))+CODE(MID(D8,7,1)) -> 2399 | E18: =CODE(RIGHT(E3))+CODE(RIGHT(E2))+CODE(RIGHT(E4))+CODE(RIGHT(E5))+CODE(RIGHT(E6))+CODE(RIGHT(E6))+CODE(RIGHT(E7))+CODE(RIGHT(E8))+CODE(RIGHT(E9))+CODE(RIGHT(E10))+CODE(RIGHT(E11))+CODE(RIGHT(E12))+CODE(RIGHT(E13))+CODE(RIGHT(E14))+CODE(RIGHT(E15))+CODE(RIGHT(E16))+CODE(LEFT(E2))+CODE(LEFT(E3))+CODE(LEFT(E4))+CODE(LEFT(E5))+CODE(LEFT(E6))+CODE(LEFT(E6)) -> 2175 | F18: =SUM(F2:F16)+F3+F6+F10+F14 -> 533700 | G18: =SUM(G2:G16)+G3+G7+G10+G13 -> 5495300 | H18: =SUM(H2:H16)+H2+H5+H9+H13+H15 -> 1037275 | I18: =CODE( LEFT(I3))+CODE( LEFT(I2))+CODE( LEFT(I4))+CODE( LEFT(I5))+CODE( LEFT(I6))+CODE( LEFT(I6))+CODE( LEFT(I7))+CODE( LEFT(I8))+CODE( LEFT(I9))+CODE( LEFT(I10))+CODE( LEFT(I11))+CODE( LEFT(I12))+CODE( LEFT(I13))+CODE( LEFT(I14))+CODE( LEFT(I15))+CODE( LEFT(I16))+CODE(RIGHT(I2))+CODE(RIGHT(I3))+CODE(RIGHT(I4))+CODE(RIGHT(I5))+CODE(RIGHT(I6))+CODE(RIGHT(I6)) -> 1932 | J18: =SUM(J2:J16)+J3+J6+J10+J13 -> 92500 | K18: =SUM(K2:K16)+K4+K8+K13+K16 -> 4964050 | L18: =L2*100+L3 -> 3952975 | M18: =INT(M4+M5) -> 26240966
B20: *** | C20: Valuu F | D20: =IFERROR(DEC2HEX(IF(OR(D2="",D2=0),D22,D18)),"EEEE")&D31 -> 95F1 | E20: =IFERROR(DEC2HEX(IF(OR(E2="",E2=0),E22,E18)),"EEEE")&E31 -> 87F1 | F20: =IFERROR(DEC2HEX(IF(OR(F2="",F2=0),F22,F18)),"EEEE")&F31 -> 824C41 | G20: =IFERROR(DEC2HEX(IF(OR(G2="",G2=0),G22,G18)),"EEEE")&G31 -> 53DA041 | H20: =IFERROR(DEC2HEX(IF(OR(H2="",H2=0),H22,H18)),"EEEE")&H31 -> FD3DB1 | I20: =IFERROR(DEC2HEX(IF(OR(I2="",I2=0),I22,I18)),"EEEE")&I31 -> 78C1 | J20: =IFERROR(DEC2HEX(IF(OR(J2="",J2=0),J22,J18)),"EEEE")&J31 -> 169541 | K20: =IFERROR(DEC2HEX(IF(OR(K2="",K2=0),K22,K18)),"EEEE")&K31 -> 4BBED21 | ... M20: =IFERROR(DEC2HEX(IF(OR(M2="",M2=0),M22,M18)),"EEEE")&M31 -> 19067C61
C22: Random | D22: 5567 | E22: 8646 | F22: 1669 | G22: 3015 | H22: 2054 | I22: 4590 | J22: 7598 | K22: 7048 | L22: 9956 | M22: 4653
C24: TRUE | D24: =LEFT(DEC2HEX(D22),2) -> 15 | E24: =LEFT(DEC2HEX(E22),2) -> 21 | F24: =LEFT(DEC2HEX(F22),2) -> 68 | G24: =LEFT(DEC2HEX(G22),2) -> BC | H24: =LEFT(DEC2HEX(H22),2) -> 80 | I24: =LEFT(DEC2HEX(I22),2) -> 11 | J24: =LEFT(DEC2HEX(J22),2) -> 1D | K24: =LEFT(DEC2HEX(K22),2) -> 1B | ... M24: =LEFT(DEC2HEX(M22),2) -> 12
C25: FALSE | D25: =RIGHT(DEC2HEX(D22),2) -> BF | E25: =RIGHT(DEC2HEX(E22),2) -> C6 | F25: =RIGHT(DEC2HEX(F22),2) -> 85 | G25: =RIGHT(DEC2HEX(G22),2) -> C7 | H25: =RIGHT(DEC2HEX(H22),2) -> 06 | I25: =RIGHT(DEC2HEX(I22),2) -> EE | J25: =RIGHT(DEC2HEX(J22),2) -> AE | K25: =RIGHT(DEC2HEX(K22),2) -> 88 | ... M25: =RIGHT(DEC2HEX(M22),2) -> 2D
C28: Cek Wajib | D28: =AND(OR(ISNUMBER(FIND("(B",U2)),ISNUMBER(FIND("(C",U2)),ISNUMBER(FIND(":E",U2))),OR(ISNUMBER(FIND("66",U2)),ISNUMBER(FIND("67",U2)),ISNUMBER(FIND("68",U2)))) -> TRUE | E28: =AND(OR(ISNUMBER(FIND(";G",SUBSTITUTE(V2,",",";"))),ISNUMBER(FIND(":H",V2)),ISNUMBER(FIND(":I",V2))),ISNUMBER(FIND(";1;",SUBSTITUTE(V2,",",";")))) -> TRUE | F28: =OR(ISNUMBER(FIND(";G",SUBSTITUTE(W2,",",";"))),ISNUMBER(FIND(":I",W2))) -> TRUE | G28: TRUE | H28: =AND(OR(ISNUMBER(FIND("(K",Y2)),ISNUMBER(FIND(":M",Y2))),OR(ISNUMBER(FIND("66",Y2)),ISNUMBER(FIND("67",Y2)),ISNUMBER(FIND("68",Y2)),ISNUMBER(FIND("69",Y2)),ISNUMBER(FIND("70",Y2)))) -> TRUE | I28: =OR(ISNUMBER(FIND("{",Z2)),ISNUMBER(FIND("}",Z2)),ISNUMBER(FIND("STACK",Z2))) -> TRUE | J28: =AND(ISNUMBER(FIND(":E",AA2)),ISNUMBER(FIND(":D",AA2))) -> TRUE | K28: TRUE | L28: TRUE | M28: TRUE
C29: cek rumus | D29: =AND(ISNUMBER(FIND("=",U2)),ISNUMBER(FIND("(",U2))) -> TRUE | E29: =AND(ISNUMBER(FIND("=",V2)),ISNUMBER(FIND("(",V2))) -> TRUE | F29: =AND(ISNUMBER(FIND("=",W2)),ISNUMBER(FIND("(",W2))) -> TRUE | G29: =AND(ISNUMBER(FIND("=",X2))) -> TRUE | H29: =AND(ISNUMBER(FIND("=",Y2)),ISNUMBER(FIND("(",Y2))) -> TRUE | I29: =AND(ISNUMBER(FIND("=",Z2)),ISNUMBER(FIND("(",Z2))) -> TRUE | J29: =AND(ISNUMBER(FIND("=",AA2)),ISNUMBER(FIND("(",AA2))) -> TRUE | K29: =AND(ISNUMBER(FIND("=",AB2))) -> TRUE | L29: =AND(ISNUMBER(FIND("=",AC2))) -> TRUE | M29: =AND(ISNUMBER(FIND("=",AD2))) -> TRUE
C30: Cek Wajib | D30: =AND(ISNUMBER(FIND("VLO",U2))) -> TRUE | E30: =AND(ISNUMBER(FIND("VLO",V2))) -> TRUE | F30: =AND(ISNUMBER(FIND("VLO",W2))) -> TRUE | G30: TRUE | H30: =AND(ISNUMBER(FIND("HLO",Y2))) -> TRUE | I30: =AND(ISNUMBER(FIND("VLO",Z2))) -> TRUE | J30: =AND(ISNUMBER(FIND("VLO",AA2))) -> TRUE | K30: TRUE | L30: TRUE | M30: TRUE
B31: ** | D31: =AND(D28:D30,D62)+0 -> 1 | E31: =AND(E28:E30,E62)+0 -> 1 | F31: =AND(F28:F30,F62)+0 -> 1 | G31: =AND(G28:G30,G62)+0 -> 1 | H31: =AND(H28:H30,H62)+0 -> 1 | I31: =AND(I28:I30,I62)+0 -> 1 | J31: =AND(J28:J30,J62)+0 -> 1 | K31: =AND(K28:K30,K62)+0 -> 1 | ... M31: =AND(M28:M30,M62)+0 -> 1
C33: Cek Formula | D33: =IFERROR(LEN(U2)-LEN(SUBSTITUTE(U2,"(","")),99) -> 2 | E33: =IFERROR(LEN(V2)-LEN(SUBSTITUTE(V2,"(","")),99) -> 2 | F33: =IFERROR(LEN(W2)-LEN(SUBSTITUTE(W2,"(","")),99) -> 1 | G33: =IFERROR(LEN(X2)-LEN(SUBSTITUTE(X2,"(","")),99) -> 1 | H33: =IFERROR(LEN(Y2)-LEN(SUBSTITUTE(Y2,"(","")),99) -> 2 | I33: =IFERROR(LEN(Z2)-LEN(SUBSTITUTE(Z2,"(","")),99) -> 1 | J33: =IFERROR(LEN(AA2)-LEN(SUBSTITUTE(AA2,"(","")),99) -> 2 | K33: =IFERROR(LEN(AB2)-LEN(SUBSTITUTE(AB2,"(","")),99) -> 0 | ... M33: =IFERROR(LEN(AD2)-LEN(SUBSTITUTE(AD2,"(","")),99) -> 1
D34: 2 | E34: 2 | F34: 2 | G34: 1 | H34: 2 | I34: 2 | J34: 2 | K34: 0 | L34: 1 | M34: 1
D35: =D33<=D34 -> TRUE | E35: =E33<=E34 -> TRUE | F35: =F33<=F34 -> TRUE | G35: TRUE | H35: =H33<=H34 -> TRUE | I35: =I33<=I34 -> TRUE | J35: =J33<=J34 -> TRUE | K35: TRUE | L35: =L33<=L34 -> TRUE | M35: =M33<=M34 -> TRUE
D36: =D35+0 -> 1 | E36: =E35+0 -> 1 | F36: =F35+0 -> 1 | G36: =G35+0 -> 1 | H36: =H35+0 -> 1 | I36: =I35+0 -> 1 | J36: =J35+0 -> 1 | K36: =K35+0 -> 1 | ... M36: =M35+0 -> 1
C37: Cek Formula | D37: =OR(AND(ISNUMBER(FIND("VLO",U2)),ISNUMBER(FIND("TRAN",U2))),AND(ISNUMBER(FIND("VLO",U2)),OR(ISNUMBER(FIND("MATCH",U2)),ISNUMBER(FIND("IF",U2)),ISNUMBER(FIND("RIGH",U2))))) -> TRUE | E37: =AND(ISNUMBER(FIND("VLO",V2)),ISNUMBER(FIND("*",V2))) -> TRUE | F37: =AND(ISNUMBER(FIND("VLO",W2)),ISNUMBER(FIND("*",W2))) -> TRUE | G37: =OR(ISNUMBER(FIND("*",X2)),ISNUMBER(FIND("PROD",X2))) -> TRUE | H37: =AND(ISNUMBER(FIND("HLO",Y2)),ISNUMBER(FIND("TRAN",Y2))) -> TRUE | I37: =AND(ISNUMBER(FIND("VLO",Z2)),OR(ISNUMBER(FIND("{",Z2)),ISNUMBER(FIND("STACK",Z2)))) -> TRUE | J37: =AND(ISNUMBER(FIND("VLO",AA2)),ISNUMBER(FIND("{",AA2))) -> TRUE | K37: =AND(ISNUMBER(FIND("-",AB2))) -> TRUE | L37: =AND(ISNUMBER(FIND("SUM",AC2))) -> TRUE | M37: =AND(ISNUMBER(FIND("AVE",AD2))) -> TRUE
B39: *** | D39: =IF(D37,D24,D25)&D36 -> 151 | E39: =IF(E37,E24,E25)&E36 -> 211 | F39: =IF(F37,F24,F25)&F36 -> 681 | G39: =IF(G37,G24,G25)&G36 -> BC1 | H39: =IF(H37,H24,H25)&H36 -> 801 | I39: =IF(I37,I24,I25)&I36 -> 111 | J39: =IF(J37,J24,J25)&J36 -> 1D1 | K39: =IF(K37,K24,K25)&K36 -> 1B1 | ... M39: =IF(M37,M24,M25)&M36 -> 121
C43: 1 | D43: =IFERROR(LEN(_xlfn.FORMULATEXT('XL-Test'!E46)),0) -> 40 | E43: =IFERROR(LEN(_xlfn.FORMULATEXT('XL-Test'!G46)),0) -> 52 | F43: =IFERROR(LEN(_xlfn.FORMULATEXT('XL-Test'!I46)),0) -> 41 | G43: =IFERROR(LEN(_xlfn.FORMULATEXT('XL-Test'!J46)),0) -> 20 | H43: =IFERROR(LEN(_xlfn.FORMULATEXT('XL-Test'!K46)),0) -> 47 | I43: =IFERROR(LEN(_xlfn.FORMULATEXT('XL-Test'!L46)),0) -> 63 | J43: =IFERROR(LEN(_xlfn.FORMULATEXT('XL-Test'!M46)),0) -> 51 | K43: =IFERROR(LEN(_xlfn.FORMULATEXT('XL-Test'!N46)),0) -> 12
C44: 2 | D44: =IFERROR(LEN(_xlfn.FORMULATEXT('XL-Test'!E47)),0) -> 40 | E44: =IFERROR(LEN(_xlfn.FORMULATEXT('XL-Test'!G47)),0) -> 52 | F44: =IFERROR(LEN(_xlfn.FORMULATEXT('XL-Test'!I47)),0) -> 41 | G44: =IFERROR(LEN(_xlfn.FORMULATEXT('XL-Test'!J47)),0) -> 20 | H44: =IFERROR(LEN(_xlfn.FORMULATEXT('XL-Test'!K47)),0) -> 47 | I44: =IFERROR(LEN(_xlfn.FORMULATEXT('XL-Test'!L47)),0) -> 63 | J44: =IFERROR(LEN(_xlfn.FORMULATEXT('XL-Test'!M47)),0) -> 51 | K44: =IFERROR(LEN(_xlfn.FORMULATEXT('XL-Test'!N47)),0) -> 12
C45: 3 | D45: =IFERROR(LEN(_xlfn.FORMULATEXT('XL-Test'!E48)),0) -> 40 | E45: =IFERROR(LEN(_xlfn.FORMULATEXT('XL-Test'!G48)),0) -> 52 | F45: =IFERROR(LEN(_xlfn.FORMULATEXT('XL-Test'!I48)),0) -> 41 | G45: =IFERROR(LEN(_xlfn.FORMULATEXT('XL-Test'!J48)),0) -> 20 | H45: =IFERROR(LEN(_xlfn.FORMULATEXT('XL-Test'!K48)),0) -> 47 | I45: =IFERROR(LEN(_xlfn.FORMULATEXT('XL-Test'!L48)),0) -> 63 | J45: =IFERROR(LEN(_xlfn.FORMULATEXT('XL-Test'!M48)),0) -> 51 | K45: =IFERROR(LEN(_xlfn.FORMULATEXT('XL-Test'!N48)),0) -> 12
C46: 4 | D46: =IFERROR(LEN(_xlfn.FORMULATEXT('XL-Test'!E49)),0) -> 40 | E46: =IFERROR(LEN(_xlfn.FORMULATEXT('XL-Test'!G49)),0) -> 52 | F46: =IFERROR(LEN(_xlfn.FORMULATEXT('XL-Test'!I49)),0) -> 41 | G46: =IFERROR(LEN(_xlfn.FORMULATEXT('XL-Test'!J49)),0) -> 20 | H46: =IFERROR(LEN(_xlfn.FORMULATEXT('XL-Test'!K49)),0) -> 47 | I46: =IFERROR(LEN(_xlfn.FORMULATEXT('XL-Test'!L49)),0) -> 63 | J46: =IFERROR(LEN(_xlfn.FORMULATEXT('XL-Test'!M49)),0) -> 51 | K46: =IFERROR(LEN(_xlfn.FORMULATEXT('XL-Test'!N49)),0) -> 12
C47: 5 | D47: =IFERROR(LEN(_xlfn.FORMULATEXT('XL-Test'!E50)),0) -> 40 | E47: =IFERROR(LEN(_xlfn.FORMULATEXT('XL-Test'!G50)),0) -> 52 | F47: =IFERROR(LEN(_xlfn.FORMULATEXT('XL-Test'!I50)),0) -> 41 | G47: =IFERROR(LEN(_xlfn.FORMULATEXT('XL-Test'!J50)),0) -> 20 | H47: =IFERROR(LEN(_xlfn.FORMULATEXT('XL-Test'!K50)),0) -> 47 | I47: =IFERROR(LEN(_xlfn.FORMULATEXT('XL-Test'!L50)),0) -> 63 | J47: =IFERROR(LEN(_xlfn.FORMULATEXT('XL-Test'!M50)),0) -> 51 | K47: =IFERROR(LEN(_xlfn.FORMULATEXT('XL-Test'!N50)),0) -> 12
C48: 6 | D48: =IFERROR(LEN(_xlfn.FORMULATEXT('XL-Test'!E51)),0) -> 40 | E48: =IFERROR(LEN(_xlfn.FORMULATEXT('XL-Test'!G51)),0) -> 52 | F48: =IFERROR(LEN(_xlfn.FORMULATEXT('XL-Test'!I51)),0) -> 41 | G48: =IFERROR(LEN(_xlfn.FORMULATEXT('XL-Test'!J51)),0) -> 20 | H48: =IFERROR(LEN(_xlfn.FORMULATEXT('XL-Test'!K51)),0) -> 47 | I48: =IFERROR(LEN(_xlfn.FORMULATEXT('XL-Test'!L51)),0) -> 63 | J48: =IFERROR(LEN(_xlfn.FORMULATEXT('XL-Test'!M51)),0) -> 51 | K48: =IFERROR(LEN(_xlfn.FORMULATEXT('XL-Test'!N51)),0) -> 12
C49: 7 | D49: =IFERROR(LEN(_xlfn.FORMULATEXT('XL-Test'!E52)),0) -> 40 | E49: =IFERROR(LEN(_xlfn.FORMULATEXT('XL-Test'!G52)),0) -> 52 | F49: =IFERROR(LEN(_xlfn.FORMULATEXT('XL-Test'!I52)),0) -> 41 | G49: =IFERROR(LEN(_xlfn.FORMULATEXT('XL-Test'!J52)),0) -> 20 | H49: =IFERROR(LEN(_xlfn.FORMULATEXT('XL-Test'!K52)),0) -> 47 | I49: =IFERROR(LEN(_xlfn.FORMULATEXT('XL-Test'!L52)),0) -> 63 | J49: =IFERROR(LEN(_xlfn.FORMULATEXT('XL-Test'!M52)),0) -> 51 | K49: =IFERROR(LEN(_xlfn.FORMULATEXT('XL-Test'!N52)),0) -> 12
C50: 8 | D50: =IFERROR(LEN(_xlfn.FORMULATEXT('XL-Test'!E53)),0) -> 40 | E50: =IFERROR(LEN(_xlfn.FORMULATEXT('XL-Test'!G53)),0) -> 52 | F50: =IFERROR(LEN(_xlfn.FORMULATEXT('XL-Test'!I53)),0) -> 41 | G50: =IFERROR(LEN(_xlfn.FORMULATEXT('XL-Test'!J53)),0) -> 20 | H50: =IFERROR(LEN(_xlfn.FORMULATEXT('XL-Test'!K53)),0) -> 47 | I50: =IFERROR(LEN(_xlfn.FORMULATEXT('XL-Test'!L53)),0) -> 63 | J50: =IFERROR(LEN(_xlfn.FORMULATEXT('XL-Test'!M53)),0) -> 51 | K50: =IFERROR(LEN(_xlfn.FORMULATEXT('XL-Test'!N53)),0) -> 12
C51: 9 | D51: =IFERROR(LEN(_xlfn.FORMULATEXT('XL-Test'!E54)),0) -> 40 | E51: =IFERROR(LEN(_xlfn.FORMULATEXT('XL-Test'!G54)),0) -> 52 | F51: =IFERROR(LEN(_xlfn.FORMULATEXT('XL-Test'!I54)),0) -> 41 | G51: =IFERROR(LEN(_xlfn.FORMULATEXT('XL-Test'!J54)),0) -> 20 | H51: =IFERROR(LEN(_xlfn.FORMULATEXT('XL-Test'!K54)),0) -> 47 | I51: =IFERROR(LEN(_xlfn.FORMULATEXT('XL-Test'!L54)),0) -> 63 | J51: =IFERROR(LEN(_xlfn.FORMULATEXT('XL-Test'!M54)),0) -> 51 | K51: =IFERROR(LEN(_xlfn.FORMULATEXT('XL-Test'!N54)),0) -> 12
...
